/*
*** MADE BY MITHION'S .SCHEMATIC TO JAVA CONVERTING TOOL v1.6 ***
*/

package arcticraft.gen;

import java.util.Random;

import net.minecraft.block.Block;
import net.minecraft.world.World;
import net.minecraft.world.gen.feature.WorldGenerator;
import arcticraft.main.MainRegistry;

public class AC_GenEskimoVillage extends WorldGenerator
{

	public AC_GenEskimoVillage()
	{
	}

	public boolean generate(World world, Random rand, int i, int j, int k)
	{
		if (world.getBlockId(i, j + 1, k + 1) != 78)
		{
			return false;
		}
		if (world.getBlockId(i, j + 1, k - 1) != 78)
		{
			return false;
		}
		if (world.getBlockId(i + 1, j + 1, k) != 78)
		{
			return false;
		}
		if (world.getBlockId(i - 1, j + 1, k) != 78)
		{
			return false;
		}
		if (world.getBlockId(i, j + 1, k) != 78)
		{
			return false;
		}

		world.setBlock(i + 0, j + 0, k + 0, Block.dirt.blockID);
		world.setBlock(i + 0, j + 0, k + 1, Block.dirt.blockID);
		world.setBlock(i + 0, j + 0, k + 2, Block.dirt.blockID);
		world.setBlock(i + 0, j + 0, k + 3, Block.dirt.blockID);
		world.setBlock(i + 0, j + 0, k + 4, Block.dirt.blockID);
		world.setBlock(i + 0, j + 0, k + 5, Block.dirt.blockID);
		world.setBlock(i + 0, j + 0, k + 6, Block.dirt.blockID);
		world.setBlock(i + 0, j + 0, k + 7, Block.dirt.blockID);
		world.setBlock(i + 0, j + 0, k + 8, Block.dirt.blockID);
		world.setBlock(i + 0, j + 0, k + 9, Block.dirt.blockID);
		world.setBlock(i + 0, j + 0, k + 10, Block.dirt.blockID);
		world.setBlock(i + 0, j + 0, k + 11, Block.dirt.blockID);
		world.setBlock(i + 0, j + 0, k + 12, Block.dirt.blockID);
		world.setBlock(i + 0, j + 0, k + 13, Block.dirt.blockID);
		world.setBlock(i + 0, j + 0, k + 14, Block.dirt.blockID);
		world.setBlock(i + 0, j + 0, k + 15, Block.dirt.blockID);
		world.setBlock(i + 0, j + 0, k + 16, Block.dirt.blockID);
		world.setBlock(i + 0, j + 0, k + 17, Block.dirt.blockID);
		world.setBlock(i + 0, j + 0, k + 18, Block.dirt.blockID);
		world.setBlock(i + 0, j + 0, k + 19, Block.dirt.blockID);
		world.setBlock(i + 0, j + 0, k + 20, Block.dirt.blockID);
		world.setBlock(i + 0, j + 0, k + 21, Block.dirt.blockID);
		world.setBlock(i + 0, j + 0, k + 22, Block.dirt.blockID);
		world.setBlock(i + 0, j + 0, k + 23, Block.dirt.blockID);
		world.setBlock(i + 0, j + 0, k + 24, Block.dirt.blockID);
		world.setBlock(i + 0, j + 0, k + 25, Block.dirt.blockID);
		world.setBlock(i + 0, j + 0, k + 26, Block.dirt.blockID);
		world.setBlock(i + 0, j + 1, k + 0, Block.dirt.blockID);
		world.setBlock(i + 0, j + 1, k + 1, Block.dirt.blockID);
		world.setBlock(i + 0, j + 1, k + 2, Block.dirt.blockID);
		world.setBlock(i + 0, j + 1, k + 3, Block.dirt.blockID);
		world.setBlock(i + 0, j + 1, k + 4, Block.dirt.blockID);
		world.setBlock(i + 0, j + 1, k + 5, Block.dirt.blockID);
		world.setBlock(i + 0, j + 1, k + 6, Block.dirt.blockID);
		world.setBlock(i + 0, j + 1, k + 7, Block.dirt.blockID);
		world.setBlock(i + 0, j + 1, k + 8, Block.dirt.blockID);
		world.setBlock(i + 0, j + 1, k + 9, Block.dirt.blockID);
		world.setBlock(i + 0, j + 1, k + 10, Block.dirt.blockID);
		world.setBlock(i + 0, j + 1, k + 11, Block.dirt.blockID);
		world.setBlock(i + 0, j + 1, k + 12, Block.dirt.blockID);
		world.setBlock(i + 0, j + 1, k + 13, Block.dirt.blockID);
		world.setBlock(i + 0, j + 1, k + 14, Block.dirt.blockID);
		world.setBlock(i + 0, j + 1, k + 15, Block.dirt.blockID);
		world.setBlock(i + 0, j + 1, k + 16, Block.dirt.blockID);
		world.setBlock(i + 0, j + 1, k + 17, Block.dirt.blockID);
		world.setBlock(i + 0, j + 1, k + 18, Block.dirt.blockID);
		world.setBlock(i + 0, j + 1, k + 19, Block.dirt.blockID);
		world.setBlock(i + 0, j + 1, k + 20, Block.dirt.blockID);
		world.setBlock(i + 0, j + 1, k + 21, Block.dirt.blockID);
		world.setBlock(i + 0, j + 1, k + 22, Block.dirt.blockID);
		world.setBlock(i + 0, j + 1, k + 23, Block.dirt.blockID);
		world.setBlock(i + 0, j + 1, k + 24, Block.dirt.blockID);
		world.setBlock(i + 0, j + 1, k + 25, Block.dirt.blockID);
		world.setBlock(i + 0, j + 1, k + 26, Block.dirt.blockID);
		world.setBlock(i + 0, j + 2, k + 0, Block.grass.blockID);
		world.setBlock(i + 0, j + 2, k + 1, Block.grass.blockID);
		world.setBlock(i + 0, j + 2, k + 2, Block.grass.blockID);
		world.setBlock(i + 0, j + 2, k + 3, Block.grass.blockID);
		world.setBlock(i + 0, j + 2, k + 4, Block.grass.blockID);
		world.setBlock(i + 0, j + 2, k + 5, Block.grass.blockID);
		world.setBlock(i + 0, j + 2, k + 6, Block.grass.blockID);
		world.setBlock(i + 0, j + 2, k + 7, Block.grass.blockID);
		world.setBlock(i + 0, j + 2, k + 8, Block.grass.blockID);
		world.setBlock(i + 0, j + 2, k + 9, Block.grass.blockID);
		world.setBlock(i + 0, j + 2, k + 10, Block.grass.blockID);
		world.setBlock(i + 0, j + 2, k + 11, Block.grass.blockID);
		world.setBlock(i + 0, j + 2, k + 12, Block.grass.blockID);
		world.setBlock(i + 0, j + 2, k + 13, Block.grass.blockID);
		world.setBlock(i + 0, j + 2, k + 14, Block.grass.blockID);
		world.setBlock(i + 0, j + 2, k + 15, Block.grass.blockID);
		world.setBlock(i + 0, j + 2, k + 16, Block.grass.blockID);
		world.setBlock(i + 0, j + 2, k + 17, Block.grass.blockID);
		world.setBlock(i + 0, j + 2, k + 18, Block.grass.blockID);
		world.setBlock(i + 0, j + 2, k + 19, Block.grass.blockID);
		world.setBlock(i + 0, j + 2, k + 20, Block.grass.blockID);
		world.setBlock(i + 0, j + 2, k + 21, Block.grass.blockID);
		world.setBlock(i + 0, j + 2, k + 22, Block.grass.blockID);
		world.setBlock(i + 0, j + 2, k + 23, Block.grass.blockID);
		world.setBlock(i + 0, j + 2, k + 24, Block.grass.blockID);
		world.setBlock(i + 0, j + 2, k + 25, Block.grass.blockID);
		world.setBlock(i + 0, j + 2, k + 26, Block.grass.blockID);
		world.setBlock(i + 1, j + 0, k + 0, Block.dirt.blockID);
		world.setBlock(i + 1, j + 0, k + 1, Block.dirt.blockID);
		world.setBlock(i + 1, j + 0, k + 2, Block.dirt.blockID);
		world.setBlock(i + 1, j + 0, k + 3, Block.dirt.blockID);
		world.setBlock(i + 1, j + 0, k + 4, Block.dirt.blockID);
		world.setBlock(i + 1, j + 0, k + 5, Block.dirt.blockID);
		world.setBlock(i + 1, j + 0, k + 6, Block.dirt.blockID);
		world.setBlock(i + 1, j + 0, k + 7, Block.dirt.blockID);
		world.setBlock(i + 1, j + 0, k + 8, Block.dirt.blockID);
		world.setBlock(i + 1, j + 0, k + 9, Block.dirt.blockID);
		world.setBlock(i + 1, j + 0, k + 10, Block.dirt.blockID);
		world.setBlock(i + 1, j + 0, k + 11, Block.dirt.blockID);
		world.setBlock(i + 1, j + 0, k + 12, Block.dirt.blockID);
		world.setBlock(i + 1, j + 0, k + 13, Block.dirt.blockID);
		world.setBlock(i + 1, j + 0, k + 14, Block.dirt.blockID);
		world.setBlock(i + 1, j + 0, k + 15, Block.dirt.blockID);
		world.setBlock(i + 1, j + 0, k + 16, Block.dirt.blockID);
		world.setBlock(i + 1, j + 0, k + 17, Block.dirt.blockID);
		world.setBlock(i + 1, j + 0, k + 18, Block.dirt.blockID);
		world.setBlock(i + 1, j + 0, k + 19, Block.dirt.blockID);
		world.setBlock(i + 1, j + 0, k + 20, Block.dirt.blockID);
		world.setBlock(i + 1, j + 0, k + 21, Block.dirt.blockID);
		world.setBlock(i + 1, j + 0, k + 22, Block.dirt.blockID);
		world.setBlock(i + 1, j + 0, k + 23, Block.dirt.blockID);
		world.setBlock(i + 1, j + 0, k + 24, Block.dirt.blockID);
		world.setBlock(i + 1, j + 0, k + 25, Block.dirt.blockID);
		world.setBlock(i + 1, j + 0, k + 26, Block.dirt.blockID);
		world.setBlock(i + 1, j + 1, k + 0, Block.dirt.blockID);
		world.setBlock(i + 1, j + 1, k + 1, Block.dirt.blockID);
		world.setBlock(i + 1, j + 1, k + 2, Block.dirt.blockID);
		world.setBlock(i + 1, j + 1, k + 3, Block.dirt.blockID);
		world.setBlock(i + 1, j + 1, k + 4, Block.dirt.blockID);
		world.setBlock(i + 1, j + 1, k + 5, Block.dirt.blockID);
		world.setBlock(i + 1, j + 1, k + 6, Block.dirt.blockID);
		world.setBlock(i + 1, j + 1, k + 7, Block.dirt.blockID);
		world.setBlock(i + 1, j + 1, k + 8, Block.dirt.blockID);
		world.setBlock(i + 1, j + 1, k + 9, Block.dirt.blockID);
		world.setBlock(i + 1, j + 1, k + 10, Block.dirt.blockID);
		world.setBlock(i + 1, j + 1, k + 11, Block.dirt.blockID);
		world.setBlock(i + 1, j + 1, k + 12, Block.dirt.blockID);
		world.setBlock(i + 1, j + 1, k + 13, Block.dirt.blockID);
		world.setBlock(i + 1, j + 1, k + 14, Block.dirt.blockID);
		world.setBlock(i + 1, j + 1, k + 15, Block.dirt.blockID);
		world.setBlock(i + 1, j + 1, k + 16, Block.dirt.blockID);
		world.setBlock(i + 1, j + 1, k + 17, Block.dirt.blockID);
		world.setBlock(i + 1, j + 1, k + 18, Block.dirt.blockID);
		world.setBlock(i + 1, j + 1, k + 19, Block.dirt.blockID);
		world.setBlock(i + 1, j + 1, k + 20, Block.dirt.blockID);
		world.setBlock(i + 1, j + 1, k + 21, Block.dirt.blockID);
		world.setBlock(i + 1, j + 1, k + 22, Block.dirt.blockID);
		world.setBlock(i + 1, j + 1, k + 23, Block.dirt.blockID);
		world.setBlock(i + 1, j + 1, k + 24, Block.dirt.blockID);
		world.setBlock(i + 1, j + 1, k + 25, Block.dirt.blockID);
		world.setBlock(i + 1, j + 1, k + 26, Block.dirt.blockID);
		world.setBlock(i + 1, j + 2, k + 0, Block.grass.blockID);
		world.setBlock(i + 1, j + 2, k + 1, Block.grass.blockID);
		world.setBlock(i + 1, j + 2, k + 2, Block.grass.blockID);
		world.setBlock(i + 1, j + 2, k + 3, Block.grass.blockID);
		world.setBlock(i + 1, j + 2, k + 4, Block.grass.blockID);
		world.setBlock(i + 1, j + 2, k + 5, Block.grass.blockID);
		world.setBlock(i + 1, j + 2, k + 6, Block.grass.blockID);
		world.setBlock(i + 1, j + 2, k + 7, Block.grass.blockID);
		world.setBlock(i + 1, j + 2, k + 8, Block.grass.blockID);
		world.setBlock(i + 1, j + 2, k + 9, Block.grass.blockID);
		world.setBlock(i + 1, j + 2, k + 10, Block.grass.blockID);
		world.setBlock(i + 1, j + 2, k + 11, Block.blockSnow.blockID);
		world.setBlock(i + 1, j + 2, k + 12, Block.blockSnow.blockID);
		world.setBlock(i + 1, j + 2, k + 13, Block.blockSnow.blockID);
		world.setBlock(i + 1, j + 2, k + 14, Block.blockSnow.blockID);
		world.setBlock(i + 1, j + 2, k + 15, Block.blockSnow.blockID);
		world.setBlock(i + 1, j + 2, k + 16, Block.grass.blockID);
		world.setBlock(i + 1, j + 2, k + 17, Block.grass.blockID);
		world.setBlock(i + 1, j + 2, k + 18, Block.grass.blockID);
		world.setBlock(i + 1, j + 2, k + 19, Block.grass.blockID);
		world.setBlock(i + 1, j + 2, k + 20, Block.grass.blockID);
		world.setBlock(i + 1, j + 2, k + 21, Block.grass.blockID);
		world.setBlock(i + 1, j + 2, k + 22, Block.grass.blockID);
		world.setBlock(i + 1, j + 2, k + 23, Block.grass.blockID);
		world.setBlock(i + 1, j + 2, k + 24, Block.grass.blockID);
		world.setBlock(i + 1, j + 2, k + 25, Block.grass.blockID);
		world.setBlock(i + 1, j + 2, k + 26, Block.grass.blockID);
		world.setBlock(i + 1, j + 3, k + 11, Block.blockSnow.blockID);
		world.setBlock(i + 1, j + 3, k + 12, Block.blockSnow.blockID);
		world.setBlock(i + 1, j + 3, k + 13, Block.blockSnow.blockID);
		world.setBlock(i + 1, j + 3, k + 14, Block.blockSnow.blockID);
		world.setBlock(i + 1, j + 3, k + 15, Block.blockSnow.blockID);
		world.setBlock(i + 1, j + 4, k + 11, Block.ice.blockID);
		world.setBlock(i + 1, j + 4, k + 12, Block.ice.blockID);
		world.setBlock(i + 1, j + 4, k + 13, Block.ice.blockID);
		world.setBlock(i + 1, j + 4, k + 14, Block.ice.blockID);
		world.setBlock(i + 1, j + 4, k + 15, Block.ice.blockID);
		world.setBlock(i + 1, j + 5, k + 11, Block.ice.blockID);
		world.setBlock(i + 1, j + 5, k + 12, Block.ice.blockID);
		world.setBlock(i + 1, j + 5, k + 13, Block.ice.blockID);
		world.setBlock(i + 1, j + 5, k + 14, Block.ice.blockID);
		world.setBlock(i + 1, j + 5, k + 15, Block.ice.blockID);
		world.setBlock(i + 1, j + 6, k + 11, Block.ice.blockID);
		world.setBlock(i + 1, j + 6, k + 12, Block.ice.blockID);
		world.setBlock(i + 1, j + 6, k + 13, Block.ice.blockID);
		world.setBlock(i + 1, j + 6, k + 14, Block.ice.blockID);
		world.setBlock(i + 1, j + 6, k + 15, Block.ice.blockID);
		world.setBlock(i + 1, j + 7, k + 11, Block.ice.blockID);
		world.setBlock(i + 1, j + 7, k + 12, Block.ice.blockID);
		world.setBlock(i + 1, j + 7, k + 13, Block.ice.blockID);
		world.setBlock(i + 1, j + 7, k + 14, Block.ice.blockID);
		world.setBlock(i + 1, j + 7, k + 15, Block.ice.blockID);
		world.setBlock(i + 1, j + 8, k + 11, Block.ice.blockID);
		world.setBlock(i + 1, j + 8, k + 12, Block.ice.blockID);
		world.setBlock(i + 1, j + 8, k + 13, Block.ice.blockID);
		world.setBlock(i + 1, j + 8, k + 14, Block.ice.blockID);
		world.setBlock(i + 1, j + 8, k + 15, Block.ice.blockID);
		world.setBlock(i + 1, j + 9, k + 11, Block.ice.blockID);
		world.setBlock(i + 1, j + 9, k + 12, Block.ice.blockID);
		world.setBlock(i + 1, j + 9, k + 13, Block.ice.blockID);
		world.setBlock(i + 1, j + 9, k + 14, Block.ice.blockID);
		world.setBlock(i + 1, j + 9, k + 15, Block.ice.blockID);
		world.setBlock(i + 1, j + 10, k + 11, Block.ice.blockID);
		world.setBlock(i + 1, j + 10, k + 12, Block.ice.blockID);
		world.setBlock(i + 1, j + 10, k + 13, Block.ice.blockID);
		world.setBlock(i + 1, j + 10, k + 14, Block.ice.blockID);
		world.setBlock(i + 1, j + 10, k + 15, Block.ice.blockID);
		world.setBlock(i + 2, j + 0, k + 0, Block.dirt.blockID);
		world.setBlock(i + 2, j + 0, k + 1, Block.dirt.blockID);
		world.setBlock(i + 2, j + 0, k + 2, Block.dirt.blockID);
		world.setBlock(i + 2, j + 0, k + 3, Block.dirt.blockID);
		world.setBlock(i + 2, j + 0, k + 4, Block.dirt.blockID);
		world.setBlock(i + 2, j + 0, k + 5, Block.dirt.blockID);
		world.setBlock(i + 2, j + 0, k + 6, Block.dirt.blockID);
		world.setBlock(i + 2, j + 0, k + 7, Block.dirt.blockID);
		world.setBlock(i + 2, j + 0, k + 8, Block.dirt.blockID);
		world.setBlock(i + 2, j + 0, k + 9, Block.dirt.blockID);
		world.setBlock(i + 2, j + 0, k + 10, Block.dirt.blockID);
		world.setBlock(i + 2, j + 0, k + 11, Block.dirt.blockID);
		world.setBlock(i + 2, j + 0, k + 12, Block.dirt.blockID);
		world.setBlock(i + 2, j + 0, k + 13, Block.dirt.blockID);
		world.setBlock(i + 2, j + 0, k + 14, Block.dirt.blockID);
		world.setBlock(i + 2, j + 0, k + 15, Block.dirt.blockID);
		world.setBlock(i + 2, j + 0, k + 16, Block.dirt.blockID);
		world.setBlock(i + 2, j + 0, k + 17, Block.dirt.blockID);
		world.setBlock(i + 2, j + 0, k + 18, Block.dirt.blockID);
		world.setBlock(i + 2, j + 0, k + 19, Block.dirt.blockID);
		world.setBlock(i + 2, j + 0, k + 20, Block.dirt.blockID);
		world.setBlock(i + 2, j + 0, k + 21, Block.dirt.blockID);
		world.setBlock(i + 2, j + 0, k + 22, Block.dirt.blockID);
		world.setBlock(i + 2, j + 0, k + 23, Block.dirt.blockID);
		world.setBlock(i + 2, j + 0, k + 24, Block.dirt.blockID);
		world.setBlock(i + 2, j + 0, k + 25, Block.dirt.blockID);
		world.setBlock(i + 2, j + 0, k + 26, Block.dirt.blockID);
		world.setBlock(i + 2, j + 1, k + 0, Block.dirt.blockID);
		world.setBlock(i + 2, j + 1, k + 1, Block.dirt.blockID);
		world.setBlock(i + 2, j + 1, k + 2, Block.dirt.blockID);
		world.setBlock(i + 2, j + 1, k + 3, Block.dirt.blockID);
		world.setBlock(i + 2, j + 1, k + 4, Block.dirt.blockID);
		world.setBlock(i + 2, j + 1, k + 5, Block.dirt.blockID);
		world.setBlock(i + 2, j + 1, k + 6, Block.dirt.blockID);
		world.setBlock(i + 2, j + 1, k + 7, Block.dirt.blockID);
		world.setBlock(i + 2, j + 1, k + 8, Block.dirt.blockID);
		world.setBlock(i + 2, j + 1, k + 9, Block.dirt.blockID);
		world.setBlock(i + 2, j + 1, k + 10, Block.dirt.blockID);
		world.setBlock(i + 2, j + 1, k + 11, Block.dirt.blockID);
		world.setBlock(i + 2, j + 1, k + 12, Block.dirt.blockID);
		world.setBlock(i + 2, j + 1, k + 13, Block.dirt.blockID);
		world.setBlock(i + 2, j + 1, k + 14, Block.dirt.blockID);
		world.setBlock(i + 2, j + 1, k + 15, Block.dirt.blockID);
		world.setBlock(i + 2, j + 1, k + 16, Block.dirt.blockID);
		world.setBlock(i + 2, j + 1, k + 17, Block.dirt.blockID);
		world.setBlock(i + 2, j + 1, k + 18, Block.dirt.blockID);
		world.setBlock(i + 2, j + 1, k + 19, Block.dirt.blockID);
		world.setBlock(i + 2, j + 1, k + 20, Block.dirt.blockID);
		world.setBlock(i + 2, j + 1, k + 21, Block.dirt.blockID);
		world.setBlock(i + 2, j + 1, k + 22, Block.dirt.blockID);
		world.setBlock(i + 2, j + 1, k + 23, Block.dirt.blockID);
		world.setBlock(i + 2, j + 1, k + 24, Block.dirt.blockID);
		world.setBlock(i + 2, j + 1, k + 25, Block.dirt.blockID);
		world.setBlock(i + 2, j + 1, k + 26, Block.dirt.blockID);
		world.setBlock(i + 2, j + 2, k + 0, Block.grass.blockID);
		world.setBlock(i + 2, j + 2, k + 1, Block.grass.blockID);
		world.setBlock(i + 2, j + 2, k + 2, Block.grass.blockID);
		world.setBlock(i + 2, j + 2, k + 3, Block.grass.blockID);
		world.setBlock(i + 2, j + 2, k + 4, Block.grass.blockID);
		world.setBlock(i + 2, j + 2, k + 5, Block.grass.blockID);
		world.setBlock(i + 2, j + 2, k + 6, Block.grass.blockID);
		world.setBlock(i + 2, j + 2, k + 7, Block.grass.blockID);
		world.setBlock(i + 2, j + 2, k + 8, Block.grass.blockID);
		world.setBlock(i + 2, j + 2, k + 9, Block.grass.blockID);
		world.setBlock(i + 2, j + 2, k + 10, Block.blockSnow.blockID);
		world.setBlock(i + 2, j + 2, k + 11, MainRegistry.frostPlanks.blockID);
		world.setBlock(i + 2, j + 2, k + 12, MainRegistry.frostPlanks.blockID);
		world.setBlock(i + 2, j + 2, k + 13, MainRegistry.frostPlanks.blockID);
		world.setBlock(i + 2, j + 2, k + 14, MainRegistry.frostPlanks.blockID);
		world.setBlock(i + 2, j + 2, k + 15, MainRegistry.frostPlanks.blockID);
		world.setBlock(i + 2, j + 2, k + 16, Block.blockSnow.blockID);
		world.setBlock(i + 2, j + 2, k + 17, Block.grass.blockID);
		world.setBlock(i + 2, j + 2, k + 18, Block.grass.blockID);
		world.setBlock(i + 2, j + 2, k + 19, Block.grass.blockID);
		world.setBlock(i + 2, j + 2, k + 20, Block.grass.blockID);
		world.setBlock(i + 2, j + 2, k + 21, Block.grass.blockID);
		world.setBlock(i + 2, j + 2, k + 22, Block.grass.blockID);
		world.setBlock(i + 2, j + 2, k + 23, Block.grass.blockID);
		world.setBlock(i + 2, j + 2, k + 24, Block.grass.blockID);
		world.setBlock(i + 2, j + 2, k + 25, Block.grass.blockID);
		world.setBlock(i + 2, j + 2, k + 26, Block.grass.blockID);
		world.setBlock(i + 2, j + 3, k + 10, Block.blockSnow.blockID);
		world.setBlock(i + 2, j + 3, k + 16, Block.blockSnow.blockID);
		world.setBlock(i + 2, j + 4, k + 10, Block.ice.blockID);
		world.setBlock(i + 2, j + 4, k + 16, Block.ice.blockID);
		world.setBlock(i + 2, j + 5, k + 10, Block.ice.blockID);
		world.setBlock(i + 2, j + 5, k + 16, Block.ice.blockID);
		world.setBlock(i + 2, j + 6, k + 10, Block.ice.blockID);
		world.setBlock(i + 2, j + 6, k + 16, Block.ice.blockID);
		world.setBlock(i + 2, j + 7, k + 10, Block.ice.blockID);
		world.setBlock(i + 2, j + 7, k + 16, Block.ice.blockID);
		world.setBlock(i + 2, j + 8, k + 10, Block.ice.blockID);
		world.setBlock(i + 2, j + 8, k + 13, Block.oreIron.blockID);
		world.setBlock(i + 2, j + 8, k + 16, Block.ice.blockID);
		world.setBlock(i + 2, j + 9, k + 10, Block.ice.blockID);
		world.setBlock(i + 2, j + 9, k + 16, Block.ice.blockID);
		world.setBlock(i + 2, j + 10, k + 10, Block.ice.blockID);
		world.setBlock(i + 2, j + 10, k + 16, Block.ice.blockID);
		world.setBlock(i + 2, j + 11, k + 11, Block.ice.blockID);
		world.setBlock(i + 2, j + 11, k + 12, Block.ice.blockID);
		world.setBlock(i + 2, j + 11, k + 13, Block.ice.blockID);
		world.setBlock(i + 2, j + 11, k + 14, Block.ice.blockID);
		world.setBlock(i + 2, j + 11, k + 15, Block.ice.blockID);
		world.setBlock(i + 3, j + 0, k + 0, Block.dirt.blockID);
		world.setBlock(i + 3, j + 0, k + 1, Block.dirt.blockID);
		world.setBlock(i + 3, j + 0, k + 2, Block.dirt.blockID);
		world.setBlock(i + 3, j + 0, k + 3, Block.dirt.blockID);
		world.setBlock(i + 3, j + 0, k + 4, Block.dirt.blockID);
		world.setBlock(i + 3, j + 0, k + 5, Block.dirt.blockID);
		world.setBlock(i + 3, j + 0, k + 6, Block.dirt.blockID);
		world.setBlock(i + 3, j + 0, k + 7, Block.dirt.blockID);
		world.setBlock(i + 3, j + 0, k + 8, Block.dirt.blockID);
		world.setBlock(i + 3, j + 0, k + 9, Block.dirt.blockID);
		world.setBlock(i + 3, j + 0, k + 10, Block.dirt.blockID);
		world.setBlock(i + 3, j + 0, k + 11, Block.dirt.blockID);
		world.setBlock(i + 3, j + 0, k + 12, Block.dirt.blockID);
		world.setBlock(i + 3, j + 0, k + 13, Block.dirt.blockID);
		world.setBlock(i + 3, j + 0, k + 14, Block.dirt.blockID);
		world.setBlock(i + 3, j + 0, k + 15, Block.dirt.blockID);
		world.setBlock(i + 3, j + 0, k + 16, Block.dirt.blockID);
		world.setBlock(i + 3, j + 0, k + 17, Block.dirt.blockID);
		world.setBlock(i + 3, j + 0, k + 18, Block.dirt.blockID);
		world.setBlock(i + 3, j + 0, k + 19, Block.dirt.blockID);
		world.setBlock(i + 3, j + 0, k + 20, Block.dirt.blockID);
		world.setBlock(i + 3, j + 0, k + 21, Block.dirt.blockID);
		world.setBlock(i + 3, j + 0, k + 22, Block.dirt.blockID);
		world.setBlock(i + 3, j + 0, k + 23, Block.dirt.blockID);
		world.setBlock(i + 3, j + 0, k + 24, Block.dirt.blockID);
		world.setBlock(i + 3, j + 0, k + 25, Block.dirt.blockID);
		world.setBlock(i + 3, j + 0, k + 26, Block.dirt.blockID);
		world.setBlock(i + 3, j + 1, k + 0, Block.dirt.blockID);
		world.setBlock(i + 3, j + 1, k + 1, Block.dirt.blockID);
		world.setBlock(i + 3, j + 1, k + 2, Block.dirt.blockID);
		world.setBlock(i + 3, j + 1, k + 3, Block.dirt.blockID);
		world.setBlock(i + 3, j + 1, k + 4, Block.dirt.blockID);
		world.setBlock(i + 3, j + 1, k + 5, Block.dirt.blockID);
		world.setBlock(i + 3, j + 1, k + 6, Block.dirt.blockID);
		world.setBlock(i + 3, j + 1, k + 7, Block.dirt.blockID);
		world.setBlock(i + 3, j + 1, k + 8, Block.dirt.blockID);
		world.setBlock(i + 3, j + 1, k + 9, Block.dirt.blockID);
		world.setBlock(i + 3, j + 1, k + 10, Block.dirt.blockID);
		world.setBlock(i + 3, j + 1, k + 11, Block.dirt.blockID);
		world.setBlock(i + 3, j + 1, k + 12, Block.dirt.blockID);
		world.setBlock(i + 3, j + 1, k + 13, Block.dirt.blockID);
		world.setBlock(i + 3, j + 1, k + 14, Block.dirt.blockID);
		world.setBlock(i + 3, j + 1, k + 15, Block.dirt.blockID);
		world.setBlock(i + 3, j + 1, k + 16, Block.dirt.blockID);
		world.setBlock(i + 3, j + 1, k + 17, Block.dirt.blockID);
		world.setBlock(i + 3, j + 1, k + 18, Block.dirt.blockID);
		world.setBlock(i + 3, j + 1, k + 19, Block.dirt.blockID);
		world.setBlock(i + 3, j + 1, k + 20, Block.dirt.blockID);
		world.setBlock(i + 3, j + 1, k + 21, Block.dirt.blockID);
		world.setBlock(i + 3, j + 1, k + 22, Block.dirt.blockID);
		world.setBlock(i + 3, j + 1, k + 23, Block.dirt.blockID);
		world.setBlock(i + 3, j + 1, k + 24, Block.dirt.blockID);
		world.setBlock(i + 3, j + 1, k + 25, Block.dirt.blockID);
		world.setBlock(i + 3, j + 1, k + 26, Block.dirt.blockID);
		world.setBlock(i + 3, j + 2, k + 0, Block.grass.blockID);
		world.setBlock(i + 3, j + 2, k + 1, Block.grass.blockID);
		world.setBlock(i + 3, j + 2, k + 2, Block.grass.blockID);
		world.setBlock(i + 3, j + 2, k + 3, Block.grass.blockID);
		world.setBlock(i + 3, j + 2, k + 4, Block.grass.blockID);
		world.setBlock(i + 3, j + 2, k + 5, Block.grass.blockID);
		world.setBlock(i + 3, j + 2, k + 6, Block.grass.blockID);
		world.setBlock(i + 3, j + 2, k + 7, Block.grass.blockID);
		world.setBlock(i + 3, j + 2, k + 8, Block.grass.blockID);
		world.setBlock(i + 3, j + 2, k + 9, Block.blockSnow.blockID);
		world.setBlock(i + 3, j + 2, k + 10, MainRegistry.frostPlanks.blockID);
		world.setBlock(i + 3, j + 2, k + 11, MainRegistry.frostPlanks.blockID);
		world.setBlock(i + 3, j + 2, k + 12, MainRegistry.frostPlanks.blockID);
		world.setBlock(i + 3, j + 2, k + 13, MainRegistry.frostPlanks.blockID);
		world.setBlock(i + 3, j + 2, k + 14, MainRegistry.frostPlanks.blockID);
		world.setBlock(i + 3, j + 2, k + 15, MainRegistry.frostPlanks.blockID);
		world.setBlock(i + 3, j + 2, k + 16, MainRegistry.frostPlanks.blockID);
		world.setBlock(i + 3, j + 2, k + 17, Block.blockSnow.blockID);
		world.setBlock(i + 3, j + 2, k + 18, Block.grass.blockID);
		world.setBlock(i + 3, j + 2, k + 19, Block.grass.blockID);
		world.setBlock(i + 3, j + 2, k + 20, Block.grass.blockID);
		world.setBlock(i + 3, j + 2, k + 21, Block.grass.blockID);
		world.setBlock(i + 3, j + 2, k + 22, Block.grass.blockID);
		world.setBlock(i + 3, j + 2, k + 23, Block.grass.blockID);
		world.setBlock(i + 3, j + 2, k + 24, Block.grass.blockID);
		world.setBlock(i + 3, j + 2, k + 25, Block.grass.blockID);
		world.setBlock(i + 3, j + 2, k + 26, Block.grass.blockID);
		world.setBlock(i + 3, j + 3, k + 9, Block.blockSnow.blockID);
		world.setBlock(i + 3, j + 3, k + 17, Block.blockSnow.blockID);
		world.setBlock(i + 3, j + 4, k + 9, Block.ice.blockID);
		world.setBlock(i + 3, j + 4, k + 17, Block.ice.blockID);
		world.setBlock(i + 3, j + 5, k + 9, Block.ice.blockID);
		world.setBlock(i + 3, j + 5, k + 17, Block.ice.blockID);
		world.setBlock(i + 3, j + 6, k + 9, Block.ice.blockID);
		world.setBlock(i + 3, j + 6, k + 17, Block.ice.blockID);
		world.setBlock(i + 3, j + 7, k + 9, Block.ice.blockID);
		world.setBlock(i + 3, j + 7, k + 17, Block.ice.blockID);
		world.setBlock(i + 3, j + 8, k + 9, Block.ice.blockID);
		world.setBlock(i + 3, j + 8, k + 17, Block.ice.blockID);
		world.setBlock(i + 3, j + 9, k + 9, Block.ice.blockID);
		world.setBlock(i + 3, j + 9, k + 17, Block.ice.blockID);
		world.setBlock(i + 3, j + 10, k + 9, Block.ice.blockID);
		world.setBlock(i + 3, j + 10, k + 17, Block.ice.blockID);
		world.setBlock(i + 3, j + 11, k + 10, Block.ice.blockID);
		world.setBlock(i + 3, j + 11, k + 16, Block.ice.blockID);
		world.setBlock(i + 3, j + 12, k + 11, Block.ice.blockID);
		world.setBlock(i + 3, j + 12, k + 12, Block.ice.blockID);
		world.setBlock(i + 3, j + 12, k + 13, Block.ice.blockID);
		world.setBlock(i + 3, j + 12, k + 14, Block.ice.blockID);
		world.setBlock(i + 3, j + 12, k + 15, Block.ice.blockID);
		world.setBlock(i + 4, j + 0, k + 0, Block.dirt.blockID);
		world.setBlock(i + 4, j + 0, k + 1, Block.dirt.blockID);
		world.setBlock(i + 4, j + 0, k + 2, Block.dirt.blockID);
		world.setBlock(i + 4, j + 0, k + 3, Block.dirt.blockID);
		world.setBlock(i + 4, j + 0, k + 4, Block.dirt.blockID);
		world.setBlock(i + 4, j + 0, k + 5, Block.dirt.blockID);
		world.setBlock(i + 4, j + 0, k + 6, Block.dirt.blockID);
		world.setBlock(i + 4, j + 0, k + 7, Block.dirt.blockID);
		world.setBlock(i + 4, j + 0, k + 8, Block.dirt.blockID);
		world.setBlock(i + 4, j + 0, k + 9, Block.dirt.blockID);
		world.setBlock(i + 4, j + 0, k + 10, Block.dirt.blockID);
		world.setBlock(i + 4, j + 0, k + 11, Block.dirt.blockID);
		world.setBlock(i + 4, j + 0, k + 12, Block.dirt.blockID);
		world.setBlock(i + 4, j + 0, k + 13, Block.dirt.blockID);
		world.setBlock(i + 4, j + 0, k + 14, Block.dirt.blockID);
		world.setBlock(i + 4, j + 0, k + 15, Block.dirt.blockID);
		world.setBlock(i + 4, j + 0, k + 16, Block.dirt.blockID);
		world.setBlock(i + 4, j + 0, k + 17, Block.dirt.blockID);
		world.setBlock(i + 4, j + 0, k + 18, Block.dirt.blockID);
		world.setBlock(i + 4, j + 0, k + 19, Block.dirt.blockID);
		world.setBlock(i + 4, j + 0, k + 20, Block.dirt.blockID);
		world.setBlock(i + 4, j + 0, k + 21, Block.dirt.blockID);
		world.setBlock(i + 4, j + 0, k + 22, Block.dirt.blockID);
		world.setBlock(i + 4, j + 0, k + 23, Block.dirt.blockID);
		world.setBlock(i + 4, j + 0, k + 24, Block.dirt.blockID);
		world.setBlock(i + 4, j + 0, k + 25, Block.dirt.blockID);
		world.setBlock(i + 4, j + 0, k + 26, Block.dirt.blockID);
		world.setBlock(i + 4, j + 1, k + 0, Block.dirt.blockID);
		world.setBlock(i + 4, j + 1, k + 1, Block.dirt.blockID);
		world.setBlock(i + 4, j + 1, k + 2, Block.dirt.blockID);
		world.setBlock(i + 4, j + 1, k + 3, Block.dirt.blockID);
		world.setBlock(i + 4, j + 1, k + 4, Block.dirt.blockID);
		world.setBlock(i + 4, j + 1, k + 5, Block.dirt.blockID);
		world.setBlock(i + 4, j + 1, k + 6, Block.dirt.blockID);
		world.setBlock(i + 4, j + 1, k + 7, Block.dirt.blockID);
		world.setBlock(i + 4, j + 1, k + 8, Block.dirt.blockID);
		world.setBlock(i + 4, j + 1, k + 9, Block.dirt.blockID);
		world.setBlock(i + 4, j + 1, k + 10, Block.dirt.blockID);
		world.setBlock(i + 4, j + 1, k + 11, Block.dirt.blockID);
		world.setBlock(i + 4, j + 1, k + 12, Block.dirt.blockID);
		world.setBlock(i + 4, j + 1, k + 13, Block.dirt.blockID);
		world.setBlock(i + 4, j + 1, k + 14, Block.dirt.blockID);
		world.setBlock(i + 4, j + 1, k + 15, Block.dirt.blockID);
		world.setBlock(i + 4, j + 1, k + 16, Block.dirt.blockID);
		world.setBlock(i + 4, j + 1, k + 17, Block.dirt.blockID);
		world.setBlock(i + 4, j + 1, k + 18, Block.dirt.blockID);
		world.setBlock(i + 4, j + 1, k + 19, Block.dirt.blockID);
		world.setBlock(i + 4, j + 1, k + 20, Block.dirt.blockID);
		world.setBlock(i + 4, j + 1, k + 21, Block.dirt.blockID);
		world.setBlock(i + 4, j + 1, k + 22, Block.dirt.blockID);
		world.setBlock(i + 4, j + 1, k + 23, Block.dirt.blockID);
		world.setBlock(i + 4, j + 1, k + 24, Block.dirt.blockID);
		world.setBlock(i + 4, j + 1, k + 25, Block.dirt.blockID);
		world.setBlock(i + 4, j + 1, k + 26, Block.dirt.blockID);
		world.setBlock(i + 4, j + 2, k + 0, Block.grass.blockID);
		world.setBlock(i + 4, j + 2, k + 1, Block.grass.blockID);
		world.setBlock(i + 4, j + 2, k + 2, Block.grass.blockID);
		world.setBlock(i + 4, j + 2, k + 3, Block.grass.blockID);
		world.setBlock(i + 4, j + 2, k + 4, Block.grass.blockID);
		world.setBlock(i + 4, j + 2, k + 5, Block.grass.blockID);
		world.setBlock(i + 4, j + 2, k + 6, Block.grass.blockID);
		world.setBlock(i + 4, j + 2, k + 7, Block.grass.blockID);
		world.setBlock(i + 4, j + 2, k + 8, Block.grass.blockID);
		world.setBlock(i + 4, j + 2, k + 9, Block.blockSnow.blockID);
		world.setBlock(i + 4, j + 2, k + 10, MainRegistry.frostPlanks.blockID);
		world.setBlock(i + 4, j + 2, k + 11, MainRegistry.frostPlanks.blockID);
		world.setBlock(i + 4, j + 2, k + 12, MainRegistry.frostPlanks.blockID);
		world.setBlock(i + 4, j + 2, k + 13, MainRegistry.frostPlanks.blockID);
		world.setBlock(i + 4, j + 2, k + 14, MainRegistry.frostPlanks.blockID);
		world.setBlock(i + 4, j + 2, k + 15, MainRegistry.frostPlanks.blockID);
		world.setBlock(i + 4, j + 2, k + 16, MainRegistry.frostPlanks.blockID);
		world.setBlock(i + 4, j + 2, k + 17, Block.blockSnow.blockID);
		world.setBlock(i + 4, j + 2, k + 18, Block.grass.blockID);
		world.setBlock(i + 4, j + 2, k + 19, Block.grass.blockID);
		world.setBlock(i + 4, j + 2, k + 20, Block.grass.blockID);
		world.setBlock(i + 4, j + 2, k + 21, Block.grass.blockID);
		world.setBlock(i + 4, j + 2, k + 22, Block.grass.blockID);
		world.setBlock(i + 4, j + 2, k + 23, Block.grass.blockID);
		world.setBlock(i + 4, j + 2, k + 24, Block.grass.blockID);
		world.setBlock(i + 4, j + 2, k + 25, Block.grass.blockID);
		world.setBlock(i + 4, j + 2, k + 26, Block.grass.blockID);
		world.setBlock(i + 4, j + 3, k + 9, Block.blockSnow.blockID);
		world.setBlock(i + 4, j + 3, k + 13, Block.blockDiamond.blockID);
		world.setBlock(i + 4, j + 3, k + 17, Block.blockSnow.blockID);
		world.setBlock(i + 4, j + 4, k + 9, Block.ice.blockID);
		world.setBlock(i + 4, j + 4, k + 17, Block.ice.blockID);
		world.setBlock(i + 4, j + 5, k + 9, Block.ice.blockID);
		world.setBlock(i + 4, j + 5, k + 17, Block.ice.blockID);
		world.setBlock(i + 4, j + 6, k + 9, Block.ice.blockID);
		world.setBlock(i + 4, j + 6, k + 17, Block.ice.blockID);
		world.setBlock(i + 4, j + 7, k + 9, Block.ice.blockID);
		world.setBlock(i + 4, j + 7, k + 17, Block.ice.blockID);
		world.setBlock(i + 4, j + 8, k + 9, Block.ice.blockID);
		world.setBlock(i + 4, j + 8, k + 17, Block.ice.blockID);
		world.setBlock(i + 4, j + 9, k + 9, Block.ice.blockID);
		world.setBlock(i + 4, j + 9, k + 17, Block.ice.blockID);
		world.setBlock(i + 4, j + 10, k + 9, Block.ice.blockID);
		world.setBlock(i + 4, j + 10, k + 17, Block.ice.blockID);
		world.setBlock(i + 4, j + 11, k + 10, Block.ice.blockID);
		world.setBlock(i + 4, j + 11, k + 16, Block.ice.blockID);
		world.setBlock(i + 4, j + 12, k + 11, Block.ice.blockID);
		world.setBlock(i + 4, j + 12, k + 15, Block.ice.blockID);
		world.setBlock(i + 4, j + 13, k + 12, Block.ice.blockID);
		world.setBlock(i + 4, j + 13, k + 13, Block.ice.blockID);
		world.setBlock(i + 4, j + 13, k + 14, Block.ice.blockID);
		world.setBlock(i + 5, j + 0, k + 0, Block.dirt.blockID);
		world.setBlock(i + 5, j + 0, k + 1, Block.dirt.blockID);
		world.setBlock(i + 5, j + 0, k + 2, Block.dirt.blockID);
		world.setBlock(i + 5, j + 0, k + 3, Block.dirt.blockID);
		world.setBlock(i + 5, j + 0, k + 4, Block.dirt.blockID);
		world.setBlock(i + 5, j + 0, k + 5, Block.dirt.blockID);
		world.setBlock(i + 5, j + 0, k + 6, Block.dirt.blockID);
		world.setBlock(i + 5, j + 0, k + 7, Block.dirt.blockID);
		world.setBlock(i + 5, j + 0, k + 8, Block.dirt.blockID);
		world.setBlock(i + 5, j + 0, k + 9, Block.dirt.blockID);
		world.setBlock(i + 5, j + 0, k + 10, Block.dirt.blockID);
		world.setBlock(i + 5, j + 0, k + 11, Block.dirt.blockID);
		world.setBlock(i + 5, j + 0, k + 12, Block.dirt.blockID);
		world.setBlock(i + 5, j + 0, k + 13, Block.dirt.blockID);
		world.setBlock(i + 5, j + 0, k + 14, Block.dirt.blockID);
		world.setBlock(i + 5, j + 0, k + 15, Block.dirt.blockID);
		world.setBlock(i + 5, j + 0, k + 16, Block.dirt.blockID);
		world.setBlock(i + 5, j + 0, k + 17, Block.dirt.blockID);
		world.setBlock(i + 5, j + 0, k + 18, Block.dirt.blockID);
		world.setBlock(i + 5, j + 0, k + 19, Block.dirt.blockID);
		world.setBlock(i + 5, j + 0, k + 20, Block.dirt.blockID);
		world.setBlock(i + 5, j + 0, k + 21, Block.dirt.blockID);
		world.setBlock(i + 5, j + 0, k + 22, Block.dirt.blockID);
		world.setBlock(i + 5, j + 0, k + 23, Block.dirt.blockID);
		world.setBlock(i + 5, j + 0, k + 24, Block.dirt.blockID);
		world.setBlock(i + 5, j + 0, k + 25, Block.dirt.blockID);
		world.setBlock(i + 5, j + 0, k + 26, Block.dirt.blockID);
		world.setBlock(i + 5, j + 1, k + 0, Block.dirt.blockID);
		world.setBlock(i + 5, j + 1, k + 1, Block.dirt.blockID);
		world.setBlock(i + 5, j + 1, k + 2, Block.dirt.blockID);
		world.setBlock(i + 5, j + 1, k + 3, Block.dirt.blockID);
		world.setBlock(i + 5, j + 1, k + 4, Block.dirt.blockID);
		world.setBlock(i + 5, j + 1, k + 5, Block.dirt.blockID);
		world.setBlock(i + 5, j + 1, k + 6, Block.dirt.blockID);
		world.setBlock(i + 5, j + 1, k + 7, Block.dirt.blockID);
		world.setBlock(i + 5, j + 1, k + 8, Block.dirt.blockID);
		world.setBlock(i + 5, j + 1, k + 9, Block.dirt.blockID);
		world.setBlock(i + 5, j + 1, k + 10, Block.dirt.blockID);
		world.setBlock(i + 5, j + 1, k + 11, Block.dirt.blockID);
		world.setBlock(i + 5, j + 1, k + 12, Block.dirt.blockID);
		world.setBlock(i + 5, j + 1, k + 13, Block.dirt.blockID);
		world.setBlock(i + 5, j + 1, k + 14, Block.dirt.blockID);
		world.setBlock(i + 5, j + 1, k + 15, Block.dirt.blockID);
		world.setBlock(i + 5, j + 1, k + 16, Block.dirt.blockID);
		world.setBlock(i + 5, j + 1, k + 17, Block.dirt.blockID);
		world.setBlock(i + 5, j + 1, k + 18, Block.dirt.blockID);
		world.setBlock(i + 5, j + 1, k + 19, Block.dirt.blockID);
		world.setBlock(i + 5, j + 1, k + 20, Block.dirt.blockID);
		world.setBlock(i + 5, j + 1, k + 21, Block.dirt.blockID);
		world.setBlock(i + 5, j + 1, k + 22, Block.dirt.blockID);
		world.setBlock(i + 5, j + 1, k + 23, Block.dirt.blockID);
		world.setBlock(i + 5, j + 1, k + 24, Block.dirt.blockID);
		world.setBlock(i + 5, j + 1, k + 25, Block.dirt.blockID);
		world.setBlock(i + 5, j + 1, k + 26, Block.dirt.blockID);
		world.setBlock(i + 5, j + 2, k + 0, Block.grass.blockID);
		world.setBlock(i + 5, j + 2, k + 1, Block.grass.blockID);
		world.setBlock(i + 5, j + 2, k + 2, Block.grass.blockID);
		world.setBlock(i + 5, j + 2, k + 3, Block.grass.blockID);
		world.setBlock(i + 5, j + 2, k + 4, Block.grass.blockID);
		world.setBlock(i + 5, j + 2, k + 5, Block.grass.blockID);
		world.setBlock(i + 5, j + 2, k + 6, Block.grass.blockID);
		world.setBlock(i + 5, j + 2, k + 7, Block.grass.blockID);
		world.setBlock(i + 5, j + 2, k + 8, Block.grass.blockID);
		world.setBlock(i + 5, j + 2, k + 9, Block.blockSnow.blockID);
		world.setBlock(i + 5, j + 2, k + 10, MainRegistry.frostPlanks.blockID);
		world.setBlock(i + 5, j + 2, k + 11, MainRegistry.frostPlanks.blockID);
		world.setBlock(i + 5, j + 2, k + 12, MainRegistry.frostPlanks.blockID);
		world.setBlock(i + 5, j + 2, k + 13, MainRegistry.frostPlanks.blockID);
		world.setBlock(i + 5, j + 2, k + 14, MainRegistry.frostPlanks.blockID);
		world.setBlock(i + 5, j + 2, k + 15, MainRegistry.frostPlanks.blockID);
		world.setBlock(i + 5, j + 2, k + 16, MainRegistry.frostPlanks.blockID);
		world.setBlock(i + 5, j + 2, k + 17, Block.blockSnow.blockID);
		world.setBlock(i + 5, j + 2, k + 18, Block.grass.blockID);
		world.setBlock(i + 5, j + 2, k + 19, Block.grass.blockID);
		world.setBlock(i + 5, j + 2, k + 20, Block.grass.blockID);
		world.setBlock(i + 5, j + 2, k + 21, Block.grass.blockID);
		world.setBlock(i + 5, j + 2, k + 22, Block.grass.blockID);
		world.setBlock(i + 5, j + 2, k + 23, Block.grass.blockID);
		world.setBlock(i + 5, j + 2, k + 24, Block.grass.blockID);
		world.setBlock(i + 5, j + 2, k + 25, Block.grass.blockID);
		world.setBlock(i + 5, j + 2, k + 26, Block.grass.blockID);
		world.setBlock(i + 5, j + 3, k + 9, Block.blockSnow.blockID);
		world.setBlock(i + 5, j + 3, k + 17, Block.blockSnow.blockID);
		world.setBlock(i + 5, j + 4, k + 9, Block.ice.blockID);
		world.setBlock(i + 5, j + 4, k + 17, Block.ice.blockID);
		world.setBlock(i + 5, j + 5, k + 9, Block.ice.blockID);
		world.setBlock(i + 5, j + 5, k + 17, Block.ice.blockID);
		world.setBlock(i + 5, j + 6, k + 9, Block.ice.blockID);
		world.setBlock(i + 5, j + 6, k + 17, Block.ice.blockID);
		world.setBlock(i + 5, j + 7, k + 9, Block.ice.blockID);
		world.setBlock(i + 5, j + 7, k + 17, Block.ice.blockID);
		world.setBlock(i + 5, j + 8, k + 9, Block.ice.blockID);
		world.setBlock(i + 5, j + 8, k + 17, Block.ice.blockID);
		world.setBlock(i + 5, j + 9, k + 9, Block.ice.blockID);
		world.setBlock(i + 5, j + 9, k + 17, Block.ice.blockID);
		world.setBlock(i + 5, j + 10, k + 9, Block.ice.blockID);
		world.setBlock(i + 5, j + 10, k + 17, Block.ice.blockID);
		world.setBlock(i + 5, j + 11, k + 10, Block.ice.blockID);
		world.setBlock(i + 5, j + 11, k + 16, Block.ice.blockID);
		world.setBlock(i + 5, j + 12, k + 11, Block.ice.blockID);
		world.setBlock(i + 5, j + 12, k + 15, Block.ice.blockID);
		world.setBlock(i + 5, j + 13, k + 12, Block.ice.blockID);
		world.setBlock(i + 5, j + 13, k + 14, Block.ice.blockID);
		world.setBlock(i + 5, j + 14, k + 13, Block.ice.blockID);
		world.setBlock(i + 6, j + 0, k + 0, Block.dirt.blockID);
		world.setBlock(i + 6, j + 0, k + 1, Block.dirt.blockID);
		world.setBlock(i + 6, j + 0, k + 2, Block.dirt.blockID);
		world.setBlock(i + 6, j + 0, k + 3, Block.dirt.blockID);
		world.setBlock(i + 6, j + 0, k + 4, Block.dirt.blockID);
		world.setBlock(i + 6, j + 0, k + 5, Block.dirt.blockID);
		world.setBlock(i + 6, j + 0, k + 6, Block.dirt.blockID);
		world.setBlock(i + 6, j + 0, k + 7, Block.dirt.blockID);
		world.setBlock(i + 6, j + 0, k + 8, Block.dirt.blockID);
		world.setBlock(i + 6, j + 0, k + 9, Block.dirt.blockID);
		world.setBlock(i + 6, j + 0, k + 10, Block.dirt.blockID);
		world.setBlock(i + 6, j + 0, k + 11, Block.dirt.blockID);
		world.setBlock(i + 6, j + 0, k + 12, Block.dirt.blockID);
		world.setBlock(i + 6, j + 0, k + 13, Block.dirt.blockID);
		world.setBlock(i + 6, j + 0, k + 14, Block.dirt.blockID);
		world.setBlock(i + 6, j + 0, k + 15, Block.dirt.blockID);
		world.setBlock(i + 6, j + 0, k + 16, Block.dirt.blockID);
		world.setBlock(i + 6, j + 0, k + 17, Block.dirt.blockID);
		world.setBlock(i + 6, j + 0, k + 18, Block.dirt.blockID);
		world.setBlock(i + 6, j + 0, k + 19, Block.dirt.blockID);
		world.setBlock(i + 6, j + 0, k + 20, Block.dirt.blockID);
		world.setBlock(i + 6, j + 0, k + 21, Block.dirt.blockID);
		world.setBlock(i + 6, j + 0, k + 22, Block.dirt.blockID);
		world.setBlock(i + 6, j + 0, k + 23, Block.dirt.blockID);
		world.setBlock(i + 6, j + 0, k + 24, Block.dirt.blockID);
		world.setBlock(i + 6, j + 0, k + 25, Block.dirt.blockID);
		world.setBlock(i + 6, j + 0, k + 26, Block.dirt.blockID);
		world.setBlock(i + 6, j + 1, k + 0, Block.dirt.blockID);
		world.setBlock(i + 6, j + 1, k + 1, Block.dirt.blockID);
		world.setBlock(i + 6, j + 1, k + 2, Block.dirt.blockID);
		world.setBlock(i + 6, j + 1, k + 3, Block.dirt.blockID);
		world.setBlock(i + 6, j + 1, k + 4, Block.dirt.blockID);
		world.setBlock(i + 6, j + 1, k + 5, Block.dirt.blockID);
		world.setBlock(i + 6, j + 1, k + 6, Block.dirt.blockID);
		world.setBlock(i + 6, j + 1, k + 7, Block.dirt.blockID);
		world.setBlock(i + 6, j + 1, k + 8, Block.dirt.blockID);
		world.setBlock(i + 6, j + 1, k + 9, Block.dirt.blockID);
		world.setBlock(i + 6, j + 1, k + 10, Block.dirt.blockID);
		world.setBlock(i + 6, j + 1, k + 11, Block.dirt.blockID);
		world.setBlock(i + 6, j + 1, k + 12, Block.dirt.blockID);
		world.setBlock(i + 6, j + 1, k + 13, Block.dirt.blockID);
		world.setBlock(i + 6, j + 1, k + 14, Block.dirt.blockID);
		world.setBlock(i + 6, j + 1, k + 15, Block.dirt.blockID);
		world.setBlock(i + 6, j + 1, k + 16, Block.dirt.blockID);
		world.setBlock(i + 6, j + 1, k + 17, Block.dirt.blockID);
		world.setBlock(i + 6, j + 1, k + 18, Block.dirt.blockID);
		world.setBlock(i + 6, j + 1, k + 19, Block.dirt.blockID);
		world.setBlock(i + 6, j + 1, k + 20, Block.dirt.blockID);
		world.setBlock(i + 6, j + 1, k + 21, Block.dirt.blockID);
		world.setBlock(i + 6, j + 1, k + 22, Block.dirt.blockID);
		world.setBlock(i + 6, j + 1, k + 23, Block.dirt.blockID);
		world.setBlock(i + 6, j + 1, k + 24, Block.dirt.blockID);
		world.setBlock(i + 6, j + 1, k + 25, Block.dirt.blockID);
		world.setBlock(i + 6, j + 1, k + 26, Block.dirt.blockID);
		world.setBlock(i + 6, j + 2, k + 0, Block.grass.blockID);
		world.setBlock(i + 6, j + 2, k + 1, Block.grass.blockID);
		world.setBlock(i + 6, j + 2, k + 2, Block.grass.blockID);
		world.setBlock(i + 6, j + 2, k + 3, Block.grass.blockID);
		world.setBlock(i + 6, j + 2, k + 4, Block.grass.blockID);
		world.setBlock(i + 6, j + 2, k + 5, Block.grass.blockID);
		world.setBlock(i + 6, j + 2, k + 6, Block.grass.blockID);
		world.setBlock(i + 6, j + 2, k + 7, Block.grass.blockID);
		world.setBlock(i + 6, j + 2, k + 8, Block.grass.blockID);
		world.setBlock(i + 6, j + 2, k + 9, Block.blockSnow.blockID);
		world.setBlock(i + 6, j + 2, k + 10, MainRegistry.frostPlanks.blockID);
		world.setBlock(i + 6, j + 2, k + 11, MainRegistry.frostPlanks.blockID);
		world.setBlock(i + 6, j + 2, k + 12, MainRegistry.frostPlanks.blockID);
		world.setBlock(i + 6, j + 2, k + 13, MainRegistry.frostPlanks.blockID);
		world.setBlock(i + 6, j + 2, k + 14, MainRegistry.frostPlanks.blockID);
		world.setBlock(i + 6, j + 2, k + 15, MainRegistry.frostPlanks.blockID);
		world.setBlock(i + 6, j + 2, k + 16, MainRegistry.frostPlanks.blockID);
		world.setBlock(i + 6, j + 2, k + 17, Block.blockSnow.blockID);
		world.setBlock(i + 6, j + 2, k + 18, Block.grass.blockID);
		world.setBlock(i + 6, j + 2, k + 19, Block.grass.blockID);
		world.setBlock(i + 6, j + 2, k + 20, Block.grass.blockID);
		world.setBlock(i + 6, j + 2, k + 21, Block.grass.blockID);
		world.setBlock(i + 6, j + 2, k + 22, Block.grass.blockID);
		world.setBlock(i + 6, j + 2, k + 23, Block.grass.blockID);
		world.setBlock(i + 6, j + 2, k + 24, Block.grass.blockID);
		world.setBlock(i + 6, j + 2, k + 25, Block.grass.blockID);
		world.setBlock(i + 6, j + 2, k + 26, Block.grass.blockID);
		world.setBlock(i + 6, j + 3, k + 9, Block.blockSnow.blockID);
		world.setBlock(i + 6, j + 3, k + 17, Block.blockSnow.blockID);
		world.setBlock(i + 6, j + 4, k + 9, Block.ice.blockID);
		world.setBlock(i + 6, j + 4, k + 17, Block.ice.blockID);
		world.setBlock(i + 6, j + 5, k + 9, Block.ice.blockID);
		world.setBlock(i + 6, j + 5, k + 17, Block.ice.blockID);
		world.setBlock(i + 6, j + 6, k + 9, Block.ice.blockID);
		world.setBlock(i + 6, j + 6, k + 17, Block.ice.blockID);
		world.setBlock(i + 6, j + 7, k + 9, Block.ice.blockID);
		world.setBlock(i + 6, j + 7, k + 17, Block.ice.blockID);
		world.setBlock(i + 6, j + 8, k + 9, Block.ice.blockID);
		world.setBlock(i + 6, j + 8, k + 17, Block.ice.blockID);
		world.setBlock(i + 6, j + 9, k + 9, Block.ice.blockID);
		world.setBlock(i + 6, j + 9, k + 17, Block.ice.blockID);
		world.setBlock(i + 6, j + 10, k + 9, Block.ice.blockID);
		world.setBlock(i + 6, j + 10, k + 17, Block.ice.blockID);
		world.setBlock(i + 6, j + 11, k + 10, Block.ice.blockID);
		world.setBlock(i + 6, j + 11, k + 16, Block.ice.blockID);
		world.setBlock(i + 6, j + 12, k + 11, Block.ice.blockID);
		world.setBlock(i + 6, j + 12, k + 15, Block.ice.blockID);
		world.setBlock(i + 6, j + 13, k + 12, Block.ice.blockID);
		world.setBlock(i + 6, j + 13, k + 14, Block.ice.blockID);
		world.setBlock(i + 6, j + 14, k + 13, Block.ice.blockID);
		world.setBlock(i + 7, j + 0, k + 0, Block.dirt.blockID);
		world.setBlock(i + 7, j + 0, k + 1, Block.dirt.blockID);
		world.setBlock(i + 7, j + 0, k + 2, Block.dirt.blockID);
		world.setBlock(i + 7, j + 0, k + 3, Block.dirt.blockID);
		world.setBlock(i + 7, j + 0, k + 4, Block.dirt.blockID);
		world.setBlock(i + 7, j + 0, k + 5, Block.dirt.blockID);
		world.setBlock(i + 7, j + 0, k + 6, Block.dirt.blockID);
		world.setBlock(i + 7, j + 0, k + 7, Block.dirt.blockID);
		world.setBlock(i + 7, j + 0, k + 8, Block.dirt.blockID);
		world.setBlock(i + 7, j + 0, k + 9, Block.dirt.blockID);
		world.setBlock(i + 7, j + 0, k + 10, Block.dirt.blockID);
		world.setBlock(i + 7, j + 0, k + 11, Block.dirt.blockID);
		world.setBlock(i + 7, j + 0, k + 12, Block.dirt.blockID);
		world.setBlock(i + 7, j + 0, k + 13, Block.dirt.blockID);
		world.setBlock(i + 7, j + 0, k + 14, Block.dirt.blockID);
		world.setBlock(i + 7, j + 0, k + 15, Block.dirt.blockID);
		world.setBlock(i + 7, j + 0, k + 16, Block.dirt.blockID);
		world.setBlock(i + 7, j + 0, k + 17, Block.dirt.blockID);
		world.setBlock(i + 7, j + 0, k + 18, Block.dirt.blockID);
		world.setBlock(i + 7, j + 0, k + 19, Block.dirt.blockID);
		world.setBlock(i + 7, j + 0, k + 20, Block.dirt.blockID);
		world.setBlock(i + 7, j + 0, k + 21, Block.dirt.blockID);
		world.setBlock(i + 7, j + 0, k + 22, Block.dirt.blockID);
		world.setBlock(i + 7, j + 0, k + 23, Block.dirt.blockID);
		world.setBlock(i + 7, j + 0, k + 24, Block.dirt.blockID);
		world.setBlock(i + 7, j + 0, k + 25, Block.dirt.blockID);
		world.setBlock(i + 7, j + 0, k + 26, Block.dirt.blockID);
		world.setBlock(i + 7, j + 1, k + 0, Block.dirt.blockID);
		world.setBlock(i + 7, j + 1, k + 1, Block.dirt.blockID);
		world.setBlock(i + 7, j + 1, k + 2, Block.dirt.blockID);
		world.setBlock(i + 7, j + 1, k + 3, Block.dirt.blockID);
		world.setBlock(i + 7, j + 1, k + 4, Block.dirt.blockID);
		world.setBlock(i + 7, j + 1, k + 5, Block.dirt.blockID);
		world.setBlock(i + 7, j + 1, k + 6, Block.dirt.blockID);
		world.setBlock(i + 7, j + 1, k + 7, Block.dirt.blockID);
		world.setBlock(i + 7, j + 1, k + 8, Block.dirt.blockID);
		world.setBlock(i + 7, j + 1, k + 9, Block.dirt.blockID);
		world.setBlock(i + 7, j + 1, k + 10, Block.dirt.blockID);
		world.setBlock(i + 7, j + 1, k + 11, Block.dirt.blockID);
		world.setBlock(i + 7, j + 1, k + 12, Block.dirt.blockID);
		world.setBlock(i + 7, j + 1, k + 13, Block.dirt.blockID);
		world.setBlock(i + 7, j + 1, k + 14, Block.dirt.blockID);
		world.setBlock(i + 7, j + 1, k + 15, Block.dirt.blockID);
		world.setBlock(i + 7, j + 1, k + 16, Block.dirt.blockID);
		world.setBlock(i + 7, j + 1, k + 17, Block.dirt.blockID);
		world.setBlock(i + 7, j + 1, k + 18, Block.dirt.blockID);
		world.setBlock(i + 7, j + 1, k + 19, Block.dirt.blockID);
		world.setBlock(i + 7, j + 1, k + 20, Block.dirt.blockID);
		world.setBlock(i + 7, j + 1, k + 21, Block.dirt.blockID);
		world.setBlock(i + 7, j + 1, k + 22, Block.dirt.blockID);
		world.setBlock(i + 7, j + 1, k + 23, Block.dirt.blockID);
		world.setBlock(i + 7, j + 1, k + 24, Block.dirt.blockID);
		world.setBlock(i + 7, j + 1, k + 25, Block.dirt.blockID);
		world.setBlock(i + 7, j + 1, k + 26, Block.dirt.blockID);
		world.setBlock(i + 7, j + 2, k + 0, Block.grass.blockID);
		world.setBlock(i + 7, j + 2, k + 1, Block.grass.blockID);
		world.setBlock(i + 7, j + 2, k + 2, Block.grass.blockID);
		world.setBlock(i + 7, j + 2, k + 3, Block.grass.blockID);
		world.setBlock(i + 7, j + 2, k + 4, Block.grass.blockID);
		world.setBlock(i + 7, j + 2, k + 5, Block.grass.blockID);
		world.setBlock(i + 7, j + 2, k + 6, Block.grass.blockID);
		world.setBlock(i + 7, j + 2, k + 7, Block.grass.blockID);
		world.setBlock(i + 7, j + 2, k + 8, Block.blockSnow.blockID);
		world.setBlock(i + 7, j + 2, k + 9, MainRegistry.frostPlanks.blockID);
		world.setBlock(i + 7, j + 2, k + 10, MainRegistry.frostPlanks.blockID);
		world.setBlock(i + 7, j + 2, k + 11, MainRegistry.frostPlanks.blockID);
		world.setBlock(i + 7, j + 2, k + 12, MainRegistry.frostPlanks.blockID);
		world.setBlock(i + 7, j + 2, k + 13, MainRegistry.frostPlanks.blockID);
		world.setBlock(i + 7, j + 2, k + 14, MainRegistry.frostPlanks.blockID);
		world.setBlock(i + 7, j + 2, k + 15, MainRegistry.frostPlanks.blockID);
		world.setBlock(i + 7, j + 2, k + 16, MainRegistry.frostPlanks.blockID);
		world.setBlock(i + 7, j + 2, k + 17, MainRegistry.frostPlanks.blockID);
		world.setBlock(i + 7, j + 2, k + 18, Block.blockSnow.blockID);
		world.setBlock(i + 7, j + 2, k + 19, Block.grass.blockID);
		world.setBlock(i + 7, j + 2, k + 20, Block.grass.blockID);
		world.setBlock(i + 7, j + 2, k + 21, Block.grass.blockID);
		world.setBlock(i + 7, j + 2, k + 22, Block.grass.blockID);
		world.setBlock(i + 7, j + 2, k + 23, Block.grass.blockID);
		world.setBlock(i + 7, j + 2, k + 24, Block.grass.blockID);
		world.setBlock(i + 7, j + 2, k + 25, Block.grass.blockID);
		world.setBlock(i + 7, j + 2, k + 26, Block.grass.blockID);
		world.setBlock(i + 7, j + 3, k + 8, Block.blockSnow.blockID);
		world.setBlock(i + 7, j + 3, k + 18, Block.blockSnow.blockID);
		world.setBlock(i + 7, j + 4, k + 8, Block.ice.blockID);
		world.setBlock(i + 7, j + 4, k + 18, Block.ice.blockID);
		world.setBlock(i + 7, j + 5, k + 8, Block.ice.blockID);
		world.setBlock(i + 7, j + 5, k + 18, Block.ice.blockID);
		world.setBlock(i + 7, j + 6, k + 8, Block.ice.blockID);
		world.setBlock(i + 7, j + 6, k + 18, Block.ice.blockID);
		world.setBlock(i + 7, j + 7, k + 8, Block.ice.blockID);
		world.setBlock(i + 7, j + 7, k + 18, Block.ice.blockID);
		world.setBlock(i + 7, j + 8, k + 8, Block.ice.blockID);
		world.setBlock(i + 7, j + 8, k + 18, Block.ice.blockID);
		world.setBlock(i + 7, j + 9, k + 8, Block.ice.blockID);
		world.setBlock(i + 7, j + 9, k + 18, Block.ice.blockID);
		world.setBlock(i + 7, j + 10, k + 8, Block.ice.blockID);
		world.setBlock(i + 7, j + 10, k + 18, Block.ice.blockID);
		world.setBlock(i + 7, j + 11, k + 9, Block.ice.blockID);
		world.setBlock(i + 7, j + 11, k + 17, Block.ice.blockID);
		world.setBlock(i + 7, j + 12, k + 10, Block.ice.blockID);
		world.setBlock(i + 7, j + 12, k + 16, Block.ice.blockID);
		world.setBlock(i + 7, j + 13, k + 11, Block.ice.blockID);
		world.setBlock(i + 7, j + 13, k + 15, Block.ice.blockID);
		world.setBlock(i + 7, j + 14, k + 12, Block.ice.blockID);
		world.setBlock(i + 7, j + 14, k + 13, Block.ice.blockID);
		world.setBlock(i + 7, j + 14, k + 14, Block.ice.blockID);
		world.setBlock(i + 8, j + 0, k + 0, Block.dirt.blockID);
		world.setBlock(i + 8, j + 0, k + 1, Block.dirt.blockID);
		world.setBlock(i + 8, j + 0, k + 2, Block.dirt.blockID);
		world.setBlock(i + 8, j + 0, k + 3, Block.dirt.blockID);
		world.setBlock(i + 8, j + 0, k + 4, Block.dirt.blockID);
		world.setBlock(i + 8, j + 0, k + 5, Block.dirt.blockID);
		world.setBlock(i + 8, j + 0, k + 6, Block.dirt.blockID);
		world.setBlock(i + 8, j + 0, k + 7, Block.dirt.blockID);
		world.setBlock(i + 8, j + 0, k + 8, Block.dirt.blockID);
		world.setBlock(i + 8, j + 0, k + 9, Block.dirt.blockID);
		world.setBlock(i + 8, j + 0, k + 10, Block.dirt.blockID);
		world.setBlock(i + 8, j + 0, k + 11, Block.dirt.blockID);
		world.setBlock(i + 8, j + 0, k + 12, Block.dirt.blockID);
		world.setBlock(i + 8, j + 0, k + 13, Block.dirt.blockID);
		world.setBlock(i + 8, j + 0, k + 14, Block.dirt.blockID);
		world.setBlock(i + 8, j + 0, k + 15, Block.dirt.blockID);
		world.setBlock(i + 8, j + 0, k + 16, Block.dirt.blockID);
		world.setBlock(i + 8, j + 0, k + 17, Block.dirt.blockID);
		world.setBlock(i + 8, j + 0, k + 18, Block.dirt.blockID);
		world.setBlock(i + 8, j + 0, k + 19, Block.dirt.blockID);
		world.setBlock(i + 8, j + 0, k + 20, Block.dirt.blockID);
		world.setBlock(i + 8, j + 0, k + 21, Block.dirt.blockID);
		world.setBlock(i + 8, j + 0, k + 22, Block.dirt.blockID);
		world.setBlock(i + 8, j + 0, k + 23, Block.dirt.blockID);
		world.setBlock(i + 8, j + 0, k + 24, Block.dirt.blockID);
		world.setBlock(i + 8, j + 0, k + 25, Block.dirt.blockID);
		world.setBlock(i + 8, j + 0, k + 26, Block.dirt.blockID);
		world.setBlock(i + 8, j + 1, k + 0, Block.dirt.blockID);
		world.setBlock(i + 8, j + 1, k + 1, Block.dirt.blockID);
		world.setBlock(i + 8, j + 1, k + 2, Block.dirt.blockID);
		world.setBlock(i + 8, j + 1, k + 3, Block.dirt.blockID);
		world.setBlock(i + 8, j + 1, k + 4, Block.dirt.blockID);
		world.setBlock(i + 8, j + 1, k + 5, Block.dirt.blockID);
		world.setBlock(i + 8, j + 1, k + 6, Block.dirt.blockID);
		world.setBlock(i + 8, j + 1, k + 7, Block.dirt.blockID);
		world.setBlock(i + 8, j + 1, k + 8, Block.dirt.blockID);
		world.setBlock(i + 8, j + 1, k + 9, Block.dirt.blockID);
		world.setBlock(i + 8, j + 1, k + 10, Block.dirt.blockID);
		world.setBlock(i + 8, j + 1, k + 11, Block.dirt.blockID);
		world.setBlock(i + 8, j + 1, k + 12, Block.dirt.blockID);
		world.setBlock(i + 8, j + 1, k + 13, Block.dirt.blockID);
		world.setBlock(i + 8, j + 1, k + 14, Block.dirt.blockID);
		world.setBlock(i + 8, j + 1, k + 15, Block.dirt.blockID);
		world.setBlock(i + 8, j + 1, k + 16, Block.dirt.blockID);
		world.setBlock(i + 8, j + 1, k + 17, Block.dirt.blockID);
		world.setBlock(i + 8, j + 1, k + 18, Block.dirt.blockID);
		world.setBlock(i + 8, j + 1, k + 19, Block.dirt.blockID);
		world.setBlock(i + 8, j + 1, k + 20, Block.dirt.blockID);
		world.setBlock(i + 8, j + 1, k + 21, Block.dirt.blockID);
		world.setBlock(i + 8, j + 1, k + 22, Block.dirt.blockID);
		world.setBlock(i + 8, j + 1, k + 23, Block.dirt.blockID);
		world.setBlock(i + 8, j + 1, k + 24, Block.dirt.blockID);
		world.setBlock(i + 8, j + 1, k + 25, Block.dirt.blockID);
		world.setBlock(i + 8, j + 1, k + 26, Block.dirt.blockID);
		world.setBlock(i + 8, j + 2, k + 0, Block.grass.blockID);
		world.setBlock(i + 8, j + 2, k + 1, Block.grass.blockID);
		world.setBlock(i + 8, j + 2, k + 2, Block.grass.blockID);
		world.setBlock(i + 8, j + 2, k + 3, Block.grass.blockID);
		world.setBlock(i + 8, j + 2, k + 4, Block.grass.blockID);
		world.setBlock(i + 8, j + 2, k + 5, Block.grass.blockID);
		world.setBlock(i + 8, j + 2, k + 6, Block.grass.blockID);
		world.setBlock(i + 8, j + 2, k + 7, Block.blockSnow.blockID);
		world.setBlock(i + 8, j + 2, k + 8, MainRegistry.frostPlanks.blockID);
		world.setBlock(i + 8, j + 2, k + 9, MainRegistry.frostPlanks.blockID);
		world.setBlock(i + 8, j + 2, k + 10, MainRegistry.frostPlanks.blockID);
		world.setBlock(i + 8, j + 2, k + 11, MainRegistry.frostPlanks.blockID);
		world.setBlock(i + 8, j + 2, k + 12, MainRegistry.frostPlanks.blockID);
		world.setBlock(i + 8, j + 2, k + 13, MainRegistry.frostPlanks.blockID);
		world.setBlock(i + 8, j + 2, k + 14, MainRegistry.frostPlanks.blockID);
		world.setBlock(i + 8, j + 2, k + 15, MainRegistry.frostPlanks.blockID);
		world.setBlock(i + 8, j + 2, k + 16, MainRegistry.frostPlanks.blockID);
		world.setBlock(i + 8, j + 2, k + 17, MainRegistry.frostPlanks.blockID);
		world.setBlock(i + 8, j + 2, k + 18, MainRegistry.frostPlanks.blockID);
		world.setBlock(i + 8, j + 2, k + 19, Block.blockSnow.blockID);
		world.setBlock(i + 8, j + 2, k + 20, Block.grass.blockID);
		world.setBlock(i + 8, j + 2, k + 21, Block.grass.blockID);
		world.setBlock(i + 8, j + 2, k + 22, Block.grass.blockID);
		world.setBlock(i + 8, j + 2, k + 23, Block.grass.blockID);
		world.setBlock(i + 8, j + 2, k + 24, Block.grass.blockID);
		world.setBlock(i + 8, j + 2, k + 25, Block.grass.blockID);
		world.setBlock(i + 8, j + 2, k + 26, Block.grass.blockID);
		world.setBlock(i + 8, j + 3, k + 7, Block.blockSnow.blockID);
		world.setBlock(i + 8, j + 3, k + 12, Block.stoneBrick.blockID);
		world.setBlock(i + 8, j + 3, k + 13, Block.stoneBrick.blockID);
		world.setBlock(i + 8, j + 3, k + 14, Block.stoneBrick.blockID);
		world.setBlock(i + 8, j + 3, k + 19, Block.blockSnow.blockID);
		world.setBlock(i + 8, j + 4, k + 7, Block.ice.blockID);
		world.setBlock(i + 8, j + 4, k + 19, Block.ice.blockID);
		world.setBlock(i + 8, j + 5, k + 7, Block.ice.blockID);
		world.setBlock(i + 8, j + 5, k + 19, Block.ice.blockID);
		world.setBlock(i + 8, j + 6, k + 7, Block.ice.blockID);
		world.setBlock(i + 8, j + 6, k + 19, Block.ice.blockID);
		world.setBlock(i + 8, j + 7, k + 7, Block.ice.blockID);
		world.setBlock(i + 8, j + 7, k + 19, Block.ice.blockID);
		world.setBlock(i + 8, j + 8, k + 7, Block.ice.blockID);
		world.setBlock(i + 8, j + 8, k + 19, Block.ice.blockID);
		world.setBlock(i + 8, j + 9, k + 7, Block.ice.blockID);
		world.setBlock(i + 8, j + 9, k + 19, Block.ice.blockID);
		world.setBlock(i + 8, j + 10, k + 7, Block.ice.blockID);
		world.setBlock(i + 8, j + 10, k + 19, Block.ice.blockID);
		world.setBlock(i + 8, j + 11, k + 8, Block.ice.blockID);
		world.setBlock(i + 8, j + 11, k + 18, Block.ice.blockID);
		world.setBlock(i + 8, j + 12, k + 9, Block.ice.blockID);
		world.setBlock(i + 8, j + 12, k + 17, Block.ice.blockID);
		world.setBlock(i + 8, j + 13, k + 10, Block.ice.blockID);
		world.setBlock(i + 8, j + 13, k + 16, Block.ice.blockID);
		world.setBlock(i + 8, j + 14, k + 11, Block.ice.blockID);
		world.setBlock(i + 8, j + 14, k + 12, Block.ice.blockID);
		world.setBlock(i + 8, j + 14, k + 13, Block.ice.blockID);
		world.setBlock(i + 8, j + 14, k + 14, Block.ice.blockID);
		world.setBlock(i + 8, j + 14, k + 15, Block.ice.blockID);
		world.setBlock(i + 9, j + 0, k + 0, Block.dirt.blockID);
		world.setBlock(i + 9, j + 0, k + 1, Block.dirt.blockID);
		world.setBlock(i + 9, j + 0, k + 2, Block.dirt.blockID);
		world.setBlock(i + 9, j + 0, k + 3, Block.dirt.blockID);
		world.setBlock(i + 9, j + 0, k + 4, Block.dirt.blockID);
		world.setBlock(i + 9, j + 0, k + 5, Block.dirt.blockID);
		world.setBlock(i + 9, j + 0, k + 6, Block.dirt.blockID);
		world.setBlock(i + 9, j + 0, k + 7, Block.dirt.blockID);
		world.setBlock(i + 9, j + 0, k + 8, Block.dirt.blockID);
		world.setBlock(i + 9, j + 0, k + 9, Block.dirt.blockID);
		world.setBlock(i + 9, j + 0, k + 10, Block.dirt.blockID);
		world.setBlock(i + 9, j + 0, k + 11, Block.dirt.blockID);
		world.setBlock(i + 9, j + 0, k + 12, Block.dirt.blockID);
		world.setBlock(i + 9, j + 0, k + 13, Block.dirt.blockID);
		world.setBlock(i + 9, j + 0, k + 14, Block.dirt.blockID);
		world.setBlock(i + 9, j + 0, k + 15, Block.dirt.blockID);
		world.setBlock(i + 9, j + 0, k + 16, Block.dirt.blockID);
		world.setBlock(i + 9, j + 0, k + 17, Block.dirt.blockID);
		world.setBlock(i + 9, j + 0, k + 18, Block.dirt.blockID);
		world.setBlock(i + 9, j + 0, k + 19, Block.dirt.blockID);
		world.setBlock(i + 9, j + 0, k + 20, Block.dirt.blockID);
		world.setBlock(i + 9, j + 0, k + 21, Block.dirt.blockID);
		world.setBlock(i + 9, j + 0, k + 22, Block.dirt.blockID);
		world.setBlock(i + 9, j + 0, k + 23, Block.dirt.blockID);
		world.setBlock(i + 9, j + 0, k + 24, Block.dirt.blockID);
		world.setBlock(i + 9, j + 0, k + 25, Block.dirt.blockID);
		world.setBlock(i + 9, j + 0, k + 26, Block.dirt.blockID);
		world.setBlock(i + 9, j + 1, k + 0, Block.dirt.blockID);
		world.setBlock(i + 9, j + 1, k + 1, Block.dirt.blockID);
		world.setBlock(i + 9, j + 1, k + 2, Block.dirt.blockID);
		world.setBlock(i + 9, j + 1, k + 3, Block.dirt.blockID);
		world.setBlock(i + 9, j + 1, k + 4, Block.dirt.blockID);
		world.setBlock(i + 9, j + 1, k + 5, Block.dirt.blockID);
		world.setBlock(i + 9, j + 1, k + 6, Block.dirt.blockID);
		world.setBlock(i + 9, j + 1, k + 7, Block.dirt.blockID);
		world.setBlock(i + 9, j + 1, k + 8, Block.dirt.blockID);
		world.setBlock(i + 9, j + 1, k + 9, Block.dirt.blockID);
		world.setBlock(i + 9, j + 1, k + 10, Block.dirt.blockID);
		world.setBlock(i + 9, j + 1, k + 11, Block.dirt.blockID);
		world.setBlock(i + 9, j + 1, k + 12, Block.dirt.blockID);
		world.setBlock(i + 9, j + 1, k + 13, Block.dirt.blockID);
		world.setBlock(i + 9, j + 1, k + 14, Block.dirt.blockID);
		world.setBlock(i + 9, j + 1, k + 15, Block.dirt.blockID);
		world.setBlock(i + 9, j + 1, k + 16, Block.dirt.blockID);
		world.setBlock(i + 9, j + 1, k + 17, Block.dirt.blockID);
		world.setBlock(i + 9, j + 1, k + 18, Block.dirt.blockID);
		world.setBlock(i + 9, j + 1, k + 19, Block.dirt.blockID);
		world.setBlock(i + 9, j + 1, k + 20, Block.dirt.blockID);
		world.setBlock(i + 9, j + 1, k + 21, Block.dirt.blockID);
		world.setBlock(i + 9, j + 1, k + 22, Block.dirt.blockID);
		world.setBlock(i + 9, j + 1, k + 23, Block.dirt.blockID);
		world.setBlock(i + 9, j + 1, k + 24, Block.dirt.blockID);
		world.setBlock(i + 9, j + 1, k + 25, Block.dirt.blockID);
		world.setBlock(i + 9, j + 1, k + 26, Block.dirt.blockID);
		world.setBlock(i + 9, j + 2, k + 0, Block.grass.blockID);
		world.setBlock(i + 9, j + 2, k + 1, Block.grass.blockID);
		world.setBlock(i + 9, j + 2, k + 2, Block.grass.blockID);
		world.setBlock(i + 9, j + 2, k + 3, Block.grass.blockID);
		world.setBlock(i + 9, j + 2, k + 4, Block.grass.blockID);
		world.setBlock(i + 9, j + 2, k + 5, Block.grass.blockID);
		world.setBlock(i + 9, j + 2, k + 6, Block.blockSnow.blockID);
		world.setBlock(i + 9, j + 2, k + 7, MainRegistry.frostPlanks.blockID);
		world.setBlock(i + 9, j + 2, k + 8, MainRegistry.frostPlanks.blockID);
		world.setBlock(i + 9, j + 2, k + 9, MainRegistry.frostPlanks.blockID);
		world.setBlock(i + 9, j + 2, k + 10, MainRegistry.frostPlanks.blockID);
		world.setBlock(i + 9, j + 2, k + 11, MainRegistry.frostPlanks.blockID);
		world.setBlock(i + 9, j + 2, k + 12, MainRegistry.frostPlanks.blockID);
		world.setBlock(i + 9, j + 2, k + 13, MainRegistry.frostPlanks.blockID);
		world.setBlock(i + 9, j + 2, k + 14, MainRegistry.frostPlanks.blockID);
		world.setBlock(i + 9, j + 2, k + 15, MainRegistry.frostPlanks.blockID);
		world.setBlock(i + 9, j + 2, k + 16, MainRegistry.frostPlanks.blockID);
		world.setBlock(i + 9, j + 2, k + 17, MainRegistry.frostPlanks.blockID);
		world.setBlock(i + 9, j + 2, k + 18, MainRegistry.frostPlanks.blockID);
		world.setBlock(i + 9, j + 2, k + 19, MainRegistry.frostPlanks.blockID);
		world.setBlock(i + 9, j + 2, k + 20, Block.blockSnow.blockID);
		world.setBlock(i + 9, j + 2, k + 21, Block.grass.blockID);
		world.setBlock(i + 9, j + 2, k + 22, Block.grass.blockID);
		world.setBlock(i + 9, j + 2, k + 23, Block.grass.blockID);
		world.setBlock(i + 9, j + 2, k + 24, Block.grass.blockID);
		world.setBlock(i + 9, j + 2, k + 25, Block.grass.blockID);
		world.setBlock(i + 9, j + 2, k + 26, Block.grass.blockID);
		world.setBlock(i + 9, j + 3, k + 6, Block.blockSnow.blockID);
		world.setBlock(i + 9, j + 3, k + 12, Block.stoneBrick.blockID);
		world.setBlock(i + 9, j + 3, k + 13, Block.cloth.blockID, 15, 2);
		world.setBlock(i + 9, j + 3, k + 14, Block.stoneBrick.blockID);
		world.setBlock(i + 9, j + 3, k + 20, Block.blockSnow.blockID);
		world.setBlock(i + 9, j + 4, k + 6, Block.ice.blockID);
		world.setBlock(i + 9, j + 4, k + 13, MainRegistry.frostPlanks.blockID);
		world.setBlock(i + 9, j + 4, k + 20, Block.ice.blockID);
		world.setBlock(i + 9, j + 5, k + 6, Block.ice.blockID);
		world.setBlock(i + 9, j + 5, k + 13, Block.sponge.blockID);
		world.setBlock(i + 9, j + 5, k + 20, Block.ice.blockID);
		world.setBlock(i + 9, j + 6, k + 6, Block.ice.blockID);
		world.setBlock(i + 9, j + 6, k + 20, Block.ice.blockID);
		world.setBlock(i + 9, j + 7, k + 6, Block.ice.blockID);
		world.setBlock(i + 9, j + 7, k + 20, Block.ice.blockID);
		world.setBlock(i + 9, j + 8, k + 6, Block.ice.blockID);
		world.setBlock(i + 9, j + 8, k + 20, Block.ice.blockID);
		world.setBlock(i + 9, j + 9, k + 6, Block.ice.blockID);
		world.setBlock(i + 9, j + 9, k + 20, Block.ice.blockID);
		world.setBlock(i + 9, j + 10, k + 6, Block.ice.blockID);
		world.setBlock(i + 9, j + 10, k + 20, Block.ice.blockID);
		world.setBlock(i + 9, j + 11, k + 7, Block.ice.blockID);
		world.setBlock(i + 9, j + 11, k + 19, Block.ice.blockID);
		world.setBlock(i + 9, j + 12, k + 8, Block.ice.blockID);
		world.setBlock(i + 9, j + 12, k + 18, Block.ice.blockID);
		world.setBlock(i + 9, j + 13, k + 9, Block.ice.blockID);
		world.setBlock(i + 9, j + 13, k + 17, Block.ice.blockID);
		world.setBlock(i + 9, j + 14, k + 10, Block.ice.blockID);
		world.setBlock(i + 9, j + 14, k + 11, Block.ice.blockID);
		world.setBlock(i + 9, j + 14, k + 12, Block.ice.blockID);
		world.setBlock(i + 9, j + 14, k + 13, Block.ice.blockID);
		world.setBlock(i + 9, j + 14, k + 14, Block.ice.blockID);
		world.setBlock(i + 9, j + 14, k + 15, Block.ice.blockID);
		world.setBlock(i + 9, j + 14, k + 16, Block.ice.blockID);
		world.setBlock(i + 10, j + 0, k + 0, Block.dirt.blockID);
		world.setBlock(i + 10, j + 0, k + 1, Block.dirt.blockID);
		world.setBlock(i + 10, j + 0, k + 2, Block.dirt.blockID);
		world.setBlock(i + 10, j + 0, k + 3, Block.dirt.blockID);
		world.setBlock(i + 10, j + 0, k + 4, Block.dirt.blockID);
		world.setBlock(i + 10, j + 0, k + 5, Block.dirt.blockID);
		world.setBlock(i + 10, j + 0, k + 6, Block.dirt.blockID);
		world.setBlock(i + 10, j + 0, k + 7, Block.dirt.blockID);
		world.setBlock(i + 10, j + 0, k + 8, Block.dirt.blockID);
		world.setBlock(i + 10, j + 0, k + 9, Block.dirt.blockID);
		world.setBlock(i + 10, j + 0, k + 10, Block.dirt.blockID);
		world.setBlock(i + 10, j + 0, k + 11, Block.dirt.blockID);
		world.setBlock(i + 10, j + 0, k + 12, Block.dirt.blockID);
		world.setBlock(i + 10, j + 0, k + 13, Block.dirt.blockID);
		world.setBlock(i + 10, j + 0, k + 14, Block.dirt.blockID);
		world.setBlock(i + 10, j + 0, k + 15, Block.dirt.blockID);
		world.setBlock(i + 10, j + 0, k + 16, Block.dirt.blockID);
		world.setBlock(i + 10, j + 0, k + 17, Block.dirt.blockID);
		world.setBlock(i + 10, j + 0, k + 18, Block.dirt.blockID);
		world.setBlock(i + 10, j + 0, k + 19, Block.dirt.blockID);
		world.setBlock(i + 10, j + 0, k + 20, Block.dirt.blockID);
		world.setBlock(i + 10, j + 0, k + 21, Block.dirt.blockID);
		world.setBlock(i + 10, j + 0, k + 22, Block.dirt.blockID);
		world.setBlock(i + 10, j + 0, k + 23, Block.dirt.blockID);
		world.setBlock(i + 10, j + 0, k + 24, Block.dirt.blockID);
		world.setBlock(i + 10, j + 0, k + 25, Block.dirt.blockID);
		world.setBlock(i + 10, j + 0, k + 26, Block.dirt.blockID);
		world.setBlock(i + 10, j + 1, k + 0, Block.dirt.blockID);
		world.setBlock(i + 10, j + 1, k + 1, Block.dirt.blockID);
		world.setBlock(i + 10, j + 1, k + 2, Block.dirt.blockID);
		world.setBlock(i + 10, j + 1, k + 3, Block.dirt.blockID);
		world.setBlock(i + 10, j + 1, k + 4, Block.dirt.blockID);
		world.setBlock(i + 10, j + 1, k + 5, Block.dirt.blockID);
		world.setBlock(i + 10, j + 1, k + 6, Block.dirt.blockID);
		world.setBlock(i + 10, j + 1, k + 7, Block.dirt.blockID);
		world.setBlock(i + 10, j + 1, k + 8, Block.dirt.blockID);
		world.setBlock(i + 10, j + 1, k + 9, Block.dirt.blockID);
		world.setBlock(i + 10, j + 1, k + 10, Block.dirt.blockID);
		world.setBlock(i + 10, j + 1, k + 11, Block.dirt.blockID);
		world.setBlock(i + 10, j + 1, k + 12, Block.dirt.blockID);
		world.setBlock(i + 10, j + 1, k + 13, Block.dirt.blockID);
		world.setBlock(i + 10, j + 1, k + 14, Block.dirt.blockID);
		world.setBlock(i + 10, j + 1, k + 15, Block.dirt.blockID);
		world.setBlock(i + 10, j + 1, k + 16, Block.dirt.blockID);
		world.setBlock(i + 10, j + 1, k + 17, Block.dirt.blockID);
		world.setBlock(i + 10, j + 1, k + 18, Block.dirt.blockID);
		world.setBlock(i + 10, j + 1, k + 19, Block.dirt.blockID);
		world.setBlock(i + 10, j + 1, k + 20, Block.dirt.blockID);
		world.setBlock(i + 10, j + 1, k + 21, Block.dirt.blockID);
		world.setBlock(i + 10, j + 1, k + 22, Block.dirt.blockID);
		world.setBlock(i + 10, j + 1, k + 23, Block.dirt.blockID);
		world.setBlock(i + 10, j + 1, k + 24, Block.dirt.blockID);
		world.setBlock(i + 10, j + 1, k + 25, Block.dirt.blockID);
		world.setBlock(i + 10, j + 1, k + 26, Block.dirt.blockID);
		world.setBlock(i + 10, j + 2, k + 0, Block.grass.blockID);
		world.setBlock(i + 10, j + 2, k + 1, Block.grass.blockID);
		world.setBlock(i + 10, j + 2, k + 2, Block.grass.blockID);
		world.setBlock(i + 10, j + 2, k + 3, Block.grass.blockID);
		world.setBlock(i + 10, j + 2, k + 4, Block.grass.blockID);
		world.setBlock(i + 10, j + 2, k + 5, Block.blockSnow.blockID);
		world.setBlock(i + 10, j + 2, k + 6, MainRegistry.frostPlanks.blockID);
		world.setBlock(i + 10, j + 2, k + 7, MainRegistry.frostPlanks.blockID);
		world.setBlock(i + 10, j + 2, k + 8, MainRegistry.frostPlanks.blockID);
		world.setBlock(i + 10, j + 2, k + 9, MainRegistry.frostPlanks.blockID);
		world.setBlock(i + 10, j + 2, k + 10, MainRegistry.frostPlanks.blockID);
		world.setBlock(i + 10, j + 2, k + 11, MainRegistry.frostPlanks.blockID);
		world.setBlock(i + 10, j + 2, k + 12, MainRegistry.frostPlanks.blockID);
		world.setBlock(i + 10, j + 2, k + 13, MainRegistry.frostPlanks.blockID);
		world.setBlock(i + 10, j + 2, k + 14, MainRegistry.frostPlanks.blockID);
		world.setBlock(i + 10, j + 2, k + 15, MainRegistry.frostPlanks.blockID);
		world.setBlock(i + 10, j + 2, k + 16, MainRegistry.frostPlanks.blockID);
		world.setBlock(i + 10, j + 2, k + 17, MainRegistry.frostPlanks.blockID);
		world.setBlock(i + 10, j + 2, k + 18, MainRegistry.frostPlanks.blockID);
		world.setBlock(i + 10, j + 2, k + 19, MainRegistry.frostPlanks.blockID);
		world.setBlock(i + 10, j + 2, k + 20, MainRegistry.frostPlanks.blockID);
		world.setBlock(i + 10, j + 2, k + 21, Block.blockSnow.blockID);
		world.setBlock(i + 10, j + 2, k + 22, Block.grass.blockID);
		world.setBlock(i + 10, j + 2, k + 23, Block.grass.blockID);
		world.setBlock(i + 10, j + 2, k + 24, Block.grass.blockID);
		world.setBlock(i + 10, j + 2, k + 25, Block.grass.blockID);
		world.setBlock(i + 10, j + 2, k + 26, Block.grass.blockID);
		world.setBlock(i + 10, j + 3, k + 5, Block.blockSnow.blockID);
		world.setBlock(i + 10, j + 3, k + 12, Block.stairsStoneBrick.blockID);
		world.setBlock(i + 10, j + 3, k + 13, Block.stairsStoneBrick.blockID);
		world.setBlock(i + 10, j + 3, k + 14, Block.stairsStoneBrick.blockID);
		world.setBlock(i + 10, j + 3, k + 21, Block.blockSnow.blockID);
		world.setBlock(i + 10, j + 4, k + 5, Block.ice.blockID);
		world.setBlock(i + 10, j + 4, k + 21, Block.ice.blockID);
		world.setBlock(i + 10, j + 5, k + 5, Block.ice.blockID);
		world.setBlock(i + 10, j + 5, k + 21, Block.ice.blockID);
		world.setBlock(i + 10, j + 6, k + 5, Block.ice.blockID);
		world.setBlock(i + 10, j + 6, k + 21, Block.ice.blockID);
		world.setBlock(i + 10, j + 7, k + 5, Block.ice.blockID);
		world.setBlock(i + 10, j + 7, k + 21, Block.ice.blockID);
		world.setBlock(i + 10, j + 8, k + 5, Block.ice.blockID);
		world.setBlock(i + 10, j + 8, k + 21, Block.ice.blockID);
		world.setBlock(i + 10, j + 9, k + 5, Block.ice.blockID);
		world.setBlock(i + 10, j + 9, k + 21, Block.ice.blockID);
		world.setBlock(i + 10, j + 10, k + 5, Block.ice.blockID);
		world.setBlock(i + 10, j + 10, k + 21, Block.ice.blockID);
		world.setBlock(i + 10, j + 11, k + 6, Block.ice.blockID);
		world.setBlock(i + 10, j + 11, k + 20, Block.ice.blockID);
		world.setBlock(i + 10, j + 12, k + 7, Block.ice.blockID);
		world.setBlock(i + 10, j + 12, k + 19, Block.ice.blockID);
		world.setBlock(i + 10, j + 13, k + 8, Block.ice.blockID);
		world.setBlock(i + 10, j + 13, k + 18, Block.ice.blockID);
		world.setBlock(i + 10, j + 14, k + 9, Block.ice.blockID);
		world.setBlock(i + 10, j + 14, k + 10, Block.ice.blockID);
		world.setBlock(i + 10, j + 14, k + 11, Block.ice.blockID);
		world.setBlock(i + 10, j + 14, k + 12, Block.ice.blockID);
		world.setBlock(i + 10, j + 14, k + 13, Block.ice.blockID);
		world.setBlock(i + 10, j + 14, k + 14, Block.ice.blockID);
		world.setBlock(i + 10, j + 14, k + 15, Block.ice.blockID);
		world.setBlock(i + 10, j + 14, k + 16, Block.ice.blockID);
		world.setBlock(i + 10, j + 14, k + 17, Block.ice.blockID);
		world.setBlock(i + 11, j + 0, k + 0, Block.dirt.blockID);
		world.setBlock(i + 11, j + 0, k + 1, Block.dirt.blockID);
		world.setBlock(i + 11, j + 0, k + 2, Block.dirt.blockID);
		world.setBlock(i + 11, j + 0, k + 3, Block.dirt.blockID);
		world.setBlock(i + 11, j + 0, k + 4, Block.dirt.blockID);
		world.setBlock(i + 11, j + 0, k + 5, Block.dirt.blockID);
		world.setBlock(i + 11, j + 0, k + 6, Block.dirt.blockID);
		world.setBlock(i + 11, j + 0, k + 7, Block.dirt.blockID);
		world.setBlock(i + 11, j + 0, k + 8, Block.dirt.blockID);
		world.setBlock(i + 11, j + 0, k + 9, Block.dirt.blockID);
		world.setBlock(i + 11, j + 0, k + 10, Block.dirt.blockID);
		world.setBlock(i + 11, j + 0, k + 11, Block.dirt.blockID);
		world.setBlock(i + 11, j + 0, k + 12, Block.dirt.blockID);
		world.setBlock(i + 11, j + 0, k + 13, Block.dirt.blockID);
		world.setBlock(i + 11, j + 0, k + 14, Block.dirt.blockID);
		world.setBlock(i + 11, j + 0, k + 15, Block.dirt.blockID);
		world.setBlock(i + 11, j + 0, k + 16, Block.dirt.blockID);
		world.setBlock(i + 11, j + 0, k + 17, Block.dirt.blockID);
		world.setBlock(i + 11, j + 0, k + 18, Block.dirt.blockID);
		world.setBlock(i + 11, j + 0, k + 19, Block.dirt.blockID);
		world.setBlock(i + 11, j + 0, k + 20, Block.dirt.blockID);
		world.setBlock(i + 11, j + 0, k + 21, Block.dirt.blockID);
		world.setBlock(i + 11, j + 0, k + 22, Block.dirt.blockID);
		world.setBlock(i + 11, j + 0, k + 23, Block.dirt.blockID);
		world.setBlock(i + 11, j + 0, k + 24, Block.dirt.blockID);
		world.setBlock(i + 11, j + 0, k + 25, Block.dirt.blockID);
		world.setBlock(i + 11, j + 0, k + 26, Block.dirt.blockID);
		world.setBlock(i + 11, j + 1, k + 0, Block.dirt.blockID);
		world.setBlock(i + 11, j + 1, k + 1, Block.dirt.blockID);
		world.setBlock(i + 11, j + 1, k + 2, Block.dirt.blockID);
		world.setBlock(i + 11, j + 1, k + 3, Block.dirt.blockID);
		world.setBlock(i + 11, j + 1, k + 4, Block.dirt.blockID);
		world.setBlock(i + 11, j + 1, k + 5, Block.dirt.blockID);
		world.setBlock(i + 11, j + 1, k + 6, Block.dirt.blockID);
		world.setBlock(i + 11, j + 1, k + 7, Block.dirt.blockID);
		world.setBlock(i + 11, j + 1, k + 8, Block.dirt.blockID);
		world.setBlock(i + 11, j + 1, k + 9, Block.dirt.blockID);
		world.setBlock(i + 11, j + 1, k + 10, Block.dirt.blockID);
		world.setBlock(i + 11, j + 1, k + 11, Block.dirt.blockID);
		world.setBlock(i + 11, j + 1, k + 12, Block.dirt.blockID);
		world.setBlock(i + 11, j + 1, k + 13, Block.dirt.blockID);
		world.setBlock(i + 11, j + 1, k + 14, Block.dirt.blockID);
		world.setBlock(i + 11, j + 1, k + 15, Block.dirt.blockID);
		world.setBlock(i + 11, j + 1, k + 16, Block.dirt.blockID);
		world.setBlock(i + 11, j + 1, k + 17, Block.dirt.blockID);
		world.setBlock(i + 11, j + 1, k + 18, Block.dirt.blockID);
		world.setBlock(i + 11, j + 1, k + 19, Block.dirt.blockID);
		world.setBlock(i + 11, j + 1, k + 20, Block.dirt.blockID);
		world.setBlock(i + 11, j + 1, k + 21, Block.dirt.blockID);
		world.setBlock(i + 11, j + 1, k + 22, Block.dirt.blockID);
		world.setBlock(i + 11, j + 1, k + 23, Block.dirt.blockID);
		world.setBlock(i + 11, j + 1, k + 24, Block.dirt.blockID);
		world.setBlock(i + 11, j + 1, k + 25, Block.dirt.blockID);
		world.setBlock(i + 11, j + 1, k + 26, Block.dirt.blockID);
		world.setBlock(i + 11, j + 2, k + 0, Block.grass.blockID);
		world.setBlock(i + 11, j + 2, k + 1, Block.grass.blockID);
		world.setBlock(i + 11, j + 2, k + 2, Block.grass.blockID);
		world.setBlock(i + 11, j + 2, k + 3, Block.grass.blockID);
		world.setBlock(i + 11, j + 2, k + 4, Block.grass.blockID);
		world.setBlock(i + 11, j + 2, k + 5, Block.blockSnow.blockID);
		world.setBlock(i + 11, j + 2, k + 6, MainRegistry.frostPlanks.blockID);
		world.setBlock(i + 11, j + 2, k + 7, MainRegistry.frostPlanks.blockID);
		world.setBlock(i + 11, j + 2, k + 8, MainRegistry.frostPlanks.blockID);
		world.setBlock(i + 11, j + 2, k + 9, MainRegistry.frostPlanks.blockID);
		world.setBlock(i + 11, j + 2, k + 10, MainRegistry.frostPlanks.blockID);
		world.setBlock(i + 11, j + 2, k + 11, MainRegistry.frostPlanks.blockID);
		world.setBlock(i + 11, j + 2, k + 12, MainRegistry.frostPlanks.blockID);
		world.setBlock(i + 11, j + 2, k + 13, MainRegistry.frostPlanks.blockID);
		world.setBlock(i + 11, j + 2, k + 14, MainRegistry.frostPlanks.blockID);
		world.setBlock(i + 11, j + 2, k + 15, MainRegistry.frostPlanks.blockID);
		world.setBlock(i + 11, j + 2, k + 16, MainRegistry.frostPlanks.blockID);
		world.setBlock(i + 11, j + 2, k + 17, MainRegistry.frostPlanks.blockID);
		world.setBlock(i + 11, j + 2, k + 18, MainRegistry.frostPlanks.blockID);
		world.setBlock(i + 11, j + 2, k + 19, MainRegistry.frostPlanks.blockID);
		world.setBlock(i + 11, j + 2, k + 20, MainRegistry.frostPlanks.blockID);
		world.setBlock(i + 11, j + 2, k + 21, Block.blockSnow.blockID);
		world.setBlock(i + 11, j + 2, k + 22, Block.grass.blockID);
		world.setBlock(i + 11, j + 2, k + 23, Block.grass.blockID);
		world.setBlock(i + 11, j + 2, k + 24, Block.grass.blockID);
		world.setBlock(i + 11, j + 2, k + 25, Block.grass.blockID);
		world.setBlock(i + 11, j + 2, k + 26, Block.grass.blockID);
		world.setBlock(i + 11, j + 3, k + 5, Block.blockSnow.blockID);
		world.setBlock(i + 11, j + 3, k + 21, Block.blockSnow.blockID);
		world.setBlock(i + 11, j + 4, k + 5, Block.ice.blockID);
		world.setBlock(i + 11, j + 4, k + 21, Block.ice.blockID);
		world.setBlock(i + 11, j + 5, k + 5, Block.ice.blockID);
		world.setBlock(i + 11, j + 5, k + 21, Block.ice.blockID);
		world.setBlock(i + 11, j + 6, k + 5, Block.ice.blockID);
		world.setBlock(i + 11, j + 6, k + 21, Block.ice.blockID);
		world.setBlock(i + 11, j + 7, k + 5, Block.ice.blockID);
		world.setBlock(i + 11, j + 7, k + 21, Block.ice.blockID);
		world.setBlock(i + 11, j + 8, k + 5, Block.ice.blockID);
		world.setBlock(i + 11, j + 8, k + 21, Block.ice.blockID);
		world.setBlock(i + 11, j + 9, k + 5, Block.ice.blockID);
		world.setBlock(i + 11, j + 9, k + 21, Block.ice.blockID);
		world.setBlock(i + 11, j + 10, k + 5, Block.ice.blockID);
		world.setBlock(i + 11, j + 10, k + 21, Block.ice.blockID);
		world.setBlock(i + 11, j + 11, k + 6, Block.ice.blockID);
		world.setBlock(i + 11, j + 11, k + 20, Block.ice.blockID);
		world.setBlock(i + 11, j + 12, k + 7, Block.ice.blockID);
		world.setBlock(i + 11, j + 12, k + 19, Block.ice.blockID);
		world.setBlock(i + 11, j + 13, k + 8, Block.ice.blockID);
		world.setBlock(i + 11, j + 13, k + 18, Block.ice.blockID);
		world.setBlock(i + 11, j + 14, k + 9, Block.ice.blockID);
		world.setBlock(i + 11, j + 14, k + 10, Block.ice.blockID);
		world.setBlock(i + 11, j + 14, k + 11, Block.ice.blockID);
		world.setBlock(i + 11, j + 14, k + 12, Block.ice.blockID);
		world.setBlock(i + 11, j + 14, k + 13, Block.ice.blockID);
		world.setBlock(i + 11, j + 14, k + 14, Block.ice.blockID);
		world.setBlock(i + 11, j + 14, k + 15, Block.ice.blockID);
		world.setBlock(i + 11, j + 14, k + 16, Block.ice.blockID);
		world.setBlock(i + 11, j + 14, k + 17, Block.ice.blockID);
		world.setBlock(i + 12, j + 0, k + 0, Block.dirt.blockID);
		world.setBlock(i + 12, j + 0, k + 1, Block.dirt.blockID);
		world.setBlock(i + 12, j + 0, k + 2, Block.dirt.blockID);
		world.setBlock(i + 12, j + 0, k + 3, Block.dirt.blockID);
		world.setBlock(i + 12, j + 0, k + 4, Block.dirt.blockID);
		world.setBlock(i + 12, j + 0, k + 5, Block.dirt.blockID);
		world.setBlock(i + 12, j + 0, k + 6, Block.dirt.blockID);
		world.setBlock(i + 12, j + 0, k + 7, Block.dirt.blockID);
		world.setBlock(i + 12, j + 0, k + 8, Block.dirt.blockID);
		world.setBlock(i + 12, j + 0, k + 9, Block.dirt.blockID);
		world.setBlock(i + 12, j + 0, k + 10, Block.dirt.blockID);
		world.setBlock(i + 12, j + 0, k + 11, Block.dirt.blockID);
		world.setBlock(i + 12, j + 0, k + 12, Block.dirt.blockID);
		world.setBlock(i + 12, j + 0, k + 13, Block.dirt.blockID);
		world.setBlock(i + 12, j + 0, k + 14, Block.dirt.blockID);
		world.setBlock(i + 12, j + 0, k + 15, Block.dirt.blockID);
		world.setBlock(i + 12, j + 0, k + 16, Block.dirt.blockID);
		world.setBlock(i + 12, j + 0, k + 17, Block.dirt.blockID);
		world.setBlock(i + 12, j + 0, k + 18, Block.dirt.blockID);
		world.setBlock(i + 12, j + 0, k + 19, Block.dirt.blockID);
		world.setBlock(i + 12, j + 0, k + 20, Block.dirt.blockID);
		world.setBlock(i + 12, j + 0, k + 21, Block.dirt.blockID);
		world.setBlock(i + 12, j + 0, k + 22, Block.dirt.blockID);
		world.setBlock(i + 12, j + 0, k + 23, Block.dirt.blockID);
		world.setBlock(i + 12, j + 0, k + 24, Block.dirt.blockID);
		world.setBlock(i + 12, j + 0, k + 25, Block.dirt.blockID);
		world.setBlock(i + 12, j + 0, k + 26, Block.dirt.blockID);
		world.setBlock(i + 12, j + 1, k + 0, Block.dirt.blockID);
		world.setBlock(i + 12, j + 1, k + 1, Block.dirt.blockID);
		world.setBlock(i + 12, j + 1, k + 2, Block.dirt.blockID);
		world.setBlock(i + 12, j + 1, k + 3, Block.dirt.blockID);
		world.setBlock(i + 12, j + 1, k + 4, Block.dirt.blockID);
		world.setBlock(i + 12, j + 1, k + 5, Block.dirt.blockID);
		world.setBlock(i + 12, j + 1, k + 6, Block.dirt.blockID);
		world.setBlock(i + 12, j + 1, k + 7, Block.dirt.blockID);
		world.setBlock(i + 12, j + 1, k + 8, Block.dirt.blockID);
		world.setBlock(i + 12, j + 1, k + 9, Block.dirt.blockID);
		world.setBlock(i + 12, j + 1, k + 10, Block.dirt.blockID);
		world.setBlock(i + 12, j + 1, k + 11, Block.dirt.blockID);
		world.setBlock(i + 12, j + 1, k + 12, Block.dirt.blockID);
		world.setBlock(i + 12, j + 1, k + 13, Block.dirt.blockID);
		world.setBlock(i + 12, j + 1, k + 14, Block.dirt.blockID);
		world.setBlock(i + 12, j + 1, k + 15, Block.dirt.blockID);
		world.setBlock(i + 12, j + 1, k + 16, Block.dirt.blockID);
		world.setBlock(i + 12, j + 1, k + 17, Block.dirt.blockID);
		world.setBlock(i + 12, j + 1, k + 18, Block.dirt.blockID);
		world.setBlock(i + 12, j + 1, k + 19, Block.dirt.blockID);
		world.setBlock(i + 12, j + 1, k + 21, Block.dirt.blockID);
		world.setBlock(i + 12, j + 1, k + 22, Block.dirt.blockID);
		world.setBlock(i + 12, j + 1, k + 23, Block.dirt.blockID);
		world.setBlock(i + 12, j + 1, k + 24, Block.dirt.blockID);
		world.setBlock(i + 12, j + 1, k + 25, Block.dirt.blockID);
		world.setBlock(i + 12, j + 1, k + 26, Block.dirt.blockID);
		world.setBlock(i + 12, j + 2, k + 0, Block.grass.blockID);
		world.setBlock(i + 12, j + 2, k + 1, Block.grass.blockID);
		world.setBlock(i + 12, j + 2, k + 2, Block.grass.blockID);
		world.setBlock(i + 12, j + 2, k + 3, Block.grass.blockID);
		world.setBlock(i + 12, j + 2, k + 4, Block.grass.blockID);
		world.setBlock(i + 12, j + 2, k + 5, Block.blockSnow.blockID);
		world.setBlock(i + 12, j + 2, k + 6, MainRegistry.frostPlanks.blockID);
		world.setBlock(i + 12, j + 2, k + 7, MainRegistry.frostPlanks.blockID);
		world.setBlock(i + 12, j + 2, k + 8, MainRegistry.frostPlanks.blockID);
		world.setBlock(i + 12, j + 2, k + 9, MainRegistry.frostPlanks.blockID);
		world.setBlock(i + 12, j + 2, k + 10, MainRegistry.frostPlanks.blockID);
		world.setBlock(i + 12, j + 2, k + 11, MainRegistry.frostPlanks.blockID);
		world.setBlock(i + 12, j + 2, k + 12, MainRegistry.frostPlanks.blockID);
		world.setBlock(i + 12, j + 2, k + 13, MainRegistry.frostPlanks.blockID);
		world.setBlock(i + 12, j + 2, k + 14, MainRegistry.frostPlanks.blockID);
		world.setBlock(i + 12, j + 2, k + 15, MainRegistry.frostPlanks.blockID);
		world.setBlock(i + 12, j + 2, k + 16, MainRegistry.frostPlanks.blockID);
		world.setBlock(i + 12, j + 2, k + 17, MainRegistry.frostPlanks.blockID);
		world.setBlock(i + 12, j + 2, k + 18, MainRegistry.frostPlanks.blockID);
		world.setBlock(i + 12, j + 2, k + 19, MainRegistry.frostPlanks.blockID);
		world.setBlock(i + 12, j + 2, k + 20, MainRegistry.frostPlanks.blockID);
		world.setBlock(i + 12, j + 2, k + 21, Block.blockSnow.blockID);
		world.setBlock(i + 12, j + 2, k + 22, Block.grass.blockID);
		world.setBlock(i + 12, j + 2, k + 23, Block.grass.blockID);
		world.setBlock(i + 12, j + 2, k + 24, Block.grass.blockID);
		world.setBlock(i + 12, j + 2, k + 25, Block.grass.blockID);
		world.setBlock(i + 12, j + 2, k + 26, Block.grass.blockID);
		world.setBlock(i + 12, j + 3, k + 5, Block.blockSnow.blockID);
		world.setBlock(i + 12, j + 3, k + 21, Block.blockSnow.blockID);
		world.setBlock(i + 12, j + 4, k + 5, Block.ice.blockID);
		world.setBlock(i + 12, j + 4, k + 21, Block.ice.blockID);
		world.setBlock(i + 12, j + 5, k + 5, Block.ice.blockID);
		world.setBlock(i + 12, j + 5, k + 21, Block.ice.blockID);
		world.setBlock(i + 12, j + 6, k + 5, Block.ice.blockID);
		world.setBlock(i + 12, j + 6, k + 6, Block.oreIron.blockID);
		world.setBlock(i + 12, j + 6, k + 20, Block.oreIron.blockID);
		world.setBlock(i + 12, j + 6, k + 21, Block.ice.blockID);
		world.setBlock(i + 12, j + 7, k + 5, Block.ice.blockID);
		world.setBlock(i + 12, j + 7, k + 21, Block.ice.blockID);
		world.setBlock(i + 12, j + 8, k + 5, Block.ice.blockID);
		world.setBlock(i + 12, j + 8, k + 21, Block.ice.blockID);
		world.setBlock(i + 12, j + 9, k + 5, Block.ice.blockID);
		world.setBlock(i + 12, j + 9, k + 21, Block.ice.blockID);
		world.setBlock(i + 12, j + 10, k + 5, Block.ice.blockID);
		world.setBlock(i + 12, j + 10, k + 21, Block.ice.blockID);
		world.setBlock(i + 12, j + 11, k + 6, Block.ice.blockID);
		world.setBlock(i + 12, j + 11, k + 20, Block.ice.blockID);
		world.setBlock(i + 12, j + 12, k + 7, Block.ice.blockID);
		world.setBlock(i + 12, j + 12, k + 19, Block.ice.blockID);
		world.setBlock(i + 12, j + 13, k + 8, Block.ice.blockID);
		world.setBlock(i + 12, j + 13, k + 18, Block.ice.blockID);
		world.setBlock(i + 12, j + 14, k + 9, Block.ice.blockID);
		world.setBlock(i + 12, j + 14, k + 10, Block.ice.blockID);
		world.setBlock(i + 12, j + 14, k + 11, Block.ice.blockID);
		world.setBlock(i + 12, j + 14, k + 12, Block.ice.blockID);
		world.setBlock(i + 12, j + 14, k + 13, Block.ice.blockID);
		world.setBlock(i + 12, j + 14, k + 14, Block.ice.blockID);
		world.setBlock(i + 12, j + 14, k + 15, Block.ice.blockID);
		world.setBlock(i + 12, j + 14, k + 16, Block.ice.blockID);
		world.setBlock(i + 12, j + 14, k + 17, Block.ice.blockID);
		world.setBlock(i + 13, j + 0, k + 0, Block.dirt.blockID);
		world.setBlock(i + 13, j + 0, k + 1, Block.dirt.blockID);
		world.setBlock(i + 13, j + 0, k + 2, Block.dirt.blockID);
		world.setBlock(i + 13, j + 0, k + 3, Block.dirt.blockID);
		world.setBlock(i + 13, j + 0, k + 4, Block.dirt.blockID);
		world.setBlock(i + 13, j + 0, k + 5, Block.dirt.blockID);
		world.setBlock(i + 13, j + 0, k + 6, Block.dirt.blockID);
		world.setBlock(i + 13, j + 0, k + 7, Block.dirt.blockID);
		world.setBlock(i + 13, j + 0, k + 8, Block.dirt.blockID);
		world.setBlock(i + 13, j + 0, k + 9, Block.dirt.blockID);
		world.setBlock(i + 13, j + 0, k + 10, Block.dirt.blockID);
		world.setBlock(i + 13, j + 0, k + 11, Block.dirt.blockID);
		world.setBlock(i + 13, j + 0, k + 12, Block.dirt.blockID);
		world.setBlock(i + 13, j + 0, k + 13, Block.dirt.blockID);
		world.setBlock(i + 13, j + 0, k + 14, Block.dirt.blockID);
		world.setBlock(i + 13, j + 0, k + 15, Block.dirt.blockID);
		world.setBlock(i + 13, j + 0, k + 16, Block.dirt.blockID);
		world.setBlock(i + 13, j + 0, k + 17, Block.dirt.blockID);
		world.setBlock(i + 13, j + 0, k + 18, Block.dirt.blockID);
		world.setBlock(i + 13, j + 0, k + 19, Block.dirt.blockID);
		world.setBlock(i + 13, j + 0, k + 20, Block.dirt.blockID);
		world.setBlock(i + 13, j + 0, k + 21, Block.dirt.blockID);
		world.setBlock(i + 13, j + 0, k + 22, Block.dirt.blockID);
		world.setBlock(i + 13, j + 0, k + 23, Block.dirt.blockID);
		world.setBlock(i + 13, j + 0, k + 24, Block.dirt.blockID);
		world.setBlock(i + 13, j + 0, k + 25, Block.dirt.blockID);
		world.setBlock(i + 13, j + 0, k + 26, Block.dirt.blockID);
		world.setBlock(i + 13, j + 1, k + 0, Block.dirt.blockID);
		world.setBlock(i + 13, j + 1, k + 1, Block.dirt.blockID);
		world.setBlock(i + 13, j + 1, k + 2, Block.dirt.blockID);
		world.setBlock(i + 13, j + 1, k + 3, Block.dirt.blockID);
		world.setBlock(i + 13, j + 1, k + 4, Block.dirt.blockID);
		world.setBlock(i + 13, j + 1, k + 5, Block.dirt.blockID);
		world.setBlock(i + 13, j + 1, k + 6, Block.dirt.blockID);
		world.setBlock(i + 13, j + 1, k + 7, Block.dirt.blockID);
		world.setBlock(i + 13, j + 1, k + 8, Block.dirt.blockID);
		world.setBlock(i + 13, j + 1, k + 9, Block.dirt.blockID);
		world.setBlock(i + 13, j + 1, k + 10, Block.dirt.blockID);
		world.setBlock(i + 13, j + 1, k + 11, Block.dirt.blockID);
		world.setBlock(i + 13, j + 1, k + 12, Block.dirt.blockID);
		world.setBlock(i + 13, j + 1, k + 13, Block.dirt.blockID);
		world.setBlock(i + 13, j + 1, k + 14, Block.dirt.blockID);
		world.setBlock(i + 13, j + 1, k + 15, Block.dirt.blockID);
		world.setBlock(i + 13, j + 1, k + 16, Block.dirt.blockID);
		world.setBlock(i + 13, j + 1, k + 17, Block.dirt.blockID);
		world.setBlock(i + 13, j + 1, k + 18, Block.dirt.blockID);
		world.setBlock(i + 13, j + 1, k + 19, Block.dirt.blockID);
		world.setBlock(i + 13, j + 1, k + 20, Block.dirt.blockID);
		world.setBlock(i + 13, j + 1, k + 21, Block.dirt.blockID);
		world.setBlock(i + 13, j + 1, k + 22, Block.dirt.blockID);
		world.setBlock(i + 13, j + 1, k + 23, Block.dirt.blockID);
		world.setBlock(i + 13, j + 1, k + 24, Block.dirt.blockID);
		world.setBlock(i + 13, j + 1, k + 25, Block.dirt.blockID);
		world.setBlock(i + 13, j + 1, k + 26, Block.dirt.blockID);
		world.setBlock(i + 13, j + 2, k + 0, Block.grass.blockID);
		world.setBlock(i + 13, j + 2, k + 1, Block.grass.blockID);
		world.setBlock(i + 13, j + 2, k + 2, Block.grass.blockID);
		world.setBlock(i + 13, j + 2, k + 3, Block.grass.blockID);
		world.setBlock(i + 13, j + 2, k + 4, Block.grass.blockID);
		world.setBlock(i + 13, j + 2, k + 5, Block.blockSnow.blockID);
		world.setBlock(i + 13, j + 2, k + 6, MainRegistry.frostPlanks.blockID);
		world.setBlock(i + 13, j + 2, k + 7, MainRegistry.frostPlanks.blockID);
		world.setBlock(i + 13, j + 2, k + 8, MainRegistry.frostPlanks.blockID);
		world.setBlock(i + 13, j + 2, k + 9, MainRegistry.frostPlanks.blockID);
		world.setBlock(i + 13, j + 2, k + 10, MainRegistry.frostPlanks.blockID);
		world.setBlock(i + 13, j + 2, k + 11, MainRegistry.frostPlanks.blockID);
		world.setBlock(i + 13, j + 2, k + 12, MainRegistry.frostPlanks.blockID);
		world.setBlock(i + 13, j + 2, k + 13, MainRegistry.frostPlanks.blockID);
		world.setBlock(i + 13, j + 2, k + 14, MainRegistry.frostPlanks.blockID);
		world.setBlock(i + 13, j + 2, k + 15, MainRegistry.frostPlanks.blockID);
		world.setBlock(i + 13, j + 2, k + 16, MainRegistry.frostPlanks.blockID);
		world.setBlock(i + 13, j + 2, k + 17, MainRegistry.frostPlanks.blockID);
		world.setBlock(i + 13, j + 2, k + 18, MainRegistry.frostPlanks.blockID);
		world.setBlock(i + 13, j + 2, k + 19, MainRegistry.frostPlanks.blockID);
		world.setBlock(i + 13, j + 2, k + 20, MainRegistry.frostPlanks.blockID);
		world.setBlock(i + 13, j + 2, k + 21, Block.blockSnow.blockID);
		world.setBlock(i + 13, j + 2, k + 22, Block.grass.blockID);
		world.setBlock(i + 13, j + 2, k + 23, Block.grass.blockID);
		world.setBlock(i + 13, j + 2, k + 24, Block.grass.blockID);
		world.setBlock(i + 13, j + 2, k + 25, Block.grass.blockID);
		world.setBlock(i + 13, j + 2, k + 26, Block.grass.blockID);
		world.setBlock(i + 13, j + 3, k + 5, Block.blockSnow.blockID);
		world.setBlock(i + 13, j + 3, k + 10, -122);
		world.setBlock(i + 13, j + 3, k + 11, -122);
		world.setBlock(i + 13, j + 3, k + 15, -122);
		world.setBlock(i + 13, j + 3, k + 16, -122);
		world.setBlock(i + 13, j + 3, k + 21, Block.blockSnow.blockID);
		world.setBlock(i + 13, j + 4, k + 5, Block.ice.blockID);
		world.setBlock(i + 13, j + 4, k + 21, Block.ice.blockID);
		world.setBlock(i + 13, j + 5, k + 5, Block.ice.blockID);
		world.setBlock(i + 13, j + 5, k + 21, Block.ice.blockID);
		world.setBlock(i + 13, j + 6, k + 5, Block.ice.blockID);
		world.setBlock(i + 13, j + 6, k + 21, Block.ice.blockID);
		world.setBlock(i + 13, j + 7, k + 5, Block.ice.blockID);
		world.setBlock(i + 13, j + 7, k + 21, Block.ice.blockID);
		world.setBlock(i + 13, j + 8, k + 5, Block.ice.blockID);
		world.setBlock(i + 13, j + 8, k + 21, Block.ice.blockID);
		world.setBlock(i + 13, j + 9, k + 5, Block.ice.blockID);
		world.setBlock(i + 13, j + 9, k + 21, Block.ice.blockID);
		world.setBlock(i + 13, j + 10, k + 5, Block.ice.blockID);
		world.setBlock(i + 13, j + 10, k + 21, Block.ice.blockID);
		world.setBlock(i + 13, j + 11, k + 6, Block.ice.blockID);
		world.setBlock(i + 13, j + 11, k + 20, Block.ice.blockID);
		world.setBlock(i + 13, j + 12, k + 7, Block.ice.blockID);
		world.setBlock(i + 13, j + 12, k + 19, Block.ice.blockID);
		world.setBlock(i + 13, j + 13, k + 8, Block.ice.blockID);

		generate2(world, rand, i, j, k);
		return true;
	}
	public boolean generate2(World world, Random rand, int i, int j, int k)
	{
		world.setBlock(i + 13, j + 13, k + 18, Block.ice.blockID);
		world.setBlock(i + 13, j + 14, k + 9, Block.ice.blockID);
		world.setBlock(i + 13, j + 14, k + 10, Block.ice.blockID);
		world.setBlock(i + 13, j + 14, k + 11, Block.ice.blockID);
		world.setBlock(i + 13, j + 14, k + 12, Block.ice.blockID);
		world.setBlock(i + 13, j + 14, k + 13, Block.ice.blockID);
		world.setBlock(i + 13, j + 14, k + 14, Block.ice.blockID);
		world.setBlock(i + 13, j + 14, k + 15, Block.ice.blockID);
		world.setBlock(i + 13, j + 14, k + 16, Block.ice.blockID);
		world.setBlock(i + 13, j + 14, k + 17, Block.ice.blockID);
		world.setBlock(i + 14, j + 0, k + 0, Block.dirt.blockID);
		world.setBlock(i + 14, j + 0, k + 1, Block.dirt.blockID);
		world.setBlock(i + 14, j + 0, k + 2, Block.dirt.blockID);
		world.setBlock(i + 14, j + 0, k + 3, Block.dirt.blockID);
		world.setBlock(i + 14, j + 0, k + 4, Block.dirt.blockID);
		world.setBlock(i + 14, j + 0, k + 5, Block.dirt.blockID);
		world.setBlock(i + 14, j + 0, k + 6, Block.dirt.blockID);
		world.setBlock(i + 14, j + 0, k + 7, Block.dirt.blockID);
		world.setBlock(i + 14, j + 0, k + 8, Block.dirt.blockID);
		world.setBlock(i + 14, j + 0, k + 9, Block.dirt.blockID);
		world.setBlock(i + 14, j + 0, k + 10, Block.dirt.blockID);
		world.setBlock(i + 14, j + 0, k + 11, Block.dirt.blockID);
		world.setBlock(i + 14, j + 0, k + 12, Block.dirt.blockID);
		world.setBlock(i + 14, j + 0, k + 13, Block.dirt.blockID);
		world.setBlock(i + 14, j + 0, k + 14, Block.dirt.blockID);
		world.setBlock(i + 14, j + 0, k + 15, Block.dirt.blockID);
		world.setBlock(i + 14, j + 0, k + 16, Block.dirt.blockID);
		world.setBlock(i + 14, j + 0, k + 17, Block.dirt.blockID);
		world.setBlock(i + 14, j + 0, k + 18, Block.dirt.blockID);
		world.setBlock(i + 14, j + 0, k + 19, Block.dirt.blockID);
		world.setBlock(i + 14, j + 0, k + 20, Block.dirt.blockID);
		world.setBlock(i + 14, j + 0, k + 21, Block.dirt.blockID);
		world.setBlock(i + 14, j + 0, k + 22, Block.dirt.blockID);
		world.setBlock(i + 14, j + 0, k + 23, Block.dirt.blockID);
		world.setBlock(i + 14, j + 0, k + 24, Block.dirt.blockID);
		world.setBlock(i + 14, j + 0, k + 25, Block.dirt.blockID);
		world.setBlock(i + 14, j + 0, k + 26, Block.dirt.blockID);
		world.setBlock(i + 14, j + 1, k + 0, Block.dirt.blockID);
		world.setBlock(i + 14, j + 1, k + 1, Block.dirt.blockID);
		world.setBlock(i + 14, j + 1, k + 2, Block.dirt.blockID);
		world.setBlock(i + 14, j + 1, k + 3, Block.dirt.blockID);
		world.setBlock(i + 14, j + 1, k + 4, Block.dirt.blockID);
		world.setBlock(i + 14, j + 1, k + 5, Block.dirt.blockID);
		world.setBlock(i + 14, j + 1, k + 6, Block.dirt.blockID);
		world.setBlock(i + 14, j + 1, k + 7, Block.dirt.blockID);
		world.setBlock(i + 14, j + 1, k + 8, Block.dirt.blockID);
		world.setBlock(i + 14, j + 1, k + 9, Block.dirt.blockID);
		world.setBlock(i + 14, j + 1, k + 10, Block.dirt.blockID);
		world.setBlock(i + 14, j + 1, k + 11, Block.dirt.blockID);
		world.setBlock(i + 14, j + 1, k + 12, Block.dirt.blockID);
		world.setBlock(i + 14, j + 1, k + 13, Block.dirt.blockID);
		world.setBlock(i + 14, j + 1, k + 14, Block.dirt.blockID);
		world.setBlock(i + 14, j + 1, k + 15, Block.dirt.blockID);
		world.setBlock(i + 14, j + 1, k + 16, Block.dirt.blockID);
		world.setBlock(i + 14, j + 1, k + 17, Block.dirt.blockID);
		world.setBlock(i + 14, j + 1, k + 18, Block.dirt.blockID);
		world.setBlock(i + 14, j + 1, k + 19, Block.dirt.blockID);
		world.setBlock(i + 14, j + 1, k + 20, Block.dirt.blockID);
		world.setBlock(i + 14, j + 1, k + 21, Block.dirt.blockID);
		world.setBlock(i + 14, j + 1, k + 22, Block.dirt.blockID);
		world.setBlock(i + 14, j + 1, k + 23, Block.dirt.blockID);
		world.setBlock(i + 14, j + 1, k + 24, Block.dirt.blockID);
		world.setBlock(i + 14, j + 1, k + 25, Block.dirt.blockID);
		world.setBlock(i + 14, j + 1, k + 26, Block.dirt.blockID);
		world.setBlock(i + 14, j + 2, k + 0, Block.grass.blockID);
		world.setBlock(i + 14, j + 2, k + 1, Block.grass.blockID);
		world.setBlock(i + 14, j + 2, k + 2, Block.grass.blockID);
		world.setBlock(i + 14, j + 2, k + 3, Block.grass.blockID);
		world.setBlock(i + 14, j + 2, k + 4, Block.grass.blockID);
		world.setBlock(i + 14, j + 2, k + 5, Block.blockSnow.blockID);
		world.setBlock(i + 14, j + 2, k + 6, MainRegistry.frostPlanks.blockID);
		world.setBlock(i + 14, j + 2, k + 7, MainRegistry.frostPlanks.blockID);
		world.setBlock(i + 14, j + 2, k + 8, MainRegistry.frostPlanks.blockID);
		world.setBlock(i + 14, j + 2, k + 9, MainRegistry.frostPlanks.blockID);
		world.setBlock(i + 14, j + 2, k + 10, MainRegistry.frostPlanks.blockID);
		world.setBlock(i + 14, j + 2, k + 11, MainRegistry.frostPlanks.blockID);
		world.setBlock(i + 14, j + 2, k + 12, MainRegistry.frostPlanks.blockID);
		world.setBlock(i + 14, j + 2, k + 13, MainRegistry.frostPlanks.blockID);
		world.setBlock(i + 14, j + 2, k + 14, MainRegistry.frostPlanks.blockID);
		world.setBlock(i + 14, j + 2, k + 15, MainRegistry.frostPlanks.blockID);
		world.setBlock(i + 14, j + 2, k + 16, MainRegistry.frostPlanks.blockID);
		world.setBlock(i + 14, j + 2, k + 17, MainRegistry.frostPlanks.blockID);
		world.setBlock(i + 14, j + 2, k + 18, MainRegistry.frostPlanks.blockID);
		world.setBlock(i + 14, j + 2, k + 19, MainRegistry.frostPlanks.blockID);
		world.setBlock(i + 14, j + 2, k + 20, MainRegistry.frostPlanks.blockID);
		world.setBlock(i + 14, j + 2, k + 21, Block.blockSnow.blockID);
		world.setBlock(i + 14, j + 2, k + 22, Block.grass.blockID);
		world.setBlock(i + 14, j + 2, k + 23, Block.grass.blockID);
		world.setBlock(i + 14, j + 2, k + 24, Block.grass.blockID);
		world.setBlock(i + 14, j + 2, k + 25, Block.grass.blockID);
		world.setBlock(i + 14, j + 2, k + 26, Block.grass.blockID);
		world.setBlock(i + 14, j + 3, k + 5, Block.blockSnow.blockID);
		world.setBlock(i + 14, j + 3, k + 21, Block.blockSnow.blockID);
		world.setBlock(i + 14, j + 4, k + 5, Block.ice.blockID);
		world.setBlock(i + 14, j + 4, k + 21, Block.ice.blockID);
		world.setBlock(i + 14, j + 5, k + 5, Block.ice.blockID);
		world.setBlock(i + 14, j + 5, k + 21, Block.ice.blockID);
		world.setBlock(i + 14, j + 6, k + 5, Block.ice.blockID);
		world.setBlock(i + 14, j + 6, k + 21, Block.ice.blockID);
		world.setBlock(i + 14, j + 7, k + 5, Block.ice.blockID);
		world.setBlock(i + 14, j + 7, k + 21, Block.ice.blockID);
		world.setBlock(i + 14, j + 8, k + 5, Block.ice.blockID);
		world.setBlock(i + 14, j + 8, k + 21, Block.ice.blockID);
		world.setBlock(i + 14, j + 9, k + 5, Block.ice.blockID);
		world.setBlock(i + 14, j + 9, k + 21, Block.ice.blockID);
		world.setBlock(i + 14, j + 10, k + 5, Block.ice.blockID);
		world.setBlock(i + 14, j + 10, k + 21, Block.ice.blockID);
		world.setBlock(i + 14, j + 11, k + 6, Block.ice.blockID);
		world.setBlock(i + 14, j + 11, k + 20, Block.ice.blockID);
		world.setBlock(i + 14, j + 12, k + 7, Block.ice.blockID);
		world.setBlock(i + 14, j + 12, k + 19, Block.ice.blockID);
