/*
*** MADE BY MITHION'S .SCHEMATIC TO JAVA CONVERTING TOOL v1.6 ***
*/

package arcticraft.gen;

import java.util.Random;

import net.minecraft.block.Block;
import net.minecraft.world.World;
import net.minecraft.world.gen.feature.WorldGenerator;
import arcticraft.entities.AC_EntityChefEskimo;
import arcticraft.entities.AC_EntityCheifEskimo;
import arcticraft.entities.AC_EntityEskimo;
import arcticraft.entities.AC_EntityHunterEskimo;
import arcticraft.entities.AC_EntityTraderEskimo;
import arcticraft.main.MainRegistry;

public class AC_GenEskimoVillage extends WorldGenerator
{

	protected int [] GetValidSpawnBlocks()
	{
		return new int []
			{Block.snow.blockID, Block.blockSnow.blockID, MainRegistry.thickSnow.blockID};
	}

	public boolean LocationIsValidSpawn(World world, int i, int j, int k)
	{
		int distanceToAir = 0;
		int checkID = world.getBlockId(i, j, k);

		while (checkID != 0)
		{
			distanceToAir++;
			checkID = world.getBlockId(i, j + distanceToAir, k);
		}

		if (distanceToAir > 0)
		{
			return false;
		}
		j += distanceToAir - 1;

		int blockID = world.getBlockId(i, j, k);
		int blockIDAbove = world.getBlockId(i, j + 1, k);
		int blockIDBelow = world.getBlockId(i, j - 1, k);
		for (int x : GetValidSpawnBlocks())
		{
			if (blockIDAbove != 0)
			{
				return false;
			}
			if (blockID == x)
			{
				return true;
			}
			else if (blockID == Block.snow.blockID && blockIDBelow == x)
			{
				return true;
			}
		}
		return false;
	}

	public AC_GenEskimoVillage()
	{
	}

	public boolean generate(World world, Random rand, int i, int j, int k)
	{
		//check that each corner is one of the valid spawn blocks
		if (!LocationIsValidSpawn(world, i, j, k) || !LocationIsValidSpawn(world, i + 69, j, k) || !LocationIsValidSpawn(world, i + 69, j, k + 28) || !LocationIsValidSpawn(world, i, j, k + 28))
		{
			return false;
		}

		world.setBlock(i + 1, j + 0, k + 12, Block.blockSnow.blockID);
		world.setBlock(i + 1, j + 0, k + 13, Block.blockSnow.blockID);
		world.setBlock(i + 1, j + 0, k + 14, Block.blockSnow.blockID);
		world.setBlock(i + 1, j + 0, k + 15, Block.blockSnow.blockID);
		world.setBlock(i + 1, j + 0, k + 16, Block.blockSnow.blockID);
		world.setBlock(i + 1, j + 1, k + 12, Block.blockSnow.blockID);
		world.setBlock(i + 1, j + 1, k + 13, Block.blockSnow.blockID);
		world.setBlock(i + 1, j + 1, k + 14, Block.blockSnow.blockID);
		world.setBlock(i + 1, j + 1, k + 15, Block.blockSnow.blockID);
		world.setBlock(i + 1, j + 1, k + 16, Block.blockSnow.blockID);
		world.setBlock(i + 1, j + 2, k + 12, MainRegistry.unbreakableIce.blockID);
		world.setBlock(i + 1, j + 2, k + 13, MainRegistry.unbreakableIce.blockID);
		world.setBlock(i + 1, j + 2, k + 14, MainRegistry.unbreakableIce.blockID);
		world.setBlock(i + 1, j + 2, k + 15, MainRegistry.unbreakableIce.blockID);
		world.setBlock(i + 1, j + 2, k + 16, MainRegistry.unbreakableIce.blockID);
		world.setBlock(i + 1, j + 3, k + 12, MainRegistry.unbreakableIce.blockID);
		world.setBlock(i + 1, j + 3, k + 13, MainRegistry.unbreakableIce.blockID);
		world.setBlock(i + 1, j + 3, k + 14, MainRegistry.unbreakableIce.blockID);
		world.setBlock(i + 1, j + 3, k + 15, MainRegistry.unbreakableIce.blockID);
		world.setBlock(i + 1, j + 3, k + 16, MainRegistry.unbreakableIce.blockID);
		world.setBlock(i + 1, j + 4, k + 12, MainRegistry.unbreakableIce.blockID);
		world.setBlock(i + 1, j + 4, k + 13, MainRegistry.unbreakableIce.blockID);
		world.setBlock(i + 1, j + 4, k + 14, MainRegistry.unbreakableIce.blockID);
		world.setBlock(i + 1, j + 4, k + 15, MainRegistry.unbreakableIce.blockID);
		world.setBlock(i + 1, j + 4, k + 16, MainRegistry.unbreakableIce.blockID);
		world.setBlock(i + 1, j + 5, k + 12, MainRegistry.unbreakableIce.blockID);
		world.setBlock(i + 1, j + 5, k + 13, MainRegistry.unbreakableIce.blockID);
		world.setBlock(i + 1, j + 5, k + 14, MainRegistry.unbreakableIce.blockID);
		world.setBlock(i + 1, j + 5, k + 15, MainRegistry.unbreakableIce.blockID);
		world.setBlock(i + 1, j + 5, k + 16, MainRegistry.unbreakableIce.blockID);
		world.setBlock(i + 1, j + 6, k + 12, MainRegistry.unbreakableIce.blockID);
		world.setBlock(i + 1, j + 6, k + 13, MainRegistry.unbreakableIce.blockID);
		world.setBlock(i + 1, j + 6, k + 14, MainRegistry.unbreakableIce.blockID);
		world.setBlock(i + 1, j + 6, k + 15, MainRegistry.unbreakableIce.blockID);
		world.setBlock(i + 1, j + 6, k + 16, MainRegistry.unbreakableIce.blockID);
		world.setBlock(i + 1, j + 7, k + 12, MainRegistry.unbreakableIce.blockID);
		world.setBlock(i + 1, j + 7, k + 13, MainRegistry.unbreakableIce.blockID);
		world.setBlock(i + 1, j + 7, k + 14, MainRegistry.unbreakableIce.blockID);
		world.setBlock(i + 1, j + 7, k + 15, MainRegistry.unbreakableIce.blockID);
		world.setBlock(i + 1, j + 7, k + 16, MainRegistry.unbreakableIce.blockID);
		world.setBlock(i + 1, j + 8, k + 12, MainRegistry.unbreakableIce.blockID);
		world.setBlock(i + 1, j + 8, k + 13, MainRegistry.unbreakableIce.blockID);
		world.setBlock(i + 1, j + 8, k + 14, MainRegistry.unbreakableIce.blockID);
		world.setBlock(i + 1, j + 8, k + 15, MainRegistry.unbreakableIce.blockID);
		world.setBlock(i + 1, j + 8, k + 16, MainRegistry.unbreakableIce.blockID);
		world.setBlock(i + 2, j + 0, k + 11, Block.blockSnow.blockID);
		world.setBlock(i + 2, j + 0, k + 12, MainRegistry.frostPlanks.blockID);
		world.setBlock(i + 2, j + 0, k + 13, MainRegistry.frostPlanks.blockID);
		world.setBlock(i + 2, j + 0, k + 14, MainRegistry.frostPlanks.blockID);
		world.setBlock(i + 2, j + 0, k + 15, MainRegistry.frostPlanks.blockID);
		world.setBlock(i + 2, j + 0, k + 16, MainRegistry.frostPlanks.blockID);
		world.setBlock(i + 2, j + 0, k + 17, Block.blockSnow.blockID);
		world.setBlock(i + 2, j + 1, k + 11, Block.blockSnow.blockID);
		world.setBlock(i + 2, j + 1, k + 12, MainRegistry.arcaneStone.blockID);
		world.setBlock(i + 2, j + 1, k + 13, 0);
		world.setBlock(i + 2, j + 1, k + 14, 0);
		world.setBlock(i + 2, j + 1, k + 15, 0);
		world.setBlock(i + 2, j + 1, k + 16, MainRegistry.arcaneStone.blockID);
		world.setBlock(i + 2, j + 1, k + 17, Block.blockSnow.blockID);
		world.setBlock(i + 2, j + 2, k + 11, MainRegistry.unbreakableIce.blockID);
		world.setBlock(i + 2, j + 2, k + 12, 0);
		world.setBlock(i + 2, j + 2, k + 13, 0);
		world.setBlock(i + 2, j + 2, k + 14, 0);
		world.setBlock(i + 2, j + 2, k + 15, 0);
		world.setBlock(i + 2, j + 2, k + 16, 0);
		world.setBlock(i + 2, j + 2, k + 17, MainRegistry.unbreakableIce.blockID);
		world.setBlock(i + 2, j + 3, k + 11, MainRegistry.unbreakableIce.blockID);
		world.setBlock(i + 2, j + 3, k + 17, MainRegistry.unbreakableIce.blockID);
		world.setBlock(i + 2, j + 4, k + 11, MainRegistry.unbreakableIce.blockID);
		world.setBlock(i + 2, j + 4, k + 17, MainRegistry.unbreakableIce.blockID);
		world.setBlock(i + 2, j + 5, k + 11, MainRegistry.unbreakableIce.blockID);
		world.setBlock(i + 2, j + 5, k + 17, MainRegistry.unbreakableIce.blockID);
		world.setBlock(i + 2, j + 6, k + 11, MainRegistry.unbreakableIce.blockID);
		world.setBlock(i + 2, j + 6, k + 17, MainRegistry.unbreakableIce.blockID);
		world.setBlock(i + 2, j + 7, k + 11, MainRegistry.unbreakableIce.blockID);
		world.setBlock(i + 2, j + 7, k + 17, MainRegistry.unbreakableIce.blockID);
		world.setBlock(i + 2, j + 8, k + 11, MainRegistry.unbreakableIce.blockID);
		world.setBlock(i + 2, j + 8, k + 17, MainRegistry.unbreakableIce.blockID);
		world.setBlock(i + 2, j + 9, k + 12, MainRegistry.unbreakableIce.blockID);
		world.setBlock(i + 2, j + 9, k + 13, MainRegistry.unbreakableIce.blockID);
		world.setBlock(i + 2, j + 9, k + 14, MainRegistry.unbreakableIce.blockID);
		world.setBlock(i + 2, j + 9, k + 15, MainRegistry.unbreakableIce.blockID);
		world.setBlock(i + 2, j + 9, k + 16, MainRegistry.unbreakableIce.blockID);
		world.setBlock(i + 3, j + 0, k + 10, Block.blockSnow.blockID);
		world.setBlock(i + 3, j + 0, k + 11, MainRegistry.frostPlanks.blockID);
		world.setBlock(i + 3, j + 0, k + 12, MainRegistry.frostPlanks.blockID);
		world.setBlock(i + 3, j + 0, k + 13, MainRegistry.frostPlanks.blockID);
		world.setBlock(i + 3, j + 0, k + 14, MainRegistry.frostPlanks.blockID);
		world.setBlock(i + 3, j + 0, k + 15, MainRegistry.frostPlanks.blockID);
		world.setBlock(i + 3, j + 0, k + 16, MainRegistry.frostPlanks.blockID);
		world.setBlock(i + 3, j + 0, k + 17, MainRegistry.frostPlanks.blockID);
		world.setBlock(i + 3, j + 0, k + 18, Block.blockSnow.blockID);
		world.setBlock(i + 3, j + 1, k + 10, Block.blockSnow.blockID);
		world.setBlock(i + 3, j + 1, k + 11, 0);
		world.setBlock(i + 3, j + 1, k + 12, 0);
		world.setBlock(i + 3, j + 1, k + 13, 0);
		world.setBlock(i + 3, j + 1, k + 14, 0);
		world.setBlock(i + 3, j + 1, k + 15, 0);
		world.setBlock(i + 3, j + 1, k + 16, 0);
		world.setBlock(i + 3, j + 1, k + 17, 0);
		world.setBlock(i + 3, j + 1, k + 18, Block.blockSnow.blockID);
		world.setBlock(i + 3, j + 2, k + 10, MainRegistry.unbreakableIce.blockID);
		world.setBlock(i + 3, j + 2, k + 11, 0);
		world.setBlock(i + 3, j + 2, k + 12, 0);
		world.setBlock(i + 3, j + 2, k + 13, 0);
		world.setBlock(i + 3, j + 2, k + 14, 0);
		world.setBlock(i + 3, j + 2, k + 15, 0);
		world.setBlock(i + 3, j + 2, k + 16, 0);
		world.setBlock(i + 3, j + 2, k + 17, 0);
		world.setBlock(i + 3, j + 2, k + 18, MainRegistry.unbreakableIce.blockID);
		world.setBlock(i + 3, j + 3, k + 10, MainRegistry.unbreakableIce.blockID);
		world.setBlock(i + 3, j + 3, k + 18, MainRegistry.unbreakableIce.blockID);
		world.setBlock(i + 3, j + 4, k + 10, MainRegistry.unbreakableIce.blockID);
		world.setBlock(i + 3, j + 4, k + 18, MainRegistry.unbreakableIce.blockID);
		world.setBlock(i + 3, j + 5, k + 10, MainRegistry.unbreakableIce.blockID);
		world.setBlock(i + 3, j + 5, k + 18, MainRegistry.unbreakableIce.blockID);
		world.setBlock(i + 3, j + 6, k + 10, MainRegistry.unbreakableIce.blockID);
		world.setBlock(i + 3, j + 6, k + 18, MainRegistry.unbreakableIce.blockID);
		world.setBlock(i + 3, j + 7, k + 10, MainRegistry.unbreakableIce.blockID);
		world.setBlock(i + 3, j + 7, k + 18, MainRegistry.unbreakableIce.blockID);
		world.setBlock(i + 3, j + 8, k + 10, MainRegistry.unbreakableIce.blockID);
		world.setBlock(i + 3, j + 8, k + 18, MainRegistry.unbreakableIce.blockID);
		world.setBlock(i + 3, j + 9, k + 11, MainRegistry.unbreakableIce.blockID);
		world.setBlock(i + 3, j + 9, k + 17, MainRegistry.unbreakableIce.blockID);
		world.setBlock(i + 3, j + 10, k + 12, MainRegistry.unbreakableIce.blockID);
		world.setBlock(i + 3, j + 10, k + 13, MainRegistry.unbreakableIce.blockID);
		world.setBlock(i + 3, j + 10, k + 14, MainRegistry.unbreakableIce.blockID);
		world.setBlock(i + 3, j + 10, k + 15, MainRegistry.unbreakableIce.blockID);
		world.setBlock(i + 3, j + 10, k + 16, MainRegistry.unbreakableIce.blockID);
		world.setBlock(i + 4, j + 0, k + 10, Block.blockSnow.blockID);
		world.setBlock(i + 4, j + 0, k + 11, MainRegistry.frostPlanks.blockID);
		world.setBlock(i + 4, j + 0, k + 12, MainRegistry.frostPlanks.blockID);
		world.setBlock(i + 4, j + 0, k + 13, MainRegistry.frostPlanks.blockID);
		world.setBlock(i + 4, j + 0, k + 14, MainRegistry.frostPlanks.blockID);
		world.setBlock(i + 4, j + 0, k + 15, MainRegistry.frostPlanks.blockID);
		world.setBlock(i + 4, j + 0, k + 16, MainRegistry.frostPlanks.blockID);
		world.setBlock(i + 4, j + 0, k + 17, MainRegistry.frostPlanks.blockID);
		world.setBlock(i + 4, j + 0, k + 18, Block.blockSnow.blockID);
		world.setBlock(i + 4, j + 1, k + 10, Block.blockSnow.blockID);
		world.setBlock(i + 4, j + 1, k + 11, 0);
		world.setBlock(i + 4, j + 1, k + 12, 0);
		world.setBlock(i + 4, j + 1, k + 13, 0);
		world.setBlock(i + 4, j + 1, k + 14, Block.blockDiamond.blockID);
		world.setBlock(i + 4, j + 1, k + 15, 0);
		world.setBlock(i + 4, j + 1, k + 16, 0);
		world.setBlock(i + 4, j + 1, k + 17, 0);
		world.setBlock(i + 4, j + 1, k + 18, Block.blockSnow.blockID);
		world.setBlock(i + 4, j + 2, k + 10, MainRegistry.unbreakableIce.blockID);
		world.setBlock(i + 4, j + 2, k + 11, 0);
		world.setBlock(i + 4, j + 2, k + 12, 0);
		world.setBlock(i + 4, j + 2, k + 13, 0);
		world.setBlock(i + 4, j + 2, k + 14, 0);
		world.setBlock(i + 4, j + 2, k + 15, 0);
		world.setBlock(i + 4, j + 2, k + 16, 0);
		world.setBlock(i + 4, j + 2, k + 17, 0);
		world.setBlock(i + 4, j + 2, k + 18, MainRegistry.unbreakableIce.blockID);
		world.setBlock(i + 4, j + 3, k + 10, MainRegistry.unbreakableIce.blockID);
		world.setBlock(i + 4, j + 3, k + 18, MainRegistry.unbreakableIce.blockID);
		world.setBlock(i + 4, j + 4, k + 10, MainRegistry.unbreakableIce.blockID);
		world.setBlock(i + 4, j + 4, k + 18, MainRegistry.unbreakableIce.blockID);
		world.setBlock(i + 4, j + 5, k + 10, MainRegistry.unbreakableIce.blockID);
		world.setBlock(i + 4, j + 5, k + 18, MainRegistry.unbreakableIce.blockID);
		world.setBlock(i + 4, j + 6, k + 10, MainRegistry.unbreakableIce.blockID);
		world.setBlock(i + 4, j + 6, k + 18, MainRegistry.unbreakableIce.blockID);
		world.setBlock(i + 4, j + 7, k + 10, MainRegistry.unbreakableIce.blockID);
		world.setBlock(i + 4, j + 7, k + 18, MainRegistry.unbreakableIce.blockID);
		world.setBlock(i + 4, j + 8, k + 10, MainRegistry.unbreakableIce.blockID);
		world.setBlock(i + 4, j + 8, k + 18, MainRegistry.unbreakableIce.blockID);
		world.setBlock(i + 4, j + 9, k + 11, MainRegistry.unbreakableIce.blockID);
		world.setBlock(i + 4, j + 9, k + 17, MainRegistry.unbreakableIce.blockID);
		world.setBlock(i + 4, j + 10, k + 12, MainRegistry.unbreakableIce.blockID);
		world.setBlock(i + 4, j + 10, k + 16, MainRegistry.unbreakableIce.blockID);
		world.setBlock(i + 4, j + 11, k + 13, MainRegistry.unbreakableIce.blockID);
		world.setBlock(i + 4, j + 11, k + 14, MainRegistry.unbreakableIce.blockID);
		world.setBlock(i + 4, j + 11, k + 15, MainRegistry.unbreakableIce.blockID);
		world.setBlock(i + 5, j + 0, k + 10, Block.blockSnow.blockID);
		world.setBlock(i + 5, j + 0, k + 11, MainRegistry.frostPlanks.blockID);
		world.setBlock(i + 5, j + 0, k + 12, MainRegistry.frostPlanks.blockID);
		world.setBlock(i + 5, j + 0, k + 13, MainRegistry.frostPlanks.blockID);
		world.setBlock(i + 5, j + 0, k + 14, MainRegistry.frostPlanks.blockID);
		world.setBlock(i + 5, j + 0, k + 15, MainRegistry.frostPlanks.blockID);
		world.setBlock(i + 5, j + 0, k + 16, MainRegistry.frostPlanks.blockID);
		world.setBlock(i + 5, j + 0, k + 17, MainRegistry.frostPlanks.blockID);
		world.setBlock(i + 5, j + 0, k + 18, Block.blockSnow.blockID);
		world.setBlock(i + 5, j + 1, k + 10, Block.blockSnow.blockID);
		world.setBlock(i + 5, j + 1, k + 11, 0);
		world.setBlock(i + 5, j + 1, k + 12, 0);
		world.setBlock(i + 5, j + 1, k + 13, 0);
		world.setBlock(i + 5, j + 1, k + 14, 0);
		world.setBlock(i + 5, j + 1, k + 15, 0);
		world.setBlock(i + 5, j + 1, k + 16, 0);
		world.setBlock(i + 5, j + 1, k + 17, 0);
		world.setBlock(i + 5, j + 1, k + 18, Block.blockSnow.blockID);
		world.setBlock(i + 5, j + 2, k + 10, MainRegistry.unbreakableIce.blockID);
		world.setBlock(i + 5, j + 2, k + 11, 0);
		world.setBlock(i + 5, j + 2, k + 12, 0);
		world.setBlock(i + 5, j + 2, k + 13, 0);
		world.setBlock(i + 5, j + 2, k + 14, 0);
		world.setBlock(i + 5, j + 2, k + 15, 0);
		world.setBlock(i + 5, j + 2, k + 16, 0);
		world.setBlock(i + 5, j + 2, k + 17, 0);
		world.setBlock(i + 5, j + 2, k + 18, MainRegistry.unbreakableIce.blockID);
		world.setBlock(i + 5, j + 3, k + 10, MainRegistry.unbreakableIce.blockID);
		world.setBlock(i + 5, j + 3, k + 18, MainRegistry.unbreakableIce.blockID);
		world.setBlock(i + 5, j + 4, k + 10, MainRegistry.unbreakableIce.blockID);
		world.setBlock(i + 5, j + 4, k + 18, MainRegistry.unbreakableIce.blockID);
		world.setBlock(i + 5, j + 5, k + 10, MainRegistry.unbreakableIce.blockID);
		world.setBlock(i + 5, j + 5, k + 18, MainRegistry.unbreakableIce.blockID);
		world.setBlock(i + 5, j + 6, k + 10, MainRegistry.unbreakableIce.blockID);
		world.setBlock(i + 5, j + 6, k + 18, MainRegistry.unbreakableIce.blockID);
		world.setBlock(i + 5, j + 7, k + 10, MainRegistry.unbreakableIce.blockID);
		world.setBlock(i + 5, j + 7, k + 18, MainRegistry.unbreakableIce.blockID);
		world.setBlock(i + 5, j + 8, k + 10, MainRegistry.unbreakableIce.blockID);
		world.setBlock(i + 5, j + 8, k + 18, MainRegistry.unbreakableIce.blockID);
		world.setBlock(i + 5, j + 9, k + 11, MainRegistry.unbreakableIce.blockID);
		world.setBlock(i + 5, j + 9, k + 17, MainRegistry.unbreakableIce.blockID);
		world.setBlock(i + 5, j + 10, k + 12, MainRegistry.unbreakableIce.blockID);
		world.setBlock(i + 5, j + 10, k + 16, MainRegistry.unbreakableIce.blockID);
		world.setBlock(i + 5, j + 11, k + 13, MainRegistry.unbreakableIce.blockID);
		world.setBlock(i + 5, j + 11, k + 15, MainRegistry.unbreakableIce.blockID);
		world.setBlock(i + 5, j + 12, k + 14, MainRegistry.unbreakableIce.blockID);
		world.setBlock(i + 6, j + 0, k + 10, Block.blockSnow.blockID);
		world.setBlock(i + 6, j + 0, k + 11, MainRegistry.frostPlanks.blockID);
		world.setBlock(i + 6, j + 0, k + 12, MainRegistry.frostPlanks.blockID);
		world.setBlock(i + 6, j + 0, k + 13, MainRegistry.frostPlanks.blockID);
		world.setBlock(i + 6, j + 0, k + 14, MainRegistry.frostPlanks.blockID);
		world.setBlock(i + 6, j + 0, k + 15, MainRegistry.frostPlanks.blockID);
		world.setBlock(i + 6, j + 0, k + 16, MainRegistry.frostPlanks.blockID);
		world.setBlock(i + 6, j + 0, k + 17, MainRegistry.frostPlanks.blockID);
		world.setBlock(i + 6, j + 0, k + 18, Block.blockSnow.blockID);
		world.setBlock(i + 6, j + 1, k + 10, Block.blockSnow.blockID);
		world.setBlock(i + 6, j + 1, k + 11, 0);
		world.setBlock(i + 6, j + 1, k + 12, 0);
		world.setBlock(i + 6, j + 1, k + 13, 0);
		world.setBlock(i + 6, j + 1, k + 14, 0);
		world.setBlock(i + 6, j + 1, k + 15, 0);
		world.setBlock(i + 6, j + 1, k + 16, 0);
		world.setBlock(i + 6, j + 1, k + 17, 0);
		world.setBlock(i + 6, j + 1, k + 18, Block.blockSnow.blockID);
		world.setBlock(i + 6, j + 2, k + 10, MainRegistry.unbreakableIce.blockID);
		world.setBlock(i + 6, j + 2, k + 11, 0);
		world.setBlock(i + 6, j + 2, k + 12, 0);
		world.setBlock(i + 6, j + 2, k + 13, 0);
		world.setBlock(i + 6, j + 2, k + 14, 0);
		world.setBlock(i + 6, j + 2, k + 15, 0);
		world.setBlock(i + 6, j + 2, k + 16, 0);
		world.setBlock(i + 6, j + 2, k + 17, 0);
		world.setBlock(i + 6, j + 2, k + 18, MainRegistry.unbreakableIce.blockID);
		world.setBlock(i + 6, j + 3, k + 10, MainRegistry.unbreakableIce.blockID);
		world.setBlock(i + 6, j + 3, k + 18, MainRegistry.unbreakableIce.blockID);
		world.setBlock(i + 6, j + 4, k + 10, MainRegistry.unbreakableIce.blockID);
		world.setBlock(i + 6, j + 4, k + 18, MainRegistry.unbreakableIce.blockID);
		world.setBlock(i + 6, j + 5, k + 10, MainRegistry.unbreakableIce.blockID);
		world.setBlock(i + 6, j + 5, k + 18, MainRegistry.unbreakableIce.blockID);
		world.setBlock(i + 6, j + 6, k + 10, MainRegistry.unbreakableIce.blockID);
		world.setBlock(i + 6, j + 6, k + 18, MainRegistry.unbreakableIce.blockID);
		world.setBlock(i + 6, j + 7, k + 10, MainRegistry.unbreakableIce.blockID);
		world.setBlock(i + 6, j + 7, k + 18, MainRegistry.unbreakableIce.blockID);
		world.setBlock(i + 6, j + 8, k + 10, MainRegistry.unbreakableIce.blockID);
		world.setBlock(i + 6, j + 8, k + 18, MainRegistry.unbreakableIce.blockID);
		world.setBlock(i + 6, j + 9, k + 11, MainRegistry.unbreakableIce.blockID);
		world.setBlock(i + 6, j + 9, k + 17, MainRegistry.unbreakableIce.blockID);
		world.setBlock(i + 6, j + 10, k + 12, MainRegistry.unbreakableIce.blockID);
		world.setBlock(i + 6, j + 10, k + 16, MainRegistry.unbreakableIce.blockID);
		world.setBlock(i + 6, j + 11, k + 13, MainRegistry.unbreakableIce.blockID);
		world.setBlock(i + 6, j + 11, k + 15, MainRegistry.unbreakableIce.blockID);
		world.setBlock(i + 6, j + 12, k + 14, MainRegistry.unbreakableIce.blockID);
		world.setBlock(i + 7, j + 0, k + 9, Block.blockSnow.blockID);
		world.setBlock(i + 7, j + 0, k + 10, MainRegistry.frostPlanks.blockID);
		world.setBlock(i + 7, j + 0, k + 11, MainRegistry.frostPlanks.blockID);
		world.setBlock(i + 7, j + 0, k + 12, MainRegistry.frostPlanks.blockID);
		world.setBlock(i + 7, j + 0, k + 13, MainRegistry.frostPlanks.blockID);
		world.setBlock(i + 7, j + 0, k + 14, MainRegistry.frostPlanks.blockID);
		world.setBlock(i + 7, j + 0, k + 15, MainRegistry.frostPlanks.blockID);
		world.setBlock(i + 7, j + 0, k + 16, MainRegistry.frostPlanks.blockID);
		world.setBlock(i + 7, j + 0, k + 17, MainRegistry.frostPlanks.blockID);
		world.setBlock(i + 7, j + 0, k + 18, MainRegistry.frostPlanks.blockID);
		world.setBlock(i + 7, j + 0, k + 19, Block.blockSnow.blockID);
		world.setBlock(i + 7, j + 1, k + 9, Block.blockSnow.blockID);
		world.setBlock(i + 7, j + 1, k + 10, 0);
		world.setBlock(i + 7, j + 1, k + 11, 0);
		world.setBlock(i + 7, j + 1, k + 12, 0);
		world.setBlock(i + 7, j + 1, k + 13, 0);
		world.setBlock(i + 7, j + 1, k + 14, 0);
		world.setBlock(i + 7, j + 1, k + 15, 0);
		world.setBlock(i + 7, j + 1, k + 16, 0);
		world.setBlock(i + 7, j + 1, k + 17, 0);
		world.setBlock(i + 7, j + 1, k + 18, 0);
		world.setBlock(i + 7, j + 1, k + 19, Block.blockSnow.blockID);
		world.setBlock(i + 7, j + 2, k + 9, MainRegistry.unbreakableIce.blockID);
		world.setBlock(i + 7, j + 2, k + 10, 0);
		world.setBlock(i + 7, j + 2, k + 11, 0);
		world.setBlock(i + 7, j + 2, k + 12, 0);
		world.setBlock(i + 7, j + 2, k + 13, 0);
		world.setBlock(i + 7, j + 2, k + 14, 0);
		world.setBlock(i + 7, j + 2, k + 15, 0);
		world.setBlock(i + 7, j + 2, k + 16, 0);
		world.setBlock(i + 7, j + 2, k + 17, 0);
		world.setBlock(i + 7, j + 2, k + 18, 0);
		world.setBlock(i + 7, j + 2, k + 19, MainRegistry.unbreakableIce.blockID);
		world.setBlock(i + 7, j + 3, k + 9, MainRegistry.unbreakableIce.blockID);
		world.setBlock(i + 7, j + 3, k + 19, MainRegistry.unbreakableIce.blockID);
		world.setBlock(i + 7, j + 4, k + 9, MainRegistry.unbreakableIce.blockID);
		world.setBlock(i + 7, j + 4, k + 19, MainRegistry.unbreakableIce.blockID);
		world.setBlock(i + 7, j + 5, k + 9, MainRegistry.unbreakableIce.blockID);
		world.setBlock(i + 7, j + 5, k + 19, MainRegistry.unbreakableIce.blockID);
		world.setBlock(i + 7, j + 6, k + 9, MainRegistry.unbreakableIce.blockID);
		world.setBlock(i + 7, j + 6, k + 19, MainRegistry.unbreakableIce.blockID);
		world.setBlock(i + 7, j + 7, k + 9, MainRegistry.unbreakableIce.blockID);
		world.setBlock(i + 7, j + 7, k + 19, MainRegistry.unbreakableIce.blockID);
		world.setBlock(i + 7, j + 8, k + 9, MainRegistry.unbreakableIce.blockID);
		world.setBlock(i + 7, j + 8, k + 19, MainRegistry.unbreakableIce.blockID);
		world.setBlock(i + 7, j + 9, k + 10, MainRegistry.unbreakableIce.blockID);
		world.setBlock(i + 7, j + 9, k + 18, MainRegistry.unbreakableIce.blockID);
		world.setBlock(i + 7, j + 10, k + 11, MainRegistry.unbreakableIce.blockID);
		world.setBlock(i + 7, j + 10, k + 17, MainRegistry.unbreakableIce.blockID);
		world.setBlock(i + 7, j + 11, k + 12, MainRegistry.unbreakableIce.blockID);
		world.setBlock(i + 7, j + 11, k + 16, MainRegistry.unbreakableIce.blockID);
		world.setBlock(i + 7, j + 12, k + 13, MainRegistry.unbreakableIce.blockID);
		world.setBlock(i + 7, j + 12, k + 14, MainRegistry.unbreakableIce.blockID);
		world.setBlock(i + 7, j + 12, k + 15, MainRegistry.unbreakableIce.blockID);
		world.setBlock(i + 8, j + 0, k + 8, Block.blockSnow.blockID);
		world.setBlock(i + 8, j + 0, k + 9, MainRegistry.frostPlanks.blockID);
		world.setBlock(i + 8, j + 0, k + 10, MainRegistry.frostPlanks.blockID);
		world.setBlock(i + 8, j + 0, k + 11, MainRegistry.frostPlanks.blockID);
		world.setBlock(i + 8, j + 0, k + 12, MainRegistry.frostPlanks.blockID);
		world.setBlock(i + 8, j + 0, k + 13, MainRegistry.frostPlanks.blockID);
		world.setBlock(i + 8, j + 0, k + 14, MainRegistry.frostPlanks.blockID);
		world.setBlock(i + 8, j + 0, k + 15, MainRegistry.frostPlanks.blockID);
		world.setBlock(i + 8, j + 0, k + 16, MainRegistry.frostPlanks.blockID);
		world.setBlock(i + 8, j + 0, k + 17, MainRegistry.frostPlanks.blockID);
		world.setBlock(i + 8, j + 0, k + 18, MainRegistry.frostPlanks.blockID);
		world.setBlock(i + 8, j + 0, k + 19, MainRegistry.frostPlanks.blockID);
		world.setBlock(i + 8, j + 0, k + 20, Block.blockSnow.blockID);
		world.setBlock(i + 8, j + 1, k + 8, Block.blockSnow.blockID);
		world.setBlock(i + 8, j + 1, k + 9, MainRegistry.arcaneStone.blockID);
		world.setBlock(i + 8, j + 1, k + 10, 0);
		world.setBlock(i + 8, j + 1, k + 11, 0);
		world.setBlock(i + 8, j + 1, k + 12, 0);
		world.setBlock(i + 8, j + 1, k + 13, Block.stoneBrick.blockID);
		world.setBlock(i + 8, j + 1, k + 14, Block.stoneBrick.blockID);
		world.setBlock(i + 8, j + 1, k + 15, Block.stoneBrick.blockID);
		world.setBlock(i + 8, j + 1, k + 16, 0);
		world.setBlock(i + 8, j + 1, k + 17, 0);
		world.setBlock(i + 8, j + 1, k + 18, 0);
		world.setBlock(i + 8, j + 1, k + 19, MainRegistry.arcaneStone.blockID);
		world.setBlock(i + 8, j + 1, k + 20, Block.blockSnow.blockID);
		world.setBlock(i + 8, j + 2, k + 8, MainRegistry.unbreakableIce.blockID);
		world.setBlock(i + 8, j + 2, k + 9, 0);
		world.setBlock(i + 8, j + 2, k + 10, 0);
		world.setBlock(i + 8, j + 2, k + 11, 0);
		world.setBlock(i + 8, j + 2, k + 12, 0);
		world.setBlock(i + 8, j + 2, k + 13, 0);
		world.setBlock(i + 8, j + 2, k + 14, 0);
		world.setBlock(i + 8, j + 2, k + 15, 0);
		world.setBlock(i + 8, j + 2, k + 16, 0);
		world.setBlock(i + 8, j + 2, k + 17, 0);
		world.setBlock(i + 8, j + 2, k + 18, 0);
		world.setBlock(i + 8, j + 2, k + 19, 0);
		world.setBlock(i + 8, j + 2, k + 20, MainRegistry.unbreakableIce.blockID);
		world.setBlock(i + 8, j + 3, k + 8, MainRegistry.unbreakableIce.blockID);
		world.setBlock(i + 8, j + 3, k + 20, MainRegistry.unbreakableIce.blockID);
		world.setBlock(i + 8, j + 4, k + 8, MainRegistry.unbreakableIce.blockID);
		world.setBlock(i + 8, j + 4, k + 20, MainRegistry.unbreakableIce.blockID);
		world.setBlock(i + 8, j + 5, k + 8, MainRegistry.unbreakableIce.blockID);
		world.setBlock(i + 8, j + 5, k + 20, MainRegistry.unbreakableIce.blockID);
		world.setBlock(i + 8, j + 6, k + 8, MainRegistry.unbreakableIce.blockID);
		world.setBlock(i + 8, j + 6, k + 20, MainRegistry.unbreakableIce.blockID);
		world.setBlock(i + 8, j + 7, k + 8, MainRegistry.unbreakableIce.blockID);
		world.setBlock(i + 8, j + 7, k + 20, MainRegistry.unbreakableIce.blockID);
		world.setBlock(i + 8, j + 8, k + 8, MainRegistry.unbreakableIce.blockID);
		world.setBlock(i + 8, j + 8, k + 20, MainRegistry.unbreakableIce.blockID);
		world.setBlock(i + 8, j + 9, k + 9, MainRegistry.unbreakableIce.blockID);
		world.setBlock(i + 8, j + 9, k + 19, MainRegistry.unbreakableIce.blockID);
		world.setBlock(i + 8, j + 10, k + 10, MainRegistry.unbreakableIce.blockID);
		world.setBlock(i + 8, j + 10, k + 18, MainRegistry.unbreakableIce.blockID);
		world.setBlock(i + 8, j + 11, k + 11, MainRegistry.unbreakableIce.blockID);
		world.setBlock(i + 8, j + 11, k + 17, MainRegistry.unbreakableIce.blockID);
		world.setBlock(i + 8, j + 12, k + 12, MainRegistry.unbreakableIce.blockID);
		world.setBlock(i + 8, j + 12, k + 13, MainRegistry.unbreakableIce.blockID);
		world.setBlock(i + 8, j + 12, k + 14, MainRegistry.unbreakableIce.blockID);
		world.setBlock(i + 8, j + 12, k + 15, MainRegistry.unbreakableIce.blockID);
		world.setBlock(i + 8, j + 12, k + 16, MainRegistry.unbreakableIce.blockID);
		world.setBlock(i + 9, j + 0, k + 7, Block.blockSnow.blockID);
		world.setBlock(i + 9, j + 0, k + 8, MainRegistry.frostPlanks.blockID);
		world.setBlock(i + 9, j + 0, k + 9, MainRegistry.frostPlanks.blockID);
		world.setBlock(i + 9, j + 0, k + 10, MainRegistry.frostPlanks.blockID);
		world.setBlock(i + 9, j + 0, k + 11, MainRegistry.frostPlanks.blockID);
		world.setBlock(i + 9, j + 0, k + 12, MainRegistry.frostPlanks.blockID);
		world.setBlock(i + 9, j + 0, k + 13, MainRegistry.frostPlanks.blockID);
		world.setBlock(i + 9, j + 0, k + 14, MainRegistry.frostPlanks.blockID);
		world.setBlock(i + 9, j + 0, k + 15, MainRegistry.frostPlanks.blockID);
		world.setBlock(i + 9, j + 0, k + 16, MainRegistry.frostPlanks.blockID);
		world.setBlock(i + 9, j + 0, k + 17, MainRegistry.frostPlanks.blockID);
		world.setBlock(i + 9, j + 0, k + 18, MainRegistry.frostPlanks.blockID);
		world.setBlock(i + 9, j + 0, k + 19, MainRegistry.frostPlanks.blockID);
		world.setBlock(i + 9, j + 0, k + 20, MainRegistry.frostPlanks.blockID);
		world.setBlock(i + 9, j + 0, k + 21, Block.blockSnow.blockID);
		world.setBlock(i + 9, j + 1, k + 7, Block.blockSnow.blockID);
		world.setBlock(i + 9, j + 1, k + 8, 0);
		world.setBlock(i + 9, j + 1, k + 9, 0);
		world.setBlock(i + 9, j + 1, k + 10, 0);
		world.setBlock(i + 9, j + 1, k + 11, 0);
		world.setBlock(i + 9, j + 1, k + 12, 0);
		world.setBlock(i + 9, j + 1, k + 13, Block.stoneBrick.blockID);
		world.setBlock(i + 9, j + 1, k + 15, Block.stoneBrick.blockID);
		world.setBlock(i + 9, j + 1, k + 16, 0);
		world.setBlock(i + 9, j + 1, k + 17, 0);
		world.setBlock(i + 9, j + 1, k + 18, 0);
		world.setBlock(i + 9, j + 1, k + 19, 0);
		world.setBlock(i + 9, j + 1, k + 20, 0);
		world.setBlock(i + 9, j + 1, k + 21, Block.blockSnow.blockID);
		world.setBlock(i + 9, j + 2, k + 7, MainRegistry.unbreakableIce.blockID);
		world.setBlock(i + 9, j + 2, k + 8, 0);
		world.setBlock(i + 9, j + 2, k + 9, 0);
		world.setBlock(i + 9, j + 2, k + 10, 0);
		world.setBlock(i + 9, j + 2, k + 11, 0);
		world.setBlock(i + 9, j + 2, k + 12, 0);
		world.setBlock(i + 9, j + 2, k + 13, 0);
		world.setBlock(i + 9, j + 2, k + 14, MainRegistry.frostPlanks.blockID);
		world.setBlock(i + 9, j + 2, k + 15, 0);
		world.setBlock(i + 9, j + 2, k + 16, 0);
		world.setBlock(i + 9, j + 2, k + 17, 0);
		world.setBlock(i + 9, j + 2, k + 18, 0);
		world.setBlock(i + 9, j + 2, k + 19, 0);
		world.setBlock(i + 9, j + 2, k + 20, 0);
		world.setBlock(i + 9, j + 2, k + 21, MainRegistry.unbreakableIce.blockID);
		world.setBlock(i + 9, j + 3, k + 7, MainRegistry.unbreakableIce.blockID);
		world.setBlock(i + 9, j + 3, k + 14, Block.skull.blockID);
		world.setBlock(i + 9, j + 3, k + 21, MainRegistry.unbreakableIce.blockID);
		world.setBlock(i + 9, j + 4, k + 7, MainRegistry.unbreakableIce.blockID);
		world.setBlock(i + 9, j + 4, k + 21, MainRegistry.unbreakableIce.blockID);
		world.setBlock(i + 9, j + 5, k + 7, MainRegistry.unbreakableIce.blockID);
		world.setBlock(i + 9, j + 5, k + 21, MainRegistry.unbreakableIce.blockID);
		world.setBlock(i + 9, j + 6, k + 7, MainRegistry.unbreakableIce.blockID);
		world.setBlock(i + 9, j + 6, k + 21, MainRegistry.unbreakableIce.blockID);
		world.setBlock(i + 9, j + 7, k + 7, MainRegistry.unbreakableIce.blockID);
		world.setBlock(i + 9, j + 7, k + 21, MainRegistry.unbreakableIce.blockID);
		world.setBlock(i + 9, j + 8, k + 7, MainRegistry.unbreakableIce.blockID);
		world.setBlock(i + 9, j + 8, k + 21, MainRegistry.unbreakableIce.blockID);
		world.setBlock(i + 9, j + 9, k + 8, MainRegistry.unbreakableIce.blockID);
		world.setBlock(i + 9, j + 9, k + 20, MainRegistry.unbreakableIce.blockID);
		world.setBlock(i + 9, j + 10, k + 9, MainRegistry.unbreakableIce.blockID);
		world.setBlock(i + 9, j + 10, k + 19, MainRegistry.unbreakableIce.blockID);
		world.setBlock(i + 9, j + 11, k + 10, MainRegistry.unbreakableIce.blockID);
		world.setBlock(i + 9, j + 11, k + 18, MainRegistry.unbreakableIce.blockID);
		world.setBlock(i + 9, j + 12, k + 11, MainRegistry.unbreakableIce.blockID);
		world.setBlock(i + 9, j + 12, k + 12, MainRegistry.unbreakableIce.blockID);
		world.setBlock(i + 9, j + 12, k + 13, MainRegistry.unbreakableIce.blockID);
		world.setBlock(i + 9, j + 12, k + 14, MainRegistry.unbreakableIce.blockID);
		world.setBlock(i + 9, j + 12, k + 15, MainRegistry.unbreakableIce.blockID);
		world.setBlock(i + 9, j + 12, k + 16, MainRegistry.unbreakableIce.blockID);
		world.setBlock(i + 9, j + 12, k + 17, MainRegistry.unbreakableIce.blockID);
		world.setBlock(i + 10, j + 0, k + 6, Block.blockSnow.blockID);
		world.setBlock(i + 10, j + 0, k + 7, MainRegistry.frostPlanks.blockID);
		world.setBlock(i + 10, j + 0, k + 8, MainRegistry.frostPlanks.blockID);
		world.setBlock(i + 10, j + 0, k + 9, MainRegistry.frostPlanks.blockID);
		world.setBlock(i + 10, j + 0, k + 10, MainRegistry.frostPlanks.blockID);
		world.setBlock(i + 10, j + 0, k + 11, MainRegistry.frostPlanks.blockID);
		world.setBlock(i + 10, j + 0, k + 12, MainRegistry.frostPlanks.blockID);
		world.setBlock(i + 10, j + 0, k + 13, MainRegistry.frostPlanks.blockID);
		world.setBlock(i + 10, j + 0, k + 14, MainRegistry.frostPlanks.blockID);
		world.setBlock(i + 10, j + 0, k + 15, MainRegistry.frostPlanks.blockID);
		world.setBlock(i + 10, j + 0, k + 16, MainRegistry.frostPlanks.blockID);
		world.setBlock(i + 10, j + 0, k + 17, MainRegistry.frostPlanks.blockID);
		world.setBlock(i + 10, j + 0, k + 18, MainRegistry.frostPlanks.blockID);
		world.setBlock(i + 10, j + 0, k + 19, MainRegistry.frostPlanks.blockID);
		world.setBlock(i + 10, j + 0, k + 20, MainRegistry.frostPlanks.blockID);
		world.setBlock(i + 10, j + 0, k + 21, MainRegistry.frostPlanks.blockID);
		world.setBlock(i + 10, j + 0, k + 22, Block.blockSnow.blockID);
		world.setBlock(i + 10, j + 1, k + 6, Block.blockSnow.blockID);
		world.setBlock(i + 10, j + 1, k + 7, 0);
		world.setBlock(i + 10, j + 1, k + 8, 0);
		world.setBlock(i + 10, j + 1, k + 9, 0);
		world.setBlock(i + 10, j + 1, k + 10, 0);
		world.setBlock(i + 10, j + 1, k + 11, 0);
		world.setBlock(i + 10, j + 1, k + 12, 0);
		world.setBlock(i + 10, j + 1, k + 13, Block.stairsStoneBrick.blockID, 1, 3);
		world.setBlock(i + 10, j + 1, k + 14, Block.stairsStoneBrick.blockID, 1, 3);
		world.setBlock(i + 10, j + 1, k + 15, Block.stairsStoneBrick.blockID, 1, 3);
		world.setBlock(i + 10, j + 1, k + 16, 0);
		world.setBlock(i + 10, j + 1, k + 17, 0);
		world.setBlock(i + 10, j + 1, k + 18, 0);
		world.setBlock(i + 10, j + 1, k + 19, 0);
		world.setBlock(i + 10, j + 1, k + 20, 0);
		world.setBlock(i + 10, j + 1, k + 21, 0);
		world.setBlock(i + 10, j + 1, k + 22, Block.blockSnow.blockID);
		world.setBlock(i + 10, j + 2, k + 6, MainRegistry.unbreakableIce.blockID);
		world.setBlock(i + 10, j + 2, k + 7, 0);
		world.setBlock(i + 10, j + 2, k + 8, 0);
		world.setBlock(i + 10, j + 2, k + 9, 0);
		world.setBlock(i + 10, j + 2, k + 10, 0);
		world.setBlock(i + 10, j + 2, k + 11, 0);
		world.setBlock(i + 10, j + 2, k + 12, 0);
		world.setBlock(i + 10, j + 2, k + 13, 0);
		world.setBlock(i + 10, j + 2, k + 14, 0);
		world.setBlock(i + 10, j + 2, k + 15, 0);
		world.setBlock(i + 10, j + 2, k + 16, 0);
		world.setBlock(i + 10, j + 2, k + 17, 0);
		world.setBlock(i + 10, j + 2, k + 18, 0);
		world.setBlock(i + 10, j + 2, k + 19, 0);
		world.setBlock(i + 10, j + 2, k + 20, 0);
		world.setBlock(i + 10, j + 2, k + 21, 0);
		world.setBlock(i + 10, j + 2, k + 22, MainRegistry.unbreakableIce.blockID);
		world.setBlock(i + 10, j + 3, k + 6, MainRegistry.unbreakableIce.blockID);
		world.setBlock(i + 10, j + 3, k + 22, MainRegistry.unbreakableIce.blockID);
		world.setBlock(i + 10, j + 4, k + 6, MainRegistry.unbreakableIce.blockID);
		world.setBlock(i + 10, j + 4, k + 22, MainRegistry.unbreakableIce.blockID);
		world.setBlock(i + 10, j + 5, k + 6, MainRegistry.unbreakableIce.blockID);
		world.setBlock(i + 10, j + 5, k + 22, MainRegistry.unbreakableIce.blockID);
		world.setBlock(i + 10, j + 6, k + 6, MainRegistry.unbreakableIce.blockID);
		world.setBlock(i + 10, j + 6, k + 22, MainRegistry.unbreakableIce.blockID);
		world.setBlock(i + 10, j + 7, k + 6, MainRegistry.unbreakableIce.blockID);
		world.setBlock(i + 10, j + 7, k + 22, MainRegistry.unbreakableIce.blockID);
		world.setBlock(i + 10, j + 8, k + 6, MainRegistry.unbreakableIce.blockID);
		world.setBlock(i + 10, j + 8, k + 22, MainRegistry.unbreakableIce.blockID);
		world.setBlock(i + 10, j + 9, k + 7, MainRegistry.unbreakableIce.blockID);
		world.setBlock(i + 10, j + 9, k + 21, MainRegistry.unbreakableIce.blockID);
		world.setBlock(i + 10, j + 10, k + 8, MainRegistry.unbreakableIce.blockID);
		world.setBlock(i + 10, j + 10, k + 20, MainRegistry.unbreakableIce.blockID);
		world.setBlock(i + 10, j + 11, k + 9, MainRegistry.unbreakableIce.blockID);
		world.setBlock(i + 10, j + 11, k + 19, MainRegistry.unbreakableIce.blockID);
		world.setBlock(i + 10, j + 12, k + 10, MainRegistry.unbreakableIce.blockID);
		world.setBlock(i + 10, j + 12, k + 11, MainRegistry.unbreakableIce.blockID);
		world.setBlock(i + 10, j + 12, k + 12, MainRegistry.unbreakableIce.blockID);
		world.setBlock(i + 10, j + 12, k + 13, MainRegistry.unbreakableIce.blockID);
		world.setBlock(i + 10, j + 12, k + 14, MainRegistry.unbreakableIce.blockID);
		world.setBlock(i + 10, j + 12, k + 15, MainRegistry.unbreakableIce.blockID);
		world.setBlock(i + 10, j + 12, k + 16, MainRegistry.unbreakableIce.blockID);
		world.setBlock(i + 10, j + 12, k + 17, MainRegistry.unbreakableIce.blockID);
		world.setBlock(i + 10, j + 12, k + 18, MainRegistry.unbreakableIce.blockID);
		world.setBlock(i + 11, j + 0, k + 6, Block.blockSnow.blockID);
		world.setBlock(i + 11, j + 0, k + 7, MainRegistry.frostPlanks.blockID);
		world.setBlock(i + 11, j + 0, k + 8, MainRegistry.frostPlanks.blockID);
		world.setBlock(i + 11, j + 0, k + 9, MainRegistry.frostPlanks.blockID);
		world.setBlock(i + 11, j + 0, k + 10, MainRegistry.frostPlanks.blockID);
		world.setBlock(i + 11, j + 0, k + 11, MainRegistry.frostPlanks.blockID);
		world.setBlock(i + 11, j + 0, k + 12, MainRegistry.frostPlanks.blockID);
		world.setBlock(i + 11, j + 0, k + 13, MainRegistry.frostPlanks.blockID);
		world.setBlock(i + 11, j + 0, k + 14, MainRegistry.frostPlanks.blockID);
		world.setBlock(i + 11, j + 0, k + 15, MainRegistry.frostPlanks.blockID);
		world.setBlock(i + 11, j + 0, k + 16, MainRegistry.frostPlanks.blockID);
		world.setBlock(i + 11, j + 0, k + 17, MainRegistry.frostPlanks.blockID);
		world.setBlock(i + 11, j + 0, k + 18, MainRegistry.frostPlanks.blockID);
		world.setBlock(i + 11, j + 0, k + 19, MainRegistry.frostPlanks.blockID);
		world.setBlock(i + 11, j + 0, k + 20, MainRegistry.frostPlanks.blockID);
		world.setBlock(i + 11, j + 0, k + 21, MainRegistry.frostPlanks.blockID);
		world.setBlock(i + 11, j + 0, k + 22, Block.blockSnow.blockID);
		world.setBlock(i + 11, j + 1, k + 6, Block.blockSnow.blockID);
		world.setBlock(i + 11, j + 1, k + 7, 0);
		world.setBlock(i + 11, j + 1, k + 8, 0);
		world.setBlock(i + 11, j + 1, k + 9, 0);
		world.setBlock(i + 11, j + 1, k + 10, 0);
		world.setBlock(i + 11, j + 1, k + 11, 0);
		world.setBlock(i + 11, j + 1, k + 12, 0);
		world.setBlock(i + 11, j + 1, k + 13, 0);
		world.setBlock(i + 11, j + 1, k + 14, 0);
		world.setBlock(i + 11, j + 1, k + 15, 0);
		world.setBlock(i + 11, j + 1, k + 16, 0);
		world.setBlock(i + 11, j + 1, k + 17, 0);
		world.setBlock(i + 11, j + 1, k + 18, 0);
		world.setBlock(i + 11, j + 1, k + 19, 0);
		world.setBlock(i + 11, j + 1, k + 20, 0);
		world.setBlock(i + 11, j + 1, k + 21, 0);
		world.setBlock(i + 11, j + 1, k + 22, Block.blockSnow.blockID);
		world.setBlock(i + 11, j + 2, k + 6, MainRegistry.unbreakableIce.blockID);
		world.setBlock(i + 11, j + 2, k + 7, 0);
		world.setBlock(i + 11, j + 2, k + 8, 0);
		world.setBlock(i + 11, j + 2, k + 9, 0);
		world.setBlock(i + 11, j + 2, k + 10, 0);
		world.setBlock(i + 11, j + 2, k + 11, 0);
		world.setBlock(i + 11, j + 2, k + 12, 0);
		world.setBlock(i + 11, j + 2, k + 13, 0);
		world.setBlock(i + 11, j + 2, k + 14, 0);
		world.setBlock(i + 11, j + 2, k + 15, 0);
		world.setBlock(i + 11, j + 2, k + 16, 0);
		world.setBlock(i + 11, j + 2, k + 17, 0);
		world.setBlock(i + 11, j + 2, k + 18, 0);
		world.setBlock(i + 11, j + 2, k + 19, 0);
		world.setBlock(i + 11, j + 2, k + 20, 0);
		world.setBlock(i + 11, j + 2, k + 21, 0);
		world.setBlock(i + 11, j + 2, k + 22, MainRegistry.unbreakableIce.blockID);
		world.setBlock(i + 11, j + 3, k + 6, MainRegistry.unbreakableIce.blockID);
		world.setBlock(i + 11, j + 3, k + 22, MainRegistry.unbreakableIce.blockID);
		world.setBlock(i + 11, j + 4, k + 6, MainRegistry.unbreakableIce.blockID);
		world.setBlock(i + 11, j + 4, k + 22, MainRegistry.unbreakableIce.blockID);
		world.setBlock(i + 11, j + 5, k + 6, MainRegistry.unbreakableIce.blockID);
		world.setBlock(i + 11, j + 5, k + 22, MainRegistry.unbreakableIce.blockID);
		world.setBlock(i + 11, j + 6, k + 6, MainRegistry.unbreakableIce.blockID);
		world.setBlock(i + 11, j + 6, k + 22, MainRegistry.unbreakableIce.blockID);
		world.setBlock(i + 11, j + 7, k + 6, MainRegistry.unbreakableIce.blockID);
		world.setBlock(i + 11, j + 7, k + 22, MainRegistry.unbreakableIce.blockID);
		world.setBlock(i + 11, j + 8, k + 6, MainRegistry.unbreakableIce.blockID);
		world.setBlock(i + 11, j + 8, k + 22, MainRegistry.unbreakableIce.blockID);
		world.setBlock(i + 11, j + 9, k + 7, MainRegistry.unbreakableIce.blockID);
		world.setBlock(i + 11, j + 9, k + 21, MainRegistry.unbreakableIce.blockID);
		world.setBlock(i + 11, j + 10, k + 8, MainRegistry.unbreakableIce.blockID);
		world.setBlock(i + 11, j + 10, k + 20, MainRegistry.unbreakableIce.blockID);
		world.setBlock(i + 11, j + 11, k + 9, MainRegistry.unbreakableIce.blockID);
		world.setBlock(i + 11, j + 11, k + 19, MainRegistry.unbreakableIce.blockID);
		world.setBlock(i + 11, j + 12, k + 10, MainRegistry.unbreakableIce.blockID);
		world.setBlock(i + 11, j + 12, k + 11, MainRegistry.unbreakableIce.blockID);
		world.setBlock(i + 11, j + 12, k + 12, MainRegistry.unbreakableIce.blockID);
		world.setBlock(i + 11, j + 12, k + 13, MainRegistry.unbreakableIce.blockID);
		world.setBlock(i + 11, j + 12, k + 14, MainRegistry.unbreakableIce.blockID);
		world.setBlock(i + 11, j + 12, k + 15, MainRegistry.unbreakableIce.blockID);
		world.setBlock(i + 11, j + 12, k + 16, MainRegistry.unbreakableIce.blockID);
		world.setBlock(i + 11, j + 12, k + 17, MainRegistry.unbreakableIce.blockID);
		world.setBlock(i + 11, j + 12, k + 18, MainRegistry.unbreakableIce.blockID);
		world.setBlock(i + 12, j + 0, k + 6, Block.blockSnow.blockID);
		world.setBlock(i + 12, j + 0, k + 7, MainRegistry.frostPlanks.blockID);
		world.setBlock(i + 12, j + 0, k + 8, MainRegistry.frostPlanks.blockID);
		world.setBlock(i + 12, j + 0, k + 9, MainRegistry.frostPlanks.blockID);
		world.setBlock(i + 12, j + 0, k + 10, MainRegistry.frostPlanks.blockID);
		world.setBlock(i + 12, j + 0, k + 11, MainRegistry.frostPlanks.blockID);
		world.setBlock(i + 12, j + 0, k + 12, MainRegistry.frostPlanks.blockID);
		world.setBlock(i + 12, j + 0, k + 13, MainRegistry.frostPlanks.blockID);
		world.setBlock(i + 12, j + 0, k + 14, MainRegistry.frostPlanks.blockID);
		world.setBlock(i + 12, j + 0, k + 15, MainRegistry.frostPlanks.blockID);
		world.setBlock(i + 12, j + 0, k + 16, MainRegistry.frostPlanks.blockID);
		world.setBlock(i + 12, j + 0, k + 17, MainRegistry.frostPlanks.blockID);
		world.setBlock(i + 12, j + 0, k + 18, MainRegistry.frostPlanks.blockID);
		world.setBlock(i + 12, j + 0, k + 19, MainRegistry.frostPlanks.blockID);
		world.setBlock(i + 12, j + 0, k + 20, MainRegistry.frostPlanks.blockID);
		world.setBlock(i + 12, j + 0, k + 21, MainRegistry.frostPlanks.blockID);
		world.setBlock(i + 12, j + 0, k + 22, Block.blockSnow.blockID);
		world.setBlock(i + 12, j + 1, k + 6, Block.blockSnow.blockID);
		world.setBlock(i + 12, j + 1, k + 7, 0);
		world.setBlock(i + 12, j + 1, k + 8, 0);
		world.setBlock(i + 12, j + 1, k + 9, 0);
		world.setBlock(i + 12, j + 1, k + 10, 0);
		world.setBlock(i + 12, j + 1, k + 11, 0);
		world.setBlock(i + 12, j + 1, k + 12, 0);
		world.setBlock(i + 12, j + 1, k + 13, 0);
		world.setBlock(i + 12, j + 1, k + 14, 0);
		world.setBlock(i + 12, j + 1, k + 15, 0);
		world.setBlock(i + 12, j + 1, k + 16, 0);
		world.setBlock(i + 12, j + 1, k + 17, 0);
		world.setBlock(i + 12, j + 1, k + 18, 0);
		world.setBlock(i + 12, j + 1, k + 19, 0);
		world.setBlock(i + 12, j + 1, k + 20, 0);
		world.setBlock(i + 12, j + 1, k + 21, 0);
		world.setBlock(i + 12, j + 1, k + 22, Block.blockSnow.blockID);
		world.setBlock(i + 12, j + 2, k + 6, MainRegistry.unbreakableIce.blockID);
		world.setBlock(i + 12, j + 2, k + 7, 0);
		world.setBlock(i + 12, j + 2, k + 8, 0);
		world.setBlock(i + 12, j + 2, k + 9, 0);
		world.setBlock(i + 12, j + 2, k + 10, 0);
		world.setBlock(i + 12, j + 2, k + 11, 0);
		world.setBlock(i + 12, j + 2, k + 12, 0);
		world.setBlock(i + 12, j + 2, k + 13, 0);
		world.setBlock(i + 12, j + 2, k + 14, 0);
		world.setBlock(i + 12, j + 2, k + 15, 0);
		world.setBlock(i + 12, j + 2, k + 16, 0);
		world.setBlock(i + 12, j + 2, k + 17, 0);
		world.setBlock(i + 12, j + 2, k + 18, 0);
		world.setBlock(i + 12, j + 2, k + 19, 0);
		world.setBlock(i + 12, j + 2, k + 20, 0);
		world.setBlock(i + 12, j + 2, k + 21, 0);
		world.setBlock(i + 12, j + 2, k + 22, MainRegistry.unbreakableIce.blockID);
		world.setBlock(i + 12, j + 3, k + 6, MainRegistry.unbreakableIce.blockID);
		world.setBlock(i + 12, j + 3, k + 22, MainRegistry.unbreakableIce.blockID);
		world.setBlock(i + 12, j + 4, k + 6, MainRegistry.unbreakableIce.blockID);
		world.setBlock(i + 12, j + 4, k + 22, MainRegistry.unbreakableIce.blockID);
		world.setBlock(i + 12, j + 5, k + 6, MainRegistry.unbreakableIce.blockID);
		world.setBlock(i + 12, j + 5, k + 22, MainRegistry.unbreakableIce.blockID);
		world.setBlock(i + 12, j + 6, k + 6, MainRegistry.unbreakableIce.blockID);
		world.setBlock(i + 12, j + 6, k + 22, MainRegistry.unbreakableIce.blockID);
		world.setBlock(i + 12, j + 7, k + 6, MainRegistry.unbreakableIce.blockID);
		world.setBlock(i + 12, j + 7, k + 22, MainRegistry.unbreakableIce.blockID);
		world.setBlock(i + 12, j + 8, k + 6, MainRegistry.unbreakableIce.blockID);
		world.setBlock(i + 12, j + 8, k + 22, MainRegistry.unbreakableIce.blockID);
		world.setBlock(i + 12, j + 9, k + 7, MainRegistry.unbreakableIce.blockID);
		world.setBlock(i + 12, j + 9, k + 21, MainRegistry.unbreakableIce.blockID);
		world.setBlock(i + 12, j + 10, k + 8, MainRegistry.unbreakableIce.blockID);
		world.setBlock(i + 12, j + 10, k + 20, MainRegistry.unbreakableIce.blockID);
		world.setBlock(i + 12, j + 11, k + 9, MainRegistry.unbreakableIce.blockID);
		world.setBlock(i + 12, j + 11, k + 19, MainRegistry.unbreakableIce.blockID);
		world.setBlock(i + 12, j + 12, k + 10, MainRegistry.unbreakableIce.blockID);
		world.setBlock(i + 12, j + 12, k + 11, MainRegistry.unbreakableIce.blockID);
		world.setBlock(i + 12, j + 12, k + 12, MainRegistry.unbreakableIce.blockID);
		world.setBlock(i + 12, j + 12, k + 13, MainRegistry.unbreakableIce.blockID);
		world.setBlock(i + 12, j + 12, k + 14, MainRegistry.unbreakableIce.blockID);
		world.setBlock(i + 12, j + 12, k + 15, MainRegistry.unbreakableIce.blockID);
		world.setBlock(i + 12, j + 12, k + 16, MainRegistry.unbreakableIce.blockID);
		world.setBlock(i + 12, j + 12, k + 17, MainRegistry.unbreakableIce.blockID);
		world.setBlock(i + 12, j + 12, k + 18, MainRegistry.unbreakableIce.blockID);
		world.setBlock(i + 13, j + 0, k + 6, Block.blockSnow.blockID);
		world.setBlock(i + 13, j + 0, k + 7, MainRegistry.frostPlanks.blockID);
		world.setBlock(i + 13, j + 0, k + 8, MainRegistry.frostPlanks.blockID);
		world.setBlock(i + 13, j + 0, k + 9, MainRegistry.frostPlanks.blockID);
		world.setBlock(i + 13, j + 0, k + 10, MainRegistry.frostPlanks.blockID);
		world.setBlock(i + 13, j + 0, k + 11, MainRegistry.frostPlanks.blockID);
		world.setBlock(i + 13, j + 0, k + 12, MainRegistry.frostPlanks.blockID);
		world.setBlock(i + 13, j + 0, k + 13, MainRegistry.frostPlanks.blockID);
		world.setBlock(i + 13, j + 0, k + 14, MainRegistry.frostPlanks.blockID);
		world.setBlock(i + 13, j + 0, k + 15, MainRegistry.frostPlanks.blockID);
		world.setBlock(i + 13, j + 0, k + 16, MainRegistry.frostPlanks.blockID);
		world.setBlock(i + 13, j + 0, k + 17, MainRegistry.frostPlanks.blockID);
		world.setBlock(i + 13, j + 0, k + 18, MainRegistry.frostPlanks.blockID);
		world.setBlock(i + 13, j + 0, k + 19, MainRegistry.frostPlanks.blockID);
		world.setBlock(i + 13, j + 0, k + 20, MainRegistry.frostPlanks.blockID);
		world.setBlock(i + 13, j + 0, k + 21, MainRegistry.frostPlanks.blockID);
		world.setBlock(i + 13, j + 0, k + 22, Block.blockSnow.blockID);
		world.setBlock(i + 13, j + 1, k + 6, Block.blockSnow.blockID);
		world.setBlock(i + 13, j + 1, k + 7, 0);
		world.setBlock(i + 13, j + 1, k + 8, 0);
		world.setBlock(i + 13, j + 1, k + 9, 0);
		world.setBlock(i + 13, j + 1, k + 10, 0);
		world.setBlock(i + 13, j + 1, k + 11, MainRegistry.frostStairs.blockID);
		world.setBlock(i + 13, j + 1, k + 12, MainRegistry.frostStairs.blockID);
		world.setBlock(i + 13, j + 1, k + 13, 0);
		world.setBlock(i + 13, j + 1, k + 14, 0);
		world.setBlock(i + 13, j + 1, k + 15, 0);
		world.setBlock(i + 13, j + 1, k + 16, MainRegistry.frostStairs.blockID);
		world.setBlock(i + 13, j + 1, k + 17, MainRegistry.frostStairs.blockID);
		world.setBlock(i + 13, j + 1, k + 18, 0);
		world.setBlock(i + 13, j + 1, k + 19, 0);
		world.setBlock(i + 13, j + 1, k + 20, 0);
		world.setBlock(i + 13, j + 1, k + 21, 0);
		world.setBlock(i + 13, j + 1, k + 22, Block.blockSnow.blockID);
		world.setBlock(i + 13, j + 2, k + 6, MainRegistry.unbreakableIce.blockID);
		world.setBlock(i + 13, j + 2, k + 7, 0);
		world.setBlock(i + 13, j + 2, k + 8, 0);
		world.setBlock(i + 13, j + 2, k + 9, 0);
		world.setBlock(i + 13, j + 2, k + 10, 0);
		world.setBlock(i + 13, j + 2, k + 11, 0);
		world.setBlock(i + 13, j + 2, k + 12, 0);
		world.setBlock(i + 13, j + 2, k + 13, 0);
		world.setBlock(i + 13, j + 2, k + 14, 0);
		world.setBlock(i + 13, j + 2, k + 15, 0);
		world.setBlock(i + 13, j + 2, k + 16, 0);
		world.setBlock(i + 13, j + 2, k + 17, 0);
		world.setBlock(i + 13, j + 2, k + 18, 0);
		world.setBlock(i + 13, j + 2, k + 19, 0);
		world.setBlock(i + 13, j + 2, k + 20, 0);
		world.setBlock(i + 13, j + 2, k + 21, 0);
		world.setBlock(i + 13, j + 2, k + 22, MainRegistry.unbreakableIce.blockID);
		world.setBlock(i + 13, j + 3, k + 6, MainRegistry.unbreakableIce.blockID);
		world.setBlock(i + 13, j + 3, k + 22, MainRegistry.unbreakableIce.blockID);
		world.setBlock(i + 13, j + 4, k + 6, MainRegistry.unbreakableIce.blockID);
		world.setBlock(i + 13, j + 4, k + 22, MainRegistry.unbreakableIce.blockID);
		world.setBlock(i + 13, j + 5, k + 6, MainRegistry.unbreakableIce.blockID);
		world.setBlock(i + 13, j + 5, k + 22, MainRegistry.unbreakableIce.blockID);
		world.setBlock(i + 13, j + 6, k + 6, MainRegistry.unbreakableIce.blockID);
		world.setBlock(i + 13, j + 6, k + 22, MainRegistry.unbreakableIce.blockID);
		world.setBlock(i + 13, j + 7, k + 6, MainRegistry.unbreakableIce.blockID);
		world.setBlock(i + 13, j + 7, k + 22, MainRegistry.unbreakableIce.blockID);
		world.setBlock(i + 13, j + 8, k + 6, MainRegistry.unbreakableIce.blockID);
		world.setBlock(i + 13, j + 8, k + 22, MainRegistry.unbreakableIce.blockID);
		world.setBlock(i + 13, j + 9, k + 7, MainRegistry.unbreakableIce.blockID);
		world.setBlock(i + 13, j + 9, k + 21, MainRegistry.unbreakableIce.blockID);
		world.setBlock(i + 13, j + 10, k + 8, MainRegistry.unbreakableIce.blockID);
		world.setBlock(i + 13, j + 10, k + 20, MainRegistry.unbreakableIce.blockID);
		world.setBlock(i + 13, j + 11, k + 9, MainRegistry.unbreakableIce.blockID);
		world.setBlock(i + 13, j + 11, k + 19, MainRegistry.unbreakableIce.blockID);
		world.setBlock(i + 13, j + 12, k + 10, MainRegistry.unbreakableIce.blockID);
		world.setBlock(i + 13, j + 12, k + 11, MainRegistry.unbreakableIce.blockID);
		world.setBlock(i + 13, j + 12, k + 12, MainRegistry.unbreakableIce.blockID);
		world.setBlock(i + 13, j + 12, k + 13, MainRegistry.unbreakableIce.blockID);
		world.setBlock(i + 13, j + 12, k + 14, MainRegistry.unbreakableIce.blockID);
		world.setBlock(i + 13, j + 12, k + 15, MainRegistry.unbreakableIce.blockID);
		world.setBlock(i + 13, j + 12, k + 16, MainRegistry.unbreakableIce.blockID);
		world.setBlock(i + 13, j + 12, k + 17, MainRegistry.unbreakableIce.blockID);
		world.setBlock(i + 13, j + 12, k + 18, MainRegistry.unbreakableIce.blockID);
		world.setBlock(i + 14, j + 0, k + 6, Block.blockSnow.blockID);
		world.setBlock(i + 14, j + 0, k + 7, MainRegistry.frostPlanks.blockID);
		world.setBlock(i + 14, j + 0, k + 8, MainRegistry.frostPlanks.blockID);
		world.setBlock(i + 14, j + 0, k + 9, MainRegistry.frostPlanks.blockID);
		world.setBlock(i + 14, j + 0, k + 10, MainRegistry.frostPlanks.blockID);
		world.setBlock(i + 14, j + 0, k + 11, MainRegistry.frostPlanks.blockID);
		world.setBlock(i + 14, j + 0, k + 12, MainRegistry.frostPlanks.blockID);
		world.setBlock(i + 14, j + 0, k + 13, MainRegistry.frostPlanks.blockID);
		world.setBlock(i + 14, j + 0, k + 14, MainRegistry.frostPlanks.blockID);
		world.setBlock(i + 14, j + 0, k + 15, MainRegistry.frostPlanks.blockID);
		world.setBlock(i + 14, j + 0, k + 16, MainRegistry.frostPlanks.blockID);
		world.setBlock(i + 14, j + 0, k + 17, MainRegistry.frostPlanks.blockID);
		world.setBlock(i + 14, j + 0, k + 18, MainRegistry.frostPlanks.blockID);
		world.setBlock(i + 14, j + 0, k + 19, MainRegistry.frostPlanks.blockID);
		world.setBlock(i + 14, j + 0, k + 20, MainRegistry.frostPlanks.blockID);
		world.setBlock(i + 14, j + 0, k + 21, MainRegistry.frostPlanks.blockID);
		world.setBlock(i + 14, j + 0, k + 22, Block.blockSnow.blockID);
		world.setBlock(i + 14, j + 1, k + 6, Block.blockSnow.blockID);
		world.setBlock(i + 14, j + 1, k + 7, 0);
		world.setBlock(i + 14, j + 1, k + 8, 0);
		world.setBlock(i + 14, j + 1, k + 9, 0);
		world.setBlock(i + 14, j + 1, k + 10, 0);
		world.setBlock(i + 14, j + 1, k + 11, 0);
		world.setBlock(i + 14, j + 1, k + 12, 0);
		world.setBlock(i + 14, j + 1, k + 13, 0);
		world.setBlock(i + 14, j + 1, k + 14, 0);
		world.setBlock(i + 14, j + 1, k + 15, 0);
		world.setBlock(i + 14, j + 1, k + 16, 0);
		world.setBlock(i + 14, j + 1, k + 17, 0);
		world.setBlock(i + 14, j + 1, k + 18, 0);
		world.setBlock(i + 14, j + 1, k + 19, 0);
		world.setBlock(i + 14, j + 1, k + 20, 0);
		world.setBlock(i + 14, j + 1, k + 21, 0);
		world.setBlock(i + 14, j + 1, k + 22, Block.blockSnow.blockID);
		world.setBlock(i + 14, j + 2, k + 6, MainRegistry.unbreakableIce.blockID);
		world.setBlock(i + 14, j + 2, k + 7, 0);
		world.setBlock(i + 14, j + 2, k + 8, 0);
		world.setBlock(i + 14, j + 2, k + 9, 0);
		world.setBlock(i + 14, j + 2, k + 10, 0);
		world.setBlock(i + 14, j + 2, k + 11, 0);
		world.setBlock(i + 14, j + 2, k + 12, 0);
		world.setBlock(i + 14, j + 2, k + 13, 0);
		world.setBlock(i + 14, j + 2, k + 14, 0);
		world.setBlock(i + 14, j + 2, k + 15, 0);
		world.setBlock(i + 14, j + 2, k + 16, 0);
		world.setBlock(i + 14, j + 2, k + 17, 0);
		world.setBlock(i + 14, j + 2, k + 18, 0);
		world.setBlock(i + 14, j + 2, k + 19, 0);
		world.setBlock(i + 14, j + 2, k + 20, 0);
		world.setBlock(i + 14, j + 2, k + 21, 0);
		world.setBlock(i + 14, j + 2, k + 22, MainRegistry.unbreakableIce.blockID);
		world.setBlock(i + 14, j + 3, k + 6, MainRegistry.unbreakableIce.blockID);
		world.setBlock(i + 14, j + 3, k + 22, MainRegistry.unbreakableIce.blockID);
		world.setBlock(i + 14, j + 4, k + 6, MainRegistry.unbreakableIce.blockID);
		world.setBlock(i + 14, j + 4, k + 22, MainRegistry.unbreakableIce.blockID);
		world.setBlock(i + 14, j + 5, k + 6, MainRegistry.unbreakableIce.blockID);
		world.setBlock(i + 14, j + 5, k + 22, MainRegistry.unbreakableIce.blockID);
		world.setBlock(i + 14, j + 6, k + 6, MainRegistry.unbreakableIce.blockID);
		world.setBlock(i + 14, j + 6, k + 22, MainRegistry.unbreakableIce.blockID);
		world.setBlock(i + 14, j + 7, k + 6, MainRegistry.unbreakableIce.blockID);
		world.setBlock(i + 14, j + 7, k + 22, MainRegistry.unbreakableIce.blockID);
		world.setBlock(i + 14, j + 8, k + 6, MainRegistry.unbreakableIce.blockID);
		world.setBlock(i + 14, j + 8, k + 22, MainRegistry.unbreakableIce.blockID);
		world.setBlock(i + 14, j + 9, k + 7, MainRegistry.unbreakableIce.blockID);
		world.setBlock(i + 14, j + 9, k + 21, MainRegistry.unbreakableIce.blockID);
		world.setBlock(i + 14, j + 10, k + 8, MainRegistry.unbreakableIce.blockID);
		world.setBlock(i + 14, j + 10, k + 20, MainRegistry.unbreakableIce.blockID);
		world.setBlock(i + 14, j + 11, k + 9, MainRegistry.unbreakableIce.blockID);
		world.setBlock(i + 14, j + 11, k + 19, MainRegistry.unbreakableIce.blockID);
		world.setBlock(i + 14, j + 12, k + 10, MainRegistry.unbreakableIce.blockID);
		world.setBlock(i + 14, j + 12, k + 11, MainRegistry.unbreakableIce.blockID);
		world.setBlock(i + 14, j + 12, k + 12, MainRegistry.unbreakableIce.blockID);
		world.setBlock(i + 14, j + 12, k + 13, MainRegistry.unbreakableIce.blockID);
		world.setBlock(i + 14, j + 12, k + 14, MainRegistry.unbreakableIce.blockID);
		world.setBlock(i + 14, j + 12, k + 15, MainRegistry.unbreakableIce.blockID);
		world.setBlock(i + 14, j + 12, k + 16, MainRegistry.unbreakableIce.blockID);
		world.setBlock(i + 14, j + 12, k + 17, MainRegistry.unbreakableIce.blockID);
		world.setBlock(i + 14, j + 12, k + 18, MainRegistry.unbreakableIce.blockID);
		world.setBlock(i + 15, j + 0, k + 7, Block.blockSnow.blockID);
		world.setBlock(i + 15, j + 0, k + 8, MainRegistry.frostPlanks.blockID);
		world.setBlock(i + 15, j + 0, k + 9, MainRegistry.frostPlanks.blockID);
		world.setBlock(i + 15, j + 0, k + 10, MainRegistry.frostPlanks.blockID);
		world.setBlock(i + 15, j + 0, k + 11, MainRegistry.frostPlanks.blockID);
		world.setBlock(i + 15, j + 0, k + 12, MainRegistry.frostPlanks.blockID);
		world.setBlock(i + 15, j + 0, k + 13, MainRegistry.frostPlanks.blockID);
		world.setBlock(i + 15, j + 0, k + 14, MainRegistry.frostPlanks.blockID);
		world.setBlock(i + 15, j + 0, k + 15, MainRegistry.frostPlanks.blockID);
		world.setBlock(i + 15, j + 0, k + 16, MainRegistry.frostPlanks.blockID);
		world.setBlock(i + 15, j + 0, k + 17, MainRegistry.frostPlanks.blockID);
		world.setBlock(i + 15, j + 0, k + 18, MainRegistry.frostPlanks.blockID);
		world.setBlock(i + 15, j + 0, k + 19, MainRegistry.frostPlanks.blockID);
		world.setBlock(i + 15, j + 0, k + 20, MainRegistry.frostPlanks.blockID);
		world.setBlock(i + 15, j + 0, k + 21, Block.blockSnow.blockID);
		world.setBlock(i + 15, j + 1, k + 7, Block.blockSnow.blockID);
		world.setBlock(i + 15, j + 1, k + 8, 0);
		world.setBlock(i + 15, j + 1, k + 9, 0);
		world.setBlock(i + 15, j + 1, k + 10, 0);
		world.setBlock(i + 15, j + 1, k + 11, MainRegistry.frostStairs.blockID);
		world.setBlock(i + 15, j + 1, k + 12, MainRegistry.frostStairs.blockID);
		world.setBlock(i + 15, j + 1, k + 13, 0);
		world.setBlock(i + 15, j + 1, k + 14, 0);
		world.setBlock(i + 15, j + 1, k + 15, 0);
		world.setBlock(i + 15, j + 1, k + 16, MainRegistry.frostStairs.blockID);
		world.setBlock(i + 15, j + 1, k + 17, MainRegistry.frostStairs.blockID);
		world.setBlock(i + 15, j + 1, k + 18, 0);
		world.setBlock(i + 15, j + 1, k + 19, 0);
		world.setBlock(i + 15, j + 1, k + 20, 0);
		world.setBlock(i + 15, j + 1, k + 21, Block.blockSnow.blockID);
		world.setBlock(i + 15, j + 2, k + 7, MainRegistry.unbreakableIce.blockID);
		world.setBlock(i + 15, j + 2, k + 8, 0);
		world.setBlock(i + 15, j + 2, k + 9, 0);
		world.setBlock(i + 15, j + 2, k + 10, 0);
		world.setBlock(i + 15, j + 2, k + 11, 0);
		world.setBlock(i + 15, j + 2, k + 12, 0);
		world.setBlock(i + 15, j + 2, k + 13, 0);
		world.setBlock(i + 15, j + 2, k + 14, 0);
		world.setBlock(i + 15, j + 2, k + 15, 0);
		world.setBlock(i + 15, j + 2, k + 16, 0);
		world.setBlock(i + 15, j + 2, k + 17, 0);
		world.setBlock(i + 15, j + 2, k + 18, 0);
		world.setBlock(i + 15, j + 2, k + 19, 0);
		world.setBlock(i + 15, j + 2, k + 20, 0);
		world.setBlock(i + 15, j + 2, k + 21, MainRegistry.unbreakableIce.blockID);
		world.setBlock(i + 15, j + 3, k + 7, MainRegistry.unbreakableIce.blockID);
		world.setBlock(i + 15, j + 3, k + 21, MainRegistry.unbreakableIce.blockID);
		world.setBlock(i + 15, j + 4, k + 7, MainRegistry.unbreakableIce.blockID);
		world.setBlock(i + 15, j + 4, k + 21, MainRegistry.unbreakableIce.blockID);
		world.setBlock(i + 15, j + 5, k + 7, MainRegistry.unbreakableIce.blockID);
		world.setBlock(i + 15, j + 5, k + 21, MainRegistry.unbreakableIce.blockID);
		world.setBlock(i + 15, j + 6, k + 7, MainRegistry.unbreakableIce.blockID);
		world.setBlock(i + 15, j + 6, k + 21, MainRegistry.unbreakableIce.blockID);
		world.setBlock(i + 15, j + 7, k + 7, MainRegistry.unbreakableIce.blockID);
		world.setBlock(i + 15, j + 7, k + 21, MainRegistry.unbreakableIce.blockID);
		world.setBlock(i + 15, j + 8, k + 7, MainRegistry.unbreakableIce.blockID);
		world.setBlock(i + 15, j + 8, k + 21, MainRegistry.unbreakableIce.blockID);
		world.setBlock(i + 15, j + 9, k + 8, MainRegistry.unbreakableIce.blockID);
		world.setBlock(i + 15, j + 9, k + 20, MainRegistry.unbreakableIce.blockID);
		world.setBlock(i + 15, j + 10, k + 9, MainRegistry.unbreakableIce.blockID);
		world.setBlock(i + 15, j + 10, k + 19, MainRegistry.unbreakableIce.blockID);
		world.setBlock(i + 15, j + 11, k + 10, MainRegistry.unbreakableIce.blockID);
		world.setBlock(i + 15, j + 11, k + 18, MainRegistry.unbreakableIce.blockID);
		world.setBlock(i + 15, j + 12, k + 11, MainRegistry.unbreakableIce.blockID);
		world.setBlock(i + 15, j + 12, k + 12, MainRegistry.unbreakableIce.blockID);
		world.setBlock(i + 15, j + 12, k + 13, MainRegistry.unbreakableIce.blockID);
		world.setBlock(i + 15, j + 12, k + 14, MainRegistry.unbreakableIce.blockID);
		world.setBlock(i + 15, j + 12, k + 15, MainRegistry.unbreakableIce.blockID);
		world.setBlock(i + 15, j + 12, k + 16, MainRegistry.unbreakableIce.blockID);
		world.setBlock(i + 15, j + 12, k + 17, MainRegistry.unbreakableIce.blockID);
		world.setBlock(i + 16, j + 0, k + 8, Block.blockSnow.blockID);
		world.setBlock(i + 16, j + 0, k + 9, MainRegistry.frostPlanks.blockID);
		world.setBlock(i + 16, j + 0, k + 10, MainRegistry.frostPlanks.blockID);
		world.setBlock(i + 16, j + 0, k + 11, MainRegistry.frostPlanks.blockID);
		world.setBlock(i + 16, j + 0, k + 12, MainRegistry.frostPlanks.blockID);
		world.setBlock(i + 16, j + 0, k + 13, MainRegistry.frostPlanks.blockID);
		world.setBlock(i + 16, j + 0, k + 14, MainRegistry.frostPlanks.blockID);
		world.setBlock(i + 16, j + 0, k + 15, MainRegistry.frostPlanks.blockID);
		world.setBlock(i + 16, j + 0, k + 16, MainRegistry.frostPlanks.blockID);
		world.setBlock(i + 16, j + 0, k + 17, MainRegistry.frostPlanks.blockID);
		world.setBlock(i + 16, j + 0, k + 18, MainRegistry.frostPlanks.blockID);
		world.setBlock(i + 16, j + 0, k + 19, MainRegistry.frostPlanks.blockID);
		world.setBlock(i + 16, j + 0, k + 20, Block.blockSnow.blockID);
		world.setBlock(i + 16, j + 1, k + 8, Block.blockSnow.blockID);
		world.setBlock(i + 16, j + 1, k + 9, MainRegistry.arcaneStone.blockID);
		world.setBlock(i + 16, j + 1, k + 10, 0);
		world.setBlock(i + 16, j + 1, k + 11, 0);
		world.setBlock(i + 16, j + 1, k + 12, 0);
		world.setBlock(i + 16, j + 1, k + 13, 0);
		world.setBlock(i + 16, j + 1, k + 14, 0);
		world.setBlock(i + 16, j + 1, k + 15, 0);
		world.setBlock(i + 16, j + 1, k + 16, 0);
		world.setBlock(i + 16, j + 1, k + 17, 0);
		world.setBlock(i + 16, j + 1, k + 18, 0);
		world.setBlock(i + 16, j + 1, k + 19, MainRegistry.arcaneStone.blockID);
		world.setBlock(i + 16, j + 1, k + 20, Block.blockSnow.blockID);
		world.setBlock(i + 16, j + 2, k + 8, MainRegistry.unbreakableIce.blockID);
		world.setBlock(i + 16, j + 2, k + 9, 0);
		world.setBlock(i + 16, j + 2, k + 10, 0);
		world.setBlock(i + 16, j + 2, k + 11, 0);
		world.setBlock(i + 16, j + 2, k + 12, 0);
		world.setBlock(i + 16, j + 2, k + 13, 0);
		world.setBlock(i + 16, j + 2, k + 14, 0);
		world.setBlock(i + 16, j + 2, k + 15, 0);
		world.setBlock(i + 16, j + 2, k + 16, 0);
		world.setBlock(i + 16, j + 2, k + 17, 0);
		world.setBlock(i + 16, j + 2, k + 18, 0);
		world.setBlock(i + 16, j + 2, k + 19, 0);
		world.setBlock(i + 16, j + 2, k + 20, MainRegistry.unbreakableIce.blockID);
		world.setBlock(i + 16, j + 3, k + 8, MainRegistry.unbreakableIce.blockID);
		world.setBlock(i + 16, j + 3, k + 20, MainRegistry.unbreakableIce.blockID);
		world.setBlock(i + 16, j + 4, k + 8, MainRegistry.unbreakableIce.blockID);
		world.setBlock(i + 16, j + 4, k + 20, MainRegistry.unbreakableIce.blockID);
		world.setBlock(i + 16, j + 5, k + 8, MainRegistry.unbreakableIce.blockID);
		world.setBlock(i + 16, j + 5, k + 20, MainRegistry.unbreakableIce.blockID);
		world.setBlock(i + 16, j + 6, k + 8, MainRegistry.unbreakableIce.blockID);
		world.setBlock(i + 16, j + 6, k + 20, MainRegistry.unbreakableIce.blockID);
		world.setBlock(i + 16, j + 7, k + 8, MainRegistry.unbreakableIce.blockID);
		world.setBlock(i + 16, j + 7, k + 20, MainRegistry.unbreakableIce.blockID);
		world.setBlock(i + 16, j + 8, k + 8, MainRegistry.unbreakableIce.blockID);
		world.setBlock(i + 16, j + 8, k + 20, MainRegistry.unbreakableIce.blockID);
		world.setBlock(i + 16, j + 9, k + 9, MainRegistry.unbreakableIce.blockID);
		world.setBlock(i + 16, j + 9, k + 19, MainRegistry.unbreakableIce.blockID);
		world.setBlock(i + 16, j + 10, k + 10, MainRegistry.unbreakableIce.blockID);
		world.setBlock(i + 16, j + 10, k + 18, MainRegistry.unbreakableIce.blockID);
		world.setBlock(i + 16, j + 11, k + 11, MainRegistry.unbreakableIce.blockID);
		world.setBlock(i + 16, j + 11, k + 12, MainRegistry.unbreakableIce.blockID);
		world.setBlock(i + 16, j + 11, k + 17, MainRegistry.unbreakableIce.blockID);
		world.setBlock(i + 16, j + 12, k + 12, MainRegistry.unbreakableIce.blockID);
		world.setBlock(i + 16, j + 12, k + 13, MainRegistry.unbreakableIce.blockID);
		world.setBlock(i + 16, j + 12, k + 14, MainRegistry.unbreakableIce.blockID);
		world.setBlock(i + 16, j + 12, k + 15, MainRegistry.unbreakableIce.blockID);
		world.setBlock(i + 16, j + 12, k + 16, MainRegistry.unbreakableIce.blockID);
		world.setBlock(i + 17, j + 0, k + 9, Block.blockSnow.blockID);
		world.setBlock(i + 17, j + 0, k + 10, MainRegistry.frostPlanks.blockID);
		world.setBlock(i + 17, j + 0, k + 11, MainRegistry.frostPlanks.blockID);
		world.setBlock(i + 17, j + 0, k + 12, MainRegistry.frostPlanks.blockID);
		world.setBlock(i + 17, j + 0, k + 13, MainRegistry.frostPlanks.blockID);
		world.setBlock(i + 17, j + 0, k + 14, MainRegistry.frostPlanks.blockID);
		world.setBlock(i + 17, j + 0, k + 15, MainRegistry.frostPlanks.blockID);
		world.setBlock(i + 17, j + 0, k + 16, MainRegistry.frostPlanks.blockID);
		world.setBlock(i + 17, j + 0, k + 17, MainRegistry.frostPlanks.blockID);
		world.setBlock(i + 17, j + 0, k + 18, MainRegistry.frostPlanks.blockID);
		world.setBlock(i + 17, j + 0, k + 19, Block.blockSnow.blockID);
		world.setBlock(i + 17, j + 1, k + 9, Block.blockSnow.blockID);
		world.setBlock(i + 17, j + 1, k + 10, 0);
		world.setBlock(i + 17, j + 1, k + 11, MainRegistry.frostStairs.blockID);
		world.setBlock(i + 17, j + 1, k + 12, MainRegistry.frostStairs.blockID);
		world.setBlock(i + 17, j + 1, k + 13, 0);
		world.setBlock(i + 17, j + 1, k + 14, 0);
		world.setBlock(i + 17, j + 1, k + 15, 0);
		world.setBlock(i + 17, j + 1, k + 16, MainRegistry.frostStairs.blockID);
		world.setBlock(i + 17, j + 1, k + 17, MainRegistry.frostStairs.blockID);
		world.setBlock(i + 17, j + 1, k + 18, 0);
		world.setBlock(i + 17, j + 1, k + 19, Block.blockSnow.blockID);
		world.setBlock(i + 17, j + 2, k + 9, MainRegistry.unbreakableIce.blockID);
		world.setBlock(i + 17, j + 2, k + 10, 0);
		world.setBlock(i + 17, j + 2, k + 11, 0);
		world.setBlock(i + 17, j + 2, k + 12, 0);
		world.setBlock(i + 17, j + 2, k + 13, 0);
		world.setBlock(i + 17, j + 2, k + 14, 0);
		world.setBlock(i + 17, j + 2, k + 15, 0);
		world.setBlock(i + 17, j + 2, k + 16, 0);
		world.setBlock(i + 17, j + 2, k + 17, 0);
		world.setBlock(i + 17, j + 2, k + 18, 0);
		world.setBlock(i + 17, j + 2, k + 19, MainRegistry.unbreakableIce.blockID);
		world.setBlock(i + 17, j + 3, k + 9, MainRegistry.unbreakableIce.blockID);
		world.setBlock(i + 17, j + 3, k + 19, MainRegistry.unbreakableIce.blockID);
		world.setBlock(i + 17, j + 4, k + 9, MainRegistry.unbreakableIce.blockID);
		world.setBlock(i + 17, j + 4, k + 19, MainRegistry.unbreakableIce.blockID);
		world.setBlock(i + 17, j + 5, k + 9, MainRegistry.unbreakableIce.blockID);
		world.setBlock(i + 17, j + 5, k + 19, MainRegistry.unbreakableIce.blockID);
		world.setBlock(i + 17, j + 6, k + 9, MainRegistry.unbreakableIce.blockID);
		world.setBlock(i + 17, j + 6, k + 19, MainRegistry.unbreakableIce.blockID);
		world.setBlock(i + 17, j + 7, k + 9, MainRegistry.unbreakableIce.blockID);
		world.setBlock(i + 17, j + 7, k + 19, MainRegistry.unbreakableIce.blockID);
		world.setBlock(i + 17, j + 8, k + 9, MainRegistry.unbreakableIce.blockID);
		world.setBlock(i + 17, j + 8, k + 19, MainRegistry.unbreakableIce.blockID);
		world.setBlock(i + 17, j + 9, k + 10, MainRegistry.unbreakableIce.blockID);
		world.setBlock(i + 17, j + 9, k + 18, MainRegistry.unbreakableIce.blockID);
		world.setBlock(i + 17, j + 10, k + 11, MainRegistry.unbreakableIce.blockID);
		world.setBlock(i + 17, j + 10, k + 17, MainRegistry.unbreakableIce.blockID);
		world.setBlock(i + 17, j + 11, k + 12, MainRegistry.unbreakableIce.blockID);
		world.setBlock(i + 17, j + 11, k + 16, MainRegistry.unbreakableIce.blockID);
		world.setBlock(i + 17, j + 12, k + 13, MainRegistry.unbreakableIce.blockID);
		world.setBlock(i + 17, j + 12, k + 14, MainRegistry.unbreakableIce.blockID);
		world.setBlock(i + 17, j + 12, k + 15, MainRegistry.unbreakableIce.blockID);
		world.setBlock(i + 18, j + 0, k + 9, Block.blockSnow.blockID);
		world.setBlock(i + 18, j + 0, k + 10, MainRegistry.frostPlanks.blockID);
		world.setBlock(i + 18, j + 0, k + 11, MainRegistry.frostPlanks.blockID);
		world.setBlock(i + 18, j + 0, k + 12, MainRegistry.frostPlanks.blockID);
		world.setBlock(i + 18, j + 0, k + 13, MainRegistry.frostPlanks.blockID);
		world.setBlock(i + 18, j + 0, k + 14, MainRegistry.frostPlanks.blockID);
		world.setBlock(i + 18, j + 0, k + 15, MainRegistry.frostPlanks.blockID);
		world.setBlock(i + 18, j + 0, k + 16, MainRegistry.frostPlanks.blockID);
		world.setBlock(i + 18, j + 0, k + 17, MainRegistry.frostPlanks.blockID);
		world.setBlock(i + 18, j + 0, k + 18, MainRegistry.frostPlanks.blockID);
		world.setBlock(i + 18, j + 0, k + 19, Block.blockSnow.blockID);
		world.setBlock(i + 18, j + 1, k + 9, Block.blockSnow.blockID);
		world.setBlock(i + 18, j + 1, k + 10, 0);
		world.setBlock(i + 18, j + 1, k + 11, 0);
		world.setBlock(i + 18, j + 1, k + 12, 0);
		world.setBlock(i + 18, j + 1, k + 13, 0);
		world.setBlock(i + 18, j + 1, k + 14, 0);
		world.setBlock(i + 18, j + 1, k + 15, 0);
		world.setBlock(i + 18, j + 1, k + 16, 0);
		world.setBlock(i + 18, j + 1, k + 17, 0);
		world.setBlock(i + 18, j + 1, k + 18, 0);
		world.setBlock(i + 18, j + 1, k + 19, Block.blockSnow.blockID);
		world.setBlock(i + 18, j + 2, k + 9, MainRegistry.unbreakableIce.blockID);
		world.setBlock(i + 18, j + 2, k + 10, 0);
		world.setBlock(i + 18, j + 2, k + 11, 0);
		world.setBlock(i + 18, j + 2, k + 12, 0);
		world.setBlock(i + 18, j + 2, k + 13, 0);
		world.setBlock(i + 18, j + 2, k + 14, 0);
		world.setBlock(i + 18, j + 2, k + 15, 0);
		world.setBlock(i + 18, j + 2, k + 16, 0);
		world.setBlock(i + 18, j + 2, k + 17, 0);
		world.setBlock(i + 18, j + 2, k + 18, 0);
		world.setBlock(i + 18, j + 2, k + 19, MainRegistry.unbreakableIce.blockID);
		world.setBlock(i + 18, j + 3, k + 9, MainRegistry.unbreakableIce.blockID);
		world.setBlock(i + 18, j + 3, k + 19, MainRegistry.unbreakableIce.blockID);
		world.setBlock(i + 18, j + 4, k + 9, MainRegistry.unbreakableIce.blockID);
		world.setBlock(i + 18, j + 4, k + 19, MainRegistry.unbreakableIce.blockID);
		world.setBlock(i + 18, j + 5, k + 9, MainRegistry.unbreakableIce.blockID);
		world.setBlock(i + 18, j + 5, k + 19, MainRegistry.unbreakableIce.blockID);
		world.setBlock(i + 18, j + 6, k + 9, MainRegistry.unbreakableIce.blockID);
		world.setBlock(i + 18, j + 6, k + 19, MainRegistry.unbreakableIce.blockID);
		world.setBlock(i + 18, j + 7, k + 9, MainRegistry.unbreakableIce.blockID);
		world.setBlock(i + 18, j + 7, k + 19, MainRegistry.unbreakableIce.blockID);
		world.setBlock(i + 18, j + 8, k + 9, MainRegistry.unbreakableIce.blockID);
		world.setBlock(i + 18, j + 8, k + 19, MainRegistry.unbreakableIce.blockID);
		world.setBlock(i + 18, j + 9, k + 10, MainRegistry.unbreakableIce.blockID);
		world.setBlock(i + 18, j + 9, k + 18, MainRegistry.unbreakableIce.blockID);
		world.setBlock(i + 18, j + 10, k + 11, MainRegistry.unbreakableIce.blockID);
		world.setBlock(i + 18, j + 10, k + 17, MainRegistry.unbreakableIce.blockID);
		world.setBlock(i + 18, j + 11, k + 12, MainRegistry.unbreakableIce.blockID);
		world.setBlock(i + 18, j + 11, k + 16, MainRegistry.unbreakableIce.blockID);
		world.setBlock(i + 18, j + 12, k + 13, MainRegistry.unbreakableIce.blockID);
		world.setBlock(i + 18, j + 12, k + 14, MainRegistry.unbreakableIce.blockID);
		world.setBlock(i + 18, j + 12, k + 15, MainRegistry.unbreakableIce.blockID);
		world.setBlock(i + 19, j + 0, k + 9, Block.blockSnow.blockID);
		world.setBlock(i + 19, j + 0, k + 10, MainRegistry.frostPlanks.blockID);
		world.setBlock(i + 19, j + 0, k + 11, MainRegistry.frostPlanks.blockID);
		world.setBlock(i + 19, j + 0, k + 12, MainRegistry.frostPlanks.blockID);
		world.setBlock(i + 19, j + 0, k + 13, MainRegistry.frostPlanks.blockID);
		world.setBlock(i + 19, j + 0, k + 14, MainRegistry.frostPlanks.blockID);
		world.setBlock(i + 19, j + 0, k + 15, MainRegistry.frostPlanks.blockID);
		world.setBlock(i + 19, j + 0, k + 16, MainRegistry.frostPlanks.blockID);
		world.setBlock(i + 19, j + 0, k + 17, MainRegistry.frostPlanks.blockID);
		world.setBlock(i + 19, j + 0, k + 18, MainRegistry.frostPlanks.blockID);
		world.setBlock(i + 19, j + 0, k + 19, Block.blockSnow.blockID);
		world.setBlock(i + 19, j + 1, k + 9, Block.blockSnow.blockID);
		world.setBlock(i + 19, j + 1, k + 10, 0);
		world.setBlock(i + 19, j + 1, k + 11, 0);
		world.setBlock(i + 19, j + 1, k + 12, 0);
		world.setBlock(i + 19, j + 1, k + 13, 0);
		world.setBlock(i + 19, j + 1, k + 14, 0);
		world.setBlock(i + 19, j + 1, k + 15, 0);
		world.setBlock(i + 19, j + 1, k + 16, 0);
		world.setBlock(i + 19, j + 1, k + 17, 0);
		world.setBlock(i + 19, j + 1, k + 18, 0);
		world.setBlock(i + 19, j + 1, k + 19, Block.blockSnow.blockID);
		world.setBlock(i + 19, j + 2, k + 9, MainRegistry.unbreakableIce.blockID);
		world.setBlock(i + 19, j + 2, k + 10, 0);
		world.setBlock(i + 19, j + 2, k + 11, 0);
		world.setBlock(i + 19, j + 2, k + 12, 0);
		world.setBlock(i + 19, j + 2, k + 13, 0);
		world.setBlock(i + 19, j + 2, k + 14, 0);
		world.setBlock(i + 19, j + 2, k + 15, 0);
		world.setBlock(i + 19, j + 2, k + 16, 0);
		world.setBlock(i + 19, j + 2, k + 17, 0);
		world.setBlock(i + 19, j + 2, k + 18, 0);
		world.setBlock(i + 19, j + 2, k + 19, MainRegistry.unbreakableIce.blockID);
		world.setBlock(i + 19, j + 3, k + 9, MainRegistry.unbreakableIce.blockID);
		world.setBlock(i + 19, j + 3, k + 19, MainRegistry.unbreakableIce.blockID);
		world.setBlock(i + 19, j + 4, k + 9, MainRegistry.unbreakableIce.blockID);
		world.setBlock(i + 19, j + 4, k + 19, MainRegistry.unbreakableIce.blockID);
		world.setBlock(i + 19, j + 5, k + 9, MainRegistry.unbreakableIce.blockID);
		world.setBlock(i + 19, j + 5, k + 19, MainRegistry.unbreakableIce.blockID);
		world.setBlock(i + 19, j + 6, k + 9, MainRegistry.unbreakableIce.blockID);
		world.setBlock(i + 19, j + 6, k + 19, MainRegistry.unbreakableIce.blockID);
		world.setBlock(i + 19, j + 7, k + 9, MainRegistry.unbreakableIce.blockID);
		world.setBlock(i + 19, j + 7, k + 19, MainRegistry.unbreakableIce.blockID);
		world.setBlock(i + 19, j + 8, k + 9, MainRegistry.unbreakableIce.blockID);
		world.setBlock(i + 19, j + 8, k + 19, MainRegistry.unbreakableIce.blockID);
		world.setBlock(i + 19, j + 9, k + 10, MainRegistry.unbreakableIce.blockID);
		world.setBlock(i + 19, j + 9, k + 18, MainRegistry.unbreakableIce.blockID);
		world.setBlock(i + 19, j + 10, k + 11, MainRegistry.unbreakableIce.blockID);
		world.setBlock(i + 19, j + 10, k + 17, MainRegistry.unbreakableIce.blockID);
		world.setBlock(i + 19, j + 11, k + 12, MainRegistry.unbreakableIce.blockID);
		world.setBlock(i + 19, j + 11, k + 16, MainRegistry.unbreakableIce.blockID);
		world.setBlock(i + 19, j + 12, k + 13, MainRegistry.unbreakableIce.blockID);
		world.setBlock(i + 19, j + 12, k + 14, MainRegistry.unbreakableIce.blockID);
		world.setBlock(i + 19, j + 12, k + 15, MainRegistry.unbreakableIce.blockID);
		world.setBlock(i + 20, j + 0, k + 9, Block.blockSnow.blockID);
		world.setBlock(i + 20, j + 0, k + 10, MainRegistry.frostPlanks.blockID);
		world.setBlock(i + 20, j + 0, k + 11, MainRegistry.frostPlanks.blockID);
		world.setBlock(i + 20, j + 0, k + 12, MainRegistry.frostPlanks.blockID);
		world.setBlock(i + 20, j + 0, k + 13, MainRegistry.frostPlanks.blockID);
		world.setBlock(i + 20, j + 0, k + 14, MainRegistry.frostPlanks.blockID);
		world.setBlock(i + 20, j + 0, k + 15, MainRegistry.frostPlanks.blockID);
		world.setBlock(i + 20, j + 0, k + 16, MainRegistry.frostPlanks.blockID);
		world.setBlock(i + 20, j + 0, k + 17, MainRegistry.frostPlanks.blockID);
		world.setBlock(i + 20, j + 0, k + 18, MainRegistry.frostPlanks.blockID);
		world.setBlock(i + 20, j + 0, k + 19, Block.blockSnow.blockID);
		world.setBlock(i + 20, j + 1, k + 9, Block.blockSnow.blockID);
		world.setBlock(i + 20, j + 1, k + 10, 0);
		world.setBlock(i + 20, j + 1, k + 11, 0);
		world.setBlock(i + 20, j + 1, k + 12, 0);
		world.setBlock(i + 20, j + 1, k + 13, 0);
		world.setBlock(i + 20, j + 1, k + 14, 0);
		world.setBlock(i + 20, j + 1, k + 15, 0);
		world.setBlock(i + 20, j + 1, k + 16, 0);
		world.setBlock(i + 20, j + 1, k + 17, 0);
		world.setBlock(i + 20, j + 1, k + 18, 0);
		world.setBlock(i + 20, j + 1, k + 19, Block.blockSnow.blockID);
		world.setBlock(i + 20, j + 2, k + 9, MainRegistry.unbreakableIce.blockID);
		world.setBlock(i + 20, j + 2, k + 10, 0);
		world.setBlock(i + 20, j + 2, k + 11, 0);
		world.setBlock(i + 20, j + 2, k + 12, 0);
		world.setBlock(i + 20, j + 2, k + 13, 0);
		world.setBlock(i + 20, j + 2, k + 14, 0);
		world.setBlock(i + 20, j + 2, k + 15, 0);
		world.setBlock(i + 20, j + 2, k + 16, 0);
		world.setBlock(i + 20, j + 2, k + 17, 0);
		world.setBlock(i + 20, j + 2, k + 18, 0);
		world.setBlock(i + 20, j + 2, k + 19, MainRegistry.unbreakableIce.blockID);
		world.setBlock(i + 20, j + 3, k + 9, MainRegistry.unbreakableIce.blockID);
		world.setBlock(i + 20, j + 3, k + 19, MainRegistry.unbreakableIce.blockID);
		world.setBlock(i + 20, j + 4, k + 9, MainRegistry.unbreakableIce.blockID);
		world.setBlock(i + 20, j + 4, k + 19, MainRegistry.unbreakableIce.blockID);
		world.setBlock(i + 20, j + 5, k + 9, MainRegistry.unbreakableIce.blockID);
		world.setBlock(i + 20, j + 5, k + 19, MainRegistry.unbreakableIce.blockID);
		world.setBlock(i + 20, j + 6, k + 9, MainRegistry.unbreakableIce.blockID);
		world.setBlock(i + 20, j + 6, k + 19, MainRegistry.unbreakableIce.blockID);
		world.setBlock(i + 20, j + 7, k + 9, MainRegistry.unbreakableIce.blockID);
		world.setBlock(i + 20, j + 7, k + 19, MainRegistry.unbreakableIce.blockID);
		world.setBlock(i + 20, j + 8, k + 9, MainRegistry.unbreakableIce.blockID);
		world.setBlock(i + 20, j + 8, k + 19, MainRegistry.unbreakableIce.blockID);
		world.setBlock(i + 20, j + 9, k + 10, MainRegistry.unbreakableIce.blockID);
		world.setBlock(i + 20, j + 9, k + 18, MainRegistry.unbreakableIce.blockID);
		world.setBlock(i + 20, j + 10, k + 11, MainRegistry.unbreakableIce.blockID);
		world.setBlock(i + 20, j + 10, k + 17, MainRegistry.unbreakableIce.blockID);
		world.setBlock(i + 20, j + 11, k + 12, MainRegistry.unbreakableIce.blockID);
		world.setBlock(i + 20, j + 11, k + 13, MainRegistry.unbreakableIce.blockID);
		world.setBlock(i + 20, j + 11, k + 14, MainRegistry.unbreakableIce.blockID);
		world.setBlock(i + 20, j + 11, k + 15, MainRegistry.unbreakableIce.blockID);
		world.setBlock(i + 20, j + 11, k + 16, MainRegistry.unbreakableIce.blockID);
		world.setBlock(i + 21, j + 0, k + 10, Block.blockSnow.blockID);
		world.setBlock(i + 21, j + 0, k + 11, MainRegistry.frostPlanks.blockID);
		world.setBlock(i + 21, j + 0, k + 12, MainRegistry.frostPlanks.blockID);
		world.setBlock(i + 21, j + 0, k + 13, MainRegistry.frostPlanks.blockID);
		world.setBlock(i + 21, j + 0, k + 14, MainRegistry.frostPlanks.blockID);
		world.setBlock(i + 21, j + 0, k + 15, MainRegistry.frostPlanks.blockID);
		world.setBlock(i + 21, j + 0, k + 16, MainRegistry.frostPlanks.blockID);
		world.setBlock(i + 21, j + 0, k + 17, MainRegistry.frostPlanks.blockID);
		world.setBlock(i + 21, j + 0, k + 18, Block.blockSnow.blockID);
		world.setBlock(i + 21, j + 1, k + 10, Block.blockSnow.blockID);
		world.setBlock(i + 21, j + 1, k + 11, 0);
		world.setBlock(i + 21, j + 1, k + 12, 0);
		world.setBlock(i + 21, j + 1, k + 13, 0);
		world.setBlock(i + 21, j + 1, k + 14, 0);
		world.setBlock(i + 21, j + 1, k + 15, 0);
		world.setBlock(i + 21, j + 1, k + 16, 0);
		world.setBlock(i + 21, j + 1, k + 17, 0);
		world.setBlock(i + 21, j + 1, k + 18, Block.blockSnow.blockID);
		world.setBlock(i + 21, j + 2, k + 10, MainRegistry.unbreakableIce.blockID);
		world.setBlock(i + 21, j + 2, k + 11, 0);
		world.setBlock(i + 21, j + 2, k + 12, 0);
		world.setBlock(i + 21, j + 2, k + 13, 0);
		world.setBlock(i + 21, j + 2, k + 14, 0);
		world.setBlock(i + 21, j + 2, k + 15, 0);
		world.setBlock(i + 21, j + 2, k + 16, 0);
		world.setBlock(i + 21, j + 2, k + 17, 0);
		world.setBlock(i + 21, j + 2, k + 18, MainRegistry.unbreakableIce.blockID);
		world.setBlock(i + 21, j + 3, k + 10, MainRegistry.unbreakableIce.blockID);
		world.setBlock(i + 21, j + 3, k + 18, MainRegistry.unbreakableIce.blockID);
		world.setBlock(i + 21, j + 4, k + 10, MainRegistry.unbreakableIce.blockID);
		world.setBlock(i + 21, j + 4, k + 18, MainRegistry.unbreakableIce.blockID);
		world.setBlock(i + 21, j + 5, k + 10, MainRegistry.unbreakableIce.blockID);
		world.setBlock(i + 21, j + 5, k + 18, MainRegistry.unbreakableIce.blockID);
		world.setBlock(i + 21, j + 6, k + 10, MainRegistry.unbreakableIce.blockID);
		world.setBlock(i + 21, j + 6, k + 18, MainRegistry.unbreakableIce.blockID);
		world.setBlock(i + 21, j + 7, k + 10, MainRegistry.unbreakableIce.blockID);
		world.setBlock(i + 21, j + 7, k + 18, MainRegistry.unbreakableIce.blockID);
		world.setBlock(i + 21, j + 8, k + 10, MainRegistry.unbreakableIce.blockID);
		world.setBlock(i + 21, j + 8, k + 18, MainRegistry.unbreakableIce.blockID);
		world.setBlock(i + 21, j + 9, k + 11, MainRegistry.unbreakableIce.blockID);
		world.setBlock(i + 21, j + 9, k + 17, MainRegistry.unbreakableIce.blockID);
		world.setBlock(i + 21, j + 10, k + 12, MainRegistry.unbreakableIce.blockID);
		world.setBlock(i + 21, j + 10, k + 13, MainRegistry.unbreakableIce.blockID);
		world.setBlock(i + 21, j + 10, k + 14, MainRegistry.unbreakableIce.blockID);
		world.setBlock(i + 21, j + 10, k + 15, MainRegistry.unbreakableIce.blockID);
		world.setBlock(i + 21, j + 10, k + 16, MainRegistry.unbreakableIce.blockID);
		world.setBlock(i + 22, j + 0, k + 11, Block.blockSnow.blockID);
		world.setBlock(i + 22, j + 0, k + 12, MainRegistry.frostPlanks.blockID);
		world.setBlock(i + 22, j + 0, k + 13, MainRegistry.frostPlanks.blockID);
		world.setBlock(i + 22, j + 0, k + 14, MainRegistry.frostPlanks.blockID);
		world.setBlock(i + 22, j + 0, k + 15, MainRegistry.frostPlanks.blockID);
		world.setBlock(i + 22, j + 0, k + 16, MainRegistry.frostPlanks.blockID);
		world.setBlock(i + 22, j + 0, k + 17, Block.blockSnow.blockID);
		world.setBlock(i + 22, j + 1, k + 11, Block.blockSnow.blockID);
		world.setBlock(i + 22, j + 1, k + 12, MainRegistry.arcaneStone.blockID);
		world.setBlock(i + 22, j + 1, k + 13, 0);
		world.setBlock(i + 22, j + 1, k + 14, 0);
		world.setBlock(i + 22, j + 1, k + 15, 0);
		world.setBlock(i + 22, j + 1, k + 16, MainRegistry.arcaneStone.blockID);
		world.setBlock(i + 22, j + 1, k + 17, Block.blockSnow.blockID);
		world.setBlock(i + 22, j + 2, k + 11, MainRegistry.unbreakableIce.blockID);
		world.setBlock(i + 22, j + 2, k + 12, 0);
		world.setBlock(i + 22, j + 2, k + 13, 0);
		world.setBlock(i + 22, j + 2, k + 14, 0);
		world.setBlock(i + 22, j + 2, k + 15, 0);
		world.setBlock(i + 22, j + 2, k + 16, 0);
		world.setBlock(i + 22, j + 2, k + 17, MainRegistry.unbreakableIce.blockID);
		world.setBlock(i + 22, j + 3, k + 11, MainRegistry.unbreakableIce.blockID);
		world.setBlock(i + 22, j + 3, k + 17, MainRegistry.unbreakableIce.blockID);
		world.setBlock(i + 22, j + 4, k + 11, MainRegistry.unbreakableIce.blockID);
		world.setBlock(i + 22, j + 4, k + 17, MainRegistry.unbreakableIce.blockID);
		world.setBlock(i + 22, j + 5, k + 11, MainRegistry.unbreakableIce.blockID);
		world.setBlock(i + 22, j + 5, k + 17, MainRegistry.unbreakableIce.blockID);
		world.setBlock(i + 22, j + 6, k + 11, MainRegistry.unbreakableIce.blockID);
		world.setBlock(i + 22, j + 6, k + 17, MainRegistry.unbreakableIce.blockID);
		world.setBlock(i + 22, j + 7, k + 11, MainRegistry.unbreakableIce.blockID);
		world.setBlock(i + 22, j + 7, k + 17, MainRegistry.unbreakableIce.blockID);
		world.setBlock(i + 22, j + 8, k + 11, MainRegistry.unbreakableIce.blockID);
		world.setBlock(i + 22, j + 8, k + 17, MainRegistry.unbreakableIce.blockID);
		world.setBlock(i + 22, j + 9, k + 12, MainRegistry.unbreakableIce.blockID);
		world.setBlock(i + 22, j + 9, k + 13, MainRegistry.unbreakableIce.blockID);
		world.setBlock(i + 22, j + 9, k + 14, MainRegistry.unbreakableIce.blockID);
		world.setBlock(i + 22, j + 9, k + 15, MainRegistry.unbreakableIce.blockID);
		world.setBlock(i + 22, j + 9, k + 16, MainRegistry.unbreakableIce.blockID);
		world.setBlock(i + 23, j + 0, k + 12, MainRegistry.unbreakableIce.blockID);
		world.setBlock(i + 23, j + 0, k + 13, MainRegistry.frostPlanks.blockID);
		world.setBlock(i + 23, j + 0, k + 14, MainRegistry.frostPlanks.blockID);
		world.setBlock(i + 23, j + 0, k + 15, MainRegistry.frostPlanks.blockID);
		world.setBlock(i + 23, j + 0, k + 16, MainRegistry.unbreakableIce.blockID);
		world.setBlock(i + 23, j + 1, k + 12, Block.blockSnow.blockID);
		world.setBlock(i + 23, j + 1, k + 13, Block.fenceIron.blockID);
		world.setBlock(i + 23, j + 1, k + 14, Block.fenceIron.blockID);
		world.setBlock(i + 23, j + 1, k + 15, Block.fenceIron.blockID);
		world.setBlock(i + 23, j + 1, k + 16, Block.blockSnow.blockID);
		world.setBlock(i + 23, j + 2, k + 12, Block.blockSnow.blockID);
		world.setBlock(i + 23, j + 2, k + 13, Block.fenceIron.blockID);
		world.setBlock(i + 23, j + 2, k + 14, Block.fenceIron.blockID);
		world.setBlock(i + 23, j + 2, k + 15, Block.fenceIron.blockID);
		world.setBlock(i + 23, j + 2, k + 16, Block.blockSnow.blockID);
		world.setBlock(i + 23, j + 3, k + 12, Block.blockSnow.blockID);
		world.setBlock(i + 23, j + 3, k + 13, Block.blockSnow.blockID);
		world.setBlock(i + 23, j + 3, k + 14, Block.fenceIron.blockID);
		world.setBlock(i + 23, j + 3, k + 15, Block.blockSnow.blockID);
		world.setBlock(i + 23, j + 3, k + 16, Block.blockSnow.blockID);
		world.setBlock(i + 23, j + 4, k + 12, Block.blockSnow.blockID);
		world.setBlock(i + 23, j + 4, k + 13, Block.blockSnow.blockID);
		world.setBlock(i + 23, j + 4, k + 14, Block.blockSnow.blockID);
		world.setBlock(i + 23, j + 4, k + 15, Block.blockSnow.blockID);
		world.setBlock(i + 23, j + 4, k + 16, Block.blockSnow.blockID);
		world.setBlock(i + 23, j + 5, k + 12, MainRegistry.unbreakableIce.blockID);
		world.setBlock(i + 23, j + 5, k + 13, Block.blockSnow.blockID);
		world.setBlock(i + 23, j + 5, k + 14, Block.blockSnow.blockID);
		world.setBlock(i + 23, j + 5, k + 15, Block.blockSnow.blockID);
		world.setBlock(i + 23, j + 5, k + 16, MainRegistry.unbreakableIce.blockID);
		world.setBlock(i + 23, j + 6, k + 12, MainRegistry.unbreakableIce.blockID);
		world.setBlock(i + 23, j + 6, k + 13, MainRegistry.unbreakableIce.blockID);
		world.setBlock(i + 23, j + 6, k + 14, MainRegistry.unbreakableIce.blockID);
		world.setBlock(i + 23, j + 6, k + 15, MainRegistry.unbreakableIce.blockID);
		world.setBlock(i + 23, j + 6, k + 16, MainRegistry.unbreakableIce.blockID);
		world.setBlock(i + 23, j + 7, k + 12, MainRegistry.unbreakableIce.blockID);
		world.setBlock(i + 23, j + 7, k + 13, MainRegistry.unbreakableIce.blockID);
		world.setBlock(i + 23, j + 7, k + 14, MainRegistry.unbreakableIce.blockID);
		world.setBlock(i + 23, j + 7, k + 15, MainRegistry.unbreakableIce.blockID);
		world.setBlock(i + 23, j + 7, k + 16, MainRegistry.unbreakableIce.blockID);
		world.setBlock(i + 23, j + 8, k + 12, MainRegistry.unbreakableIce.blockID);
		world.setBlock(i + 23, j + 8, k + 13, MainRegistry.unbreakableIce.blockID);
		world.setBlock(i + 23, j + 8, k + 14, MainRegistry.unbreakableIce.blockID);
		world.setBlock(i + 23, j + 8, k + 15, MainRegistry.unbreakableIce.blockID);
		world.setBlock(i + 23, j + 8, k + 16, MainRegistry.unbreakableIce.blockID);
		world.setBlock(i + 24, j + 0, k + 13, MainRegistry.unbreakableIce.blockID);
		world.setBlock(i + 24, j + 0, k + 14, Block.blockSnow.blockID);
		world.setBlock(i + 24, j + 0, k + 15, MainRegistry.unbreakableIce.blockID);
		world.setBlock(i + 24, j + 1, k + 13, 0);
		world.setBlock(i + 24, j + 1, k + 14, 0);
		world.setBlock(i + 24, j + 1, k + 15, 0);
		world.setBlock(i + 24, j + 2, k + 13, 0);
		world.setBlock(i + 24, j + 2, k + 14, 0);
		world.setBlock(i + 24, j + 2, k + 15, 0);
		world.setBlock(i + 24, j + 3, k + 13, 0);
		world.setBlock(i + 24, j + 3, k + 14, 0);
		world.setBlock(i + 24, j + 3, k + 15, 0);
		world.setBlock(i + 25, j + 0, k + 13, MainRegistry.unbreakableIce.blockID);
		world.setBlock(i + 25, j + 0, k + 14, Block.blockSnow.blockID);
		world.setBlock(i + 25, j + 0, k + 15, MainRegistry.unbreakableIce.blockID);
		world.setBlock(i + 25, j + 1, k + 13, 0);
		world.setBlock(i + 25, j + 1, k + 14, 0);
		world.setBlock(i + 25, j + 1, k + 15, 0);
		world.setBlock(i + 25, j + 2, k + 13, 0);
		world.setBlock(i + 25, j + 2, k + 14, 0);
		world.setBlock(i + 25, j + 2, k + 15, 0);
		world.setBlock(i + 25, j + 3, k + 13, 0);
		world.setBlock(i + 25, j + 3, k + 14, 0);
		world.setBlock(i + 25, j + 3, k + 15, 0);
		world.setBlock(i + 26, j + 0, k + 13, MainRegistry.unbreakableIce.blockID);
		world.setBlock(i + 26, j + 0, k + 14, Block.blockSnow.blockID);
		world.setBlock(i + 26, j + 0, k + 15, MainRegistry.unbreakableIce.blockID);
		world.setBlock(i + 26, j + 1, k + 13, 0);
		world.setBlock(i + 26, j + 1, k + 14, 0);
		world.setBlock(i + 26, j + 1, k + 15, 0);
		world.setBlock(i + 26, j + 2, k + 13, 0);
		world.setBlock(i + 26, j + 2, k + 14, 0);
		world.setBlock(i + 26, j + 2, k + 15, 0);
		world.setBlock(i + 26, j + 3, k + 13, 0);
		world.setBlock(i + 26, j + 3, k + 14, 0);
		world.setBlock(i + 26, j + 3, k + 15, 0);
		world.setBlock(i + 27, j + 0, k + 13, MainRegistry.unbreakableIce.blockID);
		world.setBlock(i + 27, j + 0, k + 14, Block.blockSnow.blockID);
		world.setBlock(i + 27, j + 0, k + 15, MainRegistry.unbreakableIce.blockID);
		world.setBlock(i + 27, j + 1, k + 13, MainRegistry.frostFence.blockID);
		world.setBlock(i + 27, j + 1, k + 14, 0);
		world.setBlock(i + 27, j + 1, k + 15, MainRegistry.frostFence.blockID);
		world.setBlock(i + 27, j + 2, k + 13, MainRegistry.frostFence.blockID);
		world.setBlock(i + 27, j + 2, k + 14, 0);
		world.setBlock(i + 27, j + 2, k + 15, MainRegistry.frostFence.blockID);
		world.setBlock(i + 27, j + 3, k + 13, MainRegistry.frostFence.blockID);
		world.setBlock(i + 27, j + 3, k + 14, MainRegistry.arcaneStone.blockID);
		world.setBlock(i + 27, j + 3, k + 15, MainRegistry.frostFence.blockID);
		world.setBlock(i + 28, j + 0, k + 13, MainRegistry.unbreakableIce.blockID);
		world.setBlock(i + 28, j + 0, k + 14, Block.blockSnow.blockID);
		world.setBlock(i + 28, j + 0, k + 15, MainRegistry.unbreakableIce.blockID);
		world.setBlock(i + 28, j + 1, k + 13, 0);
		world.setBlock(i + 28, j + 1, k + 14, 0);
		world.setBlock(i + 28, j + 1, k + 15, 0);
		world.setBlock(i + 28, j + 2, k + 13, 0);
		world.setBlock(i + 28, j + 2, k + 14, 0);
		world.setBlock(i + 28, j + 2, k + 15, 0);
		world.setBlock(i + 28, j + 3, k + 13, 0);
		world.setBlock(i + 28, j + 3, k + 14, 0);
		world.setBlock(i + 28, j + 3, k + 15, 0);
		world.setBlock(i + 29, j + 0, k + 4, Block.blockSnow.blockID);
		world.setBlock(i + 29, j + 0, k + 5, Block.blockSnow.blockID);
		world.setBlock(i + 29, j + 0, k + 6, Block.blockSnow.blockID);
		world.setBlock(i + 29, j + 0, k + 7, Block.blockSnow.blockID);
		world.setBlock(i + 29, j + 0, k + 8, Block.blockSnow.blockID);
		world.setBlock(i + 29, j + 0, k + 13, MainRegistry.unbreakableIce.blockID);
		world.setBlock(i + 29, j + 0, k + 14, Block.blockSnow.blockID);
		world.setBlock(i + 29, j + 0, k + 15, MainRegistry.unbreakableIce.blockID);
		world.setBlock(i + 29, j + 0, k + 20, Block.blockSnow.blockID);
		world.setBlock(i + 29, j + 0, k + 21, Block.blockSnow.blockID);
		world.setBlock(i + 29, j + 0, k + 22, Block.blockSnow.blockID);
		world.setBlock(i + 29, j + 0, k + 23, Block.blockSnow.blockID);
		world.setBlock(i + 29, j + 0, k + 24, Block.blockSnow.blockID);
		world.setBlock(i + 29, j + 1, k + 4, Block.blockSnow.blockID);
		world.setBlock(i + 29, j + 1, k + 5, Block.blockSnow.blockID);
		world.setBlock(i + 29, j + 1, k + 6, Block.blockSnow.blockID);
		world.setBlock(i + 29, j + 1, k + 7, Block.blockSnow.blockID);
		world.setBlock(i + 29, j + 1, k + 8, Block.blockSnow.blockID);
		world.setBlock(i + 29, j + 1, k + 13, 0);
		world.setBlock(i + 29, j + 1, k + 14, 0);
		world.setBlock(i + 29, j + 1, k + 15, 0);
		world.setBlock(i + 29, j + 1, k + 20, Block.blockSnow.blockID);
		world.setBlock(i + 29, j + 1, k + 21, Block.blockSnow.blockID);
		world.setBlock(i + 29, j + 1, k + 22, Block.blockSnow.blockID);
		world.setBlock(i + 29, j + 1, k + 23, Block.blockSnow.blockID);
		world.setBlock(i + 29, j + 1, k + 24, Block.blockSnow.blockID);
		world.setBlock(i + 29, j + 2, k + 4, Block.blockSnow.blockID);
		world.setBlock(i + 29, j + 2, k + 5, Block.blockSnow.blockID);
		world.setBlock(i + 29, j + 2, k + 6, Block.blockSnow.blockID);
		world.setBlock(i + 29, j + 2, k + 7, Block.blockSnow.blockID);
		world.setBlock(i + 29, j + 2, k + 8, Block.blockSnow.blockID);
		world.setBlock(i + 29, j + 2, k + 13, 0);
		world.setBlock(i + 29, j + 2, k + 14, 0);
		world.setBlock(i + 29, j + 2, k + 15, 0);
		world.setBlock(i + 29, j + 2, k + 20, Block.blockSnow.blockID);
		world.setBlock(i + 29, j + 2, k + 21, Block.blockSnow.blockID);
		world.setBlock(i + 29, j + 2, k + 22, Block.blockSnow.blockID);
		world.setBlock(i + 29, j + 2, k + 23, Block.blockSnow.blockID);
		world.setBlock(i + 29, j + 2, k + 24, Block.blockSnow.blockID);
		world.setBlock(i + 29, j + 3, k + 5, Block.blockSnow.blockID);
		world.setBlock(i + 29, j + 3, k + 6, Block.blockSnow.blockID);
		world.setBlock(i + 29, j + 3, k + 7, Block.blockSnow.blockID);
		world.setBlock(i + 29, j + 3, k + 13, 0);
		world.setBlock(i + 29, j + 3, k + 14, 0);
		world.setBlock(i + 29, j + 3, k + 15, 0);
		world.setBlock(i + 29, j + 3, k + 21, Block.blockSnow.blockID);
		world.setBlock(i + 29, j + 3, k + 22, Block.blockSnow.blockID);
		world.setBlock(i + 29, j + 3, k + 23, Block.blockSnow.blockID);
		world.setBlock(i + 30, j + 0, k + 3, Block.blockSnow.blockID);
		world.setBlock(i + 30, j + 0, k + 4, Block.blockSnow.blockID);
		world.setBlock(i + 30, j + 0, k + 5, Block.blockSnow.blockID);
		world.setBlock(i + 30, j + 0, k + 6, Block.blockSnow.blockID);
		world.setBlock(i + 30, j + 0, k + 7, Block.blockSnow.blockID);
		world.setBlock(i + 30, j + 0, k + 8, Block.blockSnow.blockID);
		world.setBlock(i + 30, j + 0, k + 9, Block.blockSnow.blockID);
		world.setBlock(i + 30, j + 0, k + 13, MainRegistry.unbreakableIce.blockID);
		world.setBlock(i + 30, j + 0, k + 14, Block.blockSnow.blockID);
		world.setBlock(i + 30, j + 0, k + 15, MainRegistry.unbreakableIce.blockID);
		world.setBlock(i + 30, j + 0, k + 19, Block.blockSnow.blockID);
		world.setBlock(i + 30, j + 0, k + 20, Block.blockSnow.blockID);
		world.setBlock(i + 30, j + 0, k + 21, Block.blockSnow.blockID);
		world.setBlock(i + 30, j + 0, k + 22, Block.blockSnow.blockID);
		world.setBlock(i + 30, j + 0, k + 23, Block.blockSnow.blockID);
		world.setBlock(i + 30, j + 0, k + 24, Block.blockSnow.blockID);
		world.setBlock(i + 30, j + 0, k + 25, Block.blockSnow.blockID);
		world.setBlock(i + 30, j + 1, k + 3, Block.blockSnow.blockID);
		world.setBlock(i + 30, j + 1, k + 4, 0);
		world.setBlock(i + 30, j + 1, k + 5, 0);
		world.setBlock(i + 30, j + 1, k + 6, 0);
		world.setBlock(i + 30, j + 1, k + 7, 0);
		world.setBlock(i + 30, j + 1, k + 8, 0);
		world.setBlock(i + 30, j + 1, k + 9, Block.blockSnow.blockID);
		world.setBlock(i + 30, j + 1, k + 13, 0);
		world.setBlock(i + 30, j + 1, k + 14, 0);
		world.setBlock(i + 30, j + 1, k + 15, 0);
		world.setBlock(i + 30, j + 1, k + 19, Block.blockSnow.blockID);
		world.setBlock(i + 30, j + 1, k + 20, 0);
		world.setBlock(i + 30, j + 1, k + 21, 0);
		world.setBlock(i + 30, j + 1, k + 22, 0);
		world.setBlock(i + 30, j + 1, k + 23, 0);
		world.setBlock(i + 30, j + 1, k + 24, 0);
		world.setBlock(i + 30, j + 1, k + 25, Block.blockSnow.blockID);
		world.setBlock(i + 30, j + 2, k + 3, Block.blockSnow.blockID);
		world.setBlock(i + 30, j + 2, k + 4, 0);
		world.setBlock(i + 30, j + 2, k + 5, 0);
		world.setBlock(i + 30, j + 2, k + 6, 0);
		world.setBlock(i + 30, j + 2, k + 7, 0);
		world.setBlock(i + 30, j + 2, k + 8, 0);
		world.setBlock(i + 30, j + 2, k + 9, Block.blockSnow.blockID);
		world.setBlock(i + 30, j + 2, k + 13, 0);
		world.setBlock(i + 30, j + 2, k + 14, 0);
		world.setBlock(i + 30, j + 2, k + 15, 0);
		world.setBlock(i + 30, j + 2, k + 19, Block.blockSnow.blockID);
		world.setBlock(i + 30, j + 2, k + 20, 0);
		world.setBlock(i + 30, j + 2, k + 21, 0);
		world.setBlock(i + 30, j + 2, k + 22, 0);
		world.setBlock(i + 30, j + 2, k + 23, 0);
		world.setBlock(i + 30, j + 2, k + 24, 0);
		world.setBlock(i + 30, j + 2, k + 25, Block.blockSnow.blockID);
		world.setBlock(i + 30, j + 3, k + 3, Block.blockSnow.blockID);
		world.setBlock(i + 30, j + 3, k + 4, Block.blockSnow.blockID);
		world.setBlock(i + 30, j + 3, k + 5, 0);
		world.setBlock(i + 30, j + 3, k + 6, 0);
		world.setBlock(i + 30, j + 3, k + 7, 0);
		world.setBlock(i + 30, j + 3, k + 8, Block.blockSnow.blockID);
		world.setBlock(i + 30, j + 3, k + 9, Block.blockSnow.blockID);
		world.setBlock(i + 30, j + 3, k + 13, 0);
		world.setBlock(i + 30, j + 3, k + 14, 0);
		world.setBlock(i + 30, j + 3, k + 15, 0);
		world.setBlock(i + 30, j + 3, k + 19, Block.blockSnow.blockID);
		world.setBlock(i + 30, j + 3, k + 20, Block.blockSnow.blockID);
		world.setBlock(i + 30, j + 3, k + 21, 0);
		world.setBlock(i + 30, j + 3, k + 22, 0);
		world.setBlock(i + 30, j + 3, k + 23, 0);
		world.setBlock(i + 30, j + 3, k + 24, Block.blockSnow.blockID);
		world.setBlock(i + 30, j + 3, k + 25, Block.blockSnow.blockID);
		world.setBlock(i + 30, j + 4, k + 4, Block.blockSnow.blockID);
		world.setBlock(i + 30, j + 4, k + 5, Block.blockSnow.blockID);

		generate2(world, rand, i, j, k);
		return true;
	}

	public boolean generate2(World world, Random rand, int i, int j, int k)
	{
		world.setBlock(i + 30, j + 4, k + 6, Block.blockSnow.blockID);
		world.setBlock(i + 30, j + 4, k + 7, Block.blockSnow.blockID);
		world.setBlock(i + 30, j + 4, k + 8, Block.blockSnow.blockID);
		world.setBlock(i + 30, j + 4, k + 20, Block.blockSnow.blockID);
		world.setBlock(i + 30, j + 4, k + 21, Block.blockSnow.blockID);
		world.setBlock(i + 30, j + 4, k + 22, Block.blockSnow.blockID);
		world.setBlock(i + 30, j + 4, k + 23, Block.blockSnow.blockID);
		world.setBlock(i + 30, j + 4, k + 24, Block.blockSnow.blockID);
		world.setBlock(i + 31, j + 0, k + 2, Block.blockSnow.blockID);
		world.setBlock(i + 31, j + 0, k + 3, Block.blockSnow.blockID);
		world.setBlock(i + 31, j + 0, k + 4, Block.blockSnow.blockID);
		world.setBlock(i + 31, j + 0, k + 5, Block.blockSnow.blockID);
		world.setBlock(i + 31, j + 0, k + 6, Block.blockSnow.blockID);
		world.setBlock(i + 31, j + 0, k + 7, Block.blockSnow.blockID);
