/*
 *** MADE BY MITHION'S .SCHEMATIC TO JAVA CONVERTING TOOLv0.1 ***
 */
package arcticraft.gen; import java.util.Random;

import net.minecraft.block.Block;
import net.minecraft.item.ItemDoor;
import net.minecraft.tileentity.TileEntityChest;
import net.minecraft.world.World;
import net.minecraft.world.gen.feature.WorldGenerator;
import arcticraft.entities.AC_EntityCaptain;
import arcticraft.entities.AC_EntityPirate;
import arcticraft.helpers.AC_WorldGenHelpers;
import arcticraft.main.MainRegistry;



public class AC_GenShip extends WorldGenerator
{
	public AC_GenShip() { }

	public boolean generate(World world, Random rand, int i, int j, int k) {

		if (world.getBlockId(i, j, k) != MainRegistry.acWaterStill.blockID || world.getBlockId(i, j+1, k) != 0)
		{
			return false;
		}
		world.setBlock(i + 3, j + 0, k + 15, 5);
		world.setBlock(i + 3, j + 0, k + 14, 5);
		world.setBlock(i + 3, j + 0, k + 13, 5);
		world.setBlock(i + 3, j + 0, k + 12, 5);
		world.setBlock(i + 3, j + 0, k + 11, 5);
		world.setBlock(i + 3, j + 0, k + 10, 5);
		world.setBlock(i + 3, j + 0, k + 9, 5);
		world.setBlock(i + 3, j + 0, k + 8, 5);
		world.setBlock(i + 3, j + 0, k + 7, 5);
		world.setBlock(i + 3, j + 0, k + 6, 5);
		world.setBlock(i + 3, j + 0, k + 5, 5);
		world.setBlock(i + 3, j + 0, k + 4, 5);
		world.setBlock(i + 3, j + 0, k + 3, 5);
		world.setBlock(i + 3, j + 0, k + 2, 5);
		world.setBlock(i + 3, j + 0, k + 1, 5);
		world.setBlock(i + 4, j + 0, k + 19, 5);
		world.setBlock(i + 4, j + 0, k + 18, 5);
		world.setBlock(i + 4, j + 0, k + 17, 5);
		world.setBlock(i + 4, j + 0, k + 16, 5);
		world.setBlock(i + 4, j + 0, k + 15, 5);
		world.setBlock(i + 4, j + 0, k + 14, 5);
		world.setBlock(i + 4, j + 0, k + 13, 5);
		world.setBlock(i + 4, j + 0, k + 12, 5);
		world.setBlock(i + 4, j + 0, k + 11, 5);
		world.setBlock(i + 4, j + 0, k + 10, 5);
		world.setBlock(i + 4, j + 0, k + 9, 5);
		world.setBlock(i + 4, j + 0, k + 8, 5);
		world.setBlock(i + 4, j + 0, k + 7, 5);
		world.setBlock(i + 4, j + 0, k + 6, 5);
		world.setBlock(i + 4, j + 0, k + 5, 5);
		world.setBlock(i + 4, j + 0, k + 4, 5);
		world.setBlock(i + 4, j + 0, k + 3, 5);
		world.setBlock(i + 4, j + 0, k + 2, 5);
		world.setBlock(i + 4, j + 0, k + 1, 5);
		world.setBlock(i + 4, j + 0, k + 0, 5);
		world.setBlock(i + 5, j + 0, k + 22, 17);
		world.setBlock(i + 5, j + 0, k + 21, 17);
		world.setBlock(i + 5, j + 0, k + 20, 17);
		world.setBlock(i + 5, j + 0, k + 19, 17);
		world.setBlock(i + 5, j + 0, k + 18, 17);
		world.setBlock(i + 5, j + 0, k + 17, 17);
		world.setBlock(i + 5, j + 0, k + 16, 17);
		world.setBlock(i + 5, j + 0, k + 15, 17);
		world.setBlock(i + 5, j + 0, k + 14, 17);
		world.setBlock(i + 5, j + 0, k + 13, 17);
		world.setBlock(i + 5, j + 0, k + 12, 17);
		world.setBlock(i + 5, j + 0, k + 11, 17);
		world.setBlock(i + 5, j + 0, k + 10, 17);
		world.setBlock(i + 5, j + 0, k + 9, 17);
		world.setBlock(i + 5, j + 0, k + 8, 17);
		world.setBlock(i + 5, j + 0, k + 7, 17);
		world.setBlock(i + 5, j + 0, k + 6, 17);
		world.setBlock(i + 5, j + 0, k + 5, 17);
		world.setBlock(i + 5, j + 0, k + 4, 17);
		world.setBlock(i + 5, j + 0, k + 3, 17);
		world.setBlock(i + 5, j + 0, k + 2, 17);
		world.setBlock(i + 5, j + 0, k + 1, 17);
		world.setBlock(i + 5, j + 0, k + 0, 17);
		world.setBlock(i + 6, j + 0, k + 19, 5);
		world.setBlock(i + 6, j + 0, k + 18, 5);
		world.setBlock(i + 6, j + 0, k + 17, 5);
		world.setBlock(i + 6, j + 0, k + 16, 5);
		world.setBlock(i + 6, j + 0, k + 15, 5);
		world.setBlock(i + 6, j + 0, k + 14, 5);
		world.setBlock(i + 6, j + 0, k + 13, 5);
		world.setBlock(i + 6, j + 0, k + 12, 5);
		world.setBlock(i + 6, j + 0, k + 11, 5);
		world.setBlock(i + 6, j + 0, k + 10, 5);
		world.setBlock(i + 6, j + 0, k + 9, 5);
		world.setBlock(i + 6, j + 0, k + 8, 5);
		world.setBlock(i + 6, j + 0, k + 7, 5);
		world.setBlock(i + 6, j + 0, k + 6, 5);
		world.setBlock(i + 6, j + 0, k + 5, 5);
		world.setBlock(i + 6, j + 0, k + 4, 5);
		world.setBlock(i + 6, j + 0, k + 3, 5);
		world.setBlock(i + 6, j + 0, k + 2, 5);
		world.setBlock(i + 6, j + 0, k + 1, 5);
		world.setBlock(i + 6, j + 0, k + 0, 5);
		world.setBlock(i + 7, j + 0, k + 15, 5);
		world.setBlock(i + 7, j + 0, k + 14, 5);
		world.setBlock(i + 7, j + 0, k + 13, 5);
		world.setBlock(i + 7, j + 0, k + 12, 5);
		world.setBlock(i + 7, j + 0, k + 11, 5);
		world.setBlock(i + 7, j + 0, k + 10, 5);
		world.setBlock(i + 7, j + 0, k + 9, 5);
		world.setBlock(i + 7, j + 0, k + 8, 5);
		world.setBlock(i + 7, j + 0, k + 7, 5);
		world.setBlock(i + 7, j + 0, k + 6, 5);
		world.setBlock(i + 7, j + 0, k + 5, 5);
		world.setBlock(i + 7, j + 0, k + 4, 5);
		world.setBlock(i + 7, j + 0, k + 3, 5);
		world.setBlock(i + 7, j + 0, k + 2, 5);
		world.setBlock(i + 7, j + 0, k + 1, 5);
		world.setBlock(i + 2, j + 1, k + 15, 5);
		world.setBlock(i + 2, j + 1, k + 14, 5);
		world.setBlock(i + 2, j + 1, k + 13, 5);
		world.setBlock(i + 2, j + 1, k + 12, 5);
		world.setBlock(i + 2, j + 1, k + 11, 5);
		world.setBlock(i + 2, j + 1, k + 10, 5);
		world.setBlock(i + 2, j + 1, k + 9, 5);
		world.setBlock(i + 2, j + 1, k + 8, 5);
		world.setBlock(i + 2, j + 1, k + 7, 5);
		world.setBlock(i + 2, j + 1, k + 6, 5);
		world.setBlock(i + 2, j + 1, k + 5, 5);
		world.setBlock(i + 2, j + 1, k + 4, 5);
		world.setBlock(i + 2, j + 1, k + 3, 5);
		world.setBlock(i + 2, j + 1, k + 2, 5);
		world.setBlock(i + 2, j + 1, k + 1, 5);
		world.setBlock(i + 2, j + 1, k + 0, 5);
		world.setBlock(i + 3, j + 1, k + 19, 5);
		world.setBlock(i + 3, j + 1, k + 18, 5);
		world.setBlock(i + 3, j + 1, k + 17, 5);
		world.setBlock(i + 3, j + 1, k + 16, 5);
		world.setBlock(i + 3, j + 1, k + 10, 5);
		world.setBlock(i + 3, j + 1, k + 0, 5);
		world.setBlock(i + 4, j + 1, k + 23, 5);
		world.setBlock(i + 4, j + 1, k + 22, 5);
		world.setBlock(i + 4, j + 1, k + 21, 5);
		world.setBlock(i + 4, j + 1, k + 20, 5);
		world.setBlock(i + 4, j + 1, k + 10, 5);
		world.setBlock(i + 4, j + 1, k + 0, 5);
		world.setBlock(i + 5, j + 1, k + 25, 17);
		world.setBlock(i + 5, j + 1, k + 24, 17);
		world.setBlock(i + 5, j + 1, k + 23, 17);
		world.setBlock(i + 5, j + 1, k + 11, 65);
		world.setBlock(i + 5, j + 1, k + 10, 5);
		world.setBlock(i + 5, j + 1, k + 0, 5);
		world.setBlock(i + 6, j + 1, k + 23, 5);
		world.setBlock(i + 6, j + 1, k + 22, 5);
		world.setBlock(i + 6, j + 1, k + 21, 5);
		world.setBlock(i + 6, j + 1, k + 20, 5);
		world.setBlock(i + 6, j + 1, k + 10, 5);
		world.setBlock(i + 6, j + 1, k + 0, 5);
		world.setBlock(i + 7, j + 1, k + 19, 5);
		world.setBlock(i + 7, j + 1, k + 18, 5);
		world.setBlock(i + 7, j + 1, k + 17, 5);
		world.setBlock(i + 7, j + 1, k + 16, 5);
		world.setBlock(i + 7, j + 1, k + 10, 5);
		world.setBlock(i + 7, j + 1, k + 0, 5);
		world.setBlock(i + 8, j + 1, k + 15, 5);
		world.setBlock(i + 8, j + 1, k + 14, 5);
		world.setBlock(i + 8, j + 1, k + 13, 5);
		world.setBlock(i + 8, j + 1, k + 12, 5);
		world.setBlock(i + 8, j + 1, k + 11, 5);
		world.setBlock(i + 8, j + 1, k + 10, 5);
		world.setBlock(i + 8, j + 1, k + 9, 5);
		world.setBlock(i + 8, j + 1, k + 8, 5);
		world.setBlock(i + 8, j + 1, k + 7, 5);
		world.setBlock(i + 8, j + 1, k + 6, 5);
		world.setBlock(i + 8, j + 1, k + 5, 5);
		world.setBlock(i + 8, j + 1, k + 4, 5);
		world.setBlock(i + 8, j + 1, k + 3, 5);
		world.setBlock(i + 8, j + 1, k + 2, 5);
		world.setBlock(i + 8, j + 1, k + 1, 5);
		world.setBlock(i + 8, j + 1, k + 0, 5);
		world.setBlock(i + 1, j + 2, k + 15, 5);
		world.setBlock(i + 1, j + 2, k + 14, 5);
		world.setBlock(i + 1, j + 2, k + 13, 20);
		world.setBlock(i + 1, j + 2, k + 12, 5);
		world.setBlock(i + 1, j + 2, k + 11, 5);
		world.setBlock(i + 1, j + 2, k + 10, 5);
		world.setBlock(i + 1, j + 2, k + 9, 5);
		world.setBlock(i + 1, j + 2, k + 8, 5);
		world.setBlock(i + 1, j + 2, k + 7, 5);
		world.setBlock(i + 1, j + 2, k + 6, 5);
		world.setBlock(i + 1, j + 2, k + 5, 5);
		world.setBlock(i + 1, j + 2, k + 4, 5);
		world.setBlock(i + 1, j + 2, k + 3, 5);
		world.setBlock(i + 1, j + 2, k + 2, 5);
		world.setBlock(i + 1, j + 2, k + 1, 5);
		world.setBlock(i + 2, j + 2, k + 19, 5);
		world.setBlock(i + 2, j + 2, k + 18, 20);
		world.setBlock(i + 2, j + 2, k + 17, 5);
		world.setBlock(i + 2, j + 2, k + 16, 5);
		world.setBlock(i + 2, j + 2, k + 10, 5);
		world.setBlock(i + 2, j + 2, k + 9, 5);
		world.setBlock(i + 2, j + 2, k + 8, 5);
		world.setBlock(i + 2, j + 2, k + 7, 5);
		world.setBlock(i + 2, j + 2, k + 0, 5);
		world.setBlock(i + 3, j + 2, k + 23, 5);
		world.setBlock(i + 3, j + 2, k + 22, 5);
		world.setBlock(i + 3, j + 2, k + 21, 5);
		world.setBlock(i + 3, j + 2, k + 20, 5);
		world.setBlock(i + 3, j + 2, k + 10, 5);
		world.setBlock(i + 3, j + 2, k + 9, 5);
		world.setBlock(i + 3, j + 2, k + 8, 5);
		world.setBlock(i + 3, j + 2, k + 7, 5);
		world.setBlock(i + 3, j + 2, k + 0, 5);
		world.setBlock(i + 4, j + 2, k + 26, 5);
		world.setBlock(i + 4, j + 2, k + 25, 5);
		world.setBlock(i + 4, j + 2, k + 24, 5);
		world.setBlock(i + 4, j + 2, k + 10, 5);
		world.setBlock(i + 4, j + 2, k + 9, 5);
		world.setBlock(i + 4, j + 2, k + 8, 5);
		world.setBlock(i + 4, j + 2, k + 7, 5);
		world.setBlock(i + 4, j + 2, k + 0, 5);
		world.setBlock(i + 5, j + 2, k + 27, 17);
		world.setBlock(i + 5, j + 2, k + 26, 17);
		world.setBlock(i + 5, j + 2, k + 11, 65);
		world.setBlock(i + 5, j + 2, k + 10, 5);
		world.setBlock(i + 5, j + 2, k + 9, 5);
		world.setBlock(i + 5, j + 2, k + 8, 5);
		world.setBlock(i + 5, j + 2, k + 7, 5);
		world.setBlock(i + 5, j + 2, k + 0, 5);
		world.setBlock(i + 6, j + 2, k + 26, 5);
		world.setBlock(i + 6, j + 2, k + 25, 5);
		world.setBlock(i + 6, j + 2, k + 24, 5);
	
		world.setBlock(i + 6, j + 2, k + 10, 5);
		world.setBlock(i + 6, j + 2, k + 9, 5);
		world.setBlock(i + 6, j + 2, k + 8, 5);
		world.setBlock(i + 6, j + 2, k + 7, 5);
		world.setBlock(i + 6, j + 2, k + 0, 5);
		world.setBlock(i + 7, j + 2, k + 23, 5);
		world.setBlock(i + 7, j + 2, k + 22, 5);
		world.setBlock(i + 7, j + 2, k + 21, 5);
		world.setBlock(i + 7, j + 2, k + 20, 5);
		world.setBlock(i + 7, j + 2, k + 10, 5);
		world.setBlock(i + 7, j + 2, k + 9, 5);
		world.setBlock(i + 7, j + 2, k + 8, 5);
		world.setBlock(i + 7, j + 2, k + 7, 5);
		world.setBlock(i + 7, j + 2, k + 0, 5);
		world.setBlock(i + 8, j + 2, k + 19, 5);
		world.setBlock(i + 8, j + 2, k + 18, 20);
		world.setBlock(i + 8, j + 2, k + 17, 5);
		world.setBlock(i + 8, j + 2, k + 16, 5);
		world.setBlock(i + 8, j + 2, k + 10, 5);
		world.setBlock(i + 8, j + 2, k + 9, 5);
		world.setBlock(i + 8, j + 2, k + 8, 5);
		world.setBlock(i + 8, j + 2, k + 7, 5);
		world.setBlock(i + 8, j + 2, k + 0, 5);
		world.setBlock(i + 9, j + 2, k + 15, 5);
		world.setBlock(i + 9, j + 2, k + 14, 5);
		world.setBlock(i + 9, j + 2, k + 13, 20);
		world.setBlock(i + 9, j + 2, k + 12, 5);
		world.setBlock(i + 9, j + 2, k + 11, 5);
		world.setBlock(i + 9, j + 2, k + 10, 5);
		world.setBlock(i + 9, j + 2, k + 9, 5);
		world.setBlock(i + 9, j + 2, k + 8, 5);
		world.setBlock(i + 9, j + 2, k + 7, 5);
		world.setBlock(i + 9, j + 2, k + 6, 5);
		world.setBlock(i + 9, j + 2, k + 5, 5);
		world.setBlock(i + 9, j + 2, k + 4, 5);
		world.setBlock(i + 9, j + 2, k + 3, 5);
		world.setBlock(i + 9, j + 2, k + 2, 5);
		world.setBlock(i + 9, j + 2, k + 1, 5);
		world.setBlock(i + 1, j + 3, k + 19, 5);
		world.setBlock(i + 1, j + 3, k + 18, 5);
		world.setBlock(i + 1, j + 3, k + 17, 5);
		world.setBlock(i + 1, j + 3, k + 16, 5);
		world.setBlock(i + 1, j + 3, k + 15, 5);
		world.setBlock(i + 1, j + 3, k + 14, 5);
		world.setBlock(i + 1, j + 3, k + 13, 5);
		world.setBlock(i + 1, j + 3, k + 12, 5);
		world.setBlock(i + 1, j + 3, k + 11, 5);
		world.setBlock(i + 1, j + 3, k + 10, 5);
		world.setBlock(i + 1, j + 3, k + 9, 5);
		world.setBlock(i + 1, j + 3, k + 8, 5);
		world.setBlock(i + 1, j + 3, k + 7, 5);
		world.setBlock(i + 1, j + 3, k + 6, 5);
		world.setBlock(i + 1, j + 3, k + 5, 5);
		world.setBlock(i + 1, j + 3, k + 4, 5);
		world.setBlock(i + 1, j + 3, k + 3, 5);
		world.setBlock(i + 1, j + 3, k + 2, 5);
		world.setBlock(i + 1, j + 3, k + 1, 5);
		world.setBlock(i + 2, j + 3, k + 23, 5);
		world.setBlock(i + 2, j + 3, k + 22, 5);
		world.setBlock(i + 2, j + 3, k + 21, 5);
		world.setBlock(i + 2, j + 3, k + 20, 5);
		world.setBlock(i + 2, j + 3, k + 10, 5);
		world.setBlock(i + 2, j + 3, k + 0, 5);
		world.setBlock(i + 3, j + 3, k + 26, 5);
		world.setBlock(i + 3, j + 3, k + 25, 5);
		world.setBlock(i + 3, j + 3, k + 24, 5);
		world.setBlock(i + 3, j + 3, k + 10, 5);
		world.setBlock(i + 3, j + 3, k + 0, 5);
		world.setBlock(i + 4, j + 3, k + 28, 5);
		world.setBlock(i + 4, j + 3, k + 27, 5);
		world.setBlock(i + 4, j + 3, k + 10, 5);
		world.setBlock(i + 4, j + 3, k + 0, 5);
		world.setBlock(i + 5, j + 3, k + 30, 17);
		world.setBlock(i + 5, j + 3, k + 29, 17);
		world.setBlock(i + 5, j + 3, k + 28, 17);
		world.setBlock(i + 5, j + 3, k + 11, 65);
		world.setBlock(i + 5, j + 3, k + 10, 5);
		world.setBlock(i + 5, j + 3, k + 0, 5);
		world.setBlock(i + 6, j + 3, k + 28, 5);
		world.setBlock(i + 6, j + 3, k + 27, 5);
		world.setBlock(i + 6, j + 3, k + 10, 5);
		world.setBlock(i + 6, j + 3, k + 0, 5);
		world.setBlock(i + 7, j + 3, k + 26, 5);
		world.setBlock(i + 7, j + 3, k + 25, 5);
		world.setBlock(i + 7, j + 3, k + 24, 5);
		world.setBlock(i + 7, j + 3, k + 10, 5);
		world.setBlock(i + 7, j + 3, k + 0, 5);
		world.setBlock(i + 8, j + 3, k + 23, 5);
		world.setBlock(i + 8, j + 3, k + 22, 5);
		world.setBlock(i + 8, j + 3, k + 21, 5);
		world.setBlock(i + 8, j + 3, k + 20, 5);
		world.setBlock(i + 8, j + 3, k + 10, 5);
		world.setBlock(i + 8, j + 3, k + 0, 5);
		world.setBlock(i + 9, j + 3, k + 19, 5);
		world.setBlock(i + 9, j + 3, k + 18, 5);
		world.setBlock(i + 9, j + 3, k + 17, 5);
		world.setBlock(i + 9, j + 3, k + 16, 5);
		world.setBlock(i + 9, j + 3, k + 15, 5);
		world.setBlock(i + 9, j + 3, k + 14, 5);
		world.setBlock(i + 9, j + 3, k + 13, 5);
		world.setBlock(i + 9, j + 3, k + 12, 5);
		world.setBlock(i + 9, j + 3, k + 11, 5);
		world.setBlock(i + 9, j + 3, k + 10, 5);
		world.setBlock(i + 9, j + 3, k + 9, 5);
		world.setBlock(i + 9, j + 3, k + 8, 5);
		world.setBlock(i + 9, j + 3, k + 7, 5);
		world.setBlock(i + 9, j + 3, k + 6, 5);
		world.setBlock(i + 9, j + 3, k + 5, 5);
		world.setBlock(i + 9, j + 3, k + 4, 5);
		world.setBlock(i + 9, j + 3, k + 3, 5);
		world.setBlock(i + 9, j + 3, k + 2, 5);
		world.setBlock(i + 9, j + 3, k + 1, 5);
		world.setBlock(i + 1, j + 4, k + 21, 5);
		world.setBlock(i + 1, j + 4, k + 20, 5);
		world.setBlock(i + 1, j + 4, k + 19, 5);
		world.setBlock(i + 1, j + 4, k + 18, 5);
		world.setBlock(i + 1, j + 4, k + 17, 5);
		world.setBlock(i + 1, j + 4, k + 16, 5);
		world.setBlock(i + 1, j + 4, k + 15, 5);
		world.setBlock(i + 1, j + 4, k + 14, 5);
		world.setBlock(i + 1, j + 4, k + 13, 5);
		world.setBlock(i + 1, j + 4, k + 12, 5);
		world.setBlock(i + 1, j + 4, k + 11, 5);
		world.setBlock(i + 1, j + 4, k + 10, 5);
		world.setBlock(i + 1, j + 4, k + 9, 5);
		world.setBlock(i + 1, j + 4, k + 8, 5);
		world.setBlock(i + 1, j + 4, k + 7, 5);
		world.setBlock(i + 1, j + 4, k + 6, 5);
		world.setBlock(i + 1, j + 4, k + 5, 5);
		world.setBlock(i + 1, j + 4, k + 4, 5);
		world.setBlock(i + 1, j + 4, k + 3, 5);
		world.setBlock(i + 1, j + 4, k + 2, 5);
		world.setBlock(i + 1, j + 4, k + 1, 5);
		world.setBlock(i + 2, j + 4, k + 28, 5);
		world.setBlock(i + 2, j + 4, k + 27, 5);
		world.setBlock(i + 2, j + 4, k + 26, 5);
		world.setBlock(i + 2, j + 4, k + 25, 5);
		world.setBlock(i + 2, j + 4, k + 24, 5);
		world.setBlock(i + 2, j + 4, k + 23, 5);
		world.setBlock(i + 2, j + 4, k + 22, 5);
		world.setBlock(i + 2, j + 4, k + 21, 5);
		world.setBlock(i + 2, j + 4, k + 20, 5);
		world.setBlock(i + 2, j + 4, k + 19, 5);
		world.setBlock(i + 2, j + 4, k + 18, 5);
		world.setBlock(i + 2, j + 4, k + 17, 5);
		world.setBlock(i + 2, j + 4, k + 16, 5);
		world.setBlock(i + 2, j + 4, k + 15, 5);
		world.setBlock(i + 2, j + 4, k + 14, 5);
		world.setBlock(i + 2, j + 4, k + 13, 5);
		world.setBlock(i + 2, j + 4, k + 12, 5);
		world.setBlock(i + 2, j + 4, k + 11, 5);
		world.setBlock(i + 2, j + 4, k + 10, 5);
		world.setBlock(i + 2, j + 4, k + 9, 5);
		world.setBlock(i + 2, j + 4, k + 8, 5);
		world.setBlock(i + 2, j + 4, k + 7, 5);
		world.setBlock(i + 2, j + 4, k + 6, 5);
		world.setBlock(i + 2, j + 4, k + 5, 5);
		world.setBlock(i + 2, j + 4, k + 4, 5);
		world.setBlock(i + 2, j + 4, k + 3, 5);
		world.setBlock(i + 2, j + 4, k + 2, 5);
		world.setBlock(i + 2, j + 4, k + 1, 5);
		world.setBlock(i + 2, j + 4, k + 0, 5);
		world.setBlock(i + 3, j + 4, k + 31, 17);
		world.setBlock(i + 3, j + 4, k + 30, 5);
		world.setBlock(i + 3, j + 4, k + 29, 5);
		world.setBlock(i + 3, j + 4, k + 28, 5);
		world.setBlock(i + 3, j + 4, k + 27, 5);
		world.setBlock(i + 3, j + 4, k + 26, 5);
		world.setBlock(i + 3, j + 4, k + 25, 5);
		world.setBlock(i + 3, j + 4, k + 24, 5);
		world.setBlock(i + 3, j + 4, k + 23, 5);
		world.setBlock(i + 3, j + 4, k + 22, 5);
		world.setBlock(i + 3, j + 4, k + 21, 5);
		world.setBlock(i + 3, j + 4, k + 20, 5);
		world.setBlock(i + 3, j + 4, k + 19, 5);
		world.setBlock(i + 3, j + 4, k + 18, 5);
		world.setBlock(i + 3, j + 4, k + 17, 5);
		world.setBlock(i + 3, j + 4, k + 16, 5);
		world.setBlock(i + 3, j + 4, k + 15, 5);
		world.setBlock(i + 3, j + 4, k + 14, 5);
		world.setBlock(i + 3, j + 4, k + 13, 5);
		world.setBlock(i + 3, j + 4, k + 12, 5);
		world.setBlock(i + 3, j + 4, k + 11, 5);
		world.setBlock(i + 3, j + 4, k + 10, 5);
		world.setBlock(i + 3, j + 4, k + 9, 5);
		world.setBlock(i + 3, j + 4, k + 8, 5);
		world.setBlock(i + 3, j + 4, k + 7, 5);
		world.setBlock(i + 3, j + 4, k + 6, 5);
		world.setBlock(i + 3, j + 4, k + 5, 5);
		world.setBlock(i + 3, j + 4, k + 4, 5);
		world.setBlock(i + 3, j + 4, k + 3, 5);
		world.setBlock(i + 3, j + 4, k + 2, 5);
		world.setBlock(i + 3, j + 4, k + 1, 5);
		world.setBlock(i + 3, j + 4, k + 0, 5);
		world.setBlock(i + 4, j + 4, k + 32, 17);
		world.setBlock(i + 4, j + 4, k + 31, 17);
		world.setBlock(i + 4, j + 4, k + 30, 5);
		world.setBlock(i + 4, j + 4, k + 29, 5);
		world.setBlock(i + 4, j + 4, k + 28, 5);
		world.setBlock(i + 4, j + 4, k + 27, 5);
		world.setBlock(i + 4, j + 4, k + 26, 5);
		world.setBlock(i + 4, j + 4, k + 25, 5);
		world.setBlock(i + 4, j + 4, k + 24, 5);
		world.setBlock(i + 4, j + 4, k + 23, 5);
		world.setBlock(i + 4, j + 4, k + 22, 5);
		world.setBlock(i + 4, j + 4, k + 21, 5);
		world.setBlock(i + 4, j + 4, k + 20, 5);
		world.setBlock(i + 4, j + 4, k + 19, 5);
		world.setBlock(i + 4, j + 4, k + 18, 5);
		world.setBlock(i + 4, j + 4, k + 17, 5);
		world.setBlock(i + 4, j + 4, k + 16, 5);
		world.setBlock(i + 4, j + 4, k + 15, 5);
		world.setBlock(i + 4, j + 4, k + 14, 5);
		world.setBlock(i + 4, j + 4, k + 13, 5);
		world.setBlock(i + 4, j + 4, k + 12, 5);
		world.setBlock(i + 4, j + 4, k + 11, 5);
		world.setBlock(i + 4, j + 4, k + 10, 5);
		world.setBlock(i + 4, j + 4, k + 9, 5);
		world.setBlock(i + 4, j + 4, k + 8, 5);
		world.setBlock(i + 4, j + 4, k + 7, 5);
		world.setBlock(i + 4, j + 4, k + 6, 5);
		world.setBlock(i + 4, j + 4, k + 5, 5);
		world.setBlock(i + 4, j + 4, k + 4, 5);
		world.setBlock(i + 4, j + 4, k + 3, 5);
		world.setBlock(i + 4, j + 4, k + 2, 5);
		world.setBlock(i + 4, j + 4, k + 1, 5);
		world.setBlock(i + 4, j + 4, k + 0, 5);
		world.setBlock(i + 5, j + 4, k + 33, 17);
		world.setBlock(i + 5, j + 4, k + 32, 17);
		world.setBlock(i + 5, j + 4, k + 31, 17);
		world.setBlock(i + 5, j + 4, k + 30, 5);
		world.setBlock(i + 5, j + 4, k + 29, 5);
		world.setBlock(i + 5, j + 4, k + 28, 5);
		world.setBlock(i + 5, j + 4, k + 27, 5);
		world.setBlock(i + 5, j + 4, k + 26, 5);
		world.setBlock(i + 5, j + 4, k + 25, 5);
		world.setBlock(i + 5, j + 4, k + 24, 5);
		world.setBlock(i + 5, j + 4, k + 23, 5);
		world.setBlock(i + 5, j + 4, k + 22, 5);
		world.setBlock(i + 5, j + 4, k + 21, 5);
		world.setBlock(i + 5, j + 4, k + 20, 5);
		world.setBlock(i + 5, j + 4, k + 19, 5);
		world.setBlock(i + 5, j + 4, k + 18, 5);
		world.setBlock(i + 5, j + 4, k + 17, 5);
		world.setBlock(i + 5, j + 4, k + 16, 5);
		world.setBlock(i + 5, j + 4, k + 15, 5);
		world.setBlock(i + 5, j + 4, k + 14, 5);
		world.setBlock(i + 5, j + 4, k + 13, 5);
		world.setBlock(i + 5, j + 4, k + 12, 5);
		world.setBlock(i + 5, j + 4, k + 11, 65);
		world.setBlock(i + 5, j + 4, k + 10, 5);
		world.setBlock(i + 5, j + 4, k + 9, 5);
		world.setBlock(i + 5, j + 4, k + 8, 5);
		world.setBlock(i + 5, j + 4, k + 7, 5);
		world.setBlock(i + 5, j + 4, k + 6, 5);
		world.setBlock(i + 5, j + 4, k + 5, 5);
		world.setBlock(i + 5, j + 4, k + 4, 5);
		world.setBlock(i + 5, j + 4, k + 3, 5);
		world.setBlock(i + 5, j + 4, k + 2, 5);
		world.setBlock(i + 5, j + 4, k + 1, 5);
		world.setBlock(i + 5, j + 4, k + 0, 5);
		world.setBlock(i + 6, j + 4, k + 32, 17);
		world.setBlock(i + 6, j + 4, k + 31, 17);
		world.setBlock(i + 6, j + 4, k + 30, 5);
		world.setBlock(i + 6, j + 4, k + 29, 5);
		world.setBlock(i + 6, j + 4, k + 28, 5);
		world.setBlock(i + 6, j + 4, k + 27, 5);
		world.setBlock(i + 6, j + 4, k + 26, 5);
		world.setBlock(i + 6, j + 4, k + 25, 5);
		world.setBlock(i + 6, j + 4, k + 24, 5);
		world.setBlock(i + 6, j + 4, k + 23, 5);
		world.setBlock(i + 6, j + 4, k + 22, 5);
		world.setBlock(i + 6, j + 4, k + 21, 5);
		world.setBlock(i + 6, j + 4, k + 20, 5);
		world.setBlock(i + 6, j + 4, k + 19, 5);
		world.setBlock(i + 6, j + 4, k + 18, 5);
		world.setBlock(i + 6, j + 4, k + 17, 5);
		world.setBlock(i + 6, j + 4, k + 16, 5);
		world.setBlock(i + 6, j + 4, k + 15, 5);
		world.setBlock(i + 6, j + 4, k + 14, 5);
		world.setBlock(i + 6, j + 4, k + 13, 5);
		world.setBlock(i + 6, j + 4, k + 12, 5);
		world.setBlock(i + 6, j + 4, k + 11, 5);
		world.setBlock(i + 6, j + 4, k + 10, 5);
		world.setBlock(i + 6, j + 4, k + 9, 5);
		world.setBlock(i + 6, j + 4, k + 8, 5);
		world.setBlock(i + 6, j + 4, k + 7, 5);
		world.setBlock(i + 6, j + 4, k + 6, 5);
		world.setBlock(i + 6, j + 4, k + 5, 5);
		world.setBlock(i + 6, j + 4, k + 4, 5);
		world.setBlock(i + 6, j + 4, k + 3, 5);
		world.setBlock(i + 6, j + 4, k + 2, 5);
		world.setBlock(i + 6, j + 4, k + 1, 5);
		world.setBlock(i + 6, j + 4, k + 0, 5);
		world.setBlock(i + 7, j + 4, k + 31, 17);
		world.setBlock(i + 7, j + 4, k + 30, 5);
		world.setBlock(i + 7, j + 4, k + 29, 5);
		world.setBlock(i + 7, j + 4, k + 28, 5);
		world.setBlock(i + 7, j + 4, k + 27, 5);
		world.setBlock(i + 7, j + 4, k + 26, 5);
		world.setBlock(i + 7, j + 4, k + 25, 5);
		world.setBlock(i + 7, j + 4, k + 24, 5);
		world.setBlock(i + 7, j + 4, k + 23, 5);
		world.setBlock(i + 7, j + 4, k + 22, 5);
		world.setBlock(i + 7, j + 4, k + 21, 5);
		world.setBlock(i + 7, j + 4, k + 20, 5);
		world.setBlock(i + 7, j + 4, k + 19, 5);
		world.setBlock(i + 7, j + 4, k + 18, 5);
		world.setBlock(i + 7, j + 4, k + 17, 5);
		world.setBlock(i + 7, j + 4, k + 16, 5);
		world.setBlock(i + 7, j + 4, k + 15, 5);
		world.setBlock(i + 7, j + 4, k + 14, 5);
		world.setBlock(i + 7, j + 4, k + 13, 5);
		world.setBlock(i + 7, j + 4, k + 12, 5);
		world.setBlock(i + 7, j + 4, k + 11, 5);
		world.setBlock(i + 7, j + 4, k + 10, 5);
		world.setBlock(i + 7, j + 4, k + 9, 5);
		world.setBlock(i + 7, j + 4, k + 8, 5);
		world.setBlock(i + 7, j + 4, k + 7, 5);
		world.setBlock(i + 7, j + 4, k + 6, 5);
		world.setBlock(i + 7, j + 4, k + 5, 5);
		world.setBlock(i + 7, j + 4, k + 4, 5);
		world.setBlock(i + 7, j + 4, k + 3, 5);
		world.setBlock(i + 7, j + 4, k + 2, 5);
		world.setBlock(i + 7, j + 4, k + 1, 5);
		world.setBlock(i + 7, j + 4, k + 0, 5);
		world.setBlock(i + 8, j + 4, k + 28, 5);
		world.setBlock(i + 8, j + 4, k + 27, 5);
		world.setBlock(i + 8, j + 4, k + 26, 5);
		world.setBlock(i + 8, j + 4, k + 25, 5);
		world.setBlock(i + 8, j + 4, k + 24, 5);
		world.setBlock(i + 8, j + 4, k + 23, 5);
		world.setBlock(i + 8, j + 4, k + 22, 5);
		world.setBlock(i + 8, j + 4, k + 21, 5);
		world.setBlock(i + 8, j + 4, k + 20, 5);
		world.setBlock(i + 8, j + 4, k + 19, 5);
		world.setBlock(i + 8, j + 4, k + 18, 5);
		world.setBlock(i + 8, j + 4, k + 17, 5);
		world.setBlock(i + 8, j + 4, k + 16, 5);
		world.setBlock(i + 8, j + 4, k + 15, 5);
		world.setBlock(i + 8, j + 4, k + 14, 5);
		world.setBlock(i + 8, j + 4, k + 13, 5);
		world.setBlock(i + 8, j + 4, k + 12, 5);
		world.setBlock(i + 8, j + 4, k + 11, 5);
		world.setBlock(i + 8, j + 4, k + 10, 5);
		world.setBlock(i + 8, j + 4, k + 9, 5);
		world.setBlock(i + 8, j + 4, k + 8, 5);
		world.setBlock(i + 8, j + 4, k + 7, 5);
		world.setBlock(i + 8, j + 4, k + 6, 5);
		world.setBlock(i + 8, j + 4, k + 5, 5);
		world.setBlock(i + 8, j + 4, k + 4, 5);
		world.setBlock(i + 8, j + 4, k + 3, 5);
		world.setBlock(i + 8, j + 4, k + 2, 5);
		world.setBlock(i + 8, j + 4, k + 1, 5);
		world.setBlock(i + 8, j + 4, k + 0, 5);
		world.setBlock(i + 9, j + 4, k + 21, 5);
		world.setBlock(i + 9, j + 4, k + 20, 5);
		world.setBlock(i + 9, j + 4, k + 19, 5);
		world.setBlock(i + 9, j + 4, k + 18, 5);
		world.setBlock(i + 9, j + 4, k + 17, 5);
		world.setBlock(i + 9, j + 4, k + 16, 5);
		world.setBlock(i + 9, j + 4, k + 15, 5);
		world.setBlock(i + 9, j + 4, k + 14, 5);
		world.setBlock(i + 9, j + 4, k + 13, 5);
		world.setBlock(i + 9, j + 4, k + 12, 5);
		world.setBlock(i + 9, j + 4, k + 11, 5);
		world.setBlock(i + 9, j + 4, k + 10, 5);
		world.setBlock(i + 9, j + 4, k + 9, 5);
		world.setBlock(i + 9, j + 4, k + 8, 5);
		world.setBlock(i + 9, j + 4, k + 7, 5);
		world.setBlock(i + 9, j + 4, k + 6, 5);
		world.setBlock(i + 9, j + 4, k + 5, 5);
		world.setBlock(i + 9, j + 4, k + 4, 5);
		world.setBlock(i + 9, j + 4, k + 3, 5);
		world.setBlock(i + 9, j + 4, k + 2, 5);
		world.setBlock(i + 9, j + 4, k + 1, 5);
		world.setBlock(i + 1, j + 5, k + 21, 85);
		world.setBlock(i + 1, j + 5, k + 20, 85);
		world.setBlock(i + 1, j + 5, k + 19, 85);
		world.setBlock(i + 1, j + 5, k + 18, 85);
		world.setBlock(i + 1, j + 5, k + 17, 85);
		world.setBlock(i + 1, j + 5, k + 16, 85);
		world.setBlock(i + 1, j + 5, k + 15, 85);
		world.setBlock(i + 1, j + 5, k + 14, 85);
		world.setBlock(i + 1, j + 5, k + 13, 85);
		world.setBlock(i + 1, j + 5, k + 12, 85);
		world.setBlock(i + 1, j + 5, k + 11, 85);
		world.setBlock(i + 1, j + 5, k + 10, 85);
		world.setBlock(i + 1, j + 5, k + 9, 85);
		world.setBlock(i + 1, j + 5, k + 8, 5);
		world.setBlock(i + 1, j + 5, k + 7, 5);
		world.setBlock(i + 1, j + 5, k + 6, 5);
		world.setBlock(i + 1, j + 5, k + 5, 5);
		world.setBlock(i + 1, j + 5, k + 4, 5);
		world.setBlock(i + 1, j + 5, k + 3, 5);
		world.setBlock(i + 1, j + 5, k + 2, 5);
		world.setBlock(i + 1, j + 5, k + 1, 5);
		world.setBlock(i + 2, j + 5, k + 28, 85);
		world.setBlock(i + 2, j + 5, k + 27, 85);
		world.setBlock(i + 2, j + 5, k + 26, 85);
		world.setBlock(i + 2, j + 5, k + 25, 85);
		world.setBlock(i + 2, j + 5, k + 24, 85);
		world.setBlock(i + 2, j + 5, k + 23, 85);
		world.setBlock(i + 2, j + 5, k + 22, 85);
		world.setBlock(i + 2, j + 5, k + 21, 85);
		world.setBlock(i + 2, j + 5, k + 19, 78);
		world.setBlock(i + 2, j + 5, k + 15, 78);
		world.setBlock(i + 2, j + 5, k + 13, 78);

		world.setBlock(i + 2, j + 5, k + 7, 5);
		world.setBlock(i + 2, j + 5, k + 4, 5);
	
		world.setBlock(i + 2, j + 5, k + 0, 5);
		world.setBlock(i + 3, j + 5, k + 31, 17);
		world.setBlock(i + 3, j + 5, k + 30, 85);
		world.setBlock(i + 3, j + 5, k + 29, 85);
		world.setBlock(i + 3, j + 5, k + 28, 85);
		world.setBlock(i + 3, j + 5, k + 24, 78);
		world.setBlock(i + 3, j + 5, k + 22, 78);
		world.setBlock(i + 3, j + 5, k + 18, 78);
		world.setBlock(i + 3, j + 5, k + 12, 78);
		world.setBlock(i + 3, j + 5, k + 11, 78);
		world.setBlock(i + 3, j + 5, k + 9, 78);
		world.setBlock(i + 3, j + 5, k + 8, 5);
		world.setBlock(i + 3, j + 5, k + 7, 5);
		world.setBlock(i + 3, j + 5, k + 6, 5);
		world.setBlock(i + 3, j + 5, k + 5, 5);
		world.setBlock(i + 3, j + 5, k + 4, 5);
		world.setBlock(i + 3, j + 5, k + 3, 5);
		world.setBlock(i + 3, j + 5, k + 1, 5);
		world.setBlock(i + 3, j + 5, k + 0, 5);
		world.setBlock(i + 4, j + 5, k + 33, 17);
		world.setBlock(i + 4, j + 5, k + 32, 17);
		world.setBlock(i + 4, j + 5, k + 31, 17);
		world.setBlock(i + 4, j + 5, k + 26, 78);
		world.setBlock(i + 4, j + 5, k + 24, 78);
		world.setBlock(i + 4, j + 5, k + 22, 44);
		world.setBlock(i + 4, j + 5, k + 20, 78);
		world.setBlock(i + 4, j + 5, k + 16, 78);
		world.setBlock(i + 4, j + 5, k + 14, 44);
		world.setBlock(i + 4, j + 5, k + 12, 78);
		world.setBlock(i + 4, j + 5, k + 8, 5);
		world.setBlock(i + 4, j + 5, k + 1, 68);
		world.setBlock(i + 4, j + 5, k + 0, 20);
		world.setBlock(i + 5, j + 5, k + 34, 17);
		world.setBlock(i + 5, j + 5, k + 33, 17);
		world.setBlock(i + 5, j + 5, k + 32, 17);
		world.setBlock(i + 5, j + 5, k + 29, 78);
		world.setBlock(i + 5, j + 5, k + 28, 78);
		world.setBlock(i + 5, j + 5, k + 24, 78);
		world.setBlock(i + 5, j + 5, k + 23, 44);
		world.setBlock(i + 5, j + 5, k + 22, 1);
		world.setBlock(i + 5, j + 5, k + 21, 44);
		world.setBlock(i + 5, j + 5, k + 15, 44);
		world.setBlock(i + 5, j + 5, k + 14, 1);
		world.setBlock(i + 5, j + 5, k + 13, 44);
		world.setBlock(i + 5, j + 5, k + 12, 5);
		world.setBlock(i + 5, j + 5, k + 11, 96);
		world.setBlock(i + 5, j + 5, k + 9, 72);

		world.setBlock(i + 5, j + 5, k + 7, 72);
		world.setBlock(i + 5, j + 5, k + 5, 85);

		world.setBlock(i + 5, j + 5, k + 0, 20);
		world.setBlock(i + 6, j + 5, k + 33, 17);
		world.setBlock(i + 6, j + 5, k + 32, 17);
		world.setBlock(i + 6, j + 5, k + 31, 17);
		world.setBlock(i + 6, j + 5, k + 27, 78);
		world.setBlock(i + 6, j + 5, k + 22, 44);
		world.setBlock(i + 6, j + 5, k + 20, 78);
		world.setBlock(i + 6, j + 5, k + 19, 78);
		world.setBlock(i + 6, j + 5, k + 15, 78);
		world.setBlock(i + 6, j + 5, k + 14, 44);
		world.setBlock(i + 6, j + 5, k + 10, 78);
		world.setBlock(i + 6, j + 5, k + 8, 5);
		world.setBlock(i + 6, j + 5, k + 1, 68);
		world.setBlock(i + 6, j + 5, k + 0, 20);
		world.setBlock(i + 7, j + 5, k + 31, 17);
		world.setBlock(i + 7, j + 5, k + 30, 85);
		world.setBlock(i + 7, j + 5, k + 29, 85);
		world.setBlock(i + 7, j + 5, k + 28, 85);
		world.setBlock(i + 7, j + 5, k + 25, 78);
		world.setBlock(i + 7, j + 5, k + 23, 78);
		world.setBlock(i + 7, j + 5, k + 20, 78);
		world.setBlock(i + 7, j + 5, k + 19, 78);
		world.setBlock(i + 7, j + 5, k + 17, 78);
		world.setBlock(i + 7, j + 5, k + 12, 78);
		world.setBlock(i + 7, j + 5, k + 11, 78);
		world.setBlock(i + 7, j + 5, k + 8, 5);
		world.setBlock(i + 7, j + 5, k + 7, 5);
		world.setBlock(i + 7, j + 5, k + 6, 5);
		world.setBlock(i + 7, j + 5, k + 5, 5);
		world.setBlock(i + 7, j + 5, k + 4, 5);
		world.setBlock(i + 7, j + 5, k + 3, 5);
		world.setBlock(i + 7, j + 5, k + 1, 5);
		world.setBlock(i + 7, j + 5, k + 0, 5);
		world.setBlock(i + 8, j + 5, k + 28, 85);
		world.setBlock(i + 8, j + 5, k + 27, 85);
		world.setBlock(i + 8, j + 5, k + 26, 85);
		world.setBlock(i + 8, j + 5, k + 25, 85);
		world.setBlock(i + 8, j + 5, k + 24, 85);
		world.setBlock(i + 8, j + 5, k + 23, 85);
		world.setBlock(i + 8, j + 5, k + 22, 85);
		world.setBlock(i + 8, j + 5, k + 21, 85);
		world.setBlock(i + 8, j + 5, k + 18, 78);
		world.setBlock(i + 8, j + 5, k + 15, 78);
		world.setBlock(i + 8, j + 5, k + 12, 78);
		world.setBlock(i + 8, j + 5, k + 11, 78);

		world.setBlock(i + 8, j + 5, k + 7, 5);
		world.setBlock(i + 8, j + 5, k + 4, 5);
	
		world.setBlock(i + 8, j + 5, k + 0, 5);
		world.setBlock(i + 9, j + 5, k + 21, 85);
		world.setBlock(i + 9, j + 5, k + 20, 85);
		world.setBlock(i + 9, j + 5, k + 19, 85);
		world.setBlock(i + 9, j + 5, k + 18, 85);
		world.setBlock(i + 9, j + 5, k + 17, 85);
		world.setBlock(i + 9, j + 5, k + 16, 85);
		world.setBlock(i + 9, j + 5, k + 15, 85);
		world.setBlock(i + 9, j + 5, k + 14, 85);
		world.setBlock(i + 9, j + 5, k + 13, 85);
		world.setBlock(i + 9, j + 5, k + 12, 85);
		world.setBlock(i + 9, j + 5, k + 11, 85);
		world.setBlock(i + 9, j + 5, k + 10, 85);
		world.setBlock(i + 9, j + 5, k + 9, 85);
		world.setBlock(i + 9, j + 5, k + 8, 5);
		world.setBlock(i + 9, j + 5, k + 7, 5);
		world.setBlock(i + 9, j + 5, k + 6, 5);
		world.setBlock(i + 9, j + 5, k + 5, 5);
		world.setBlock(i + 9, j + 5, k + 4, 5);
		world.setBlock(i + 9, j + 5, k + 3, 5);
		world.setBlock(i + 9, j + 5, k + 2, 5);
		world.setBlock(i + 9, j + 5, k + 1, 5);
		world.setBlock(i + 1, j + 6, k + 8, 5);
		world.setBlock(i + 1, j + 6, k + 7, 5);
		world.setBlock(i + 1, j + 6, k + 6, 5);
		world.setBlock(i + 1, j + 6, k + 5, 5);
		world.setBlock(i + 1, j + 6, k + 4, 5);
		world.setBlock(i + 1, j + 6, k + 3, 5);
		world.setBlock(i + 1, j + 6, k + 2, 5);
		world.setBlock(i + 1, j + 6, k + 1, 5);

		world.setBlock(i + 2, j + 6, k + 6, 5);
		world.setBlock(i + 2, j + 6, k + 4, 5);
		world.setBlock(i + 2, j + 6, k + 0, 5);
		world.setBlock(i + 3, j + 6, k + 31, 78);
		world.setBlock(i + 3, j + 6, k + 8, 5);
		world.setBlock(i + 3, j + 6, k + 7, 5);
		world.setBlock(i + 3, j + 6, k + 6, 5);
		world.setBlock(i + 3, j + 6, k + 5, 5);
		world.setBlock(i + 3, j + 6, k + 4, 5);
		world.setBlock(i + 3, j + 6, k + 3, 5);
		world.setBlock(i + 3, j + 6, k + 1, 5);
		world.setBlock(i + 3, j + 6, k + 0, 5);
		world.setBlock(i + 4, j + 6, k + 33, 17);
		world.setBlock(i + 4, j + 6, k + 8, 20);
		world.setBlock(i + 4, j + 6, k + 5, 50);
		world.setBlock(i + 4, j + 6, k + 0, 20);
		world.setBlock(i + 5, j + 6, k + 34, 85);
		world.setBlock(i + 5, j + 6, k + 33, 17);
		world.setBlock(i + 5, j + 6, k + 22, 85);
		world.setBlock(i + 5, j + 6, k + 14, 85);

		world.setBlock(i + 5, j + 6, k + 5, 72);
		world.setBlock(i + 5, j + 6, k + 0, 20);
		world.setBlock(i + 6, j + 6, k + 33, 17);
		world.setBlock(i + 6, j + 6, k + 8, 20);
		world.setBlock(i + 6, j + 6, k + 5, 50);
		world.setBlock(i + 6, j + 6, k + 0, 20);
		world.setBlock(i + 7, j + 6, k + 8, 5);
		world.setBlock(i + 7, j + 6, k + 7, 5);
		world.setBlock(i + 7, j + 6, k + 6, 5);
		world.setBlock(i + 7, j + 6, k + 5, 5);
		world.setBlock(i + 7, j + 6, k + 4, 5);
		world.setBlock(i + 7, j + 6, k + 3, 5);
		world.setBlock(i + 7, j + 6, k + 1, 5);
		world.setBlock(i + 7, j + 6, k + 0, 5);

		world.setBlock(i + 8, j + 6, k + 6, 5);
		world.setBlock(i + 8, j + 6, k + 4, 5);
		world.setBlock(i + 8, j + 6, k + 0, 5);
		world.setBlock(i + 9, j + 6, k + 8, 5);
		world.setBlock(i + 9, j + 6, k + 7, 5);
		world.setBlock(i + 9, j + 6, k + 6, 5);
		world.setBlock(i + 9, j + 6, k + 5, 5);
		world.setBlock(i + 9, j + 6, k + 4, 5);
		world.setBlock(i + 9, j + 6, k + 3, 5);
		world.setBlock(i + 9, j + 6, k + 2, 5);
		world.setBlock(i + 9, j + 6, k + 1, 5);
		world.setBlock(i + 0, j + 7, k + 15, 35);
		world.setBlock(i + 1, j + 7, k + 15, 35);

		world.setBlock(i + 1, j + 7, k + 7, 5);
		world.setBlock(i + 1, j + 7, k + 6, 5);
		world.setBlock(i + 1, j + 7, k + 5, 5);
		world.setBlock(i + 1, j + 7, k + 4, 5);
		world.setBlock(i + 1, j + 7, k + 3, 5);
		world.setBlock(i + 1, j + 7, k + 2, 5);
		world.setBlock(i + 1, j + 7, k + 1, 5);
		world.setBlock(i + 2, j + 7, k + 15, 35);

		world.setBlock(i + 2, j + 7, k + 5, 5);
		world.setBlock(i + 2, j + 7, k + 4, 5);
		world.setBlock(i + 2, j + 7, k + 0, 5);
		world.setBlock(i + 3, j + 7, k + 15, 35);
		world.setBlock(i + 3, j + 7, k + 8, 5);
		world.setBlock(i + 3, j + 7, k + 7, 5);
		world.setBlock(i + 3, j + 7, k + 6, 5);
		world.setBlock(i + 3, j + 7, k + 5, 5);
		world.setBlock(i + 3, j + 7, k + 4, 5);
		world.setBlock(i + 3, j + 7, k + 3, 5);
		world.setBlock(i + 3, j + 7, k + 2, 5);
		world.setBlock(i + 3, j + 7, k + 1, 5);
		world.setBlock(i + 3, j + 7, k + 0, 5);
		world.setBlock(i + 4, j + 7, k + 33, 78);
		world.setBlock(i + 4, j + 7, k + 15, 35);
		world.setBlock(i + 4, j + 7, k + 8, 5);
		world.setBlock(i + 4, j + 7, k + 0, 20);
		world.setBlock(i + 5, j + 7, k + 34, 85);
		world.setBlock(i + 5, j + 7, k + 22, 85);
		world.setBlock(i + 5, j + 7, k + 15, 35);
		world.setBlock(i + 5, j + 7, k + 14, 85);
		world.setBlock(i + 5, j + 7, k + 8, 5);
		world.setBlock(i + 5, j + 7, k + 0, 20);
		world.setBlock(i + 6, j + 7, k + 15, 35);
		world.setBlock(i + 6, j + 7, k + 8, 5);
		world.setBlock(i + 6, j + 7, k + 0, 20);
		world.setBlock(i + 7, j + 7, k + 17, 79);
		world.setBlock(i + 7, j + 7, k + 15, 35);
		world.setBlock(i + 7, j + 7, k + 8, 5);
		world.setBlock(i + 7, j + 7, k + 7, 5);
		world.setBlock(i + 7, j + 7, k + 6, 5);
		world.setBlock(i + 7, j + 7, k + 5, 5);
		world.setBlock(i + 7, j + 7, k + 4, 5);
		world.setBlock(i + 7, j + 7, k + 3, 5);
		world.setBlock(i + 7, j + 7, k + 2, 5);
		world.setBlock(i + 7, j + 7, k + 1, 5);
		world.setBlock(i + 7, j + 7, k + 0, 5);
		world.setBlock(i + 8, j + 7, k + 15, 35);

		world.setBlock(i + 8, j + 7, k + 5, 5);
		world.setBlock(i + 8, j + 7, k + 4, 5);
		world.setBlock(i + 8, j + 7, k + 0, 5);
		world.setBlock(i + 9, j + 7, k + 15, 35);

		world.setBlock(i + 9, j + 7, k + 7, 5);
		world.setBlock(i + 9, j + 7, k + 6, 5);
		world.setBlock(i + 9, j + 7, k + 5, 5);
		world.setBlock(i + 9, j + 7, k + 4, 5);
		world.setBlock(i + 9, j + 7, k + 3, 5);
		world.setBlock(i + 9, j + 7, k + 2, 5);
		world.setBlock(i + 9, j + 7, k + 1, 5);
		world.setBlock(i + 10, j + 7, k + 15, 35);
		world.setBlock(i + 0, j + 8, k + 16, 35);
		world.setBlock(i + 1, j + 8, k + 16, 35);

		world.setBlock(i + 1, j + 8, k + 6, 17);
		world.setBlock(i + 1, j + 8, k + 5, 17);
		world.setBlock(i + 1, j + 8, k + 4, 17);
		world.setBlock(i + 1, j + 8, k + 3, 17);
		world.setBlock(i + 1, j + 8, k + 2, 17);
		world.setBlock(i + 1, j + 8, k + 1, 17);
		world.setBlock(i + 2, j + 8, k + 17, 79);
		world.setBlock(i + 2, j + 8, k + 16, 35);

		world.setBlock(i + 2, j + 8, k + 4, 17);
		world.setBlock(i + 2, j + 8, k + 3, 5);
		world.setBlock(i + 2, j + 8, k + 2, 5);
		world.setBlock(i + 2, j + 8, k + 1, 5);
		world.setBlock(i + 2, j + 8, k + 0, 17);
		world.setBlock(i + 3, j + 8, k + 23, 35);
		world.setBlock(i + 3, j + 8, k + 16, 35);
		world.setBlock(i + 3, j + 8, k + 8, 17);
		world.setBlock(i + 3, j + 8, k + 7, 17);
		world.setBlock(i + 3, j + 8, k + 6, 17);
		world.setBlock(i + 3, j + 8, k + 5, 17);
		world.setBlock(i + 3, j + 8, k + 4, 17);
		world.setBlock(i + 3, j + 8, k + 3, 5);
		world.setBlock(i + 3, j + 8, k + 2, 5);
		world.setBlock(i + 3, j + 8, k + 1, 5);
		world.setBlock(i + 3, j + 8, k + 0, 17);
		world.setBlock(i + 4, j + 8, k + 34, 85);
		world.setBlock(i + 4, j + 8, k + 23, 35);
		world.setBlock(i + 4, j + 8, k + 16, 35);
		world.setBlock(i + 4, j + 8, k + 8, 17);
		world.setBlock(i + 4, j + 8, k + 7, 5);
		world.setBlock(i + 4, j + 8, k + 6, 5);
		world.setBlock(i + 4, j + 8, k + 5, 5);
		world.setBlock(i + 4, j + 8, k + 4, 5);
		world.setBlock(i + 4, j + 8, k + 3, 5);
		world.setBlock(i + 4, j + 8, k + 2, 5);
		world.setBlock(i + 4, j + 8, k + 1, 5);
		world.setBlock(i + 4, j + 8, k + 0, 17);
		world.setBlock(i + 5, j + 8, k + 34, 85);
		world.setBlock(i + 5, j + 8, k + 33, 85);
		world.setBlock(i + 5, j + 8, k + 23, 35);
		world.setBlock(i + 5, j + 8, k + 22, 85);
		world.setBlock(i + 5, j + 8, k + 16, 35);
		world.setBlock(i + 5, j + 8, k + 14, 85);
		world.setBlock(i + 5, j + 8, k + 8, 17);
		world.setBlock(i + 5, j + 8, k + 7, 5);
		world.setBlock(i + 5, j + 8, k + 6, 5);
		world.setBlock(i + 5, j + 8, k + 5, 5);
		world.setBlock(i + 5, j + 8, k + 4, 5);
		world.setBlock(i + 5, j + 8, k + 3, 5);
		world.setBlock(i + 5, j + 8, k + 2, 5);
		world.setBlock(i + 5, j + 8, k + 1, 5);
		world.setBlock(i + 5, j + 8, k + 0, 17);
		world.setBlock(i + 6, j + 8, k + 34, 85);
		world.setBlock(i + 6, j + 8, k + 23, 35);
		world.setBlock(i + 6, j + 8, k + 16, 35);
		world.setBlock(i + 6, j + 8, k + 8, 17);
		world.setBlock(i + 6, j + 8, k + 7, 5);
		world.setBlock(i + 6, j + 8, k + 6, 5);
		world.setBlock(i + 6, j + 8, k + 5, 5);
		world.setBlock(i + 6, j + 8, k + 4, 5);
		world.setBlock(i + 6, j + 8, k + 3, 5);
		world.setBlock(i + 6, j + 8, k + 2, 5);
		world.setBlock(i + 6, j + 8, k + 1, 5);
		world.setBlock(i + 6, j + 8, k + 0, 17);
		world.setBlock(i + 7, j + 8, k + 23, 35);
		world.setBlock(i + 7, j + 8, k + 17, 79);
		world.setBlock(i + 7, j + 8, k + 16, 35);
		world.setBlock(i + 7, j + 8, k + 8, 17);
		world.setBlock(i + 7, j + 8, k + 7, 17);
		world.setBlock(i + 7, j + 8, k + 6, 17);
		world.setBlock(i + 7, j + 8, k + 5, 17);
		world.setBlock(i + 7, j + 8, k + 4, 17);
		world.setBlock(i + 7, j + 8, k + 3, 5);
		world.setBlock(i + 7, j + 8, k + 2, 5);
		world.setBlock(i + 7, j + 8, k + 1, 5);
		world.setBlock(i + 7, j + 8, k + 0, 17);
		world.setBlock(i + 8, j + 8, k + 16, 35);

		world.setBlock(i + 8, j + 8, k + 4, 17);
		world.setBlock(i + 8, j + 8, k + 3, 5);
		world.setBlock(i + 8, j + 8, k + 2, 5);
		world.setBlock(i + 8, j + 8, k + 1, 5);
		world.setBlock(i + 8, j + 8, k + 0, 17);
		world.setBlock(i + 9, j + 8, k + 16, 35);

		world.setBlock(i + 9, j + 8, k + 6, 17);
		world.setBlock(i + 9, j + 8, k + 5, 17);
		world.setBlock(i + 9, j + 8, k + 4, 17);
		world.setBlock(i + 9, j + 8, k + 3, 17);
		world.setBlock(i + 9, j + 8, k + 2, 17);
		world.setBlock(i + 9, j + 8, k + 1, 17);
		world.setBlock(i + 10, j + 8, k + 16, 35);
		world.setBlock(i + 0, j + 9, k + 16, 35);
		world.setBlock(i + 1, j + 9, k + 16, 35);
		world.setBlock(i + 1, j + 9, k + 6, 85);
		world.setBlock(i + 1, j + 9, k + 5, 85);
		world.setBlock(i + 1, j + 9, k + 4, 85);
		world.setBlock(i + 1, j + 9, k + 3, 85);
		world.setBlock(i + 1, j + 9, k + 2, 85);
		world.setBlock(i + 1, j + 9, k + 1, 85);
		world.setBlock(i + 2, j + 9, k + 17, 79);
		world.setBlock(i + 2, j + 9, k + 16, 35);
		world.setBlock(i + 2, j + 9, k + 1, 85);
		world.setBlock(i + 2, j + 9, k + 0, 85);
		world.setBlock(i + 3, j + 9, k + 24, 35);
		world.setBlock(i + 3, j + 9, k + 16, 35);
		world.setBlock(i + 3, j + 9, k + 8, 85);
		world.setBlock(i + 3, j + 9, k + 7, 85);
		world.setBlock(i + 3, j + 9, k + 6, 85);
		world.setBlock(i + 3, j + 9, k + 5, 85);
		world.setBlock(i + 3, j + 9, k + 4, 85);
		world.setBlock(i + 3, j + 9, k + 0, 85);
		world.setBlock(i + 4, j + 9, k + 24, 35);
		world.setBlock(i + 4, j + 9, k + 16, 35);
		world.setBlock(i + 4, j + 9, k + 8, 85);
		world.setBlock(i + 4, j + 9, k + 0, 85);
		world.setBlock(i + 5, j + 9, k + 34, 85);
		world.setBlock(i + 5, j + 9, k + 24, 35);
		world.setBlock(i + 5, j + 9, k + 22, 85);
		world.setBlock(i + 5, j + 9, k + 16, 35);
		world.setBlock(i + 5, j + 9, k + 14, 85);
		world.setBlock(i + 5, j + 9, k + 8, 85);
		world.setBlock(i + 5, j + 9, k + 6, 5);
		world.setBlock(i + 5, j + 9, k + 0, 85);
		world.setBlock(i + 6, j + 9, k + 24, 35);
		world.setBlock(i + 6, j + 9, k + 16, 35);
		world.setBlock(i + 6, j + 9, k + 8, 85);
		world.setBlock(i + 6, j + 9, k + 0, 85);
		world.setBlock(i + 7, j + 9, k + 24, 35);
		world.setBlock(i + 7, j + 9, k + 17, 79);
		world.setBlock(i + 7, j + 9, k + 16, 35);
		world.setBlock(i + 7, j + 9, k + 8, 85);
		world.setBlock(i + 7, j + 9, k + 7, 85);
		world.setBlock(i + 7, j + 9, k + 6, 85);
		world.setBlock(i + 7, j + 9, k + 5, 85);
		world.setBlock(i + 7, j + 9, k + 4, 85);
		world.setBlock(i + 7, j + 9, k + 0, 85);
		world.setBlock(i + 8, j + 9, k + 16, 35);
		world.setBlock(i + 8, j + 9, k + 1, 85);
		world.setBlock(i + 8, j + 9, k + 0, 85);
		world.setBlock(i + 9, j + 9, k + 16, 35);
		world.setBlock(i + 9, j + 9, k + 6, 85);
		world.setBlock(i + 9, j + 9, k + 5, 85);
		world.setBlock(i + 9, j + 9, k + 4, 85);
		world.setBlock(i + 9, j + 9, k + 3, 85);
		world.setBlock(i + 9, j + 9, k + 2, 85);
		world.setBlock(i + 9, j + 9, k + 1, 85);
		world.setBlock(i + 10, j + 9, k + 16, 35);
		world.setBlock(i + 0, j + 10, k + 17, 35);
		world.setBlock(i + 1, j + 10, k + 17, 35);
		world.setBlock(i + 2, j + 10, k + 17, 35);
		world.setBlock(i + 3, j + 10, k + 24, 35);
		world.setBlock(i + 3, j + 10, k + 17, 35);
		world.setBlock(i + 4, j + 10, k + 24, 35);
		world.setBlock(i + 4, j + 10, k + 17, 35);
		world.setBlock(i + 5, j + 10, k + 24, 35);
		world.setBlock(i + 5, j + 10, k + 22, 85);
		world.setBlock(i + 5, j + 10, k + 17, 35);
		world.setBlock(i + 5, j + 10, k + 14, 85);
		world.setBlock(i + 5, j + 10, k + 6, 5);
		world.setBlock(i + 6, j + 10, k + 24, 35);
		world.setBlock(i + 6, j + 10, k + 17, 35);
		world.setBlock(i + 7, j + 10, k + 24, 35);
		world.setBlock(i + 7, j + 10, k + 17, 35);
		world.setBlock(i + 8, j + 10, k + 17, 35);
		world.setBlock(i + 9, j + 10, k + 17, 35);
		world.setBlock(i + 10, j + 10, k + 17, 35);
		world.setBlock(i + 0, j + 11, k + 17, 35);
		world.setBlock(i + 1, j + 11, k + 17, 35);
		world.setBlock(i + 2, j + 11, k + 17, 35);
		world.setBlock(i + 3, j + 11, k + 24, 35);
		world.setBlock(i + 3, j + 11, k + 17, 35);
		world.setBlock(i + 4, j + 11, k + 24, 35);
		world.setBlock(i + 4, j + 11, k + 17, 35);
		world.setBlock(i + 5, j + 11, k + 24, 35);
		world.setBlock(i + 5, j + 11, k + 22, 85);
		world.setBlock(i + 5, j + 11, k + 17, 35);
		world.setBlock(i + 5, j + 11, k + 14, 85);
		world.setBlock(i + 6, j + 11, k + 24, 35);
		world.setBlock(i + 6, j + 11, k + 23, 79);
		world.setBlock(i + 6, j + 11, k + 17, 35);
		world.setBlock(i + 7, j + 11, k + 24, 35);
		world.setBlock(i + 7, j + 11, k + 17, 35);
		world.setBlock(i + 8, j + 11, k + 17, 35);
		world.setBlock(i + 9, j + 11, k + 17, 35);
		world.setBlock(i + 10, j + 11, k + 17, 35);
		world.setBlock(i + 0, j + 12, k + 17, 35);
		world.setBlock(i + 1, j + 12, k + 17, 35);
		world.setBlock(i + 2, j + 12, k + 17, 35);
		world.setBlock(i + 3, j + 12, k + 23, 35);
		world.setBlock(i + 3, j + 12, k + 17, 35);
		world.setBlock(i + 4, j + 12, k + 23, 35);
		world.setBlock(i + 4, j + 12, k + 17, 35);
		world.setBlock(i + 5, j + 12, k + 23, 35);
		world.setBlock(i + 5, j + 12, k + 22, 85);
		world.setBlock(i + 5, j + 12, k + 17, 35);
		world.setBlock(i + 5, j + 12, k + 16, 79);
		world.setBlock(i + 5, j + 12, k + 14, 85);
		world.setBlock(i + 6, j + 12, k + 23, 35);
		world.setBlock(i + 6, j + 12, k + 17, 35);
		world.setBlock(i + 7, j + 12, k + 23, 35);
		world.setBlock(i + 7, j + 12, k + 17, 35);
		world.setBlock(i + 8, j + 12, k + 17, 35);
		world.setBlock(i + 9, j + 12, k + 17, 35);
		world.setBlock(i + 9, j + 12, k + 16, 79);
		world.setBlock(i + 10, j + 12, k + 17, 35);
		world.setBlock(i + 0, j + 13, k + 17, 35);
		world.setBlock(i + 1, j + 13, k + 17, 35);
		world.setBlock(i + 2, j + 13, k + 17, 35);
		world.setBlock(i + 3, j + 13, k + 17, 35);
		world.setBlock(i + 4, j + 13, k + 17, 35);
		world.setBlock(i + 5, j + 13, k + 22, 85);
		world.setBlock(i + 5, j + 13, k + 17, 35);
		world.setBlock(i + 5, j + 13, k + 16, 79);
		world.setBlock(i + 5, j + 13, k + 14, 85);
		world.setBlock(i + 6, j + 13, k + 17, 35);
		world.setBlock(i + 7, j + 13, k + 17, 35);
		world.setBlock(i + 8, j + 13, k + 17, 35);
		world.setBlock(i + 9, j + 13, k + 17, 35);
		world.setBlock(i + 9, j + 13, k + 16, 79);
		world.setBlock(i + 10, j + 13, k + 17, 35);
		world.setBlock(i + 0, j + 14, k + 16, 35);
		world.setBlock(i + 1, j + 14, k + 16, 35);
		world.setBlock(i + 2, j + 14, k + 16, 35);
		world.setBlock(i + 3, j + 14, k + 16, 35);
		world.setBlock(i + 4, j + 14, k + 16, 35);
		world.setBlock(i + 5, j + 14, k + 16, 35);
		world.setBlock(i + 5, j + 14, k + 14, 85);
		world.setBlock(i + 6, j + 14, k + 16, 35);
		world.setBlock(i + 7, j + 14, k + 16, 35);
		world.setBlock(i + 8, j + 14, k + 16, 35);
		world.setBlock(i + 9, j + 14, k + 16, 35);
		world.setBlock(i + 10, j + 14, k + 16, 35);
		world.setBlock(i + 0, j + 15, k + 16, 35);
		world.setBlock(i + 1, j + 15, k + 16, 35);
		world.setBlock(i + 2, j + 15, k + 16, 35);
		world.setBlock(i + 3, j + 15, k + 16, 35);
		world.setBlock(i + 4, j + 15, k + 16, 35);
		world.setBlock(i + 5, j + 15, k + 16, 35);
		world.setBlock(i + 5, j + 15, k + 14, 85);
		world.setBlock(i + 6, j + 15, k + 16, 35);
		world.setBlock(i + 7, j + 15, k + 16, 35);
		world.setBlock(i + 8, j + 15, k + 16, 35);
		world.setBlock(i + 9, j + 15, k + 16, 35);
		world.setBlock(i + 10, j + 15, k + 16, 35);
		world.setBlock(i + 0, j + 16, k + 15, 35);
		world.setBlock(i + 1, j + 16, k + 15, 35);
		world.setBlock(i + 2, j + 16, k + 15, 35);
		world.setBlock(i + 3, j + 16, k + 15, 35);
		world.setBlock(i + 4, j + 16, k + 15, 35);
		world.setBlock(i + 5, j + 16, k + 15, 35);
		world.setBlock(i + 5, j + 16, k + 14, 85);
		world.setBlock(i + 6, j + 16, k + 15, 35);
		world.setBlock(i + 7, j + 16, k + 15, 35);
		world.setBlock(i + 8, j + 16, k + 15, 35);
		world.setBlock(i + 9, j + 16, k + 15, 35);
		world.setBlock(i + 10, j + 16, k + 15, 35);
		world.setBlock(i + 5, j + 17, k + 14, 85);
		world.setBlock(i + 6, j + 17, k + 14, 79);
		world.setBlock(i + 4, j + 18, k + 15, 5);
		world.setBlock(i + 4, j + 18, k + 14, 5);
		world.setBlock(i + 4, j + 18, k + 13, 5);
		world.setBlock(i + 5, j + 18, k + 15, 5);
		world.setBlock(i + 5, j + 18, k + 14, 5);
		world.setBlock(i + 5, j + 18, k + 13, 5);
		world.setBlock(i + 6, j + 18, k + 15,5);
		world.setBlock(i + 6, j + 18, k + 14, 5);
		world.setBlock(i + 6, j + 18, k + 13, 5);
		world.setBlock(i + 4, j + 19, k + 15, 5);

		world.setBlock(i + 4, j + 19, k + 13, 5);

		world.setBlock(i + 5, j + 19, k + 14, 85);

		world.setBlock(i + 6, j + 19, k + 15, 5);

		world.setBlock(i + 6, j + 19, k + 13, 5);
		world.setBlock(i + 5, j + 20, k + 14, 85);
		world.setBlock(i + 5, j + 21, k + 14, 85);


		ItemDoor.placeDoorBlock(world, i + 5, j + 5, k + 8, 4, Block.doorSteel);

		world.setBlock(i + 4, j + 2, k + 22, 54);
		world.setBlock(i + 4, j + 2, k + 21, 54);
		world.setBlock(i + 6, j + 2, k + 22, 54);
		world.setBlock(i + 6, j + 2, k + 21, 54);
		world.setBlock(i + 2, j + 5, k + 3, 54);
		world.setBlock(i + 2, j + 5, k + 1, 54);
		world.setBlock(i + 4, j + 5, k + 3, 54);
		world.setBlock(i + 6, j + 5, k + 3, 54);
		world.setBlock(i + 8, j + 5, k + 3, 54);
		world.setBlock(i + 8, j + 5, k + 1, 54);
		world.setBlock(i + 5, j + 2, k + 23, 54);
		

//		EntityPirate entitypirate = new EntityPirate(world);
//		entitypirate.setLocationAndAngles((double)i+ 5, j +6, (double)k + 1, 0.0F, 0.0F);
//        world.spawnEntityInWorld(entitypirate);
//        
//    	EntityPirate entitypirate1 = new EntityPirate(world);
//		entitypirate1.setLocationAndAngles((double)i+ 5, j +7, (double)k + 1, 0.0F, 0.0F);
//        world.spawnEntityInWorld(entitypirate1);
//        
//    	EntityPirate entitypirate2 = new EntityPirate(world);
//    	entitypirate2.setLocationAndAngles((double)i+ 5, j +5, (double)k + 1, 0.0F, 0.0F);
//        world.spawnEntityInWorld(entitypirate2);
//
//    	EntityPirate entitypirate3 = new EntityPirate(world);
//    	entitypirate3.setLocationAndAngles((double)i+ 5, j +6, (double)k + 1, 0.0F, 0.0F);
//        world.spawnEntityInWorld(entitypirate3);
//        
//    	EntityPirate entitypirate4 = new EntityPirate(world);
//    	entitypirate4.setLocationAndAngles((double)i+ 5, j +17, (double)k + 1, 0.0F, 0.0F);
//        world.spawnEntityInWorld(entitypirate4);
//        
//    	EntityPirate entitypirate5 = new EntityPirate(world);
//    	entitypirate5.setLocationAndAngles((double)i+ 5, j +4, (double)k + 1, 0.0F, 0.0F);
//        world.spawnEntityInWorld(entitypirate5);


		ItemDoor.placeDoorBlock(world, i + 5, j + 5, k + 8, 4, Block.doorSteel);

		
		world.setBlock(i + 4, j + 2, k + 22, 54);
		world.setBlock(i + 4, j + 2, k + 21, 54);
		world.setBlock(i + 6, j + 2, k + 22, 54);
		world.setBlock(i + 6, j + 2, k + 21, 54);
		world.setBlock(i + 2, j + 5, k + 3, 54);
		world.setBlock(i + 2, j + 5, k + 1, 54);
		world.setBlock(i + 4, j + 5, k + 3, 54);
		world.setBlock(i + 6, j + 5, k + 3, 54);
		world.setBlock(i + 8, j + 5, k + 3, 54);
		world.setBlock(i + 8, j + 5, k + 1, 54);
		world.setBlock(i + 5, j + 2, k + 23, 54);
		
		TileEntityChest chest0 = (TileEntityChest)world.getBlockTileEntity(i + 4, j + 2, k + 22);
		TileEntityChest chest1 = (TileEntityChest)world.getBlockTileEntity(i + 4, j + 2, k + 21);		
		TileEntityChest chest2 = (TileEntityChest)world.getBlockTileEntity(i + 6, j + 2, k + 22);		
		TileEntityChest chest3 = (TileEntityChest)world.getBlockTileEntity(i + 6, j + 2, k + 21);		
		TileEntityChest chest4 = (TileEntityChest)world.getBlockTileEntity(i + 2, j + 5, k + 3);		
		TileEntityChest chest5 = (TileEntityChest)world.getBlockTileEntity(i + 2, j + 5, k + 1);		
		TileEntityChest chest6 = (TileEntityChest)world.getBlockTileEntity(i + 4, j + 5, k + 3);		
		TileEntityChest chest7 = (TileEntityChest)world.getBlockTileEntity(i + 6, j + 5, k + 3);
		TileEntityChest chest8 = (TileEntityChest)world.getBlockTileEntity(i + 8, j + 5, k + 3);
		TileEntityChest chest9 = (TileEntityChest)world.getBlockTileEntity(i + 8, j + 5, k + 1);
		TileEntityChest chest10 = (TileEntityChest)world.getBlockTileEntity(i + 5, j + 2, k + 23);
		
		if (chest0 != null || chest1 != null ||chest2 != null ||chest3 != null ||chest4 != null ||chest5 != null ||chest6 != null ||chest7 != null ||chest8 != null ||chest9 != null ||chest10 != null )
        {
			AC_WorldGenHelpers.addRandomDungeonLoot(new TileEntityChest[] { chest0, chest1, chest2, chest3, chest4, chest5, chest6, chest7, chest8, chest9, chest10 }, "ship");
        }
		
		AC_EntityPirate entitypirate1 = new AC_EntityPirate(world);
		entitypirate1.setPosition(i + 3.5, j + 5, k + 10.5);
		world.spawnEntityInWorld(entitypirate1);	

		AC_EntityPirate entitypirate2 = new AC_EntityPirate(world);
		entitypirate2.setPosition(i + 3.5, j - 5, k + 14.5);
		world.spawnEntityInWorld(entitypirate2);
		
		AC_EntityPirate entitypirate3 = new AC_EntityPirate(world);
		entitypirate3.setPosition(i + 3.5, j - 5, k + 18.5);
		world.spawnEntityInWorld(entitypirate3);
		
		AC_EntityPirate entitypirate4 = new AC_EntityPirate(world);
		entitypirate4.setPosition(i + 8.5, j + 5, k + 10.5);
		world.spawnEntityInWorld(entitypirate4);
		
		AC_EntityPirate entitypirate5 = new AC_EntityPirate(world);
		entitypirate5.setPosition(i + 8.5, j + 5, k + 14.5);
		world.spawnEntityInWorld(entitypirate5);
		
		AC_EntityPirate entitypirate6 = new AC_EntityPirate(world);
		entitypirate6.setPosition(i + 8.5, j + 5, k + 18.5);
		world.spawnEntityInWorld(entitypirate6);
		
		AC_EntityCaptain entitycaptain = new AC_EntityCaptain(world);
		entitycaptain.setPosition(i + 5.5, j + 14, k + 3.5);
		world.spawnEntityInWorld(entitycaptain);
		
		return true;
	}
}

	