package arcticraft.gen; 
import java.util.Random;

import net.minecraft.block.Block;
import net.minecraft.world.World;
import net.minecraft.world.gen.feature.WorldGenerator;
import arcticraft.main.MainRegistry;



public class AC_GenIceCastle extends WorldGenerator
{
	protected int[] GetValidSpawnBlocks() {
		return new int[] {
				MainRegistry.acWaterStill.blockID
		};
	}

	public boolean LocationIsValidSpawn(World world, int i, int j, int k)
	{
		int distanceToAir = 0;
		int checkID = world.getBlockId(i, j, k);

		while (checkID != 0){
			distanceToAir++;
			checkID = world.getBlockId(i, j + distanceToAir, k);
		}

		if (distanceToAir > 0){
			return false;
		}
		j += distanceToAir - 1;

		int blockID = world.getBlockId(i, j, k);
		int blockIDAbove = world.getBlockId(i, j+1, k);
		int blockIDBelow = world.getBlockId(i, j-1, k);
		for (int x : GetValidSpawnBlocks()){
			if (blockIDAbove != 0){
				return false;
			}
			if (blockID == x){
				return true;
			}else if (blockID == Block.snow.blockID && blockIDBelow == x){
				return true;
			}
		}
		return false;
	}

	public AC_GenIceCastle() { }

	public boolean generate(World world, Random rand, int i, int j, int k)
	{
		//check that each corner is one of the valid spawn blocks
		if(!LocationIsValidSpawn(world, i, j, k) || !LocationIsValidSpawn(world, i + 47, j, k) || !LocationIsValidSpawn(world, i + 47, j, k + 65) || !LocationIsValidSpawn(world, i, j, k + 65))
		{
			return false;
		}
		
		world.setBlock(i + 0, j + 0, k + 0, MainRegistry.unbreakableIce.blockID);
		world.setBlock(i + 0, j + 0, k + 1, MainRegistry.unbreakableIce.blockID);
		world.setBlock(i + 0, j + 0, k + 2, MainRegistry.unbreakableIce.blockID);
		world.setBlock(i + 0, j + 0, k + 3, MainRegistry.unbreakableIce.blockID);
		world.setBlock(i + 0, j + 0, k + 4, MainRegistry.unbreakableIce.blockID);
		world.setBlock(i + 0, j + 0, k + 5, MainRegistry.unbreakableIce.blockID);
		world.setBlock(i + 0, j + 0, k + 6, MainRegistry.unbreakableIce.blockID);
		world.setBlock(i + 0, j + 0, k + 7, MainRegistry.unbreakableIce.blockID);
		world.setBlock(i + 0, j + 0, k + 8, MainRegistry.unbreakableIce.blockID);
		world.setBlock(i + 0, j + 0, k + 9, MainRegistry.unbreakableIce.blockID);
		world.setBlock(i + 0, j + 0, k + 10, MainRegistry.unbreakableIce.blockID);
		world.setBlock(i + 0, j + 0, k + 11, MainRegistry.unbreakableIce.blockID);
		world.setBlock(i + 0, j + 0, k + 12, MainRegistry.unbreakableIce.blockID);
		world.setBlock(i + 0, j + 0, k + 13, MainRegistry.unbreakableIce.blockID);
		world.setBlock(i + 0, j + 0, k + 14, MainRegistry.unbreakableIce.blockID);
		world.setBlock(i + 0, j + 0, k + 15, MainRegistry.unbreakableIce.blockID);
		world.setBlock(i + 0, j + 0, k + 16, MainRegistry.unbreakableIce.blockID);
		world.setBlock(i + 0, j + 0, k + 17, MainRegistry.unbreakableIce.blockID);
		world.setBlock(i + 0, j + 0, k + 18, MainRegistry.unbreakableIce.blockID);
		world.setBlock(i + 0, j + 0, k + 19, MainRegistry.unbreakableIce.blockID);
		world.setBlock(i + 0, j + 0, k + 20, MainRegistry.unbreakableIce.blockID);
		world.setBlock(i + 0, j + 0, k + 21, MainRegistry.unbreakableIce.blockID);
		world.setBlock(i + 0, j + 0, k + 22, MainRegistry.unbreakableIce.blockID);
		world.setBlock(i + 0, j + 0, k + 23, MainRegistry.unbreakableIce.blockID);
		world.setBlock(i + 0, j + 0, k + 24, MainRegistry.unbreakableIce.blockID);
		world.setBlock(i + 0, j + 0, k + 25, MainRegistry.unbreakableIce.blockID);
		world.setBlock(i + 0, j + 0, k + 26, MainRegistry.unbreakableIce.blockID);
		world.setBlock(i + 0, j + 0, k + 27, MainRegistry.unbreakableIce.blockID);
		world.setBlock(i + 0, j + 0, k + 28, MainRegistry.unbreakableIce.blockID);
		world.setBlock(i + 0, j + 0, k + 29, MainRegistry.unbreakableIce.blockID);
		world.setBlock(i + 0, j + 0, k + 30, MainRegistry.unbreakableIce.blockID);
		world.setBlock(i + 0, j + 0, k + 31, MainRegistry.unbreakableIce.blockID);
		world.setBlock(i + 0, j + 0, k + 32, MainRegistry.unbreakableIce.blockID);
		world.setBlock(i + 0, j + 0, k + 33, MainRegistry.unbreakableIce.blockID);
		world.setBlock(i + 0, j + 0, k + 34, MainRegistry.unbreakableIce.blockID);
		world.setBlock(i + 0, j + 0, k + 35, MainRegistry.unbreakableIce.blockID);
		world.setBlock(i + 0, j + 0, k + 36, MainRegistry.unbreakableIce.blockID);
		world.setBlock(i + 0, j + 0, k + 37, MainRegistry.unbreakableIce.blockID);
		world.setBlock(i + 0, j + 0, k + 38, MainRegistry.unbreakableIce.blockID);
		world.setBlock(i + 0, j + 0, k + 39, MainRegistry.unbreakableIce.blockID);
		world.setBlock(i + 0, j + 0, k + 40, MainRegistry.unbreakableIce.blockID);
		world.setBlock(i + 0, j + 0, k + 41, MainRegistry.unbreakableIce.blockID);
		world.setBlock(i + 0, j + 0, k + 42, MainRegistry.unbreakableIce.blockID);
		world.setBlock(i + 0, j + 0, k + 43, MainRegistry.unbreakableIce.blockID);
		world.setBlock(i + 0, j + 0, k + 44, MainRegistry.unbreakableIce.blockID);
		world.setBlock(i + 0, j + 0, k + 45, MainRegistry.unbreakableIce.blockID);
		world.setBlock(i + 0, j + 0, k + 46, MainRegistry.unbreakableIce.blockID);
		world.setBlock(i + 0, j + 0, k + 47, MainRegistry.unbreakableIce.blockID);
		world.setBlock(i + 0, j + 0, k + 48, MainRegistry.unbreakableIce.blockID);
		world.setBlock(i + 0, j + 0, k + 49, MainRegistry.unbreakableIce.blockID);
		world.setBlock(i + 0, j + 0, k + 50, MainRegistry.unbreakableIce.blockID);
		world.setBlock(i + 0, j + 0, k + 51, MainRegistry.unbreakableIce.blockID);
		world.setBlock(i + 0, j + 0, k + 52, MainRegistry.unbreakableIce.blockID);
		world.setBlock(i + 0, j + 0, k + 53, MainRegistry.unbreakableIce.blockID);
		world.setBlock(i + 0, j + 0, k + 54, MainRegistry.unbreakableIce.blockID);
		world.setBlock(i + 0, j + 0, k + 55, MainRegistry.unbreakableIce.blockID);
		world.setBlock(i + 0, j + 0, k + 56, MainRegistry.unbreakableIce.blockID);
		world.setBlock(i + 0, j + 0, k + 57, MainRegistry.unbreakableIce.blockID);
		world.setBlock(i + 0, j + 0, k + 58, MainRegistry.unbreakableIce.blockID);
		world.setBlock(i + 0, j + 0, k + 59, MainRegistry.unbreakableIce.blockID);
		world.setBlock(i + 0, j + 0, k + 60, MainRegistry.unbreakableIce.blockID);
		world.setBlock(i + 0, j + 0, k + 61, MainRegistry.unbreakableIce.blockID);
		world.setBlock(i + 0, j + 0, k + 62, MainRegistry.unbreakableIce.blockID);
		world.setBlock(i + 0, j + 1, k + 29, MainRegistry.frostPlanks.blockID);
		world.setBlock(i + 0, j + 1, k + 30, MainRegistry.frostPlanks.blockID);
		world.setBlock(i + 0, j + 1, k + 31, MainRegistry.frostPlanks.blockID);
		world.setBlock(i + 0, j + 1, k + 32, MainRegistry.frostPlanks.blockID);
		world.setBlock(i + 0, j + 1, k + 33, MainRegistry.frostPlanks.blockID);
		world.setBlock(i + 0, j + 1, k + 34, MainRegistry.frostPlanks.blockID);
		world.setBlock(i + 0, j + 1, k + 35, MainRegistry.frostPlanks.blockID);
		world.setBlock(i + 0, j + 1, k + 36, MainRegistry.frostPlanks.blockID);
		world.setBlock(i + 0, j + 2, k + 29, MainRegistry.unbreakableIce.blockID);
		world.setBlock(i + 0, j + 2, k + 30, MainRegistry.unbreakableIce.blockID);
		world.setBlock(i + 0, j + 2, k + 31, 80);
		world.setBlock(i + 0, j + 2, k + 34, 80);
		world.setBlock(i + 0, j + 2, k + 35, MainRegistry.unbreakableIce.blockID);
		world.setBlock(i + 0, j + 2, k + 36, MainRegistry.unbreakableIce.blockID);
		world.setBlock(i + 0, j + 3, k + 29, MainRegistry.unbreakableIce.blockID);
		world.setBlock(i + 0, j + 3, k + 30, MainRegistry.unbreakableIce.blockID);
		world.setBlock(i + 0, j + 3, k + 31, 80);
		world.setBlock(i + 0, j + 3, k + 34, 80);
		world.setBlock(i + 0, j + 3, k + 35, MainRegistry.unbreakableIce.blockID);
		world.setBlock(i + 0, j + 3, k + 36, MainRegistry.unbreakableIce.blockID);
		world.setBlock(i + 0, j + 4, k + 29, MainRegistry.unbreakableIce.blockID);
		world.setBlock(i + 0, j + 4, k + 30, MainRegistry.unbreakableIce.blockID);
		world.setBlock(i + 0, j + 4, k + 31, MainRegistry.unbreakableIce.blockID);
		world.setBlock(i + 0, j + 4, k + 32, 80);
		world.setBlock(i + 0, j + 4, k + 33, 80);
		world.setBlock(i + 0, j + 4, k + 34, MainRegistry.unbreakableIce.blockID);
		world.setBlock(i + 0, j + 4, k + 35, MainRegistry.unbreakableIce.blockID);
		world.setBlock(i + 0, j + 4, k + 36, MainRegistry.unbreakableIce.blockID);
		world.setBlock(i + 0, j + 5, k + 29, MainRegistry.unbreakableIce.blockID);
		world.setBlock(i + 0, j + 5, k + 30, MainRegistry.unbreakableIce.blockID);
		world.setBlock(i + 0, j + 5, k + 31, MainRegistry.unbreakableIce.blockID);
		world.setBlock(i + 0, j + 5, k + 32, MainRegistry.unbreakableIce.blockID);
		world.setBlock(i + 0, j + 5, k + 33, MainRegistry.unbreakableIce.blockID);
		world.setBlock(i + 0, j + 5, k + 34, MainRegistry.unbreakableIce.blockID);
		world.setBlock(i + 0, j + 5, k + 35, MainRegistry.unbreakableIce.blockID);
		world.setBlock(i + 0, j + 5, k + 36, MainRegistry.unbreakableIce.blockID);
		world.setBlock(i + 0, j + 6, k + 29, MainRegistry.unbreakableIce.blockID);
		world.setBlock(i + 0, j + 6, k + 30, MainRegistry.unbreakableIce.blockID);
		world.setBlock(i + 0, j + 6, k + 31, MainRegistry.unbreakableIce.blockID);
		world.setBlock(i + 0, j + 6, k + 32, MainRegistry.unbreakableIce.blockID);
		world.setBlock(i + 0, j + 6, k + 33, MainRegistry.unbreakableIce.blockID);
		world.setBlock(i + 0, j + 6, k + 34, MainRegistry.unbreakableIce.blockID);
		world.setBlock(i + 0, j + 6, k + 35, MainRegistry.unbreakableIce.blockID);
		world.setBlock(i + 0, j + 6, k + 36, MainRegistry.unbreakableIce.blockID);
		world.setBlock(i + 0, j + 7, k + 29, MainRegistry.unbreakableIce.blockID);
		world.setBlock(i + 0, j + 7, k + 30, MainRegistry.unbreakableIce.blockID);
		world.setBlock(i + 0, j + 7, k + 31, MainRegistry.unbreakableIce.blockID);
		world.setBlock(i + 0, j + 7, k + 32, MainRegistry.unbreakableIce.blockID);
		world.setBlock(i + 0, j + 7, k + 33, MainRegistry.unbreakableIce.blockID);
		world.setBlock(i + 0, j + 7, k + 34, MainRegistry.unbreakableIce.blockID);
		world.setBlock(i + 0, j + 7, k + 35, MainRegistry.unbreakableIce.blockID);
		world.setBlock(i + 0, j + 7, k + 36, MainRegistry.unbreakableIce.blockID);
		world.setBlock(i + 0, j + 8, k + 29, MainRegistry.unbreakableIce.blockID);
		world.setBlock(i + 0, j + 8, k + 30, MainRegistry.unbreakableIce.blockID);
		world.setBlock(i + 0, j + 8, k + 31, MainRegistry.unbreakableIce.blockID);
		world.setBlock(i + 0, j + 8, k + 32, MainRegistry.unbreakableIce.blockID);
		world.setBlock(i + 0, j + 8, k + 33, MainRegistry.unbreakableIce.blockID);
		world.setBlock(i + 0, j + 8, k + 34, MainRegistry.unbreakableIce.blockID);
		world.setBlock(i + 0, j + 8, k + 35, MainRegistry.unbreakableIce.blockID);
		world.setBlock(i + 0, j + 8, k + 36, MainRegistry.unbreakableIce.blockID);
		world.setBlock(i + 0, j + 9, k + 29, MainRegistry.unbreakableIce.blockID);
		world.setBlock(i + 0, j + 9, k + 30, MainRegistry.unbreakableIce.blockID);
		world.setBlock(i + 0, j + 9, k + 31, MainRegistry.unbreakableIce.blockID);
		world.setBlock(i + 0, j + 9, k + 32, MainRegistry.unbreakableIce.blockID);
		world.setBlock(i + 0, j + 9, k + 33, MainRegistry.unbreakableIce.blockID);
		world.setBlock(i + 0, j + 9, k + 34, MainRegistry.unbreakableIce.blockID);
		world.setBlock(i + 0, j + 9, k + 35, MainRegistry.unbreakableIce.blockID);
		world.setBlock(i + 0, j + 9, k + 36, MainRegistry.unbreakableIce.blockID);
		world.setBlock(i + 0, j + 10, k + 29, MainRegistry.unbreakableIce.blockID);
		world.setBlock(i + 0, j + 10, k + 30, MainRegistry.unbreakableIce.blockID);
		world.setBlock(i + 0, j + 10, k + 31, MainRegistry.unbreakableIce.blockID);
		world.setBlock(i + 0, j + 10, k + 32, MainRegistry.unbreakableIce.blockID);
		world.setBlock(i + 0, j + 10, k + 33, MainRegistry.unbreakableIce.blockID);
		world.setBlock(i + 0, j + 10, k + 34, MainRegistry.unbreakableIce.blockID);
		world.setBlock(i + 0, j + 10, k + 35, MainRegistry.unbreakableIce.blockID);
		world.setBlock(i + 0, j + 10, k + 36, MainRegistry.unbreakableIce.blockID);
		world.setBlock(i + 0, j + 11, k + 29, MainRegistry.unbreakableIce.blockID);
		world.setBlock(i + 0, j + 11, k + 30, MainRegistry.unbreakableIce.blockID);
		world.setBlock(i + 0, j + 11, k + 31, 80);
		world.setBlock(i + 0, j + 11, k + 32, 80);
		world.setBlock(i + 0, j + 11, k + 33, 80);
		world.setBlock(i + 0, j + 11, k + 34, 80);
		world.setBlock(i + 0, j + 11, k + 35, MainRegistry.unbreakableIce.blockID);
		world.setBlock(i + 0, j + 11, k + 36, MainRegistry.unbreakableIce.blockID);
		world.setBlock(i + 0, j + 12, k + 29, MainRegistry.unbreakableIce.blockID);
		world.setBlock(i + 0, j + 12, k + 30, 80);
		world.setBlock(i + 0, j + 12, k + 31, 80);
		world.setBlock(i + 0, j + 12, k + 32, 80);
		world.setBlock(i + 0, j + 12, k + 33, 80);
		world.setBlock(i + 0, j + 12, k + 34, 80);
		world.setBlock(i + 0, j + 12, k + 35, 80);
		world.setBlock(i + 0, j + 12, k + 36, MainRegistry.unbreakableIce.blockID);
		world.setBlock(i + 1, j + 0, k + 0, MainRegistry.unbreakableIce.blockID);
		world.setBlock(i + 1, j + 0, k + 1, MainRegistry.unbreakableIce.blockID);
		world.setBlock(i + 1, j + 0, k + 2, MainRegistry.unbreakableIce.blockID);
		world.setBlock(i + 1, j + 0, k + 3, MainRegistry.unbreakableIce.blockID);
		world.setBlock(i + 1, j + 0, k + 4, MainRegistry.unbreakableIce.blockID);
		world.setBlock(i + 1, j + 0, k + 5, MainRegistry.unbreakableIce.blockID);
		world.setBlock(i + 1, j + 0, k + 6, MainRegistry.unbreakableIce.blockID);
		world.setBlock(i + 1, j + 0, k + 7, MainRegistry.unbreakableIce.blockID);
		world.setBlock(i + 1, j + 0, k + 8, MainRegistry.unbreakableIce.blockID);
		world.setBlock(i + 1, j + 0, k + 9, MainRegistry.unbreakableIce.blockID);
		world.setBlock(i + 1, j + 0, k + 10, MainRegistry.unbreakableIce.blockID);
		world.setBlock(i + 1, j + 0, k + 11, MainRegistry.unbreakableIce.blockID);
		world.setBlock(i + 1, j + 0, k + 12, MainRegistry.unbreakableIce.blockID);
		world.setBlock(i + 1, j + 0, k + 13, MainRegistry.unbreakableIce.blockID);
		world.setBlock(i + 1, j + 0, k + 14, MainRegistry.unbreakableIce.blockID);
		world.setBlock(i + 1, j + 0, k + 15, MainRegistry.unbreakableIce.blockID);
		world.setBlock(i + 1, j + 0, k + 16, MainRegistry.unbreakableIce.blockID);
		world.setBlock(i + 1, j + 0, k + 17, MainRegistry.unbreakableIce.blockID);
		world.setBlock(i + 1, j + 0, k + 18, MainRegistry.unbreakableIce.blockID);
		world.setBlock(i + 1, j + 0, k + 19, MainRegistry.unbreakableIce.blockID);
		world.setBlock(i + 1, j + 0, k + 20, MainRegistry.unbreakableIce.blockID);
		world.setBlock(i + 1, j + 0, k + 21, MainRegistry.unbreakableIce.blockID);
		world.setBlock(i + 1, j + 0, k + 22, MainRegistry.unbreakableIce.blockID);
		world.setBlock(i + 1, j + 0, k + 23, MainRegistry.unbreakableIce.blockID);
		world.setBlock(i + 1, j + 0, k + 24, MainRegistry.unbreakableIce.blockID);
		world.setBlock(i + 1, j + 0, k + 25, MainRegistry.unbreakableIce.blockID);
		world.setBlock(i + 1, j + 0, k + 26, MainRegistry.unbreakableIce.blockID);
		world.setBlock(i + 1, j + 0, k + 27, MainRegistry.unbreakableIce.blockID);
		world.setBlock(i + 1, j + 0, k + 28, MainRegistry.unbreakableIce.blockID);
		world.setBlock(i + 1, j + 0, k + 29, MainRegistry.unbreakableIce.blockID);
		world.setBlock(i + 1, j + 0, k + 30, MainRegistry.unbreakableIce.blockID);
		world.setBlock(i + 1, j + 0, k + 31, MainRegistry.unbreakableIce.blockID);
		world.setBlock(i + 1, j + 0, k + 32, MainRegistry.unbreakableIce.blockID);
		world.setBlock(i + 1, j + 0, k + 33, MainRegistry.unbreakableIce.blockID);
		world.setBlock(i + 1, j + 0, k + 34, MainRegistry.unbreakableIce.blockID);
		world.setBlock(i + 1, j + 0, k + 35, MainRegistry.unbreakableIce.blockID);
		world.setBlock(i + 1, j + 0, k + 36, MainRegistry.unbreakableIce.blockID);
		world.setBlock(i + 1, j + 0, k + 37, MainRegistry.unbreakableIce.blockID);
		world.setBlock(i + 1, j + 0, k + 38, MainRegistry.unbreakableIce.blockID);
		world.setBlock(i + 1, j + 0, k + 39, MainRegistry.unbreakableIce.blockID);
		world.setBlock(i + 1, j + 0, k + 40, MainRegistry.unbreakableIce.blockID);
		world.setBlock(i + 1, j + 0, k + 41, MainRegistry.unbreakableIce.blockID);
		world.setBlock(i + 1, j + 0, k + 42, MainRegistry.unbreakableIce.blockID);
		world.setBlock(i + 1, j + 0, k + 43, MainRegistry.unbreakableIce.blockID);
		world.setBlock(i + 1, j + 0, k + 44, MainRegistry.unbreakableIce.blockID);
		world.setBlock(i + 1, j + 0, k + 45, MainRegistry.unbreakableIce.blockID);
		world.setBlock(i + 1, j + 0, k + 46, MainRegistry.unbreakableIce.blockID);
		world.setBlock(i + 1, j + 0, k + 47, MainRegistry.unbreakableIce.blockID);
		world.setBlock(i + 1, j + 0, k + 48, MainRegistry.unbreakableIce.blockID);
		world.setBlock(i + 1, j + 0, k + 49, MainRegistry.unbreakableIce.blockID);
		world.setBlock(i + 1, j + 0, k + 50, MainRegistry.unbreakableIce.blockID);
		world.setBlock(i + 1, j + 0, k + 51, MainRegistry.unbreakableIce.blockID);
		world.setBlock(i + 1, j + 0, k + 52, MainRegistry.unbreakableIce.blockID);
		world.setBlock(i + 1, j + 0, k + 53, MainRegistry.unbreakableIce.blockID);
		world.setBlock(i + 1, j + 0, k + 54, MainRegistry.unbreakableIce.blockID);
		world.setBlock(i + 1, j + 0, k + 55, MainRegistry.unbreakableIce.blockID);
		world.setBlock(i + 1, j + 0, k + 56, MainRegistry.unbreakableIce.blockID);
		world.setBlock(i + 1, j + 0, k + 57, MainRegistry.unbreakableIce.blockID);
		world.setBlock(i + 1, j + 0, k + 58, MainRegistry.unbreakableIce.blockID);
		world.setBlock(i + 1, j + 0, k + 59, MainRegistry.unbreakableIce.blockID);
		world.setBlock(i + 1, j + 0, k + 60, MainRegistry.unbreakableIce.blockID);
		world.setBlock(i + 1, j + 0, k + 61, MainRegistry.unbreakableIce.blockID);
		world.setBlock(i + 1, j + 0, k + 62, MainRegistry.unbreakableIce.blockID);
		world.setBlock(i + 1, j + 1, k + 28, MainRegistry.frostPlanks.blockID);
		world.setBlock(i + 1, j + 1, k + 29, MainRegistry.frostPlanks.blockID);
		world.setBlock(i + 1, j + 1, k + 30, MainRegistry.frostPlanks.blockID);
		world.setBlock(i + 1, j + 1, k + 31, MainRegistry.frostPlanks.blockID);
		world.setBlock(i + 1, j + 1, k + 32, MainRegistry.frostPlanks.blockID);
		world.setBlock(i + 1, j + 1, k + 33, MainRegistry.frostPlanks.blockID);
		world.setBlock(i + 1, j + 1, k + 34, MainRegistry.frostPlanks.blockID);
		world.setBlock(i + 1, j + 1, k + 35, MainRegistry.frostPlanks.blockID);
		world.setBlock(i + 1, j + 1, k + 36, MainRegistry.frostPlanks.blockID);
		world.setBlock(i + 1, j + 1, k + 37, MainRegistry.frostPlanks.blockID);
		world.setBlock(i + 1, j + 2, k + 28, MainRegistry.unbreakableIce.blockID);
		world.setBlock(i + 1, j + 2, k + 37, MainRegistry.unbreakableIce.blockID);
		world.setBlock(i + 1, j + 3, k + 28, MainRegistry.unbreakableIce.blockID);
		world.setBlock(i + 1, j + 3, k + 37, MainRegistry.unbreakableIce.blockID);
		world.setBlock(i + 1, j + 4, k + 28, MainRegistry.unbreakableIce.blockID);
		world.setBlock(i + 1, j + 4, k + 37, MainRegistry.unbreakableIce.blockID);
		world.setBlock(i + 1, j + 5, k + 28, MainRegistry.unbreakableIce.blockID);
		world.setBlock(i + 1, j + 5, k + 37, MainRegistry.unbreakableIce.blockID);
		world.setBlock(i + 1, j + 6, k + 28, MainRegistry.unbreakableIce.blockID);
		world.setBlock(i + 1, j + 6, k + 37, MainRegistry.unbreakableIce.blockID);
		world.setBlock(i + 1, j + 7, k + 28, MainRegistry.unbreakableIce.blockID);
		world.setBlock(i + 1, j + 7, k + 37, MainRegistry.unbreakableIce.blockID);
		world.setBlock(i + 1, j + 8, k + 28, MainRegistry.unbreakableIce.blockID);
		world.setBlock(i + 1, j + 8, k + 32, 30);
		world.setBlock(i + 1, j + 8, k + 37, MainRegistry.unbreakableIce.blockID);
		world.setBlock(i + 1, j + 9, k + 28, MainRegistry.unbreakableIce.blockID);
		world.setBlock(i + 1, j + 9, k + 30, 30);
		world.setBlock(i + 1, j + 9, k + 37, MainRegistry.unbreakableIce.blockID);
		world.setBlock(i + 1, j + 10, k + 28, MainRegistry.unbreakableIce.blockID);
		world.setBlock(i + 1, j + 10, k + 37, MainRegistry.unbreakableIce.blockID);
		world.setBlock(i + 1, j + 11, k + 28, MainRegistry.unbreakableIce.blockID);
		world.setBlock(i + 1, j + 11, k + 34, 30);
		world.setBlock(i + 1, j + 11, k + 37, MainRegistry.unbreakableIce.blockID);
		world.setBlock(i + 1, j + 12, k + 28, MainRegistry.unbreakableIce.blockID);
		world.setBlock(i + 1, j + 12, k + 35, 30);
		world.setBlock(i + 1, j + 12, k + 37, MainRegistry.unbreakableIce.blockID);
		world.setBlock(i + 1, j + 13, k + 28, MainRegistry.unbreakableIce.blockID);
		world.setBlock(i + 1, j + 13, k + 29, 80);
		world.setBlock(i + 1, j + 13, k + 30, 80);
		world.setBlock(i + 1, j + 13, k + 31, 80);
		world.setBlock(i + 1, j + 13, k + 32, 80);
		world.setBlock(i + 1, j + 13, k + 33, 80);
		world.setBlock(i + 1, j + 13, k + 34, 80);
		world.setBlock(i + 1, j + 13, k + 35, 80);
		world.setBlock(i + 1, j + 13, k + 36, 80);
		world.setBlock(i + 1, j + 13, k + 37, MainRegistry.unbreakableIce.blockID);
		world.setBlock(i + 2, j + 0, k + 0, MainRegistry.unbreakableIce.blockID);
		world.setBlock(i + 2, j + 0, k + 1, MainRegistry.unbreakableIce.blockID);
		world.setBlock(i + 2, j + 0, k + 2, MainRegistry.unbreakableIce.blockID);
		world.setBlock(i + 2, j + 0, k + 3, MainRegistry.unbreakableIce.blockID);
		world.setBlock(i + 2, j + 0, k + 4, MainRegistry.unbreakableIce.blockID);
		world.setBlock(i + 2, j + 0, k + 5, MainRegistry.unbreakableIce.blockID);
		world.setBlock(i + 2, j + 0, k + 6, MainRegistry.unbreakableIce.blockID);
		world.setBlock(i + 2, j + 0, k + 7, MainRegistry.unbreakableIce.blockID);
		world.setBlock(i + 2, j + 0, k + 8, MainRegistry.unbreakableIce.blockID);
		world.setBlock(i + 2, j + 0, k + 9, MainRegistry.unbreakableIce.blockID);
		world.setBlock(i + 2, j + 0, k + 10, MainRegistry.unbreakableIce.blockID);
		world.setBlock(i + 2, j + 0, k + 11, MainRegistry.unbreakableIce.blockID);
		world.setBlock(i + 2, j + 0, k + 12, MainRegistry.unbreakableIce.blockID);
		world.setBlock(i + 2, j + 0, k + 13, MainRegistry.unbreakableIce.blockID);
		world.setBlock(i + 2, j + 0, k + 14, MainRegistry.unbreakableIce.blockID);
		world.setBlock(i + 2, j + 0, k + 15, MainRegistry.unbreakableIce.blockID);
		world.setBlock(i + 2, j + 0, k + 16, MainRegistry.unbreakableIce.blockID);
		world.setBlock(i + 2, j + 0, k + 17, MainRegistry.unbreakableIce.blockID);
		world.setBlock(i + 2, j + 0, k + 18, MainRegistry.unbreakableIce.blockID);
		world.setBlock(i + 2, j + 0, k + 19, MainRegistry.unbreakableIce.blockID);
		world.setBlock(i + 2, j + 0, k + 20, MainRegistry.unbreakableIce.blockID);
		world.setBlock(i + 2, j + 0, k + 21, MainRegistry.unbreakableIce.blockID);
		world.setBlock(i + 2, j + 0, k + 22, MainRegistry.unbreakableIce.blockID);
		world.setBlock(i + 2, j + 0, k + 23, MainRegistry.unbreakableIce.blockID);
		world.setBlock(i + 2, j + 0, k + 24, MainRegistry.unbreakableIce.blockID);
		world.setBlock(i + 2, j + 0, k + 25, MainRegistry.unbreakableIce.blockID);
		world.setBlock(i + 2, j + 0, k + 26, MainRegistry.unbreakableIce.blockID);
		world.setBlock(i + 2, j + 0, k + 27, MainRegistry.unbreakableIce.blockID);
		world.setBlock(i + 2, j + 0, k + 28, MainRegistry.unbreakableIce.blockID);
		world.setBlock(i + 2, j + 0, k + 29, MainRegistry.unbreakableIce.blockID);
		world.setBlock(i + 2, j + 0, k + 30, MainRegistry.unbreakableIce.blockID);
		world.setBlock(i + 2, j + 0, k + 31, MainRegistry.unbreakableIce.blockID);
		world.setBlock(i + 2, j + 0, k + 32, MainRegistry.unbreakableIce.blockID);
		world.setBlock(i + 2, j + 0, k + 33, MainRegistry.unbreakableIce.blockID);
		world.setBlock(i + 2, j + 0, k + 34, MainRegistry.unbreakableIce.blockID);
		world.setBlock(i + 2, j + 0, k + 35, MainRegistry.unbreakableIce.blockID);
		world.setBlock(i + 2, j + 0, k + 36, MainRegistry.unbreakableIce.blockID);
		world.setBlock(i + 2, j + 0, k + 37, MainRegistry.unbreakableIce.blockID);
		world.setBlock(i + 2, j + 0, k + 38, MainRegistry.unbreakableIce.blockID);
		world.setBlock(i + 2, j + 0, k + 39, MainRegistry.unbreakableIce.blockID);
		world.setBlock(i + 2, j + 0, k + 40, MainRegistry.unbreakableIce.blockID);
		world.setBlock(i + 2, j + 0, k + 41, MainRegistry.unbreakableIce.blockID);
		world.setBlock(i + 2, j + 0, k + 42, MainRegistry.unbreakableIce.blockID);
		world.setBlock(i + 2, j + 0, k + 43, MainRegistry.unbreakableIce.blockID);
		world.setBlock(i + 2, j + 0, k + 44, MainRegistry.unbreakableIce.blockID);
		world.setBlock(i + 2, j + 0, k + 45, MainRegistry.unbreakableIce.blockID);
		world.setBlock(i + 2, j + 0, k + 46, MainRegistry.unbreakableIce.blockID);
		world.setBlock(i + 2, j + 0, k + 47, MainRegistry.unbreakableIce.blockID);
		world.setBlock(i + 2, j + 0, k + 48, MainRegistry.unbreakableIce.blockID);
		world.setBlock(i + 2, j + 0, k + 49, MainRegistry.unbreakableIce.blockID);
		world.setBlock(i + 2, j + 0, k + 50, MainRegistry.unbreakableIce.blockID);
		world.setBlock(i + 2, j + 0, k + 51, MainRegistry.unbreakableIce.blockID);
		world.setBlock(i + 2, j + 0, k + 52, MainRegistry.unbreakableIce.blockID);
		world.setBlock(i + 2, j + 0, k + 53, MainRegistry.unbreakableIce.blockID);
		world.setBlock(i + 2, j + 0, k + 54, MainRegistry.unbreakableIce.blockID);
		world.setBlock(i + 2, j + 0, k + 55, MainRegistry.unbreakableIce.blockID);
		world.setBlock(i + 2, j + 0, k + 56, MainRegistry.unbreakableIce.blockID);
		world.setBlock(i + 2, j + 0, k + 57, MainRegistry.unbreakableIce.blockID);
		world.setBlock(i + 2, j + 0, k + 58, MainRegistry.unbreakableIce.blockID);
		world.setBlock(i + 2, j + 0, k + 59, MainRegistry.unbreakableIce.blockID);
		world.setBlock(i + 2, j + 0, k + 60, MainRegistry.unbreakableIce.blockID);
		world.setBlock(i + 2, j + 0, k + 61, MainRegistry.unbreakableIce.blockID);
		world.setBlock(i + 2, j + 0, k + 62, MainRegistry.unbreakableIce.blockID);
		world.setBlock(i + 2, j + 1, k + 27, MainRegistry.frostPlanks.blockID);
		world.setBlock(i + 2, j + 1, k + 28, MainRegistry.frostPlanks.blockID);
		world.setBlock(i + 2, j + 1, k + 29, MainRegistry.frostPlanks.blockID);
		world.setBlock(i + 2, j + 1, k + 30, MainRegistry.frostPlanks.blockID);
		world.setBlock(i + 2, j + 1, k + 31, MainRegistry.frostPlanks.blockID);
		world.setBlock(i + 2, j + 1, k + 32, MainRegistry.frostPlanks.blockID);
		world.setBlock(i + 2, j + 1, k + 33, MainRegistry.frostPlanks.blockID);
		world.setBlock(i + 2, j + 1, k + 34, MainRegistry.frostPlanks.blockID);
		world.setBlock(i + 2, j + 1, k + 35, MainRegistry.frostPlanks.blockID);
		world.setBlock(i + 2, j + 1, k + 36, MainRegistry.frostPlanks.blockID);
		world.setBlock(i + 2, j + 1, k + 37, MainRegistry.frostPlanks.blockID);
		world.setBlock(i + 2, j + 1, k + 38, MainRegistry.frostPlanks.blockID);
		world.setBlock(i + 2, j + 2, k + 27, MainRegistry.unbreakableIce.blockID);
		world.setBlock(i + 2, j + 2, k + 38, MainRegistry.unbreakableIce.blockID);
		world.setBlock(i + 2, j + 3, k + 27, MainRegistry.unbreakableIce.blockID);
		world.setBlock(i + 2, j + 3, k + 38, MainRegistry.unbreakableIce.blockID);
		world.setBlock(i + 2, j + 4, k + 27, MainRegistry.unbreakableIce.blockID);
		world.setBlock(i + 2, j + 4, k + 38, MainRegistry.unbreakableIce.blockID);
		world.setBlock(i + 2, j + 5, k + 27, MainRegistry.unbreakableIce.blockID);
		world.setBlock(i + 2, j + 5, k + 38, MainRegistry.unbreakableIce.blockID);
		world.setBlock(i + 2, j + 6, k + 27, MainRegistry.unbreakableIce.blockID);
		world.setBlock(i + 2, j + 6, k + 38, MainRegistry.unbreakableIce.blockID);
		world.setBlock(i + 2, j + 7, k + 27, MainRegistry.unbreakableIce.blockID);
		world.setBlock(i + 2, j + 7, k + 38, MainRegistry.unbreakableIce.blockID);
		world.setBlock(i + 2, j + 8, k + 27, MainRegistry.unbreakableIce.blockID);
		world.setBlock(i + 2, j + 8, k + 38, MainRegistry.unbreakableIce.blockID);
		world.setBlock(i + 2, j + 9, k + 27, MainRegistry.unbreakableIce.blockID);
		world.setBlock(i + 2, j + 9, k + 38, MainRegistry.unbreakableIce.blockID);
		world.setBlock(i + 2, j + 10, k + 27, MainRegistry.unbreakableIce.blockID);
		world.setBlock(i + 2, j + 10, k + 38, MainRegistry.unbreakableIce.blockID);
		world.setBlock(i + 2, j + 11, k + 27, MainRegistry.unbreakableIce.blockID);
		world.setBlock(i + 2, j + 11, k + 38, MainRegistry.unbreakableIce.blockID);
		world.setBlock(i + 2, j + 12, k + 27, MainRegistry.unbreakableIce.blockID);
		world.setBlock(i + 2, j + 12, k + 37, 30);
		world.setBlock(i + 2, j + 12, k + 38, MainRegistry.unbreakableIce.blockID);
		world.setBlock(i + 2, j + 13, k + 27, MainRegistry.unbreakableIce.blockID);
		world.setBlock(i + 2, j + 13, k + 38, MainRegistry.unbreakableIce.blockID);
		world.setBlock(i + 2, j + 14, k + 27, MainRegistry.unbreakableIce.blockID);
		world.setBlock(i + 2, j + 14, k + 28, 80);
		world.setBlock(i + 2, j + 14, k + 29, 80);
		world.setBlock(i + 2, j + 14, k + 30, 80);
		world.setBlock(i + 2, j + 14, k + 31, 80);
		world.setBlock(i + 2, j + 14, k + 32, 80);
		world.setBlock(i + 2, j + 14, k + 33, 80);
		world.setBlock(i + 2, j + 14, k + 34, 80);
		world.setBlock(i + 2, j + 14, k + 35, 80);
		world.setBlock(i + 2, j + 14, k + 36, 80);
		world.setBlock(i + 2, j + 14, k + 37, 80);
		world.setBlock(i + 2, j + 14, k + 38, MainRegistry.unbreakableIce.blockID);
		world.setBlock(i + 3, j + 0, k + 0, MainRegistry.unbreakableIce.blockID);
		world.setBlock(i + 3, j + 0, k + 1, MainRegistry.unbreakableIce.blockID);
		world.setBlock(i + 3, j + 0, k + 2, MainRegistry.unbreakableIce.blockID);
		world.setBlock(i + 3, j + 0, k + 3, MainRegistry.unbreakableIce.blockID);
		world.setBlock(i + 3, j + 0, k + 4, MainRegistry.unbreakableIce.blockID);
		world.setBlock(i + 3, j + 0, k + 5, MainRegistry.unbreakableIce.blockID);
		world.setBlock(i + 3, j + 0, k + 6, MainRegistry.unbreakableIce.blockID);
		world.setBlock(i + 3, j + 0, k + 7, MainRegistry.unbreakableIce.blockID);
		world.setBlock(i + 3, j + 0, k + 8, MainRegistry.unbreakableIce.blockID);
		world.setBlock(i + 3, j + 0, k + 9, MainRegistry.unbreakableIce.blockID);
		world.setBlock(i + 3, j + 0, k + 10, MainRegistry.unbreakableIce.blockID);
		world.setBlock(i + 3, j + 0, k + 11, MainRegistry.unbreakableIce.blockID);
		world.setBlock(i + 3, j + 0, k + 12, MainRegistry.unbreakableIce.blockID);
		world.setBlock(i + 3, j + 0, k + 13, MainRegistry.unbreakableIce.blockID);
		world.setBlock(i + 3, j + 0, k + 14, MainRegistry.unbreakableIce.blockID);
		world.setBlock(i + 3, j + 0, k + 15, MainRegistry.unbreakableIce.blockID);
		world.setBlock(i + 3, j + 0, k + 16, MainRegistry.unbreakableIce.blockID);
		world.setBlock(i + 3, j + 0, k + 17, MainRegistry.unbreakableIce.blockID);
		world.setBlock(i + 3, j + 0, k + 18, MainRegistry.unbreakableIce.blockID);
		world.setBlock(i + 3, j + 0, k + 19, MainRegistry.unbreakableIce.blockID);
		world.setBlock(i + 3, j + 0, k + 20, MainRegistry.unbreakableIce.blockID);
		world.setBlock(i + 3, j + 0, k + 21, MainRegistry.unbreakableIce.blockID);
		world.setBlock(i + 3, j + 0, k + 22, MainRegistry.unbreakableIce.blockID);
		world.setBlock(i + 3, j + 0, k + 23, MainRegistry.unbreakableIce.blockID);
		world.setBlock(i + 3, j + 0, k + 24, MainRegistry.unbreakableIce.blockID);
		world.setBlock(i + 3, j + 0, k + 25, MainRegistry.unbreakableIce.blockID);
		world.setBlock(i + 3, j + 0, k + 26, MainRegistry.unbreakableIce.blockID);
		world.setBlock(i + 3, j + 0, k + 27, MainRegistry.unbreakableIce.blockID);
		world.setBlock(i + 3, j + 0, k + 28, MainRegistry.unbreakableIce.blockID);
		world.setBlock(i + 3, j + 0, k + 29, MainRegistry.unbreakableIce.blockID);
		world.setBlock(i + 3, j + 0, k + 30, MainRegistry.unbreakableIce.blockID);
		world.setBlock(i + 3, j + 0, k + 31, MainRegistry.unbreakableIce.blockID);
		world.setBlock(i + 3, j + 0, k + 32, MainRegistry.unbreakableIce.blockID);
		world.setBlock(i + 3, j + 0, k + 33, MainRegistry.unbreakableIce.blockID);
		world.setBlock(i + 3, j + 0, k + 34, MainRegistry.unbreakableIce.blockID);
		world.setBlock(i + 3, j + 0, k + 35, MainRegistry.unbreakableIce.blockID);
		world.setBlock(i + 3, j + 0, k + 36, MainRegistry.unbreakableIce.blockID);
		world.setBlock(i + 3, j + 0, k + 37, MainRegistry.unbreakableIce.blockID);
		world.setBlock(i + 3, j + 0, k + 38, MainRegistry.unbreakableIce.blockID);
		world.setBlock(i + 3, j + 0, k + 39, MainRegistry.unbreakableIce.blockID);
		world.setBlock(i + 3, j + 0, k + 40, MainRegistry.unbreakableIce.blockID);
		world.setBlock(i + 3, j + 0, k + 41, MainRegistry.unbreakableIce.blockID);
		world.setBlock(i + 3, j + 0, k + 42, MainRegistry.unbreakableIce.blockID);
		world.setBlock(i + 3, j + 0, k + 43, MainRegistry.unbreakableIce.blockID);
		world.setBlock(i + 3, j + 0, k + 44, MainRegistry.unbreakableIce.blockID);
		world.setBlock(i + 3, j + 0, k + 45, MainRegistry.unbreakableIce.blockID);
		world.setBlock(i + 3, j + 0, k + 46, MainRegistry.unbreakableIce.blockID);
		world.setBlock(i + 3, j + 0, k + 47, MainRegistry.unbreakableIce.blockID);
		world.setBlock(i + 3, j + 0, k + 48, MainRegistry.unbreakableIce.blockID);
		world.setBlock(i + 3, j + 0, k + 49, MainRegistry.unbreakableIce.blockID);
		world.setBlock(i + 3, j + 0, k + 50, MainRegistry.unbreakableIce.blockID);
		world.setBlock(i + 3, j + 0, k + 51, MainRegistry.unbreakableIce.blockID);
		world.setBlock(i + 3, j + 0, k + 52, MainRegistry.unbreakableIce.blockID);
		world.setBlock(i + 3, j + 0, k + 53, MainRegistry.unbreakableIce.blockID);
		world.setBlock(i + 3, j + 0, k + 54, MainRegistry.unbreakableIce.blockID);
		world.setBlock(i + 3, j + 0, k + 55, MainRegistry.unbreakableIce.blockID);
		world.setBlock(i + 3, j + 0, k + 56, MainRegistry.unbreakableIce.blockID);
		world.setBlock(i + 3, j + 0, k + 57, MainRegistry.unbreakableIce.blockID);
		world.setBlock(i + 3, j + 0, k + 58, MainRegistry.unbreakableIce.blockID);
		world.setBlock(i + 3, j + 0, k + 59, MainRegistry.unbreakableIce.blockID);
		world.setBlock(i + 3, j + 0, k + 60, MainRegistry.unbreakableIce.blockID);
		world.setBlock(i + 3, j + 0, k + 61, MainRegistry.unbreakableIce.blockID);
		world.setBlock(i + 3, j + 0, k + 62, MainRegistry.unbreakableIce.blockID);
		world.setBlock(i + 3, j + 1, k + 26, MainRegistry.frostPlanks.blockID);
		world.setBlock(i + 3, j + 1, k + 27, MainRegistry.frostPlanks.blockID);
		world.setBlock(i + 3, j + 1, k + 28, MainRegistry.frostPlanks.blockID);
		world.setBlock(i + 3, j + 1, k + 29, MainRegistry.frostPlanks.blockID);
		world.setBlock(i + 3, j + 1, k + 30, MainRegistry.frostPlanks.blockID);
		world.setBlock(i + 3, j + 1, k + 31, MainRegistry.frostPlanks.blockID);
		world.setBlock(i + 3, j + 1, k + 32, MainRegistry.frostPlanks.blockID);
		world.setBlock(i + 3, j + 1, k + 33, MainRegistry.frostPlanks.blockID);
		world.setBlock(i + 3, j + 1, k + 34, MainRegistry.frostPlanks.blockID);
		world.setBlock(i + 3, j + 1, k + 35, MainRegistry.frostPlanks.blockID);
		world.setBlock(i + 3, j + 1, k + 36, MainRegistry.frostPlanks.blockID);
		world.setBlock(i + 3, j + 1, k + 37, MainRegistry.frostPlanks.blockID);
		world.setBlock(i + 3, j + 1, k + 38, MainRegistry.frostPlanks.blockID);
		world.setBlock(i + 3, j + 1, k + 39, MainRegistry.frostPlanks.blockID);
		world.setBlock(i + 3, j + 2, k + 26, MainRegistry.unbreakableIce.blockID);
		world.setBlock(i + 3, j + 2, k + 39, MainRegistry.unbreakableIce.blockID);
		world.setBlock(i + 3, j + 3, k + 26, MainRegistry.unbreakableIce.blockID);
		world.setBlock(i + 3, j + 3, k + 39, MainRegistry.unbreakableIce.blockID);
		world.setBlock(i + 3, j + 4, k + 26, MainRegistry.unbreakableIce.blockID);
		world.setBlock(i + 3, j + 4, k + 39, MainRegistry.unbreakableIce.blockID);
		world.setBlock(i + 3, j + 5, k + 26, MainRegistry.unbreakableIce.blockID);
		world.setBlock(i + 3, j + 5, k + 39, MainRegistry.unbreakableIce.blockID);
		world.setBlock(i + 3, j + 6, k + 26, MainRegistry.unbreakableIce.blockID);
		world.setBlock(i + 3, j + 6, k + 39, MainRegistry.unbreakableIce.blockID);
		world.setBlock(i + 3, j + 7, k + 26, MainRegistry.unbreakableIce.blockID);
		world.setBlock(i + 3, j + 7, k + 39, MainRegistry.unbreakableIce.blockID);
		world.setBlock(i + 3, j + 8, k + 26, MainRegistry.unbreakableIce.blockID);
		world.setBlock(i + 3, j + 8, k + 39, MainRegistry.unbreakableIce.blockID);
		world.setBlock(i + 3, j + 9, k + 26, MainRegistry.unbreakableIce.blockID);
		world.setBlock(i + 3, j + 9, k + 38, 30);
		world.setBlock(i + 3, j + 9, k + 39, MainRegistry.unbreakableIce.blockID);
		world.setBlock(i + 3, j + 10, k + 26, MainRegistry.unbreakableIce.blockID);
		world.setBlock(i + 3, j + 10, k + 27, 30);
		world.setBlock(i + 3, j + 10, k + 39, MainRegistry.unbreakableIce.blockID);
		world.setBlock(i + 3, j + 11, k + 26, MainRegistry.unbreakableIce.blockID);
		world.setBlock(i + 3, j + 11, k + 39, MainRegistry.unbreakableIce.blockID);
		world.setBlock(i + 3, j + 12, k + 26, MainRegistry.unbreakableIce.blockID);
		world.setBlock(i + 3, j + 12, k + 39, MainRegistry.unbreakableIce.blockID);
		world.setBlock(i + 3, j + 13, k + 26, MainRegistry.unbreakableIce.blockID);
		world.setBlock(i + 3, j + 13, k + 39, MainRegistry.unbreakableIce.blockID);
		world.setBlock(i + 3, j + 14, k + 26, MainRegistry.unbreakableIce.blockID);
		world.setBlock(i + 3, j + 14, k + 39, MainRegistry.unbreakableIce.blockID);
		world.setBlock(i + 3, j + 15, k + 26, MainRegistry.unbreakableIce.blockID);
		world.setBlock(i + 3, j + 15, k + 27, 80);
		world.setBlock(i + 3, j + 15, k + 28, 80);
		world.setBlock(i + 3, j + 15, k + 29, 80);
		world.setBlock(i + 3, j + 15, k + 30, 80);
		world.setBlock(i + 3, j + 15, k + 31, 80);
		world.setBlock(i + 3, j + 15, k + 32, 80);
		world.setBlock(i + 3, j + 15, k + 33, 80);
		world.setBlock(i + 3, j + 15, k + 34, 80);
		world.setBlock(i + 3, j + 15, k + 35, 80);
		world.setBlock(i + 3, j + 15, k + 36, 80);
		world.setBlock(i + 3, j + 15, k + 37, 80);
		world.setBlock(i + 3, j + 15, k + 38, 80);
		world.setBlock(i + 3, j + 15, k + 39, MainRegistry.unbreakableIce.blockID);
		world.setBlock(i + 4, j + 0, k + 0, MainRegistry.unbreakableIce.blockID);
		world.setBlock(i + 4, j + 0, k + 1, MainRegistry.unbreakableIce.blockID);
		world.setBlock(i + 4, j + 0, k + 2, MainRegistry.unbreakableIce.blockID);
		world.setBlock(i + 4, j + 0, k + 3, MainRegistry.unbreakableIce.blockID);
		world.setBlock(i + 4, j + 0, k + 4, MainRegistry.unbreakableIce.blockID);
		world.setBlock(i + 4, j + 0, k + 5, MainRegistry.unbreakableIce.blockID);
		world.setBlock(i + 4, j + 0, k + 6, MainRegistry.unbreakableIce.blockID);
		world.setBlock(i + 4, j + 0, k + 7, MainRegistry.unbreakableIce.blockID);
		world.setBlock(i + 4, j + 0, k + 8, MainRegistry.unbreakableIce.blockID);
		world.setBlock(i + 4, j + 0, k + 9, MainRegistry.unbreakableIce.blockID);
		world.setBlock(i + 4, j + 0, k + 10, MainRegistry.unbreakableIce.blockID);
		world.setBlock(i + 4, j + 0, k + 11, MainRegistry.unbreakableIce.blockID);
		world.setBlock(i + 4, j + 0, k + 12, MainRegistry.unbreakableIce.blockID);
		world.setBlock(i + 4, j + 0, k + 13, MainRegistry.unbreakableIce.blockID);
		world.setBlock(i + 4, j + 0, k + 14, MainRegistry.unbreakableIce.blockID);
		world.setBlock(i + 4, j + 0, k + 15, MainRegistry.unbreakableIce.blockID);
		world.setBlock(i + 4, j + 0, k + 16, MainRegistry.unbreakableIce.blockID);
		world.setBlock(i + 4, j + 0, k + 17, MainRegistry.unbreakableIce.blockID);
		world.setBlock(i + 4, j + 0, k + 18, MainRegistry.unbreakableIce.blockID);
		world.setBlock(i + 4, j + 0, k + 19, MainRegistry.unbreakableIce.blockID);
		world.setBlock(i + 4, j + 0, k + 20, MainRegistry.unbreakableIce.blockID);
		world.setBlock(i + 4, j + 0, k + 21, MainRegistry.unbreakableIce.blockID);
		world.setBlock(i + 4, j + 0, k + 22, MainRegistry.unbreakableIce.blockID);
		world.setBlock(i + 4, j + 0, k + 23, MainRegistry.unbreakableIce.blockID);
		world.setBlock(i + 4, j + 0, k + 24, MainRegistry.unbreakableIce.blockID);
		world.setBlock(i + 4, j + 0, k + 25, MainRegistry.unbreakableIce.blockID);
		world.setBlock(i + 4, j + 0, k + 26, MainRegistry.unbreakableIce.blockID);
		world.setBlock(i + 4, j + 0, k + 27, MainRegistry.unbreakableIce.blockID);
		world.setBlock(i + 4, j + 0, k + 28, MainRegistry.unbreakableIce.blockID);
		world.setBlock(i + 4, j + 0, k + 29, MainRegistry.unbreakableIce.blockID);
		world.setBlock(i + 4, j + 0, k + 30, MainRegistry.unbreakableIce.blockID);
		world.setBlock(i + 4, j + 0, k + 31, MainRegistry.unbreakableIce.blockID);
		world.setBlock(i + 4, j + 0, k + 32, MainRegistry.unbreakableIce.blockID);
		world.setBlock(i + 4, j + 0, k + 33, MainRegistry.unbreakableIce.blockID);
		world.setBlock(i + 4, j + 0, k + 34, MainRegistry.unbreakableIce.blockID);
		world.setBlock(i + 4, j + 0, k + 35, MainRegistry.unbreakableIce.blockID);
		world.setBlock(i + 4, j + 0, k + 36, MainRegistry.unbreakableIce.blockID);
		world.setBlock(i + 4, j + 0, k + 37, MainRegistry.unbreakableIce.blockID);
		world.setBlock(i + 4, j + 0, k + 38, MainRegistry.unbreakableIce.blockID);
		world.setBlock(i + 4, j + 0, k + 39, MainRegistry.unbreakableIce.blockID);
		world.setBlock(i + 4, j + 0, k + 40, MainRegistry.unbreakableIce.blockID);
		world.setBlock(i + 4, j + 0, k + 41, MainRegistry.unbreakableIce.blockID);
		world.setBlock(i + 4, j + 0, k + 42, MainRegistry.unbreakableIce.blockID);
		world.setBlock(i + 4, j + 0, k + 43, MainRegistry.unbreakableIce.blockID);
		world.setBlock(i + 4, j + 0, k + 44, MainRegistry.unbreakableIce.blockID);
		world.setBlock(i + 4, j + 0, k + 45, MainRegistry.unbreakableIce.blockID);
		world.setBlock(i + 4, j + 0, k + 46, MainRegistry.unbreakableIce.blockID);
		world.setBlock(i + 4, j + 0, k + 47, MainRegistry.unbreakableIce.blockID);
		world.setBlock(i + 4, j + 0, k + 48, MainRegistry.unbreakableIce.blockID);
		world.setBlock(i + 4, j + 0, k + 49, MainRegistry.unbreakableIce.blockID);
		world.setBlock(i + 4, j + 0, k + 50, MainRegistry.unbreakableIce.blockID);
		world.setBlock(i + 4, j + 0, k + 51, MainRegistry.unbreakableIce.blockID);
		world.setBlock(i + 4, j + 0, k + 52, MainRegistry.unbreakableIce.blockID);
		world.setBlock(i + 4, j + 0, k + 53, MainRegistry.unbreakableIce.blockID);
		world.setBlock(i + 4, j + 0, k + 54, MainRegistry.unbreakableIce.blockID);
		world.setBlock(i + 4, j + 0, k + 55, MainRegistry.unbreakableIce.blockID);
		world.setBlock(i + 4, j + 0, k + 56, MainRegistry.unbreakableIce.blockID);
		world.setBlock(i + 4, j + 0, k + 57, MainRegistry.unbreakableIce.blockID);
		world.setBlock(i + 4, j + 0, k + 58, MainRegistry.unbreakableIce.blockID);
		world.setBlock(i + 4, j + 0, k + 59, MainRegistry.unbreakableIce.blockID);
		world.setBlock(i + 4, j + 0, k + 60, MainRegistry.unbreakableIce.blockID);
		world.setBlock(i + 4, j + 0, k + 61, MainRegistry.unbreakableIce.blockID);
		world.setBlock(i + 4, j + 0, k + 62, MainRegistry.unbreakableIce.blockID);
		world.setBlock(i + 4, j + 1, k + 26, MainRegistry.frostPlanks.blockID);
		world.setBlock(i + 4, j + 1, k + 27, MainRegistry.frostPlanks.blockID);
		world.setBlock(i + 4, j + 1, k + 28, MainRegistry.frostPlanks.blockID);
		world.setBlock(i + 4, j + 1, k + 29, MainRegistry.frostPlanks.blockID);
		world.setBlock(i + 4, j + 1, k + 30, MainRegistry.frostPlanks.blockID);
		world.setBlock(i + 4, j + 1, k + 31, MainRegistry.frostPlanks.blockID);
		world.setBlock(i + 4, j + 1, k + 32, MainRegistry.frostPlanks.blockID);
		world.setBlock(i + 4, j + 1, k + 33, MainRegistry.frostPlanks.blockID);
		world.setBlock(i + 4, j + 1, k + 34, MainRegistry.frostPlanks.blockID);
		world.setBlock(i + 4, j + 1, k + 35, MainRegistry.frostPlanks.blockID);
		world.setBlock(i + 4, j + 1, k + 36, MainRegistry.frostPlanks.blockID);
		world.setBlock(i + 4, j + 1, k + 37, MainRegistry.frostPlanks.blockID);
		world.setBlock(i + 4, j + 1, k + 38, MainRegistry.frostPlanks.blockID);
		world.setBlock(i + 4, j + 1, k + 39, MainRegistry.frostPlanks.blockID);
		world.setBlock(i + 4, j + 1, k + 40, MainRegistry.frostPlanks.blockID);
		world.setBlock(i + 4, j + 2, k + 26, MainRegistry.unbreakableIce.blockID);
		world.setBlock(i + 4, j + 2, k + 33, 30);
		world.setBlock(i + 4, j + 2, k + 35, 30);
		world.setBlock(i + 4, j + 2, k + 40, MainRegistry.unbreakableIce.blockID);
		world.setBlock(i + 4, j + 3, k + 26, MainRegistry.unbreakableIce.blockID);
		world.setBlock(i + 4, j + 3, k + 40, MainRegistry.unbreakableIce.blockID);
		world.setBlock(i + 4, j + 4, k + 26, MainRegistry.unbreakableIce.blockID);
		world.setBlock(i + 4, j + 4, k + 40, MainRegistry.unbreakableIce.blockID);
		world.setBlock(i + 4, j + 5, k + 26, MainRegistry.unbreakableIce.blockID);
		world.setBlock(i + 4, j + 5, k + 40, MainRegistry.unbreakableIce.blockID);
		world.setBlock(i + 4, j + 6, k + 26, MainRegistry.unbreakableIce.blockID);
		world.setBlock(i + 4, j + 6, k + 40, MainRegistry.unbreakableIce.blockID);
		world.setBlock(i + 4, j + 7, k + 26, MainRegistry.unbreakableIce.blockID);
		world.setBlock(i + 4, j + 7, k + 40, MainRegistry.unbreakableIce.blockID);
		world.setBlock(i + 4, j + 8, k + 26, MainRegistry.unbreakableIce.blockID);
		world.setBlock(i + 4, j + 8, k + 39, 30);
		world.setBlock(i + 4, j + 8, k + 40, MainRegistry.unbreakableIce.blockID);
		world.setBlock(i + 4, j + 9, k + 26, MainRegistry.unbreakableIce.blockID);
		world.setBlock(i + 4, j + 9, k + 40, MainRegistry.unbreakableIce.blockID);
		world.setBlock(i + 4, j + 10, k + 26, MainRegistry.unbreakableIce.blockID);
		world.setBlock(i + 4, j + 10, k + 40, MainRegistry.unbreakableIce.blockID);
		world.setBlock(i + 4, j + 11, k + 26, MainRegistry.unbreakableIce.blockID);
		world.setBlock(i + 4, j + 11, k + 40, MainRegistry.unbreakableIce.blockID);
		world.setBlock(i + 4, j + 12, k + 26, MainRegistry.unbreakableIce.blockID);
		world.setBlock(i + 4, j + 12, k + 40, MainRegistry.unbreakableIce.blockID);
		world.setBlock(i + 4, j + 13, k + 26, MainRegistry.unbreakableIce.blockID);
		world.setBlock(i + 4, j + 13, k + 40, MainRegistry.unbreakableIce.blockID);
		world.setBlock(i + 4, j + 14, k + 26, MainRegistry.unbreakableIce.blockID);
		world.setBlock(i + 4, j + 14, k + 40, MainRegistry.unbreakableIce.blockID);
		world.setBlock(i + 4, j + 15, k + 26, MainRegistry.unbreakableIce.blockID);
		world.setBlock(i + 4, j + 15, k + 40, MainRegistry.unbreakableIce.blockID);
		world.setBlock(i + 4, j + 16, k + 26, MainRegistry.unbreakableIce.blockID);
		world.setBlock(i + 4, j + 16, k + 27, 80);
		world.setBlock(i + 4, j + 16, k + 28, 80);
		world.setBlock(i + 4, j + 16, k + 29, 80);
		world.setBlock(i + 4, j + 16, k + 30, 80);
		world.setBlock(i + 4, j + 16, k + 31, 80);
		world.setBlock(i + 4, j + 16, k + 32, 80);
		world.setBlock(i + 4, j + 16, k + 33, 80);
		world.setBlock(i + 4, j + 16, k + 34, 80);
		world.setBlock(i + 4, j + 16, k + 35, 80);
		world.setBlock(i + 4, j + 16, k + 36, 80);
		world.setBlock(i + 4, j + 16, k + 37, 80);
		world.setBlock(i + 4, j + 16, k + 38, 80);
		world.setBlock(i + 4, j + 16, k + 39, 80);
		world.setBlock(i + 4, j + 16, k + 40, MainRegistry.unbreakableIce.blockID);
		world.setBlock(i + 5, j + 0, k + 0, MainRegistry.unbreakableIce.blockID);
		world.setBlock(i + 5, j + 0, k + 1, MainRegistry.unbreakableIce.blockID);
		world.setBlock(i + 5, j + 0, k + 2, MainRegistry.unbreakableIce.blockID);
		world.setBlock(i + 5, j + 0, k + 3, MainRegistry.unbreakableIce.blockID);
		world.setBlock(i + 5, j + 0, k + 4, MainRegistry.unbreakableIce.blockID);
		world.setBlock(i + 5, j + 0, k + 5, MainRegistry.unbreakableIce.blockID);
		world.setBlock(i + 5, j + 0, k + 6, MainRegistry.unbreakableIce.blockID);
		world.setBlock(i + 5, j + 0, k + 7, MainRegistry.unbreakableIce.blockID);
		world.setBlock(i + 5, j + 0, k + 8, MainRegistry.unbreakableIce.blockID);
		world.setBlock(i + 5, j + 0, k + 9, MainRegistry.unbreakableIce.blockID);
		world.setBlock(i + 5, j + 0, k + 10, MainRegistry.unbreakableIce.blockID);
		world.setBlock(i + 5, j + 0, k + 11, MainRegistry.unbreakableIce.blockID);
		world.setBlock(i + 5, j + 0, k + 12, MainRegistry.unbreakableIce.blockID);
		world.setBlock(i + 5, j + 0, k + 13, MainRegistry.unbreakableIce.blockID);
		world.setBlock(i + 5, j + 0, k + 14, MainRegistry.unbreakableIce.blockID);
		world.setBlock(i + 5, j + 0, k + 15, MainRegistry.unbreakableIce.blockID);
		world.setBlock(i + 5, j + 0, k + 16, MainRegistry.unbreakableIce.blockID);
		world.setBlock(i + 5, j + 0, k + 17, MainRegistry.unbreakableIce.blockID);
		world.setBlock(i + 5, j + 0, k + 18, MainRegistry.unbreakableIce.blockID);
		world.setBlock(i + 5, j + 0, k + 19, MainRegistry.unbreakableIce.blockID);
		world.setBlock(i + 5, j + 0, k + 20, MainRegistry.unbreakableIce.blockID);
		world.setBlock(i + 5, j + 0, k + 21, MainRegistry.unbreakableIce.blockID);
		world.setBlock(i + 5, j + 0, k + 22, MainRegistry.unbreakableIce.blockID);
		world.setBlock(i + 5, j + 0, k + 23, MainRegistry.unbreakableIce.blockID);
		world.setBlock(i + 5, j + 0, k + 24, MainRegistry.unbreakableIce.blockID);
		world.setBlock(i + 5, j + 0, k + 25, MainRegistry.unbreakableIce.blockID);
		world.setBlock(i + 5, j + 0, k + 26, MainRegistry.unbreakableIce.blockID);
		world.setBlock(i + 5, j + 0, k + 27, MainRegistry.unbreakableIce.blockID);
		world.setBlock(i + 5, j + 0, k + 28, MainRegistry.unbreakableIce.blockID);
		world.setBlock(i + 5, j + 0, k + 29, MainRegistry.unbreakableIce.blockID);
		world.setBlock(i + 5, j + 0, k + 30, MainRegistry.unbreakableIce.blockID);
		world.setBlock(i + 5, j + 0, k + 31, MainRegistry.unbreakableIce.blockID);
		world.setBlock(i + 5, j + 0, k + 32, MainRegistry.unbreakableIce.blockID);
		world.setBlock(i + 5, j + 0, k + 33, MainRegistry.unbreakableIce.blockID);
		world.setBlock(i + 5, j + 0, k + 34, MainRegistry.unbreakableIce.blockID);
		world.setBlock(i + 5, j + 0, k + 35, MainRegistry.unbreakableIce.blockID);
		world.setBlock(i + 5, j + 0, k + 36, MainRegistry.unbreakableIce.blockID);
		world.setBlock(i + 5, j + 0, k + 37, MainRegistry.unbreakableIce.blockID);
		world.setBlock(i + 5, j + 0, k + 38, MainRegistry.unbreakableIce.blockID);
		world.setBlock(i + 5, j + 0, k + 39, MainRegistry.unbreakableIce.blockID);
		world.setBlock(i + 5, j + 0, k + 40, MainRegistry.unbreakableIce.blockID);
		world.setBlock(i + 5, j + 0, k + 41, MainRegistry.unbreakableIce.blockID);
		world.setBlock(i + 5, j + 0, k + 42, MainRegistry.unbreakableIce.blockID);
		world.setBlock(i + 5, j + 0, k + 43, MainRegistry.unbreakableIce.blockID);
		world.setBlock(i + 5, j + 0, k + 44, MainRegistry.unbreakableIce.blockID);
		world.setBlock(i + 5, j + 0, k + 45, MainRegistry.unbreakableIce.blockID);
		world.setBlock(i + 5, j + 0, k + 46, MainRegistry.unbreakableIce.blockID);
		world.setBlock(i + 5, j + 0, k + 47, MainRegistry.unbreakableIce.blockID);
		world.setBlock(i + 5, j + 0, k + 48, MainRegistry.unbreakableIce.blockID);
		world.setBlock(i + 5, j + 0, k + 49, MainRegistry.unbreakableIce.blockID);
		world.setBlock(i + 5, j + 0, k + 50, MainRegistry.unbreakableIce.blockID);
		world.setBlock(i + 5, j + 0, k + 51, MainRegistry.unbreakableIce.blockID);
		world.setBlock(i + 5, j + 0, k + 52, MainRegistry.unbreakableIce.blockID);
		world.setBlock(i + 5, j + 0, k + 53, MainRegistry.unbreakableIce.blockID);
		world.setBlock(i + 5, j + 0, k + 54, MainRegistry.unbreakableIce.blockID);
		world.setBlock(i + 5, j + 0, k + 55, MainRegistry.unbreakableIce.blockID);
		world.setBlock(i + 5, j + 0, k + 56, MainRegistry.unbreakableIce.blockID);
		world.setBlock(i + 5, j + 0, k + 57, MainRegistry.unbreakableIce.blockID);
		world.setBlock(i + 5, j + 0, k + 58, MainRegistry.unbreakableIce.blockID);
		world.setBlock(i + 5, j + 0, k + 59, MainRegistry.unbreakableIce.blockID);
		world.setBlock(i + 5, j + 0, k + 60, MainRegistry.unbreakableIce.blockID);
		world.setBlock(i + 5, j + 0, k + 61, MainRegistry.unbreakableIce.blockID);
		world.setBlock(i + 5, j + 0, k + 62, MainRegistry.unbreakableIce.blockID);
		world.setBlock(i + 5, j + 1, k + 26, MainRegistry.frostPlanks.blockID);
		world.setBlock(i + 5, j + 1, k + 27, MainRegistry.frostPlanks.blockID);
		world.setBlock(i + 5, j + 1, k + 28, MainRegistry.frostPlanks.blockID);
		world.setBlock(i + 5, j + 1, k + 29, MainRegistry.frostPlanks.blockID);
		world.setBlock(i + 5, j + 1, k + 30, MainRegistry.frostPlanks.blockID);
		world.setBlock(i + 5, j + 1, k + 31, MainRegistry.frostPlanks.blockID);
		world.setBlock(i + 5, j + 1, k + 32, MainRegistry.frostPlanks.blockID);
		world.setBlock(i + 5, j + 1, k + 33, MainRegistry.frostPlanks.blockID);
		world.setBlock(i + 5, j + 1, k + 34, MainRegistry.frostPlanks.blockID);
		world.setBlock(i + 5, j + 1, k + 35, MainRegistry.frostPlanks.blockID);
		world.setBlock(i + 5, j + 1, k + 36, MainRegistry.frostPlanks.blockID);
		world.setBlock(i + 5, j + 1, k + 37, MainRegistry.frostPlanks.blockID);
		world.setBlock(i + 5, j + 1, k + 38, MainRegistry.frostPlanks.blockID);
		world.setBlock(i + 5, j + 1, k + 39, MainRegistry.frostPlanks.blockID);
		world.setBlock(i + 5, j + 1, k + 40, MainRegistry.frostPlanks.blockID);
		world.setBlock(i + 5, j + 2, k + 26, MainRegistry.unbreakableIce.blockID);
		world.setBlock(i + 5, j + 2, k + 40, MainRegistry.unbreakableIce.blockID);
		world.setBlock(i + 5, j + 3, k + 26, MainRegistry.unbreakableIce.blockID);
		world.setBlock(i + 5, j + 3, k + 40, MainRegistry.unbreakableIce.blockID);
		world.setBlock(i + 5, j + 4, k + 26, MainRegistry.unbreakableIce.blockID);
		world.setBlock(i + 5, j + 4, k + 40, MainRegistry.unbreakableIce.blockID);
		world.setBlock(i + 5, j + 5, k + 26, MainRegistry.unbreakableIce.blockID);
		world.setBlock(i + 5, j + 5, k + 40, MainRegistry.unbreakableIce.blockID);
		world.setBlock(i + 5, j + 6, k + 26, MainRegistry.unbreakableIce.blockID);
		world.setBlock(i + 5, j + 6, k + 40, MainRegistry.unbreakableIce.blockID);
		world.setBlock(i + 5, j + 7, k + 26, MainRegistry.unbreakableIce.blockID);
		world.setBlock(i + 5, j + 7, k + 40, MainRegistry.unbreakableIce.blockID);
		world.setBlock(i + 5, j + 8, k + 26, MainRegistry.unbreakableIce.blockID);
		world.setBlock(i + 5, j + 8, k + 40, MainRegistry.unbreakableIce.blockID);
		world.setBlock(i + 5, j + 9, k + 26, MainRegistry.unbreakableIce.blockID);
		world.setBlock(i + 5, j + 9, k + 40, MainRegistry.unbreakableIce.blockID);
		world.setBlock(i + 5, j + 10, k + 26, MainRegistry.unbreakableIce.blockID);
		world.setBlock(i + 5, j + 10, k + 40, MainRegistry.unbreakableIce.blockID);
		world.setBlock(i + 5, j + 11, k + 26, MainRegistry.unbreakableIce.blockID);
		world.setBlock(i + 5, j + 11, k + 40, MainRegistry.unbreakableIce.blockID);
		world.setBlock(i + 5, j + 12, k + 26, MainRegistry.unbreakableIce.blockID);
		world.setBlock(i + 5, j + 12, k + 40, MainRegistry.unbreakableIce.blockID);
		world.setBlock(i + 5, j + 13, k + 26, MainRegistry.unbreakableIce.blockID);
		world.setBlock(i + 5, j + 13, k + 40, MainRegistry.unbreakableIce.blockID);
		world.setBlock(i + 5, j + 14, k + 26, MainRegistry.unbreakableIce.blockID);
		world.setBlock(i + 5, j + 14, k + 40, MainRegistry.unbreakableIce.blockID);
		world.setBlock(i + 5, j + 15, k + 26, MainRegistry.unbreakableIce.blockID);
		world.setBlock(i + 5, j + 15, k + 40, MainRegistry.unbreakableIce.blockID);
		world.setBlock(i + 5, j + 16, k + 26, MainRegistry.unbreakableIce.blockID);
		world.setBlock(i + 5, j + 16, k + 27, 80);
		world.setBlock(i + 5, j + 16, k + 28, 80);
		world.setBlock(i + 5, j + 16, k + 29, 80);
		world.setBlock(i + 5, j + 16, k + 30, 80);
		world.setBlock(i + 5, j + 16, k + 31, 80);
		world.setBlock(i + 5, j + 16, k + 32, 80);
		world.setBlock(i + 5, j + 16, k + 33, 80);
		world.setBlock(i + 5, j + 16, k + 34, 80);
		world.setBlock(i + 5, j + 16, k + 35, 80);
		world.setBlock(i + 5, j + 16, k + 36, 80);
		world.setBlock(i + 5, j + 16, k + 37, 80);
		world.setBlock(i + 5, j + 16, k + 38, 80);
		world.setBlock(i + 5, j + 16, k + 39, 80);
		world.setBlock(i + 5, j + 16, k + 40, MainRegistry.unbreakableIce.blockID);
		world.setBlock(i + 6, j + 0, k + 0, MainRegistry.unbreakableIce.blockID);
		world.setBlock(i + 6, j + 0, k + 1, MainRegistry.unbreakableIce.blockID);
		world.setBlock(i + 6, j + 0, k + 2, MainRegistry.unbreakableIce.blockID);
		world.setBlock(i + 6, j + 0, k + 3, MainRegistry.unbreakableIce.blockID);
		world.setBlock(i + 6, j + 0, k + 4, MainRegistry.unbreakableIce.blockID);
		world.setBlock(i + 6, j + 0, k + 5, MainRegistry.unbreakableIce.blockID);
		world.setBlock(i + 6, j + 0, k + 6, MainRegistry.unbreakableIce.blockID);
		world.setBlock(i + 6, j + 0, k + 7, MainRegistry.unbreakableIce.blockID);
		world.setBlock(i + 6, j + 0, k + 8, MainRegistry.unbreakableIce.blockID);
		world.setBlock(i + 6, j + 0, k + 9, MainRegistry.unbreakableIce.blockID);
		world.setBlock(i + 6, j + 0, k + 10, MainRegistry.unbreakableIce.blockID);
		world.setBlock(i + 6, j + 0, k + 11, MainRegistry.unbreakableIce.blockID);
		world.setBlock(i + 6, j + 0, k + 12, MainRegistry.unbreakableIce.blockID);
		world.setBlock(i + 6, j + 0, k + 13, MainRegistry.unbreakableIce.blockID);
		world.setBlock(i + 6, j + 0, k + 14, MainRegistry.unbreakableIce.blockID);
		world.setBlock(i + 6, j + 0, k + 15, MainRegistry.unbreakableIce.blockID);
		world.setBlock(i + 6, j + 0, k + 16, MainRegistry.unbreakableIce.blockID);
		world.setBlock(i + 6, j + 0, k + 17, MainRegistry.unbreakableIce.blockID);
		world.setBlock(i + 6, j + 0, k + 18, MainRegistry.unbreakableIce.blockID);
		world.setBlock(i + 6, j + 0, k + 19, MainRegistry.unbreakableIce.blockID);
		world.setBlock(i + 6, j + 0, k + 20, MainRegistry.unbreakableIce.blockID);
		world.setBlock(i + 6, j + 0, k + 21, MainRegistry.unbreakableIce.blockID);
		world.setBlock(i + 6, j + 0, k + 22, MainRegistry.unbreakableIce.blockID);
		world.setBlock(i + 6, j + 0, k + 23, MainRegistry.unbreakableIce.blockID);
		world.setBlock(i + 6, j + 0, k + 24, MainRegistry.unbreakableIce.blockID);
		world.setBlock(i + 6, j + 0, k + 25, MainRegistry.unbreakableIce.blockID);
		world.setBlock(i + 6, j + 0, k + 26, MainRegistry.unbreakableIce.blockID);
		world.setBlock(i + 6, j + 0, k + 27, MainRegistry.unbreakableIce.blockID);
		world.setBlock(i + 6, j + 0, k + 28, MainRegistry.unbreakableIce.blockID);
		world.setBlock(i + 6, j + 0, k + 29, MainRegistry.unbreakableIce.blockID);
		world.setBlock(i + 6, j + 0, k + 30, MainRegistry.unbreakableIce.blockID);
		world.setBlock(i + 6, j + 0, k + 31, MainRegistry.unbreakableIce.blockID);
		world.setBlock(i + 6, j + 0, k + 32, MainRegistry.unbreakableIce.blockID);
		world.setBlock(i + 6, j + 0, k + 33, MainRegistry.unbreakableIce.blockID);
		world.setBlock(i + 6, j + 0, k + 34, MainRegistry.unbreakableIce.blockID);
		world.setBlock(i + 6, j + 0, k + 35, MainRegistry.unbreakableIce.blockID);
		world.setBlock(i + 6, j + 0, k + 36, MainRegistry.unbreakableIce.blockID);
		world.setBlock(i + 6, j + 0, k + 37, MainRegistry.unbreakableIce.blockID);
		world.setBlock(i + 6, j + 0, k + 38, MainRegistry.unbreakableIce.blockID);
		world.setBlock(i + 6, j + 0, k + 39, MainRegistry.unbreakableIce.blockID);
		world.setBlock(i + 6, j + 0, k + 40, MainRegistry.unbreakableIce.blockID);
		world.setBlock(i + 6, j + 0, k + 41, MainRegistry.unbreakableIce.blockID);
		world.setBlock(i + 6, j + 0, k + 42, MainRegistry.unbreakableIce.blockID);
		world.setBlock(i + 6, j + 0, k + 43, MainRegistry.unbreakableIce.blockID);
		world.setBlock(i + 6, j + 0, k + 44, MainRegistry.unbreakableIce.blockID);
		world.setBlock(i + 6, j + 0, k + 45, MainRegistry.unbreakableIce.blockID);
		world.setBlock(i + 6, j + 0, k + 46, MainRegistry.unbreakableIce.blockID);
		world.setBlock(i + 6, j + 0, k + 47, MainRegistry.unbreakableIce.blockID);
		world.setBlock(i + 6, j + 0, k + 48, MainRegistry.unbreakableIce.blockID);
		world.setBlock(i + 6, j + 0, k + 49, MainRegistry.unbreakableIce.blockID);
		world.setBlock(i + 6, j + 0, k + 50, MainRegistry.unbreakableIce.blockID);
		world.setBlock(i + 6, j + 0, k + 51, MainRegistry.unbreakableIce.blockID);
		world.setBlock(i + 6, j + 0, k + 52, MainRegistry.unbreakableIce.blockID);
		world.setBlock(i + 6, j + 0, k + 53, MainRegistry.unbreakableIce.blockID);
		world.setBlock(i + 6, j + 0, k + 54, MainRegistry.unbreakableIce.blockID);
		world.setBlock(i + 6, j + 0, k + 55, MainRegistry.unbreakableIce.blockID);
		world.setBlock(i + 6, j + 0, k + 56, MainRegistry.unbreakableIce.blockID);
		world.setBlock(i + 6, j + 0, k + 57, MainRegistry.unbreakableIce.blockID);
		world.setBlock(i + 6, j + 0, k + 58, MainRegistry.unbreakableIce.blockID);
		world.setBlock(i + 6, j + 0, k + 59, MainRegistry.unbreakableIce.blockID);
		world.setBlock(i + 6, j + 0, k + 60, MainRegistry.unbreakableIce.blockID);
		world.setBlock(i + 6, j + 0, k + 61, MainRegistry.unbreakableIce.blockID);
		world.setBlock(i + 6, j + 0, k + 62, MainRegistry.unbreakableIce.blockID);
		world.setBlock(i + 6, j + 1, k + 26, MainRegistry.frostPlanks.blockID);
		world.setBlock(i + 6, j + 1, k + 27, MainRegistry.frostPlanks.blockID);
		world.setBlock(i + 6, j + 1, k + 28, MainRegistry.frostPlanks.blockID);
		world.setBlock(i + 6, j + 1, k + 29, MainRegistry.frostPlanks.blockID);
		world.setBlock(i + 6, j + 1, k + 30, MainRegistry.frostPlanks.blockID);
		world.setBlock(i + 6, j + 1, k + 31, MainRegistry.frostPlanks.blockID);
		world.setBlock(i + 6, j + 1, k + 32, MainRegistry.frostPlanks.blockID);
		world.setBlock(i + 6, j + 1, k + 33, MainRegistry.frostPlanks.blockID);
		world.setBlock(i + 6, j + 1, k + 34, MainRegistry.frostPlanks.blockID);
		world.setBlock(i + 6, j + 1, k + 35, MainRegistry.frostPlanks.blockID);
		world.setBlock(i + 6, j + 1, k + 36, MainRegistry.frostPlanks.blockID);
		world.setBlock(i + 6, j + 1, k + 37, MainRegistry.frostPlanks.blockID);
		world.setBlock(i + 6, j + 1, k + 38, MainRegistry.frostPlanks.blockID);
		world.setBlock(i + 6, j + 1, k + 39, MainRegistry.frostPlanks.blockID);
		world.setBlock(i + 6, j + 1, k + 40, MainRegistry.frostPlanks.blockID);
		world.setBlock(i + 6, j + 2, k + 26, MainRegistry.unbreakableIce.blockID);
		world.setBlock(i + 6, j + 2, k + 31, 30);
		world.setBlock(i + 6, j + 2, k + 33, 30);
		world.setBlock(i + 6, j + 2, k + 40, MainRegistry.unbreakableIce.blockID);
		world.setBlock(i + 6, j + 3, k + 26, MainRegistry.unbreakableIce.blockID);
		world.setBlock(i + 6, j + 3, k + 40, MainRegistry.unbreakableIce.blockID);
		world.setBlock(i + 6, j + 4, k + 26, MainRegistry.unbreakableIce.blockID);
		world.setBlock(i + 6, j + 4, k + 40, MainRegistry.unbreakableIce.blockID);
		world.setBlock(i + 6, j + 5, k + 26, MainRegistry.unbreakableIce.blockID);
		world.setBlock(i + 6, j + 5, k + 40, MainRegistry.unbreakableIce.blockID);
		world.setBlock(i + 6, j + 6, k + 26, MainRegistry.unbreakableIce.blockID);
		world.setBlock(i + 6, j + 6, k + 40, MainRegistry.unbreakableIce.blockID);
		world.setBlock(i + 6, j + 7, k + 26, MainRegistry.unbreakableIce.blockID);
		world.setBlock(i + 6, j + 7, k + 40, MainRegistry.unbreakableIce.blockID);
		world.setBlock(i + 6, j + 8, k + 26, MainRegistry.unbreakableIce.blockID);
		world.setBlock(i + 6, j + 8, k + 40, MainRegistry.unbreakableIce.blockID);
		world.setBlock(i + 6, j + 9, k + 26, MainRegistry.unbreakableIce.blockID);
		world.setBlock(i + 6, j + 9, k + 40, MainRegistry.unbreakableIce.blockID);
		world.setBlock(i + 6, j + 10, k + 26, MainRegistry.unbreakableIce.blockID);
		world.setBlock(i + 6, j + 10, k + 40, MainRegistry.unbreakableIce.blockID);
		world.setBlock(i + 6, j + 11, k + 26, MainRegistry.unbreakableIce.blockID);
		world.setBlock(i + 6, j + 11, k + 40, MainRegistry.unbreakableIce.blockID);
		world.setBlock(i + 6, j + 12, k + 26, MainRegistry.unbreakableIce.blockID);
		world.setBlock(i + 6, j + 12, k + 40, MainRegistry.unbreakableIce.blockID);
		world.setBlock(i + 6, j + 13, k + 26, MainRegistry.unbreakableIce.blockID);
		world.setBlock(i + 6, j + 13, k + 40, MainRegistry.unbreakableIce.blockID);
		world.setBlock(i + 6, j + 14, k + 26, MainRegistry.unbreakableIce.blockID);
		world.setBlock(i + 6, j + 14, k + 40, MainRegistry.unbreakableIce.blockID);
		world.setBlock(i + 6, j + 15, k + 26, MainRegistry.unbreakableIce.blockID);
		world.setBlock(i + 6, j + 15, k + 27, 80);
		world.setBlock(i + 6, j + 15, k + 28, 80);
		world.setBlock(i + 6, j + 15, k + 29, 80);
		world.setBlock(i + 6, j + 15, k + 30, 80);
		world.setBlock(i + 6, j + 15, k + 31, 80);
		world.setBlock(i + 6, j + 15, k + 32, 80);
		world.setBlock(i + 6, j + 15, k + 33, 80);
		world.setBlock(i + 6, j + 15, k + 34, 80);
		world.setBlock(i + 6, j + 15, k + 35, 80);
		world.setBlock(i + 6, j + 15, k + 36, 80);
		world.setBlock(i + 6, j + 15, k + 37, 80);
		world.setBlock(i + 6, j + 15, k + 38, 80);
		world.setBlock(i + 6, j + 15, k + 39, 80);
		world.setBlock(i + 6, j + 15, k + 40, MainRegistry.unbreakableIce.blockID);
		world.setBlock(i + 7, j + 0, k + 0, MainRegistry.unbreakableIce.blockID);
		world.setBlock(i + 7, j + 0, k + 1, MainRegistry.unbreakableIce.blockID);
		world.setBlock(i + 7, j + 0, k + 2, MainRegistry.unbreakableIce.blockID);
		world.setBlock(i + 7, j + 0, k + 3, MainRegistry.unbreakableIce.blockID);
		world.setBlock(i + 7, j + 0, k + 4, MainRegistry.unbreakableIce.blockID);
		world.setBlock(i + 7, j + 0, k + 5, MainRegistry.unbreakableIce.blockID);
		world.setBlock(i + 7, j + 0, k + 6, MainRegistry.unbreakableIce.blockID);
		world.setBlock(i + 7, j + 0, k + 7, MainRegistry.unbreakableIce.blockID);
		world.setBlock(i + 7, j + 0, k + 8, MainRegistry.unbreakableIce.blockID);
		world.setBlock(i + 7, j + 0, k + 9, MainRegistry.unbreakableIce.blockID);
		world.setBlock(i + 7, j + 0, k + 10, MainRegistry.unbreakableIce.blockID);
		world.setBlock(i + 7, j + 0, k + 11, MainRegistry.unbreakableIce.blockID);
		world.setBlock(i + 7, j + 0, k + 12, MainRegistry.unbreakableIce.blockID);
		world.setBlock(i + 7, j + 0, k + 13, MainRegistry.unbreakableIce.blockID);
		world.setBlock(i + 7, j + 0, k + 14, MainRegistry.unbreakableIce.blockID);
		world.setBlock(i + 7, j + 0, k + 15, MainRegistry.unbreakableIce.blockID);
		world.setBlock(i + 7, j + 0, k + 16, MainRegistry.unbreakableIce.blockID);
		world.setBlock(i + 7, j + 0, k + 17, MainRegistry.unbreakableIce.blockID);
		world.setBlock(i + 7, j + 0, k + 18, MainRegistry.unbreakableIce.blockID);
		world.setBlock(i + 7, j + 0, k + 19, MainRegistry.unbreakableIce.blockID);
		world.setBlock(i + 7, j + 0, k + 20, MainRegistry.unbreakableIce.blockID);
		world.setBlock(i + 7, j + 0, k + 21, MainRegistry.unbreakableIce.blockID);
		world.setBlock(i + 7, j + 0, k + 22, MainRegistry.unbreakableIce.blockID);
		world.setBlock(i + 7, j + 0, k + 23, MainRegistry.unbreakableIce.blockID);
		world.setBlock(i + 7, j + 0, k + 24, MainRegistry.unbreakableIce.blockID);
		world.setBlock(i + 7, j + 0, k + 25, MainRegistry.unbreakableIce.blockID);
		world.setBlock(i + 7, j + 0, k + 26, MainRegistry.unbreakableIce.blockID);
		world.setBlock(i + 7, j + 0, k + 27, MainRegistry.unbreakableIce.blockID);
		world.setBlock(i + 7, j + 0, k + 28, MainRegistry.unbreakableIce.blockID);
		world.setBlock(i + 7, j + 0, k + 29, MainRegistry.unbreakableIce.blockID);
		world.setBlock(i + 7, j + 0, k + 30, MainRegistry.unbreakableIce.blockID);
		world.setBlock(i + 7, j + 0, k + 31, MainRegistry.unbreakableIce.blockID);
		world.setBlock(i + 7, j + 0, k + 32, MainRegistry.unbreakableIce.blockID);
		world.setBlock(i + 7, j + 0, k + 33, MainRegistry.unbreakableIce.blockID);
		world.setBlock(i + 7, j + 0, k + 34, MainRegistry.unbreakableIce.blockID);
		world.setBlock(i + 7, j + 0, k + 35, MainRegistry.unbreakableIce.blockID);
		world.setBlock(i + 7, j + 0, k + 36, MainRegistry.unbreakableIce.blockID);
		world.setBlock(i + 7, j + 0, k + 37, MainRegistry.unbreakableIce.blockID);
		world.setBlock(i + 7, j + 0, k + 38, MainRegistry.unbreakableIce.blockID);
		world.setBlock(i + 7, j + 0, k + 39, MainRegistry.unbreakableIce.blockID);
		world.setBlock(i + 7, j + 0, k + 40, MainRegistry.unbreakableIce.blockID);
		world.setBlock(i + 7, j + 0, k + 41, MainRegistry.unbreakableIce.blockID);
		world.setBlock(i + 7, j + 0, k + 42, MainRegistry.unbreakableIce.blockID);
		world.setBlock(i + 7, j + 0, k + 43, MainRegistry.unbreakableIce.blockID);
		world.setBlock(i + 7, j + 0, k + 44, MainRegistry.unbreakableIce.blockID);
		world.setBlock(i + 7, j + 0, k + 45, MainRegistry.unbreakableIce.blockID);
		world.setBlock(i + 7, j + 0, k + 46, MainRegistry.unbreakableIce.blockID);
		world.setBlock(i + 7, j + 0, k + 47, MainRegistry.unbreakableIce.blockID);
		world.setBlock(i + 7, j + 0, k + 48, MainRegistry.unbreakableIce.blockID);
		world.setBlock(i + 7, j + 0, k + 49, MainRegistry.unbreakableIce.blockID);
		world.setBlock(i + 7, j + 0, k + 50, MainRegistry.unbreakableIce.blockID);
		world.setBlock(i + 7, j + 0, k + 51, MainRegistry.unbreakableIce.blockID);
		world.setBlock(i + 7, j + 0, k + 52, MainRegistry.unbreakableIce.blockID);
		world.setBlock(i + 7, j + 0, k + 53, MainRegistry.unbreakableIce.blockID);
		world.setBlock(i + 7, j + 0, k + 54, MainRegistry.unbreakableIce.blockID);
		world.setBlock(i + 7, j + 0, k + 55, MainRegistry.unbreakableIce.blockID);
		world.setBlock(i + 7, j + 0, k + 56, MainRegistry.unbreakableIce.blockID);
		world.setBlock(i + 7, j + 0, k + 57, MainRegistry.unbreakableIce.blockID);
		world.setBlock(i + 7, j + 0, k + 58, MainRegistry.unbreakableIce.blockID);
		world.setBlock(i + 7, j + 0, k + 59, MainRegistry.unbreakableIce.blockID);
		world.setBlock(i + 7, j + 0, k + 60, MainRegistry.unbreakableIce.blockID);
		world.setBlock(i + 7, j + 0, k + 61, MainRegistry.unbreakableIce.blockID);
		world.setBlock(i + 7, j + 0, k + 62, MainRegistry.unbreakableIce.blockID);
		world.setBlock(i + 7, j + 1, k + 25, MainRegistry.frostPlanks.blockID);
		world.setBlock(i + 7, j + 1, k + 26, MainRegistry.frostPlanks.blockID);
		world.setBlock(i + 7, j + 1, k + 27, MainRegistry.frostPlanks.blockID);
		world.setBlock(i + 7, j + 1, k + 28, MainRegistry.frostPlanks.blockID);
		world.setBlock(i + 7, j + 1, k + 29, MainRegistry.frostPlanks.blockID);
		world.setBlock(i + 7, j + 1, k + 30, MainRegistry.frostPlanks.blockID);
		world.setBlock(i + 7, j + 1, k + 31, MainRegistry.frostPlanks.blockID);
		world.setBlock(i + 7, j + 1, k + 32, MainRegistry.frostPlanks.blockID);
		world.setBlock(i + 7, j + 1, k + 33, MainRegistry.frostPlanks.blockID);
		world.setBlock(i + 7, j + 1, k + 34, MainRegistry.frostPlanks.blockID);
		world.setBlock(i + 7, j + 1, k + 35, MainRegistry.frostPlanks.blockID);
		world.setBlock(i + 7, j + 1, k + 36, MainRegistry.frostPlanks.blockID);
		world.setBlock(i + 7, j + 1, k + 37, MainRegistry.frostPlanks.blockID);
		world.setBlock(i + 7, j + 1, k + 38, MainRegistry.frostPlanks.blockID);
		world.setBlock(i + 7, j + 1, k + 39, MainRegistry.frostPlanks.blockID);
		world.setBlock(i + 7, j + 1, k + 40, MainRegistry.frostPlanks.blockID);
		world.setBlock(i + 7, j + 1, k + 41, MainRegistry.frostPlanks.blockID);
		world.setBlock(i + 7, j + 2, k + 25, MainRegistry.unbreakableIce.blockID);
		world.setBlock(i + 7, j + 2, k + 41, MainRegistry.unbreakableIce.blockID);
		world.setBlock(i + 7, j + 3, k + 25, MainRegistry.unbreakableIce.blockID);
		world.setBlock(i + 7, j + 3, k + 41, MainRegistry.unbreakableIce.blockID);
		world.setBlock(i + 7, j + 4, k + 25, MainRegistry.unbreakableIce.blockID);
		world.setBlock(i + 7, j + 4, k + 41, MainRegistry.unbreakableIce.blockID);
		world.setBlock(i + 7, j + 5, k + 25, MainRegistry.unbreakableIce.blockID);
		world.setBlock(i + 7, j + 5, k + 41, MainRegistry.unbreakableIce.blockID);
		world.setBlock(i + 7, j + 6, k + 25, MainRegistry.unbreakableIce.blockID);
		world.setBlock(i + 7, j + 6, k + 41, MainRegistry.unbreakableIce.blockID);
		world.setBlock(i + 7, j + 7, k + 25, MainRegistry.unbreakableIce.blockID);
		world.setBlock(i + 7, j + 7, k + 40, 30);
		world.setBlock(i + 7, j + 7, k + 41, MainRegistry.unbreakableIce.blockID);
		world.setBlock(i + 7, j + 8, k + 25, MainRegistry.unbreakableIce.blockID);
		world.setBlock(i + 7, j + 8, k + 40, 30);
		world.setBlock(i + 7, j + 8, k + 41, MainRegistry.unbreakableIce.blockID);
		world.setBlock(i + 7, j + 9, k + 25, MainRegistry.unbreakableIce.blockID);
		world.setBlock(i + 7, j + 9, k + 41, MainRegistry.unbreakableIce.blockID);
		world.setBlock(i + 7, j + 10, k + 25, MainRegistry.unbreakableIce.blockID);
		world.setBlock(i + 7, j + 10, k + 41, MainRegistry.unbreakableIce.blockID);
		world.setBlock(i + 7, j + 11, k + 25, MainRegistry.unbreakableIce.blockID);
		world.setBlock(i + 7, j + 11, k + 26, 30);
		world.setBlock(i + 7, j + 11, k + 41, MainRegistry.unbreakableIce.blockID);
		world.setBlock(i + 7, j + 12, k + 25, MainRegistry.unbreakableIce.blockID);
		world.setBlock(i + 7, j + 12, k + 41, MainRegistry.unbreakableIce.blockID);
		world.setBlock(i + 7, j + 13, k + 25, MainRegistry.unbreakableIce.blockID);
		world.setBlock(i + 7, j + 13, k + 41, MainRegistry.unbreakableIce.blockID);
		world.setBlock(i + 7, j + 14, k + 25, MainRegistry.unbreakableIce.blockID);
		world.setBlock(i + 7, j + 14, k + 41, MainRegistry.unbreakableIce.blockID);
		world.setBlock(i + 7, j + 15, k + 25, MainRegistry.unbreakableIce.blockID);
		world.setBlock(i + 7, j + 15, k + 26, 80);
		world.setBlock(i + 7, j + 15, k + 27, 80);
		world.setBlock(i + 7, j + 15, k + 28, 80);
		world.setBlock(i + 7, j + 15, k + 29, 80);
		world.setBlock(i + 7, j + 15, k + 30, 80);
		world.setBlock(i + 7, j + 15, k + 31, 80);
		world.setBlock(i + 7, j + 15, k + 32, 80);
		world.setBlock(i + 7, j + 15, k + 33, 80);
		world.setBlock(i + 7, j + 15, k + 34, 80);
		world.setBlock(i + 7, j + 15, k + 35, 80);
		world.setBlock(i + 7, j + 15, k + 36, 80);
		world.setBlock(i + 7, j + 15, k + 37, 80);
		world.setBlock(i + 7, j + 15, k + 38, 80);
		world.setBlock(i + 7, j + 15, k + 39, 80);
		world.setBlock(i + 7, j + 15, k + 40, 80);
		world.setBlock(i + 7, j + 15, k + 41, MainRegistry.unbreakableIce.blockID);
		world.setBlock(i + 8, j + 0, k + 0, MainRegistry.unbreakableIce.blockID);
		world.setBlock(i + 8, j + 0, k + 1, MainRegistry.unbreakableIce.blockID);
		world.setBlock(i + 8, j + 0, k + 2, MainRegistry.unbreakableIce.blockID);
		world.setBlock(i + 8, j + 0, k + 3, MainRegistry.unbreakableIce.blockID);
		world.setBlock(i + 8, j + 0, k + 4, MainRegistry.unbreakableIce.blockID);
		world.setBlock(i + 8, j + 0, k + 5, MainRegistry.unbreakableIce.blockID);
		world.setBlock(i + 8, j + 0, k + 6, MainRegistry.unbreakableIce.blockID);
		world.setBlock(i + 8, j + 0, k + 7, MainRegistry.unbreakableIce.blockID);
		world.setBlock(i + 8, j + 0, k + 8, MainRegistry.unbreakableIce.blockID);
		world.setBlock(i + 8, j + 0, k + 9, MainRegistry.unbreakableIce.blockID);
		world.setBlock(i + 8, j + 0, k + 10, MainRegistry.unbreakableIce.blockID);
		world.setBlock(i + 8, j + 0, k + 11, MainRegistry.unbreakableIce.blockID);
		world.setBlock(i + 8, j + 0, k + 12, MainRegistry.unbreakableIce.blockID);
		world.setBlock(i + 8, j + 0, k + 13, MainRegistry.unbreakableIce.blockID);
		world.setBlock(i + 8, j + 0, k + 14, MainRegistry.unbreakableIce.blockID);
		world.setBlock(i + 8, j + 0, k + 15, MainRegistry.unbreakableIce.blockID);
		world.setBlock(i + 8, j + 0, k + 16, MainRegistry.unbreakableIce.blockID);
		world.setBlock(i + 8, j + 0, k + 17, MainRegistry.unbreakableIce.blockID);
		world.setBlock(i + 8, j + 0, k + 18, MainRegistry.unbreakableIce.blockID);
		world.setBlock(i + 8, j + 0, k + 19, MainRegistry.unbreakableIce.blockID);
		world.setBlock(i + 8, j + 0, k + 20, MainRegistry.unbreakableIce.blockID);
		world.setBlock(i + 8, j + 0, k + 21, MainRegistry.unbreakableIce.blockID);
		world.setBlock(i + 8, j + 0, k + 22, MainRegistry.unbreakableIce.blockID);
		world.setBlock(i + 8, j + 0, k + 23, MainRegistry.unbreakableIce.blockID);
		world.setBlock(i + 8, j + 0, k + 24, MainRegistry.unbreakableIce.blockID);
		world.setBlock(i + 8, j + 0, k + 25, MainRegistry.unbreakableIce.blockID);
		world.setBlock(i + 8, j + 0, k + 26, MainRegistry.unbreakableIce.blockID);
		world.setBlock(i + 8, j + 0, k + 27, MainRegistry.unbreakableIce.blockID);
		world.setBlock(i + 8, j + 0, k + 28, MainRegistry.unbreakableIce.blockID);
		world.setBlock(i + 8, j + 0, k + 29, MainRegistry.unbreakableIce.blockID);
		world.setBlock(i + 8, j + 0, k + 30, MainRegistry.unbreakableIce.blockID);
		world.setBlock(i + 8, j + 0, k + 31, MainRegistry.unbreakableIce.blockID);
		world.setBlock(i + 8, j + 0, k + 32, MainRegistry.unbreakableIce.blockID);
		world.setBlock(i + 8, j + 0, k + 33, MainRegistry.unbreakableIce.blockID);
		world.setBlock(i + 8, j + 0, k + 34, MainRegistry.unbreakableIce.blockID);
		world.setBlock(i + 8, j + 0, k + 35, MainRegistry.unbreakableIce.blockID);
		world.setBlock(i + 8, j + 0, k + 36, MainRegistry.unbreakableIce.blockID);
		world.setBlock(i + 8, j + 0, k + 37, MainRegistry.unbreakableIce.blockID);
		world.setBlock(i + 8, j + 0, k + 38, MainRegistry.unbreakableIce.blockID);
		world.setBlock(i + 8, j + 0, k + 39, MainRegistry.unbreakableIce.blockID);
		world.setBlock(i + 8, j + 0, k + 40, MainRegistry.unbreakableIce.blockID);
		world.setBlock(i + 8, j + 0, k + 41, MainRegistry.unbreakableIce.blockID);
		world.setBlock(i + 8, j + 0, k + 42, MainRegistry.unbreakableIce.blockID);
		world.setBlock(i + 8, j + 0, k + 43, MainRegistry.unbreakableIce.blockID);
		world.setBlock(i + 8, j + 0, k + 44, MainRegistry.unbreakableIce.blockID);
		world.setBlock(i + 8, j + 0, k + 45, MainRegistry.unbreakableIce.blockID);
		world.setBlock(i + 8, j + 0, k + 46, MainRegistry.unbreakableIce.blockID);
		world.setBlock(i + 8, j + 0, k + 47, MainRegistry.unbreakableIce.blockID);
		world.setBlock(i + 8, j + 0, k + 48, MainRegistry.unbreakableIce.blockID);
		world.setBlock(i + 8, j + 0, k + 49, MainRegistry.unbreakableIce.blockID);
		world.setBlock(i + 8, j + 0, k + 50, MainRegistry.unbreakableIce.blockID);
		world.setBlock(i + 8, j + 0, k + 51, MainRegistry.unbreakableIce.blockID);
		world.setBlock(i + 8, j + 0, k + 52, MainRegistry.unbreakableIce.blockID);
		world.setBlock(i + 8, j + 0, k + 53, MainRegistry.unbreakableIce.blockID);
		world.setBlock(i + 8, j + 0, k + 54, MainRegistry.unbreakableIce.blockID);
		world.setBlock(i + 8, j + 0, k + 55, MainRegistry.unbreakableIce.blockID);
		world.setBlock(i + 8, j + 0, k + 56, MainRegistry.unbreakableIce.blockID);
		world.setBlock(i + 8, j + 0, k + 57, MainRegistry.unbreakableIce.blockID);
		world.setBlock(i + 8, j + 0, k + 58, MainRegistry.unbreakableIce.blockID);
		world.setBlock(i + 8, j + 0, k + 59, MainRegistry.unbreakableIce.blockID);
		world.setBlock(i + 8, j + 0, k + 60, MainRegistry.unbreakableIce.blockID);
		world.setBlock(i + 8, j + 0, k + 61, MainRegistry.unbreakableIce.blockID);
		world.setBlock(i + 8, j + 0, k + 62, MainRegistry.unbreakableIce.blockID);
		world.setBlock(i + 8, j + 1, k + 15, MainRegistry.frostPlanks.blockID);
		world.setBlock(i + 8, j + 1, k + 16, MainRegistry.frostPlanks.blockID);
		world.setBlock(i + 8, j + 1, k + 17, MainRegistry.frostPlanks.blockID);
		world.setBlock(i + 8, j + 1, k + 18, MainRegistry.frostPlanks.blockID);
		world.setBlock(i + 8, j + 1, k + 24, MainRegistry.frostPlanks.blockID);
		world.setBlock(i + 8, j + 1, k + 25, MainRegistry.frostPlanks.blockID);
		world.setBlock(i + 8, j + 1, k + 26, MainRegistry.frostPlanks.blockID);
		world.setBlock(i + 8, j + 1, k + 27, MainRegistry.frostPlanks.blockID);
		world.setBlock(i + 8, j + 1, k + 28, MainRegistry.frostPlanks.blockID);
		world.setBlock(i + 8, j + 1, k + 29, MainRegistry.frostPlanks.blockID);
		world.setBlock(i + 8, j + 1, k + 30, MainRegistry.frostPlanks.blockID);
		world.setBlock(i + 8, j + 1, k + 31, MainRegistry.frostPlanks.blockID);
		world.setBlock(i + 8, j + 1, k + 32, MainRegistry.frostPlanks.blockID);
		world.setBlock(i + 8, j + 1, k + 33, MainRegistry.frostPlanks.blockID);
		world.setBlock(i + 8, j + 1, k + 34, MainRegistry.frostPlanks.blockID);
		world.setBlock(i + 8, j + 1, k + 35, MainRegistry.frostPlanks.blockID);
		world.setBlock(i + 8, j + 1, k + 36, MainRegistry.frostPlanks.blockID);
		world.setBlock(i + 8, j + 1, k + 37, MainRegistry.frostPlanks.blockID);
		world.setBlock(i + 8, j + 1, k + 38, MainRegistry.frostPlanks.blockID);
		world.setBlock(i + 8, j + 1, k + 39, MainRegistry.frostPlanks.blockID);
		world.setBlock(i + 8, j + 1, k + 40, MainRegistry.frostPlanks.blockID);
		world.setBlock(i + 8, j + 1, k + 41, MainRegistry.frostPlanks.blockID);
		world.setBlock(i + 8, j + 1, k + 42, MainRegistry.frostPlanks.blockID);
		world.setBlock(i + 8, j + 1, k + 47, MainRegistry.frostPlanks.blockID);
		world.setBlock(i + 8, j + 1, k + 48, MainRegistry.frostPlanks.blockID);
		world.setBlock(i + 8, j + 1, k + 49, MainRegistry.frostPlanks.blockID);
		world.setBlock(i + 8, j + 1, k + 50, MainRegistry.frostPlanks.blockID);
		world.setBlock(i + 8, j + 2, k + 15, MainRegistry.unbreakableIce.blockID);
		world.setBlock(i + 8, j + 2, k + 16, MainRegistry.unbreakableIce.blockID);
		world.setBlock(i + 8, j + 2, k + 17, MainRegistry.unbreakableIce.blockID);
		world.setBlock(i + 8, j + 2, k + 18, MainRegistry.unbreakableIce.blockID);
		world.setBlock(i + 8, j + 2, k + 24, MainRegistry.unbreakableIce.blockID);
		world.setBlock(i + 8, j + 2, k + 35, 30);
		world.setBlock(i + 8, j + 2, k + 42, MainRegistry.unbreakableIce.blockID);
		world.setBlock(i + 8, j + 2, k + 47, MainRegistry.unbreakableIce.blockID);
		world.setBlock(i + 8, j + 2, k + 48, MainRegistry.unbreakableIce.blockID);
		world.setBlock(i + 8, j + 2, k + 49, MainRegistry.unbreakableIce.blockID);
		world.setBlock(i + 8, j + 2, k + 50, MainRegistry.unbreakableIce.blockID);
		world.setBlock(i + 8, j + 3, k + 15, 80);
		world.setBlock(i + 8, j + 3, k + 16, 80);
		world.setBlock(i + 8, j + 3, k + 17, 80);
		world.setBlock(i + 8, j + 3, k + 18, 80);
		world.setBlock(i + 8, j + 3, k + 24, MainRegistry.unbreakableIce.blockID);
		world.setBlock(i + 8, j + 3, k + 42, MainRegistry.unbreakableIce.blockID);
		world.setBlock(i + 8, j + 3, k + 47, 80);
		world.setBlock(i + 8, j + 3, k + 48, 80);
		world.setBlock(i + 8, j + 3, k + 49, 80);
		world.setBlock(i + 8, j + 3, k + 50, 80);
		world.setBlock(i + 8, j + 4, k + 15, MainRegistry.unbreakableIce.blockID);
		world.setBlock(i + 8, j + 4, k + 16, MainRegistry.unbreakableIce.blockID);
		world.setBlock(i + 8, j + 4, k + 17, MainRegistry.unbreakableIce.blockID);
		world.setBlock(i + 8, j + 4, k + 18, MainRegistry.unbreakableIce.blockID);
		world.setBlock(i + 8, j + 4, k + 24, MainRegistry.unbreakableIce.blockID);
		world.setBlock(i + 8, j + 4, k + 42, MainRegistry.unbreakableIce.blockID);
		world.setBlock(i + 8, j + 4, k + 47, MainRegistry.unbreakableIce.blockID);
		world.setBlock(i + 8, j + 4, k + 48, MainRegistry.unbreakableIce.blockID);
		world.setBlock(i + 8, j + 4, k + 49, MainRegistry.unbreakableIce.blockID);
		world.setBlock(i + 8, j + 4, k + 50, MainRegistry.unbreakableIce.blockID);
		world.setBlock(i + 8, j + 5, k + 15, MainRegistry.unbreakableIce.blockID);
		world.setBlock(i + 8, j + 5, k + 16, MainRegistry.unbreakableIce.blockID);
		world.setBlock(i + 8, j + 5, k + 17, MainRegistry.unbreakableIce.blockID);
		world.setBlock(i + 8, j + 5, k + 18, MainRegistry.unbreakableIce.blockID);
		world.setBlock(i + 8, j + 5, k + 24, MainRegistry.unbreakableIce.blockID);
		world.setBlock(i + 8, j + 5, k + 42, MainRegistry.unbreakableIce.blockID);
		world.setBlock(i + 8, j + 5, k + 47, MainRegistry.unbreakableIce.blockID);
		world.setBlock(i + 8, j + 5, k + 48, MainRegistry.unbreakableIce.blockID);
		world.setBlock(i + 8, j + 5, k + 49, MainRegistry.unbreakableIce.blockID);
		world.setBlock(i + 8, j + 5, k + 50, MainRegistry.unbreakableIce.blockID);
		world.setBlock(i + 8, j + 6, k + 15, MainRegistry.unbreakableIce.blockID);
		world.setBlock(i + 8, j + 6, k + 16, MainRegistry.unbreakableIce.blockID);
		world.setBlock(i + 8, j + 6, k + 17, MainRegistry.unbreakableIce.blockID);
		world.setBlock(i + 8, j + 6, k + 18, MainRegistry.unbreakableIce.blockID);
		world.setBlock(i + 8, j + 6, k + 24, MainRegistry.unbreakableIce.blockID);
		world.setBlock(i + 8, j + 6, k + 42, MainRegistry.unbreakableIce.blockID);
		world.setBlock(i + 8, j + 6, k + 47, MainRegistry.unbreakableIce.blockID);
		world.setBlock(i + 8, j + 6, k + 48, MainRegistry.unbreakableIce.blockID);
		world.setBlock(i + 8, j + 6, k + 49, MainRegistry.unbreakableIce.blockID);
		world.setBlock(i + 8, j + 6, k + 50, MainRegistry.unbreakableIce.blockID);
		world.setBlock(i + 8, j + 7, k + 15, MainRegistry.unbreakableIce.blockID);
		world.setBlock(i + 8, j + 7, k + 16, MainRegistry.unbreakableIce.blockID);
		world.setBlock(i + 8, j + 7, k + 17, MainRegistry.unbreakableIce.blockID);
		world.setBlock(i + 8, j + 7, k + 18, MainRegistry.unbreakableIce.blockID);
		world.setBlock(i + 8, j + 7, k + 24, MainRegistry.unbreakableIce.blockID);
		world.setBlock(i + 8, j + 7, k + 25, 30);
		world.setBlock(i + 8, j + 7, k + 42, MainRegistry.unbreakableIce.blockID);
		world.setBlock(i + 8, j + 7, k + 47, MainRegistry.unbreakableIce.blockID);
		world.setBlock(i + 8, j + 7, k + 48, MainRegistry.unbreakableIce.blockID);
		world.setBlock(i + 8, j + 7, k + 49, MainRegistry.unbreakableIce.blockID);
		world.setBlock(i + 8, j + 7, k + 50, MainRegistry.unbreakableIce.blockID);
		world.setBlock(i + 8, j + 8, k + 24, MainRegistry.unbreakableIce.blockID);
		world.setBlock(i + 8, j + 8, k + 41, 30);
		world.setBlock(i + 8, j + 8, k + 42, MainRegistry.unbreakableIce.blockID);
		world.setBlock(i + 8, j + 9, k + 24, MainRegistry.unbreakableIce.blockID);
		world.setBlock(i + 8, j + 9, k + 42, MainRegistry.unbreakableIce.blockID);
		world.setBlock(i + 8, j + 10, k + 24, MainRegistry.unbreakableIce.blockID);
		world.setBlock(i + 8, j + 10, k + 42, MainRegistry.unbreakableIce.blockID);
		world.setBlock(i + 8, j + 11, k + 24, MainRegistry.unbreakableIce.blockID);
		world.setBlock(i + 8, j + 11, k + 42, MainRegistry.unbreakableIce.blockID);
		world.setBlock(i + 8, j + 12, k + 24, MainRegistry.unbreakableIce.blockID);
		world.setBlock(i + 8, j + 12, k + 42, MainRegistry.unbreakableIce.blockID);
		world.setBlock(i + 8, j + 13, k + 24, MainRegistry.unbreakableIce.blockID);
		world.setBlock(i + 8, j + 13, k + 42, MainRegistry.unbreakableIce.blockID);
		world.setBlock(i + 8, j + 14, k + 24, MainRegistry.unbreakableIce.blockID);
		world.setBlock(i + 8, j + 14, k + 25, 80);
		world.setBlock(i + 8, j + 14, k + 26, 80);
		world.setBlock(i + 8, j + 14, k + 27, 80);
		world.setBlock(i + 8, j + 14, k + 28, 80);
		world.setBlock(i + 8, j + 14, k + 29, 80);
		world.setBlock(i + 8, j + 14, k + 30, 80);
		world.setBlock(i + 8, j + 14, k + 31, 80);
		world.setBlock(i + 8, j + 14, k + 32, 80);
		world.setBlock(i + 8, j + 14, k + 33, 80);
		world.setBlock(i + 8, j + 14, k + 34, 80);
		world.setBlock(i + 8, j + 14, k + 35, 80);
		world.setBlock(i + 8, j + 14, k + 36, 80);
		world.setBlock(i + 8, j + 14, k + 37, 80);
		world.setBlock(i + 8, j + 14, k + 38, 80);
		world.setBlock(i + 8, j + 14, k + 39, 80);
		world.setBlock(i + 8, j + 14, k + 40, 80);
		world.setBlock(i + 8, j + 14, k + 41, 80);
		world.setBlock(i + 8, j + 14, k + 42, MainRegistry.unbreakableIce.blockID);
		world.setBlock(i + 9, j + 0, k + 0, MainRegistry.unbreakableIce.blockID);
		world.setBlock(i + 9, j + 0, k + 1, MainRegistry.unbreakableIce.blockID);
		world.setBlock(i + 9, j + 0, k + 2, MainRegistry.unbreakableIce.blockID);
		world.setBlock(i + 9, j + 0, k + 3, MainRegistry.unbreakableIce.blockID);
		world.setBlock(i + 9, j + 0, k + 4, MainRegistry.unbreakableIce.blockID);
		world.setBlock(i + 9, j + 0, k + 5, MainRegistry.unbreakableIce.blockID);
		world.setBlock(i + 9, j + 0, k + 6, MainRegistry.unbreakableIce.blockID);
		world.setBlock(i + 9, j + 0, k + 7, MainRegistry.unbreakableIce.blockID);
		world.setBlock(i + 9, j + 0, k + 8, MainRegistry.unbreakableIce.blockID);
		world.setBlock(i + 9, j + 0, k + 9, MainRegistry.unbreakableIce.blockID);
		world.setBlock(i + 9, j + 0, k + 10, MainRegistry.unbreakableIce.blockID);
		world.setBlock(i + 9, j + 0, k + 11, MainRegistry.unbreakableIce.blockID);
		world.setBlock(i + 9, j + 0, k + 12, MainRegistry.unbreakableIce.blockID);
		world.setBlock(i + 9, j + 0, k + 13, MainRegistry.unbreakableIce.blockID);
		world.setBlock(i + 9, j + 0, k + 14, MainRegistry.unbreakableIce.blockID);
		world.setBlock(i + 9, j + 0, k + 15, MainRegistry.unbreakableIce.blockID);
		world.setBlock(i + 9, j + 0, k + 16, MainRegistry.unbreakableIce.blockID);
		world.setBlock(i + 9, j + 0, k + 17, MainRegistry.unbreakableIce.blockID);
		world.setBlock(i + 9, j + 0, k + 18, MainRegistry.unbreakableIce.blockID);
		world.setBlock(i + 9, j + 0, k + 19, MainRegistry.unbreakableIce.blockID);
		world.setBlock(i + 9, j + 0, k + 20, MainRegistry.unbreakableIce.blockID);
		world.setBlock(i + 9, j + 0, k + 21, MainRegistry.unbreakableIce.blockID);
		world.setBlock(i + 9, j + 0, k + 22, MainRegistry.unbreakableIce.blockID);
		world.setBlock(i + 9, j + 0, k + 23, MainRegistry.unbreakableIce.blockID);
		world.setBlock(i + 9, j + 0, k + 24, MainRegistry.unbreakableIce.blockID);
		world.setBlock(i + 9, j + 0, k + 25, MainRegistry.unbreakableIce.blockID);
		world.setBlock(i + 9, j + 0, k + 26, MainRegistry.unbreakableIce.blockID);
		world.setBlock(i + 9, j + 0, k + 27, MainRegistry.unbreakableIce.blockID);
		world.setBlock(i + 9, j + 0, k + 28, MainRegistry.unbreakableIce.blockID);
		world.setBlock(i + 9, j + 0, k + 29, MainRegistry.unbreakableIce.blockID);
		world.setBlock(i + 9, j + 0, k + 30, MainRegistry.unbreakableIce.blockID);
		world.setBlock(i + 9, j + 0, k + 31, MainRegistry.unbreakableIce.blockID);
		world.setBlock(i + 9, j + 0, k + 32, MainRegistry.unbreakableIce.blockID);
		world.setBlock(i + 9, j + 0, k + 33, MainRegistry.unbreakableIce.blockID);
		world.setBlock(i + 9, j + 0, k + 34, MainRegistry.unbreakableIce.blockID);
		world.setBlock(i + 9, j + 0, k + 35, MainRegistry.unbreakableIce.blockID);
		world.setBlock(i + 9, j + 0, k + 36, MainRegistry.unbreakableIce.blockID);
		world.setBlock(i + 9, j + 0, k + 37, MainRegistry.unbreakableIce.blockID);
		world.setBlock(i + 9, j + 0, k + 38, MainRegistry.unbreakableIce.blockID);
		world.setBlock(i + 9, j + 0, k + 39, MainRegistry.unbreakableIce.blockID);
		world.setBlock(i + 9, j + 0, k + 40, MainRegistry.unbreakableIce.blockID);
		world.setBlock(i + 9, j + 0, k + 41, MainRegistry.unbreakableIce.blockID);
		world.setBlock(i + 9, j + 0, k + 42, MainRegistry.unbreakableIce.blockID);
		world.setBlock(i + 9, j + 0, k + 43, MainRegistry.unbreakableIce.blockID);
		world.setBlock(i + 9, j + 0, k + 44, MainRegistry.unbreakableIce.blockID);
		world.setBlock(i + 9, j + 0, k + 45, MainRegistry.unbreakableIce.blockID);
		world.setBlock(i + 9, j + 0, k + 46, MainRegistry.unbreakableIce.blockID);
		world.setBlock(i + 9, j + 0, k + 47, MainRegistry.unbreakableIce.blockID);
		world.setBlock(i + 9, j + 0, k + 48, MainRegistry.unbreakableIce.blockID);
		world.setBlock(i + 9, j + 0, k + 49, MainRegistry.unbreakableIce.blockID);
		world.setBlock(i + 9, j + 0, k + 50, MainRegistry.unbreakableIce.blockID);
		world.setBlock(i + 9, j + 0, k + 51, MainRegistry.unbreakableIce.blockID);
		world.setBlock(i + 9, j + 0, k + 52, MainRegistry.unbreakableIce.blockID);
		world.setBlock(i + 9, j + 0, k + 53, MainRegistry.unbreakableIce.blockID);
		world.setBlock(i + 9, j + 0, k + 54, MainRegistry.unbreakableIce.blockID);
		world.setBlock(i + 9, j + 0, k + 55, MainRegistry.unbreakableIce.blockID);
		world.setBlock(i + 9, j + 0, k + 56, MainRegistry.unbreakableIce.blockID);
		world.setBlock(i + 9, j + 0, k + 57, MainRegistry.unbreakableIce.blockID);
		world.setBlock(i + 9, j + 0, k + 58, MainRegistry.unbreakableIce.blockID);
		world.setBlock(i + 9, j + 0, k + 59, MainRegistry.unbreakableIce.blockID);
		world.setBlock(i + 9, j + 0, k + 60, MainRegistry.unbreakableIce.blockID);
		world.setBlock(i + 9, j + 0, k + 61, MainRegistry.unbreakableIce.blockID);
		world.setBlock(i + 9, j + 0, k + 62, MainRegistry.unbreakableIce.blockID);
		world.setBlock(i + 9, j + 1, k + 14, MainRegistry.frostPlanks.blockID);
		world.setBlock(i + 9, j + 1, k + 15, MainRegistry.frostPlanks.blockID);
		world.setBlock(i + 9, j + 1, k + 16, MainRegistry.frostPlanks.blockID);
		world.setBlock(i + 9, j + 1, k + 17, MainRegistry.frostPlanks.blockID);
		world.setBlock(i + 9, j + 1, k + 18, MainRegistry.frostPlanks.blockID);
		world.setBlock(i + 9, j + 1, k + 19, MainRegistry.frostPlanks.blockID);
		world.setBlock(i + 9, j + 1, k + 23, MainRegistry.frostPlanks.blockID);
		world.setBlock(i + 9, j + 1, k + 24, MainRegistry.frostPlanks.blockID);
		world.setBlock(i + 9, j + 1, k + 25, MainRegistry.frostPlanks.blockID);
		world.setBlock(i + 9, j + 1, k + 26, MainRegistry.frostPlanks.blockID);
		world.setBlock(i + 9, j + 1, k + 27, MainRegistry.frostPlanks.blockID);
		world.setBlock(i + 9, j + 1, k + 28, MainRegistry.frostPlanks.blockID);
		world.setBlock(i + 9, j + 1, k + 29, MainRegistry.frostPlanks.blockID);
		world.setBlock(i + 9, j + 1, k + 30, MainRegistry.frostPlanks.blockID);
		world.setBlock(i + 9, j + 1, k + 31, MainRegistry.frostPlanks.blockID);
		world.setBlock(i + 9, j + 1, k + 32, MainRegistry.frostPlanks.blockID);
		world.setBlock(i + 9, j + 1, k + 33, MainRegistry.frostPlanks.blockID);
		world.setBlock(i + 9, j + 1, k + 34, MainRegistry.frostPlanks.blockID);
		world.setBlock(i + 9, j + 1, k + 35, MainRegistry.frostPlanks.blockID);
		world.setBlock(i + 9, j + 1, k + 36, MainRegistry.frostPlanks.blockID);
		world.setBlock(i + 9, j + 1, k + 37, MainRegistry.frostPlanks.blockID);
		world.setBlock(i + 9, j + 1, k + 38, MainRegistry.frostPlanks.blockID);
		world.setBlock(i + 9, j + 1, k + 39, MainRegistry.frostPlanks.blockID);
		world.setBlock(i + 9, j + 1, k + 40, MainRegistry.frostPlanks.blockID);
		world.setBlock(i + 9, j + 1, k + 41, MainRegistry.frostPlanks.blockID);
		world.setBlock(i + 9, j + 1, k + 42, MainRegistry.frostPlanks.blockID);
		world.setBlock(i + 9, j + 1, k + 43, MainRegistry.frostPlanks.blockID);
		world.setBlock(i + 9, j + 1, k + 46, MainRegistry.frostPlanks.blockID);
		world.setBlock(i + 9, j + 1, k + 47, MainRegistry.frostPlanks.blockID);
		world.setBlock(i + 9, j + 1, k + 48, MainRegistry.frostPlanks.blockID);
		world.setBlock(i + 9, j + 1, k + 49, MainRegistry.frostPlanks.blockID);
		world.setBlock(i + 9, j + 1, k + 50, MainRegistry.frostPlanks.blockID);
		world.setBlock(i + 9, j + 1, k + 51, MainRegistry.frostPlanks.blockID);
		world.setBlock(i + 9, j + 2, k + 14, MainRegistry.unbreakableIce.blockID);
		world.setBlock(i + 9, j + 2, k + 17, Block.mobSpawner.blockID);
		world.setBlock(i + 9, j + 2, k + 19, MainRegistry.unbreakableIce.blockID);
		world.setBlock(i + 9, j + 2, k + 23, MainRegistry.unbreakableIce.blockID);
		world.setBlock(i + 9, j + 2, k + 28, 30);
		world.setBlock(i + 9, j + 2, k + 43, MainRegistry.unbreakableIce.blockID);
		world.setBlock(i + 9, j + 2, k + 46, MainRegistry.unbreakableIce.blockID);
		world.setBlock(i + 9, j + 2, k + 49, Block.mobSpawner.blockID);
		world.setBlock(i + 9, j + 2, k + 51, MainRegistry.unbreakableIce.blockID);
		world.setBlock(i + 9, j + 3, k + 14, 80);
		world.setBlock(i + 9, j + 3, k + 17, MainRegistry.frostPlanks.blockID);
		world.setBlock(i + 9, j + 3, k + 19, 80);
		world.setBlock(i + 9, j + 3, k + 23, MainRegistry.unbreakableIce.blockID);
		world.setBlock(i + 9, j + 3, k + 43, MainRegistry.unbreakableIce.blockID);
		world.setBlock(i + 9, j + 3, k + 46, 80);
		world.setBlock(i + 9, j + 3, k + 49, MainRegistry.frostPlanks.blockID);
		world.setBlock(i + 9, j + 3, k + 51, 80);
		world.setBlock(i + 9, j + 4, k + 14, MainRegistry.unbreakableIce.blockID);
		world.setBlock(i + 9, j + 4, k + 17, MainRegistry.frostPlanks.blockID);
		world.setBlock(i + 9, j + 4, k + 19, MainRegistry.unbreakableIce.blockID);
		world.setBlock(i + 9, j + 4, k + 23, MainRegistry.unbreakableIce.blockID);
		world.setBlock(i + 9, j + 4, k + 43, MainRegistry.unbreakableIce.blockID);
		world.setBlock(i + 9, j + 4, k + 46, MainRegistry.unbreakableIce.blockID);
		world.setBlock(i + 9, j + 4, k + 49, MainRegistry.frostPlanks.blockID);
		world.setBlock(i + 9, j + 4, k + 51, MainRegistry.unbreakableIce.blockID);
		world.setBlock(i + 9, j + 5, k + 14, MainRegistry.unbreakableIce.blockID);
		world.setBlock(i + 9, j + 5, k + 17, MainRegistry.frostPlanks.blockID);
		world.setBlock(i + 9, j + 5, k + 19, MainRegistry.unbreakableIce.blockID);
		world.setBlock(i + 9, j + 5, k + 23, MainRegistry.unbreakableIce.blockID);
		world.setBlock(i + 9, j + 5, k + 43, MainRegistry.unbreakableIce.blockID);
		world.setBlock(i + 9, j + 5, k + 46, MainRegistry.unbreakableIce.blockID);
		world.setBlock(i + 9, j + 5, k + 49, MainRegistry.frostPlanks.blockID);
		world.setBlock(i + 9, j + 5, k + 51, MainRegistry.unbreakableIce.blockID);
		world.setBlock(i + 9, j + 6, k + 14, MainRegistry.unbreakableIce.blockID);
		world.setBlock(i + 9, j + 6, k + 17, MainRegistry.frostPlanks.blockID);
		world.setBlock(i + 9, j + 6, k + 19, MainRegistry.unbreakableIce.blockID);
		world.setBlock(i + 9, j + 6, k + 23, MainRegistry.unbreakableIce.blockID);
		world.setBlock(i + 9, j + 6, k + 43, MainRegistry.unbreakableIce.blockID);
		world.setBlock(i + 9, j + 6, k + 46, MainRegistry.unbreakableIce.blockID);
		world.setBlock(i + 9, j + 6, k + 49, MainRegistry.frostPlanks.blockID);
		world.setBlock(i + 9, j + 6, k + 51, MainRegistry.unbreakableIce.blockID);
		world.setBlock(i + 9, j + 7, k + 14, MainRegistry.unbreakableIce.blockID);
		world.setBlock(i + 9, j + 7, k + 15, MainRegistry.frostPlanks.blockID);
		world.setBlock(i + 9, j + 7, k + 16, MainRegistry.frostPlanks.blockID);
		world.setBlock(i + 9, j + 7, k + 17, MainRegistry.frostPlanks.blockID);
		world.setBlock(i + 9, j + 7, k + 18, MainRegistry.frostPlanks.blockID);
		world.setBlock(i + 9, j + 7, k + 19, MainRegistry.unbreakableIce.blockID);
		world.setBlock(i + 9, j + 7, k + 23, MainRegistry.unbreakableIce.blockID);
		world.setBlock(i + 9, j + 7, k + 43, MainRegistry.unbreakableIce.blockID);
		world.setBlock(i + 9, j + 7, k + 46, MainRegistry.unbreakableIce.blockID);
		world.setBlock(i + 9, j + 7, k + 47, MainRegistry.frostPlanks.blockID);
		world.setBlock(i + 9, j + 7, k + 48, MainRegistry.frostPlanks.blockID);
		world.setBlock(i + 9, j + 7, k + 49, MainRegistry.frostPlanks.blockID);
		world.setBlock(i + 9, j + 7, k + 50, MainRegistry.frostPlanks.blockID);
		world.setBlock(i + 9, j + 7, k + 51, MainRegistry.unbreakableIce.blockID);
		world.setBlock(i + 9, j + 8, k + 15, MainRegistry.unbreakableIce.blockID);
		world.setBlock(i + 9, j + 8, k + 16, MainRegistry.unbreakableIce.blockID);
		world.setBlock(i + 9, j + 8, k + 17, MainRegistry.unbreakableIce.blockID);
		world.setBlock(i + 9, j + 8, k + 18, MainRegistry.unbreakableIce.blockID);
		world.setBlock(i + 9, j + 8, k + 23, MainRegistry.unbreakableIce.blockID);
		world.setBlock(i + 9, j + 8, k + 43, MainRegistry.unbreakableIce.blockID);
		world.setBlock(i + 9, j + 8, k + 47, MainRegistry.unbreakableIce.blockID);
		world.setBlock(i + 9, j + 8, k + 48, MainRegistry.unbreakableIce.blockID);
		world.setBlock(i + 9, j + 8, k + 49, MainRegistry.unbreakableIce.blockID);
		world.setBlock(i + 9, j + 8, k + 50, MainRegistry.unbreakableIce.blockID);
		world.setBlock(i + 9, j + 9, k + 15, 80);
		world.setBlock(i + 9, j + 9, k + 16, 80);
		world.setBlock(i + 9, j + 9, k + 17, 80);
		world.setBlock(i + 9, j + 9, k + 18, 80);
		world.setBlock(i + 9, j + 9, k + 23, MainRegistry.unbreakableIce.blockID);
		world.setBlock(i + 9, j + 9, k + 43, MainRegistry.unbreakableIce.blockID);
		world.setBlock(i + 9, j + 9, k + 47, 80);
		world.setBlock(i + 9, j + 9, k + 48, 80);
		world.setBlock(i + 9, j + 9, k + 49, 80);
		world.setBlock(i + 9, j + 9, k + 50, 80);
		world.setBlock(i + 9, j + 10, k + 15, MainRegistry.unbreakableIce.blockID);
		world.setBlock(i + 9, j + 10, k + 16, MainRegistry.unbreakableIce.blockID);
		world.setBlock(i + 9, j + 10, k + 17, MainRegistry.unbreakableIce.blockID);
		world.setBlock(i + 9, j + 10, k + 18, MainRegistry.unbreakableIce.blockID);
		world.setBlock(i + 9, j + 10, k + 23, MainRegistry.unbreakableIce.blockID);
		world.setBlock(i + 9, j + 10, k + 43, MainRegistry.unbreakableIce.blockID);
		world.setBlock(i + 9, j + 10, k + 47, MainRegistry.unbreakableIce.blockID);
		world.setBlock(i + 9, j + 10, k + 48, MainRegistry.unbreakableIce.blockID);
		world.setBlock(i + 9, j + 10, k + 49, MainRegistry.unbreakableIce.blockID);
		world.setBlock(i + 9, j + 10, k + 50, MainRegistry.unbreakableIce.blockID);
