package arcticraft.gen;
import java.util.Random;

import arcticraft.main.MainRegistry;

import net.minecraft.block.Block;
import net.minecraft.item.Item;
import net.minecraft.item.ItemStack;
import net.minecraft.world.World;
import net.minecraft.world.gen.feature.WorldGenerator;

public class AC_GenMageTower extends WorldGenerator
{
	public AC_GenMageTower() { }

	public boolean generate(World world, Random rand, int i, int j, int k) 
	{
		if (world.getBlockId(i, j, k) != Block.grass.blockID)
		{
			return false;
		}
		if (world.getBlockId(i, j + 1, k + 1) != 78)
		{
			return false;
		}
		if (world.getBlockId(i, j + 1, k - 1) != 78)
		{
			return false;
		}
		if (world.getBlockId(i + 1, j + 1, k) != 78)
		{
			return false;
		}
		if (world.getBlockId(i - 1, j + 1, k) != 78)
		{
			return false;
		}
		if (world.getBlockId(i, j + 1, k) != 78)
		{
			return false;
		}
		
		world.setBlock(i + 1, j + 0, k + 6, Block.netherBrick.blockID, 0, 2);
		world.setBlock(i + 1, j + 0, k + 7, Block.planks.blockID, 2, 2);
		world.setBlock(i + 1, j + 0, k + 8, Block.planks.blockID, 2, 2);
		world.setBlock(i + 1, j + 0, k + 9, Block.netherBrick.blockID, 0, 2);
		world.setBlock(i + 1, j + 1, k + 6, Block.stairsNetherBrick.blockID, 0, 2);
		world.setBlock(i + 1, j + 1, k + 9, Block.stairsNetherBrick.blockID, 0, 2);
		world.setBlock(i + 1, j + 2, k + 5, Block.netherFence.blockID, 0, 2);
		world.setBlock(i + 1, j + 2, k + 6, Block.stairsNetherBrick.blockID, 0, 2);
		world.setBlock(i + 1, j + 2, k + 9, Block.stairsNetherBrick.blockID, 0, 2);
		world.setBlock(i + 1, j + 2, k + 10, Block.netherFence.blockID, 0, 2);
		world.setBlock(i + 1, j + 3, k + 6, Block.stairsNetherBrick.blockID, 2, 2);
		world.setBlock(i + 1, j + 3, k + 7, Block.stairsNetherBrick.blockID, 0, 2);
		world.setBlock(i + 1, j + 3, k + 8, Block.stairsNetherBrick.blockID, 0, 2);
		world.setBlock(i + 1, j + 3, k + 9, Block.stairsNetherBrick.blockID, 3, 2);
		world.setBlock(i + 1, j + 5, k + 6, Block.stairsBrick.blockID, 0, 2);
		world.setBlock(i + 1, j + 5, k + 7, Block.stairsBrick.blockID, 0, 2);
		world.setBlock(i + 1, j + 5, k + 8, Block.stairsBrick.blockID, 0, 2);
		world.setBlock(i + 1, j + 5, k + 9, Block.stairsBrick.blockID, 0, 2);
		world.setBlock(i + 2, j + 0, k + 5, Block.wood.blockID, 1, 2);
		world.setBlock(i + 2, j + 0, k + 6, Block.stoneBrick.blockID, this.pickStoneBrickType(rand), 2);
		world.setBlock(i + 2, j + 0, k + 7, Block.planks.blockID, 2, 2);
		world.setBlock(i + 2, j + 0, k + 8, Block.planks.blockID, 2, 2);
		world.setBlock(i + 2, j + 0, k + 9, Block.stoneBrick.blockID, this.pickStoneBrickType(rand), 2);
		world.setBlock(i + 2, j + 0, k + 10, Block.wood.blockID, 1, 2);
		world.setBlock(i + 2, j + 1, k + 5, Block.wood.blockID, 1, 2);
		world.setBlock(i + 2, j + 1, k + 6, Block.stoneBrick.blockID, this.pickStoneBrickType(rand), 2);
		world.setBlock(i + 2, j + 1, k + 9, Block.stoneBrick.blockID, this.pickStoneBrickType(rand), 2);
		world.setBlock(i + 2, j + 1, k + 10, Block.wood.blockID, 1, 2);
		world.setBlock(i + 2, j + 2, k + 5, Block.wood.blockID, 1, 2);
		world.setBlock(i + 2, j + 2, k + 6, Block.stoneBrick.blockID, this.pickStoneBrickType(rand), 2);
		world.setBlock(i + 2, j + 2, k + 9, Block.stoneBrick.blockID, this.pickStoneBrickType(rand), 2);
		world.setBlock(i + 2, j + 2, k + 10, Block.wood.blockID, 1, 2);
		world.setBlock(i + 2, j + 3, k + 5, Block.wood.blockID, 1, 2);
		world.setBlock(i + 2, j + 3, k + 6, Block.stoneBrick.blockID, this.pickStoneBrickType(rand), 2);
		world.setBlock(i + 2, j + 3, k + 7, Block.netherBrick.blockID, 0, 2);
		world.setBlock(i + 2, j + 3, k + 8, Block.netherBrick.blockID, 0, 2);
		world.setBlock(i + 2, j + 3, k + 9, Block.stoneBrick.blockID, this.pickStoneBrickType(rand), 2);
		world.setBlock(i + 2, j + 3, k + 10, Block.wood.blockID, 1, 2);
		world.setBlock(i + 2, j + 4, k + 5, Block.wood.blockID, 1, 2);
		world.setBlock(i + 2, j + 4, k + 6, Block.stoneBrick.blockID, this.pickStoneBrickType(rand), 2);
		world.setBlock(i + 2, j + 4, k + 7, Block.thinGlass.blockID, 0, 2);
		world.setBlock(i + 2, j + 4, k + 8, Block.thinGlass.blockID, 0, 2);
		world.setBlock(i + 2, j + 4, k + 9, Block.stoneBrick.blockID, this.pickStoneBrickType(rand), 2);
		world.setBlock(i + 2, j + 4, k + 10, Block.wood.blockID, 1, 2);
		world.setBlock(i + 2, j + 5, k + 4, Block.stairsBrick.blockID, 0, 2);
		world.setBlock(i + 2, j + 5, k + 5, Block.stairsBrick.blockID, 0, 2);
		world.setBlock(i + 2, j + 5, k + 6, Block.brick.blockID, 0, 2);
		world.setBlock(i + 2, j + 5, k + 7, Block.stoneBrick.blockID, this.pickStoneBrickType(rand), 2);
		world.setBlock(i + 2, j + 5, k + 8, Block.stoneBrick.blockID, this.pickStoneBrickType(rand), 2);
		world.setBlock(i + 2, j + 5, k + 9, Block.brick.blockID, 0, 2);
		world.setBlock(i + 2, j + 5, k + 10, Block.stairsBrick.blockID, 0, 2);
		world.setBlock(i + 2, j + 5, k + 11, Block.stairsBrick.blockID, 0, 2);
		world.setBlock(i + 2, j + 6, k + 6, Block.stairsBrick.blockID, 0, 2);
		world.setBlock(i + 2, j + 6, k + 7, Block.stairsBrick.blockID, 0, 2);
		world.setBlock(i + 2, j + 6, k + 8, Block.stairsBrick.blockID, 0, 2);
		world.setBlock(i + 2, j + 6, k + 9, Block.stairsBrick.blockID, 0, 2);
		world.setBlock(i + 3, j + 0, k + 4, Block.stoneBrick.blockID, this.pickStoneBrickType(rand), 2);
		world.setBlock(i + 3, j + 0, k + 5, Block.stoneBrick.blockID, this.pickStoneBrickType(rand), 2);
		world.setBlock(i + 3, j + 0, k + 6, Block.planks.blockID, 2, 2);
		world.setBlock(i + 3, j + 0, k + 7, Block.planks.blockID, 2, 2);
		world.setBlock(i + 3, j + 0, k + 8, Block.planks.blockID, 2, 2);
		world.setBlock(i + 3, j + 0, k + 9, Block.planks.blockID, 2, 2);
		world.setBlock(i + 3, j + 0, k + 10, Block.planks.blockID, 2, 2);
		world.setBlock(i + 3, j + 0, k + 11, Block.stoneBrick.blockID, this.pickStoneBrickType(rand), 2);
		world.setBlock(i + 3, j + 1, k + 4, Block.stoneBrick.blockID, this.pickStoneBrickType(rand), 2);
		world.setBlock(i + 3, j + 1, k + 5, Block.stoneBrick.blockID, this.pickStoneBrickType(rand), 2);
		world.setBlock(i + 3, j + 1, k + 6, Block.woodSingleSlab.blockID, 2, 2);
		world.setBlock(i + 3, j + 1, k + 7, 0, 0, 2);
		world.setBlock(i + 3, j + 1, k + 8, 0, 0, 2);
		world.setBlock(i + 3, j + 1, k + 9, Block.woodSingleSlab.blockID, 2, 2);
		world.setBlock(i + 3, j + 1, k + 10, Block.stoneBrick.blockID, this.pickStoneBrickType(rand), 2);
		world.setBlock(i + 3, j + 1, k + 11, Block.stoneBrick.blockID, this.pickStoneBrickType(rand), 2);
		world.setBlock(i + 3, j + 2, k + 4, Block.stoneBrick.blockID, this.pickStoneBrickType(rand), 2);
		world.setBlock(i + 3, j + 2, k + 5, Block.stoneBrick.blockID, this.pickStoneBrickType(rand), 2);
		world.setBlock(i + 3, j + 2, k + 6, Block.woodSingleSlab.blockID, 9, 2);
		world.setBlock(i + 3, j + 2, k + 7, 0, 0, 2);
		world.setBlock(i + 3, j + 2, k + 8, 0, 0, 2);
		world.setBlock(i + 3, j + 2, k + 9, Block.woodSingleSlab.blockID, 9, 2);
		world.setBlock(i + 3, j + 2, k + 10, Block.stoneBrick.blockID, this.pickStoneBrickType(rand), 2);
		world.setBlock(i + 3, j + 2, k + 11, Block.stoneBrick.blockID, this.pickStoneBrickType(rand), 2);
		world.setBlock(i + 3, j + 3, k + 4, Block.stoneBrick.blockID, this.pickStoneBrickType(rand), 2);
		world.setBlock(i + 3, j + 3, k + 5, Block.stoneBrick.blockID, this.pickStoneBrickType(rand), 2);
		world.setBlock(i + 3, j + 3, k + 6, Block.woodDoubleSlab.blockID, 1, 2);
		world.setBlock(i + 3, j + 3, k + 7, Block.woodSingleSlab.blockID, 9, 2);
		world.setBlock(i + 3, j + 3, k + 8, Block.woodSingleSlab.blockID, 9, 2);
		world.setBlock(i + 3, j + 3, k + 9, Block.woodDoubleSlab.blockID, 1, 2);
		world.setBlock(i + 3, j + 3, k + 10, Block.stoneBrick.blockID, this.pickStoneBrickType(rand), 2);
		world.setBlock(i + 3, j + 3, k + 11, Block.stoneBrick.blockID, this.pickStoneBrickType(rand), 2);
		world.setBlock(i + 3, j + 4, k + 4, Block.stoneBrick.blockID, this.pickStoneBrickType(rand), 2);
		world.setBlock(i + 3, j + 4, k + 5, Block.stoneBrick.blockID, this.pickStoneBrickType(rand), 2);
		world.setBlock(i + 3, j + 4, k + 7, 0, 0, 2);
		world.setBlock(i + 3, j + 4, k + 8, 0, 0, 2);
		world.setBlock(i + 3, j + 4, k + 10, Block.stoneBrick.blockID, this.pickStoneBrickType(rand), 2);
		world.setBlock(i + 3, j + 4, k + 11, Block.stoneBrick.blockID, this.pickStoneBrickType(rand), 2);
		world.setBlock(i + 3, j + 5, k + 3, Block.stairsBrick.blockID, 0, 2);
		world.setBlock(i + 3, j + 5, k + 4, Block.brick.blockID, 0, 2);
		world.setBlock(i + 3, j + 5, k + 5, Block.stoneBrick.blockID, this.pickStoneBrickType(rand), 2);
		world.setBlock(i + 3, j + 5, k + 6, 0, 0, 2);
		world.setBlock(i + 3, j + 5, k + 7, 0, 0, 2);
		world.setBlock(i + 3, j + 5, k + 8, 0, 0, 2);
		world.setBlock(i + 3, j + 5, k + 9, 0, 0, 2);
		world.setBlock(i + 3, j + 5, k + 10, Block.stoneBrick.blockID, this.pickStoneBrickType(rand), 2);
		world.setBlock(i + 3, j + 5, k + 11, Block.brick.blockID, 0, 2);
		world.setBlock(i + 3, j + 5, k + 12, Block.stairsBrick.blockID, 0, 2);
		world.setBlock(i + 3, j + 6, k + 4, Block.stairsBrick.blockID, 0, 2);
		world.setBlock(i + 3, j + 6, k + 5, Block.stairsBrick.blockID, 0, 2);
		world.setBlock(i + 3, j + 6, k + 6, Block.brick.blockID, 0, 2);
		world.setBlock(i + 3, j + 6, k + 7, Block.stoneBrick.blockID, this.pickStoneBrickType(rand), 2);
		world.setBlock(i + 3, j + 6, k + 8, Block.stoneBrick.blockID, this.pickStoneBrickType(rand), 2);
		world.setBlock(i + 3, j + 6, k + 9, Block.brick.blockID, 0, 2);
		world.setBlock(i + 3, j + 6, k + 10, Block.stairsBrick.blockID, 0, 2);
		world.setBlock(i + 3, j + 6, k + 11, Block.stairsBrick.blockID, 0, 2);
		world.setBlock(i + 3, j + 7, k + 6, Block.wood.blockID, 1, 2);
		world.setBlock(i + 3, j + 7, k + 7, Block.stoneBrick.blockID, this.pickStoneBrickType(rand), 2);
		world.setBlock(i + 3, j + 7, k + 8, Block.stoneBrick.blockID, this.pickStoneBrickType(rand), 2);
		world.setBlock(i + 3, j + 7, k + 9, Block.wood.blockID, 1, 2);
		world.setBlock(i + 3, j + 8, k + 6, Block.wood.blockID, 1, 2);
		world.setBlock(i + 3, j + 8, k + 7, Block.netherrack.blockID, 0, 2);
		world.setBlock(i + 3, j + 8, k + 8, Block.netherrack.blockID, 0, 2);
		world.setBlock(i + 3, j + 8, k + 9, Block.wood.blockID, 1, 2);
		world.setBlock(i + 3, j + 9, k + 6, Block.wood.blockID, 1, 2);
		world.setBlock(i + 3, j + 9, k + 7, Block.netherrack.blockID, 0, 2);
		world.setBlock(i + 3, j + 9, k + 8, Block.netherrack.blockID, 0, 2);
		world.setBlock(i + 3, j + 9, k + 9, Block.wood.blockID, 1, 2);
		world.setBlock(i + 3, j + 10, k + 6, Block.wood.blockID, 1, 2);
		world.setBlock(i + 3, j + 10, k + 7, Block.stoneBrick.blockID, this.pickStoneBrickType(rand), 2);
		world.setBlock(i + 3, j + 10, k + 8, Block.stoneBrick.blockID, this.pickStoneBrickType(rand), 2);
		world.setBlock(i + 3, j + 10, k + 9, Block.wood.blockID, 1, 2);
		world.setBlock(i + 3, j + 11, k + 6, Block.wood.blockID, 1, 2);
		world.setBlock(i + 3, j + 11, k + 7, Block.stoneBrick.blockID, this.pickStoneBrickType(rand), 2);
		world.setBlock(i + 3, j + 11, k + 8, Block.stoneBrick.blockID, this.pickStoneBrickType(rand), 2);
		world.setBlock(i + 3, j + 11, k + 9, Block.wood.blockID, 1, 2);
		world.setBlock(i + 3, j + 17, k + 5, Block.cloth.blockID, 11, 2);
		world.setBlock(i + 3, j + 17, k + 6, Block.cloth.blockID, 11, 2);
		world.setBlock(i + 3, j + 17, k + 7, Block.cloth.blockID, 11, 2);
		world.setBlock(i + 3, j + 17, k + 8, Block.cloth.blockID, 11, 2);
		world.setBlock(i + 3, j + 17, k + 9, Block.cloth.blockID, 11, 2);
		world.setBlock(i + 3, j + 17, k + 10, Block.cloth.blockID, 11, 2);
		world.setBlock(i + 4, j + 0, k + 3, Block.stoneBrick.blockID, this.pickStoneBrickType(rand), 2);
		world.setBlock(i + 4, j + 0, k + 4, Block.planks.blockID, 2, 2);
		world.setBlock(i + 4, j + 0, k + 5, Block.planks.blockID, 2, 2);
		world.setBlock(i + 4, j + 0, k + 6, Block.planks.blockID, 1, 2);
		world.setBlock(i + 4, j + 0, k + 7, Block.planks.blockID, 1, 2);
		world.setBlock(i + 4, j + 0, k + 8, Block.planks.blockID, 1, 2);
		world.setBlock(i + 4, j + 0, k + 9, Block.planks.blockID, 1, 2);
		world.setBlock(i + 4, j + 0, k + 10, Block.planks.blockID, 2, 2);
		world.setBlock(i + 4, j + 0, k + 11, Block.planks.blockID, 2, 2);
		world.setBlock(i + 4, j + 0, k + 12, Block.stoneBrick.blockID, this.pickStoneBrickType(rand), 2);
		world.setBlock(i + 4, j + 1, k + 3, Block.stoneBrick.blockID, this.pickStoneBrickType(rand), 2);
		world.setBlock(i + 4, j + 1, k + 4, Block.woodSingleSlab.blockID, 2, 2);
		world.setBlock(i + 4, j + 1, k + 5, Block.woodSingleSlab.blockID, 2, 2);
		world.setBlock(i + 4, j + 1, k + 6, 0, 0, 2);
		world.setBlock(i + 4, j + 1, k + 7, 0, 0, 2);
		world.setBlock(i + 4, j + 1, k + 8, 0, 0, 2);
		world.setBlock(i + 4, j + 1, k + 9, 0, 0, 2);
		world.setBlock(i + 4, j + 1, k + 10, Block.woodSingleSlab.blockID, 2, 2);
		world.setBlock(i + 4, j + 1, k + 11, Block.woodSingleSlab.blockID, 2, 2);
		world.setBlock(i + 4, j + 1, k + 12, Block.stoneBrick.blockID, this.pickStoneBrickType(rand), 2);
		world.setBlock(i + 4, j + 2, k + 3, Block.stoneBrick.blockID, this.pickStoneBrickType(rand), 2);
		world.setBlock(i + 4, j + 2, k + 4, Block.woodSingleSlab.blockID, 9, 2);
		world.setBlock(i + 4, j + 2, k + 5, Block.woodSingleSlab.blockID, 9, 2);
		world.setBlock(i + 4, j + 2, k + 6, 0, 0, 2);
		world.setBlock(i + 4, j + 2, k + 7, 0, 0, 2);
		world.setBlock(i + 4, j + 2, k + 8, 0, 0, 2);
		world.setBlock(i + 4, j + 2, k + 9, 0, 0, 2);
		world.setBlock(i + 4, j + 2, k + 10, Block.woodSingleSlab.blockID, 9, 2);
		world.setBlock(i + 4, j + 2, k + 11, Block.woodSingleSlab.blockID, 9, 2);
		world.setBlock(i + 4, j + 2, k + 12, Block.stoneBrick.blockID, this.pickStoneBrickType(rand), 2);
		world.setBlock(i + 4, j + 3, k + 3, Block.stoneBrick.blockID, this.pickStoneBrickType(rand), 2);
		world.setBlock(i + 4, j + 3, k + 4, Block.bookShelf.blockID, 0, 2);
		world.setBlock(i + 4, j + 3, k + 5, Block.bookShelf.blockID, 0, 2);
		world.setBlock(i + 4, j + 3, k + 6, 0, 0, 2);
		world.setBlock(i + 4, j + 3, k + 7, 0, 0, 2);
		world.setBlock(i + 4, j + 3, k + 8, 0, 0, 2);
		world.setBlock(i + 4, j + 3, k + 9, 0, 0, 2);
		world.setBlock(i + 4, j + 3, k + 10, Block.bookShelf.blockID, 0, 2);
		world.setBlock(i + 4, j + 3, k + 11, Block.bookShelf.blockID, 0, 2);
		world.setBlock(i + 4, j + 3, k + 12, Block.stoneBrick.blockID, this.pickStoneBrickType(rand), 2);
		world.setBlock(i + 4, j + 4, k + 3, Block.stoneBrick.blockID, this.pickStoneBrickType(rand), 2);
		world.setBlock(i + 4, j + 4, k + 4, 0, 0, 2);
		world.setBlock(i + 4, j + 4, k + 5, 0, 0, 2);
		world.setBlock(i + 4, j + 4, k + 6, 0, 0, 2);
		world.setBlock(i + 4, j + 4, k + 7, 0, 0, 2);
		world.setBlock(i + 4, j + 4, k + 8, 0, 0, 2);
		world.setBlock(i + 4, j + 4, k + 9, 0, 0, 2);
		world.setBlock(i + 4, j + 4, k + 10, 0, 0, 2);
		world.setBlock(i + 4, j + 4, k + 11, 0, 0, 2);
		world.setBlock(i + 4, j + 4, k + 12, Block.stoneBrick.blockID, this.pickStoneBrickType(rand), 2);
		world.setBlock(i + 4, j + 5, k + 2, Block.stairsBrick.blockID, 2, 2);
		world.setBlock(i + 4, j + 5, k + 3, Block.stoneBrick.blockID, this.pickStoneBrickType(rand), 2);
		world.setBlock(i + 4, j + 5, k + 4, 0, 0, 2);
		world.setBlock(i + 4, j + 5, k + 5, 0, 0, 2);
		world.setBlock(i + 4, j + 5, k + 6, 0, 0, 2);
		world.setBlock(i + 4, j + 5, k + 7, 0, 0, 2);
		world.setBlock(i + 4, j + 5, k + 8, 0, 0, 2);
		world.setBlock(i + 4, j + 5, k + 9, 0, 0, 2);
		world.setBlock(i + 4, j + 5, k + 10, 0, 0, 2);
		world.setBlock(i + 4, j + 5, k + 11, 0, 0, 2);
		world.setBlock(i + 4, j + 5, k + 12, Block.stoneBrick.blockID, this.pickStoneBrickType(rand), 2);
		world.setBlock(i + 4, j + 5, k + 13, Block.stairsBrick.blockID, 3, 2);
		world.setBlock(i + 4, j + 6, k + 3, Block.stoneSingleSlab.blockID, 4, 2);
		world.setBlock(i + 4, j + 6, k + 4, Block.brick.blockID, 0, 2);
		world.setBlock(i + 4, j + 6, k + 5, Block.stoneBrick.blockID, this.pickStoneBrickType(rand), 2);
		world.setBlock(i + 4, j + 6, k + 6, Block.stoneBrick.blockID, this.pickStoneBrickType(rand), 2);
		world.setBlock(i + 4, j + 6, k + 7, this.pickDungeonBlock(rand), 0, 2);
		world.setBlock(i + 4, j + 6, k + 8, Block.stoneBrick.blockID, this.pickStoneBrickType(rand), 2);
		world.setBlock(i + 4, j + 6, k + 9, this.pickDungeonBlock(rand), 0, 2);
		world.setBlock(i + 4, j + 6, k + 10, Block.stoneBrick.blockID, this.pickStoneBrickType(rand), 2);
		world.setBlock(i + 4, j + 6, k + 11, Block.brick.blockID, 0, 2);
		world.setBlock(i + 4, j + 6, k + 12, Block.stoneSingleSlab.blockID, 4, 2);
		world.setBlock(i + 4, j + 7, k + 4, Block.stoneBrick.blockID, this.pickStoneBrickType(rand), 2);
		world.setBlock(i + 4, j + 7, k + 5, Block.stoneBrick.blockID, this.pickStoneBrickType(rand), 2);
		world.setBlock(i + 4, j + 7, k + 6, this.pickDungeonBlock(rand), 0, 2);
		world.setBlock(i + 4, j + 7, k + 7, 0, 0, 2);
		world.setBlock(i + 4, j + 7, k + 8, Block.stoneBrick.blockID, this.pickStoneBrickType(rand), 2);
		world.setBlock(i + 4, j + 7, k + 9, 0, 0, 2);
		world.setBlock(i + 4, j + 7, k + 10, Block.stoneBrick.blockID, this.pickStoneBrickType(rand), 2);
		world.setBlock(i + 4, j + 7, k + 11, Block.stoneBrick.blockID, this.pickStoneBrickType(rand), 2);
		world.setBlock(i + 4, j + 8, k + 4, Block.stoneBrick.blockID, this.pickStoneBrickType(rand), 2);
		world.setBlock(i + 4, j + 8, k + 5, Block.stoneBrick.blockID, this.pickStoneBrickType(rand), 2);
		world.setBlock(i + 4, j + 8, k + 6, 0, 0, 2);
		world.setBlock(i + 4, j + 8, k + 7, 0, 0, 2);
		world.setBlock(i + 4, j + 8, k + 8, 0, 0, 2);
		world.setBlock(i + 4, j + 8, k + 9, this.pickDungeonBlock(rand), 0, 2);
		world.setBlock(i + 4, j + 8, k + 10, Block.stoneBrick.blockID, this.pickStoneBrickType(rand), 2);
		world.setBlock(i + 4, j + 8, k + 11, Block.stoneBrick.blockID, this.pickStoneBrickType(rand), 2);
		world.setBlock(i + 4, j + 9, k + 4, Block.stoneBrick.blockID, this.pickStoneBrickType(rand), 2);
		world.setBlock(i + 4, j + 9, k + 5, Block.stoneBrick.blockID, this.pickStoneBrickType(rand), 2);
		world.setBlock(i + 4, j + 9, k + 6, 0, 0, 2);
		world.setBlock(i + 4, j + 9, k + 7, 0, 0, 2);
		world.setBlock(i + 4, j + 9, k + 8, 0, 0, 2);
		world.setBlock(i + 4, j + 9, k + 9, 0, 0, 2);
		world.setBlock(i + 4, j + 9, k + 10, Block.stoneBrick.blockID, this.pickStoneBrickType(rand), 2);
		world.setBlock(i + 4, j + 9, k + 11, Block.stoneBrick.blockID, this.pickStoneBrickType(rand), 2);
		world.setBlock(i + 4, j + 10, k + 4, Block.stoneBrick.blockID, this.pickStoneBrickType(rand), 2);
		world.setBlock(i + 4, j + 10, k + 5, Block.stoneBrick.blockID, this.pickStoneBrickType(rand), 2);
		world.setBlock(i + 4, j + 10, k + 6, 0, 0, 2);
		world.setBlock(i + 4, j + 10, k + 7, 0, 0, 2);
		world.setBlock(i + 4, j + 10, k + 8, 0, 0, 2);
		world.setBlock(i + 4, j + 10, k + 9, 0, 0, 2);
		world.setBlock(i + 4, j + 10, k + 10, Block.stoneBrick.blockID, this.pickStoneBrickType(rand), 2);
		world.setBlock(i + 4, j + 10, k + 11, Block.stoneBrick.blockID, this.pickStoneBrickType(rand), 2);
		world.setBlock(i + 4, j + 11, k + 4, Block.stoneBrick.blockID, this.pickStoneBrickType(rand), 2);
		world.setBlock(i + 4, j + 11, k + 5, Block.stoneBrick.blockID, this.pickStoneBrickType(rand), 2);
		world.setBlock(i + 4, j + 11, k + 6, Block.wood.blockID, 0, 2);
		world.setBlock(i + 4, j + 11, k + 7, Block.wood.blockID, 0, 2);
		world.setBlock(i + 4, j + 11, k + 8, Block.wood.blockID, 0, 2);
		world.setBlock(i + 4, j + 11, k + 9, Block.wood.blockID, 0, 2);
		world.setBlock(i + 4, j + 11, k + 10, Block.stoneBrick.blockID, this.pickStoneBrickType(rand), 2);
		world.setBlock(i + 4, j + 11, k + 11, Block.stoneBrick.blockID, this.pickStoneBrickType(rand), 2);
		world.setBlock(i + 4, j + 12, k + 6, Block.wood.blockID, 1, 2);
		world.setBlock(i + 4, j + 12, k + 7, Block.stoneBrick.blockID, this.pickStoneBrickType(rand), 2);
		world.setBlock(i + 4, j + 12, k + 8, Block.stoneBrick.blockID, this.pickStoneBrickType(rand), 2);
		world.setBlock(i + 4, j + 12, k + 9, Block.wood.blockID, 1, 2);
		world.setBlock(i + 4, j + 13, k + 6, Block.wood.blockID, 1, 2);
		world.setBlock(i + 4, j + 13, k + 7, Block.thinGlass.blockID, 0, 2);
		world.setBlock(i + 4, j + 13, k + 8, Block.thinGlass.blockID, 0, 2);
		world.setBlock(i + 4, j + 13, k + 9, Block.wood.blockID, 1, 2);
		world.setBlock(i + 4, j + 14, k + 6, Block.wood.blockID, 1, 2);
		world.setBlock(i + 4, j + 14, k + 7, Block.thinGlass.blockID, 0, 2);
		world.setBlock(i + 4, j + 14, k + 8, Block.thinGlass.blockID, 0, 2);
		world.setBlock(i + 4, j + 14, k + 9, Block.wood.blockID, 1, 2);
		world.setBlock(i + 4, j + 15, k + 6, Block.wood.blockID, 1, 2);
		world.setBlock(i + 4, j + 15, k + 7, Block.stoneBrick.blockID, this.pickStoneBrickType(rand), 2);
		world.setBlock(i + 4, j + 15, k + 8, Block.stoneBrick.blockID, this.pickStoneBrickType(rand), 2);
		world.setBlock(i + 4, j + 15, k + 9, Block.wood.blockID, 1, 2);
		world.setBlock(i + 4, j + 16, k + 6, Block.wood.blockID, 1, 2);
		world.setBlock(i + 4, j + 16, k + 7, Block.stoneBrick.blockID, this.pickStoneBrickType(rand), 2);
		world.setBlock(i + 4, j + 16, k + 8, Block.stoneBrick.blockID, this.pickStoneBrickType(rand), 2);
		world.setBlock(i + 4, j + 16, k + 9, Block.wood.blockID, 1, 2);
		world.setBlock(i + 4, j + 17, k + 3, Block.cloth.blockID, 11, 2);
		world.setBlock(i + 4, j + 17, k + 4, Block.cloth.blockID, 11, 2);
		world.setBlock(i + 4, j + 17, k + 5, Block.cloth.blockID, 11, 2);
		world.setBlock(i + 4, j + 17, k + 6, Block.wood.blockID, 1, 2);
		world.setBlock(i + 4, j + 17, k + 7, Block.stoneBrick.blockID, this.pickStoneBrickType(rand), 2);
		world.setBlock(i + 4, j + 17, k + 8, Block.stoneBrick.blockID, this.pickStoneBrickType(rand), 2);
		world.setBlock(i + 4, j + 17, k + 9, Block.wood.blockID, 1, 2);
		world.setBlock(i + 4, j + 17, k + 10, Block.cloth.blockID, 11, 2);
		world.setBlock(i + 4, j + 17, k + 11, Block.cloth.blockID, 11, 2);
		world.setBlock(i + 4, j + 17, k + 12, Block.cloth.blockID, 11, 2);
		world.setBlock(i + 4, j + 18, k + 5, Block.cloth.blockID, 11, 2);
		world.setBlock(i + 4, j + 18, k + 6, Block.cloth.blockID, 11, 2);
		world.setBlock(i + 4, j + 18, k + 7, Block.cloth.blockID, 11, 2);
		world.setBlock(i + 4, j + 18, k + 8, Block.cloth.blockID, 11, 2);
		world.setBlock(i + 4, j + 18, k + 9, Block.cloth.blockID, 11, 2);
		world.setBlock(i + 4, j + 18, k + 10, Block.cloth.blockID, 11, 2);
		world.setBlock(i + 5, j + 0, k + 2, Block.stoneBrick.blockID, this.pickStoneBrickType(rand), 2);
		world.setBlock(i + 5, j + 0, k + 3, Block.planks.blockID, 2, 2);
		world.setBlock(i + 5, j + 0, k + 4, Block.glowStone.blockID, 0, 2);
		world.setBlock(i + 5, j + 0, k + 5, Block.planks.blockID, 1, 2);
		world.setBlock(i + 5, j + 0, k + 6, Block.planks.blockID, 2, 2);
		world.setBlock(i + 5, j + 0, k + 7, Block.planks.blockID, 2, 2);
		world.setBlock(i + 5, j + 0, k + 8, Block.planks.blockID, 2, 2);
		world.setBlock(i + 5, j + 0, k + 9, Block.planks.blockID, 2, 2);
		world.setBlock(i + 5, j + 0, k + 10, Block.planks.blockID, 1, 2);
		world.setBlock(i + 5, j + 0, k + 11, Block.glowStone.blockID, 0, 2);
		world.setBlock(i + 5, j + 0, k + 12, Block.planks.blockID, 2, 2);
		world.setBlock(i + 5, j + 0, k + 13, Block.stoneBrick.blockID, this.pickStoneBrickType(rand), 2);
		world.setBlock(i + 5, j + 1, k + 2, Block.stoneBrick.blockID, this.pickStoneBrickType(rand), 2);
		world.setBlock(i + 5, j + 1, k + 3, Block.woodSingleSlab.blockID, 2, 2);
		world.setBlock(i + 5, j + 1, k + 4, 0, 0, 2);
		world.setBlock(i + 5, j + 1, k + 5, 0, 0, 2);
		world.setBlock(i + 5, j + 1, k + 6, 0, 0, 2);
		world.setBlock(i + 5, j + 1, k + 7, 0, 0, 2);
		world.setBlock(i + 5, j + 1, k + 8, 0, 0, 2);
		world.setBlock(i + 5, j + 1, k + 9, 0, 0, 2);
		world.setBlock(i + 5, j + 1, k + 10, 0, 0, 2);
		world.setBlock(i + 5, j + 1, k + 11, 0, 0, 2);
		world.setBlock(i + 5, j + 1, k + 12, Block.woodSingleSlab.blockID, 2, 2);
		world.setBlock(i + 5, j + 1, k + 13, Block.stoneBrick.blockID, this.pickStoneBrickType(rand), 2);
		world.setBlock(i + 5, j + 2, k + 2, Block.stoneBrick.blockID, this.pickStoneBrickType(rand), 2);
		world.setBlock(i + 5, j + 2, k + 3, Block.woodSingleSlab.blockID, 9, 2);
		world.setBlock(i + 5, j + 2, k + 4, 0, 0, 2);
		world.setBlock(i + 5, j + 2, k + 5, 0, 0, 2);
		world.setBlock(i + 5, j + 2, k + 6, 0, 0, 2);
		world.setBlock(i + 5, j + 2, k + 7, 0, 0, 2);
		world.setBlock(i + 5, j + 2, k + 8, 0, 0, 2);
		world.setBlock(i + 5, j + 2, k + 9, 0, 0, 2);
		world.setBlock(i + 5, j + 2, k + 10, 0, 0, 2);
		world.setBlock(i + 5, j + 2, k + 11, 0, 0, 2);
		world.setBlock(i + 5, j + 2, k + 12, Block.woodSingleSlab.blockID, 9, 2);
		world.setBlock(i + 5, j + 2, k + 13, Block.stoneBrick.blockID, this.pickStoneBrickType(rand), 2);
		world.setBlock(i + 5, j + 3, k + 2, Block.stoneBrick.blockID, this.pickStoneBrickType(rand), 2);
		world.setBlock(i + 5, j + 3, k + 3, Block.bookShelf.blockID, 0, 2);
		world.setBlock(i + 5, j + 3, k + 4, 0, 0, 2);
		world.setBlock(i + 5, j + 3, k + 5, 0, 0, 2);
		world.setBlock(i + 5, j + 3, k + 6, 0, 0, 2);
		world.setBlock(i + 5, j + 3, k + 7, 0, 0, 2);
		world.setBlock(i + 5, j + 3, k + 8, 0, 0, 2);
		world.setBlock(i + 5, j + 3, k + 9, 0, 0, 2);
		world.setBlock(i + 5, j + 3, k + 10, 0, 0, 2);
		world.setBlock(i + 5, j + 3, k + 11, 0, 0, 2);
		world.setBlock(i + 5, j + 3, k + 12, Block.bookShelf.blockID, 0, 2);
		world.setBlock(i + 5, j + 3, k + 13, Block.stoneBrick.blockID, this.pickStoneBrickType(rand), 2);
		world.setBlock(i + 5, j + 4, k + 2, Block.stoneBrick.blockID, this.pickStoneBrickType(rand), 2);
		world.setBlock(i + 5, j + 4, k + 3, 0, 0, 2);
		world.setBlock(i + 5, j + 4, k + 4, 0, 0, 2);
		world.setBlock(i + 5, j + 4, k + 5, 0, 0, 2);
		world.setBlock(i + 5, j + 4, k + 6, 0, 0, 2);
		world.setBlock(i + 5, j + 4, k + 7, 0, 0, 2);
		world.setBlock(i + 5, j + 4, k + 8, 0, 0, 2);
		world.setBlock(i + 5, j + 4, k + 9, 0, 0, 2);
		world.setBlock(i + 5, j + 4, k + 10, 0, 0, 2);
		world.setBlock(i + 5, j + 4, k + 11, 0, 0, 2);
		world.setBlock(i + 5, j + 4, k + 12, 0, 0, 2);
		world.setBlock(i + 5, j + 4, k + 13, Block.stoneBrick.blockID, this.pickStoneBrickType(rand), 2);
		world.setBlock(i + 5, j + 5, k + 1, Block.stairsBrick.blockID, 2, 2);
		world.setBlock(i + 5, j + 5, k + 2, Block.brick.blockID, 0, 2);
		world.setBlock(i + 5, j + 5, k + 3, 0, 0, 2);
		world.setBlock(i + 5, j + 5, k + 4, 0, 0, 2);
		world.setBlock(i + 5, j + 5, k + 5, 0, 0, 2);
		world.setBlock(i + 5, j + 5, k + 6, 0, 0, 2);
		world.setBlock(i + 5, j + 5, k + 7, 0, 0, 2);
		world.setBlock(i + 5, j + 5, k + 8, 0, 0, 2);
		world.setBlock(i + 5, j + 5, k + 9, 0, 0, 2);
		world.setBlock(i + 5, j + 5, k + 10, 0, 0, 2);
		world.setBlock(i + 5, j + 5, k + 11, 0, 0, 2);
		world.setBlock(i + 5, j + 5, k + 12, 0, 0, 2);
		world.setBlock(i + 5, j + 5, k + 13, Block.brick.blockID, 0, 2);
		world.setBlock(i + 5, j + 5, k + 14, Block.stairsBrick.blockID, 3, 2);
		world.setBlock(i + 5, j + 6, k + 2, Block.stairsBrick.blockID, 2, 2);
		world.setBlock(i + 5, j + 6, k + 3, Block.brick.blockID, 0, 2);
		world.setBlock(i + 5, j + 6, k + 4, this.pickDungeonBlock(rand), 0, 2);
		world.setBlock(i + 5, j + 6, k + 5, this.pickDungeonBlock(rand), 0, 2);
		world.setBlock(i + 5, j + 6, k + 6, this.pickDungeonBlock(rand), 0, 2);
		world.setBlock(i + 5, j + 6, k + 7, this.pickDungeonBlock(rand), 0, 2);
		world.setBlock(i + 5, j + 6, k + 8, this.pickDungeonBlock(rand), 0, 2);
		world.setBlock(i + 5, j + 6, k + 9, this.pickDungeonBlock(rand), 0, 2);
		world.setBlock(i + 5, j + 6, k + 10, this.pickDungeonBlock(rand), 0, 2);
		world.setBlock(i + 5, j + 6, k + 11, this.pickDungeonBlock(rand), 0, 2);
		world.setBlock(i + 5, j + 6, k + 12, Block.brick.blockID, 0, 2);
		world.setBlock(i + 5, j + 6, k + 13, Block.stairsBrick.blockID, 3, 2);
		world.setBlock(i + 5, j + 7, k + 3, Block.stoneBrick.blockID, this.pickStoneBrickType(rand), 2);
		world.setBlock(i + 5, j + 7, k + 4, Block.blockGold.blockID, 0, 2);
		world.setBlock(i + 5, j + 7, k + 5, Block.stoneBrick.blockID, this.pickStoneBrickType(rand), 2);
		world.setBlock(i + 5, j + 7, k + 6, 0, 0, 2);
		world.setBlock(i + 5, j + 7, k + 7, 0, 0, 2);
		world.setBlock(i + 5, j + 7, k + 8, 0, 0, 2);
		world.setBlock(i + 5, j + 7, k + 9, 0, 0, 2);
		world.setBlock(i + 5, j + 7, k + 10, Block.stoneBrick.blockID, this.pickStoneBrickType(rand), 2);
		world.setBlock(i + 5, j + 7, k + 11, Block.blockGold.blockID, 0, 2);
		world.setBlock(i + 5, j + 7, k + 12, Block.stoneBrick.blockID, this.pickStoneBrickType(rand), 2);
		world.setBlock(i + 5, j + 8, k + 3, Block.stoneBrick.blockID, this.pickStoneBrickType(rand), 2);
		world.setBlock(i + 5, j + 8, k + 4, Block.blockSteel.blockID, 0, 2);
		world.setBlock(i + 5, j + 8, k + 5, 0, 0, 2);
		world.setBlock(i + 5, j + 8, k + 6, 0, 0, 2);
		world.setBlock(i + 5, j + 8, k + 7, 0, 0, 2);
		world.setBlock(i + 5, j + 8, k + 8, 0, 0, 2);
		world.setBlock(i + 5, j + 8, k + 9, 0, 0, 2);
		world.setBlock(i + 5, j + 8, k + 10, 0, 0, 2);
		world.setBlock(i + 5, j + 8, k + 11, 0, 0, 2);
		world.setBlock(i + 5, j + 8, k + 12, Block.stoneBrick.blockID, this.pickStoneBrickType(rand), 2);
		world.setBlock(i + 5, j + 9, k + 3, Block.stoneBrick.blockID, this.pickStoneBrickType(rand), 2);
		world.setBlock(i + 5, j + 9, k + 4, 0, 0, 2);
		world.setBlock(i + 5, j + 9, k + 5, 0, 0, 2);
		world.setBlock(i + 5, j + 9, k + 6, 0, 0, 2);
		world.setBlock(i + 5, j + 9, k + 7, 0, 0, 2);
		world.setBlock(i + 5, j + 9, k + 8, 0, 0, 2);
		world.setBlock(i + 5, j + 9, k + 9, 0, 0, 2);
		world.setBlock(i + 5, j + 9, k + 10, 0, 0, 2);
		world.setBlock(i + 5, j + 9, k + 11, 0, 0, 2);
		world.setBlock(i + 5, j + 9, k + 12, Block.stoneBrick.blockID, this.pickStoneBrickType(rand), 2);
		world.setBlock(i + 5, j + 10, k + 3, Block.stoneBrick.blockID, this.pickStoneBrickType(rand), 2);
		world.setBlock(i + 5, j + 10, k + 4, 0, 0, 2);
		world.setBlock(i + 5, j + 10, k + 5, 0, 0, 2);
		world.setBlock(i + 5, j + 10, k + 6, 0, 0, 2);
		world.setBlock(i + 5, j + 10, k + 7, 0, 0, 2);
		world.setBlock(i + 5, j + 10, k + 8, 0, 0, 2);
		world.setBlock(i + 5, j + 10, k + 9, 0, 0, 2);
		world.setBlock(i + 5, j + 10, k + 10, 0, 0, 2);
		world.setBlock(i + 5, j + 10, k + 11, this.pickDungeonBlock(rand), 0, 2);
		world.setBlock(i + 5, j + 10, k + 12, Block.stoneBrick.blockID, this.pickStoneBrickType(rand), 2);
		world.setBlock(i + 5, j + 11, k + 3, Block.stoneBrick.blockID, this.pickStoneBrickType(rand), 2);
		world.setBlock(i + 5, j + 11, k + 4, Block.wood.blockID, 0, 2);
		world.setBlock(i + 5, j + 11, k + 5, Block.wood.blockID, 0, 2);
		world.setBlock(i + 5, j + 11, k + 6, Block.planks.blockID, 1, 2);
		world.setBlock(i + 5, j + 11, k + 7, Block.planks.blockID, 1, 2);
		world.setBlock(i + 5, j + 11, k + 8, Block.planks.blockID, 1, 2);
		world.setBlock(i + 5, j + 11, k + 9, Block.planks.blockID, 1, 2);
		world.setBlock(i + 5, j + 11, k + 10, Block.wood.blockID, 0, 2);
		world.setBlock(i + 5, j + 11, k + 11, Block.wood.blockID, 0, 2);
		world.setBlock(i + 5, j + 11, k + 12, Block.stoneBrick.blockID, this.pickStoneBrickType(rand), 2);
		world.setBlock(i + 5, j + 12, k + 4, Block.stoneBrick.blockID, this.pickStoneBrickType(rand), 2);
		world.setBlock(i + 5, j + 12, k + 5, Block.stoneBrick.blockID, this.pickStoneBrickType(rand), 2);
		world.setBlock(i + 5, j + 12, k + 10, Block.stoneBrick.blockID, this.pickStoneBrickType(rand), 2);
		world.setBlock(i + 5, j + 12, k + 11, Block.stoneBrick.blockID, this.pickStoneBrickType(rand), 2);
		world.setBlock(i + 5, j + 13, k + 4, Block.stoneBrick.blockID, this.pickStoneBrickType(rand), 2);
		world.setBlock(i + 5, j + 13, k + 5, Block.stoneBrick.blockID, this.pickStoneBrickType(rand), 2);
		world.setBlock(i + 5, j + 13, k + 6, 0, 0, 2);
		world.setBlock(i + 5, j + 13, k + 7, 0, 0, 2);
		world.setBlock(i + 5, j + 13, k + 8, 0, 0, 2);
		world.setBlock(i + 5, j + 13, k + 9, 0, 0, 2);
		world.setBlock(i + 5, j + 13, k + 10, Block.stoneBrick.blockID, this.pickStoneBrickType(rand), 2);
		world.setBlock(i + 5, j + 13, k + 11, Block.stoneBrick.blockID, this.pickStoneBrickType(rand), 2);
		world.setBlock(i + 5, j + 14, k + 4, Block.stoneBrick.blockID, this.pickStoneBrickType(rand), 2);
		world.setBlock(i + 5, j + 14, k + 5, Block.stoneBrick.blockID, this.pickStoneBrickType(rand), 2);
		world.setBlock(i + 5, j + 14, k + 6, 0, 0, 2);
		world.setBlock(i + 5, j + 14, k + 7, 0, 0, 2);
		world.setBlock(i + 5, j + 14, k + 8, 0, 0, 2);
		world.setBlock(i + 5, j + 14, k + 9, 0, 0, 2);
		world.setBlock(i + 5, j + 14, k + 10, Block.stoneBrick.blockID, this.pickStoneBrickType(rand), 2);
		world.setBlock(i + 5, j + 14, k + 11, Block.stoneBrick.blockID, this.pickStoneBrickType(rand), 2);
		world.setBlock(i + 5, j + 15, k + 4, Block.stoneBrick.blockID, this.pickStoneBrickType(rand), 2);
		world.setBlock(i + 5, j + 15, k + 5, Block.stoneBrick.blockID, this.pickStoneBrickType(rand), 2);
		world.setBlock(i + 5, j + 15, k + 6, 0, 0, 2);
		world.setBlock(i + 5, j + 15, k + 7, 0, 0, 2);
		world.setBlock(i + 5, j + 15, k + 8, 0, 0, 2);
		world.setBlock(i + 5, j + 15, k + 9, 0, 0, 2);
		world.setBlock(i + 5, j + 15, k + 10, Block.stoneBrick.blockID, this.pickStoneBrickType(rand), 2);
		world.setBlock(i + 5, j + 15, k + 11, Block.stoneBrick.blockID, this.pickStoneBrickType(rand), 2);
		world.setBlock(i + 5, j + 16, k + 4, Block.stoneBrick.blockID, this.pickStoneBrickType(rand), 2);
		world.setBlock(i + 5, j + 16, k + 5, Block.stoneBrick.blockID, this.pickStoneBrickType(rand), 2);
		world.setBlock(i + 5, j + 16, k + 6, 0, 0, 2);
		world.setBlock(i + 5, j + 16, k + 7, 0, 0, 2);
		world.setBlock(i + 5, j + 16, k + 8, 0, 0, 2);
		world.setBlock(i + 5, j + 16, k + 9, 0, 0, 2);
		world.setBlock(i + 5, j + 16, k + 10, Block.stoneBrick.blockID, this.pickStoneBrickType(rand), 2);
		world.setBlock(i + 5, j + 16, k + 11, Block.stoneBrick.blockID, this.pickStoneBrickType(rand), 2);
		world.setBlock(i + 5, j + 17, k + 2, Block.cloth.blockID, 11, 2);
		world.setBlock(i + 5, j + 17, k + 3, Block.cloth.blockID, 11, 2);
		world.setBlock(i + 5, j + 17, k + 4, Block.stoneBrick.blockID, this.pickStoneBrickType(rand), 2);
		world.setBlock(i + 5, j + 17, k + 5, Block.stoneBrick.blockID, this.pickStoneBrickType(rand), 2);
		world.setBlock(i + 5, j + 17, k + 6, 0, 0, 2);
		world.setBlock(i + 5, j + 17, k + 7, 0, 0, 2);
		world.setBlock(i + 5, j + 17, k + 8, 0, 0, 2);
		world.setBlock(i + 5, j + 17, k + 9, 0, 0, 2);
		world.setBlock(i + 5, j + 17, k + 10, Block.stoneBrick.blockID, this.pickStoneBrickType(rand), 2);
		world.setBlock(i + 5, j + 17, k + 11, Block.stoneBrick.blockID, this.pickStoneBrickType(rand), 2);
		world.setBlock(i + 5, j + 17, k + 12, Block.cloth.blockID, 11, 2);
		world.setBlock(i + 5, j + 18, k + 4, Block.cloth.blockID, 11, 2);
		world.setBlock(i + 5, j + 18, k + 5, Block.cloth.blockID, 11, 2);
		world.setBlock(i + 5, j + 18, k + 6, 0, 0, 2);
		world.setBlock(i + 5, j + 18, k + 7, 0, 0, 2);
		world.setBlock(i + 5, j + 18, k + 8, 0, 0, 2);
		world.setBlock(i + 5, j + 18, k + 9, 0, 0, 2);
		world.setBlock(i + 5, j + 18, k + 10, Block.cloth.blockID, 11, 2);
		world.setBlock(i + 5, j + 18, k + 11, Block.cloth.blockID, 11, 2);
		world.setBlock(i + 5, j + 19, k + 6, Block.cloth.blockID, 11, 2);
		world.setBlock(i + 5, j + 19, k + 7, Block.cloth.blockID, 11, 2);
		world.setBlock(i + 5, j + 19, k + 8, Block.cloth.blockID, 11, 2);
		world.setBlock(i + 5, j + 19, k + 9, Block.cloth.blockID, 11, 2);
		world.setBlock(i + 6, j + 0, k + 2, Block.stoneBrick.blockID, this.pickStoneBrickType(rand), 2);
		world.setBlock(i + 6, j + 0, k + 3, Block.planks.blockID, 2, 2);
		world.setBlock(i + 6, j + 0, k + 4, Block.planks.blockID, 1, 2);
		world.setBlock(i + 6, j + 0, k + 5, Block.planks.blockID, 2, 2);
		world.setBlock(i + 6, j + 0, k + 6, Block.planks.blockID, 2, 2);
		world.setBlock(i + 6, j + 0, k + 7, Block.planks.blockID, 0, 2);
		world.setBlock(i + 6, j + 0, k + 8, Block.planks.blockID, 0, 2);
		world.setBlock(i + 6, j + 0, k + 9, Block.planks.blockID, 2, 2);
		world.setBlock(i + 6, j + 0, k + 10, Block.planks.blockID, 2, 2);
		world.setBlock(i + 6, j + 0, k + 11, Block.planks.blockID, 1, 2);
		world.setBlock(i + 6, j + 0, k + 12, Block.planks.blockID, 2, 2);
		world.setBlock(i + 6, j + 0, k + 13, Block.stoneBrick.blockID, this.pickStoneBrickType(rand), 2);
		world.setBlock(i + 6, j + 1, k + 2, Block.stoneBrick.blockID, this.pickStoneBrickType(rand), 2);
		world.setBlock(i + 6, j + 1, k + 3, Block.woodSingleSlab.blockID, 2, 2);
		world.setBlock(i + 6, j + 1, k + 4, 0, 0, 2);
		world.setBlock(i + 6, j + 1, k + 5, 0, 0, 2);
		world.setBlock(i + 6, j + 1, k + 6, Block.stoneBrick.blockID, 0, 2);
		world.setBlock(i + 6, j + 1, k + 7, Block.stairsWoodOak.blockID, 0, 2);
		world.setBlock(i + 6, j + 1, k + 8, Block.stairsWoodOak.blockID, 0, 2);
		world.setBlock(i + 6, j + 1, k + 9, Block.stoneBrick.blockID, 0, 2);
		world.setBlock(i + 6, j + 1, k + 10, 0, 0, 2);
		world.setBlock(i + 6, j + 1, k + 11, 0, 0, 2);
		world.setBlock(i + 6, j + 1, k + 12, Block.woodSingleSlab.blockID, 2, 2);
		world.setBlock(i + 6, j + 1, k + 13, Block.stoneBrick.blockID, this.pickStoneBrickType(rand), 2);
		world.setBlock(i + 6, j + 2, k + 2, Block.stoneBrick.blockID, this.pickStoneBrickType(rand), 2);
		world.setBlock(i + 6, j + 2, k + 3, Block.woodSingleSlab.blockID, 9, 2);
		world.setBlock(i + 6, j + 2, k + 4, 0, 0, 2);
		world.setBlock(i + 6, j + 2, k + 5, 0, 0, 2);
		world.setBlock(i + 6, j + 2, k + 6, 0, 0, 2);
		world.setBlock(i + 6, j + 2, k + 7, 0, 0, 2);
		world.setBlock(i + 6, j + 2, k + 8, 0, 0, 2);
		world.setBlock(i + 6, j + 2, k + 9, 0, 0, 2);
		world.setBlock(i + 6, j + 2, k + 10, 0, 0, 2);
		world.setBlock(i + 6, j + 2, k + 11, 0, 0, 2);
		world.setBlock(i + 6, j + 2, k + 12, Block.woodSingleSlab.blockID, 9, 2);
		world.setBlock(i + 6, j + 2, k + 13, Block.stoneBrick.blockID, this.pickStoneBrickType(rand), 2);
		world.setBlock(i + 6, j + 3, k + 2, Block.stoneBrick.blockID, this.pickStoneBrickType(rand), 2);
		world.setBlock(i + 6, j + 3, k + 3, Block.bookShelf.blockID, 0, 2);
		world.setBlock(i + 6, j + 3, k + 4, 0, 0, 2);
		world.setBlock(i + 6, j + 3, k + 5, 0, 0, 2);
		world.setBlock(i + 6, j + 3, k + 6, 0, 0, 2);
		world.setBlock(i + 6, j + 3, k + 7, 0, 0, 2);
		world.setBlock(i + 6, j + 3, k + 8, 0, 0, 2);
		world.setBlock(i + 6, j + 3, k + 9, 0, 0, 2);
		world.setBlock(i + 6, j + 3, k + 10, 0, 0, 2);
		world.setBlock(i + 6, j + 3, k + 11, 0, 0, 2);
		world.setBlock(i + 6, j + 3, k + 12, Block.bookShelf.blockID, 0, 2);
		world.setBlock(i + 6, j + 3, k + 13, Block.stoneBrick.blockID, this.pickStoneBrickType(rand), 2);
		world.setBlock(i + 6, j + 4, k + 2, Block.stoneBrick.blockID, this.pickStoneBrickType(rand), 2);
		world.setBlock(i + 6, j + 4, k + 3, 0, 0, 2);
		world.setBlock(i + 6, j + 4, k + 4, 0, 0, 2);
		world.setBlock(i + 6, j + 4, k + 5, 0, 0, 2);
		world.setBlock(i + 6, j + 4, k + 6, 0, 0, 2);
		world.setBlock(i + 6, j + 4, k + 7, 0, 0, 2);
		world.setBlock(i + 6, j + 4, k + 8, 0, 0, 2);
		world.setBlock(i + 6, j + 4, k + 9, 0, 0, 2);
		world.setBlock(i + 6, j + 4, k + 10, 0, 0, 2);
		world.setBlock(i + 6, j + 4, k + 11, 0, 0, 2);
		world.setBlock(i + 6, j + 4, k + 12, 0, 0, 2);
		world.setBlock(i + 6, j + 4, k + 13, Block.stoneBrick.blockID, this.pickStoneBrickType(rand), 2);
		world.setBlock(i + 6, j + 5, k + 1, Block.stairsBrick.blockID, 2, 2);
		world.setBlock(i + 6, j + 5, k + 2, Block.stoneBrick.blockID, this.pickStoneBrickType(rand), 2);
		world.setBlock(i + 6, j + 5, k + 3, 0, 0, 2);
		world.setBlock(i + 6, j + 5, k + 4, 0, 0, 2);
		world.setBlock(i + 6, j + 5, k + 5, 0, 0, 2);
		world.setBlock(i + 6, j + 5, k + 6, Block.wood.blockID, 5, 2);
		world.setBlock(i + 6, j + 5, k + 7, Block.wood.blockID, 9, 2);
		world.setBlock(i + 6, j + 5, k + 8, Block.wood.blockID, 9, 2);
		world.setBlock(i + 6, j + 5, k + 9, Block.wood.blockID, 5, 2);
		world.setBlock(i + 6, j + 5, k + 10, 0, 0, 2);
		world.setBlock(i + 6, j + 5, k + 11, 0, 0, 2);
		world.setBlock(i + 6, j + 5, k + 12, 0, 0, 2);
		world.setBlock(i + 6, j + 5, k + 13, Block.stoneBrick.blockID, this.pickStoneBrickType(rand), 2);
		world.setBlock(i + 6, j + 5, k + 14, Block.stairsBrick.blockID, 3, 2);
		world.setBlock(i + 6, j + 6, k + 2, Block.stairsBrick.blockID, 2, 2);
		world.setBlock(i + 6, j + 6, k + 3, Block.stoneBrick.blockID, this.pickStoneBrickType(rand), 2);
		world.setBlock(i + 6, j + 6, k + 4, Block.stoneBrick.blockID, this.pickStoneBrickType(rand), 2);
		world.setBlock(i + 6, j + 6, k + 5, this.pickDungeonBlock(rand), 0, 2);
		world.setBlock(i + 6, j + 6, k + 6, this.pickDungeonBlock(rand), 0, 2);
		world.setBlock(i + 6, j + 6, k + 7, Block.stoneBrick.blockID, this.pickStoneBrickType(rand), 2);
		world.setBlock(i + 6, j + 6, k + 8, Block.stoneBrick.blockID, this.pickStoneBrickType(rand), 2);
		world.setBlock(i + 6, j + 6, k + 9, this.pickDungeonBlock(rand), 0, 2);
		world.setBlock(i + 6, j + 6, k + 10, Block.stoneBrick.blockID, this.pickStoneBrickType(rand), 2);
		world.setBlock(i + 6, j + 6, k + 11, Block.stoneBrick.blockID, this.pickStoneBrickType(rand), 2);
		world.setBlock(i + 6, j + 6, k + 12, Block.stoneBrick.blockID, this.pickStoneBrickType(rand), 2);
		world.setBlock(i + 6, j + 6, k + 13, Block.stairsBrick.blockID, 3, 2);
		world.setBlock(i + 6, j + 7, k + 3, Block.stoneBrick.blockID, this.pickStoneBrickType(rand), 2);
		world.setBlock(i + 6, j + 7, k + 4, 0, 0, 2);
		world.setBlock(i + 6, j + 7, k + 5, 0, 0, 2);
		world.setBlock(i + 6, j + 7, k + 6, 0, 0, 2);
		world.setBlock(i + 6, j + 7, k + 7, 0, 0, 2);
		world.setBlock(i + 6, j + 7, k + 8, 0, 0, 2);
		world.setBlock(i + 6, j + 7, k + 9, 0, 0, 2);
		world.setBlock(i + 6, j + 7, k + 10, 0, 0, 2);
		world.setBlock(i + 6, j + 7, k + 11, 0, 0, 2);
		world.setBlock(i + 6, j + 7, k + 12, Block.stoneBrick.blockID, this.pickStoneBrickType(rand), 2);
		world.setBlock(i + 6, j + 8, k + 3, Block.stoneBrick.blockID, this.pickStoneBrickType(rand), 2);
		world.setBlock(i + 6, j + 8, k + 4, 0, 0, 2);
		world.setBlock(i + 6, j + 8, k + 5, 0, 0, 2);
		world.setBlock(i + 6, j + 8, k + 6, 0, 0, 2);
		world.setBlock(i + 6, j + 8, k + 7, 0, 0, 2);
		world.setBlock(i + 6, j + 8, k + 8, 0, 0, 2);
		world.setBlock(i + 6, j + 8, k + 9, 0, 0, 2);
		world.setBlock(i + 6, j + 8, k + 10, 0, 0, 2);
		world.setBlock(i + 6, j + 8, k + 11, 0, 0, 2);
		world.setBlock(i + 6, j + 8, k + 12, Block.stoneBrick.blockID, this.pickStoneBrickType(rand), 2);
		world.setBlock(i + 6, j + 9, k + 3, Block.stoneBrick.blockID, this.pickStoneBrickType(rand), 2);
		world.setBlock(i + 6, j + 9, k + 4, 0, 0, 2);
		world.setBlock(i + 6, j + 9, k + 5, 0, 0, 2);
		world.setBlock(i + 6, j + 9, k + 6, 0, 0, 2);
		world.setBlock(i + 6, j + 9, k + 7, 0, 0, 2);
		world.setBlock(i + 6, j + 9, k + 8, 0, 0, 2);
		world.setBlock(i + 6, j + 9, k + 9, 0, 0, 2);
		world.setBlock(i + 6, j + 9, k + 10, 0, 0, 2);
		world.setBlock(i + 6, j + 9, k + 11, this.pickDungeonBlock(rand), 0, 2);
		world.setBlock(i + 6, j + 9, k + 12, Block.stoneBrick.blockID, this.pickStoneBrickType(rand), 2);
		world.setBlock(i + 6, j + 10, k + 3, Block.stoneBrick.blockID, this.pickStoneBrickType(rand), 2);
		world.setBlock(i + 6, j + 10, k + 4, 0, 0, 2);
		world.setBlock(i + 6, j + 10, k + 5, 0, 0, 2);
		world.setBlock(i + 6, j + 10, k + 6, 0, 0, 2);
		world.setBlock(i + 6, j + 10, k + 7, 0, 0, 2);
		world.setBlock(i + 6, j + 10, k + 8, 0, 0, 2);
		world.setBlock(i + 6, j + 10, k + 9, 0, 0, 2);
		world.setBlock(i + 6, j + 10, k + 10, 0, 0, 2);
		world.setBlock(i + 6, j + 10, k + 11, 0, 0, 2);
		world.setBlock(i + 6, j + 10, k + 12, Block.stoneBrick.blockID, this.pickStoneBrickType(rand), 2);
		world.setBlock(i + 6, j + 11, k + 3, Block.stoneBrick.blockID, this.pickStoneBrickType(rand), 2);
		world.setBlock(i + 6, j + 11, k + 4, Block.wood.blockID, 0, 2);
		world.setBlock(i + 6, j + 11, k + 5, Block.planks.blockID, 1, 2);
		world.setBlock(i + 6, j + 11, k + 6, Block.planks.blockID, 1, 2);
		world.setBlock(i + 6, j + 11, k + 7, Block.wood.blockID, 0, 2);
		world.setBlock(i + 6, j + 11, k + 8, Block.wood.blockID, 0, 2);
		world.setBlock(i + 6, j + 11, k + 9, Block.planks.blockID, 1, 2);
		world.setBlock(i + 6, j + 11, k + 10, Block.planks.blockID, 1, 2);
		world.setBlock(i + 6, j + 11, k + 11, Block.wood.blockID, 0, 2);
		world.setBlock(i + 6, j + 11, k + 12, Block.stoneBrick.blockID, this.pickStoneBrickType(rand), 2);
		world.setBlock(i + 6, j + 12, k + 4, Block.stoneBrick.blockID, this.pickStoneBrickType(rand), 2);
		world.setBlock(i + 6, j + 12, k + 5, Block.cloth.blockID, 3, 2);
		world.setBlock(i + 6, j + 12, k + 6, 0, 0, 2);
		world.setBlock(i + 6, j + 12, k + 7, 0, 0, 2);
		world.setBlock(i + 6, j + 12, k + 8, 0, 0, 2);
		world.setBlock(i + 6, j + 12, k + 9, 0, 0, 2);
		world.setBlock(i + 6, j + 12, k + 10, 0, 0, 2);
		world.setBlock(i + 6, j + 12, k + 11, Block.stoneBrick.blockID, this.pickStoneBrickType(rand), 2);
		world.setBlock(i + 6, j + 13, k + 4, Block.stoneBrick.blockID, this.pickStoneBrickType(rand), 2);
		world.setBlock(i + 6, j + 13, k + 5, Block.cloth.blockID, 3, 2);
		world.setBlock(i + 6, j + 13, k + 6, 0, 0, 2);
		world.setBlock(i + 6, j + 13, k + 7, 0, 0, 2);
		world.setBlock(i + 6, j + 13, k + 8, 0, 0, 2);
		world.setBlock(i + 6, j + 13, k + 9, 0, 0, 2);
		world.setBlock(i + 6, j + 13, k + 10, 0, 0, 2);
		world.setBlock(i + 6, j + 13, k + 11, Block.stoneBrick.blockID, this.pickStoneBrickType(rand), 2);
		world.setBlock(i + 6, j + 14, k + 4, Block.stoneBrick.blockID, this.pickStoneBrickType(rand), 2);
		world.setBlock(i + 6, j + 14, k + 6, 0, 0, 2);
		world.setBlock(i + 6, j + 14, k + 7, 0, 0, 2);
		world.setBlock(i + 6, j + 14, k + 8, 0, 0, 2);
		world.setBlock(i + 6, j + 14, k + 9, 0, 0, 2);
		world.setBlock(i + 6, j + 14, k + 10, 0, 0, 2);
		world.setBlock(i + 6, j + 14, k + 11, Block.stoneBrick.blockID, this.pickStoneBrickType(rand), 2);
		world.setBlock(i + 6, j + 15, k + 4, Block.stoneBrick.blockID, this.pickStoneBrickType(rand), 2);
		world.setBlock(i + 6, j + 15, k + 5, 0, 0, 2);
		world.setBlock(i + 6, j + 15, k + 6, 0, 0, 2);
		world.setBlock(i + 6, j + 15, k + 7, 0, 0, 2);
		world.setBlock(i + 6, j + 15, k + 8, 0, 0, 2);
		world.setBlock(i + 6, j + 15, k + 9, 0, 0, 2);
		world.setBlock(i + 6, j + 15, k + 10, 0, 0, 2);
		world.setBlock(i + 6, j + 15, k + 11, Block.stoneBrick.blockID, this.pickStoneBrickType(rand), 2);
		world.setBlock(i + 6, j + 16, k + 4, Block.stoneBrick.blockID, this.pickStoneBrickType(rand), 2);
		world.setBlock(i + 6, j + 16, k + 5, 0, 0, 2);
		world.setBlock(i + 6, j + 16, k + 6, 0, 0, 2);
		world.setBlock(i + 6, j + 16, k + 7, 0, 0, 2);
		world.setBlock(i + 6, j + 16, k + 8, 0, 0, 2);
		world.setBlock(i + 6, j + 16, k + 9, 0, 0, 2);
		world.setBlock(i + 6, j + 16, k + 10, 0, 0, 2);
		world.setBlock(i + 6, j + 16, k + 11, Block.stoneBrick.blockID, this.pickStoneBrickType(rand), 2);
		world.setBlock(i + 6, j + 17, k + 2, Block.cloth.blockID, 11, 2);
		world.setBlock(i + 6, j + 17, k + 3, Block.cloth.blockID, 11, 2);
		world.setBlock(i + 6, j + 17, k + 4, Block.stoneBrick.blockID, this.pickStoneBrickType(rand), 2);
		world.setBlock(i + 6, j + 17, k + 5, 0, 0, 2);
		world.setBlock(i + 6, j + 17, k + 6, 0, 0, 2);
		world.setBlock(i + 6, j + 17, k + 7, 0, 0, 2);
		world.setBlock(i + 6, j + 17, k + 8, 0, 0, 2);
		world.setBlock(i + 6, j + 17, k + 9, 0, 0, 2);
		world.setBlock(i + 6, j + 17, k + 10, 0, 0, 2);
		world.setBlock(i + 6, j + 17, k + 11, Block.stoneBrick.blockID, this.pickStoneBrickType(rand), 2);
		world.setBlock(i + 6, j + 17, k + 12, Block.cloth.blockID, 11, 2);
		world.setBlock(i + 6, j + 17, k + 13, Block.cloth.blockID, 11, 2);
		world.setBlock(i + 6, j + 18, k + 3, Block.cloth.blockID, 11, 2);
		world.setBlock(i + 6, j + 18, k + 4, Block.cloth.blockID, 11, 2);
		world.setBlock(i + 6, j + 18, k + 5, 0, 0, 2);
		world.setBlock(i + 6, j + 18, k + 6, 0, 0, 2);
		world.setBlock(i + 6, j + 18, k + 7, 0, 0, 2);
		world.setBlock(i + 6, j + 18, k + 8, 0, 0, 2);
		world.setBlock(i + 6, j + 18, k + 9, 0, 0, 2);
		world.setBlock(i + 6, j + 18, k + 10, 0, 0, 2);
		world.setBlock(i + 6, j + 18, k + 11, Block.cloth.blockID, 11, 2);
		world.setBlock(i + 6, j + 18, k + 12, Block.cloth.blockID, 11, 2);
		world.setBlock(i + 6, j + 19, k + 5, Block.cloth.blockID, 11, 2);
		world.setBlock(i + 6, j + 19, k + 6, Block.cloth.blockID, 11, 2);
		world.setBlock(i + 6, j + 19, k + 7, 0, 0, 2);
		world.setBlock(i + 6, j + 19, k + 8, 0, 0, 2);
		world.setBlock(i + 6, j + 19, k + 9, Block.cloth.blockID, 11, 2);
		world.setBlock(i + 6, j + 19, k + 10, Block.cloth.blockID, 11, 2);
		world.setBlock(i + 6, j + 20, k + 7, Block.cloth.blockID, 11, 2);
		world.setBlock(i + 6, j + 20, k + 8, Block.cloth.blockID, 11, 2);
		world.setBlock(i + 7, j + 0, k + 1, Block.stoneBrick.blockID, this.pickStoneBrickType(rand), 2);
		world.setBlock(i + 7, j + 0, k + 2, Block.planks.blockID, 2, 2);
		world.setBlock(i + 7, j + 0, k + 3, Block.planks.blockID, 1, 2);
		world.setBlock(i + 7, j + 0, k + 4, Block.planks.blockID, 2, 2);
		world.setBlock(i + 7, j + 0, k + 5, Block.planks.blockID, 2, 2);
		world.setBlock(i + 7, j + 0, k + 6, Block.planks.blockID, 0, 2);
		world.setBlock(i + 7, j + 0, k + 7, Block.wood.blockID, 9, 2);
		world.setBlock(i + 7, j + 0, k + 8, Block.wood.blockID, 9, 2);
		world.setBlock(i + 7, j + 0, k + 9, Block.planks.blockID, 0, 2);
		world.setBlock(i + 7, j + 0, k + 10, Block.planks.blockID, 2, 2);
		world.setBlock(i + 7, j + 0, k + 11, Block.planks.blockID, 2, 2);
		world.setBlock(i + 7, j + 0, k + 12, Block.planks.blockID, 1, 2);
		world.setBlock(i + 7, j + 0, k + 13, Block.planks.blockID, 2, 2);
		world.setBlock(i + 7, j + 0, k + 14, Block.stoneBrick.blockID, this.pickStoneBrickType(rand), 2);
		world.setBlock(i + 7, j + 1, k + 1, Block.stoneBrick.blockID, this.pickStoneBrickType(rand), 2);
		world.setBlock(i + 7, j + 1, k + 2, Block.woodSingleSlab.blockID, 2, 2);
		world.setBlock(i + 7, j + 1, k + 3, 0, 0, 2);
		world.setBlock(i + 7, j + 1, k + 4, 0, 0, 2);
		world.setBlock(i + 7, j + 1, k + 5, Block.stoneBrick.blockID, 0, 2);
		world.setBlock(i + 7, j + 1, k + 6, Block.wood.blockID, 1, 2);
		world.setBlock(i + 7, j + 1, k + 7, Block.wood.blockID, 1, 2);
		world.setBlock(i + 7, j + 1, k + 8, Block.wood.blockID, 1, 2);
		world.setBlock(i + 7, j + 1, k + 9, Block.wood.blockID, 1, 2);
		world.setBlock(i + 7, j + 1, k + 10, Block.stoneBrick.blockID, 0, 2);
		world.setBlock(i + 7, j + 1, k + 11, 0, 0, 2);
		world.setBlock(i + 7, j + 1, k + 12, 0, 0, 2);
		world.setBlock(i + 7, j + 1, k + 13, Block.woodSingleSlab.blockID, 2, 2);
		world.setBlock(i + 7, j + 1, k + 14, Block.stoneBrick.blockID, this.pickStoneBrickType(rand), 2);
		world.setBlock(i + 7, j + 2, k + 1, Block.stoneBrick.blockID, this.pickStoneBrickType(rand), 2);
		world.setBlock(i + 7, j + 2, k + 2, Block.woodSingleSlab.blockID, 9, 2);
		world.setBlock(i + 7, j + 2, k + 3, 0, 0, 2);
		world.setBlock(i + 7, j + 2, k + 4, 0, 0, 2);
		world.setBlock(i + 7, j + 2, k + 5, 0, 0, 2);
		world.setBlock(i + 7, j + 2, k + 6, Block.wood.blockID, 1, 2);
		world.setBlock(i + 7, j + 2, k + 7, Block.stairsWoodOak.blockID, 0, 2);
		world.setBlock(i + 7, j + 2, k + 8, Block.stairsWoodOak.blockID, 0, 2);
		world.setBlock(i + 7, j + 2, k + 9, Block.wood.blockID, 1, 2);
		world.setBlock(i + 7, j + 2, k + 10, 0, 0, 2);
		world.setBlock(i + 7, j + 2, k + 11, 0, 0, 2);
		world.setBlock(i + 7, j + 2, k + 12, 0, 0, 2);
		world.setBlock(i + 7, j + 2, k + 13, Block.woodSingleSlab.blockID, 9, 2);
		world.setBlock(i + 7, j + 2, k + 14, Block.stoneBrick.blockID, this.pickStoneBrickType(rand), 2);
		world.setBlock(i + 7, j + 3, k + 1, Block.stoneBrick.blockID, this.pickStoneBrickType(rand), 2);
		world.setBlock(i + 7, j + 3, k + 2, Block.bookShelf.blockID, 0, 2);
		world.setBlock(i + 7, j + 3, k + 3, 0, 0, 2);
		world.setBlock(i + 7, j + 3, k + 4, 0, 0, 2);
		world.setBlock(i + 7, j + 3, k + 5, 0, 0, 2);
		world.setBlock(i + 7, j + 3, k + 6, Block.wood.blockID, 1, 2);
		world.setBlock(i + 7, j + 3, k + 7, 0, 0, 2);
		world.setBlock(i + 7, j + 3, k + 8, 0, 0, 2);
		world.setBlock(i + 7, j + 3, k + 9, Block.wood.blockID, 1, 2);
		world.setBlock(i + 7, j + 3, k + 10, 0, 0, 2);
		world.setBlock(i + 7, j + 3, k + 11, 0, 0, 2);
		world.setBlock(i + 7, j + 3, k + 12, 0, 0, 2);
		world.setBlock(i + 7, j + 3, k + 13, Block.bookShelf.blockID, 0, 2);
		world.setBlock(i + 7, j + 3, k + 14, Block.stoneBrick.blockID, this.pickStoneBrickType(rand), 2);
		world.setBlock(i + 7, j + 4, k + 1, Block.stoneBrick.blockID, this.pickStoneBrickType(rand), 2);
		world.setBlock(i + 7, j + 4, k + 2, 0, 0, 2);
		world.setBlock(i + 7, j + 4, k + 3, 0, 0, 2);
		world.setBlock(i + 7, j + 4, k + 4, 0, 0, 2);
		world.setBlock(i + 7, j + 4, k + 5, 0, 0, 2);
		world.setBlock(i + 7, j + 4, k + 6, Block.wood.blockID, 1, 2);
		world.setBlock(i + 7, j + 4, k + 9, Block.wood.blockID, 1, 2);
		world.setBlock(i + 7, j + 4, k + 10, 0, 0, 2);
		world.setBlock(i + 7, j + 4, k + 11, 0, 0, 2);
		world.setBlock(i + 7, j + 4, k + 12, 0, 0, 2);
		world.setBlock(i + 7, j + 4, k + 13, 0, 0, 2);
		world.setBlock(i + 7, j + 4, k + 14, Block.stoneBrick.blockID, this.pickStoneBrickType(rand), 2);
		world.setBlock(i + 7, j + 5, k + 0, Block.stairsBrick.blockID, 2, 2);
		world.setBlock(i + 7, j + 5, k + 1, Block.brick.blockID, 0, 2);
		world.setBlock(i + 7, j + 5, k + 2, 0, 0, 2);
		world.setBlock(i + 7, j + 5, k + 4, 0, 0, 2);
		world.setBlock(i + 7, j + 5, k + 5, Block.wood.blockID, 9, 2);
		world.setBlock(i + 7, j + 5, k + 6, Block.wood.blockID, 1, 2);
		world.setBlock(i + 7, j + 5, k + 9, Block.wood.blockID, 1, 2);
		world.setBlock(i + 7, j + 5, k + 10, Block.wood.blockID, 9, 2);
		world.setBlock(i + 7, j + 5, k + 11, 0, 0, 2);
		world.setBlock(i + 7, j + 5, k + 12, 0, 0, 2);
		world.setBlock(i + 7, j + 5, k + 13, 0, 0, 2);
		world.setBlock(i + 7, j + 5, k + 14, Block.brick.blockID, 0, 2);
		world.setBlock(i + 7, j + 5, k + 15, Block.stairsBrick.blockID, 3, 2);
		world.setBlock(i + 7, j + 6, k + 1, Block.stairsBrick.blockID, 2, 2);
		world.setBlock(i + 7, j + 6, k + 2, Block.brick.blockID, 0, 2);
		world.setBlock(i + 7, j + 6, k + 3, this.pickDungeonBlock(rand), 0, 2);
		world.setBlock(i + 7, j + 6, k + 4, this.pickDungeonBlock(rand), 0, 2);
		world.setBlock(i + 7, j + 6, k + 5, this.pickDungeonBlock(rand), 0, 2);
		world.setBlock(i + 7, j + 6, k + 6, Block.stoneBrick.blockID, this.pickStoneBrickType(rand), 2);
		world.setBlock(i + 7, j + 6, k + 9, this.pickDungeonBlock(rand), 0, 2);
		world.setBlock(i + 7, j + 6, k + 10, this.pickDungeonBlock(rand), 0, 2);
		world.setBlock(i + 7, j + 6, k + 11, this.pickDungeonBlock(rand), 0, 2);
		world.setBlock(i + 7, j + 6, k + 12, this.pickDungeonBlock(rand), 0, 2);
		world.setBlock(i + 7, j + 6, k + 13, Block.brick.blockID, 0, 2);
		world.setBlock(i + 7, j + 6, k + 14, Block.stairsBrick.blockID, 3, 2);
		world.setBlock(i + 7, j + 7, k + 2, Block.stoneBrick.blockID, this.pickStoneBrickType(rand), 2);
		world.setBlock(i + 7, j + 7, k + 3, 0, 0, 2);
		world.setBlock(i + 7, j + 7, k + 4, 0, 0, 2);
		world.setBlock(i + 7, j + 7, k + 5, this.pickDungeonBlock(rand), 0, 2);
		world.setBlock(i + 7, j + 7, k + 6, 0, 0, 2);
		world.setBlock(i + 7, j + 7, k + 9, 0, 0, 2);
		world.setBlock(i + 7, j + 7, k + 11, Block.stoneBrick.blockID, this.pickStoneBrickType(rand), 2);
		world.setBlock(i + 7, j + 7, k + 12, 0, 0, 2);
		world.setBlock(i + 7, j + 7, k + 13, Block.stoneBrick.blockID, this.pickStoneBrickType(rand), 2);
		world.setBlock(i + 7, j + 8, k + 2, Block.stoneBrick.blockID, this.pickStoneBrickType(rand), 2);
		world.setBlock(i + 7, j + 8, k + 3, this.pickDungeonBlock(rand), 0, 2);
		world.setBlock(i + 7, j + 8, k + 4, 0, 0, 2);
		world.setBlock(i + 7, j + 8, k + 5, 0, 0, 2);
		world.setBlock(i + 7, j + 8, k + 6, 0, 0, 2);
		world.setBlock(i + 7, j + 8, k + 7, 0, 0, 2);
		world.setBlock(i + 7, j + 8, k + 8, 0, 0, 2);
		world.setBlock(i + 7, j + 8, k + 9, 0, 0, 2);
		world.setBlock(i + 7, j + 8, k + 11, Block.stoneBrick.blockID, this.pickStoneBrickType(rand), 2);
		world.setBlock(i + 7, j + 8, k + 12, 0, 0, 2);
		world.setBlock(i + 7, j + 8, k + 13, Block.stoneBrick.blockID, this.pickStoneBrickType(rand), 2);
		world.setBlock(i + 7, j + 9, k + 2, Block.stoneBrick.blockID, this.pickStoneBrickType(rand), 2);
		world.setBlock(i + 7, j + 9, k + 3, 0, 0, 2);
		world.setBlock(i + 7, j + 9, k + 4, 0, 0, 2);
		world.setBlock(i + 7, j + 9, k + 5, 0, 0, 2);
		world.setBlock(i + 7, j + 9, k + 6, 0, 0, 2);
		world.setBlock(i + 7, j + 9, k + 7, 0, 0, 2);
		world.setBlock(i + 7, j + 9, k + 8, 0, 0, 2);
		world.setBlock(i + 7, j + 9, k + 9, 0, 0, 2);
		world.setBlock(i + 7, j + 9, k + 11, Block.stoneBrick.blockID, this.pickStoneBrickType(rand), 2);
		world.setBlock(i + 7, j + 9, k + 12, 0, 0, 2);
		world.setBlock(i + 7, j + 9, k + 13, Block.stoneBrick.blockID, this.pickStoneBrickType(rand), 2);
		world.setBlock(i + 7, j + 10, k + 2, Block.stoneBrick.blockID, this.pickStoneBrickType(rand), 2);
		world.setBlock(i + 7, j + 10, k + 3, 0, 0, 2);
		world.setBlock(i + 7, j + 10, k + 4, 0, 0, 2);
		world.setBlock(i + 7, j + 10, k + 5, 0, 0, 2);
		world.setBlock(i + 7, j + 10, k + 6, 0, 0, 2);
		world.setBlock(i + 7, j + 10, k + 7, 0, 0, 2);
		world.setBlock(i + 7, j + 10, k + 8, 0, 0, 2);
		world.setBlock(i + 7, j + 10, k + 9, 0, 0, 2);
		world.setBlock(i + 7, j + 10, k + 11, Block.stoneBrick.blockID, this.pickStoneBrickType(rand), 2);
		world.setBlock(i + 7, j + 10, k + 12, 0, 0, 2);
		world.setBlock(i + 7, j + 10, k + 13, Block.stoneBrick.blockID, this.pickStoneBrickType(rand), 2);
		world.setBlock(i + 7, j + 11, k + 2, Block.stoneBrick.blockID, this.pickStoneBrickType(rand), 2);
		world.setBlock(i + 7, j + 11, k + 3, Block.wood.blockID, 0, 2);
		world.setBlock(i + 7, j + 11, k + 4, Block.wood.blockID, 0, 2);
		world.setBlock(i + 7, j + 11, k + 5, Block.planks.blockID, 1, 2);
		world.setBlock(i + 7, j + 11, k + 6, Block.wood.blockID, 0, 2);
		world.setBlock(i + 7, j + 11, k + 7, Block.planks.blockID, 1, 2);
		world.setBlock(i + 7, j + 11, k + 8, Block.planks.blockID, 1, 2);
		world.setBlock(i + 7, j + 11, k + 9, Block.wood.blockID, 0, 2);
		world.setBlock(i + 7, j + 11, k + 11, 0, 0, 2);
		world.setBlock(i + 7, j + 11, k + 12, Block.wood.blockID, 0, 2);
		world.setBlock(i + 7, j + 11, k + 13, Block.stoneBrick.blockID, this.pickStoneBrickType(rand), 2);
		world.setBlock(i + 7, j + 12, k + 3, Block.stoneBrick.blockID, this.pickStoneBrickType(rand), 2);
		world.setBlock(i + 7, j + 12, k + 5, 0, 0, 2);
		world.setBlock(i + 7, j + 12, k + 6, 0, 0, 2);
		world.setBlock(i + 7, j + 12, k + 7, 0, 0, 2);
		world.setBlock(i + 7, j + 12, k + 8, 0, 0, 2);
		world.setBlock(i + 7, j + 12, k + 9, 0, 0, 2);
		world.setBlock(i + 7, j + 12, k + 10, 0, 0, 2);
		world.setBlock(i + 7, j + 12, k + 11, 0, 0, 2);
		world.setBlock(i + 7, j + 12, k + 12, Block.stoneBrick.blockID, this.pickStoneBrickType(rand), 2);
		world.setBlock(i + 7, j + 13, k + 3, Block.stoneBrick.blockID, this.pickStoneBrickType(rand), 2);
		world.setBlock(i + 7, j + 13, k + 4, 0, 0, 2);
		world.setBlock(i + 7, j + 13, k + 5, 0, 0, 2);
		world.setBlock(i + 7, j + 13, k + 6, 0, 0, 2);
		world.setBlock(i + 7, j + 13, k + 7, 0, 0, 2);
		world.setBlock(i + 7, j + 13, k + 8, 0, 0, 2);
		world.setBlock(i + 7, j + 13, k + 9, 0, 0, 2);
		world.setBlock(i + 7, j + 13, k + 10, 0, 0, 2);
		world.setBlock(i + 7, j + 13, k + 11, 0, 0, 2);
		world.setBlock(i + 7, j + 13, k + 12, Block.stoneBrick.blockID, this.pickStoneBrickType(rand), 2);
		world.setBlock(i + 7, j + 14, k + 3, Block.stoneBrick.blockID, this.pickStoneBrickType(rand), 2);
		world.setBlock(i + 7, j + 14, k + 4, 0, 0, 2);
		world.setBlock(i + 7, j + 14, k + 5, 0, 0, 2);
		world.setBlock(i + 7, j + 14, k + 6, 0, 0, 2);
		world.setBlock(i + 7, j + 14, k + 7, 0, 0, 2);
		world.setBlock(i + 7, j + 14, k + 8, 0, 0, 2);
		world.setBlock(i + 7, j + 14, k + 9, 0, 0, 2);
		world.setBlock(i + 7, j + 14, k + 10, 0, 0, 2);
		world.setBlock(i + 7, j + 14, k + 11, 0, 0, 2);
		world.setBlock(i + 7, j + 14, k + 12, Block.stoneBrick.blockID, this.pickStoneBrickType(rand), 2);
		world.setBlock(i + 7, j + 15, k + 3, Block.stoneBrick.blockID, this.pickStoneBrickType(rand), 2);
		world.setBlock(i + 7, j + 15, k + 4, 0, 0, 2);
		world.setBlock(i + 7, j + 15, k + 5, 0, 0, 2);
		world.setBlock(i + 7, j + 15, k + 6, 0, 0, 2);
		world.setBlock(i + 7, j + 15, k + 7, 0, 0, 2);
		world.setBlock(i + 7, j + 15, k + 8, 0, 0, 2);
		world.setBlock(i + 7, j + 15, k + 9, 0, 0, 2);
		world.setBlock(i + 7, j + 15, k + 10, 0, 0, 2);
		world.setBlock(i + 7, j + 15, k + 11, 0, 0, 2);
		world.setBlock(i + 7, j + 15, k + 12, Block.stoneBrick.blockID, this.pickStoneBrickType(rand), 2);
		world.setBlock(i + 7, j + 16, k + 3, Block.stoneBrick.blockID, this.pickStoneBrickType(rand), 2);
		world.setBlock(i + 7, j + 16, k + 4, 0, 0, 2);
		world.setBlock(i + 7, j + 16, k + 5, 0, 0, 2);
		world.setBlock(i + 7, j + 16, k + 6, 0, 0, 2);
		world.setBlock(i + 7, j + 16, k + 7, 0, 0, 2);
		world.setBlock(i + 7, j + 16, k + 8, Block.glowStone.blockID, 0, 2);
		world.setBlock(i + 7, j + 16, k + 9, 0, 0, 2);
		world.setBlock(i + 7, j + 16, k + 10, 0, 0, 2);
		world.setBlock(i + 7, j + 16, k + 11, 0, 0, 2);
		world.setBlock(i + 7, j + 16, k + 12, Block.stoneBrick.blockID, this.pickStoneBrickType(rand), 2);
		world.setBlock(i + 7, j + 17, k + 2, Block.cloth.blockID, 11, 2);
		world.setBlock(i + 7, j + 17, k + 3, Block.stoneBrick.blockID, this.pickStoneBrickType(rand), 2);
		world.setBlock(i + 7, j + 17, k + 4, 0, 0, 2);
		world.setBlock(i + 7, j + 17, k + 5, 0, 0, 2);
		world.setBlock(i + 7, j + 17, k + 6, 0, 0, 2);
		world.setBlock(i + 7, j + 17, k + 7, 0, 0, 2);
		world.setBlock(i + 7, j + 17, k + 8, Block.fence.blockID, 0, 2);
		world.setBlock(i + 7, j + 17, k + 9, 0, 0, 2);
		world.setBlock(i + 7, j + 17, k + 10, 0, 0, 2);
		world.setBlock(i + 7, j + 17, k + 11, 0, 0, 2);
		world.setBlock(i + 7, j + 17, k + 12, Block.stoneBrick.blockID, this.pickStoneBrickType(rand), 2);
		world.setBlock(i + 7, j + 17, k + 13, Block.cloth.blockID, 11, 2);
		world.setBlock(i + 7, j + 18, k + 3, Block.cloth.blockID, 11, 2);
		world.setBlock(i + 7, j + 18, k + 4, 0, 0, 2);
		world.setBlock(i + 7, j + 18, k + 5, 0, 0, 2);
		world.setBlock(i + 7, j + 18, k + 6, 0, 0, 2);
		world.setBlock(i + 7, j + 18, k + 7, 0, 0, 2);
		world.setBlock(i + 7, j + 18, k + 8, Block.fence.blockID, 0, 2);
		world.setBlock(i + 7, j + 18, k + 9, 0, 0, 2);
		world.setBlock(i + 7, j + 18, k + 10, 0, 0, 2);
		world.setBlock(i + 7, j + 18, k + 11, 0, 0, 2);
		world.setBlock(i + 7, j + 18, k + 12, Block.cloth.blockID, 11, 2);
		world.setBlock(i + 7, j + 19, k + 4, Block.cloth.blockID, 11, 2);
		world.setBlock(i + 7, j + 19, k + 5, Block.cloth.blockID, 11, 2);
		world.setBlock(i + 7, j + 19, k + 6, 0, 0, 2);
		world.setBlock(i + 7, j + 19, k + 7, 0, 0, 2);
		world.setBlock(i + 7, j + 19, k + 8, Block.fence.blockID, 0, 2);
		world.setBlock(i + 7, j + 19, k + 9, 0, 0, 2);
		world.setBlock(i + 7, j + 19, k + 10, Block.cloth.blockID, 11, 2);
		world.setBlock(i + 7, j + 19, k + 11, Block.cloth.blockID, 11, 2);
		world.setBlock(i + 7, j + 20, k + 6, Block.cloth.blockID, 11, 2);
		world.setBlock(i + 7, j + 20, k + 7, Block.cloth.blockID, 11, 2);
		world.setBlock(i + 7, j + 20, k + 8, Block.cloth.blockID, 11, 2);
		world.setBlock(i + 7, j + 20, k + 9, Block.cloth.blockID, 11, 2);
		world.setBlock(i + 8, j + 0, k + 1, Block.stoneBrick.blockID, this.pickStoneBrickType(rand), 2);
		world.setBlock(i + 8, j + 0, k + 2, Block.planks.blockID, 2, 2);
		world.setBlock(i + 8, j + 0, k + 3, Block.planks.blockID, 1, 2);
		world.setBlock(i + 8, j + 0, k + 4, Block.planks.blockID, 2, 2);
		world.setBlock(i + 8, j + 0, k + 5, Block.planks.blockID, 0, 2);
		world.setBlock(i + 8, j + 0, k + 6, Block.wood.blockID, 5, 2);
		world.setBlock(i + 8, j + 0, k + 7, Block.wood.blockID, 1, 2);
		world.setBlock(i + 8, j + 0, k + 8, Block.wood.blockID, 1, 2);
		world.setBlock(i + 8, j + 0, k + 9, Block.wood.blockID, 5, 2);
		world.setBlock(i + 8, j + 0, k + 10, Block.planks.blockID, 0, 2);
		world.setBlock(i + 8, j + 0, k + 11, Block.planks.blockID, 2, 2);
		world.setBlock(i + 8, j + 0, k + 12, Block.planks.blockID, 1, 2);
		world.setBlock(i + 8, j + 0, k + 13, Block.planks.blockID, 2, 2);
		world.setBlock(i + 8, j + 0, k + 14, Block.stoneBrick.blockID, this.pickStoneBrickType(rand), 2);
		world.setBlock(i + 8, j + 1, k + 1, Block.stoneBrick.blockID, this.pickStoneBrickType(rand), 2);
		world.setBlock(i + 8, j + 1, k + 2, Block.woodSingleSlab.blockID, 2, 2);
		world.setBlock(i + 8, j + 1, k + 3, 0, 0, 2);
		world.setBlock(i + 8, j + 1, k + 4, 0, 0, 2);
		world.setBlock(i + 8, j + 1, k + 5, Block.stairsWoodOak.blockID, 2, 2);
		world.setBlock(i + 8, j + 1, k + 6, Block.wood.blockID, 1, 2);
		world.setBlock(i + 8, j + 1, k + 7, Block.planks.blockID, 2, 2);
		world.setBlock(i + 8, j + 1, k + 8, Block.planks.blockID, 2, 2);
		world.setBlock(i + 8, j + 1, k + 9, Block.wood.blockID, 1, 2);
		world.setBlock(i + 8, j + 1, k + 10, Block.stairsWoodOak.blockID, 3, 2);
		world.setBlock(i + 8, j + 1, k + 11, 0, 0, 2);
		world.setBlock(i + 8, j + 1, k + 12, 0, 0, 2);
		world.setBlock(i + 8, j + 1, k + 13, Block.woodSingleSlab.blockID, 2, 2);
		world.setBlock(i + 8, j + 1, k + 14, Block.stoneBrick.blockID, this.pickStoneBrickType(rand), 2);
		world.setBlock(i + 8, j + 2, k + 1, Block.stoneBrick.blockID, this.pickStoneBrickType(rand), 2);
		world.setBlock(i + 8, j + 2, k + 2, Block.woodSingleSlab.blockID, 9, 2);
		world.setBlock(i + 8, j + 2, k + 3, 0, 0, 2);
		world.setBlock(i + 8, j + 2, k + 4, 0, 0, 2);
		world.setBlock(i + 8, j + 2, k + 5, 0, 0, 2);
		world.setBlock(i + 8, j + 2, k + 6, Block.stairsWoodOak.blockID, 2, 2);
		world.setBlock(i + 8, j + 2, k + 7, Block.planks.blockID, 2, 2);
		world.setBlock(i + 8, j + 2, k + 8, Block.planks.blockID, 2, 2);
		world.setBlock(i + 8, j + 2, k + 9, Block.stairsWoodOak.blockID, 3, 2);
		world.setBlock(i + 8, j + 2, k + 10, 0, 0, 2);
		world.setBlock(i + 8, j + 2, k + 11, 0, 0, 2);
		world.setBlock(i + 8, j + 2, k + 12, 0, 0, 2);
		world.setBlock(i + 8, j + 2, k + 13, Block.woodSingleSlab.blockID, 9, 2);
		world.setBlock(i + 8, j + 2, k + 14, Block.stoneBrick.blockID, this.pickStoneBrickType(rand), 2);
		world.setBlock(i + 8, j + 3, k + 1, Block.thinGlass.blockID, 0, 2);
		world.setBlock(i + 8, j + 3, k + 2, 0, 0, 2);
		world.setBlock(i + 8, j + 3, k + 3, 0, 0, 2);
		world.setBlock(i + 8, j + 3, k + 4, 0, 0, 2);
		world.setBlock(i + 8, j + 3, k + 5, 0, 0, 2);
		world.setBlock(i + 8, j + 3, k + 6, 0, 0, 2);
		world.setBlock(i + 8, j + 3, k + 7, 0, 0, 2);
		world.setBlock(i + 8, j + 3, k + 8, 0, 0, 2);
		world.setBlock(i + 8, j + 3, k + 9, 0, 0, 2);
		world.setBlock(i + 8, j + 3, k + 10, 0, 0, 2);
		world.setBlock(i + 8, j + 3, k + 11, 0, 0, 2);
		world.setBlock(i + 8, j + 3, k + 12, 0, 0, 2);
		world.setBlock(i + 8, j + 3, k + 13, 0, 0, 2);
		world.setBlock(i + 8, j + 3, k + 14, Block.thinGlass.blockID, 0, 2);
		world.setBlock(i + 8, j + 4, k + 1, Block.thinGlass.blockID, 0, 2);
		world.setBlock(i + 8, j + 4, k + 2, 0, 0, 2);
		world.setBlock(i + 8, j + 4, k + 3, 0, 0, 2);
		world.setBlock(i + 8, j + 4, k + 4, 0, 0, 2);
		world.setBlock(i + 8, j + 4, k + 5, 0, 0, 2);
		world.setBlock(i + 8, j + 4, k + 7, 0, 0, 2);
		world.setBlock(i + 8, j + 4, k + 8, 0, 0, 2);
		world.setBlock(i + 8, j + 4, k + 10, 0, 0, 2);
		world.setBlock(i + 8, j + 4, k + 11, 0, 0, 2);
		world.setBlock(i + 8, j + 4, k + 12, 0, 0, 2);
		world.setBlock(i + 8, j + 4, k + 13, 0, 0, 2);
		world.setBlock(i + 8, j + 4, k + 14, Block.thinGlass.blockID, 0, 2);
		world.setBlock(i + 8, j + 5, k + 0, Block.stairsBrick.blockID, 2, 2);
		world.setBlock(i + 8, j + 5, k + 1, Block.stoneBrick.blockID, this.pickStoneBrickType(rand), 2);
		world.setBlock(i + 8, j + 5, k + 2, 0, 0, 2);
		world.setBlock(i + 8, j + 5, k + 3, 0, 0, 2);
		world.setBlock(i + 8, j + 5, k + 4, 0, 0, 2);
		world.setBlock(i + 8, j + 5, k + 5, Block.wood.blockID, 5, 2);
		world.setBlock(i + 8, j + 5, k + 7, 0, 0, 2);
		world.setBlock(i + 8, j + 5, k + 8, 0, 0, 2);
		world.setBlock(i + 8, j + 5, k + 10, Block.wood.blockID, 5, 2);
		world.setBlock(i + 8, j + 5, k + 11, 0, 0, 2);
		world.setBlock(i + 8, j + 5, k + 12, 0, 0, 2);
		world.setBlock(i + 8, j + 5, k + 13, 0, 0, 2);
		world.setBlock(i + 8, j + 5, k + 14, Block.stoneBrick.blockID, this.pickStoneBrickType(rand), 2);
		world.setBlock(i + 8, j + 5, k + 15, Block.stairsBrick.blockID, 3, 2);
		world.setBlock(i + 8, j + 6, k + 1, Block.stairsBrick.blockID, 2, 2);
		world.setBlock(i + 8, j + 6, k + 2, Block.stoneBrick.blockID, this.pickStoneBrickType(rand), 2);
		world.setBlock(i + 8, j + 6, k + 3, Block.stoneBrick.blockID, this.pickStoneBrickType(rand), 2);
		world.setBlock(i + 8, j + 6, k + 4, this.pickDungeonBlock(rand), 0, 2);
		world.setBlock(i + 8, j + 6, k + 5, this.pickDungeonBlock(rand), 0, 2);
		world.setBlock(i + 8, j + 6, k + 7, Block.woodSingleSlab.blockID, 9, 2);
		world.setBlock(i + 8, j + 6, k + 8, Block.woodSingleSlab.blockID, 9, 2);
		world.setBlock(i + 8, j + 6, k + 10, Block.stoneBrick.blockID, this.pickStoneBrickType(rand), 2);
		world.setBlock(i + 8, j + 6, k + 11, this.pickDungeonBlock(rand), 0, 2);
		world.setBlock(i + 8, j + 6, k + 12, this.pickDungeonBlock(rand), 0, 2);
		world.setBlock(i + 8, j + 6, k + 13, Block.stoneBrick.blockID, this.pickStoneBrickType(rand), 2);
		world.setBlock(i + 8, j + 6, k + 14, Block.stairsBrick.blockID, 3, 2);
		world.setBlock(i + 8, j + 7, k + 2, Block.stoneBrick.blockID, this.pickStoneBrickType(rand), 2);
		world.setBlock(i + 8, j + 7, k + 3, 0, 0, 2);
		world.setBlock(i + 8, j + 7, k + 4, 0, 0, 2);
		world.setBlock(i + 8, j + 7, k + 5, 0, 0, 2);
		world.setBlock(i + 8, j + 7, k + 7, Block.stoneSingleSlab.blockID, 0, 2);
		world.setBlock(i + 8, j + 7, k + 8, Block.stoneSingleSlab.blockID, 0, 2);
		world.setBlock(i + 8, j + 7, k + 10, 0, 0, 2);
		world.setBlock(i + 8, j + 7, k + 11, 0, 0, 2);
		world.setBlock(i + 8, j + 7, k + 12, 0, 0, 2);
		world.setBlock(i + 8, j + 7, k + 13, Block.stoneBrick.blockID, this.pickStoneBrickType(rand), 2);
		world.setBlock(i + 8, j + 8, k + 2, Block.netherrack.blockID, 0, 2);
		world.setBlock(i + 8, j + 8, k + 3, 0, 0, 2);
		world.setBlock(i + 8, j + 8, k + 4, 0, 0, 2);
		world.setBlock(i + 8, j + 8, k + 5, 0, 0, 2);
		world.setBlock(i + 8, j + 8, k + 6, 0, 0, 2);
		world.setBlock(i + 8, j + 8, k + 7, 0, 0, 2);
		world.setBlock(i + 8, j + 8, k + 8, 0, 0, 2);
		world.setBlock(i + 8, j + 8, k + 9, 0, 0, 2);
		world.setBlock(i + 8, j + 8, k + 10, 0, 0, 2);
		world.setBlock(i + 8, j + 8, k + 11, 0, 0, 2);
		world.setBlock(i + 8, j + 8, k + 12, Block.stoneBrick.blockID, this.pickStoneBrickType(rand), 2);
		world.setBlock(i + 8, j + 8, k + 13, Block.netherrack.blockID, 0, 2);
		world.setBlock(i + 8, j + 9, k + 2, Block.netherrack.blockID, 0, 2);
		world.setBlock(i + 8, j + 9, k + 3, 0, 0, 2);
		world.setBlock(i + 8, j + 9, k + 4, 0, 0, 2);
		world.setBlock(i + 8, j + 9, k + 5, 0, 0, 2);
		world.setBlock(i + 8, j + 9, k + 6, 0, 0, 2);
		world.setBlock(i + 8, j + 9, k + 7, 0, 0, 2);
		world.setBlock(i + 8, j + 9, k + 8, 0, 0, 2);
		world.setBlock(i + 8, j + 9, k + 9, 0, 0, 2);
		world.setBlock(i + 8, j + 9, k + 10, 0, 0, 2);
		world.setBlock(i + 8, j + 9, k + 11, 0, 0, 2);
		world.setBlock(i + 8, j + 9, k + 12, 0, 0, 2);
		world.setBlock(i + 8, j + 9, k + 13, Block.netherrack.blockID, 0, 2);
		world.setBlock(i + 8, j + 10, k + 2, Block.stoneBrick.blockID, this.pickStoneBrickType(rand), 2);
		world.setBlock(i + 8, j + 10, k + 3, this.pickDungeonBlock(rand), 0, 2);
		world.setBlock(i + 8, j + 10, k + 4, 0, 0, 2);
		world.setBlock(i + 8, j + 10, k + 5, 0, 0, 2);
		world.setBlock(i + 8, j + 10, k + 6, 0, 0, 2);
		world.setBlock(i + 8, j + 10, k + 7, 0, 0, 2);
		world.setBlock(i + 8, j + 10, k + 8, 0, 0, 2);
		world.setBlock(i + 8, j + 10, k + 9, 0, 0, 2);
		world.setBlock(i + 8, j + 10, k + 10, 0, 0, 2);
		world.setBlock(i + 8, j + 10, k + 11, 0, 0, 2);
		world.setBlock(i + 8, j + 10, k + 12, 0, 0, 2);
		world.setBlock(i + 8, j + 10, k + 13, Block.stoneBrick.blockID, this.pickStoneBrickType(rand), 2);
		world.setBlock(i + 8, j + 11, k + 2, Block.stoneBrick.blockID, this.pickStoneBrickType(rand), 2);
		world.setBlock(i + 8, j + 11, k + 3, Block.wood.blockID, 0, 2);
		world.setBlock(i + 8, j + 11, k + 4, Block.planks.blockID, 1, 2);
		world.setBlock(i + 8, j + 11, k + 5, Block.wood.blockID, 0, 2);
		world.setBlock(i + 8, j + 11, k + 6, Block.planks.blockID, 1, 2);
		world.setBlock(i + 8, j + 11, k + 7, Block.wood.blockID, 0, 2);
		world.setBlock(i + 8, j + 11, k + 8, Block.wood.blockID, 0, 2);
		world.setBlock(i + 8, j + 11, k + 9, Block.planks.blockID, 1, 2);
		world.setBlock(i + 8, j + 11, k + 10, Block.wood.blockID, 0, 2);
		world.setBlock(i + 8, j + 11, k + 11, Block.planks.blockID, 1, 2);
		world.setBlock(i + 8, j + 11, k + 12, Block.wood.blockID, 0, 2);
		world.setBlock(i + 8, j + 11, k + 13, Block.stoneBrick.blockID, this.pickStoneBrickType(rand), 2);
		world.setBlock(i + 8, j + 12, k + 3, Block.stoneBrick.blockID, this.pickStoneBrickType(rand), 2);
		world.setBlock(i + 8, j + 12, k + 5, 0, 0, 2);
		world.setBlock(i + 8, j + 12, k + 6, Block.stairsWoodOak.blockID, 7, 2);
		world.setBlock(i + 8, j + 12, k + 9, 0, 0, 2);
		world.setBlock(i + 8, j + 12, k + 10, 0, 0, 2);
		world.setBlock(i + 8, j + 12, k + 11, Block.blockSteel.blockID, 0, 2);
		world.setBlock(i + 8, j + 12, k + 12, Block.stoneBrick.blockID, this.pickStoneBrickType(rand), 2);
		world.setBlock(i + 8, j + 13, k + 3, Block.thinGlass.blockID, 0, 2);
		world.setBlock(i + 8, j + 13, k + 4, 0, 0, 2);
		world.setBlock(i + 8, j + 13, k + 5, 0, 0, 2);
		world.setBlock(i + 8, j + 13, k + 6, 0, 0, 2);
		world.setBlock(i + 8, j + 13, k + 7, 0, 0, 2);
		world.setBlock(i + 8, j + 13, k + 8, 0, 0, 2);
		world.setBlock(i + 8, j + 13, k + 9, 0, 0, 2);
		world.setBlock(i + 8, j + 13, k + 10, 0, 0, 2);
		world.setBlock(i + 8, j + 13, k + 11, 0, 0, 2);
		world.setBlock(i + 8, j + 13, k + 12, Block.stoneBrick.blockID, this.pickStoneBrickType(rand), 2);
		world.setBlock(i + 8, j + 14, k + 3, Block.thinGlass.blockID, 0, 2);
		world.setBlock(i + 8, j + 14, k + 4, 0, 0, 2);
		world.setBlock(i + 8, j + 14, k + 5, 0, 0, 2);
		world.setBlock(i + 8, j + 14, k + 6, 0, 0, 2);
		world.setBlock(i + 8, j + 14, k + 7, 0, 0, 2);
		world.setBlock(i + 8, j + 14, k + 8, 0, 0, 2);
		world.setBlock(i + 8, j + 14, k + 9, 0, 0, 2);
		world.setBlock(i + 8, j + 14, k + 10, 0, 0, 2);
		world.setBlock(i + 8, j + 14, k + 11, 0, 0, 2);
		world.setBlock(i + 8, j + 14, k + 12, Block.stoneBrick.blockID, this.pickStoneBrickType(rand), 2);
		world.setBlock(i + 8, j + 15, k + 3, Block.stoneBrick.blockID, this.pickStoneBrickType(rand), 2);
		world.setBlock(i + 8, j + 15, k + 4, 0, 0, 2);
		world.setBlock(i + 8, j + 15, k + 5, 0, 0, 2);
		world.setBlock(i + 8, j + 15, k + 6, 0, 0, 2);
		world.setBlock(i + 8, j + 15, k + 7, 0, 0, 2);
		world.setBlock(i + 8, j + 15, k + 8, 0, 0, 2);
		world.setBlock(i + 8, j + 15, k + 9, 0, 0, 2);
		world.setBlock(i + 8, j + 15, k + 10, 0, 0, 2);
		world.setBlock(i + 8, j + 15, k + 11, 0, 0, 2);
		world.setBlock(i + 8, j + 15, k + 12, Block.stoneBrick.blockID, this.pickStoneBrickType(rand), 2);
		world.setBlock(i + 8, j + 16, k + 3, Block.stoneBrick.blockID, this.pickStoneBrickType(rand), 2);
		world.setBlock(i + 8, j + 16, k + 4, 0, 0, 2);
		world.setBlock(i + 8, j + 16, k + 5, 0, 0, 2);
		world.setBlock(i + 8, j + 16, k + 6, 0, 0, 2);
		world.setBlock(i + 8, j + 16, k + 7, 0, 0, 2);
		world.setBlock(i + 8, j + 16, k + 8, 0, 0, 2);
		world.setBlock(i + 8, j + 16, k + 9, 0, 0, 2);
		world.setBlock(i + 8, j + 16, k + 10, 0, 0, 2);
		world.setBlock(i + 8, j + 16, k + 11, 0, 0, 2);
		world.setBlock(i + 8, j + 16, k + 12, Block.stoneBrick.blockID, this.pickStoneBrickType(rand), 2);
		world.setBlock(i + 8, j + 17, k + 2, Block.cloth.blockID, 11, 2);
		world.setBlock(i + 8, j + 17, k + 3, Block.stoneBrick.blockID, this.pickStoneBrickType(rand), 2);
		world.setBlock(i + 8, j + 17, k + 4, 0, 0, 2);
		world.setBlock(i + 8, j + 17, k + 5, 0, 0, 2);
		world.setBlock(i + 8, j + 17, k + 6, 0, 0, 2);
		world.setBlock(i + 8, j + 17, k + 7, 0, 0, 2);
		world.setBlock(i + 8, j + 17, k + 8, 0, 0, 2);
		world.setBlock(i + 8, j + 17, k + 9, 0, 0, 2);
		world.setBlock(i + 8, j + 17, k + 10, 0, 0, 2);
		world.setBlock(i + 8, j + 17, k + 11, 0, 0, 2);
		world.setBlock(i + 8, j + 17, k + 12, Block.stoneBrick.blockID, this.pickStoneBrickType(rand), 2);
		world.setBlock(i + 8, j + 17, k + 13, Block.cloth.blockID, 11, 2);
		world.setBlock(i + 8, j + 18, k + 3, Block.cloth.blockID, 11, 2);
		world.setBlock(i + 8, j + 18, k + 4, 0, 0, 2);
		world.setBlock(i + 8, j + 18, k + 5, 0, 0, 2);
		world.setBlock(i + 8, j + 18, k + 6, 0, 0, 2);
		world.setBlock(i + 8, j + 18, k + 7, 0, 0, 2);
		world.setBlock(i + 8, j + 18, k + 8, 0, 0, 2);
		world.setBlock(i + 8, j + 18, k + 9, 0, 0, 2);
		world.setBlock(i + 8, j + 18, k + 10, 0, 0, 2);
		world.setBlock(i + 8, j + 18, k + 11, 0, 0, 2);
		world.setBlock(i + 8, j + 18, k + 12, Block.cloth.blockID, 11, 2);
		world.setBlock(i + 8, j + 19, k + 4, Block.cloth.blockID, 11, 2);
		world.setBlock(i + 8, j + 19, k + 5, 0, 0, 2);
		world.setBlock(i + 8, j + 19, k + 6, 0, 0, 2);
		world.setBlock(i + 8, j + 19, k + 7, 0, 0, 2);
		world.setBlock(i + 8, j + 19, k + 8, 0, 0, 2);
		world.setBlock(i + 8, j + 19, k + 9, 0, 0, 2);
		world.setBlock(i + 8, j + 19, k + 10, 0, 0, 2);
		world.setBlock(i + 8, j + 19, k + 11, Block.cloth.blockID, 11, 2);
		world.setBlock(i + 8, j + 20, k + 5, Block.cloth.blockID, 11, 2);
		world.setBlock(i + 8, j + 20, k + 6, Block.cloth.blockID, 11, 2);
		world.setBlock(i + 8, j + 20, k + 7, Block.ice.blockID, 0, 2);
		world.setBlock(i + 8, j + 20, k + 8, Block.ice.blockID, 0, 2);
		world.setBlock(i + 8, j + 20, k + 9, Block.cloth.blockID, 11, 2);
		world.setBlock(i + 8, j + 20, k + 10, Block.cloth.blockID, 11, 2);
		world.setBlock(i + 8, j + 21, k + 7, Block.cloth.blockID, 11, 2);
		world.setBlock(i + 8, j + 21, k + 8, Block.cloth.blockID, 11, 2);
		world.setBlock(i + 9, j + 0, k + 1, Block.stoneBrick.blockID, this.pickStoneBrickType(rand), 2);
		world.setBlock(i + 9, j + 0, k + 2, Block.planks.blockID, 2, 2);
		world.setBlock(i + 9, j + 0, k + 3, Block.planks.blockID, 1, 2);
		world.setBlock(i + 9, j + 0, k + 4, Block.planks.blockID, 2, 2);
		world.setBlock(i + 9, j + 0, k + 5, Block.planks.blockID, 0, 2);
		world.setBlock(i + 9, j + 0, k + 6, Block.wood.blockID, 5, 2);
		world.setBlock(i + 9, j + 0, k + 7, Block.wood.blockID, 1, 2);
		world.setBlock(i + 9, j + 0, k + 8, Block.wood.blockID, 1, 2);
		world.setBlock(i + 9, j + 0, k + 9, Block.wood.blockID, 5, 2);
		world.setBlock(i + 9, j + 0, k + 10, Block.planks.blockID, 0, 2);
		world.setBlock(i + 9, j + 0, k + 11, Block.planks.blockID, 2, 2);
		world.setBlock(i + 9, j + 0, k + 12, Block.planks.blockID, 1, 2);
		world.setBlock(i + 9, j + 0, k + 13, Block.planks.blockID, 2, 2);
		world.setBlock(i + 9, j + 0, k + 14, Block.stoneBrick.blockID, this.pickStoneBrickType(rand), 2);
		world.setBlock(i + 9, j + 1, k + 1, Block.stoneBrick.blockID, this.pickStoneBrickType(rand), 2);
		world.setBlock(i + 9, j + 1, k + 2, Block.woodSingleSlab.blockID, 2, 2);
		world.setBlock(i + 9, j + 1, k + 3, 0, 0, 2);
		world.setBlock(i + 9, j + 1, k + 4, 0, 0, 2);
		world.setBlock(i + 9, j + 1, k + 5, Block.stairsWoodOak.blockID, 2, 2);
		world.setBlock(i + 9, j + 1, k + 6, Block.wood.blockID, 1, 2);
		world.setBlock(i + 9, j + 1, k + 7, Block.planks.blockID, 2, 2);
		world.setBlock(i + 9, j + 1, k + 8, Block.planks.blockID, 2, 2);
		world.setBlock(i + 9, j + 1, k + 9, Block.wood.blockID, 1, 2);
		world.setBlock(i + 9, j + 1, k + 10, Block.stairsWoodOak.blockID, 3, 2);
		world.setBlock(i + 9, j + 1, k + 11, 0, 0, 2);
		world.setBlock(i + 9, j + 1, k + 12, 0, 0, 2);
		world.setBlock(i + 9, j + 1, k + 13, Block.woodSingleSlab.blockID, 2, 2);
		world.setBlock(i + 9, j + 1, k + 14, Block.stoneBrick.blockID, this.pickStoneBrickType(rand), 2);
		world.setBlock(i + 9, j + 2, k + 1, Block.stoneBrick.blockID, this.pickStoneBrickType(rand), 2);
		world.setBlock(i + 9, j + 2, k + 2, Block.woodSingleSlab.blockID, 9, 2);
		world.setBlock(i + 9, j + 2, k + 3, 0, 0, 2);
		world.setBlock(i + 9, j + 2, k + 4, 0, 0, 2);
		world.setBlock(i + 9, j + 2, k + 5, 0, 0, 2);
		world.setBlock(i + 9, j + 2, k + 6, Block.stairsWoodOak.blockID, 2, 2);
		world.setBlock(i + 9, j + 2, k + 7, Block.planks.blockID, 2, 2);
		world.setBlock(i + 9, j + 2, k + 8, Block.planks.blockID, 2, 2);
		world.setBlock(i + 9, j + 2, k + 9, Block.stairsWoodOak.blockID, 3, 2);
		world.setBlock(i + 9, j + 2, k + 10, 0, 0, 2);
		world.setBlock(i + 9, j + 2, k + 11, 0, 0, 2);
		world.setBlock(i + 9, j + 2, k + 12, 0, 0, 2);
		world.setBlock(i + 9, j + 2, k + 13, Block.woodSingleSlab.blockID, 9, 2);
		world.setBlock(i + 9, j + 2, k + 14, Block.stoneBrick.blockID, this.pickStoneBrickType(rand), 2);
		world.setBlock(i + 9, j + 3, k + 1, Block.thinGlass.blockID, 0, 2);
		world.setBlock(i + 9, j + 3, k + 2, 0, 0, 2);
		world.setBlock(i + 9, j + 3, k + 3, 0, 0, 2);
		world.setBlock(i + 9, j + 3, k + 4, 0, 0, 2);
		world.setBlock(i + 9, j + 3, k + 5, 0, 0, 2);
		world.setBlock(i + 9, j + 3, k + 6, 0, 0, 2);
		world.setBlock(i + 9, j + 3, k + 7, 0, 0, 2);
		world.setBlock(i + 9, j + 3, k + 8, 0, 0, 2);
		world.setBlock(i + 9, j + 3, k + 9, 0, 0, 2);
		world.setBlock(i + 9, j + 3, k + 10, 0, 0, 2);
		world.setBlock(i + 9, j + 3, k + 11, 0, 0, 2);
		world.setBlock(i + 9, j + 3, k + 12, 0, 0, 2);
		world.setBlock(i + 9, j + 3, k + 13, 0, 0, 2);
		world.setBlock(i + 9, j + 3, k + 14, Block.thinGlass.blockID, 0, 2);
		world.setBlock(i + 9, j + 4, k + 1, Block.thinGlass.blockID, 0, 2);
		world.setBlock(i + 9, j + 4, k + 2, 0, 0, 2);
		world.setBlock(i + 9, j + 4, k + 3, 0, 0, 2);
		world.setBlock(i + 9, j + 4, k + 4, 0, 0, 2);
		world.setBlock(i + 9, j + 4, k + 5, 0, 0, 2);
		world.setBlock(i + 9, j + 4, k + 7, 0, 0, 2);
		world.setBlock(i + 9, j + 4, k + 8, 0, 0, 2);
		world.setBlock(i + 9, j + 4, k + 10, 0, 0, 2);
		world.setBlock(i + 9, j + 4, k + 11, 0, 0, 2);
		world.setBlock(i + 9, j + 4, k + 12, 0, 0, 2);
		world.setBlock(i + 9, j + 4, k + 13, 0, 0, 2);
		world.setBlock(i + 9, j + 4, k + 14, Block.thinGlass.blockID, 0, 2);
		world.setBlock(i + 9, j + 5, k + 0, Block.stairsBrick.blockID, 2, 2);
		world.setBlock(i + 9, j + 5, k + 1, Block.stoneBrick.blockID, this.pickStoneBrickType(rand), 2);
		world.setBlock(i + 9, j + 5, k + 2, 0, 0, 2);
		world.setBlock(i + 9, j + 5, k + 3, 0, 0, 2);
		world.setBlock(i + 9, j + 5, k + 4, 0, 0, 2);
		world.setBlock(i + 9, j + 5, k + 5, Block.wood.blockID, 5, 2);
		world.setBlock(i + 9, j + 5, k + 7, 0, 0, 2);
		world.setBlock(i + 9, j + 5, k + 8, 0, 0, 2);
		world.setBlock(i + 9, j + 5, k + 10, Block.wood.blockID, 5, 2);
		world.setBlock(i + 9, j + 5, k + 11, 0, 0, 2);
		world.setBlock(i + 9, j + 5, k + 12, 0, 0, 2);
		world.setBlock(i + 9, j + 5, k + 13, 0, 0, 2);
		world.setBlock(i + 9, j + 5, k + 14, Block.stoneBrick.blockID, this.pickStoneBrickType(rand), 2);
		world.setBlock(i + 9, j + 5, k + 15, Block.stairsBrick.blockID, 3, 2);
		world.setBlock(i + 9, j + 6, k + 1, Block.stairsBrick.blockID, 2, 2);
		world.setBlock(i + 9, j + 6, k + 2, Block.stoneBrick.blockID, this.pickStoneBrickType(rand), 2);
		world.setBlock(i + 9, j + 6, k + 3, Block.stoneBrick.blockID, this.pickStoneBrickType(rand), 2);
		world.setBlock(i + 9, j + 6, k + 4, this.pickDungeonBlock(rand), 0, 2);
		world.setBlock(i + 9, j + 6, k + 5, this.pickDungeonBlock(rand), 0, 2);
		world.setBlock(i + 9, j + 6, k + 7, Block.woodSingleSlab.blockID, 9, 2);
		world.setBlock(i + 9, j + 6, k + 8, Block.woodSingleSlab.blockID, 9, 2);
		world.setBlock(i + 9, j + 6, k + 10, this.pickDungeonBlock(rand), 0, 2);
		world.setBlock(i + 9, j + 6, k + 11, this.pickDungeonBlock(rand), 0, 2);
		world.setBlock(i + 9, j + 6, k + 12, this.pickDungeonBlock(rand), 0, 2);
		world.setBlock(i + 9, j + 6, k + 13, Block.stoneBrick.blockID, this.pickStoneBrickType(rand), 2);
		world.setBlock(i + 9, j + 6, k + 14, Block.stairsBrick.blockID, 3, 2);
		world.setBlock(i + 9, j + 7, k + 2, Block.stoneBrick.blockID, this.pickStoneBrickType(rand), 2);
		world.setBlock(i + 9, j + 7, k + 3, 0, 0, 2);
		world.setBlock(i + 9, j + 7, k + 4, Block.stoneBrick.blockID, this.pickStoneBrickType(rand), 2);
		world.setBlock(i + 9, j + 7, k + 5, 0, 0, 2);
		world.setBlock(i + 9, j + 7, k + 7, Block.stoneSingleSlab.blockID, 0, 2);
		world.setBlock(i + 9, j + 7, k + 8, Block.stoneSingleSlab.blockID, 0, 2);
		world.setBlock(i + 9, j + 7, k + 10, 0, 0, 2);
		world.setBlock(i + 9, j + 7, k + 11, 0, 0, 2);
		world.setBlock(i + 9, j + 7, k + 12, this.pickDungeonBlock(rand), 0, 2);
		world.setBlock(i + 9, j + 7, k + 13, Block.stoneBrick.blockID, this.pickStoneBrickType(rand), 2);
		world.setBlock(i + 9, j + 8, k + 2, Block.netherrack.blockID, 0, 2);
		world.setBlock(i + 9, j + 8, k + 3, 0, 0, 2);
		world.setBlock(i + 9, j + 8, k + 4, 0, 0, 2);
		world.setBlock(i + 9, j + 8, k + 5, 0, 0, 2);
		world.setBlock(i + 9, j + 8, k + 6, 0, 0, 2);
		world.setBlock(i + 9, j + 8, k + 7, 0, 0, 2);
		world.setBlock(i + 9, j + 8, k + 8, 0, 0, 2);
		world.setBlock(i + 9, j + 8, k + 9, 0, 0, 2);
		world.setBlock(i + 9, j + 8, k + 10, 0, 0, 2);
		world.setBlock(i + 9, j + 8, k + 11, 0, 0, 2);
		world.setBlock(i + 9, j + 8, k + 12, 0, 0, 2);
		world.setBlock(i + 9, j + 8, k + 13, Block.netherrack.blockID, 0, 2);
		world.setBlock(i + 9, j + 9, k + 2, Block.netherrack.blockID, 0, 2);
		world.setBlock(i + 9, j + 9, k + 3, 0, 0, 2);
		world.setBlock(i + 9, j + 9, k + 4, 0, 0, 2);
		world.setBlock(i + 9, j + 9, k + 5, 0, 0, 2);
		world.setBlock(i + 9, j + 9, k + 6, 0, 0, 2);
		world.setBlock(i + 9, j + 9, k + 7, 0, 0, 2);
		world.setBlock(i + 9, j + 9, k + 8, 0, 0, 2);
		world.setBlock(i + 9, j + 9, k + 9, 0, 0, 2);
		world.setBlock(i + 9, j + 9, k + 10, 0, 0, 2);
		world.setBlock(i + 9, j + 9, k + 11, 0, 0, 2);
		world.setBlock(i + 9, j + 9, k + 12, this.pickDungeonBlock(rand), 0, 2);
		world.setBlock(i + 9, j + 9, k + 13, Block.netherrack.blockID, 0, 2);
		world.setBlock(i + 9, j + 10, k + 2, Block.stoneBrick.blockID, this.pickStoneBrickType(rand), 2);
		world.setBlock(i + 9, j + 10, k + 3, 0, 0, 2);
		world.setBlock(i + 9, j + 10, k + 4, 0, 0, 2);
		world.setBlock(i + 9, j + 10, k + 5, 0, 0, 2);
		world.setBlock(i + 9, j + 10, k + 6, 0, 0, 2);
		world.setBlock(i + 9, j + 10, k + 7, 0, 0, 2);
		world.setBlock(i + 9, j + 10, k + 8, 0, 0, 2);
		world.setBlock(i + 9, j + 10, k + 9, 0, 0, 2);
		world.setBlock(i + 9, j + 10, k + 10, 0, 0, 2);
		world.setBlock(i + 9, j + 10, k + 11, 0, 0, 2);
		world.setBlock(i + 9, j + 10, k + 12, Block.stoneBrick.blockID, this.pickStoneBrickType(rand), 2);
		world.setBlock(i + 9, j + 10, k + 13, Block.stoneBrick.blockID, this.pickStoneBrickType(rand), 2);
		world.setBlock(i + 9, j + 11, k + 2, Block.stoneBrick.blockID, this.pickStoneBrickType(rand), 2);
		world.setBlock(i + 9, j + 11, k + 3, Block.wood.blockID, 0, 2);
		world.setBlock(i + 9, j + 11, k + 4, Block.planks.blockID, 1, 2);
		world.setBlock(i + 9, j + 11, k + 5, Block.wood.blockID, 0, 2);
		world.setBlock(i + 9, j + 11, k + 6, Block.planks.blockID, 1, 2);
		world.setBlock(i + 9, j + 11, k + 7, Block.wood.blockID, 0, 2);
		world.setBlock(i + 9, j + 11, k + 8, Block.wood.blockID, 0, 2);
		world.setBlock(i + 9, j + 11, k + 9, Block.planks.blockID, 1, 2);
		world.setBlock(i + 9, j + 11, k + 10, Block.wood.blockID, 0, 2);
		world.setBlock(i + 9, j + 11, k + 11, Block.planks.blockID, 1, 2);
		world.setBlock(i + 9, j + 11, k + 12, Block.wood.blockID, 0, 2);
		world.setBlock(i + 9, j + 11, k + 13, Block.stoneBrick.blockID, this.pickStoneBrickType(rand), 2);
		world.setBlock(i + 9, j + 12, k + 3, Block.stoneBrick.blockID, this.pickStoneBrickType(rand), 2);
		world.setBlock(i + 9, j + 12, k + 5, 0, 0, 2);
		world.setBlock(i + 9, j + 12, k + 6, Block.stairsWoodOak.blockID, 7, 2);
		world.setBlock(i + 9, j + 12, k + 9, 0, 0, 2);
		world.setBlock(i + 9, j + 12, k + 10, 0, 0, 2);
		world.setBlock(i + 9, j + 12, k + 11, Block.blockSteel.blockID, 0, 2);
		world.setBlock(i + 9, j + 12, k + 12, Block.stoneBrick.blockID, this.pickStoneBrickType(rand), 2);
		world.setBlock(i + 9, j + 13, k + 3, Block.thinGlass.blockID, 0, 2);
		world.setBlock(i + 9, j + 13, k + 4, 0, 0, 2);
		world.setBlock(i + 9, j + 13, k + 5, 0, 0, 2);
		world.setBlock(i + 9, j + 13, k + 6, 0, 0, 2);
		world.setBlock(i + 9, j + 13, k + 7, 0, 0, 2);
		world.setBlock(i + 9, j + 13, k + 8, 0, 0, 2);
		world.setBlock(i + 9, j + 13, k + 9, 0, 0, 2);
		world.setBlock(i + 9, j + 13, k + 10, 0, 0, 2);
		world.setBlock(i + 9, j + 13, k + 11, 0, 0, 2);
		world.setBlock(i + 9, j + 13, k + 12, Block.stoneBrick.blockID, this.pickStoneBrickType(rand), 2);
		world.setBlock(i + 9, j + 14, k + 3, Block.thinGlass.blockID, 0, 2);
		world.setBlock(i + 9, j + 14, k + 4, 0, 0, 2);
		world.setBlock(i + 9, j + 14, k + 5, 0, 0, 2);
		world.setBlock(i + 9, j + 14, k + 6, 0, 0, 2);
		world.setBlock(i + 9, j + 14, k + 7, 0, 0, 2);
		world.setBlock(i + 9, j + 14, k + 8, 0, 0, 2);
		world.setBlock(i + 9, j + 14, k + 9, 0, 0, 2);
		world.setBlock(i + 9, j + 14, k + 10, 0, 0, 2);
		world.setBlock(i + 9, j + 14, k + 11, 0, 0, 2);
		world.setBlock(i + 9, j + 14, k + 12, Block.stoneBrick.blockID, this.pickStoneBrickType(rand), 2);
		world.setBlock(i + 9, j + 15, k + 3, Block.stoneBrick.blockID, this.pickStoneBrickType(rand), 2);
		world.setBlock(i + 9, j + 15, k + 4, 0, 0, 2);
		world.setBlock(i + 9, j + 15, k + 5, 0, 0, 2);
		world.setBlock(i + 9, j + 15, k + 6, 0, 0, 2);
		world.setBlock(i + 9, j + 15, k + 7, 0, 0, 2);
		world.setBlock(i + 9, j + 15, k + 8, 0, 0, 2);
		world.setBlock(i + 9, j + 15, k + 9, 0, 0, 2);
		world.setBlock(i + 9, j + 15, k + 10, 0, 0, 2);
		world.setBlock(i + 9, j + 15, k + 11, 0, 0, 2);
		world.setBlock(i + 9, j + 15, k + 12, Block.stoneBrick.blockID, this.pickStoneBrickType(rand), 2);
		world.setBlock(i + 9, j + 16, k + 3, Block.stoneBrick.blockID, this.pickStoneBrickType(rand), 2);
		world.setBlock(i + 9, j + 16, k + 4, 0, 0, 2);
		world.setBlock(i + 9, j + 16, k + 5, 0, 0, 2);
		world.setBlock(i + 9, j + 16, k + 6, 0, 0, 2);
		world.setBlock(i + 9, j + 16, k + 7, 0, 0, 2);
		world.setBlock(i + 9, j + 16, k + 8, 0, 0, 2);
		world.setBlock(i + 9, j + 16, k + 9, 0, 0, 2);
		world.setBlock(i + 9, j + 16, k + 10, 0, 0, 2);
		world.setBlock(i + 9, j + 16, k + 11, 0, 0, 2);
		world.setBlock(i + 9, j + 16, k + 12, Block.stoneBrick.blockID, this.pickStoneBrickType(rand), 2);
		world.setBlock(i + 9, j + 17, k + 2, Block.cloth.blockID, 11, 2);
		world.setBlock(i + 9, j + 17, k + 3, Block.stoneBrick.blockID, this.pickStoneBrickType(rand), 2);
		world.setBlock(i + 9, j + 17, k + 4, 0, 0, 2);
		world.setBlock(i + 9, j + 17, k + 5, 0, 0, 2);
		world.setBlock(i + 9, j + 17, k + 6, 0, 0, 2);
		world.setBlock(i + 9, j + 17, k + 7, 0, 0, 2);
		world.setBlock(i + 9, j + 17, k + 8, 0, 0, 2);
		world.setBlock(i + 9, j + 17, k + 9, 0, 0, 2);
		world.setBlock(i + 9, j + 17, k + 10, 0, 0, 2);
		world.setBlock(i + 9, j + 17, k + 11, 0, 0, 2);
		world.setBlock(i + 9, j + 17, k + 12, Block.stoneBrick.blockID, this.pickStoneBrickType(rand), 2);
		world.setBlock(i + 9, j + 17, k + 13, Block.cloth.blockID, 11, 2);
		world.setBlock(i + 9, j + 18, k + 3, Block.cloth.blockID, 11, 2);
		world.setBlock(i + 9, j + 18, k + 4, 0, 0, 2);
		world.setBlock(i + 9, j + 18, k + 5, 0, 0, 2);
		world.setBlock(i + 9, j + 18, k + 6, 0, 0, 2);
		world.setBlock(i + 9, j + 18, k + 7, 0, 0, 2);
		world.setBlock(i + 9, j + 18, k + 8, 0, 0, 2);
		world.setBlock(i + 9, j + 18, k + 9, 0, 0, 2);
		world.setBlock(i + 9, j + 18, k + 10, 0, 0, 2);
		world.setBlock(i + 9, j + 18, k + 11, 0, 0, 2);
		world.setBlock(i + 9, j + 18, k + 12, Block.cloth.blockID, 11, 2);
		world.setBlock(i + 9, j + 19, k + 4, Block.cloth.blockID, 11, 2);
		world.setBlock(i + 9, j + 19, k + 5, 0, 0, 2);
		world.setBlock(i + 9, j + 19, k + 6, 0, 0, 2);
		world.setBlock(i + 9, j + 19, k + 7, 0, 0, 2);
		world.setBlock(i + 9, j + 19, k + 8, 0, 0, 2);
		world.setBlock(i + 9, j + 19, k + 9, 0, 0, 2);
		world.setBlock(i + 9, j + 19, k + 10, 0, 0, 2);
		world.setBlock(i + 9, j + 19, k + 11, Block.cloth.blockID, 11, 2);
		world.setBlock(i + 9, j + 20, k + 5, Block.cloth.blockID, 11, 2);
		world.setBlock(i + 9, j + 20, k + 6, Block.cloth.blockID, 11, 2);
		world.setBlock(i + 9, j + 20, k + 7, Block.ice.blockID, 0, 2);
		world.setBlock(i + 9, j + 20, k + 8, Block.ice.blockID, 0, 2);
		world.setBlock(i + 9, j + 20, k + 9, Block.cloth.blockID, 11, 2);
		world.setBlock(i + 9, j + 20, k + 10, Block.cloth.blockID, 11, 2);
		world.setBlock(i + 9, j + 21, k + 7, Block.cloth.blockID, 11, 2);
		world.setBlock(i + 9, j + 21, k + 8, Block.cloth.blockID, 11, 2);
		world.setBlock(i + 10, j + 0, k + 1, Block.stoneBrick.blockID, this.pickStoneBrickType(rand), 2);
		world.setBlock(i + 10, j + 0, k + 2, Block.planks.blockID, 2, 2);
		world.setBlock(i + 10, j + 0, k + 3, Block.planks.blockID, 1, 2);
		world.setBlock(i + 10, j + 0, k + 4, Block.planks.blockID, 2, 2);
		world.setBlock(i + 10, j + 0, k + 5, Block.planks.blockID, 2, 2);
		world.setBlock(i + 10, j + 0, k + 6, Block.planks.blockID, 0, 2);
		world.setBlock(i + 10, j + 0, k + 7, Block.wood.blockID, 9, 2);
		world.setBlock(i + 10, j + 0, k + 8, Block.wood.blockID, 9, 2);
		world.setBlock(i + 10, j + 0, k + 9, Block.planks.blockID, 0, 2);
		world.setBlock(i + 10, j + 0, k + 10, Block.planks.blockID, 2, 2);
		world.setBlock(i + 10, j + 0, k + 11, Block.planks.blockID, 2, 2);
		world.setBlock(i + 10, j + 0, k + 12, Block.planks.blockID, 1, 2);
		world.setBlock(i + 10, j + 0, k + 13, Block.planks.blockID, 2, 2);
		world.setBlock(i + 10, j + 0, k + 14, Block.stoneBrick.blockID, this.pickStoneBrickType(rand), 2);
		world.setBlock(i + 10, j + 1, k + 1, Block.stoneBrick.blockID, this.pickStoneBrickType(rand), 2);
		world.setBlock(i + 10, j + 1, k + 2, Block.woodSingleSlab.blockID, 2, 2);
		world.setBlock(i + 10, j + 1, k + 3, 0, 0, 2);
		world.setBlock(i + 10, j + 1, k + 4, 0, 0, 2);
		world.setBlock(i + 10, j + 1, k + 5, Block.stoneBrick.blockID, 0, 2);
		world.setBlock(i + 10, j + 1, k + 6, Block.wood.blockID, 1, 2);
		world.setBlock(i + 10, j + 1, k + 7, Block.wood.blockID, 1, 2);
		world.setBlock(i + 10, j + 1, k + 8, Block.wood.blockID, 1, 2);
		world.setBlock(i + 10, j + 1, k + 9, Block.wood.blockID, 1, 2);
		world.setBlock(i + 10, j + 1, k + 10, Block.stoneBrick.blockID, 0, 2);
		world.setBlock(i + 10, j + 1, k + 11, 0, 0, 2);
		world.setBlock(i + 10, j + 1, k + 12, 0, 0, 2);
		world.setBlock(i + 10, j + 1, k + 13, Block.woodSingleSlab.blockID, 2, 2);
		world.setBlock(i + 10, j + 1, k + 14, Block.stoneBrick.blockID, this.pickStoneBrickType(rand), 2);
		world.setBlock(i + 10, j + 2, k + 1, Block.stoneBrick.blockID, this.pickStoneBrickType(rand), 2);
		world.setBlock(i + 10, j + 2, k + 2, Block.woodSingleSlab.blockID, 9, 2);
		world.setBlock(i + 10, j + 2, k + 3, 0, 0, 2);
		world.setBlock(i + 10, j + 2, k + 4, 0, 0, 2);
		world.setBlock(i + 10, j + 2, k + 5, 0, 0, 2);
		world.setBlock(i + 10, j + 2, k + 6, Block.wood.blockID, 1, 2);
		world.setBlock(i + 10, j + 2, k + 7, Block.stairsWoodOak.blockID, 1, 2);
		world.setBlock(i + 10, j + 2, k + 8, Block.stairsWoodOak.blockID, 1, 2);
		world.setBlock(i + 10, j + 2, k + 9, Block.wood.blockID, 1, 2);
		world.setBlock(i + 10, j + 2, k + 10, 0, 0, 2);
		world.setBlock(i + 10, j + 2, k + 11, 0, 0, 2);
		world.setBlock(i + 10, j + 2, k + 12, 0, 0, 2);
		world.setBlock(i + 10, j + 2, k + 13, Block.woodSingleSlab.blockID, 9, 2);
		world.setBlock(i + 10, j + 2, k + 14, Block.stoneBrick.blockID, this.pickStoneBrickType(rand), 2);
		world.setBlock(i + 10, j + 3, k + 1, Block.stoneBrick.blockID, this.pickStoneBrickType(rand), 2);
		world.setBlock(i + 10, j + 3, k + 2, Block.bookShelf.blockID, 0, 2);
		world.setBlock(i + 10, j + 3, k + 3, 0, 0, 2);
		world.setBlock(i + 10, j + 3, k + 4, 0, 0, 2);
		world.setBlock(i + 10, j + 3, k + 5, 0, 0, 2);
		world.setBlock(i + 10, j + 3, k + 6, Block.wood.blockID, 1, 2);
		world.setBlock(i + 10, j + 3, k + 7, 0, 0, 2);
		world.setBlock(i + 10, j + 3, k + 8, 0, 0, 2);
		world.setBlock(i + 10, j + 3, k + 9, Block.wood.blockID, 1, 2);
		world.setBlock(i + 10, j + 3, k + 10, 0, 0, 2);
		world.setBlock(i + 10, j + 3, k + 11, 0, 0, 2);
		world.setBlock(i + 10, j + 3, k + 12, 0, 0, 2);
		world.setBlock(i + 10, j + 3, k + 13, Block.bookShelf.blockID, 0, 2);
		world.setBlock(i + 10, j + 3, k + 14, Block.stoneBrick.blockID, this.pickStoneBrickType(rand), 2);
		world.setBlock(i + 10, j + 4, k + 1, Block.stoneBrick.blockID, this.pickStoneBrickType(rand), 2);
		world.setBlock(i + 10, j + 4, k + 2, 0, 0, 2);
		world.setBlock(i + 10, j + 4, k + 3, 0, 0, 2);
		world.setBlock(i + 10, j + 4, k + 4, 0, 0, 2);
		world.setBlock(i + 10, j + 4, k + 5, 0, 0, 2);
		world.setBlock(i + 10, j + 4, k + 6, Block.wood.blockID, 1, 2);
		world.setBlock(i + 10, j + 4, k + 9, Block.wood.blockID, 1, 2);
		world.setBlock(i + 10, j + 4, k + 10, 0, 0, 2);
		world.setBlock(i + 10, j + 4, k + 11, 0, 0, 2);
		world.setBlock(i + 10, j + 4, k + 12, 0, 0, 2);
		world.setBlock(i + 10, j + 4, k + 13, 0, 0, 2);
		world.setBlock(i + 10, j + 4, k + 14, Block.stoneBrick.blockID, this.pickStoneBrickType(rand), 2);
		world.setBlock(i + 10, j + 5, k + 0, Block.stairsBrick.blockID, 2, 2);
		world.setBlock(i + 10, j + 5, k + 1, Block.brick.blockID, 0, 2);
		world.setBlock(i + 10, j + 5, k + 2, 0, 0, 2);
		world.setBlock(i + 10, j + 5, k + 3, 0, 0, 2);
		world.setBlock(i + 10, j + 5, k + 4, 0, 0, 2);
		world.setBlock(i + 10, j + 5, k + 5, Block.wood.blockID, 9, 2);
		world.setBlock(i + 10, j + 5, k + 6, Block.wood.blockID, 1, 2);
		world.setBlock(i + 10, j + 5, k + 9, Block.wood.blockID, 1, 2);
		world.setBlock(i + 10, j + 5, k + 10, Block.wood.blockID, 9, 2);
		world.setBlock(i + 10, j + 5, k + 11, 0, 0, 2);
		world.setBlock(i + 10, j + 5, k + 12, 0, 0, 2);
		world.setBlock(i + 10, j + 5, k + 13, 0, 0, 2);
		world.setBlock(i + 10, j + 5, k + 14, Block.brick.blockID, 0, 2);
		world.setBlock(i + 10, j + 5, k + 15, Block.stairsBrick.blockID, 3, 2);
		world.setBlock(i + 10, j + 6, k + 1, Block.stairsBrick.blockID, 2, 2);
		world.setBlock(i + 10, j + 6, k + 2, Block.brick.blockID, 0, 2);
		world.setBlock(i + 10, j + 6, k + 3, this.pickDungeonBlock(rand), 0, 2);
		world.setBlock(i + 10, j + 6, k + 4, this.pickDungeonBlock(rand), 0, 2);
		world.setBlock(i + 10, j + 6, k + 5, this.pickDungeonBlock(rand), 0, 2);
		world.setBlock(i + 10, j + 6, k + 6, this.pickDungeonBlock(rand), 0, 2);
		world.setBlock(i + 10, j + 6, k + 9, Block.stoneBrick.blockID, this.pickStoneBrickType(rand), 2);
		world.setBlock(i + 10, j + 6, k + 10, this.pickDungeonBlock(rand), 0, 2);
		world.setBlock(i + 10, j + 6, k + 11, this.pickDungeonBlock(rand), 0, 2);
		world.setBlock(i + 10, j + 6, k + 12, this.pickDungeonBlock(rand), 0, 2);
		world.setBlock(i + 10, j + 6, k + 13, Block.brick.blockID, 0, 2);
		world.setBlock(i + 10, j + 6, k + 14, Block.stairsBrick.blockID, 3, 2);
		world.setBlock(i + 10, j + 7, k + 2, Block.stoneBrick.blockID, this.pickStoneBrickType(rand), 2);
		world.setBlock(i + 10, j + 7, k + 3, 0, 0, 2);
		world.setBlock(i + 10, j + 7, k + 4, Block.stoneBrick.blockID, this.pickStoneBrickType(rand), 2);
		world.setBlock(i + 10, j + 7, k + 5, this.pickDungeonBlock(rand), 0, 2);
		world.setBlock(i + 10, j + 7, k + 6, 0, 0, 2);
		world.setBlock(i + 10, j + 7, k + 9, 0, 0, 2);
		world.setBlock(i + 10, j + 7, k + 11, Block.stoneBrick.blockID, this.pickStoneBrickType(rand), 2);
		world.setBlock(i + 10, j + 7, k + 12, 0, 0, 2);
		world.setBlock(i + 10, j + 7, k + 13, Block.stoneBrick.blockID, this.pickStoneBrickType(rand), 2);
		world.setBlock(i + 10, j + 8, k + 2, Block.stoneBrick.blockID, this.pickStoneBrickType(rand), 2);
		world.setBlock(i + 10, j + 8, k + 3, 0, 0, 2);
		world.setBlock(i + 10, j + 8, k + 4, 0, 0, 2);
		world.setBlock(i + 10, j + 8, k + 5, 0, 0, 2);
		world.setBlock(i + 10, j + 8, k + 6, 0, 0, 2);
		world.setBlock(i + 10, j + 8, k + 7, 0, 0, 2);
		world.setBlock(i + 10, j + 8, k + 8, 0, 0, 2);
		world.setBlock(i + 10, j + 8, k + 9, 0, 0, 2);

		generate2(world, rand, i, j, k);
