/*
 * ** MADE BY MITHION'S .SCHEMATIC TO JAVA CONVERTING TOOLv0.1 ***
 */
package arcticraft.gen;

import java.util.Random;

import cpw.mods.fml.common.FMLLog;

import net.minecraft.block.Block;
import net.minecraft.tileentity.TileEntityChest;
import net.minecraft.util.WeightedRandomChestContent;
import net.minecraft.world.World;
import net.minecraft.world.gen.feature.WorldGenerator;
import net.minecraftforge.common.ChestGenHooks;
import arcticraft.biomes.AC_BiomeOcean;
import arcticraft.blocks.AC_Block;
import arcticraft.data_store.GeneratedShipsStore;
import arcticraft.entities.AC_EntityCaptain;
import arcticraft.entities.AC_EntityPirate;
import arcticraft.tile_entities.AC_TileEntityFrostChest;

public class AC_GenShip extends WorldGenerator
{

	private static final int MIN_SHIP_DISTANCE = 600; // Minimal distance between two ships
	private static final int SIZE_X = 16; // Ship Base
	private static final int SIZE_Y = 32;
	private static final int SIZE_Z = 64; 
	private static final int PLATFORM_AREA = SIZE_X * SIZE_Z; //Ship Base
	private static final int VOLUME = SIZE_X * SIZE_Y * SIZE_Z;  //Volume of the ship

	public AC_GenShip()
	{}

	public boolean checkSpawn(World world, Random rand, int x, int y, int z)
	{
		if(rand.nextInt(1000) > 20 || GeneratedShipsStore.instance.isAnyShipInRadius(x, z, MIN_SHIP_DISTANCE)){
			return false;
		}
		int validPlatformBlocks = 0;
		int validVolumeBlocks = 0;
		for(int xx = x; xx < x + SIZE_X; ++xx)
		{
			for(int zz = z; zz < z + SIZE_Z; ++zz)
			{
				if(world.getBlockId(xx, y, zz) == AC_Block.acWaterStill.blockID || world.getBlockId(xx, y, zz) == AC_Block.acWaterFlowing.blockID){
					validPlatformBlocks++;
				}
				for(int yy = y; yy < y + SIZE_Y; ++yy)
				{
					if(world.getBlockId(xx,yy,zz) == 0 || (Block.blocksList[world.getBlockId(xx,yy,zz)] != null && Block.blocksList[world.getBlockId(xx, yy, zz)].isBlockReplaceable(world, xx, yy, zz))){
						validVolumeBlocks++;
					}
				}
			}
		}
		double validPlatformBlocksPercentage = validPlatformBlocks / PLATFORM_AREA * 100;
		double validAreaBlocksPercentage = validVolumeBlocks / VOLUME * 100;
//		FMLLog.info("PlatformBlocks: %f ; VolumeBlocks: %f", validPlatformBlocksPercentage,validAreaBlocksPercentage);
		return (validPlatformBlocksPercentage == 100 && validAreaBlocksPercentage > 60);
	}

	public boolean generate(World world, Random rand, int x, int y, int z)
	{
		if(!checkSpawn(world, rand, x, y, z))
		{
			return false;
		}
		GeneratedShipsStore.instance.addShip(new GeneratedShipsStore.CoordinatesXZ(x, z));
		FMLLog.info("Ship has been generated at x=%d, z=%d", x, z);
		world.setBlock(x + 6, y + 0, z + 6, 17, 13, 1);
		world.setBlock(x + 7, y + 0, z + 6, 17, 13, 1);
		world.setBlock(x + 8, y + 0, z + 6, 17, 13, 1);
		world.setBlock(x + 6, y + 0, z + 7, 17, 13, 1);
		world.setBlock(x + 7, y + 0, z + 7, 17, 13, 1);
		world.setBlock(x + 8, y + 0, z + 7, 17, 13, 1);
		world.setBlock(x + 5, y + 0, z + 8, 17, 13, 1);
		world.setBlock(x + 6, y + 0, z + 8, 17, 13, 1);
		world.setBlock(x + 7, y + 0, z + 8, 17, 13, 1);
		world.setBlock(x + 8, y + 0, z + 8, 17, 13, 1);
		world.setBlock(x + 9, y + 0, z + 8, 17, 13, 1);
		world.setBlock(x + 5, y + 0, z + 9, 17, 13, 1);
		world.setBlock(x + 6, y + 0, z + 9, 17, 13, 1);
		world.setBlock(x + 7, y + 0, z + 9, 17, 13, 1);
		world.setBlock(x + 8, y + 0, z + 9, 17, 13, 1);
		world.setBlock(x + 9, y + 0, z + 9, 17, 13, 1);
		world.setBlock(x + 5, y + 0, z + 10, 17, 13, 1);
		world.setBlock(x + 6, y + 0, z + 10, 17, 13, 1);
		world.setBlock(x + 7, y + 0, z + 10, 17, 13, 1);
		world.setBlock(x + 8, y + 0, z + 10, 17, 13, 1);
		world.setBlock(x + 9, y + 0, z + 10, 17, 13, 1);
		world.setBlock(x + 5, y + 0, z + 11, 17, 13, 1);
		world.setBlock(x + 6, y + 0, z + 11, 17, 13, 1);
		world.setBlock(x + 7, y + 0, z + 11, 17, 13, 1);
		world.setBlock(x + 8, y + 0, z + 11, 17, 13, 1);
		world.setBlock(x + 9, y + 0, z + 11, 17, 13, 1);
		world.setBlock(x + 5, y + 0, z + 12, 17, 13, 1);
		world.setBlock(x + 6, y + 0, z + 12, 17, 13, 1);
		world.setBlock(x + 7, y + 0, z + 12, 17, 13, 1);
		world.setBlock(x + 8, y + 0, z + 12, 17, 13, 1);
		world.setBlock(x + 9, y + 0, z + 12, 17, 13, 1);
		world.setBlock(x + 5, y + 0, z + 13, 17, 13, 1);
		world.setBlock(x + 6, y + 0, z + 13, 17, 13, 1);
		world.setBlock(x + 7, y + 0, z + 13, 17, 13, 1);
		world.setBlock(x + 8, y + 0, z + 13, 17, 13, 1);
		world.setBlock(x + 9, y + 0, z + 13, 17, 13, 1);
		world.setBlock(x + 5, y + 0, z + 14, 17, 13, 1);
		world.setBlock(x + 6, y + 0, z + 14, 17, 13, 1);
		world.setBlock(x + 7, y + 0, z + 14, 17, 13, 1);
		world.setBlock(x + 8, y + 0, z + 14, 17, 13, 1);
		world.setBlock(x + 9, y + 0, z + 14, 17, 13, 1);
		world.setBlock(x + 5, y + 0, z + 15, 17, 13, 1);
		world.setBlock(x + 6, y + 0, z + 15, 17, 13, 1);
		world.setBlock(x + 7, y + 0, z + 15, 17, 13, 1);
		world.setBlock(x + 8, y + 0, z + 15, 17, 13, 1);
		world.setBlock(x + 9, y + 0, z + 15, 17, 13, 1);
		world.setBlock(x + 5, y + 0, z + 16, 17, 9, 1);
		world.setBlock(x + 6, y + 0, z + 16, 17, 13, 1);
		world.setBlock(x + 7, y + 0, z + 16, 17, 13, 1);
		world.setBlock(x + 8, y + 0, z + 16, 17, 13, 1);
		world.setBlock(x + 9, y + 0, z + 16, 17, 9, 1);
		world.setBlock(x + 5, y + 0, z + 17, 17, 13, 1);
		world.setBlock(x + 6, y + 0, z + 17, 17, 13, 1);
		world.setBlock(x + 7, y + 0, z + 17, 17, 13, 1);
		world.setBlock(x + 8, y + 0, z + 17, 17, 13, 1);
		world.setBlock(x + 9, y + 0, z + 17, 17, 13, 1);
		world.setBlock(x + 5, y + 0, z + 18, 17, 9, 1);
		world.setBlock(x + 6, y + 0, z + 18, 17, 13, 1);
		world.setBlock(x + 7, y + 0, z + 18, 17, 13, 1);
		world.setBlock(x + 8, y + 0, z + 18, 17, 13, 1);
		world.setBlock(x + 9, y + 0, z + 18, 17, 9, 1);
		world.setBlock(x + 5, y + 0, z + 19, 17, 13, 1);
		world.setBlock(x + 6, y + 0, z + 19, 17, 13, 1);
		world.setBlock(x + 7, y + 0, z + 19, 17, 13, 1);
		world.setBlock(x + 8, y + 0, z + 19, 17, 13, 1);
		world.setBlock(x + 9, y + 0, z + 19, 17, 13, 1);
		world.setBlock(x + 5, y + 0, z + 20, 17, 9, 1);
		world.setBlock(x + 6, y + 0, z + 20, 17, 13, 1);
		world.setBlock(x + 7, y + 0, z + 20, 17, 13, 1);
		world.setBlock(x + 8, y + 0, z + 20, 17, 13, 1);
		world.setBlock(x + 9, y + 0, z + 20, 17, 9, 1);
		world.setBlock(x + 5, y + 0, z + 21, 17, 13, 1);
		world.setBlock(x + 6, y + 0, z + 21, 17, 13, 1);
		world.setBlock(x + 7, y + 0, z + 21, 17, 13, 1);
		world.setBlock(x + 8, y + 0, z + 21, 17, 13, 1);
		world.setBlock(x + 9, y + 0, z + 21, 17, 13, 1);
		world.setBlock(x + 5, y + 0, z + 22, 17, 9, 1);
		world.setBlock(x + 6, y + 0, z + 22, 17, 13, 1);
		world.setBlock(x + 7, y + 0, z + 22, 17, 13, 1);
		world.setBlock(x + 8, y + 0, z + 22, 17, 13, 1);
		world.setBlock(x + 9, y + 0, z + 22, 17, 9, 1);
		world.setBlock(x + 5, y + 0, z + 23, 17, 13, 1);
		world.setBlock(x + 6, y + 0, z + 23, 17, 13, 1);
		world.setBlock(x + 7, y + 0, z + 23, 17, 13, 1);
		world.setBlock(x + 8, y + 0, z + 23, 17, 13, 1);
		world.setBlock(x + 9, y + 0, z + 23, 17, 13, 1);
		world.setBlock(x + 5, y + 0, z + 24, 17, 9, 1);
		world.setBlock(x + 6, y + 0, z + 24, 17, 13, 1);
		world.setBlock(x + 7, y + 0, z + 24, 17, 13, 1);
		world.setBlock(x + 8, y + 0, z + 24, 17, 13, 1);
		world.setBlock(x + 9, y + 0, z + 24, 17, 9, 1);
		world.setBlock(x + 5, y + 0, z + 25, 17, 13, 1);
		world.setBlock(x + 6, y + 0, z + 25, 17, 13, 1);
		world.setBlock(x + 7, y + 0, z + 25, 17, 13, 1);
		world.setBlock(x + 8, y + 0, z + 25, 17, 13, 1);
		world.setBlock(x + 9, y + 0, z + 25, 17, 13, 1);
		world.setBlock(x + 5, y + 0, z + 26, 17, 13, 1);
		world.setBlock(x + 6, y + 0, z + 26, 17, 13, 1);
		world.setBlock(x + 7, y + 0, z + 26, 17, 13, 1);
		world.setBlock(x + 8, y + 0, z + 26, 17, 13, 1);
		world.setBlock(x + 9, y + 0, z + 26, 17, 13, 1);
		world.setBlock(x + 5, y + 0, z + 27, 17, 13, 1);
		world.setBlock(x + 6, y + 0, z + 27, 17, 13, 1);
		world.setBlock(x + 7, y + 0, z + 27, 17, 13, 1);
		world.setBlock(x + 8, y + 0, z + 27, 17, 13, 1);
		world.setBlock(x + 9, y + 0, z + 27, 17, 13, 1);
		world.setBlock(x + 5, y + 0, z + 28, 17, 13, 1);
		world.setBlock(x + 6, y + 0, z + 28, 17, 13, 1);
		world.setBlock(x + 7, y + 0, z + 28, 17, 13, 1);
		world.setBlock(x + 8, y + 0, z + 28, 17, 13, 1);
		world.setBlock(x + 9, y + 0, z + 28, 17, 13, 1);
		world.setBlock(x + 5, y + 0, z + 29, 17, 13, 1);
		world.setBlock(x + 6, y + 0, z + 29, 17, 13, 1);
		world.setBlock(x + 7, y + 0, z + 29, 17, 13, 1);
		world.setBlock(x + 8, y + 0, z + 29, 17, 13, 1);
		world.setBlock(x + 9, y + 0, z + 29, 17, 13, 1);
		world.setBlock(x + 6, y + 0, z + 30, 17, 13, 1);
		world.setBlock(x + 7, y + 0, z + 30, 17, 13, 1);
		world.setBlock(x + 8, y + 0, z + 30, 17, 13, 1);
		world.setBlock(x + 7, y + 0, z + 31, 17, 13, 1);
		world.setBlock(x + 5, y + 1, z + 6, 17, 13, 1);
		world.setBlock(x + 6, y + 1, z + 6, 17, 13, 1);
		world.setBlock(x + 7, y + 1, z + 6, 17, 13, 1);
		world.setBlock(x + 8, y + 1, z + 6, 17, 13, 1);
		world.setBlock(x + 9, y + 1, z + 6, 17, 13, 1);
		world.setBlock(x + 5, y + 1, z + 7, 17, 13, 1);
		world.setBlock(x + 9, y + 1, z + 7, 17, 13, 1);
		world.setBlock(x + 5, y + 1, z + 8, 17, 13, 1);
		world.setBlock(x + 9, y + 1, z + 8, 17, 13, 1);
		world.setBlock(x + 5, y + 1, z + 9, 17, 13, 1);
		world.setBlock(x + 9, y + 1, z + 9, 17, 13, 1);
		world.setBlock(x + 4, y + 1, z + 10, 17, 13, 1);
		world.setBlock(x + 5, y + 1, z + 10, 17, 13, 1);
		world.setBlock(x + 9, y + 1, z + 10, 17, 13, 1);
		world.setBlock(x + 10, y + 1, z + 10, 17, 13, 1);
		world.setBlock(x + 4, y + 1, z + 11, 17, 13, 1);
		world.setBlock(x + 5, y + 1, z + 11, 17, 13, 1);
		world.setBlock(x + 9, y + 1, z + 11, 17, 13, 1);
		world.setBlock(x + 10, y + 1, z + 11, 17, 13, 1);
		world.setBlock(x + 4, y + 1, z + 12, 17, 13, 1);
		world.setBlock(x + 5, y + 1, z + 12, 17, 13, 1);
		world.setBlock(x + 9, y + 1, z + 12, 17, 13, 1);
		world.setBlock(x + 10, y + 1, z + 12, 17, 13, 1);
		world.setBlock(x + 4, y + 1, z + 13, 17, 13, 1);
		world.setBlock(x + 5, y + 1, z + 13, 17, 13, 1);
		world.setBlock(x + 6, y + 1, z + 13, 17, 13, 1);
		world.setBlock(x + 7, y + 1, z + 13, 134, 2, 1);
		world.setBlock(x + 8, y + 1, z + 13, 17, 13, 1);
		world.setBlock(x + 9, y + 1, z + 13, 17, 13, 1);
		world.setBlock(x + 10, y + 1, z + 13, 17, 13, 1);
		world.setBlock(x + 4, y + 1, z + 14, 17, 13, 1);
		world.setBlock(x + 5, y + 1, z + 14, 17, 13, 1);
		world.setBlock(x + 6, y + 1, z + 14, 17, 13, 1);
		world.setBlock(x + 7, y + 1, z + 14, 17, 13, 1);
		world.setBlock(x + 8, y + 1, z + 14, 17, 13, 1);
		world.setBlock(x + 9, y + 1, z + 14, 17, 13, 1);
		world.setBlock(x + 10, y + 1, z + 14, 17, 13, 1);
		world.setBlock(x + 4, y + 1, z + 15, 17, 9, 1);
		world.setBlock(x + 5, y + 1, z + 15, 126, 1, 1);
		world.setBlock(x + 6, y + 1, z + 15, 17, 13, 1);
		world.setBlock(x + 7, y + 1, z + 15, 17, 13, 1);
		world.setBlock(x + 8, y + 1, z + 15, 17, 13, 1);
		world.setBlock(x + 9, y + 1, z + 15, 126, 1, 1);
		world.setBlock(x + 10, y + 1, z + 15, 17, 9, 1);
		world.setBlock(x + 4, y + 1, z + 16, 17, 13, 1);
		world.setBlock(x + 10, y + 1, z + 16, 17, 13, 1);
		world.setBlock(x + 4, y + 1, z + 17, 17, 9, 1);
		world.setBlock(x + 5, y + 1, z + 17, 126, 1, 1);
		world.setBlock(x + 9, y + 1, z + 17, 126, 1, 1);
		world.setBlock(x + 10, y + 1, z + 17, 17, 9, 1);
		world.setBlock(x + 4, y + 1, z + 18, 17, 13, 1);
		world.setBlock(x + 10, y + 1, z + 18, 17, 13, 1);
		world.setBlock(x + 4, y + 1, z + 19, 17, 9, 1);
		world.setBlock(x + 5, y + 1, z + 19, 126, 1, 1);
		world.setBlock(x + 7, y + 1, z + 19, 17, 13, 1);
		world.setBlock(x + 8, y + 1, z + 19, 74, 0, 1);
		world.setBlock(x + 9, y + 1, z + 19, 126, 1, 1);
		world.setBlock(x + 10, y + 1, z + 19, 17, 9, 1);
		world.setBlock(x + 4, y + 1, z + 20, 17, 13, 1);
		world.setBlock(x + 10, y + 1, z + 20, 17, 13, 1);
		world.setBlock(x + 4, y + 1, z + 21, 17, 9, 1);
		world.setBlock(x + 5, y + 1, z + 21, 126, 1, 1);
		world.setBlock(x + 9, y + 1, z + 21, 126, 1, 1);
		world.setBlock(x + 10, y + 1, z + 21, 17, 9, 1);
		world.setBlock(x + 4, y + 1, z + 22, 17, 13, 1);
		world.setBlock(x + 10, y + 1, z + 22, 17, 13, 1);
		world.setBlock(x + 4, y + 1, z + 23, 17, 9, 1);
		world.setBlock(x + 5, y + 1, z + 23, 126, 1, 1);
		world.setBlock(x + 9, y + 1, z + 23, 126, 1, 1);
		world.setBlock(x + 10, y + 1, z + 23, 17, 9, 1);
		world.setBlock(x + 4, y + 1, z + 24, 17, 13, 1);
		world.setBlock(x + 10, y + 1, z + 24, 17, 13, 1);
		world.setBlock(x + 5, y + 1, z + 25, 17, 13, 1);
		world.setBlock(x + 7, y + 1, z + 25, 17, 1, 1);
		world.setBlock(x + 9, y + 1, z + 25, 17, 13, 1);
		world.setBlock(x + 5, y + 1, z + 26, 17, 13, 1);
		world.setBlock(x + 7, y + 1, z + 26, 65, 3, 1);
		world.setBlock(x + 9, y + 1, z + 26, 17, 13, 1);
		world.setBlock(x + 5, y + 1, z + 27, 17, 13, 1);
		world.setBlock(x + 9, y + 1, z + 27, 17, 13, 1);
		world.setBlock(x + 5, y + 1, z + 28, 17, 13, 1);
		world.setBlock(x + 7, y + 1, z + 28, 17, 13, 1);
		world.setBlock(x + 9, y + 1, z + 28, 17, 13, 1);
		world.setBlock(x + 5, y + 1, z + 29, 17, 13, 1);
		world.setBlock(x + 9, y + 1, z + 29, 17, 13, 1);
		world.setBlock(x + 5, y + 1, z + 30, 17, 13, 1);
		world.setBlock(x + 6, y + 1, z + 30, 17, 13, 1);
		world.setBlock(x + 7, y + 1, z + 30, 58, 0, 1);
		world.setBlock(x + 8, y + 1, z + 30, 17, 13, 1);
		world.setBlock(x + 9, y + 1, z + 30, 17, 13, 1);
		world.setBlock(x + 6, y + 1, z + 31, 17, 13, 1);
		world.setBlock(x + 7, y + 1, z + 31, 17, 13, 1);
		world.setBlock(x + 8, y + 1, z + 31, 17, 13, 1);
		world.setBlock(x + 7, y + 1, z + 32, 17, 13, 1);
		world.setBlock(x + 4, y + 2, z + 6, 17, 13, 1);
		world.setBlock(x + 5, y + 2, z + 6, 17, 13, 1);
		world.setBlock(x + 6, y + 2, z + 6, 17, 13, 1);
		world.setBlock(x + 7, y + 2, z + 6, 17, 13, 1);
		world.setBlock(x + 8, y + 2, z + 6, 17, 13, 1);
		world.setBlock(x + 9, y + 2, z + 6, 17, 13, 1);
		world.setBlock(x + 10, y + 2, z + 6, 17, 13, 1);
		world.setBlock(x + 4, y + 2, z + 7, 17, 13, 1);
		world.setBlock(x + 5, y + 2, z + 7, 62, 5, 1);
		world.setBlock(x + 9, y + 2, z + 7, 62, 4, 1);
		world.setBlock(x + 10, y + 2, z + 7, 17, 13, 1);
		world.setBlock(x + 4, y + 2, z + 8, 17, 13, 1);
		world.setBlock(x + 5, y + 2, z + 8, 17, 1, 1);
		world.setBlock(x + 9, y + 2, z + 8, 17, 1, 1);
		world.setBlock(x + 10, y + 2, z + 8, 17, 13, 1);
		world.setBlock(x + 4, y + 2, z + 9, 17, 13, 1);
		world.setBlock(x + 5, y + 2, z + 9, 62, 5, 1);
		world.setBlock(x + 9, y + 2, z + 9, 62, 4, 1);
		world.setBlock(x + 10, y + 2, z + 9, 17, 13, 1);
		world.setBlock(x + 4, y + 2, z + 10, 17, 13, 1);
		world.setBlock(x + 5, y + 2, z + 10, 17, 1, 1);
		world.setBlock(x + 9, y + 2, z + 10, 17, 1, 1);
		world.setBlock(x + 10, y + 2, z + 10, 17, 13, 1);
		world.setBlock(x + 4, y + 2, z + 11, 17, 13, 1);
		world.setBlock(x + 5, y + 2, z + 11, 62, 5, 1);
		world.setBlock(x + 9, y + 2, z + 11, 62, 4, 1);
		world.setBlock(x + 10, y + 2, z + 11, 17, 13, 1);
		world.setBlock(x + 4, y + 2, z + 12, 17, 13, 1);
		world.setBlock(x + 5, y + 2, z + 12, 17, 13, 1);
		world.setBlock(x + 9, y + 2, z + 12, 17, 13, 1);
		world.setBlock(x + 10, y + 2, z + 12, 17, 13, 1);
		world.setBlock(x + 4, y + 2, z + 13, 17, 13, 1);
		world.setBlock(x + 5, y + 2, z + 13, 17, 13, 1);
		world.setBlock(x + 6, y + 2, z + 13, 17, 13, 1);
		world.setBlock(x + 8, y + 2, z + 13, 17, 13, 1);
		world.setBlock(x + 9, y + 2, z + 13, 17, 13, 1);
		world.setBlock(x + 10, y + 2, z + 13, 17, 13, 1);
		world.setBlock(x + 4, y + 2, z + 14, 17, 13, 1);
		world.setBlock(x + 5, y + 2, z + 14, 17, 13, 1);
		world.setBlock(x + 6, y + 2, z + 14, 5, 1, 1);
		world.setBlock(x + 7, y + 2, z + 14, 134, 2, 1);
		world.setBlock(x + 8, y + 2, z + 14, 5, 1, 1);
		world.setBlock(x + 9, y + 2, z + 14, 17, 13, 1);
		world.setBlock(x + 10, y + 2, z + 14, 17, 13, 1);
		world.setBlock(x + 3, y + 2, z + 15, 23, 4, 1);
		world.setBlock(x + 4, y + 2, z + 15, 77, 3, 1);
		world.setBlock(x + 6, y + 2, z + 15, 17, 13, 1);
		world.setBlock(x + 7, y + 2, z + 15, 17, 13, 1);
		world.setBlock(x + 8, y + 2, z + 15, 17, 13, 1);
		world.setBlock(x + 10, y + 2, z + 15, 77, 4, 1);
		world.setBlock(x + 11, y + 2, z + 15, 23, 5, 1);
		world.setBlock(x + 4, y + 2, z + 16, 17, 13, 1);
		world.setBlock(x + 10, y + 2, z + 16, 17, 13, 1);
		world.setBlock(x + 3, y + 2, z + 17, 23, 4, 1);
		world.setBlock(x + 4, y + 2, z + 17, 77, 3, 1);
		world.setBlock(x + 10, y + 2, z + 17, 77, 4, 1);
		world.setBlock(x + 11, y + 2, z + 17, 23, 5, 1);
		world.setBlock(x + 4, y + 2, z + 18, 17, 13, 1);
		world.setBlock(x + 5, y + 2, z + 18, 50, 1, 1);
		world.setBlock(x + 9, y + 2, z + 18, 50, 2, 1);
		world.setBlock(x + 10, y + 2, z + 18, 17, 13, 1);
		world.setBlock(x + 3, y + 2, z + 19, 23, 4, 1);
		world.setBlock(x + 4, y + 2, z + 19, 77, 3, 1);
		world.setBlock(x + 7, y + 2, z + 19, 17, 13, 1);
		world.setBlock(x + 10, y + 2, z + 19, 77, 4, 1);
		world.setBlock(x + 11, y + 2, z + 19, 23, 5, 1);
		world.setBlock(x + 4, y + 2, z + 20, 17, 13, 1);
		world.setBlock(x + 10, y + 2, z + 20, 17, 13, 1);
		world.setBlock(x + 3, y + 2, z + 21, 23, 4, 1);
		world.setBlock(x + 4, y + 2, z + 21, 77, 3, 1);
		world.setBlock(x + 10, y + 2, z + 21, 77, 4, 1);
		world.setBlock(x + 11, y + 2, z + 21, 23, 5, 1);
		world.setBlock(x + 4, y + 2, z + 22, 17, 13, 1);
		world.setBlock(x + 5, y + 2, z + 22, 50, 1, 1);
		world.setBlock(x + 9, y + 2, z + 22, 50, 2, 1);
		world.setBlock(x + 10, y + 2, z + 22, 17, 13, 1);
		world.setBlock(x + 3, y + 2, z + 23, 23, 4, 1);
		world.setBlock(x + 4, y + 2, z + 23, 77, 3, 1);
		world.setBlock(x + 10, y + 2, z + 23, 77, 4, 1);
		world.setBlock(x + 11, y + 2, z + 23, 23, 5, 1);
		world.setBlock(x + 4, y + 2, z + 24, 17, 13, 1);
		world.setBlock(x + 10, y + 2, z + 24, 17, 13, 1);
		world.setBlock(x + 4, y + 2, z + 25, 17, 13, 1);
		world.setBlock(x + 7, y + 2, z + 25, 17, 1, 1);
		world.setBlock(x + 10, y + 2, z + 25, 17, 13, 1);
		world.setBlock(x + 4, y + 2, z + 26, 17, 13, 1);
		world.setBlock(x + 7, y + 2, z + 26, 65, 3, 1);
		world.setBlock(x + 10, y + 2, z + 26, 17, 13, 1);
		world.setBlock(x + 4, y + 2, z + 27, 17, 13, 1);
		world.setBlock(x + 10, y + 2, z + 27, 17, 13, 1);
		world.setBlock(x + 4, y + 2, z + 28, 17, 13, 1);
		world.setBlock(x + 7, y + 2, z + 28, 17, 13, 1);
		world.setBlock(x + 10, y + 2, z + 28, 17, 13, 1);
		world.setBlock(x + 4, y + 2, z + 29, 17, 13, 1);
		world.setBlock(x + 10, y + 2, z + 29, 17, 13, 1);
		world.setBlock(x + 5, y + 2, z + 30, 17, 13, 1);
		world.setBlock(x + 9, y + 2, z + 30, 17, 13, 1);
		world.setBlock(x + 10, y + 2, z + 30, 17, 13, 1);
		world.setBlock(x + 5, y + 2, z + 31, 17, 13, 1);
		world.setBlock(x + 6, y + 2, z + 31, 17, 13, 1);
		world.setBlock(x + 8, y + 2, z + 31, 17, 13, 1);
		world.setBlock(x + 9, y + 2, z + 31, 17, 13, 1);
		world.setBlock(x + 6, y + 2, z + 32, 17, 13, 1);
		world.setBlock(x + 7, y + 2, z + 32, 17, 13, 1);
		world.setBlock(x + 8, y + 2, z + 32, 17, 13, 1);
		world.setBlock(x + 7, y + 2, z + 33, 17, 13, 1);
		world.setBlock(x + 4, y + 3, z + 6, 17, 13, 1);
		world.setBlock(x + 5, y + 3, z + 6, 17, 13, 1);
		world.setBlock(x + 6, y + 3, z + 6, 17, 13, 1);
		world.setBlock(x + 7, y + 3, z + 6, 17, 13, 1);
		world.setBlock(x + 8, y + 3, z + 6, 17, 13, 1);
		world.setBlock(x + 9, y + 3, z + 6, 17, 13, 1);
		world.setBlock(x + 10, y + 3, z + 6, 17, 13, 1);
		world.setBlock(x + 4, y + 3, z + 7, 17, 13, 1);
		world.setBlock(x + 5, y + 3, z + 7, 17, 13, 1);
		world.setBlock(x + 6, y + 3, z + 7, 50, 3, 1);
		world.setBlock(x + 8, y + 3, z + 7, 50, 3, 1);
		world.setBlock(x + 9, y + 3, z + 7, 17, 13, 1);
		world.setBlock(x + 10, y + 3, z + 7, 17, 13, 1);
		world.setBlock(x + 4, y + 3, z + 8, 17, 13, 1);
		world.setBlock(x + 5, y + 3, z + 8, 17, 1, 1);
		world.setBlock(x + 9, y + 3, z + 8, 17, 1, 1);
		world.setBlock(x + 10, y + 3, z + 8, 17, 13, 1);
		world.setBlock(x + 4, y + 3, z + 9, 17, 13, 1);
		world.setBlock(x + 5, y + 3, z + 9, 17, 13, 1);
		world.setBlock(x + 9, y + 3, z + 9, 17, 13, 1);
		world.setBlock(x + 10, y + 3, z + 9, 17, 13, 1);
		world.setBlock(x + 4, y + 3, z + 10, 17, 13, 1);
		world.setBlock(x + 5, y + 3, z + 10, 17, 1, 1);
		world.setBlock(x + 9, y + 3, z + 10, 17, 1, 1);
		world.setBlock(x + 10, y + 3, z + 10, 17, 13, 1);
		world.setBlock(x + 4, y + 3, z + 11, 17, 13, 1);
		world.setBlock(x + 5, y + 3, z + 11, 17, 13, 1);
		world.setBlock(x + 9, y + 3, z + 11, 17, 13, 1);
		world.setBlock(x + 10, y + 3, z + 11, 17, 13, 1);
		world.setBlock(x + 4, y + 3, z + 12, 17, 13, 1);
		world.setBlock(x + 5, y + 3, z + 12, 17, 13, 1);
		world.setBlock(x + 6, y + 3, z + 12, 50, 4, 1);
		world.setBlock(x + 8, y + 3, z + 12, 50, 4, 1);
		world.setBlock(x + 9, y + 3, z + 12, 17, 13, 1);
		world.setBlock(x + 10, y + 3, z + 12, 17, 13, 1);
		world.setBlock(x + 4, y + 3, z + 13, 17, 13, 1);
		world.setBlock(x + 5, y + 3, z + 13, 17, 13, 1);
		world.setBlock(x + 6, y + 3, z + 13, 17, 13, 1);
		world.setBlock(x + 8, y + 3, z + 13, 17, 13, 1);
		world.setBlock(x + 9, y + 3, z + 13, 17, 13, 1);
		world.setBlock(x + 10, y + 3, z + 13, 17, 13, 1);
		world.setBlock(x + 4, y + 3, z + 14, 17, 13, 1);
		world.setBlock(x + 5, y + 3, z + 14, 17, 13, 1);
		world.setBlock(x + 6, y + 3, z + 14, 5, 1, 1);
		world.setBlock(x + 8, y + 3, z + 14, 5, 1, 1);
		world.setBlock(x + 9, y + 3, z + 14, 17, 13, 1);
		world.setBlock(x + 10, y + 3, z + 14, 17, 13, 1);
		world.setBlock(x + 4, y + 3, z + 15, 101, 0, 1);
		world.setBlock(x + 6, y + 3, z + 15, 5, 1, 1);
		world.setBlock(x + 7, y + 3, z + 15, 134, 2, 1);
		world.setBlock(x + 8, y + 3, z + 15, 5, 1, 1);
		world.setBlock(x + 10, y + 3, z + 15, 101, 0, 1);
		world.setBlock(x + 4, y + 3, z + 16, 17, 13, 1);
		world.setBlock(x + 7, y + 3, z + 16, 5, 1, 1);
		world.setBlock(x + 10, y + 3, z + 16, 17, 13, 1);
		world.setBlock(x + 4, y + 3, z + 17, 101, 0, 1);
		world.setBlock(x + 10, y + 3, z + 17, 101, 0, 1);
		world.setBlock(x + 4, y + 3, z + 18, 17, 13, 1);
		world.setBlock(x + 10, y + 3, z + 18, 17, 13, 1);
		world.setBlock(x + 4, y + 3, z + 19, 101, 0, 1);
		world.setBlock(x + 7, y + 3, z + 19, 17, 13, 1);
		world.setBlock(x + 10, y + 3, z + 19, 101, 0, 1);
		world.setBlock(x + 4, y + 3, z + 20, 17, 13, 1);
		world.setBlock(x + 10, y + 3, z + 20, 17, 13, 1);
		world.setBlock(x + 4, y + 3, z + 21, 101, 0, 1);
		world.setBlock(x + 10, y + 3, z + 21, 101, 0, 1);
		world.setBlock(x + 4, y + 3, z + 22, 17, 13, 1);
		world.setBlock(x + 10, y + 3, z + 22, 17, 13, 1);
		world.setBlock(x + 4, y + 3, z + 23, 101, 0, 1);
		world.setBlock(x + 10, y + 3, z + 23, 101, 0, 1);
		world.setBlock(x + 4, y + 3, z + 24, 17, 13, 1);
		world.setBlock(x + 10, y + 3, z + 24, 17, 13, 1);
		world.setBlock(x + 4, y + 3, z + 25, 17, 13, 1);
		world.setBlock(x + 7, y + 3, z + 25, 17, 1, 1);
		world.setBlock(x + 10, y + 3, z + 25, 17, 13, 1);
		world.setBlock(x + 4, y + 3, z + 26, 17, 13, 1);
		world.setBlock(x + 7, y + 3, z + 26, 65, 3, 1);
		world.setBlock(x + 10, y + 3, z + 26, 17, 13, 1);
		world.setBlock(x + 4, y + 3, z + 27, 17, 13, 1);
		world.setBlock(x + 10, y + 3, z + 27, 17, 13, 1);
		world.setBlock(x + 4, y + 3, z + 28, 17, 13, 1);
		world.setBlock(x + 7, y + 3, z + 28, 17, 13, 1);
		world.setBlock(x + 10, y + 3, z + 28, 17, 13, 1);
		world.setBlock(x + 4, y + 3, z + 29, 17, 13, 1);
		world.setBlock(x + 10, y + 3, z + 29, 17, 13, 1);
		world.setBlock(x + 4, y + 3, z + 30, 17, 13, 1);
		world.setBlock(x + 10, y + 3, z + 30, 17, 13, 1);
		world.setBlock(x + 4, y + 3, z + 31, 17, 13, 1);
		world.setBlock(x + 10, y + 3, z + 31, 17, 13, 1);
		world.setBlock(x + 5, y + 3, z + 32, 17, 13, 1);
		world.setBlock(x + 6, y + 3, z + 32, 17, 13, 1);
		world.setBlock(x + 8, y + 3, z + 32, 17, 13, 1);
		world.setBlock(x + 9, y + 3, z + 32, 17, 13, 1);
		world.setBlock(x + 6, y + 3, z + 33, 17, 13, 1);
		world.setBlock(x + 7, y + 3, z + 33, 17, 13, 1);
		world.setBlock(x + 8, y + 3, z + 33, 17, 13, 1);
		world.setBlock(x + 7, y + 3, z + 34, 17, 13, 1);
		world.setBlock(x + 4, y + 4, z + 5, 17, 13, 1);
		world.setBlock(x + 5, y + 4, z + 5, 17, 13, 1);
		world.setBlock(x + 6, y + 4, z + 5, 17, 13, 1);
		world.setBlock(x + 7, y + 4, z + 5, 17, 13, 1);
		world.setBlock(x + 8, y + 4, z + 5, 17, 13, 1);
		world.setBlock(x + 9, y + 4, z + 5, 17, 13, 1);
		world.setBlock(x + 10, y + 4, z + 5, 17, 13, 1);
		world.setBlock(x + 4, y + 4, z + 6, 17, 13, 1);
		world.setBlock(x + 5, y + 4, z + 6, 17, 13, 1);
		world.setBlock(x + 6, y + 4, z + 6, 17, 13, 1);
		world.setBlock(x + 7, y + 4, z + 6, 17, 13, 1);
		world.setBlock(x + 8, y + 4, z + 6, 17, 13, 1);
		world.setBlock(x + 9, y + 4, z + 6, 17, 13, 1);
		world.setBlock(x + 10, y + 4, z + 6, 17, 13, 1);
		world.setBlock(x + 4, y + 4, z + 7, 20, 0, 1);
		world.setBlock(x + 10, y + 4, z + 7, 20, 0, 1);
		world.setBlock(x + 4, y + 4, z + 8, 17, 13, 1);
		world.setBlock(x + 5, y + 4, z + 8, 17, 13, 1);
		world.setBlock(x + 9, y + 4, z + 8, 17, 13, 1);
		world.setBlock(x + 10, y + 4, z + 8, 17, 13, 1);
		world.setBlock(x + 4, y + 4, z + 9, 20, 0, 1);
		world.setBlock(x + 10, y + 4, z + 9, 20, 0, 1);
		world.setBlock(x + 4, y + 4, z + 10, 17, 13, 1);
		world.setBlock(x + 5, y + 4, z + 10, 17, 13, 1);
		world.setBlock(x + 9, y + 4, z + 10, 17, 13, 1);
		world.setBlock(x + 10, y + 4, z + 10, 17, 13, 1);
		world.setBlock(x + 4, y + 4, z + 11, 20, 0, 1);
		world.setBlock(x + 10, y + 4, z + 11, 20, 0, 1);
		world.setBlock(x + 4, y + 4, z + 12, 17, 13, 1);
		world.setBlock(x + 5, y + 4, z + 12, 17, 13, 1);
		world.setBlock(x + 9, y + 4, z + 12, 17, 13, 1);
		world.setBlock(x + 10, y + 4, z + 12, 17, 13, 1);
		world.setBlock(x + 4, y + 4, z + 13, 17, 13, 1);
		world.setBlock(x + 5, y + 4, z + 13, 17, 13, 1);
		world.setBlock(x + 6, y + 4, z + 13, 17, 13, 1);
		world.setBlock(x + 8, y + 4, z + 13, 17, 13, 1);
		world.setBlock(x + 9, y + 4, z + 13, 17, 13, 1);
		world.setBlock(x + 10, y + 4, z + 13, 17, 13, 1);
		world.setBlock(x + 3, y + 4, z + 14, 17, 13, 1);
		world.setBlock(x + 4, y + 4, z + 14, 5, 1, 1);
		world.setBlock(x + 5, y + 4, z + 14, 5, 1, 1);
		world.setBlock(x + 6, y + 4, z + 14, 5, 1, 1);
		world.setBlock(x + 8, y + 4, z + 14, 5, 1, 1);
		world.setBlock(x + 9, y + 4, z + 14, 5, 1, 1);
		world.setBlock(x + 10, y + 4, z + 14, 5, 1, 1);
		world.setBlock(x + 11, y + 4, z + 14, 17, 13, 1);
		world.setBlock(x + 3, y + 4, z + 15, 17, 13, 1);
		world.setBlock(x + 4, y + 4, z + 15, 5, 1, 1);
		world.setBlock(x + 5, y + 4, z + 15, 5, 1, 1);
		world.setBlock(x + 6, y + 4, z + 15, 5, 1, 1);
		world.setBlock(x + 8, y + 4, z + 15, 5, 1, 1);
		world.setBlock(x + 9, y + 4, z + 15, 5, 1, 1);
		world.setBlock(x + 10, y + 4, z + 15, 5, 1, 1);
		world.setBlock(x + 11, y + 4, z + 15, 17, 13, 1);
		world.setBlock(x + 3, y + 4, z + 16, 17, 13, 1);
		world.setBlock(x + 4, y + 4, z + 16, 5, 1, 1);
		world.setBlock(x + 5, y + 4, z + 16, 5, 1, 1);
		world.setBlock(x + 6, y + 4, z + 16, 5, 1, 1);
		world.setBlock(x + 7, y + 4, z + 16, 134, 2, 1);
		world.setBlock(x + 8, y + 4, z + 16, 5, 1, 1);
		world.setBlock(x + 9, y + 4, z + 16, 5, 1, 1);
		world.setBlock(x + 10, y + 4, z + 16, 5, 1, 1);
		world.setBlock(x + 11, y + 4, z + 16, 17, 13, 1);
		world.setBlock(x + 3, y + 4, z + 17, 17, 13, 1);
		world.setBlock(x + 4, y + 4, z + 17, 5, 1, 1);
		world.setBlock(x + 5, y + 4, z + 17, 5, 1, 1);
		world.setBlock(x + 6, y + 4, z + 17, 5, 1, 1);
		world.setBlock(x + 7, y + 4, z + 17, 5, 1, 1);
		world.setBlock(x + 8, y + 4, z + 17, 5, 1, 1);
		world.setBlock(x + 9, y + 4, z + 17, 5, 1, 1);
		world.setBlock(x + 10, y + 4, z + 17, 5, 1, 1);
		world.setBlock(x + 11, y + 4, z + 17, 17, 13, 1);
		world.setBlock(x + 3, y + 4, z + 18, 17, 13, 1);
		world.setBlock(x + 4, y + 4, z + 18, 5, 1, 1);
		world.setBlock(x + 5, y + 4, z + 18, 5, 1, 1);
		world.setBlock(x + 6, y + 4, z + 18, 5, 1, 1);
		world.setBlock(x + 7, y + 4, z + 18, 5, 1, 1);
		world.setBlock(x + 8, y + 4, z + 18, 5, 1, 1);
		world.setBlock(x + 9, y + 4, z + 18, 5, 1, 1);
		world.setBlock(x + 10, y + 4, z + 18, 5, 1, 1);
		world.setBlock(x + 11, y + 4, z + 18, 17, 13, 1);
		world.setBlock(x + 3, y + 4, z + 19, 17, 13, 1);
		world.setBlock(x + 4, y + 4, z + 19, 5, 1, 1);
		world.setBlock(x + 5, y + 4, z + 19, 5, 1, 1);
		world.setBlock(x + 6, y + 4, z + 19, 5, 1, 1);
		world.setBlock(x + 7, y + 4, z + 19, 17, 13, 1);
		world.setBlock(x + 8, y + 4, z + 19, 5, 1, 1);
		world.setBlock(x + 9, y + 4, z + 19, 5, 1, 1);
		world.setBlock(x + 10, y + 4, z + 19, 5, 1, 1);
		world.setBlock(x + 11, y + 4, z + 19, 17, 13, 1);
		world.setBlock(x + 3, y + 4, z + 20, 17, 13, 1);
		world.setBlock(x + 4, y + 4, z + 20, 5, 1, 1);
		world.setBlock(x + 5, y + 4, z + 20, 5, 1, 1);
		world.setBlock(x + 6, y + 4, z + 20, 5, 1, 1);
		world.setBlock(x + 7, y + 4, z + 20, 5, 1, 1);
		world.setBlock(x + 8, y + 4, z + 20, 5, 1, 1);
		world.setBlock(x + 9, y + 4, z + 20, 5, 1, 1);
		world.setBlock(x + 10, y + 4, z + 20, 5, 1, 1);
		world.setBlock(x + 11, y + 4, z + 20, 17, 13, 1);
		world.setBlock(x + 3, y + 4, z + 21, 17, 13, 1);
		world.setBlock(x + 4, y + 4, z + 21, 5, 1, 1);
		world.setBlock(x + 5, y + 4, z + 21, 5, 1, 1);
		world.setBlock(x + 6, y + 4, z + 21, 5, 1, 1);
		world.setBlock(x + 7, y + 4, z + 21, 5, 1, 1);
		world.setBlock(x + 8, y + 4, z + 21, 5, 1, 1);
		world.setBlock(x + 9, y + 4, z + 21, 5, 1, 1);
		world.setBlock(x + 10, y + 4, z + 21, 5, 1, 1);
		world.setBlock(x + 11, y + 4, z + 21, 17, 13, 1);
		world.setBlock(x + 3, y + 4, z + 22, 17, 13, 1);
		world.setBlock(x + 4, y + 4, z + 22, 5, 1, 1);
		world.setBlock(x + 5, y + 4, z + 22, 5, 1, 1);
		world.setBlock(x + 6, y + 4, z + 22, 5, 1, 1);
		world.setBlock(x + 7, y + 4, z + 22, 5, 1, 1);
		world.setBlock(x + 8, y + 4, z + 22, 5, 1, 1);
		world.setBlock(x + 9, y + 4, z + 22, 5, 1, 1);
		world.setBlock(x + 10, y + 4, z + 22, 5, 1, 1);
		world.setBlock(x + 11, y + 4, z + 22, 17, 13, 1);
		world.setBlock(x + 3, y + 4, z + 23, 17, 13, 1);
		world.setBlock(x + 4, y + 4, z + 23, 5, 1, 1);
		world.setBlock(x + 5, y + 4, z + 23, 5, 1, 1);
		world.setBlock(x + 6, y + 4, z + 23, 5, 1, 1);
		world.setBlock(x + 7, y + 4, z + 23, 5, 1, 1);
		world.setBlock(x + 8, y + 4, z + 23, 5, 1, 1);
		world.setBlock(x + 9, y + 4, z + 23, 5, 1, 1);
		world.setBlock(x + 10, y + 4, z + 23, 5, 1, 1);
		world.setBlock(x + 11, y + 4, z + 23, 17, 13, 1);
		world.setBlock(x + 3, y + 4, z + 24, 17, 13, 1);
		world.setBlock(x + 4, y + 4, z + 24, 5, 1, 1);
		world.setBlock(x + 5, y + 4, z + 24, 5, 1, 1);
		world.setBlock(x + 6, y + 4, z + 24, 5, 1, 1);
		world.setBlock(x + 7, y + 4, z + 24, 5, 1, 1);
		world.setBlock(x + 8, y + 4, z + 24, 5, 1, 1);
		world.setBlock(x + 9, y + 4, z + 24, 5, 1, 1);
		world.setBlock(x + 10, y + 4, z + 24, 5, 1, 1);
		world.setBlock(x + 11, y + 4, z + 24, 17, 13, 1);
		world.setBlock(x + 4, y + 4, z + 25, 20, 0, 1);
		world.setBlock(x + 7, y + 4, z + 25, 17, 1, 1);
		world.setBlock(x + 10, y + 4, z + 25, 20, 0, 1);
		world.setBlock(x + 4, y + 4, z + 26, 17, 13, 1);
		world.setBlock(x + 5, y + 4, z + 26, 50, 1, 1);
		world.setBlock(x + 7, y + 4, z + 26, 65, 3, 1);
		world.setBlock(x + 9, y + 4, z + 26, 50, 2, 1);
		world.setBlock(x + 10, y + 4, z + 26, 17, 13, 1);
		world.setBlock(x + 4, y + 4, z + 27, 20, 0, 1);
		world.setBlock(x + 10, y + 4, z + 27, 20, 0, 1);
		world.setBlock(x + 4, y + 4, z + 28, 17, 13, 1);
		world.setBlock(x + 5, y + 4, z + 28, 50, 1, 1);
		world.setBlock(x + 7, y + 4, z + 28, 17, 13, 1);
		world.setBlock(x + 9, y + 4, z + 28, 50, 2, 1);
		world.setBlock(x + 10, y + 4, z + 28, 17, 13, 1);
		world.setBlock(x + 4, y + 4, z + 29, 20, 0, 1);
		world.setBlock(x + 10, y + 4, z + 29, 20, 0, 1);
		world.setBlock(x + 4, y + 4, z + 30, 17, 13, 1);
		world.setBlock(x + 10, y + 4, z + 30, 17, 13, 1);
		world.setBlock(x + 4, y + 4, z + 31, 17, 13, 1);
		world.setBlock(x + 10, y + 4, z + 31, 20, 0, 1);
		world.setBlock(x + 4, y + 4, z + 32, 17, 13, 1);
		world.setBlock(x + 5, y + 4, z + 32, 17, 13, 1);
		world.setBlock(x + 10, y + 4, z + 32, 17, 13, 1);
		world.setBlock(x + 5, y + 4, z + 33, 17, 13, 1);
		world.setBlock(x + 6, y + 4, z + 33, 17, 13, 1);
		world.setBlock(x + 7, y + 4, z + 33, 50, 4, 1);
		world.setBlock(x + 8, y + 4, z + 33, 17, 13, 1);
		world.setBlock(x + 9, y + 4, z + 33, 17, 13, 1);
		world.setBlock(x + 6, y + 4, z + 34, 17, 13, 1);
		world.setBlock(x + 7, y + 4, z + 34, 17, 13, 1);
		world.setBlock(x + 8, y + 4, z + 34, 17, 13, 1);
		world.setBlock(x + 7, y + 4, z + 35, 17, 13, 1);
		world.setBlock(x + 4, y + 5, z + 2, 17, 13, 1);
		world.setBlock(x + 5, y + 5, z + 2, 17, 13, 1);
		world.setBlock(x + 6, y + 5, z + 2, 17, 13, 1);
		world.setBlock(x + 7, y + 5, z + 2, 17, 13, 1);
		world.setBlock(x + 8, y + 5, z + 2, 17, 13, 1);
		world.setBlock(x + 9, y + 5, z + 2, 17, 13, 1);
		world.setBlock(x + 10, y + 5, z + 2, 17, 13, 1);
		world.setBlock(x + 4, y + 5, z + 3, 17, 13, 1);
		world.setBlock(x + 5, y + 5, z + 3, 17, 13, 1);
		world.setBlock(x + 6, y + 5, z + 3, 17, 13, 1);
		world.setBlock(x + 7, y + 5, z + 3, 17, 13, 1);
		world.setBlock(x + 8, y + 5, z + 3, 17, 13, 1);
		world.setBlock(x + 9, y + 5, z + 3, 17, 13, 1);
		world.setBlock(x + 10, y + 5, z + 3, 17, 13, 1);
		world.setBlock(x + 4, y + 5, z + 4, 17, 13, 1);
		world.setBlock(x + 5, y + 5, z + 4, 17, 13, 1);
		world.setBlock(x + 6, y + 5, z + 4, 17, 13, 1);
		world.setBlock(x + 7, y + 5, z + 4, 17, 13, 1);
		world.setBlock(x + 8, y + 5, z + 4, 17, 13, 1);
		world.setBlock(x + 9, y + 5, z + 4, 17, 13, 1);
		world.setBlock(x + 10, y + 5, z + 4, 17, 13, 1);
		world.setBlock(x + 3, y + 5, z + 5, 17, 13, 1);
		world.setBlock(x + 4, y + 5, z + 5, 17, 13, 1);
		world.setBlock(x + 5, y + 5, z + 5, 17, 13, 1);
		world.setBlock(x + 6, y + 5, z + 5, 17, 13, 1);
		world.setBlock(x + 7, y + 5, z + 5, 17, 13, 1);
		world.setBlock(x + 8, y + 5, z + 5, 17, 13, 1);
		world.setBlock(x + 9, y + 5, z + 5, 17, 13, 1);
		world.setBlock(x + 10, y + 5, z + 5, 17, 13, 1);
		world.setBlock(x + 11, y + 5, z + 5, 17, 13, 1);
		world.setBlock(x + 3, y + 5, z + 6, 17, 13, 1);
		world.setBlock(x + 4, y + 5, z + 6, 17, 13, 1);
		world.setBlock(x + 5, y + 5, z + 6, 17, 13, 1);
		world.setBlock(x + 6, y + 5, z + 6, 17, 13, 1);
		world.setBlock(x + 7, y + 5, z + 6, 17, 13, 1);
		world.setBlock(x + 8, y + 5, z + 6, 17, 13, 1);
		world.setBlock(x + 9, y + 5, z + 6, 5, 1, 1);
		world.setBlock(x + 10, y + 5, z + 6, 17, 13, 1);
		world.setBlock(x + 11, y + 5, z + 6, 17, 13, 1);
		world.setBlock(x + 3, y + 5, z + 7, 17, 13, 1);
		world.setBlock(x + 4, y + 5, z + 7, 17, 13, 1);
		world.setBlock(x + 5, y + 5, z + 7, 5, 1, 1);
		world.setBlock(x + 6, y + 5, z + 7, 5, 1, 1);
		world.setBlock(x + 7, y + 5, z + 7, 5, 1, 1);
		world.setBlock(x + 8, y + 5, z + 7, 5, 1, 1);
		world.setBlock(x + 9, y + 5, z + 7, 5, 1, 1);
		world.setBlock(x + 10, y + 5, z + 7, 17, 13, 1);
		world.setBlock(x + 11, y + 5, z + 7, 17, 13, 1);
		world.setBlock(x + 3, y + 5, z + 8, 17, 13, 1);
		world.setBlock(x + 4, y + 5, z + 8, 17, 13, 1);
		world.setBlock(x + 5, y + 5, z + 8, 5, 1, 1);
		world.setBlock(x + 6, y + 5, z + 8, 5, 1, 1);
		world.setBlock(x + 7, y + 5, z + 8, 5, 1, 1);
		world.setBlock(x + 8, y + 5, z + 8, 5, 1, 1);
		world.setBlock(x + 9, y + 5, z + 8, 5, 1, 1);
		world.setBlock(x + 10, y + 5, z + 8, 17, 13, 1);
		world.setBlock(x + 11, y + 5, z + 8, 17, 13, 1);
		world.setBlock(x + 3, y + 5, z + 9, 17, 13, 1);
		world.setBlock(x + 4, y + 5, z + 9, 17, 13, 1);
		world.setBlock(x + 5, y + 5, z + 9, 5, 1, 1);
		world.setBlock(x + 6, y + 5, z + 9, 5, 1, 1);
		world.setBlock(x + 7, y + 5, z + 9, 5, 1, 1);
		world.setBlock(x + 8, y + 5, z + 9, 5, 1, 1);
		world.setBlock(x + 9, y + 5, z + 9, 5, 1, 1);
		world.setBlock(x + 10, y + 5, z + 9, 17, 13, 1);
		world.setBlock(x + 11, y + 5, z + 9, 17, 13, 1);
		world.setBlock(x + 3, y + 5, z + 10, 17, 13, 1);
		world.setBlock(x + 4, y + 5, z + 10, 17, 13, 1);
		world.setBlock(x + 5, y + 5, z + 10, 5, 1, 1);
		world.setBlock(x + 6, y + 5, z + 10, 5, 1, 1);
		world.setBlock(x + 7, y + 5, z + 10, 5, 1, 1);
		world.setBlock(x + 8, y + 5, z + 10, 5, 1, 1);
		world.setBlock(x + 9, y + 5, z + 10, 5, 1, 1);
		world.setBlock(x + 10, y + 5, z + 10, 17, 13, 1);
		world.setBlock(x + 11, y + 5, z + 10, 17, 13, 1);
		world.setBlock(x + 3, y + 5, z + 11, 17, 13, 1);
		world.setBlock(x + 4, y + 5, z + 11, 17, 13, 1);
		world.setBlock(x + 5, y + 5, z + 11, 5, 1, 1);
		world.setBlock(x + 6, y + 5, z + 11, 5, 1, 1);
		world.setBlock(x + 7, y + 5, z + 11, 5, 1, 1);
		world.setBlock(x + 8, y + 5, z + 11, 5, 1, 1);
		world.setBlock(x + 9, y + 5, z + 11, 5, 1, 1);
		world.setBlock(x + 10, y + 5, z + 11, 17, 13, 1);
		world.setBlock(x + 11, y + 5, z + 11, 17, 13, 1);
		world.setBlock(x + 3, y + 5, z + 12, 17, 13, 1);
		world.setBlock(x + 4, y + 5, z + 12, 17, 13, 1);
		world.setBlock(x + 5, y + 5, z + 12, 5, 1, 1);
		world.setBlock(x + 6, y + 5, z + 12, 5, 1, 1);
		world.setBlock(x + 7, y + 5, z + 12, 5, 1, 1);
		world.setBlock(x + 8, y + 5, z + 12, 5, 1, 1);
		world.setBlock(x + 9, y + 5, z + 12, 5, 1, 1);
		world.setBlock(x + 10, y + 5, z + 12, 17, 13, 1);
		world.setBlock(x + 11, y + 5, z + 12, 17, 13, 1);
		world.setBlock(x + 3, y + 5, z + 13, 17, 13, 1);
		world.setBlock(x + 4, y + 5, z + 13, 134, 3, 1);
		world.setBlock(x + 5, y + 5, z + 13, 17, 13, 1);
		world.setBlock(x + 6, y + 5, z + 13, 17, 13, 1);
		world.setBlock(x + 7, y + 5, z + 13, 17, 13, 1);
		world.setBlock(x + 8, y + 5, z + 13, 17, 13, 1);
		world.setBlock(x + 9, y + 5, z + 13, 17, 13, 1);
		world.setBlock(x + 10, y + 5, z + 13, 134, 3, 1);
		world.setBlock(x + 11, y + 5, z + 13, 17, 13, 1);
		world.setBlock(x + 3, y + 5, z + 14, 17, 13, 1);
		world.setBlock(x + 11, y + 5, z + 14, 17, 13, 1);
		world.setBlock(x + 3, y + 5, z + 15, 85, 0, 1);
		world.setBlock(x + 11, y + 5, z + 15, 85, 0, 1);
		world.setBlock(x + 3, y + 5, z + 16, 85, 0, 1);
		world.setBlock(x + 11, y + 5, z + 16, 85, 0, 1);
		world.setBlock(x + 3, y + 5, z + 17, 85, 0, 1);
		world.setBlock(x + 11, y + 5, z + 17, 85, 0, 1);
		world.setBlock(x + 3, y + 5, z + 18, 85, 0, 1);
		world.setBlock(x + 7, y + 5, z + 18, 65, 2, 1);
		world.setBlock(x + 11, y + 5, z + 18, 85, 0, 1);
		world.setBlock(x + 3, y + 5, z + 19, 107, 1, 1);
		world.setBlock(x + 6, y + 5, z + 19, 134, 0, 1);
		world.setBlock(x + 7, y + 5, z + 19, 17, 13, 1);
		world.setBlock(x + 8, y + 5, z + 19, 134, 1, 1);
		world.setBlock(x + 11, y + 5, z + 19, 85, 0, 1);
		world.setBlock(x + 3, y + 5, z + 20, 85, 0, 1);
		world.setBlock(x + 7, y + 5, z + 20, 134, 3, 1);
		world.setBlock(x + 11, y + 5, z + 20, 85, 0, 1);
		world.setBlock(x + 3, y + 5, z + 21, 85, 0, 1);
		world.setBlock(x + 11, y + 5, z + 21, 85, 0, 1);
		world.setBlock(x + 3, y + 5, z + 22, 85, 0, 1);
		world.setBlock(x + 11, y + 5, z + 22, 85, 0, 1);
		world.setBlock(x + 3, y + 5, z + 23, 85, 0, 1);
		world.setBlock(x + 11, y + 5, z + 23, 85, 0, 1);
		world.setBlock(x + 3, y + 5, z + 24, 17, 13, 1);
		world.setBlock(x + 11, y + 5, z + 24, 17, 13, 1);
		world.setBlock(x + 3, y + 5, z + 25, 17, 13, 1);
		world.setBlock(x + 4, y + 5, z + 25, 134, 2, 1);
		world.setBlock(x + 5, y + 5, z + 25, 134, 2, 1);
		world.setBlock(x + 6, y + 5, z + 25, 17, 1, 1);
		world.setBlock(x + 7, y + 5, z + 25, 17, 13, 1);
		world.setBlock(x + 8, y + 5, z + 25, 17, 13, 1);
		world.setBlock(x + 9, y + 5, z + 25, 134, 2, 1);
		world.setBlock(x + 10, y + 5, z + 25, 134, 2, 1);
		world.setBlock(x + 11, y + 5, z + 25, 17, 13, 1);
		world.setBlock(x + 3, y + 5, z + 26, 17, 13, 1);
		world.setBlock(x + 7, y + 5, z + 26, 65, 3, 1);
		world.setBlock(x + 11, y + 5, z + 26, 17, 13, 1);
		world.setBlock(x + 3, y + 5, z + 27, 17, 13, 1);
		world.setBlock(x + 11, y + 5, z + 27, 17, 13, 1);
		world.setBlock(x + 3, y + 5, z + 28, 17, 13, 1);
		world.setBlock(x + 7, y + 5, z + 28, 17, 13, 1);
		world.setBlock(x + 11, y + 5, z + 28, 17, 13, 1);
		world.setBlock(x + 3, y + 5, z + 29, 17, 13, 1);
		world.setBlock(x + 11, y + 5, z + 29, 17, 13, 1);
		world.setBlock(x + 3, y + 5, z + 30, 17, 13, 1);
		world.setBlock(x + 11, y + 5, z + 30, 17, 13, 1);
		world.setBlock(x + 3, y + 5, z + 31, 17, 13, 1);
		world.setBlock(x + 11, y + 5, z + 31, 17, 13, 1);
		world.setBlock(x + 4, y + 5, z + 32, 17, 13, 1);
		world.setBlock(x + 10, y + 5, z + 32, 17, 13, 1);
		world.setBlock(x + 4, y + 5, z + 33, 17, 13, 1);
		world.setBlock(x + 5, y + 5, z + 33, 17, 13, 1);
		world.setBlock(x + 9, y + 5, z + 33, 17, 13, 1);
		world.setBlock(x + 10, y + 5, z + 33, 17, 13, 1);
		world.setBlock(x + 5, y + 5, z + 34, 17, 13, 1);
		world.setBlock(x + 6, y + 5, z + 34, 17, 13, 1);
		world.setBlock(x + 8, y + 5, z + 34, 17, 13, 1);
		world.setBlock(x + 9, y + 5, z + 34, 17, 13, 1);
		world.setBlock(x + 6, y + 5, z + 35, 17, 13, 1);
		world.setBlock(x + 7, y + 5, z + 35, 17, 13, 1);
		world.setBlock(x + 8, y + 5, z + 35, 17, 13, 1);
		world.setBlock(x + 7, y + 5, z + 36, 17, 13, 1);
		world.setBlock(x + 3, y + 6, z + 1, 17, 13, 1);
		world.setBlock(x + 4, y + 6, z + 1, 17, 13, 1);
		world.setBlock(x + 5, y + 6, z + 1, 17, 13, 1);
		world.setBlock(x + 6, y + 6, z + 1, 17, 13, 1);
		world.setBlock(x + 7, y + 6, z + 1, 17, 13, 1);
		world.setBlock(x + 8, y + 6, z + 1, 17, 13, 1);
		world.setBlock(x + 9, y + 6, z + 1, 17, 13, 1);
		world.setBlock(x + 10, y + 6, z + 1, 17, 13, 1);
		world.setBlock(x + 11, y + 6, z + 1, 17, 13, 1);
		world.setBlock(x + 3, y + 6, z + 2, 17, 13, 1);
		world.setBlock(x + 4, y + 6, z + 2, 5, 1, 1);
		world.setBlock(x + 5, y + 6, z + 2, 5, 1, 1);
		world.setBlock(x + 6, y + 6, z + 2, 5, 1, 1);
		world.setBlock(x + 7, y + 6, z + 2, 5, 1, 1);
		world.setBlock(x + 8, y + 6, z + 2, 5, 1, 1);
		world.setBlock(x + 9, y + 6, z + 2, 5, 1, 1);
		world.setBlock(x + 10, y + 6, z + 2, 5, 1, 1);
		world.setBlock(x + 11, y + 6, z + 2, 17, 13, 1);
		world.setBlock(x + 3, y + 6, z + 3, 17, 13, 1);
		world.setBlock(x + 4, y + 6, z + 3, 5, 1, 1);
		world.setBlock(x + 5, y + 6, z + 3, 5, 1, 1);
		world.setBlock(x + 6, y + 6, z + 3, 5, 1, 1);
		world.setBlock(x + 7, y + 6, z + 3, 5, 1, 1);
		world.setBlock(x + 8, y + 6, z + 3, 5, 1, 1);
		world.setBlock(x + 9, y + 6, z + 3, 5, 1, 1);
		world.setBlock(x + 10, y + 6, z + 3, 5, 1, 1);
		world.setBlock(x + 11, y + 6, z + 3, 17, 13, 1);
		world.setBlock(x + 3, y + 6, z + 4, 17, 13, 1);
		world.setBlock(x + 4, y + 6, z + 4, 5, 1, 1);
		world.setBlock(x + 5, y + 6, z + 4, 5, 1, 1);
		world.setBlock(x + 6, y + 6, z + 4, 5, 1, 1);
		world.setBlock(x + 7, y + 6, z + 4, 5, 1, 1);
		world.setBlock(x + 8, y + 6, z + 4, 5, 1, 1);
		world.setBlock(x + 9, y + 6, z + 4, 5, 1, 1);
		world.setBlock(x + 10, y + 6, z + 4, 5, 1, 1);
		world.setBlock(x + 11, y + 6, z + 4, 17, 13, 1);
		world.setBlock(x + 3, y + 6, z + 5, 17, 13, 1);
		world.setBlock(x + 4, y + 6, z + 5, 5, 1, 1);
		world.setBlock(x + 5, y + 6, z + 5, 5, 1, 1);
		world.setBlock(x + 6, y + 6, z + 5, 5, 1, 1);
		world.setBlock(x + 7, y + 6, z + 5, 5, 1, 1);
		world.setBlock(x + 8, y + 6, z + 5, 5, 1, 1);
		world.setBlock(x + 9, y + 6, z + 5, 5, 1, 1);
		world.setBlock(x + 10, y + 6, z + 5, 5, 1, 1);
		world.setBlock(x + 11, y + 6, z + 5, 17, 13, 1);
		world.setBlock(x + 3, y + 6, z + 6, 17, 13, 1);
		world.setBlock(x + 4, y + 6, z + 6, 5, 1, 1);
		world.setBlock(x + 5, y + 6, z + 6, 5, 1, 1);
		world.setBlock(x + 6, y + 6, z + 6, 5, 1, 1);
		world.setBlock(x + 7, y + 6, z + 6, 5, 1, 1);
		world.setBlock(x + 8, y + 6, z + 6, 5, 1, 1);
		world.setBlock(x + 9, y + 6, z + 6, 5, 1, 1);
		world.setBlock(x + 10, y + 6, z + 6, 5, 1, 1);
		world.setBlock(x + 11, y + 6, z + 6, 17, 13, 1);
		world.setBlock(x + 3, y + 6, z + 7, 17, 13, 1);
		world.setBlock(x + 4, y + 6, z + 7, 17, 13, 1);
		world.setBlock(x + 5, y + 6, z + 7, 5, 1, 1);
		world.setBlock(x + 6, y + 6, z + 7, 5, 1, 1);
		world.setBlock(x + 7, y + 6, z + 7, 5, 1, 1);
		world.setBlock(x + 8, y + 6, z + 7, 5, 1, 1);
		world.setBlock(x + 9, y + 6, z + 7, 5, 1, 1);
		world.setBlock(x + 10, y + 6, z + 7, 17, 13, 1);
		world.setBlock(x + 11, y + 6, z + 7, 17, 13, 1);
		world.setBlock(x + 3, y + 6, z + 8, 17, 13, 1);
		world.setBlock(x + 4, y + 6, z + 8, 17, 13, 1);
		world.setBlock(x + 5, y + 6, z + 8, 5, 1, 1);
		world.setBlock(x + 6, y + 6, z + 8, 5, 1, 1);
		world.setBlock(x + 7, y + 6, z + 8, 5, 1, 1);
		world.setBlock(x + 8, y + 6, z + 8, 5, 1, 1);
		world.setBlock(x + 9, y + 6, z + 8, 5, 1, 1);
		world.setBlock(x + 10, y + 6, z + 8, 17, 13, 1);
		world.setBlock(x + 11, y + 6, z + 8, 17, 13, 1);
		world.setBlock(x + 3, y + 6, z + 9, 17, 13, 1);
		world.setBlock(x + 4, y + 6, z + 9, 17, 13, 1);
		world.setBlock(x + 5, y + 6, z + 9, 5, 1, 1);
		world.setBlock(x + 6, y + 6, z + 9, 5, 1, 1);
		world.setBlock(x + 7, y + 6, z + 9, 5, 1, 1);
		world.setBlock(x + 8, y + 6, z + 9, 5, 1, 1);
		world.setBlock(x + 9, y + 6, z + 9, 5, 1, 1);
		world.setBlock(x + 10, y + 6, z + 9, 17, 13, 1);
		world.setBlock(x + 11, y + 6, z + 9, 17, 13, 1);
		world.setBlock(x + 3, y + 6, z + 10, 17, 13, 1);
		world.setBlock(x + 4, y + 6, z + 10, 5, 1, 1);
		world.setBlock(x + 5, y + 6, z + 10, 5, 1, 1);
		world.setBlock(x + 6, y + 6, z + 10, 5, 1, 1);
		world.setBlock(x + 7, y + 6, z + 10, 5, 1, 1);
		world.setBlock(x + 8, y + 6, z + 10, 5, 1, 1);
		world.setBlock(x + 9, y + 6, z + 10, 5, 1, 1);
		world.setBlock(x + 10, y + 6, z + 10, 5, 1, 1);
		world.setBlock(x + 11, y + 6, z + 10, 17, 13, 1);
		world.setBlock(x + 3, y + 6, z + 11, 17, 13, 1);
		world.setBlock(x + 4, y + 6, z + 11, 5, 1, 1);
		world.setBlock(x + 5, y + 6, z + 11, 5, 1, 1);
		world.setBlock(x + 6, y + 6, z + 11, 5, 1, 1);
		world.setBlock(x + 7, y + 6, z + 11, 17, 0, 1);
		world.setBlock(x + 8, y + 6, z + 11, 5, 1, 1);
		world.setBlock(x + 9, y + 6, z + 11, 5, 1, 1);
		world.setBlock(x + 10, y + 6, z + 11, 5, 1, 1);
		world.setBlock(x + 11, y + 6, z + 11, 17, 13, 1);
		world.setBlock(x + 3, y + 6, z + 12, 17, 13, 1);
		world.setBlock(x + 4, y + 6, z + 12, 134, 3, 1);
		world.setBlock(x + 5, y + 6, z + 12, 5, 1, 1);
		world.setBlock(x + 6, y + 6, z + 12, 5, 1, 1);
		world.setBlock(x + 7, y + 6, z + 12, 5, 1, 1);
		world.setBlock(x + 8, y + 6, z + 12, 5, 1, 1);
		world.setBlock(x + 9, y + 6, z + 12, 5, 1, 1);
		world.setBlock(x + 10, y + 6, z + 12, 134, 3, 1);
		world.setBlock(x + 11, y + 6, z + 12, 17, 13, 1);
		world.setBlock(x + 3, y + 6, z + 13, 17, 13, 1);
		world.setBlock(x + 5, y + 6, z + 13, 17, 13, 1);
		world.setBlock(x + 6, y + 6, z + 13, 17, 13, 1);
		world.setBlock(x + 7, y + 6, z + 13, 17, 13, 1);
		world.setBlock(x + 8, y + 6, z + 13, 17, 13, 1);
		world.setBlock(x + 9, y + 6, z + 13, 17, 13, 1);
		world.setBlock(x + 11, y + 6, z + 13, 17, 13, 1);
		world.setBlock(x + 3, y + 6, z + 14, 85, 0, 1);
		world.setBlock(x + 6, y + 6, z + 14, 50, 3, 1);
		world.setBlock(x + 8, y + 6, z + 14, 50, 3, 1);
		world.setBlock(x + 11, y + 6, z + 14, 85, 0, 1);
		world.setBlock(x + 3, y + 6, z + 15, 85, 0, 1);
		world.setBlock(x + 11, y + 6, z + 15, 85, 0, 1);
		world.setBlock(x + 3, y + 6, z + 18, 50, 5, 1);
		world.setBlock(x + 7, y + 6, z + 18, 65, 2, 1);
		world.setBlock(x + 7, y + 6, z + 19, 17, 13, 1);
		world.setBlock(x + 3, y + 6, z + 20, 50, 5, 1);
		world.setBlock(x + 3, y + 6, z + 23, 85, 0, 1);
		world.setBlock(x + 11, y + 6, z + 23, 85, 0, 1);
		world.setBlock(x + 3, y + 6, z + 24, 85, 0, 1);
		world.setBlock(x + 6, y + 6, z + 24, 50, 4, 1);
		world.setBlock(x + 8, y + 6, z + 24, 50, 4, 1);
		world.setBlock(x + 11, y + 6, z + 24, 85, 0, 1);
		world.setBlock(x + 3, y + 6, z + 25, 85, 0, 1);
		world.setBlock(x + 6, y + 6, z + 25, 17, 13, 1);
		world.setBlock(x + 7, y + 6, z + 25, 17, 13, 1);
		world.setBlock(x + 8, y + 6, z + 25, 17, 13, 1);
		world.setBlock(x + 11, y + 6, z + 25, 85, 0, 1);
		world.setBlock(x + 3, y + 6, z + 26, 17, 13, 1);
		world.setBlock(x + 4, y + 6, z + 26, 134, 2, 1);
		world.setBlock(x + 5, y + 6, z + 26, 134, 2, 1);
		world.setBlock(x + 6, y + 6, z + 26, 5, 1, 1);
		world.setBlock(x + 7, y + 6, z + 26, 65, 3, 1);
		world.setBlock(x + 8, y + 6, z + 26, 5, 1, 1);
		world.setBlock(x + 9, y + 6, z + 26, 134, 2, 1);
		world.setBlock(x + 10, y + 6, z + 26, 134, 2, 1);
		world.setBlock(x + 11, y + 6, z + 26, 17, 13, 1);
		world.setBlock(x + 3, y + 6, z + 27, 17, 13, 1);
		world.setBlock(x + 4, y + 6, z + 27, 5, 1, 1);
		world.setBlock(x + 5, y + 6, z + 27, 5, 1, 1);
		world.setBlock(x + 6, y + 6, z + 27, 5, 1, 1);
		world.setBlock(x + 7, y + 6, z + 27, 5, 1, 1);
		world.setBlock(x + 8, y + 6, z + 27, 5, 1, 1);
		world.setBlock(x + 9, y + 6, z + 27, 5, 1, 1);
		world.setBlock(x + 10, y + 6, z + 27, 5, 1, 1);
		world.setBlock(x + 11, y + 6, z + 27, 17, 13, 1);
		world.setBlock(x + 3, y + 6, z + 28, 17, 13, 1);
		world.setBlock(x + 4, y + 6, z + 28, 5, 1, 1);
		world.setBlock(x + 5, y + 6, z + 28, 5, 1, 1);
		world.setBlock(x + 6, y + 6, z + 28, 5, 1, 1);
		world.setBlock(x + 7, y + 6, z + 28, 17, 13, 1);
		world.setBlock(x + 8, y + 6, z + 28, 5, 1, 1);
		world.setBlock(x + 9, y + 6, z + 28, 5, 1, 1);
		world.setBlock(x + 10, y + 6, z + 28, 5, 1, 1);
		world.setBlock(x + 11, y + 6, z + 28, 17, 13, 1);
		world.setBlock(x + 3, y + 6, z + 29, 17, 13, 1);
		world.setBlock(x + 4, y + 6, z + 29, 5, 1, 1);
		world.setBlock(x + 5, y + 6, z + 29, 5, 1, 1);
		world.setBlock(x + 6, y + 6, z + 29, 5, 1, 1);
		world.setBlock(x + 7, y + 6, z + 29, 5, 1, 1);
		world.setBlock(x + 8, y + 6, z + 29, 5, 1, 1);
		world.setBlock(x + 9, y + 6, z + 29, 5, 1, 1);
		world.setBlock(x + 10, y + 6, z + 29, 5, 1, 1);
		world.setBlock(x + 11, y + 6, z + 29, 17, 13, 1);
		world.setBlock(x + 3, y + 6, z + 30, 17, 13, 1);
		world.setBlock(x + 4, y + 6, z + 30, 5, 1, 1);
		world.setBlock(x + 5, y + 6, z + 30, 5, 1, 1);
		world.setBlock(x + 6, y + 6, z + 30, 5, 1, 1);
		world.setBlock(x + 7, y + 6, z + 30, 5, 1, 1);
		world.setBlock(x + 8, y + 6, z + 30, 5, 1, 1);
		world.setBlock(x + 9, y + 6, z + 30, 5, 1, 1);
		world.setBlock(x + 10, y + 6, z + 30, 5, 1, 1);
		world.setBlock(x + 11, y + 6, z + 30, 17, 13, 1);
		world.setBlock(x + 3, y + 6, z + 31, 17, 13, 1);
		world.setBlock(x + 11, y + 6, z + 31, 17, 13, 1);
		world.setBlock(x + 3, y + 6, z + 32, 17, 13, 1);
		world.setBlock(x + 11, y + 6, z + 32, 17, 13, 1);
		world.setBlock(x + 3, y + 6, z + 33, 17, 13, 1);
		world.setBlock(x + 11, y + 6, z + 33, 17, 13, 1);
		world.setBlock(x + 4, y + 6, z + 34, 17, 13, 1);
		world.setBlock(x + 5, y + 6, z + 34, 17, 13, 1);
		world.setBlock(x + 9, y + 6, z + 34, 17, 13, 1);
		world.setBlock(x + 10, y + 6, z + 34, 17, 13, 1);
		world.setBlock(x + 5, y + 6, z + 35, 17, 13, 1);
		world.setBlock(x + 6, y + 6, z + 35, 17, 13, 1);
		world.setBlock(x + 8, y + 6, z + 35, 17, 13, 1);
		world.setBlock(x + 9, y + 6, z + 35, 17, 13, 1);
		world.setBlock(x + 6, y + 6, z + 36, 17, 13, 1);
		world.setBlock(x + 7, y + 6, z + 36, 17, 13, 1);
		world.setBlock(x + 8, y + 6, z + 36, 17, 13, 1);
		world.setBlock(x + 7, y + 6, z + 37, 17, 13, 1);
		world.setBlock(x + 7, y + 6, z + 38, 17, 13, 1);
		world.setBlock(x + 3, y + 7, z + 0, 17, 13, 1);
		world.setBlock(x + 4, y + 7, z + 0, 17, 13, 1);
		world.setBlock(x + 5, y + 7, z + 0, 17, 13, 1);
		world.setBlock(x + 6, y + 7, z + 0, 17, 13, 1);
		world.setBlock(x + 7, y + 7, z + 0, 17, 13, 1);
		world.setBlock(x + 8, y + 7, z + 0, 17, 13, 1);
		world.setBlock(x + 9, y + 7, z + 0, 17, 13, 1);
		world.setBlock(x + 10, y + 7, z + 0, 17, 13, 1);
		world.setBlock(x + 11, y + 7, z + 0, 17, 13, 1);
		world.setBlock(x + 3, y + 7, z + 1, 17, 13, 1);
		world.setBlock(x + 4, y + 7, z + 1, 126, 1, 1);
		world.setBlock(x + 5, y + 7, z + 1, 126, 1, 1);
		world.setBlock(x + 6, y + 7, z + 1, 26, 10, 1);
		world.setBlock(x + 7, y + 7, z + 1, 26, 10, 1);
		world.setBlock(x + 8, y + 7, z + 1, 26, 10, 1);
		world.setBlock(x + 9, y + 7, z + 1, 126, 1, 1);
		world.setBlock(x + 10, y + 7, z + 1, 126, 1, 1);
		world.setBlock(x + 11, y + 7, z + 1, 17, 13, 1);
		world.setBlock(x + 3, y + 7, z + 2, 17, 13, 1);
		world.setBlock(x + 5, y + 7, z + 2, 126, 1, 1);
		world.setBlock(x + 6, y + 7, z + 2, 26, 2, 1);
		world.setBlock(x + 7, y + 7, z + 2, 26, 2, 1);
		world.setBlock(x + 8, y + 7, z + 2, 26, 2, 1);
		world.setBlock(x + 9, y + 7, z + 2, 126, 1, 1);
		world.setBlock(x + 11, y + 7, z + 2, 17, 13, 1);
		world.setBlock(x + 3, y + 7, z + 3, 17, 13, 1);
		world.setBlock(x + 6, y + 7, z + 3, 126, 1, 1);
		world.setBlock(x + 7, y + 7, z + 3, 126, 1, 1);
		world.setBlock(x + 8, y + 7, z + 3, 126, 1, 1);
		world.setBlock(x + 11, y + 7, z + 3, 17, 13, 1);
		world.setBlock(x + 3, y + 7, z + 4, 17, 13, 1);
		world.setBlock(x + 4, y + 7, z + 4, 134, 7, 1);
		world.setBlock(x + 11, y + 7, z + 4, 17, 13, 1);
		world.setBlock(x + 3, y + 7, z + 5, 17, 13, 1);
		world.setBlock(x + 4, y + 7, z + 5, 134, 6, 1);
		world.setBlock(x + 11, y + 7, z + 5, 17, 13, 1);
		world.setBlock(x + 3, y + 7, z + 6, 17, 13, 1);
		world.setBlock(x + 4, y + 7, z + 6, 17, 13, 1);
		world.setBlock(x + 10, y + 7, z + 6, 17, 13, 1);
		world.setBlock(x + 11, y + 7, z + 6, 17, 13, 1);
		world.setBlock(x + 3, y + 7, z + 7, 17, 13, 1);
		world.setBlock(x + 4, y + 7, z + 7, 17, 13, 1);
		world.setBlock(x + 5, y + 7, z + 7, 17, 13, 1);
		world.setBlock(x + 9, y + 7, z + 7, 17, 13, 1);
		world.setBlock(x + 10, y + 7, z + 7, 17, 13, 1);
		world.setBlock(x + 11, y + 7, z + 7, 17, 13, 1);
		world.setBlock(x + 3, y + 7, z + 8, 17, 13, 1);
		world.setBlock(x + 4, y + 7, z + 8, 17, 13, 1);
		world.setBlock(x + 5, y + 7, z + 8, 17, 13, 1);
		world.setBlock(x + 6, y + 7, z + 8, 17, 13, 1);
		world.setBlock(x + 7, y + 7, z + 8, 64, 3, 1);
		world.setBlock(x + 8, y + 7, z + 8, 17, 13, 1);
		world.setBlock(x + 9, y + 7, z + 8, 17, 13, 1);
		world.setBlock(x + 10, y + 7, z + 8, 17, 13, 1);
		world.setBlock(x + 11, y + 7, z + 8, 17, 13, 1);
		world.setBlock(x + 3, y + 7, z + 9, 17, 13, 1);
		world.setBlock(x + 4, y + 7, z + 9, 134, 3, 1);
		world.setBlock(x + 5, y + 7, z + 9, 85, 0, 1);
		world.setBlock(x + 9, y + 7, z + 9, 85, 0, 1);
		world.setBlock(x + 10, y + 7, z + 9, 134, 3, 1);
		world.setBlock(x + 11, y + 7, z + 9, 17, 13, 1);
		world.setBlock(x + 3, y + 7, z + 10, 85, 0, 1);
		world.setBlock(x + 11, y + 7, z + 10, 85, 0, 1);
		world.setBlock(x + 3, y + 7, z + 11, 85, 0, 1);
		world.setBlock(x + 6, y + 7, z + 11, 134, 0, 1);
		world.setBlock(x + 7, y + 7, z + 11, 17, 13, 1);
		world.setBlock(x + 8, y + 7, z + 11, 134, 1, 1);
		world.setBlock(x + 11, y + 7, z + 11, 85, 0, 1);
		world.setBlock(x + 3, y + 7, z + 12, 85, 0, 1);
		world.setBlock(x + 7, y + 7, z + 12, 134, 3, 1);
		world.setBlock(x + 11, y + 7, z + 12, 85, 0, 1);
		world.setBlock(x + 3, y + 7, z + 13, 85, 0, 1);
		world.setBlock(x + 5, y + 7, z + 13, 85, 0, 1);
		world.setBlock(x + 6, y + 7, z + 13, 85, 0, 1);
		world.setBlock(x + 7, y + 7, z + 13, 85, 0, 1);
		world.setBlock(x + 8, y + 7, z + 13, 85, 0, 1);
		world.setBlock(x + 9, y + 7, z + 13, 85, 0, 1);
		world.setBlock(x + 11, y + 7, z + 13, 85, 0, 1);
		world.setBlock(x + 3, y + 7, z + 14, 85, 0, 1);
		world.setBlock(x + 11, y + 7, z + 14, 85, 0, 1);
		world.setBlock(x + 7, y + 7, z + 18, 65, 2, 1);
		world.setBlock(x + 7, y + 7, z + 19, 17, 13, 1);
		world.setBlock(x + 3, y + 7, z + 25, 85, 0, 1);
		world.setBlock(x + 6, y + 7, z + 25, 85, 0, 1);
		world.setBlock(x + 7, y + 7, z + 25, 85, 0, 1);
		world.setBlock(x + 8, y + 7, z + 25, 85, 0, 1);
		world.setBlock(x + 11, y + 7, z + 25, 85, 0, 1);
		world.setBlock(x + 3, y + 7, z + 26, 85, 0, 1);
		world.setBlock(x + 11, y + 7, z + 26, 85, 0, 1);
		world.setBlock(x + 3, y + 7, z + 27, 85, 0, 1);
		world.setBlock(x + 7, y + 7, z + 27, 134, 2, 1);
		world.setBlock(x + 11, y + 7, z + 27, 85, 0, 1);
		world.setBlock(x + 3, y + 7, z + 28, 85, 0, 1);
		world.setBlock(x + 6, y + 7, z + 28, 134, 0, 1);
		world.setBlock(x + 7, y + 7, z + 28, 17, 13, 1);
		world.setBlock(x + 8, y + 7, z + 28, 134, 1, 1);
		world.setBlock(x + 11, y + 7, z + 28, 85, 0, 1);
		world.setBlock(x + 3, y + 7, z + 29, 85, 0, 1);
		world.setBlock(x + 7, y + 7, z + 29, 134, 3, 1);
		world.setBlock(x + 11, y + 7, z + 29, 85, 0, 1);
		world.setBlock(x + 3, y + 7, z + 30, 17, 13, 1);
		world.setBlock(x + 4, y + 7, z + 30, 134, 2, 1);
		world.setBlock(x + 5, y + 7, z + 30, 17, 13, 1);
		world.setBlock(x + 9, y + 7, z + 30, 17, 13, 1);
		world.setBlock(x + 10, y + 7, z + 30, 134, 2, 1);
		world.setBlock(x + 11, y + 7, z + 30, 17, 13, 1);
		world.setBlock(x + 3, y + 7, z + 31, 17, 13, 1);
		world.setBlock(x + 4, y + 7, z + 31, 5, 1, 1);
		world.setBlock(x + 5, y + 7, z + 31, 17, 13, 1);
		world.setBlock(x + 6, y + 7, z + 31, 17, 13, 1);
		world.setBlock(x + 7, y + 7, z + 31, 17, 13, 1);
		world.setBlock(x + 8, y + 7, z + 31, 17, 13, 1);
		world.setBlock(x + 9, y + 7, z + 31, 17, 13, 1);
		world.setBlock(x + 10, y + 7, z + 31, 5, 1, 1);
		world.setBlock(x + 11, y + 7, z + 31, 17, 13, 1);
		world.setBlock(x + 3, y + 7, z + 32, 17, 13, 1);
		world.setBlock(x + 4, y + 7, z + 32, 5, 1, 1);
		world.setBlock(x + 5, y + 7, z + 32, 5, 1, 1);
		world.setBlock(x + 6, y + 7, z + 32, 5, 1, 1);
		world.setBlock(x + 7, y + 7, z + 32, 5, 1, 1);
		world.setBlock(x + 8, y + 7, z + 32, 5, 1, 1);
		world.setBlock(x + 9, y + 7, z + 32, 5, 1, 1);
		world.setBlock(x + 10, y + 7, z + 32, 5, 1, 1);
		world.setBlock(x + 11, y + 7, z + 32, 17, 13, 1);
		world.setBlock(x + 3, y + 7, z + 33, 17, 13, 1);
		world.setBlock(x + 4, y + 7, z + 33, 5, 1, 1);
		world.setBlock(x + 5, y + 7, z + 33, 5, 1, 1);
		world.setBlock(x + 6, y + 7, z + 33, 5, 1, 1);
		world.setBlock(x + 7, y + 7, z + 33, 5, 1, 1);
		world.setBlock(x + 8, y + 7, z + 33, 5, 1, 1);
		world.setBlock(x + 9, y + 7, z + 33, 5, 1, 1);
		world.setBlock(x + 10, y + 7, z + 33, 5, 1, 1);
		world.setBlock(x + 11, y + 7, z + 33, 17, 13, 1);
		world.setBlock(x + 3, y + 7, z + 34, 17, 13, 1);
		world.setBlock(x + 4, y + 7, z + 34, 5, 1, 1);
		world.setBlock(x + 5, y + 7, z + 34, 5, 1, 1);
		world.setBlock(x + 6, y + 7, z + 34, 5, 1, 1);
		world.setBlock(x + 7, y + 7, z + 34, 5, 1, 1);
		world.setBlock(x + 8, y + 7, z + 34, 5, 1, 1);
		world.setBlock(x + 9, y + 7, z + 34, 5, 1, 1);
		world.setBlock(x + 10, y + 7, z + 34, 5, 1, 1);
		world.setBlock(x + 11, y + 7, z + 34, 17, 13, 1);
		world.setBlock(x + 4, y + 7, z + 35, 17, 13, 1);
		world.setBlock(x + 5, y + 7, z + 35, 17, 13, 1);
		world.setBlock(x + 9, y + 7, z + 35, 17, 13, 1);
		world.setBlock(x + 10, y + 7, z + 35, 17, 13, 1);
		world.setBlock(x + 5, y + 7, z + 36, 17, 13, 1);
		world.setBlock(x + 6, y + 7, z + 36, 17, 13, 1);
		world.setBlock(x + 8, y + 7, z + 36, 17, 13, 1);
		world.setBlock(x + 9, y + 7, z + 36, 17, 13, 1);
		world.setBlock(x + 6, y + 7, z + 37, 17, 13, 1);
		world.setBlock(x + 7, y + 7, z + 37, 17, 13, 1);
		world.setBlock(x + 8, y + 7, z + 37, 17, 13, 1);
		world.setBlock(x + 7, y + 7, z + 38, 17, 13, 1);
		world.setBlock(x + 7, y + 7, z + 39, 17, 13, 1);
		world.setBlock(x + 7, y + 7, z + 40, 17, 13, 1);
		world.setBlock(x + 3, y + 8, z + 0, 17, 13, 1);
		world.setBlock(x + 4, y + 8, z + 0, 17, 13, 1);
		world.setBlock(x + 5, y + 8, z + 0, 20, 0, 1);
		world.setBlock(x + 6, y + 8, z + 0, 20, 0, 1);
		world.setBlock(x + 7, y + 8, z + 0, 17, 13, 1);
		world.setBlock(x + 8, y + 8, z + 0, 20, 0, 1);
		world.setBlock(x + 9, y + 8, z + 0, 20, 0, 1);
		world.setBlock(x + 10, y + 8, z + 0, 17, 13, 1);
		world.setBlock(x + 11, y + 8, z + 0, 17, 13, 1);
		world.setBlock(x + 3, y + 8, z + 1, 20, 0, 1);
		world.setBlock(x + 11, y + 8, z + 1, 20, 0, 1);
		world.setBlock(x + 3, y + 8, z + 2, 20, 0, 1);
		world.setBlock(x + 11, y + 8, z + 2, 20, 0, 1);
		world.setBlock(x + 3, y + 8, z + 3, 17, 13, 1);
		world.setBlock(x + 11, y + 8, z + 3, 17, 13, 1);
		world.setBlock(x + 3, y + 8, z + 4, 20, 0, 1);
		world.setBlock(x + 11, y + 8, z + 4, 20, 0, 1);
		world.setBlock(x + 3, y + 8, z + 5, 20, 0, 1);
		world.setBlock(x + 11, y + 8, z + 5, 20, 0, 1);
		world.setBlock(x + 3, y + 8, z + 6, 17, 13, 1);
		world.setBlock(x + 4, y + 8, z + 6, 17, 13, 1);
		world.setBlock(x + 10, y + 8, z + 6, 17, 13, 1);
		world.setBlock(x + 11, y + 8, z + 6, 17, 13, 1);
		world.setBlock(x + 3, y + 8, z + 7, 17, 13, 1);
		world.setBlock(x + 4, y + 8, z + 7, 17, 13, 1);
		world.setBlock(x + 5, y + 8, z + 7, 17, 13, 1);
		world.setBlock(x + 9, y + 8, z + 7, 17, 13, 1);
		world.setBlock(x + 10, y + 8, z + 7, 17, 13, 1);
		world.setBlock(x + 11, y + 8, z + 7, 17, 13, 1);
		world.setBlock(x + 3, y + 8, z + 8, 17, 13, 1);
		world.setBlock(x + 4, y + 8, z + 8, 134, 3, 1);
		world.setBlock(x + 5, y + 8, z + 8, 17, 13, 1);
		world.setBlock(x + 6, y + 8, z + 8, 20, 0, 1);
		world.setBlock(x + 7, y + 8, z + 8, 64, 8, 1);
		world.setBlock(x + 8, y + 8, z + 8, 20, 0, 1);
		world.setBlock(x + 9, y + 8, z + 8, 17, 13, 1);
		world.setBlock(x + 10, y + 8, z + 8, 134, 3, 1);
		world.setBlock(x + 11, y + 8, z + 8, 17, 13, 1);
		world.setBlock(x + 3, y + 8, z + 9, 85, 0, 1);
		world.setBlock(x + 5, y + 8, z + 9, 85, 0, 1);
		world.setBlock(x + 9, y + 8, z + 9, 85, 0, 1);
		world.setBlock(x + 11, y + 8, z + 9, 85, 0, 1);
		world.setBlock(x + 3, y + 8, z + 10, 85, 0, 1);
		world.setBlock(x + 11, y + 8, z + 10, 85, 0, 1);
		world.setBlock(x + 7, y + 8, z + 11, 17, 13, 1);
		world.setBlock(x + 5, y + 8, z + 13, 50, 5, 1);
		world.setBlock(x + 9, y + 8, z + 13, 50, 5, 1);
		world.setBlock(x + 7, y + 8, z + 18, 65, 2, 1);
		world.setBlock(x + 6, y + 8, z + 19, 50, 2, 1);
		world.setBlock(x + 7, y + 8, z + 19, 17, 13, 1);
		world.setBlock(x + 8, y + 8, z + 19, 50, 1, 1);
		world.setBlock(x + 7, y + 8, z + 20, 50, 3, 1);
		world.setBlock(x + 6, y + 8, z + 25, 50, 5, 1);
		world.setBlock(x + 8, y + 8, z + 25, 50, 5, 1);
		world.setBlock(x + 7, y + 8, z + 28, 17, 13, 1);
		world.setBlock(x + 3, y + 8, z + 29, 85, 0, 1);
		world.setBlock(x + 11, y + 8, z + 29, 85, 0, 1);
		world.setBlock(x + 3, y + 8, z + 30, 85, 0, 1);
		world.setBlock(x + 5, y + 8, z + 30, 85, 0, 1);
		world.setBlock(x + 9, y + 8, z + 30, 85, 0, 1);
		world.setBlock(x + 11, y + 8, z + 30, 85, 0, 1);
		world.setBlock(x + 3, y + 8, z + 31, 85, 0, 1);
		world.setBlock(x + 5, y + 8, z + 31, 85, 0, 1);
		world.setBlock(x + 6, y + 8, z + 31, 85, 0, 1);
		world.setBlock(x + 7, y + 8, z + 31, 85, 0, 1);
		world.setBlock(x + 8, y + 8, z + 31, 85, 0, 1);
		world.setBlock(x + 9, y + 8, z + 31, 85, 0, 1);
		world.setBlock(x + 11, y + 8, z + 31, 85, 0, 1);
		world.setBlock(x + 3, y + 8, z + 32, 85, 0, 1);
		world.setBlock(x + 11, y + 8, z + 32, 85, 0, 1);
		world.setBlock(x + 3, y + 8, z + 33, 85, 0, 1);
		world.setBlock(x + 11, y + 8, z + 33, 85, 0, 1);
		world.setBlock(x + 3, y + 8, z + 34, 17, 13, 1);
		world.setBlock(x + 11, y + 8, z + 34, 17, 13, 1);
		world.setBlock(x + 3, y + 8, z + 35, 17, 13, 1);
		world.setBlock(x + 4, y + 8, z + 35, 17, 13, 1);
		world.setBlock(x + 5, y + 8, z + 35, 134, 1, 1);
		world.setBlock(x + 6, y + 8, z + 35, 134, 2, 1);
		world.setBlock(x + 7, y + 8, z + 35, 134, 2, 1);
		world.setBlock(x + 8, y + 8, z + 35, 134, 2, 1);
		world.setBlock(x + 9, y + 8, z + 35, 134, 0, 1);
		world.setBlock(x + 10, y + 8, z + 35, 17, 13, 1);
		world.setBlock(x + 11, y + 8, z + 35, 17, 13, 1);
		world.setBlock(x + 4, y + 8, z + 36, 17, 13, 1);
		world.setBlock(x + 5, y + 8, z + 36, 17, 13, 1);
		world.setBlock(x + 6, y + 8, z + 36, 5, 1, 1);
		world.setBlock(x + 7, y + 8, z + 36, 5, 1, 1);
		world.setBlock(x + 8, y + 8, z + 36, 5, 1, 1);
		world.setBlock(x + 9, y + 8, z + 36, 17, 13, 1);
		world.setBlock(x + 10, y + 8, z + 36, 17, 13, 1);
		world.setBlock(x + 5, y + 8, z + 37, 17, 13, 1);
		world.setBlock(x + 6, y + 8, z + 37, 17, 13, 1);
		world.setBlock(x + 7, y + 8, z + 37, 5, 1, 1);
		world.setBlock(x + 8, y + 8, z + 37, 17, 13, 1);
		world.setBlock(x + 9, y + 8, z + 37, 17, 13, 1);
		world.setBlock(x + 6, y + 8, z + 38, 17, 13, 1);
		world.setBlock(x + 7, y + 8, z + 38, 5, 1, 1);
		world.setBlock(x + 8, y + 8, z + 38, 17, 13, 1);
		world.setBlock(x + 7, y + 8, z + 39, 17, 13, 1);
		world.setBlock(x + 7, y + 8, z + 40, 17, 13, 1);
		world.setBlock(x + 7, y + 8, z + 41, 17, 13, 1);
		world.setBlock(x + 7, y + 8, z + 42, 17, 13, 1);
		world.setBlock(x + 7, y + 8, z + 43, 17, 13, 1);
		world.setBlock(x + 7, y + 8, z + 44, 17, 13, 1);
		world.setBlock(x + 6, y + 8, z + 45, 50, 2, 1);
		world.setBlock(x + 7, y + 8, z + 45, 17, 13, 1);
		world.setBlock(x + 8, y + 8, z + 45, 50, 1, 1);
		world.setBlock(x + 7, y + 8, z + 46, 50, 3, 1);
		world.setBlock(x + 3, y + 9, z + 0, 17, 13, 1);
		world.setBlock(x + 4, y + 9, z + 0, 17, 13, 1);
		world.setBlock(x + 5, y + 9, z + 0, 20, 0, 1);
		world.setBlock(x + 6, y + 9, z + 0, 20, 0, 1);
		world.setBlock(x + 7, y + 9, z + 0, 17, 13, 1);
		world.setBlock(x + 8, y + 9, z + 0, 20, 0, 1);
		world.setBlock(x + 9, y + 9, z + 0, 20, 0, 1);
		world.setBlock(x + 10, y + 9, z + 0, 17, 13, 1);
		world.setBlock(x + 11, y + 9, z + 0, 17, 13, 1);
		world.setBlock(x + 3, y + 9, z + 1, 20, 0, 1);
		world.setBlock(x + 4, y + 9, z + 1, 50, 3, 1);
		world.setBlock(x + 7, y + 9, z + 1, 50, 3, 1);
		world.setBlock(x + 10, y + 9, z + 1, 50, 3, 1);
		world.setBlock(x + 11, y + 9, z + 1, 20, 0, 1);
		world.setBlock(x + 3, y + 9, z + 2, 20, 0, 1);
		world.setBlock(x + 11, y + 9, z + 2, 20, 0, 1);
		world.setBlock(x + 3, y + 9, z + 3, 17, 13, 1);
		world.setBlock(x + 4, y + 9, z + 3, 50, 1, 1);
		world.setBlock(x + 10, y + 9, z + 3, 50, 2, 1);
		world.setBlock(x + 11, y + 9, z + 3, 17, 13, 1);
		world.setBlock(x + 3, y + 9, z + 4, 20, 0, 1);
		world.setBlock(x + 11, y + 9, z + 4, 20, 0, 1);
		world.setBlock(x + 3, y + 9, z + 5, 20, 0, 1);
		world.setBlock(x + 4, y + 9, z + 5, 50, 4, 1);
		world.setBlock(x + 10, y + 9, z + 5, 50, 4, 1);
		world.setBlock(x + 11, y + 9, z + 5, 20, 0, 1);
		world.setBlock(x + 3, y + 9, z + 6, 17, 13, 1);
		world.setBlock(x + 4, y + 9, z + 6, 17, 13, 1);
		world.setBlock(x + 5, y + 9, z + 6, 50, 4, 1);
		world.setBlock(x + 9, y + 9, z + 6, 50, 4, 1);
		world.setBlock(x + 10, y + 9, z + 6, 17, 13, 1);
		world.setBlock(x + 11, y + 9, z + 6, 17, 13, 1);
		world.setBlock(x + 3, y + 9, z + 7, 17, 13, 1);
		world.setBlock(x + 4, y + 9, z + 7, 134, 3, 1);
		world.setBlock(x + 5, y + 9, z + 7, 17, 13, 1);
		world.setBlock(x + 6, y + 9, z + 7, 50, 4, 1);
		world.setBlock(x + 8, y + 9, z + 7, 50, 4, 1);
		world.setBlock(x + 9, y + 9, z + 7, 17, 13, 1);
		world.setBlock(x + 10, y + 9, z + 7, 134, 3, 1);
		world.setBlock(x + 11, y + 9, z + 7, 17, 13, 1);
		world.setBlock(x + 3, y + 9, z + 8, 85, 0, 1);
		world.setBlock(x + 5, y + 9, z + 8, 17, 13, 1);
		world.setBlock(x + 6, y + 9, z + 8, 17, 13, 1);
		world.setBlock(x + 7, y + 9, z + 8, 17, 13, 1);
		world.setBlock(x + 8, y + 9, z + 8, 17, 13, 1);
		world.setBlock(x + 9, y + 9, z + 8, 17, 13, 1);
		world.setBlock(x + 11, y + 9, z + 8, 85, 0, 1);
		world.setBlock(x + 3, y + 9, z + 9, 85, 0, 1);
		world.setBlock(x + 5, y + 9, z + 9, 85, 0, 1);
		world.setBlock(x + 6, y + 9, z + 9, 50, 3, 1);
		world.setBlock(x + 8, y + 9, z + 9, 50, 3, 1);
		world.setBlock(x + 9, y + 9, z + 9, 85, 0, 1);
		world.setBlock(x + 11, y + 9, z + 9, 85, 0, 1);
		world.setBlock(x + 7, y + 9, z + 11, 17, 13, 1);
		world.setBlock(x + 7, y + 9, z + 18, 65, 2, 1);
		world.setBlock(x + 7, y + 9, z + 19, 17, 13, 1);
		world.setBlock(x + 7, y + 9, z + 28, 17, 13, 1);
		world.setBlock(x + 5, y + 9, z + 31, 50, 5, 1);
		world.setBlock(x + 9, y + 9, z + 31, 50, 5, 1);
		world.setBlock(x + 3, y + 9, z + 33, 85, 0, 1);
		world.setBlock(x + 11, y + 9, z + 33, 85, 0, 1);
		world.setBlock(x + 3, y + 9, z + 34, 85, 0, 1);
		world.setBlock(x + 11, y + 9, z + 34, 85, 0, 1);
		world.setBlock(x + 3, y + 9, z + 35, 85, 0, 1);
		world.setBlock(x + 4, y + 9, z + 35, 85, 0, 1);
		world.setBlock(x + 10, y + 9, z + 35, 85, 0, 1);
		world.setBlock(x + 11, y + 9, z + 35, 85, 0, 1);
		world.setBlock(x + 4, y + 9, z + 36, 85, 0, 1);
		world.setBlock(x + 5, y + 9, z + 36, 85, 0, 1);
		world.setBlock(x + 9, y + 9, z + 36, 85, 0, 1);
		world.setBlock(x + 10, y + 9, z + 36, 85, 0, 1);
		world.setBlock(x + 5, y + 9, z + 37, 85, 0, 1);
		world.setBlock(x + 6, y + 9, z + 37, 85, 0, 1);
		world.setBlock(x + 8, y + 9, z + 37, 85, 0, 1);
		world.setBlock(x + 9, y + 9, z + 37, 85, 0, 1);
		world.setBlock(x + 6, y + 9, z + 38, 85, 0, 1);
		world.setBlock(x + 7, y + 9, z + 38, 85, 0, 1);
		world.setBlock(x + 8, y + 9, z + 38, 85, 0, 1);
		world.setBlock(x + 7, y + 9, z + 39, 85, 0, 1);
		world.setBlock(x + 7, y + 9, z + 40, 85, 0, 1);
		world.setBlock(x + 7, y + 9, z + 41, 85, 0, 1);
		world.setBlock(x + 7, y + 9, z + 42, 85, 0, 1);
		world.setBlock(x + 7, y + 9, z + 43, 85, 0, 1);
		world.setBlock(x + 7, y + 9, z + 44, 85, 0, 1);
		world.setBlock(x + 7, y + 9, z + 45, 85, 0, 1);
		world.setBlock(x + 3, y + 10, z + 0, 17, 13, 1);
		world.setBlock(x + 4, y + 10, z + 0, 17, 13, 1);
		world.setBlock(x + 5, y + 10, z + 0, 17, 13, 1);
		world.setBlock(x + 6, y + 10, z + 0, 17, 13, 1);
		world.setBlock(x + 7, y + 10, z + 0, 17, 13, 1);
		world.setBlock(x + 8, y + 10, z + 0, 17, 13, 1);
		world.setBlock(x + 9, y + 10, z + 0, 17, 13, 1);
		world.setBlock(x + 10, y + 10, z + 0, 17, 13, 1);
		world.setBlock(x + 11, y + 10, z + 0, 17, 13, 1);
		world.setBlock(x + 3, y + 10, z + 1, 17, 13, 1);
		world.setBlock(x + 4, y + 10, z + 1, 5, 1, 1);
		world.setBlock(x + 5, y + 10, z + 1, 5, 1, 1);
		world.setBlock(x + 6, y + 10, z + 1, 5, 1, 1);
		world.setBlock(x + 7, y + 10, z + 1, 5, 1, 1);
		world.setBlock(x + 8, y + 10, z + 1, 5, 1, 1);
		world.setBlock(x + 9, y + 10, z + 1, 5, 1, 1);
		world.setBlock(x + 10, y + 10, z + 1, 5, 1, 1);
		world.setBlock(x + 11, y + 10, z + 1, 17, 13, 1);
		world.setBlock(x + 3, y + 10, z + 2, 17, 13, 1);
		world.setBlock(x + 4, y + 10, z + 2, 5, 1, 1);
		world.setBlock(x + 5, y + 10, z + 2, 5, 1, 1);
		world.setBlock(x + 6, y + 10, z + 2, 5, 1, 1);
		world.setBlock(x + 7, y + 10, z + 2, 5, 1, 1);
		world.setBlock(x + 8, y + 10, z + 2, 5, 1, 1);
		world.setBlock(x + 9, y + 10, z + 2, 5, 1, 1);
		world.setBlock(x + 10, y + 10, z + 2, 5, 1, 1);
		world.setBlock(x + 11, y + 10, z + 2, 17, 13, 1);
		world.setBlock(x + 3, y + 10, z + 3, 17, 13, 1);
		world.setBlock(x + 4, y + 10, z + 3, 5, 1, 1);
		world.setBlock(x + 5, y + 10, z + 3, 5, 1, 1);
		world.setBlock(x + 6, y + 10, z + 3, 5, 1, 1);
		world.setBlock(x + 7, y + 10, z + 3, 5, 1, 1);
		world.setBlock(x + 8, y + 10, z + 3, 5, 1, 1);
		world.setBlock(x + 9, y + 10, z + 3, 5, 1, 1);
		world.setBlock(x + 10, y + 10, z + 3, 5, 1, 1);
		world.setBlock(x + 11, y + 10, z + 3, 17, 13, 1);
		world.setBlock(x + 3, y + 10, z + 4, 17, 13, 1);
		world.setBlock(x + 4, y + 10, z + 4, 5, 1, 1);
		world.setBlock(x + 5, y + 10, z + 4, 5, 1, 1);
		world.setBlock(x + 6, y + 10, z + 4, 5, 1, 1);
		world.setBlock(x + 7, y + 10, z + 4, 5, 1, 1);
		world.setBlock(x + 8, y + 10, z + 4, 5, 1, 1);
		world.setBlock(x + 9, y + 10, z + 4, 5, 1, 1);
		world.setBlock(x + 10, y + 10, z + 4, 5, 1, 1);
		world.setBlock(x + 11, y + 10, z + 4, 17, 13, 1);
		world.setBlock(x + 3, y + 10, z + 5, 17, 13, 1);
		world.setBlock(x + 4, y + 10, z + 5, 5, 1, 1);
		world.setBlock(x + 5, y + 10, z + 5, 5, 1, 1);
		world.setBlock(x + 6, y + 10, z + 5, 5, 1, 1);
		world.setBlock(x + 7, y + 10, z + 5, 5, 1, 1);
		world.setBlock(x + 8, y + 10, z + 5, 5, 1, 1);
		world.setBlock(x + 9, y + 10, z + 5, 5, 1, 1);
		world.setBlock(x + 10, y + 10, z + 5, 5, 1, 1);
		world.setBlock(x + 11, y + 10, z + 5, 17, 13, 1);
		world.setBlock(x + 3, y + 10, z + 6, 17, 13, 1);
		world.setBlock(x + 4, y + 10, z + 6, 134, 3, 1);
		world.setBlock(x + 5, y + 10, z + 6, 5, 1, 1);
		world.setBlock(x + 6, y + 10, z + 6, 5, 1, 1);
		world.setBlock(x + 7, y + 10, z + 6, 5, 1, 1);
		world.setBlock(x + 8, y + 10, z + 6, 5, 1, 1);
		world.setBlock(x + 9, y + 10, z + 6, 5, 1, 1);
		world.setBlock(x + 10, y + 10, z + 6, 134, 3, 1);
		world.setBlock(x + 11, y + 10, z + 6, 17, 13, 1);
		world.setBlock(x + 3, y + 10, z + 7, 85, 0, 1);
		world.setBlock(x + 5, y + 10, z + 7, 17, 13, 1);
		world.setBlock(x + 6, y + 10, z + 7, 5, 1, 1);
		world.setBlock(x + 7, y + 10, z + 7, 5, 1, 1);
		world.setBlock(x + 8, y + 10, z + 7, 5, 1, 1);
		world.setBlock(x + 9, y + 10, z + 7, 17, 13, 1);
		world.setBlock(x + 11, y + 10, z + 7, 85, 0, 1);
		world.setBlock(x + 3, y + 10, z + 8, 85, 0, 1);
		world.setBlock(x + 5, y + 10, z + 8, 17, 13, 1);
		world.setBlock(x + 6, y + 10, z + 8, 17, 13, 1);
		world.setBlock(x + 7, y + 10, z + 8, 17, 13, 1);
		world.setBlock(x + 8, y + 10, z + 8, 17, 13, 1);
		world.setBlock(x + 9, y + 10, z + 8, 17, 13, 1);
		world.setBlock(x + 11, y + 10, z + 8, 85, 0, 1);
		world.setBlock(x + 5, y + 10, z + 9, 126, 1, 1);
		world.setBlock(x + 6, y + 10, z + 9, 126, 1, 1);
		world.setBlock(x + 7, y + 10, z + 9, 126, 1, 1);
		world.setBlock(x + 8, y + 10, z + 9, 126, 1, 1);
		world.setBlock(x + 9, y + 10, z + 9, 126, 1, 1);
		world.setBlock(x + 7, y + 10, z + 10, 50, 4, 1);
		world.setBlock(x + 6, y + 10, z + 11, 50, 2, 1);
		world.setBlock(x + 7, y + 10, z + 11, 17, 13, 1);
		world.setBlock(x + 8, y + 10, z + 11, 50, 1, 1);
		world.setBlock(x + 7, y + 10, z + 12, 50, 3, 1);
		world.setBlock(x + 7, y + 10, z + 18, 65, 2, 1);
		world.setBlock(x + 7, y + 10, z + 19, 17, 13, 1);
		world.setBlock(x + 7, y + 10, z + 27, 50, 4, 1);
		world.setBlock(x + 6, y + 10, z + 28, 50, 2, 1);
		world.setBlock(x + 7, y + 10, z + 28, 17, 13, 1);
		world.setBlock(x + 8, y + 10, z + 28, 50, 1, 1);
		world.setBlock(x + 7, y + 10, z + 29, 50, 3, 1);
		world.setBlock(x + 4, y + 10, z + 35, 50, 5, 1);
		world.setBlock(x + 10, y + 10, z + 35, 50, 5, 1);
		world.setBlock(x + 6, y + 10, z + 38, 50, 5, 1);
		world.setBlock(x + 8, y + 10, z + 38, 50, 5, 1);
		world.setBlock(x + 3, y + 11, z + 0, 85, 0, 1);
		world.setBlock(x + 4, y + 11, z + 0, 85, 0, 1);
		world.setBlock(x + 5, y + 11, z + 0, 85, 0, 1);
		world.setBlock(x + 6, y + 11, z + 0, 85, 0, 1);
		world.setBlock(x + 7, y + 11, z + 0, 85, 0, 1);
		world.setBlock(x + 8, y + 11, z + 0, 85, 0, 1);
		world.setBlock(x + 9, y + 11, z + 0, 85, 0, 1);
		world.setBlock(x + 10, y + 11, z + 0, 85, 0, 1);
		world.setBlock(x + 11, y + 11, z + 0, 85, 0, 1);
		world.setBlock(x + 3, y + 11, z + 1, 85, 0, 1);
		world.setBlock(x + 11, y + 11, z + 1, 85, 0, 1);
		world.setBlock(x + 3, y + 11, z + 2, 85, 0, 1);
		world.setBlock(x + 11, y + 11, z + 2, 85, 0, 1);
		world.setBlock(x + 3, y + 11, z + 3, 85, 0, 1);
		world.setBlock(x + 11, y + 11, z + 3, 85, 0, 1);
		world.setBlock(x + 3, y + 11, z + 4, 85, 0, 1);
		world.setBlock(x + 11, y + 11, z + 4, 85, 0, 1);
		world.setBlock(x + 3, y + 11, z + 5, 85, 0, 1);
		world.setBlock(x + 11, y + 11, z + 5, 85, 0, 1);
		world.setBlock(x + 3, y + 11, z + 6, 85, 0, 1);
		world.setBlock(x + 11, y + 11, z + 6, 85, 0, 1);
		world.setBlock(x + 3, y + 11, z + 7, 85, 0, 1);
		world.setBlock(x + 5, y + 11, z + 7, 85, 0, 1);
		world.setBlock(x + 7, y + 11, z + 7, 85, 0, 1);
		world.setBlock(x + 9, y + 11, z + 7, 85, 0, 1);
		world.setBlock(x + 11, y + 11, z + 7, 85, 0, 1);
		world.setBlock(x + 5, y + 11, z + 8, 85, 0, 1);
		world.setBlock(x + 6, y + 11, z + 8, 85, 0, 1);
		world.setBlock(x + 7, y + 11, z + 8, 85, 0, 1);
		world.setBlock(x + 8, y + 11, z + 8, 85, 0, 1);
		world.setBlock(x + 9, y + 11, z + 8, 85, 0, 1);
		world.setBlock(x + 7, y + 11, z + 11, 17, 13, 1);
		world.setBlock(x + 7, y + 11, z + 18, 65, 2, 1);
		world.setBlock(x + 0, y + 11, z + 19, 17, 13, 1);
		world.setBlock(x + 1, y + 11, z + 19, 17, 13, 1);
		world.setBlock(x + 2, y + 11, z + 19, 17, 13, 1);
		world.setBlock(x + 3, y + 11, z + 19, 17, 13, 1);
		world.setBlock(x + 4, y + 11, z + 19, 17, 13, 1);
		world.setBlock(x + 5, y + 11, z + 19, 17, 13, 1);
		world.setBlock(x + 6, y + 11, z + 19, 17, 13, 1);
		world.setBlock(x + 7, y + 11, z + 19, 17, 13, 1);
		world.setBlock(x + 8, y + 11, z + 19, 17, 13, 1);
		world.setBlock(x + 9, y + 11, z + 19, 17, 13, 1);
		world.setBlock(x + 10, y + 11, z + 19, 17, 13, 1);
		world.setBlock(x + 11, y + 11, z + 19, 17, 13, 1);
		world.setBlock(x + 12, y + 11, z + 19, 17, 13, 1);
		world.setBlock(x + 13, y + 11, z + 19, 17, 13, 1);
		world.setBlock(x + 14, y + 11, z + 19, 17, 13, 1);
		world.setBlock(x + 0, y + 11, z + 20, 35, 14, 1);
		world.setBlock(x + 1, y + 11, z + 20, 35, 14, 1);
		world.setBlock(x + 2, y + 11, z + 20, 35, 14, 1);
		world.setBlock(x + 3, y + 11, z + 20, 35, 0, 1);
		world.setBlock(x + 4, y + 11, z + 20, 35, 0, 1);
		world.setBlock(x + 5, y + 11, z + 20, 35, 0, 1);
		world.setBlock(x + 6, y + 11, z + 20, 35, 14, 1);
		world.setBlock(x + 7, y + 11, z + 20, 35, 14, 1);
		world.setBlock(x + 8, y + 11, z + 20, 35, 14, 1);
		world.setBlock(x + 9, y + 11, z + 20, 35, 0, 1);
		world.setBlock(x + 10, y + 11, z + 20, 35, 0, 1);
		world.setBlock(x + 11, y + 11, z + 20, 35, 0, 1);
		world.setBlock(x + 12, y + 11, z + 20, 35, 14, 1);
		world.setBlock(x + 13, y + 11, z + 20, 35, 14, 1);
		world.setBlock(x + 14, y + 11, z + 20, 35, 14, 1);
		world.setBlock(x + 7, y + 11, z + 28, 17, 13, 1);
		world.setBlock(x + 3, y + 12, z + 0, 50, 5, 1);
		world.setBlock(x + 11, y + 12, z + 0, 50, 5, 1);
		world.setBlock(x + 6, y + 12, z + 6, 69, 2, 1);
		world.setBlock(x + 7, y + 12, z + 6, 5, 1, 1);
		world.setBlock(x + 8, y + 12, z + 6, 69, 1, 1);
		world.setBlock(x + 3, y + 12, z + 7, 50, 5, 1);
		world.setBlock(x + 7, y + 12, z + 7, 85, 0, 1);
		world.setBlock(x + 11, y + 12, z + 7, 50, 5, 1);
		world.setBlock(x + 5, y + 12, z + 8, 50, 5, 1);
		world.setBlock(x + 9, y + 12, z + 8, 50, 5, 1);
		world.setBlock(x + 7, y + 12, z + 11, 17, 13, 1);
		world.setBlock(x + 7, y + 12, z + 18, 65, 2, 1);
		world.setBlock(x + 7, y + 12, z + 19, 17, 13, 1);
		world.setBlock(x + 7, y + 12, z + 20, 50, 3, 1);
		world.setBlock(x + 0, y + 12, z + 21, 35, 14, 1);
		world.setBlock(x + 1, y + 12, z + 21, 35, 14, 1);
		world.setBlock(x + 2, y + 12, z + 21, 35, 14, 1);
		world.setBlock(x + 3, y + 12, z + 21, 35, 0, 1);
		world.setBlock(x + 4, y + 12, z + 21, 35, 0, 1);
		world.setBlock(x + 5, y + 12, z + 21, 35, 0, 1);
		world.setBlock(x + 6, y + 12, z + 21, 35, 14, 1);
		world.setBlock(x + 7, y + 12, z + 21, 35, 14, 1);
		world.setBlock(x + 8, y + 12, z + 21, 35, 14, 1);
		world.setBlock(x + 9, y + 12, z + 21, 35, 0, 1);
		world.setBlock(x + 10, y + 12, z + 21, 35, 0, 1);
		world.setBlock(x + 11, y + 12, z + 21, 35, 0, 1);
		world.setBlock(x + 12, y + 12, z + 21, 35, 14, 1);
		world.setBlock(x + 13, y + 12, z + 21, 35, 14, 1);
		world.setBlock(x + 14, y + 12, z + 21, 35, 14, 1);
		world.setBlock(x + 7, y + 12, z + 28, 17, 13, 1);
		world.setBlock(x + 7, y + 13, z + 11, 17, 13, 1);
		world.setBlock(x + 7, y + 13, z + 18, 65, 2, 1);
		world.setBlock(x + 7, y + 13, z + 19, 17, 13, 1);
		world.setBlock(x + 0, y + 13, z + 21, 35, 14, 1);
		world.setBlock(x + 1, y + 13, z + 21, 35, 14, 1);
		world.setBlock(x + 2, y + 13, z + 21, 35, 14, 1);
		world.setBlock(x + 3, y + 13, z + 21, 35, 0, 1);
		world.setBlock(x + 4, y + 13, z + 21, 35, 0, 1);
		world.setBlock(x + 5, y + 13, z + 21, 35, 0, 1);
		world.setBlock(x + 6, y + 13, z + 21, 35, 14, 1);
		world.setBlock(x + 7, y + 13, z + 21, 35, 14, 1);
		world.setBlock(x + 8, y + 13, z + 21, 35, 14, 1);
		world.setBlock(x + 9, y + 13, z + 21, 35, 0, 1);
		world.setBlock(x + 10, y + 13, z + 21, 35, 0, 1);
		world.setBlock(x + 11, y + 13, z + 21, 35, 0, 1);
		world.setBlock(x + 12, y + 13, z + 21, 35, 14, 1);
		world.setBlock(x + 13, y + 13, z + 21, 35, 14, 1);
		world.setBlock(x + 14, y + 13, z + 21, 35, 14, 1);
		world.setBlock(x + 7, y + 13, z + 28, 17, 13, 1);
		world.setBlock(x + 3, y + 14, z + 11, 17, 13, 1);
		world.setBlock(x + 4, y + 14, z + 11, 17, 13, 1);
		world.setBlock(x + 5, y + 14, z + 11, 17, 13, 1);
		world.setBlock(x + 6, y + 14, z + 11, 17, 13, 1);
		world.setBlock(x + 7, y + 14, z + 11, 17, 13, 1);
		world.setBlock(x + 8, y + 14, z + 11, 17, 13, 1);
		world.setBlock(x + 9, y + 14, z + 11, 17, 13, 1);
		world.setBlock(x + 10, y + 14, z + 11, 17, 13, 1);
		world.setBlock(x + 11, y + 14, z + 11, 17, 13, 1);
		world.setBlock(x + 3, y + 14, z + 12, 35, 14, 1);
		world.setBlock(x + 4, y + 14, z + 12, 35, 0, 1);
		world.setBlock(x + 5, y + 14, z + 12, 35, 0, 1);
		world.setBlock(x + 6, y + 14, z + 12, 35, 14, 1);
		world.setBlock(x + 7, y + 14, z + 12, 35, 14, 1);
		world.setBlock(x + 8, y + 14, z + 12, 35, 14, 1);
		world.setBlock(x + 9, y + 14, z + 12, 35, 0, 1);
		world.setBlock(x + 10, y + 14, z + 12, 35, 0, 1);
		world.setBlock(x + 11, y + 14, z + 12, 35, 14, 1);
		world.setBlock(x + 7, y + 14, z + 18, 65, 2, 1);
		world.setBlock(x + 7, y + 14, z + 19, 17, 13, 1);
		world.setBlock(x + 0, y + 14, z + 21, 35, 14, 1);
		world.setBlock(x + 1, y + 14, z + 21, 35, 14, 1);
		world.setBlock(x + 2, y + 14, z + 21, 35, 14, 1);
		world.setBlock(x + 3, y + 14, z + 21, 35, 0, 1);
		world.setBlock(x + 4, y + 14, z + 21, 35, 0, 1);
		world.setBlock(x + 5, y + 14, z + 21, 35, 0, 1);
		world.setBlock(x + 6, y + 14, z + 21, 35, 14, 1);
		world.setBlock(x + 7, y + 14, z + 21, 35, 14, 1);
		world.setBlock(x + 8, y + 14, z + 21, 35, 14, 1);
		world.setBlock(x + 9, y + 14, z + 21, 35, 0, 1);
		world.setBlock(x + 10, y + 14, z + 21, 35, 0, 1);
		world.setBlock(x + 11, y + 14, z + 21, 35, 0, 1);
		world.setBlock(x + 12, y + 14, z + 21, 35, 14, 1);
		world.setBlock(x + 13, y + 14, z + 21, 35, 14, 1);
		world.setBlock(x + 14, y + 14, z + 21, 35, 14, 1);
		world.setBlock(x + 3, y + 14, z + 28, 17, 13, 1);
		world.setBlock(x + 4, y + 14, z + 28, 17, 13, 1);
		world.setBlock(x + 5, y + 14, z + 28, 17, 13, 1);
		world.setBlock(x + 6, y + 14, z + 28, 17, 13, 1);
		world.setBlock(x + 7, y + 14, z + 28, 17, 13, 1);
		world.setBlock(x + 8, y + 14, z + 28, 17, 13, 1);
		world.setBlock(x + 9, y + 14, z + 28, 17, 13, 1);
		world.setBlock(x + 10, y + 14, z + 28, 17, 13, 1);
		world.setBlock(x + 11, y + 14, z + 28, 17, 13, 1);
		world.setBlock(x + 3, y + 14, z + 29, 35, 14, 1);
		world.setBlock(x + 4, y + 14, z + 29, 35, 0, 1);
		world.setBlock(x + 5, y + 14, z + 29, 35, 0, 1);
		world.setBlock(x + 6, y + 14, z + 29, 35, 14, 1);
		world.setBlock(x + 7, y + 14, z + 29, 35, 14, 1);
		world.setBlock(x + 8, y + 14, z + 29, 35, 14, 1);
		world.setBlock(x + 9, y + 14, z + 29, 35, 0, 1);
		world.setBlock(x + 10, y + 14, z + 29, 35, 0, 1);
		world.setBlock(x + 11, y + 14, z + 29, 35, 14, 1);
		world.setBlock(x + 7, y + 15, z + 11, 17, 13, 1);
		world.setBlock(x + 7, y + 15, z + 12, 50, 3, 1);
		world.setBlock(x + 3, y + 15, z + 13, 35, 14, 1);
		world.setBlock(x + 4, y + 15, z + 13, 35, 0, 1);
		world.setBlock(x + 5, y + 15, z + 13, 35, 0, 1);
		world.setBlock(x + 6, y + 15, z + 13, 35, 14, 1);
		world.setBlock(x + 7, y + 15, z + 13, 35, 14, 1);
		world.setBlock(x + 8, y + 15, z + 13, 35, 14, 1);
		world.setBlock(x + 9, y + 15, z + 13, 35, 0, 1);
		world.setBlock(x + 10, y + 15, z + 13, 35, 0, 1);
		world.setBlock(x + 11, y + 15, z + 13, 35, 14, 1);
		world.setBlock(x + 7, y + 15, z + 18, 65, 2, 1);
		world.setBlock(x + 7, y + 15, z + 19, 17, 13, 1);
		world.setBlock(x + 0, y + 15, z + 22, 35, 14, 1);
		world.setBlock(x + 1, y + 15, z + 22, 35, 14, 1);
		world.setBlock(x + 2, y + 15, z + 22, 35, 14, 1);
		world.setBlock(x + 3, y + 15, z + 22, 35, 0, 1);
		world.setBlock(x + 4, y + 15, z + 22, 35, 0, 1);
		world.setBlock(x + 5, y + 15, z + 22, 35, 0, 1);
		world.setBlock(x + 6, y + 15, z + 22, 35, 14, 1);
		world.setBlock(x + 7, y + 15, z + 22, 35, 14, 1);
		world.setBlock(x + 8, y + 15, z + 22, 35, 14, 1);
		world.setBlock(x + 9, y + 15, z + 22, 35, 0, 1);
		world.setBlock(x + 10, y + 15, z + 22, 35, 0, 1);
		world.setBlock(x + 11, y + 15, z + 22, 35, 0, 1);
		world.setBlock(x + 12, y + 15, z + 22, 35, 14, 1);
		world.setBlock(x + 13, y + 15, z + 22, 35, 14, 1);
		world.setBlock(x + 14, y + 15, z + 22, 35, 14, 1);
		world.setBlock(x + 7, y + 15, z + 28, 17, 13, 1);
		world.setBlock(x + 7, y + 15, z + 29, 50, 3, 1);
		world.setBlock(x + 3, y + 15, z + 30, 35, 14, 1);
		world.setBlock(x + 4, y + 15, z + 30, 35, 0, 1);
		world.setBlock(x + 5, y + 15, z + 30, 35, 0, 1);
		world.setBlock(x + 6, y + 15, z + 30, 35, 14, 1);
		world.setBlock(x + 7, y + 15, z + 30, 35, 14, 1);
		world.setBlock(x + 8, y + 15, z + 30, 35, 14, 1);
		world.setBlock(x + 9, y + 15, z + 30, 35, 0, 1);
		world.setBlock(x + 10, y + 15, z + 30, 35, 0, 1);
		world.setBlock(x + 11, y + 15, z + 30, 35, 14, 1);
		world.setBlock(x + 7, y + 16, z + 11, 17, 13, 1);
		world.setBlock(x + 3, y + 16, z + 13, 35, 14, 1);
		world.setBlock(x + 4, y + 16, z + 13, 35, 0, 1);
		world.setBlock(x + 5, y + 16, z + 13, 35, 0, 1);
		world.setBlock(x + 6, y + 16, z + 13, 35, 14, 1);
		world.setBlock(x + 7, y + 16, z + 13, 35, 14, 1);
		world.setBlock(x + 8, y + 16, z + 13, 35, 14, 1);
		world.setBlock(x + 9, y + 16, z + 13, 35, 0, 1);
		world.setBlock(x + 10, y + 16, z + 13, 35, 0, 1);
		world.setBlock(x + 11, y + 16, z + 13, 35, 14, 1);
		world.setBlock(x + 7, y + 16, z + 18, 65, 2, 1);
		world.setBlock(x + 7, y + 16, z + 19, 17, 13, 1);
		world.setBlock(x + 0, y + 16, z + 22, 35, 14, 1);
		world.setBlock(x + 1, y + 16, z + 22, 35, 14, 1);
		world.setBlock(x + 2, y + 16, z + 22, 35, 14, 1);
		world.setBlock(x + 3, y + 16, z + 22, 35, 0, 1);
		world.setBlock(x + 4, y + 16, z + 22, 35, 0, 1);
		world.setBlock(x + 5, y + 16, z + 22, 35, 0, 1);
		world.setBlock(x + 6, y + 16, z + 22, 35, 14, 1);
		world.setBlock(x + 7, y + 16, z + 22, 35, 14, 1);
		world.setBlock(x + 8, y + 16, z + 22, 35, 14, 1);
		world.setBlock(x + 9, y + 16, z + 22, 35, 0, 1);
		world.setBlock(x + 10, y + 16, z + 22, 35, 0, 1);
		world.setBlock(x + 11, y + 16, z + 22, 35, 0, 1);
		world.setBlock(x + 12, y + 16, z + 22, 35, 14, 1);
		world.setBlock(x + 13, y + 16, z + 22, 35, 14, 1);
		world.setBlock(x + 14, y + 16, z + 22, 35, 14, 1);
		world.setBlock(x + 7, y + 16, z + 28, 17, 13, 1);
		world.setBlock(x + 3, y + 16, z + 30, 35, 14, 1);
		world.setBlock(x + 4, y + 16, z + 30, 35, 0, 1);
		world.setBlock(x + 5, y + 16, z + 30, 35, 0, 1);
		world.setBlock(x + 6, y + 16, z + 30, 35, 14, 1);
		world.setBlock(x + 7, y + 16, z + 30, 35, 14, 1);
		world.setBlock(x + 8, y + 16, z + 30, 35, 14, 1);
		world.setBlock(x + 9, y + 16, z + 30, 35, 0, 1);
		world.setBlock(x + 10, y + 16, z + 30, 35, 0, 1);
		world.setBlock(x + 11, y + 16, z + 30, 35, 14, 1);
		world.setBlock(x + 7, y + 17, z + 11, 17, 13, 1);
		world.setBlock(x + 3, y + 17, z + 13, 35, 14, 1);
		world.setBlock(x + 4, y + 17, z + 13, 35, 0, 1);
		world.setBlock(x + 5, y + 17, z + 13, 35, 0, 1);
		world.setBlock(x + 6, y + 17, z + 13, 35, 14, 1);
		world.setBlock(x + 7, y + 17, z + 13, 35, 14, 1);
		world.setBlock(x + 8, y + 17, z + 13, 35, 14, 1);
		world.setBlock(x + 9, y + 17, z + 13, 35, 0, 1);
		world.setBlock(x + 10, y + 17, z + 13, 35, 0, 1);
		world.setBlock(x + 11, y + 17, z + 13, 35, 14, 1);
		world.setBlock(x + 7, y + 17, z + 18, 65, 2, 1);
		world.setBlock(x + 7, y + 17, z + 19, 17, 13, 1);
		world.setBlock(x + 0, y + 17, z + 22, 35, 14, 1);
		world.setBlock(x + 1, y + 17, z + 22, 35, 14, 1);
		world.setBlock(x + 2, y + 17, z + 22, 35, 14, 1);
		world.setBlock(x + 3, y + 17, z + 22, 35, 0, 1);
		world.setBlock(x + 4, y + 17, z + 22, 35, 0, 1);
		world.setBlock(x + 5, y + 17, z + 22, 35, 0, 1);
		world.setBlock(x + 6, y + 17, z + 22, 35, 14, 1);
		world.setBlock(x + 7, y + 17, z + 22, 35, 14, 1);
		world.setBlock(x + 8, y + 17, z + 22, 35, 14, 1);
		world.setBlock(x + 9, y + 17, z + 22, 35, 0, 1);
		world.setBlock(x + 10, y + 17, z + 22, 35, 0, 1);
		world.setBlock(x + 11, y + 17, z + 22, 35, 0, 1);
		world.setBlock(x + 12, y + 17, z + 22, 35, 14, 1);
		world.setBlock(x + 13, y + 17, z + 22, 35, 14, 1);
		world.setBlock(x + 14, y + 17, z + 22, 35, 14, 1);
		world.setBlock(x + 7, y + 17, z + 28, 17, 13, 1);
		world.setBlock(x + 3, y + 17, z + 30, 35, 14, 1);
		world.setBlock(x + 4, y + 17, z + 30, 35, 0, 1);
		world.setBlock(x + 5, y + 17, z + 30, 35, 0, 1);
		world.setBlock(x + 6, y + 17, z + 30, 35, 14, 1);
		world.setBlock(x + 7, y + 17, z + 30, 35, 14, 1);
		world.setBlock(x + 8, y + 17, z + 30, 35, 14, 1);
		world.setBlock(x + 9, y + 17, z + 30, 35, 0, 1);
		world.setBlock(x + 10, y + 17, z + 30, 35, 0, 1);
		world.setBlock(x + 11, y + 17, z + 30, 35, 14, 1);
		world.setBlock(x + 7, y + 18, z + 11, 17, 13, 1);
		world.setBlock(x + 3, y + 18, z + 13, 35, 14, 1);
		world.setBlock(x + 4, y + 18, z + 13, 35, 0, 1);
		world.setBlock(x + 5, y + 18, z + 13, 35, 0, 1);
		world.setBlock(x + 6, y + 18, z + 13, 35, 14, 1);
		world.setBlock(x + 7, y + 18, z + 13, 35, 14, 1);
		world.setBlock(x + 8, y + 18, z + 13, 35, 14, 1);
		world.setBlock(x + 9, y + 18, z + 13, 35, 0, 1);
		world.setBlock(x + 10, y + 18, z + 13, 35, 0, 1);
		world.setBlock(x + 11, y + 18, z + 13, 35, 14, 1);
		world.setBlock(x + 7, y + 18, z + 18, 65, 2, 1);
		world.setBlock(x + 7, y + 18, z + 19, 17, 13, 1);
		world.setBlock(x + 0, y + 18, z + 22, 35, 14, 1);
		world.setBlock(x + 1, y + 18, z + 22, 35, 14, 1);
		world.setBlock(x + 2, y + 18, z + 22, 35, 14, 1);
		world.setBlock(x + 3, y + 18, z + 22, 35, 0, 1);
		world.setBlock(x + 4, y + 18, z + 22, 35, 0, 1);
		world.setBlock(x + 5, y + 18, z + 22, 35, 0, 1);
		world.setBlock(x + 6, y + 18, z + 22, 35, 14, 1);
		world.setBlock(x + 7, y + 18, z + 22, 35, 14, 1);
		world.setBlock(x + 8, y + 18, z + 22, 35, 14, 1);
		world.setBlock(x + 9, y + 18, z + 22, 35, 0, 1);
		world.setBlock(x + 10, y + 18, z + 22, 35, 0, 1);
		world.setBlock(x + 11, y + 18, z + 22, 35, 0, 1);
		world.setBlock(x + 12, y + 18, z + 22, 35, 14, 1);
		world.setBlock(x + 13, y + 18, z + 22, 35, 14, 1);
		world.setBlock(x + 14, y + 18, z + 22, 35, 14, 1);
		world.setBlock(x + 7, y + 18, z + 28, 17, 13, 1);
		world.setBlock(x + 3, y + 18, z + 30, 35, 14, 1);
		world.setBlock(x + 4, y + 18, z + 30, 35, 0, 1);
		world.setBlock(x + 5, y + 18, z + 30, 35, 0, 1);
		world.setBlock(x + 6, y + 18, z + 30, 35, 14, 1);
		world.setBlock(x + 7, y + 18, z + 30, 35, 14, 1);
		world.setBlock(x + 8, y + 18, z + 30, 35, 14, 1);
		world.setBlock(x + 9, y + 18, z + 30, 35, 0, 1);
		world.setBlock(x + 10, y + 18, z + 30, 35, 0, 1);
		world.setBlock(x + 11, y + 18, z + 30, 35, 14, 1);
		world.setBlock(x + 7, y + 19, z + 11, 17, 13, 1);
		world.setBlock(x + 3, y + 19, z + 13, 35, 14, 1);
		world.setBlock(x + 4, y + 19, z + 13, 35, 0, 1);
		world.setBlock(x + 5, y + 19, z + 13, 35, 0, 1);
		world.setBlock(x + 6, y + 19, z + 13, 35, 14, 1);
		world.setBlock(x + 7, y + 19, z + 13, 35, 14, 1);
		world.setBlock(x + 8, y + 19, z + 13, 35, 14, 1);
		world.setBlock(x + 9, y + 19, z + 13, 35, 0, 1);
		world.setBlock(x + 10, y + 19, z + 13, 35, 0, 1);
		world.setBlock(x + 11, y + 19, z + 13, 35, 14, 1);
		world.setBlock(x + 7, y + 19, z + 18, 65, 2, 1);
		world.setBlock(x + 7, y + 19, z + 19, 17, 13, 1);
		world.setBlock(x + 0, y + 19, z + 22, 35, 14, 1);
		world.setBlock(x + 1, y + 19, z + 22, 35, 14, 1);
		world.setBlock(x + 2, y + 19, z + 22, 35, 14, 1);
		world.setBlock(x + 3, y + 19, z + 22, 35, 0, 1);
		world.setBlock(x + 4, y + 19, z + 22, 35, 0, 1);
		world.setBlock(x + 5, y + 19, z + 22, 35, 0, 1);
		world.setBlock(x + 6, y + 19, z + 22, 35, 14, 1);
		world.setBlock(x + 7, y + 19, z + 22, 35, 14, 1);
		world.setBlock(x + 8, y + 19, z + 22, 35, 14, 1);
		world.setBlock(x + 9, y + 19, z + 22, 35, 0, 1);
		world.setBlock(x + 10, y + 19, z + 22, 35, 0, 1);
		world.setBlock(x + 11, y + 19, z + 22, 35, 0, 1);
		world.setBlock(x + 12, y + 19, z + 22, 35, 14, 1);
		world.setBlock(x + 13, y + 19, z + 22, 35, 14, 1);
		world.setBlock(x + 14, y + 19, z + 22, 35, 14, 1);
		world.setBlock(x + 7, y + 19, z + 28, 17, 13, 1);
		world.setBlock(x + 3, y + 19, z + 30, 35, 14, 1);
		world.setBlock(x + 4, y + 19, z + 30, 35, 0, 1);
		world.setBlock(x + 5, y + 19, z + 30, 35, 0, 1);
		world.setBlock(x + 6, y + 19, z + 30, 35, 14, 1);
		world.setBlock(x + 7, y + 19, z + 30, 35, 14, 1);
		world.setBlock(x + 8, y + 19, z + 30, 35, 14, 1);
		world.setBlock(x + 9, y + 19, z + 30, 35, 0, 1);
		world.setBlock(x + 10, y + 19, z + 30, 35, 0, 1);
		world.setBlock(x + 11, y + 19, z + 30, 35, 14, 1);
		world.setBlock(x + 7, y + 20, z + 11, 17, 13, 1);
		world.setBlock(x + 7, y + 20, z + 12, 50, 3, 1);
		world.setBlock(x + 3, y + 20, z + 13, 35, 14, 1);
		world.setBlock(x + 4, y + 20, z + 13, 35, 0, 1);
		world.setBlock(x + 5, y + 20, z + 13, 35, 0, 1);
		world.setBlock(x + 6, y + 20, z + 13, 35, 14, 1);
		world.setBlock(x + 7, y + 20, z + 13, 35, 14, 1);
		world.setBlock(x + 8, y + 20, z + 13, 35, 14, 1);
		world.setBlock(x + 9, y + 20, z + 13, 35, 0, 1);
		world.setBlock(x + 10, y + 20, z + 13, 35, 0, 1);
		world.setBlock(x + 11, y + 20, z + 13, 35, 14, 1);
		world.setBlock(x + 7, y + 20, z + 18, 65, 2, 1);
		world.setBlock(x + 7, y + 20, z + 19, 17, 13, 1);
		world.setBlock(x + 0, y + 20, z + 22, 35, 14, 1);
		world.setBlock(x + 1, y + 20, z + 22, 35, 14, 1);
		world.setBlock(x + 2, y + 20, z + 22, 35, 14, 1);
		world.setBlock(x + 3, y + 20, z + 22, 35, 0, 1);
		world.setBlock(x + 4, y + 20, z + 22, 35, 0, 1);
		world.setBlock(x + 5, y + 20, z + 22, 35, 0, 1);
		world.setBlock(x + 6, y + 20, z + 22, 35, 14, 1);
		world.setBlock(x + 7, y + 20, z + 22, 35, 14, 1);
		world.setBlock(x + 8, y + 20, z + 22, 35, 14, 1);
		world.setBlock(x + 9, y + 20, z + 22, 35, 0, 1);
		world.setBlock(x + 10, y + 20, z + 22, 35, 0, 1);
		world.setBlock(x + 11, y + 20, z + 22, 35, 0, 1);
		world.setBlock(x + 12, y + 20, z + 22, 35, 14, 1);
		world.setBlock(x + 13, y + 20, z + 22, 35, 14, 1);
		world.setBlock(x + 14, y + 20, z + 22, 35, 14, 1);
		world.setBlock(x + 7, y + 20, z + 28, 17, 13, 1);
		world.setBlock(x + 7, y + 20, z + 29, 50, 3, 1);
		world.setBlock(x + 3, y + 20, z + 30, 35, 14, 1);
		world.setBlock(x + 4, y + 20, z + 30, 35, 0, 1);
		world.setBlock(x + 5, y + 20, z + 30, 35, 0, 1);
		world.setBlock(x + 6, y + 20, z + 30, 35, 14, 1);
		world.setBlock(x + 7, y + 20, z + 30, 35, 14, 1);
		world.setBlock(x + 8, y + 20, z + 30, 35, 14, 1);
		world.setBlock(x + 9, y + 20, z + 30, 35, 0, 1);
		world.setBlock(x + 10, y + 20, z + 30, 35, 0, 1);
		world.setBlock(x + 11, y + 20, z + 30, 35, 14, 1);
		world.setBlock(x + 3, y + 21, z + 11, 17, 13, 1);
		world.setBlock(x + 4, y + 21, z + 11, 17, 13, 1);
		world.setBlock(x + 5, y + 21, z + 11, 17, 13, 1);
		world.setBlock(x + 6, y + 21, z + 11, 17, 13, 1);
		world.setBlock(x + 7, y + 21, z + 11, 17, 13, 1);
		world.setBlock(x + 8, y + 21, z + 11, 17, 13, 1);
		world.setBlock(x + 9, y + 21, z + 11, 17, 13, 1);
		world.setBlock(x + 10, y + 21, z + 11, 17, 13, 1);
		world.setBlock(x + 11, y + 21, z + 11, 17, 13, 1);
		world.setBlock(x + 3, y + 21, z + 12, 35, 14, 1);
		world.setBlock(x + 4, y + 21, z + 12, 35, 0, 1);
		world.setBlock(x + 5, y + 21, z + 12, 35, 0, 1);
		world.setBlock(x + 6, y + 21, z + 12, 35, 14, 1);
		world.setBlock(x + 7, y + 21, z + 12, 35, 14, 1);
		world.setBlock(x + 8, y + 21, z + 12, 35, 14, 1);
		world.setBlock(x + 9, y + 21, z + 12, 35, 0, 1);
		world.setBlock(x + 10, y + 21, z + 12, 35, 0, 1);
		world.setBlock(x + 11, y + 21, z + 12, 35, 14, 1);
		world.setBlock(x + 7, y + 21, z + 18, 65, 2, 1);
		world.setBlock(x + 7, y + 21, z + 19, 17, 13, 1);
		world.setBlock(x + 0, y + 21, z + 22, 35, 14, 1);
		world.setBlock(x + 1, y + 21, z + 22, 35, 14, 1);
		world.setBlock(x + 2, y + 21, z + 22, 35, 14, 1);
		world.setBlock(x + 3, y + 21, z + 22, 35, 0, 1);
		world.setBlock(x + 4, y + 21, z + 22, 35, 0, 1);
		world.setBlock(x + 5, y + 21, z + 22, 35, 0, 1);
		world.setBlock(x + 6, y + 21, z + 22, 35, 14, 1);
		world.setBlock(x + 7, y + 21, z + 22, 35, 14, 1);
		world.setBlock(x + 8, y + 21, z + 22, 35, 14, 1);
		world.setBlock(x + 9, y + 21, z + 22, 35, 0, 1);
		world.setBlock(x + 10, y + 21, z + 22, 35, 0, 1);
		world.setBlock(x + 11, y + 21, z + 22, 35, 0, 1);
		world.setBlock(x + 12, y + 21, z + 22, 35, 14, 1);
		world.setBlock(x + 13, y + 21, z + 22, 35, 14, 1);
		world.setBlock(x + 14, y + 21, z + 22, 35, 14, 1);
		world.setBlock(x + 3, y + 21, z + 28, 17, 13, 1);
		world.setBlock(x + 4, y + 21, z + 28, 17, 13, 1);
		world.setBlock(x + 5, y + 21, z + 28, 17, 13, 1);
		world.setBlock(x + 6, y + 21, z + 28, 17, 13, 1);
		world.setBlock(x + 7, y + 21, z + 28, 17, 13, 1);
		world.setBlock(x + 8, y + 21, z + 28, 17, 13, 1);
		world.setBlock(x + 9, y + 21, z + 28, 17, 13, 1);
		world.setBlock(x + 10, y + 21, z + 28, 17, 13, 1);
		world.setBlock(x + 11, y + 21, z + 28, 17, 13, 1);
		world.setBlock(x + 3, y + 21, z + 29, 35, 14, 1);
		world.setBlock(x + 4, y + 21, z + 29, 35, 0, 1);
		world.setBlock(x + 5, y + 21, z + 29, 35, 0, 1);
		world.setBlock(x + 6, y + 21, z + 29, 35, 14, 1);
		world.setBlock(x + 7, y + 21, z + 29, 35, 14, 1);
		world.setBlock(x + 8, y + 21, z + 29, 35, 14, 1);
		world.setBlock(x + 9, y + 21, z + 29, 35, 0, 1);
		world.setBlock(x + 10, y + 21, z + 29, 35, 0, 1);
		world.setBlock(x + 11, y + 21, z + 29, 35, 14, 1);
		world.setBlock(x + 7, y + 22, z + 11, 17, 13, 1);
		world.setBlock(x + 7, y + 22, z + 18, 65, 2, 1);
		world.setBlock(x + 7, y + 22, z + 19, 17, 13, 1);
		world.setBlock(x + 0, y + 22, z + 21, 35, 14, 1);
		world.setBlock(x + 1, y + 22, z + 21, 35, 14, 1);
		world.setBlock(x + 2, y + 22, z + 21, 35, 14, 1);
		world.setBlock(x + 3, y + 22, z + 21, 35, 0, 1);
		world.setBlock(x + 4, y + 22, z + 21, 35, 0, 1);
		world.setBlock(x + 5, y + 22, z + 21, 35, 0, 1);
		world.setBlock(x + 6, y + 22, z + 21, 35, 14, 1);
		world.setBlock(x + 7, y + 22, z + 21, 35, 14, 1);
		world.setBlock(x + 8, y + 22, z + 21, 35, 14, 1);
		world.setBlock(x + 9, y + 22, z + 21, 35, 0, 1);
		world.setBlock(x + 10, y + 22, z + 21, 35, 0, 1);
		world.setBlock(x + 11, y + 22, z + 21, 35, 0, 1);
		world.setBlock(x + 12, y + 22, z + 21, 35, 14, 1);
		world.setBlock(x + 13, y + 22, z + 21, 35, 14, 1);
		world.setBlock(x + 14, y + 22, z + 21, 35, 14, 1);
		world.setBlock(x + 7, y + 22, z + 28, 17, 13, 1);
		world.setBlock(x + 7, y + 23, z + 11, 17, 13, 1);
		world.setBlock(x + 7, y + 23, z + 18, 65, 2, 1);
		world.setBlock(x + 7, y + 23, z + 19, 17, 13, 1);
		world.setBlock(x + 0, y + 23, z + 21, 35, 14, 1);
		world.setBlock(x + 1, y + 23, z + 21, 35, 14, 1);
		world.setBlock(x + 2, y + 23, z + 21, 35, 14, 1);
		world.setBlock(x + 3, y + 23, z + 21, 35, 0, 1);
		world.setBlock(x + 4, y + 23, z + 21, 35, 0, 1);
		world.setBlock(x + 5, y + 23, z + 21, 35, 0, 1);
		world.setBlock(x + 6, y + 23, z + 21, 35, 14, 1);
		world.setBlock(x + 7, y + 23, z + 21, 35, 14, 1);
		world.setBlock(x + 8, y + 23, z + 21, 35, 14, 1);
		world.setBlock(x + 9, y + 23, z + 21, 35, 0, 1);
		world.setBlock(x + 10, y + 23, z + 21, 35, 0, 1);
		world.setBlock(x + 11, y + 23, z + 21, 35, 0, 1);
		world.setBlock(x + 12, y + 23, z + 21, 35, 14, 1);
		world.setBlock(x + 13, y + 23, z + 21, 35, 14, 1);
		world.setBlock(x + 14, y + 23, z + 21, 35, 14, 1);
		world.setBlock(x + 7, y + 23, z + 28, 17, 13, 1);
		world.setBlock(x + 7, y + 24, z + 10, 50, 4, 1);
		world.setBlock(x + 6, y + 24, z + 11, 50, 2, 1);
		world.setBlock(x + 7, y + 24, z + 11, 17, 13, 1);
		world.setBlock(x + 8, y + 24, z + 11, 50, 1, 1);
		world.setBlock(x + 7, y + 24, z + 12, 50, 3, 1);
		world.setBlock(x + 7, y + 24, z + 18, 65, 2, 1);
		world.setBlock(x + 7, y + 24, z + 19, 17, 13, 1);
		world.setBlock(x + 7, y + 24, z + 20, 50, 3, 1);
		world.setBlock(x + 0, y + 24, z + 21, 35, 14, 1);
		world.setBlock(x + 1, y + 24, z + 21, 35, 14, 1);
		world.setBlock(x + 2, y + 24, z + 21, 35, 14, 1);
		world.setBlock(x + 3, y + 24, z + 21, 35, 0, 1);
		world.setBlock(x + 4, y + 24, z + 21, 35, 0, 1);
		world.setBlock(x + 5, y + 24, z + 21, 35, 0, 1);
		world.setBlock(x + 6, y + 24, z + 21, 35, 14, 1);
		world.setBlock(x + 7, y + 24, z + 21, 35, 14, 1);
		world.setBlock(x + 8, y + 24, z + 21, 35, 14, 1);
		world.setBlock(x + 9, y + 24, z + 21, 35, 0, 1);
		world.setBlock(x + 10, y + 24, z + 21, 35, 0, 1);
		world.setBlock(x + 11, y + 24, z + 21, 35, 0, 1);
		world.setBlock(x + 12, y + 24, z + 21, 35, 14, 1);
		world.setBlock(x + 13, y + 24, z + 21, 35, 14, 1);
		world.setBlock(x + 14, y + 24, z + 21, 35, 14, 1);
		world.setBlock(x + 7, y + 24, z + 27, 50, 4, 1);
		world.setBlock(x + 6, y + 24, z + 28, 50, 2, 1);
		world.setBlock(x + 7, y + 24, z + 28, 17, 13, 1);
		world.setBlock(x + 8, y + 24, z + 28, 50, 1, 1);
		world.setBlock(x + 7, y + 24, z + 29, 50, 3, 1);
		world.setBlock(x + 7, y + 25, z + 18, 65, 2, 1);
		world.setBlock(x + 0, y + 25, z + 19, 17, 13, 1);
		world.setBlock(x + 1, y + 25, z + 19, 17, 13, 1);
		world.setBlock(x + 2, y + 25, z + 19, 17, 13, 1);
		world.setBlock(x + 3, y + 25, z + 19, 17, 13, 1);
		world.setBlock(x + 4, y + 25, z + 19, 17, 13, 1);
		world.setBlock(x + 5, y + 25, z + 19, 17, 13, 1);
		world.setBlock(x + 6, y + 25, z + 19, 17, 13, 1);
		world.setBlock(x + 7, y + 25, z + 19, 17, 13, 1);
		world.setBlock(x + 8, y + 25, z + 19, 17, 13, 1);
		world.setBlock(x + 9, y + 25, z + 19, 17, 13, 1);
