/*
*** MADE BY MITHION'S .SCHEMATIC TO JAVA CONVERTING TOOL v1.6 ***
*/

package arcticraft.gen;
import java.util.Random;

import arcticraft.main.MainRegistry;

import net.minecraft.block.Block;
import net.minecraft.world.World;
import net.minecraft.world.gen.feature.WorldGenerator;

public class AC_GenEskimoVillage extends WorldGenerator
{
	protected int[] GetValidSpawnBlocks() {
		return new int[] {
			Block.blockSnow.blockID
		};
	}

	public boolean LocationIsValidSpawn(World world, int i, int j, int k){
		int distanceToAir = 0;
		int checkID = world.getBlockId(i, j, k);

		while (checkID != 0){
			distanceToAir++;
			checkID = world.getBlockId(i, j + distanceToAir, k);
		}

		if (distanceToAir > 3){
			return false;
		}
		j += distanceToAir - 1;

		int blockID = world.getBlockId(i, j, k);
		int blockIDAbove = world.getBlockId(i, j+1, k);
		int blockIDBelow = world.getBlockId(i, j-1, k);
		for (int x : GetValidSpawnBlocks()){
			if (blockIDAbove != 0){
				return false;
			}
			if (blockID == x){
				return true;
			}else if (blockID == Block.snow.blockID && blockIDBelow == x){
				return true;
			}
		}
		return false;
	}

	public AC_GenEskimoVillage() { }

	public boolean generate(World world, Random rand, int i, int j, int k) {
		//check that each corner is one of the valid spawn blocks
		if(!LocationIsValidSpawn(world, i, j, k) || !LocationIsValidSpawn(world, i + 92, j, k) || !LocationIsValidSpawn(world, i + 92, j, k + 35) || !LocationIsValidSpawn(world, i, j, k + 35))
		{
			return false;
		}

		world.setBlock(i + 3, j + 0, k + 17, Block.blockSnow.blockID);
		world.setBlock(i + 3, j + 0, k + 18, Block.blockSnow.blockID);
		world.setBlock(i + 3, j + 0, k + 19, Block.blockSnow.blockID);
		world.setBlock(i + 3, j + 0, k + 20, Block.blockSnow.blockID);
		world.setBlock(i + 3, j + 0, k + 21, Block.blockSnow.blockID);
		world.setBlock(i + 3, j + 1, k + 17, Block.ice.blockID);
		world.setBlock(i + 3, j + 1, k + 18, Block.ice.blockID);
		world.setBlock(i + 3, j + 1, k + 19, Block.ice.blockID);
		world.setBlock(i + 3, j + 1, k + 20, Block.ice.blockID);
		world.setBlock(i + 3, j + 1, k + 21, Block.ice.blockID);
		world.setBlock(i + 3, j + 2, k + 17, Block.ice.blockID);
		world.setBlock(i + 3, j + 2, k + 18, Block.ice.blockID);
		world.setBlock(i + 3, j + 2, k + 19, Block.ice.blockID);
		world.setBlock(i + 3, j + 2, k + 20, Block.ice.blockID);
		world.setBlock(i + 3, j + 2, k + 21, Block.ice.blockID);
		world.setBlock(i + 3, j + 3, k + 17, Block.ice.blockID);
		world.setBlock(i + 3, j + 3, k + 18, Block.ice.blockID);
		world.setBlock(i + 3, j + 3, k + 19, Block.ice.blockID);
		world.setBlock(i + 3, j + 3, k + 20, Block.ice.blockID);
		world.setBlock(i + 3, j + 3, k + 21, Block.ice.blockID);
		world.setBlock(i + 3, j + 4, k + 17, Block.ice.blockID);
		world.setBlock(i + 3, j + 4, k + 18, Block.ice.blockID);
		world.setBlock(i + 3, j + 4, k + 19, Block.ice.blockID);
		world.setBlock(i + 3, j + 4, k + 20, Block.ice.blockID);
		world.setBlock(i + 3, j + 4, k + 21, Block.ice.blockID);
		world.setBlock(i + 3, j + 5, k + 17, Block.ice.blockID);
		world.setBlock(i + 3, j + 5, k + 18, Block.ice.blockID);
		world.setBlock(i + 3, j + 5, k + 19, Block.ice.blockID);
		world.setBlock(i + 3, j + 5, k + 20, Block.ice.blockID);
		world.setBlock(i + 3, j + 5, k + 21, Block.ice.blockID);
		world.setBlock(i + 3, j + 6, k + 17, Block.ice.blockID);
		world.setBlock(i + 3, j + 6, k + 18, Block.ice.blockID);
		world.setBlock(i + 3, j + 6, k + 19, Block.ice.blockID);
		world.setBlock(i + 3, j + 6, k + 20, Block.ice.blockID);
		world.setBlock(i + 3, j + 6, k + 21, Block.ice.blockID);
		world.setBlock(i + 3, j + 7, k + 17, Block.ice.blockID);
		world.setBlock(i + 3, j + 7, k + 18, Block.ice.blockID);
		world.setBlock(i + 3, j + 7, k + 19, Block.ice.blockID);
		world.setBlock(i + 3, j + 7, k + 20, Block.ice.blockID);
		world.setBlock(i + 3, j + 7, k + 21, Block.ice.blockID);
		world.setBlock(i + 4, j + 0, k + 16, Block.blockSnow.blockID);
		world.setBlock(i + 4, j + 0, k + 22, Block.blockSnow.blockID);
		world.setBlock(i + 4, j + 1, k + 16, Block.ice.blockID);
		world.setBlock(i + 4, j + 1, k + 22, Block.ice.blockID);
		world.setBlock(i + 4, j + 2, k + 16, Block.ice.blockID);
		world.setBlock(i + 4, j + 2, k + 22, Block.ice.blockID);
		world.setBlock(i + 4, j + 3, k + 16, Block.ice.blockID);
		world.setBlock(i + 4, j + 3, k + 22, Block.ice.blockID);
		world.setBlock(i + 4, j + 4, k + 16, Block.ice.blockID);
		world.setBlock(i + 4, j + 4, k + 22, Block.ice.blockID);
		world.setBlock(i + 4, j + 5, k + 16, Block.ice.blockID);
		world.setBlock(i + 4, j + 5, k + 19, Block.oreIron.blockID);
		world.setBlock(i + 4, j + 5, k + 22, Block.ice.blockID);
		world.setBlock(i + 4, j + 6, k + 16, Block.ice.blockID);
		world.setBlock(i + 4, j + 6, k + 22, Block.ice.blockID);
		world.setBlock(i + 4, j + 7, k + 16, Block.ice.blockID);
		world.setBlock(i + 4, j + 7, k + 22, Block.ice.blockID);
		world.setBlock(i + 4, j + 8, k + 17, Block.ice.blockID);
		world.setBlock(i + 4, j + 8, k + 18, Block.ice.blockID);
		world.setBlock(i + 4, j + 8, k + 19, Block.ice.blockID);
		world.setBlock(i + 4, j + 8, k + 20, Block.ice.blockID);
		world.setBlock(i + 4, j + 8, k + 21, Block.ice.blockID);
		world.setBlock(i + 5, j + 0, k + 15, Block.blockSnow.blockID);
		world.setBlock(i + 5, j + 0, k + 23, Block.blockSnow.blockID);
		world.setBlock(i + 5, j + 1, k + 15, Block.ice.blockID);
		world.setBlock(i + 5, j + 1, k + 23, Block.ice.blockID);
		world.setBlock(i + 5, j + 2, k + 15, Block.ice.blockID);
		world.setBlock(i + 5, j + 2, k + 23, Block.ice.blockID);
		world.setBlock(i + 5, j + 3, k + 15, Block.ice.blockID);
		world.setBlock(i + 5, j + 3, k + 23, Block.ice.blockID);
		world.setBlock(i + 5, j + 4, k + 15, Block.ice.blockID);
		world.setBlock(i + 5, j + 4, k + 23, Block.ice.blockID);
		world.setBlock(i + 5, j + 5, k + 15, Block.ice.blockID);
		world.setBlock(i + 5, j + 5, k + 23, Block.ice.blockID);
		world.setBlock(i + 5, j + 6, k + 15, Block.ice.blockID);
		world.setBlock(i + 5, j + 6, k + 23, Block.ice.blockID);
		world.setBlock(i + 5, j + 7, k + 15, Block.ice.blockID);
		world.setBlock(i + 5, j + 7, k + 23, Block.ice.blockID);
		world.setBlock(i + 5, j + 8, k + 16, Block.ice.blockID);
		world.setBlock(i + 5, j + 8, k + 22, Block.ice.blockID);
		world.setBlock(i + 5, j + 9, k + 17, Block.ice.blockID);
		world.setBlock(i + 5, j + 9, k + 18, Block.ice.blockID);
		world.setBlock(i + 5, j + 9, k + 19, Block.ice.blockID);
		world.setBlock(i + 5, j + 9, k + 20, Block.ice.blockID);
		world.setBlock(i + 5, j + 9, k + 21, Block.ice.blockID);
		world.setBlock(i + 6, j + 0, k + 15, Block.blockSnow.blockID);
		world.setBlock(i + 6, j + 0, k + 19, Block.blockDiamond.blockID);
		world.setBlock(i + 6, j + 0, k + 23, Block.blockSnow.blockID);
		world.setBlock(i + 6, j + 1, k + 15, Block.ice.blockID);
		world.setBlock(i + 6, j + 1, k + 23, Block.ice.blockID);
		world.setBlock(i + 6, j + 2, k + 15, Block.ice.blockID);
		world.setBlock(i + 6, j + 2, k + 23, Block.ice.blockID);
		world.setBlock(i + 6, j + 3, k + 15, Block.ice.blockID);
		world.setBlock(i + 6, j + 3, k + 23, Block.ice.blockID);
		world.setBlock(i + 6, j + 4, k + 15, Block.ice.blockID);
		world.setBlock(i + 6, j + 4, k + 23, Block.ice.blockID);
		world.setBlock(i + 6, j + 5, k + 15, Block.ice.blockID);
		world.setBlock(i + 6, j + 5, k + 23, Block.ice.blockID);
		world.setBlock(i + 6, j + 6, k + 15, Block.ice.blockID);
		world.setBlock(i + 6, j + 6, k + 23, Block.ice.blockID);
		world.setBlock(i + 6, j + 7, k + 15, Block.ice.blockID);
		world.setBlock(i + 6, j + 7, k + 23, Block.ice.blockID);
		world.setBlock(i + 6, j + 8, k + 16, Block.ice.blockID);
		world.setBlock(i + 6, j + 8, k + 22, Block.ice.blockID);
		world.setBlock(i + 6, j + 9, k + 17, Block.ice.blockID);
		world.setBlock(i + 6, j + 9, k + 21, Block.ice.blockID);
		world.setBlock(i + 6, j + 10, k + 18, Block.ice.blockID);
		world.setBlock(i + 6, j + 10, k + 19, Block.ice.blockID);
		world.setBlock(i + 6, j + 10, k + 20, Block.ice.blockID);
		world.setBlock(i + 7, j + 0, k + 15, Block.blockSnow.blockID);
		world.setBlock(i + 7, j + 0, k + 23, Block.blockSnow.blockID);
		world.setBlock(i + 7, j + 1, k + 15, Block.ice.blockID);
		world.setBlock(i + 7, j + 1, k + 23, Block.ice.blockID);
		world.setBlock(i + 7, j + 2, k + 15, Block.ice.blockID);
		world.setBlock(i + 7, j + 2, k + 23, Block.ice.blockID);
		world.setBlock(i + 7, j + 3, k + 15, Block.ice.blockID);
		world.setBlock(i + 7, j + 3, k + 23, Block.ice.blockID);
		world.setBlock(i + 7, j + 4, k + 15, Block.ice.blockID);
		world.setBlock(i + 7, j + 4, k + 23, Block.ice.blockID);
		world.setBlock(i + 7, j + 5, k + 15, Block.ice.blockID);
		world.setBlock(i + 7, j + 5, k + 23, Block.ice.blockID);
		world.setBlock(i + 7, j + 6, k + 15, Block.ice.blockID);
		world.setBlock(i + 7, j + 6, k + 23, Block.ice.blockID);
		world.setBlock(i + 7, j + 7, k + 15, Block.ice.blockID);
		world.setBlock(i + 7, j + 7, k + 23, Block.ice.blockID);
		world.setBlock(i + 7, j + 8, k + 16, Block.ice.blockID);
		world.setBlock(i + 7, j + 8, k + 22, Block.ice.blockID);
		world.setBlock(i + 7, j + 9, k + 17, Block.ice.blockID);
		world.setBlock(i + 7, j + 9, k + 21, Block.ice.blockID);
		world.setBlock(i + 7, j + 10, k + 18, Block.ice.blockID);
		world.setBlock(i + 7, j + 10, k + 20, Block.ice.blockID);
		world.setBlock(i + 7, j + 11, k + 19, Block.ice.blockID);
		world.setBlock(i + 8, j + 0, k + 15, Block.blockSnow.blockID);
		world.setBlock(i + 8, j + 0, k + 23, Block.blockSnow.blockID);
		world.setBlock(i + 8, j + 1, k + 15, Block.ice.blockID);
		world.setBlock(i + 8, j + 1, k + 23, Block.ice.blockID);
		world.setBlock(i + 8, j + 2, k + 15, Block.ice.blockID);
		world.setBlock(i + 8, j + 2, k + 23, Block.ice.blockID);
		world.setBlock(i + 8, j + 3, k + 15, Block.ice.blockID);
		world.setBlock(i + 8, j + 3, k + 23, Block.ice.blockID);
		world.setBlock(i + 8, j + 4, k + 15, Block.ice.blockID);
		world.setBlock(i + 8, j + 4, k + 23, Block.ice.blockID);
		world.setBlock(i + 8, j + 5, k + 15, Block.ice.blockID);
		world.setBlock(i + 8, j + 5, k + 23, Block.ice.blockID);
		world.setBlock(i + 8, j + 6, k + 15, Block.ice.blockID);
		world.setBlock(i + 8, j + 6, k + 23, Block.ice.blockID);
		world.setBlock(i + 8, j + 7, k + 15, Block.ice.blockID);
		world.setBlock(i + 8, j + 7, k + 23, Block.ice.blockID);
		world.setBlock(i + 8, j + 8, k + 16, Block.ice.blockID);
		world.setBlock(i + 8, j + 8, k + 22, Block.ice.blockID);
		world.setBlock(i + 8, j + 9, k + 17, Block.ice.blockID);
		world.setBlock(i + 8, j + 9, k + 21, Block.ice.blockID);
		world.setBlock(i + 8, j + 10, k + 18, Block.ice.blockID);
		world.setBlock(i + 8, j + 10, k + 20, Block.ice.blockID);
		world.setBlock(i + 8, j + 11, k + 19, Block.ice.blockID);
		world.setBlock(i + 9, j + 0, k + 14, Block.blockSnow.blockID);
		world.setBlock(i + 9, j + 0, k + 24, Block.blockSnow.blockID);
		world.setBlock(i + 9, j + 1, k + 14, Block.ice.blockID);
		world.setBlock(i + 9, j + 1, k + 24, Block.ice.blockID);
		world.setBlock(i + 9, j + 2, k + 14, Block.ice.blockID);
		world.setBlock(i + 9, j + 2, k + 24, Block.ice.blockID);
		world.setBlock(i + 9, j + 3, k + 14, Block.ice.blockID);
		world.setBlock(i + 9, j + 3, k + 24, Block.ice.blockID);
		world.setBlock(i + 9, j + 4, k + 14, Block.ice.blockID);
		world.setBlock(i + 9, j + 4, k + 24, Block.ice.blockID);
		world.setBlock(i + 9, j + 5, k + 14, Block.ice.blockID);
		world.setBlock(i + 9, j + 5, k + 24, Block.ice.blockID);
		world.setBlock(i + 9, j + 6, k + 14, Block.ice.blockID);
		world.setBlock(i + 9, j + 6, k + 24, Block.ice.blockID);
		world.setBlock(i + 9, j + 7, k + 14, Block.ice.blockID);
		world.setBlock(i + 9, j + 7, k + 24, Block.ice.blockID);
		world.setBlock(i + 9, j + 8, k + 15, Block.ice.blockID);
		world.setBlock(i + 9, j + 8, k + 23, Block.ice.blockID);
		world.setBlock(i + 9, j + 9, k + 16, Block.ice.blockID);
		world.setBlock(i + 9, j + 9, k + 22, Block.ice.blockID);
		world.setBlock(i + 9, j + 10, k + 17, Block.ice.blockID);
		world.setBlock(i + 9, j + 10, k + 21, Block.ice.blockID);
		world.setBlock(i + 9, j + 11, k + 18, Block.ice.blockID);
		world.setBlock(i + 9, j + 11, k + 19, Block.ice.blockID);
		world.setBlock(i + 9, j + 11, k + 20, Block.ice.blockID);
		world.setBlock(i + 10, j + 0, k + 13, Block.blockSnow.blockID);
		world.setBlock(i + 10, j + 0, k + 18, Block.stoneBrick.blockID);
		world.setBlock(i + 10, j + 0, k + 19, Block.stoneBrick.blockID);
		world.setBlock(i + 10, j + 0, k + 20, Block.stoneBrick.blockID);
		world.setBlock(i + 10, j + 0, k + 25, Block.blockSnow.blockID);
		world.setBlock(i + 10, j + 1, k + 13, Block.ice.blockID);
		world.setBlock(i + 10, j + 1, k + 25, Block.ice.blockID);
		world.setBlock(i + 10, j + 2, k + 13, Block.ice.blockID);
		world.setBlock(i + 10, j + 2, k + 25, Block.ice.blockID);
		world.setBlock(i + 10, j + 3, k + 13, Block.ice.blockID);
		world.setBlock(i + 10, j + 3, k + 25, Block.ice.blockID);
		world.setBlock(i + 10, j + 4, k + 13, Block.ice.blockID);
		world.setBlock(i + 10, j + 4, k + 25, Block.ice.blockID);
		world.setBlock(i + 10, j + 5, k + 13, Block.ice.blockID);
		world.setBlock(i + 10, j + 5, k + 25, Block.ice.blockID);
		world.setBlock(i + 10, j + 6, k + 13, Block.ice.blockID);
		world.setBlock(i + 10, j + 6, k + 25, Block.ice.blockID);
		world.setBlock(i + 10, j + 7, k + 13, Block.ice.blockID);
		world.setBlock(i + 10, j + 7, k + 25, Block.ice.blockID);
		world.setBlock(i + 10, j + 8, k + 14, Block.ice.blockID);
		world.setBlock(i + 10, j + 8, k + 24, Block.ice.blockID);
		world.setBlock(i + 10, j + 9, k + 15, Block.ice.blockID);
		world.setBlock(i + 10, j + 9, k + 23, Block.ice.blockID);
		world.setBlock(i + 10, j + 10, k + 16, Block.ice.blockID);
		world.setBlock(i + 10, j + 10, k + 22, Block.ice.blockID);
		world.setBlock(i + 10, j + 11, k + 17, Block.ice.blockID);
		world.setBlock(i + 10, j + 11, k + 18, Block.ice.blockID);
		world.setBlock(i + 10, j + 11, k + 19, Block.ice.blockID);
		world.setBlock(i + 10, j + 11, k + 20, Block.ice.blockID);
		world.setBlock(i + 10, j + 11, k + 21, Block.ice.blockID);
		world.setBlock(i + 11, j + 0, k + 12, Block.blockSnow.blockID);
		world.setBlock(i + 11, j + 0, k + 18, Block.stoneBrick.blockID);
		world.setBlockMetadataWithNotify(i + 11, j + 0, k + 19, Block.cloth.blockID, 15);
		world.setBlock(i + 11, j + 0, k + 20, Block.stoneBrick.blockID);
		world.setBlock(i + 11, j + 0, k + 26, Block.blockSnow.blockID);
		world.setBlock(i + 11, j + 1, k + 12, Block.ice.blockID);
		world.setBlock(i + 11, j + 1, k + 19, Block.planks.blockID);
		world.setBlock(i + 11, j + 1, k + 26, Block.ice.blockID);
		world.setBlock(i + 11, j + 2, k + 12, Block.ice.blockID);
		world.setBlock(i + 11, j + 2, k + 19, Block.sponge.blockID);
		world.setBlock(i + 11, j + 2, k + 26, Block.ice.blockID);
		world.setBlock(i + 11, j + 3, k + 12, Block.ice.blockID);
		world.setBlock(i + 11, j + 3, k + 26, Block.ice.blockID);
		world.setBlock(i + 11, j + 4, k + 12, Block.ice.blockID);
		world.setBlock(i + 11, j + 4, k + 26, Block.ice.blockID);
		world.setBlock(i + 11, j + 5, k + 12, Block.ice.blockID);
		world.setBlock(i + 11, j + 5, k + 26, Block.ice.blockID);
		world.setBlock(i + 11, j + 6, k + 12, Block.ice.blockID);
		world.setBlock(i + 11, j + 6, k + 26, Block.ice.blockID);
		world.setBlock(i + 11, j + 7, k + 12, Block.ice.blockID);
		world.setBlock(i + 11, j + 7, k + 26, Block.ice.blockID);
		world.setBlock(i + 11, j + 8, k + 13, Block.ice.blockID);
		world.setBlock(i + 11, j + 8, k + 25, Block.ice.blockID);
		world.setBlock(i + 11, j + 9, k + 14, Block.ice.blockID);
		world.setBlock(i + 11, j + 9, k + 24, Block.ice.blockID);
		world.setBlock(i + 11, j + 10, k + 15, Block.ice.blockID);
		world.setBlock(i + 11, j + 10, k + 23, Block.ice.blockID);
		world.setBlock(i + 11, j + 11, k + 16, Block.ice.blockID);
		world.setBlock(i + 11, j + 11, k + 17, Block.ice.blockID);
		world.setBlock(i + 11, j + 11, k + 18, Block.ice.blockID);
		world.setBlock(i + 11, j + 11, k + 19, Block.ice.blockID);
		world.setBlock(i + 11, j + 11, k + 20, Block.ice.blockID);
		world.setBlock(i + 11, j + 11, k + 21, Block.ice.blockID);
		world.setBlock(i + 11, j + 11, k + 22, Block.ice.blockID);
		world.setBlock(i + 12, j + 0, k + 11, Block.blockSnow.blockID);
		world.setBlockMetadataWithNotify(i + 12, j + 0, k + 18, Block.stairsStoneBrick.blockID, 1);
		world.setBlockMetadataWithNotify(i + 12, j + 0, k + 19, Block.stairsStoneBrick.blockID, 1);
		world.setBlockMetadataWithNotify(i + 12, j + 0, k + 20, Block.stairsStoneBrick.blockID, 1);
		world.setBlock(i + 12, j + 0, k + 27, Block.blockSnow.blockID);
		world.setBlock(i + 12, j + 1, k + 11, Block.ice.blockID);
		world.setBlock(i + 12, j + 1, k + 27, Block.ice.blockID);
		world.setBlock(i + 12, j + 2, k + 11, Block.ice.blockID);
		world.setBlock(i + 12, j + 2, k + 27, Block.ice.blockID);
		world.setBlock(i + 12, j + 3, k + 11, Block.ice.blockID);
		world.setBlock(i + 12, j + 3, k + 27, Block.ice.blockID);
		world.setBlock(i + 12, j + 4, k + 11, Block.ice.blockID);
		world.setBlock(i + 12, j + 4, k + 27, Block.ice.blockID);
		world.setBlock(i + 12, j + 5, k + 11, Block.ice.blockID);
		world.setBlock(i + 12, j + 5, k + 27, Block.ice.blockID);
		world.setBlock(i + 12, j + 6, k + 11, Block.ice.blockID);
		world.setBlock(i + 12, j + 6, k + 27, Block.ice.blockID);
		world.setBlock(i + 12, j + 7, k + 11, Block.ice.blockID);
		world.setBlock(i + 12, j + 7, k + 27, Block.ice.blockID);
		world.setBlock(i + 12, j + 8, k + 12, Block.ice.blockID);
		world.setBlock(i + 12, j + 8, k + 26, Block.ice.blockID);
		world.setBlock(i + 12, j + 9, k + 13, Block.ice.blockID);
		world.setBlock(i + 12, j + 9, k + 25, Block.ice.blockID);
		world.setBlock(i + 12, j + 10, k + 14, Block.ice.blockID);
		world.setBlock(i + 12, j + 10, k + 24, Block.ice.blockID);
		world.setBlock(i + 12, j + 11, k + 15, Block.ice.blockID);
		world.setBlock(i + 12, j + 11, k + 16, Block.ice.blockID);
		world.setBlock(i + 12, j + 11, k + 17, Block.ice.blockID);
		world.setBlock(i + 12, j + 11, k + 18, Block.ice.blockID);
		world.setBlock(i + 12, j + 11, k + 19, Block.ice.blockID);
		world.setBlock(i + 12, j + 11, k + 20, Block.ice.blockID);
		world.setBlock(i + 12, j + 11, k + 21, Block.ice.blockID);
		world.setBlock(i + 12, j + 11, k + 22, Block.ice.blockID);
		world.setBlock(i + 12, j + 11, k + 23, Block.ice.blockID);
		world.setBlock(i + 13, j + 0, k + 11, Block.blockSnow.blockID);
		world.setBlock(i + 13, j + 0, k + 27, Block.blockSnow.blockID);
		world.setBlock(i + 13, j + 1, k + 11, Block.ice.blockID);
		world.setBlock(i + 13, j + 1, k + 27, Block.ice.blockID);
		world.setBlock(i + 13, j + 2, k + 11, Block.ice.blockID);
		world.setBlock(i + 13, j + 2, k + 27, Block.ice.blockID);
		world.setBlock(i + 13, j + 3, k + 11, Block.ice.blockID);
		world.setBlock(i + 13, j + 3, k + 27, Block.ice.blockID);
		world.setBlock(i + 13, j + 4, k + 11, Block.ice.blockID);
		world.setBlock(i + 13, j + 4, k + 27, Block.ice.blockID);
		world.setBlock(i + 13, j + 5, k + 11, Block.ice.blockID);
		world.setBlock(i + 13, j + 5, k + 27, Block.ice.blockID);
		world.setBlock(i + 13, j + 6, k + 11, Block.ice.blockID);
		world.setBlock(i + 13, j + 6, k + 27, Block.ice.blockID);
		world.setBlock(i + 13, j + 7, k + 11, Block.ice.blockID);
		world.setBlock(i + 13, j + 7, k + 27, Block.ice.blockID);
		world.setBlock(i + 13, j + 8, k + 12, Block.ice.blockID);
		world.setBlock(i + 13, j + 8, k + 26, Block.ice.blockID);
		world.setBlock(i + 13, j + 9, k + 13, Block.ice.blockID);
		world.setBlock(i + 13, j + 9, k + 25, Block.ice.blockID);
		world.setBlock(i + 13, j + 10, k + 14, Block.ice.blockID);
		world.setBlock(i + 13, j + 10, k + 24, Block.ice.blockID);
		world.setBlock(i + 13, j + 11, k + 15, Block.ice.blockID);
		world.setBlock(i + 13, j + 11, k + 16, Block.ice.blockID);
		world.setBlock(i + 13, j + 11, k + 17, Block.ice.blockID);
		world.setBlock(i + 13, j + 11, k + 18, Block.ice.blockID);
		world.setBlock(i + 13, j + 11, k + 19, Block.ice.blockID);
		world.setBlock(i + 13, j + 11, k + 20, Block.ice.blockID);
		world.setBlock(i + 13, j + 11, k + 21, Block.ice.blockID);
		world.setBlock(i + 13, j + 11, k + 22, Block.ice.blockID);
		world.setBlock(i + 13, j + 11, k + 23, Block.ice.blockID);
		world.setBlock(i + 14, j + 0, k + 11, Block.blockSnow.blockID);
		world.setBlock(i + 14, j + 0, k + 27, Block.blockSnow.blockID);
		world.setBlock(i + 14, j + 1, k + 11, Block.ice.blockID);
		world.setBlock(i + 14, j + 1, k + 27, Block.ice.blockID);
		world.setBlock(i + 14, j + 2, k + 11, Block.ice.blockID);
		world.setBlock(i + 14, j + 2, k + 27, Block.ice.blockID);
		world.setBlock(i + 14, j + 3, k + 11, Block.ice.blockID);
		world.setBlock(i + 14, j + 3, k + 12, Block.oreIron.blockID);
		world.setBlock(i + 14, j + 3, k + 26, Block.oreIron.blockID);
		world.setBlock(i + 14, j + 3, k + 27, Block.ice.blockID);
		world.setBlock(i + 14, j + 4, k + 11, Block.ice.blockID);
		world.setBlock(i + 14, j + 4, k + 27, Block.ice.blockID);
		world.setBlock(i + 14, j + 5, k + 11, Block.ice.blockID);
		world.setBlock(i + 14, j + 5, k + 27, Block.ice.blockID);
		world.setBlock(i + 14, j + 6, k + 11, Block.ice.blockID);
		world.setBlock(i + 14, j + 6, k + 27, Block.ice.blockID);
		world.setBlock(i + 14, j + 7, k + 11, Block.ice.blockID);
		world.setBlock(i + 14, j + 7, k + 27, Block.ice.blockID);
		world.setBlock(i + 14, j + 8, k + 12, Block.ice.blockID);
		world.setBlock(i + 14, j + 8, k + 26, Block.ice.blockID);
		world.setBlock(i + 14, j + 9, k + 13, Block.ice.blockID);
		world.setBlock(i + 14, j + 9, k + 25, Block.ice.blockID);
		world.setBlock(i + 14, j + 10, k + 14, Block.ice.blockID);
		world.setBlock(i + 14, j + 10, k + 24, Block.ice.blockID);
		world.setBlock(i + 14, j + 11, k + 15, Block.ice.blockID);
		world.setBlock(i + 14, j + 11, k + 16, Block.ice.blockID);
		world.setBlock(i + 14, j + 11, k + 17, Block.ice.blockID);
		world.setBlock(i + 14, j + 11, k + 18, Block.ice.blockID);
		world.setBlock(i + 14, j + 11, k + 19, Block.ice.blockID);
		world.setBlock(i + 14, j + 11, k + 20, Block.ice.blockID);
		world.setBlock(i + 14, j + 11, k + 21, Block.ice.blockID);
		world.setBlock(i + 14, j + 11, k + 22, Block.ice.blockID);
		world.setBlock(i + 14, j + 11, k + 23, Block.ice.blockID);
		world.setBlock(i + 15, j + 0, k + 11, Block.blockSnow.blockID);
		world.setBlock(i + 15, j + 0, k + 16, MainRegistry.frostStairs.blockID);
		world.setBlock(i + 15, j + 0, k + 17, MainRegistry.frostStairs.blockID);
		world.setBlock(i + 15, j + 0, k + 21, MainRegistry.frostStairs.blockID);
		world.setBlock(i + 15, j + 0, k + 22, MainRegistry.frostStairs.blockID);
		world.setBlock(i + 15, j + 0, k + 27, Block.blockSnow.blockID);
		world.setBlock(i + 15, j + 1, k + 11, Block.ice.blockID);
		world.setBlock(i + 15, j + 1, k + 27, Block.ice.blockID);
		world.setBlock(i + 15, j + 2, k + 11, Block.ice.blockID);
		world.setBlock(i + 15, j + 2, k + 27, Block.ice.blockID);
		world.setBlock(i + 15, j + 3, k + 11, Block.ice.blockID);
		world.setBlock(i + 15, j + 3, k + 27, Block.ice.blockID);
		world.setBlock(i + 15, j + 4, k + 11, Block.ice.blockID);
		world.setBlock(i + 15, j + 4, k + 27, Block.ice.blockID);
		world.setBlock(i + 15, j + 5, k + 11, Block.ice.blockID);
		world.setBlock(i + 15, j + 5, k + 27, Block.ice.blockID);
		world.setBlock(i + 15, j + 6, k + 11, Block.ice.blockID);
		world.setBlock(i + 15, j + 6, k + 27, Block.ice.blockID);
		world.setBlock(i + 15, j + 7, k + 11, Block.ice.blockID);
		world.setBlock(i + 15, j + 7, k + 27, Block.ice.blockID);
		world.setBlock(i + 15, j + 8, k + 12, Block.ice.blockID);
		world.setBlock(i + 15, j + 8, k + 26, Block.ice.blockID);
		world.setBlock(i + 15, j + 9, k + 13, Block.ice.blockID);
		world.setBlock(i + 15, j + 9, k + 25, Block.ice.blockID);
		world.setBlock(i + 15, j + 10, k + 14, Block.ice.blockID);
		world.setBlock(i + 15, j + 10, k + 24, Block.ice.blockID);
		world.setBlock(i + 15, j + 11, k + 15, Block.ice.blockID);
		world.setBlock(i + 15, j + 11, k + 16, Block.ice.blockID);
		world.setBlock(i + 15, j + 11, k + 17, Block.ice.blockID);
		world.setBlock(i + 15, j + 11, k + 18, Block.ice.blockID);
		world.setBlock(i + 15, j + 11, k + 19, Block.ice.blockID);
		world.setBlock(i + 15, j + 11, k + 20, Block.ice.blockID);
		world.setBlock(i + 15, j + 11, k + 21, Block.ice.blockID);
		world.setBlock(i + 15, j + 11, k + 22, Block.ice.blockID);
		world.setBlock(i + 15, j + 11, k + 23, Block.ice.blockID);
		world.setBlock(i + 16, j + 0, k + 11, Block.blockSnow.blockID);
		world.setBlock(i + 16, j + 0, k + 27, Block.blockSnow.blockID);
		world.setBlock(i + 16, j + 1, k + 11, Block.ice.blockID);
		world.setBlock(i + 16, j + 1, k + 27, Block.ice.blockID);
		world.setBlock(i + 16, j + 2, k + 11, Block.ice.blockID);
		world.setBlock(i + 16, j + 2, k + 27, Block.ice.blockID);
		world.setBlock(i + 16, j + 3, k + 11, Block.ice.blockID);
		world.setBlock(i + 16, j + 3, k + 27, Block.ice.blockID);
		world.setBlock(i + 16, j + 4, k + 11, Block.ice.blockID);
		world.setBlock(i + 16, j + 4, k + 27, Block.ice.blockID);
		world.setBlock(i + 16, j + 5, k + 11, Block.ice.blockID);
		world.setBlock(i + 16, j + 5, k + 27, Block.ice.blockID);
		world.setBlock(i + 16, j + 6, k + 11, Block.ice.blockID);
		world.setBlock(i + 16, j + 6, k + 27, Block.ice.blockID);
		world.setBlock(i + 16, j + 7, k + 11, Block.ice.blockID);
		world.setBlock(i + 16, j + 7, k + 27, Block.ice.blockID);
		world.setBlock(i + 16, j + 8, k + 12, Block.ice.blockID);
		world.setBlock(i + 16, j + 8, k + 26, Block.ice.blockID);
		world.setBlock(i + 16, j + 9, k + 13, Block.ice.blockID);
		world.setBlock(i + 16, j + 9, k + 25, Block.ice.blockID);
		world.setBlock(i + 16, j + 10, k + 14, Block.ice.blockID);
		world.setBlock(i + 16, j + 10, k + 24, Block.ice.blockID);
		world.setBlock(i + 16, j + 11, k + 15, Block.ice.blockID);
		world.setBlock(i + 16, j + 11, k + 16, Block.ice.blockID);
		world.setBlock(i + 16, j + 11, k + 17, Block.ice.blockID);
		world.setBlock(i + 16, j + 11, k + 18, Block.ice.blockID);
		world.setBlock(i + 16, j + 11, k + 19, Block.ice.blockID);
		world.setBlock(i + 16, j + 11, k + 20, Block.ice.blockID);
		world.setBlock(i + 16, j + 11, k + 21, Block.ice.blockID);
		world.setBlock(i + 16, j + 11, k + 22, Block.ice.blockID);
		world.setBlock(i + 16, j + 11, k + 23, Block.ice.blockID);
		world.setBlock(i + 17, j + 0, k + 12, Block.blockSnow.blockID);
		world.setBlock(i + 17, j + 0, k + 16, MainRegistry.frostStairs.blockID);
		world.setBlock(i + 17, j + 0, k + 17, MainRegistry.frostStairs.blockID);
		world.setBlock(i + 17, j + 0, k + 21, MainRegistry.frostStairs.blockID);
		world.setBlock(i + 17, j + 0, k + 22, MainRegistry.frostStairs.blockID);
		world.setBlock(i + 17, j + 0, k + 26, Block.blockSnow.blockID);
		world.setBlock(i + 17, j + 1, k + 12, Block.ice.blockID);
		world.setBlock(i + 17, j + 1, k + 26, Block.ice.blockID);
		world.setBlock(i + 17, j + 2, k + 12, Block.ice.blockID);
		world.setBlock(i + 17, j + 2, k + 26, Block.ice.blockID);
		world.setBlock(i + 17, j + 3, k + 12, Block.ice.blockID);
		world.setBlock(i + 17, j + 3, k + 26, Block.ice.blockID);
		world.setBlock(i + 17, j + 4, k + 12, Block.ice.blockID);
		world.setBlock(i + 17, j + 4, k + 26, Block.ice.blockID);
		world.setBlock(i + 17, j + 5, k + 12, Block.ice.blockID);
		world.setBlock(i + 17, j + 5, k + 26, Block.ice.blockID);
		world.setBlock(i + 17, j + 6, k + 12, Block.ice.blockID);
		world.setBlock(i + 17, j + 6, k + 26, Block.ice.blockID);
		world.setBlock(i + 17, j + 7, k + 12, Block.ice.blockID);
		world.setBlock(i + 17, j + 7, k + 26, Block.ice.blockID);
		world.setBlock(i + 17, j + 8, k + 13, Block.ice.blockID);
		world.setBlock(i + 17, j + 8, k + 25, Block.ice.blockID);
		world.setBlock(i + 17, j + 9, k + 14, Block.ice.blockID);
		world.setBlock(i + 17, j + 9, k + 24, Block.ice.blockID);
		world.setBlock(i + 17, j + 10, k + 15, Block.ice.blockID);
		world.setBlock(i + 17, j + 10, k + 23, Block.ice.blockID);
		world.setBlock(i + 17, j + 11, k + 16, Block.ice.blockID);
		world.setBlock(i + 17, j + 11, k + 17, Block.ice.blockID);
		world.setBlock(i + 17, j + 11, k + 18, Block.ice.blockID);
		world.setBlock(i + 17, j + 11, k + 19, Block.ice.blockID);
		world.setBlock(i + 17, j + 11, k + 20, Block.ice.blockID);
		world.setBlock(i + 17, j + 11, k + 21, Block.ice.blockID);
		world.setBlock(i + 17, j + 11, k + 22, Block.ice.blockID);
		world.setBlock(i + 18, j + 0, k + 13, Block.blockSnow.blockID);
		world.setBlock(i + 18, j + 0, k + 25, Block.blockSnow.blockID);
		world.setBlock(i + 18, j + 1, k + 13, Block.ice.blockID);
		world.setBlock(i + 18, j + 1, k + 25, Block.ice.blockID);
		world.setBlock(i + 18, j + 2, k + 13, Block.ice.blockID);
		world.setBlock(i + 18, j + 2, k + 25, Block.ice.blockID);
		world.setBlock(i + 18, j + 3, k + 13, Block.ice.blockID);
		world.setBlock(i + 18, j + 3, k + 25, Block.ice.blockID);
		world.setBlock(i + 18, j + 4, k + 13, Block.ice.blockID);
		world.setBlock(i + 18, j + 4, k + 25, Block.ice.blockID);
		world.setBlock(i + 18, j + 5, k + 13, Block.ice.blockID);
		world.setBlock(i + 18, j + 5, k + 25, Block.ice.blockID);
		world.setBlock(i + 18, j + 6, k + 13, Block.ice.blockID);
		world.setBlock(i + 18, j + 6, k + 25, Block.ice.blockID);
		world.setBlock(i + 18, j + 7, k + 13, Block.ice.blockID);
		world.setBlock(i + 18, j + 7, k + 25, Block.ice.blockID);
		world.setBlock(i + 18, j + 8, k + 14, Block.ice.blockID);
		world.setBlock(i + 18, j + 8, k + 24, Block.ice.blockID);
		world.setBlock(i + 18, j + 9, k + 15, Block.ice.blockID);
		world.setBlock(i + 18, j + 9, k + 23, Block.ice.blockID);
		world.setBlock(i + 18, j + 10, k + 16, Block.ice.blockID);
		world.setBlock(i + 18, j + 10, k + 17, Block.ice.blockID);
		world.setBlock(i + 18, j + 10, k + 22, Block.ice.blockID);
		world.setBlock(i + 18, j + 11, k + 17, Block.ice.blockID);
		world.setBlock(i + 18, j + 11, k + 18, Block.ice.blockID);
		world.setBlock(i + 18, j + 11, k + 19, Block.ice.blockID);
		world.setBlock(i + 18, j + 11, k + 20, Block.ice.blockID);
		world.setBlock(i + 18, j + 11, k + 21, Block.ice.blockID);
		world.setBlock(i + 19, j + 0, k + 14, Block.blockSnow.blockID);
		world.setBlock(i + 19, j + 0, k + 16, MainRegistry.frostStairs.blockID);
		world.setBlock(i + 19, j + 0, k + 17, MainRegistry.frostStairs.blockID);
		world.setBlock(i + 19, j + 0, k + 21, MainRegistry.frostStairs.blockID);
		world.setBlock(i + 19, j + 0, k + 22, MainRegistry.frostStairs.blockID);
		world.setBlock(i + 19, j + 0, k + 24, Block.blockSnow.blockID);
		world.setBlock(i + 19, j + 1, k + 14, Block.ice.blockID);
		world.setBlock(i + 19, j + 1, k + 24, Block.ice.blockID);
		world.setBlock(i + 19, j + 2, k + 14, Block.ice.blockID);
		world.setBlock(i + 19, j + 2, k + 24, Block.ice.blockID);
		world.setBlock(i + 19, j + 3, k + 14, Block.ice.blockID);
		world.setBlock(i + 19, j + 3, k + 24, Block.ice.blockID);
		world.setBlock(i + 19, j + 4, k + 14, Block.ice.blockID);
		world.setBlock(i + 19, j + 4, k + 24, Block.ice.blockID);
		world.setBlock(i + 19, j + 5, k + 14, Block.ice.blockID);
		world.setBlock(i + 19, j + 5, k + 24, Block.ice.blockID);
		world.setBlock(i + 19, j + 6, k + 14, Block.ice.blockID);
		world.setBlock(i + 19, j + 6, k + 24, Block.ice.blockID);
		world.setBlock(i + 19, j + 7, k + 14, Block.ice.blockID);
		world.setBlock(i + 19, j + 7, k + 24, Block.ice.blockID);
		world.setBlock(i + 19, j + 8, k + 15, Block.ice.blockID);
		world.setBlock(i + 19, j + 8, k + 23, Block.ice.blockID);
		world.setBlock(i + 19, j + 9, k + 16, Block.ice.blockID);
		world.setBlock(i + 19, j + 9, k + 22, Block.ice.blockID);
		world.setBlock(i + 19, j + 10, k + 17, Block.ice.blockID);
		world.setBlock(i + 19, j + 10, k + 21, Block.ice.blockID);
		world.setBlock(i + 19, j + 11, k + 18, Block.ice.blockID);
		world.setBlock(i + 19, j + 11, k + 19, Block.ice.blockID);
		world.setBlock(i + 19, j + 11, k + 20, Block.ice.blockID);
		world.setBlock(i + 20, j + 0, k + 14, Block.blockSnow.blockID);
		world.setBlock(i + 20, j + 0, k + 24, Block.blockSnow.blockID);
		world.setBlock(i + 20, j + 1, k + 14, Block.ice.blockID);
		world.setBlock(i + 20, j + 1, k + 24, Block.ice.blockID);
		world.setBlock(i + 20, j + 2, k + 14, Block.ice.blockID);
		world.setBlock(i + 20, j + 2, k + 24, Block.ice.blockID);
		world.setBlock(i + 20, j + 3, k + 14, Block.ice.blockID);
		world.setBlock(i + 20, j + 3, k + 24, Block.ice.blockID);
		world.setBlock(i + 20, j + 4, k + 14, Block.ice.blockID);
		world.setBlock(i + 20, j + 4, k + 24, Block.ice.blockID);
		world.setBlock(i + 20, j + 5, k + 14, Block.ice.blockID);
		world.setBlock(i + 20, j + 5, k + 24, Block.ice.blockID);
		world.setBlock(i + 20, j + 6, k + 14, Block.ice.blockID);
		world.setBlock(i + 20, j + 6, k + 24, Block.ice.blockID);
		world.setBlock(i + 20, j + 7, k + 14, Block.ice.blockID);
		world.setBlock(i + 20, j + 7, k + 24, Block.ice.blockID);
		world.setBlock(i + 20, j + 8, k + 15, Block.ice.blockID);
		world.setBlock(i + 20, j + 8, k + 23, Block.ice.blockID);
		world.setBlock(i + 20, j + 9, k + 16, Block.ice.blockID);
		world.setBlock(i + 20, j + 9, k + 22, Block.ice.blockID);
		world.setBlock(i + 20, j + 10, k + 17, Block.ice.blockID);
		world.setBlock(i + 20, j + 10, k + 21, Block.ice.blockID);
		world.setBlock(i + 20, j + 11, k + 18, Block.ice.blockID);
		world.setBlock(i + 20, j + 11, k + 19, Block.ice.blockID);
		world.setBlock(i + 20, j + 11, k + 20, Block.ice.blockID);
		world.setBlock(i + 21, j + 0, k + 14, Block.blockSnow.blockID);
		world.setBlock(i + 21, j + 0, k + 24, Block.blockSnow.blockID);
		world.setBlock(i + 21, j + 1, k + 14, Block.ice.blockID);
		world.setBlock(i + 21, j + 1, k + 24, Block.ice.blockID);
		world.setBlock(i + 21, j + 2, k + 14, Block.ice.blockID);
		world.setBlock(i + 21, j + 2, k + 24, Block.ice.blockID);
		world.setBlock(i + 21, j + 3, k + 14, Block.ice.blockID);
		world.setBlock(i + 21, j + 3, k + 15, Block.oreIron.blockID);
		world.setBlock(i + 21, j + 3, k + 23, Block.oreIron.blockID);
		world.setBlock(i + 21, j + 3, k + 24, Block.ice.blockID);
		world.setBlock(i + 21, j + 4, k + 14, Block.ice.blockID);
		world.setBlock(i + 21, j + 4, k + 24, Block.ice.blockID);
		world.setBlock(i + 21, j + 5, k + 14, Block.ice.blockID);
		world.setBlock(i + 21, j + 5, k + 24, Block.ice.blockID);
		world.setBlock(i + 21, j + 6, k + 14, Block.ice.blockID);
		world.setBlock(i + 21, j + 6, k + 24, Block.ice.blockID);
		world.setBlock(i + 21, j + 7, k + 14, Block.ice.blockID);
		world.setBlock(i + 21, j + 7, k + 24, Block.ice.blockID);
		world.setBlock(i + 21, j + 8, k + 15, Block.ice.blockID);
		world.setBlock(i + 21, j + 8, k + 23, Block.ice.blockID);
		world.setBlock(i + 21, j + 9, k + 16, Block.ice.blockID);
		world.setBlock(i + 21, j + 9, k + 22, Block.ice.blockID);
		world.setBlock(i + 21, j + 10, k + 17, Block.ice.blockID);
		world.setBlock(i + 21, j + 10, k + 21, Block.ice.blockID);
		world.setBlock(i + 21, j + 11, k + 18, Block.ice.blockID);
		world.setBlock(i + 21, j + 11, k + 19, Block.ice.blockID);
		world.setBlock(i + 21, j + 11, k + 20, Block.ice.blockID);
		world.setBlock(i + 22, j + 0, k + 14, Block.blockSnow.blockID);
		world.setBlock(i + 22, j + 0, k + 24, Block.blockSnow.blockID);
		world.setBlock(i + 22, j + 1, k + 14, Block.ice.blockID);
		world.setBlock(i + 22, j + 1, k + 24, Block.ice.blockID);
		world.setBlock(i + 22, j + 2, k + 14, Block.ice.blockID);
		world.setBlock(i + 22, j + 2, k + 24, Block.ice.blockID);
		world.setBlock(i + 22, j + 3, k + 14, Block.ice.blockID);
		world.setBlock(i + 22, j + 3, k + 24, Block.ice.blockID);
		world.setBlock(i + 22, j + 4, k + 14, Block.ice.blockID);
		world.setBlock(i + 22, j + 4, k + 24, Block.ice.blockID);
		world.setBlock(i + 22, j + 5, k + 14, Block.ice.blockID);
		world.setBlock(i + 22, j + 5, k + 24, Block.ice.blockID);
		world.setBlock(i + 22, j + 6, k + 14, Block.ice.blockID);
		world.setBlock(i + 22, j + 6, k + 24, Block.ice.blockID);
		world.setBlock(i + 22, j + 7, k + 14, Block.ice.blockID);
		world.setBlock(i + 22, j + 7, k + 24, Block.ice.blockID);
		world.setBlock(i + 22, j + 8, k + 15, Block.ice.blockID);
		world.setBlock(i + 22, j + 8, k + 23, Block.ice.blockID);
		world.setBlock(i + 22, j + 9, k + 16, Block.ice.blockID);
		world.setBlock(i + 22, j + 9, k + 22, Block.ice.blockID);
		world.setBlock(i + 22, j + 10, k + 17, Block.ice.blockID);
		world.setBlock(i + 22, j + 10, k + 18, Block.ice.blockID);
		world.setBlock(i + 22, j + 10, k + 19, Block.ice.blockID);
		world.setBlock(i + 22, j + 10, k + 20, Block.ice.blockID);
		world.setBlock(i + 22, j + 10, k + 21, Block.ice.blockID);
		world.setBlock(i + 23, j + 0, k + 15, Block.blockSnow.blockID);
		world.setBlock(i + 23, j + 0, k + 23, Block.blockSnow.blockID);
		world.setBlock(i + 23, j + 1, k + 15, Block.ice.blockID);
		world.setBlock(i + 23, j + 1, k + 23, Block.ice.blockID);
		world.setBlock(i + 23, j + 2, k + 15, Block.ice.blockID);
		world.setBlock(i + 23, j + 2, k + 23, Block.ice.blockID);
		world.setBlock(i + 23, j + 3, k + 15, Block.ice.blockID);
		world.setBlock(i + 23, j + 3, k + 23, Block.ice.blockID);
		world.setBlock(i + 23, j + 4, k + 15, Block.ice.blockID);
		world.setBlock(i + 23, j + 4, k + 23, Block.ice.blockID);
		world.setBlock(i + 23, j + 5, k + 15, Block.ice.blockID);
		world.setBlock(i + 23, j + 5, k + 23, Block.ice.blockID);
		world.setBlock(i + 23, j + 6, k + 15, Block.ice.blockID);
		world.setBlock(i + 23, j + 6, k + 23, Block.ice.blockID);
		world.setBlock(i + 23, j + 7, k + 15, Block.ice.blockID);
		world.setBlock(i + 23, j + 7, k + 23, Block.ice.blockID);
		world.setBlock(i + 23, j + 8, k + 16, Block.ice.blockID);
		world.setBlock(i + 23, j + 8, k + 22, Block.ice.blockID);
		world.setBlock(i + 23, j + 9, k + 17, Block.ice.blockID);
		world.setBlock(i + 23, j + 9, k + 18, Block.ice.blockID);
		world.setBlock(i + 23, j + 9, k + 19, Block.ice.blockID);
		world.setBlock(i + 23, j + 9, k + 20, Block.ice.blockID);
		world.setBlock(i + 23, j + 9, k + 21, Block.ice.blockID);
		world.setBlock(i + 24, j + 0, k + 16, Block.blockSnow.blockID);
		world.setBlock(i + 24, j + 0, k + 22, Block.blockSnow.blockID);
		world.setBlock(i + 24, j + 1, k + 16, Block.ice.blockID);
		world.setBlock(i + 24, j + 2, k + 16, Block.ice.blockID);
		world.setBlock(i + 24, j + 3, k + 16, Block.ice.blockID);
		world.setBlock(i + 24, j + 3, k + 22, Block.ice.blockID);
		world.setBlock(i + 24, j + 4, k + 16, Block.ice.blockID);
		world.setBlock(i + 24, j + 4, k + 22, Block.ice.blockID);
		world.setBlock(i + 24, j + 5, k + 16, Block.ice.blockID);
		world.setBlock(i + 24, j + 5, k + 22, Block.ice.blockID);
		world.setBlock(i + 24, j + 6, k + 16, Block.ice.blockID);
		world.setBlock(i + 24, j + 6, k + 22, Block.ice.blockID);
		world.setBlock(i + 24, j + 7, k + 16, Block.ice.blockID);
		world.setBlock(i + 24, j + 7, k + 22, Block.ice.blockID);
		world.setBlock(i + 24, j + 8, k + 17, Block.ice.blockID);
		world.setBlock(i + 24, j + 8, k + 18, Block.ice.blockID);
		world.setBlock(i + 24, j + 8, k + 19, Block.ice.blockID);
		world.setBlock(i + 24, j + 8, k + 20, Block.ice.blockID);
		world.setBlock(i + 24, j + 8, k + 21, Block.ice.blockID);
		world.setBlock(i + 25, j + 0, k + 17, Block.blockSnow.blockID);
		world.setBlock(i + 25, j + 0, k + 18, Block.fenceIron.blockID);
		world.setBlock(i + 25, j + 0, k + 19, Block.fenceIron.blockID);
		world.setBlock(i + 25, j + 0, k + 20, Block.fenceIron.blockID);
		world.setBlock(i + 25, j + 0, k + 21, Block.blockSnow.blockID);
		world.setBlock(i + 25, j + 1, k + 17, Block.blockSnow.blockID);
		world.setBlock(i + 25, j + 1, k + 18, Block.fenceIron.blockID);
		world.setBlock(i + 25, j + 1, k + 19, Block.fenceIron.blockID);
		world.setBlock(i + 25, j + 1, k + 20, Block.fenceIron.blockID);
		world.setBlock(i + 25, j + 1, k + 21, Block.blockSnow.blockID);
		world.setBlock(i + 25, j + 2, k + 17, Block.blockSnow.blockID);
		world.setBlock(i + 25, j + 2, k + 18, Block.blockSnow.blockID);
		world.setBlock(i + 25, j + 2, k + 19, Block.fenceIron.blockID);
		world.setBlock(i + 25, j + 2, k + 20, Block.blockSnow.blockID);
		world.setBlock(i + 25, j + 2, k + 21, Block.blockSnow.blockID);
		world.setBlock(i + 25, j + 3, k + 17, Block.blockSnow.blockID);
		world.setBlock(i + 25, j + 3, k + 18, Block.blockSnow.blockID);
		world.setBlock(i + 25, j + 3, k + 19, Block.blockSnow.blockID);
		world.setBlock(i + 25, j + 3, k + 20, Block.blockSnow.blockID);
		world.setBlock(i + 25, j + 3, k + 21, Block.blockSnow.blockID);
		world.setBlock(i + 25, j + 4, k + 17, Block.ice.blockID);
		world.setBlock(i + 25, j + 4, k + 18, Block.blockSnow.blockID);
		world.setBlock(i + 25, j + 4, k + 19, Block.blockSnow.blockID);
		world.setBlock(i + 25, j + 4, k + 20, Block.blockSnow.blockID);
		world.setBlock(i + 25, j + 4, k + 21, Block.ice.blockID);
		world.setBlock(i + 25, j + 5, k + 17, Block.ice.blockID);
		world.setBlock(i + 25, j + 5, k + 18, Block.ice.blockID);
		world.setBlock(i + 25, j + 5, k + 19, Block.ice.blockID);
		world.setBlock(i + 25, j + 5, k + 20, Block.ice.blockID);
		world.setBlock(i + 25, j + 5, k + 21, Block.ice.blockID);
		world.setBlock(i + 25, j + 6, k + 17, Block.ice.blockID);
		world.setBlock(i + 25, j + 6, k + 18, Block.ice.blockID);
		world.setBlock(i + 25, j + 6, k + 19, Block.ice.blockID);
		world.setBlock(i + 25, j + 6, k + 20, Block.ice.blockID);
		world.setBlock(i + 25, j + 6, k + 21, Block.ice.blockID);
		world.setBlock(i + 25, j + 7, k + 17, Block.ice.blockID);
		world.setBlock(i + 25, j + 7, k + 18, Block.ice.blockID);
		world.setBlock(i + 25, j + 7, k + 19, Block.ice.blockID);
		world.setBlock(i + 25, j + 7, k + 20, Block.ice.blockID);
		world.setBlock(i + 25, j + 7, k + 21, Block.ice.blockID);
		world.setBlock(i + 31, j + 0, k + 9, Block.blockSnow.blockID);
		world.setBlock(i + 31, j + 0, k + 10, Block.blockSnow.blockID);
		world.setBlock(i + 31, j + 0, k + 11, Block.blockSnow.blockID);
		world.setBlock(i + 31, j + 0, k + 12, Block.blockSnow.blockID);
		world.setBlock(i + 31, j + 0, k + 13, Block.blockSnow.blockID);
		world.setBlock(i + 31, j + 0, k + 25, Block.blockSnow.blockID);
		world.setBlock(i + 31, j + 0, k + 26, Block.blockSnow.blockID);
		world.setBlock(i + 31, j + 0, k + 27, Block.blockSnow.blockID);
		world.setBlock(i + 31, j + 0, k + 28, Block.blockSnow.blockID);
		world.setBlock(i + 31, j + 0, k + 29, Block.blockSnow.blockID);
		world.setBlock(i + 31, j + 1, k + 9, Block.blockSnow.blockID);
		world.setBlock(i + 31, j + 1, k + 10, Block.blockSnow.blockID);
		world.setBlock(i + 31, j + 1, k + 11, Block.blockSnow.blockID);
		world.setBlock(i + 31, j + 1, k + 12, Block.blockSnow.blockID);
		world.setBlock(i + 31, j + 1, k + 13, Block.blockSnow.blockID);
		world.setBlock(i + 31, j + 1, k + 25, Block.blockSnow.blockID);
		world.setBlock(i + 31, j + 1, k + 26, Block.blockSnow.blockID);
		world.setBlock(i + 31, j + 1, k + 27, Block.blockSnow.blockID);
		world.setBlock(i + 31, j + 1, k + 28, Block.blockSnow.blockID);
		world.setBlock(i + 31, j + 1, k + 29, Block.blockSnow.blockID);
		world.setBlock(i + 31, j + 2, k + 10, Block.blockSnow.blockID);
		world.setBlock(i + 31, j + 2, k + 11, Block.blockSnow.blockID);
		world.setBlock(i + 31, j + 2, k + 12, Block.blockSnow.blockID);
		world.setBlock(i + 31, j + 2, k + 26, Block.blockSnow.blockID);
		world.setBlock(i + 31, j + 2, k + 27, Block.blockSnow.blockID);
		world.setBlock(i + 31, j + 2, k + 28, Block.blockSnow.blockID);
		world.setBlock(i + 32, j + 0, k + 8, Block.blockSnow.blockID);
		world.setBlock(i + 32, j + 0, k + 11, Block.blockSteel.blockID);
		world.setBlock(i + 32, j + 0, k + 14, Block.blockSnow.blockID);
		world.setBlock(i + 32, j + 0, k + 24, Block.blockSnow.blockID);
		world.setBlock(i + 32, j + 0, k + 30, Block.blockSnow.blockID);
		world.setBlock(i + 32, j + 1, k + 8, Block.blockSnow.blockID);
		world.setBlock(i + 32, j + 1, k + 14, Block.blockSnow.blockID);
		world.setBlock(i + 32, j + 1, k + 24, Block.blockSnow.blockID);
		world.setBlock(i + 32, j + 1, k + 30, Block.blockSnow.blockID);
		world.setBlock(i + 32, j + 2, k + 8, Block.blockSnow.blockID);
		world.setBlock(i + 32, j + 2, k + 9, Block.blockSnow.blockID);
		world.setBlock(i + 32, j + 2, k + 13, Block.blockSnow.blockID);
		world.setBlock(i + 32, j + 2, k + 14, Block.blockSnow.blockID);
		world.setBlock(i + 32, j + 2, k + 24, Block.blockSnow.blockID);
		world.setBlock(i + 32, j + 2, k + 25, Block.blockSnow.blockID);
		world.setBlock(i + 32, j + 2, k + 29, Block.blockSnow.blockID);
		world.setBlock(i + 32, j + 2, k + 30, Block.blockSnow.blockID);
		world.setBlock(i + 32, j + 3, k + 9, Block.blockSnow.blockID);
		world.setBlock(i + 32, j + 3, k + 10, Block.blockSnow.blockID);
		world.setBlock(i + 32, j + 3, k + 11, Block.blockSnow.blockID);
		world.setBlock(i + 32, j + 3, k + 12, Block.blockSnow.blockID);
		world.setBlock(i + 32, j + 3, k + 13, Block.blockSnow.blockID);
		world.setBlock(i + 32, j + 3, k + 25, Block.blockSnow.blockID);
		world.setBlock(i + 32, j + 3, k + 26, Block.blockSnow.blockID);
		world.setBlock(i + 32, j + 3, k + 27, Block.blockSnow.blockID);
		world.setBlock(i + 32, j + 3, k + 28, Block.blockSnow.blockID);
		world.setBlock(i + 32, j + 3, k + 29, Block.blockSnow.blockID);
		world.setBlock(i + 33, j + 0, k + 7, Block.blockSnow.blockID);
		world.setBlock(i + 33, j + 0, k + 15, Block.blockSnow.blockID);
		world.setBlock(i + 33, j + 0, k + 23, Block.blockSnow.blockID);
		world.setBlock(i + 33, j + 0, k + 31, Block.blockSnow.blockID);
		world.setBlock(i + 33, j + 1, k + 7, Block.blockSnow.blockID);
		world.setBlock(i + 33, j + 1, k + 15, Block.blockSnow.blockID);
		world.setBlock(i + 33, j + 1, k + 23, Block.blockSnow.blockID);
		world.setBlock(i + 33, j + 1, k + 31, Block.blockSnow.blockID);
		world.setBlock(i + 33, j + 2, k + 7, Block.blockSnow.blockID);
		world.setBlock(i + 33, j + 2, k + 15, Block.blockSnow.blockID);
		world.setBlock(i + 33, j + 2, k + 23, Block.blockSnow.blockID);
		world.setBlock(i + 33, j + 2, k + 31, Block.blockSnow.blockID);
		world.setBlock(i + 33, j + 3, k + 8, Block.blockSnow.blockID);
		world.setBlock(i + 33, j + 3, k + 14, Block.blockSnow.blockID);
		world.setBlock(i + 33, j + 3, k + 24, Block.blockSnow.blockID);
		world.setBlock(i + 33, j + 3, k + 30, Block.blockSnow.blockID);
		world.setBlock(i + 33, j + 4, k + 9, Block.blockSnow.blockID);
		world.setBlock(i + 33, j + 4, k + 10, Block.blockSnow.blockID);
		world.setBlock(i + 33, j + 4, k + 11, Block.blockSnow.blockID);
		world.setBlock(i + 33, j + 4, k + 12, Block.blockSnow.blockID);
		world.setBlock(i + 33, j + 4, k + 13, Block.blockSnow.blockID);
		world.setBlock(i + 33, j + 4, k + 25, Block.blockSnow.blockID);
		world.setBlock(i + 33, j + 4, k + 26, Block.blockSnow.blockID);
		world.setBlock(i + 33, j + 4, k + 27, Block.blockSnow.blockID);
		world.setBlock(i + 33, j + 4, k + 28, Block.blockSnow.blockID);
		world.setBlock(i + 33, j + 4, k + 29, Block.blockSnow.blockID);
		world.setBlock(i + 34, j + 0, k + 6, Block.blockSnow.blockID);
		world.setBlock(i + 34, j + 0, k + 16, Block.blockSnow.blockID);
		world.setBlock(i + 34, j + 0, k + 22, Block.blockSnow.blockID);
		world.setBlock(i + 34, j + 0, k + 32, Block.blockSnow.blockID);
		world.setBlock(i + 34, j + 1, k + 6, Block.blockSnow.blockID);
		world.setBlock(i + 34, j + 1, k + 16, Block.blockSnow.blockID);
		world.setBlock(i + 34, j + 1, k + 22, Block.blockSnow.blockID);
		world.setBlock(i + 34, j + 1, k + 32, Block.blockSnow.blockID);
		world.setBlock(i + 34, j + 2, k + 7, Block.blockSnow.blockID);
		world.setBlock(i + 34, j + 2, k + 15, Block.blockSnow.blockID);
		world.setBlock(i + 34, j + 2, k + 23, Block.blockSnow.blockID);
		world.setBlock(i + 34, j + 2, k + 31, Block.blockSnow.blockID);
		world.setBlock(i + 34, j + 3, k + 7, Block.blockSnow.blockID);
		world.setBlock(i + 34, j + 3, k + 15, Block.blockSnow.blockID);
		world.setBlock(i + 34, j + 3, k + 23, Block.blockSnow.blockID);
		world.setBlock(i + 34, j + 3, k + 31, Block.blockSnow.blockID);
		world.setBlock(i + 34, j + 4, k + 8, Block.blockSnow.blockID);
		world.setBlock(i + 34, j + 4, k + 9, Block.blockSnow.blockID);
		world.setBlock(i + 34, j + 4, k + 13, Block.blockSnow.blockID);
		world.setBlock(i + 34, j + 4, k + 14, Block.blockSnow.blockID);
		world.setBlock(i + 34, j + 4, k + 24, Block.blockSnow.blockID);
		world.setBlock(i + 34, j + 4, k + 25, Block.blockSnow.blockID);
		world.setBlock(i + 34, j + 4, k + 29, Block.blockSnow.blockID);
		world.setBlock(i + 34, j + 4, k + 30, Block.blockSnow.blockID);
		world.setBlock(i + 34, j + 5, k + 10, Block.blockSnow.blockID);
		world.setBlock(i + 34, j + 5, k + 11, Block.blockSnow.blockID);
		world.setBlock(i + 34, j + 5, k + 12, Block.blockSnow.blockID);
		world.setBlock(i + 34, j + 5, k + 26, Block.blockSnow.blockID);
		world.setBlock(i + 34, j + 5, k + 27, Block.blockSnow.blockID);
		world.setBlock(i + 34, j + 5, k + 28, Block.blockSnow.blockID);
		world.setBlock(i + 35, j + 0, k + 6, Block.blockSnow.blockID);
		world.setBlockMetadataWithNotify(i + 35, j + 0, k + 7, Block.furnaceIdle.blockID, 3);
		world.setBlock(i + 35, j + 0, k + 16, Block.blockSnow.blockID);
		world.setBlock(i + 35, j + 0, k + 22, Block.blockSnow.blockID);
		world.setBlock(i + 35, j + 0, k + 32, Block.blockSnow.blockID);
		world.setBlock(i + 35, j + 1, k + 6, Block.blockSnow.blockID);
		world.setBlock(i + 35, j + 1, k + 16, Block.blockSnow.blockID);
		world.setBlock(i + 35, j + 1, k + 22, Block.blockSnow.blockID);
		world.setBlock(i + 35, j + 1, k + 32, Block.blockSnow.blockID);
		world.setBlock(i + 35, j + 2, k + 6, Block.blockSnow.blockID);
		world.setBlock(i + 35, j + 2, k + 16, Block.blockSnow.blockID);
		world.setBlock(i + 35, j + 2, k + 22, Block.blockSnow.blockID);
		world.setBlock(i + 35, j + 2, k + 32, Block.blockSnow.blockID);
		world.setBlock(i + 35, j + 3, k + 7, Block.blockSnow.blockID);
		world.setBlock(i + 35, j + 3, k + 15, Block.blockSnow.blockID);
		world.setBlock(i + 35, j + 3, k + 23, Block.blockSnow.blockID);
		world.setBlock(i + 35, j + 3, k + 31, Block.blockSnow.blockID);
		world.setBlock(i + 35, j + 4, k + 8, Block.blockSnow.blockID);
		world.setBlock(i + 35, j + 4, k + 14, Block.blockSnow.blockID);
		world.setBlock(i + 35, j + 4, k + 24, Block.blockSnow.blockID);
		world.setBlock(i + 35, j + 4, k + 30, Block.blockSnow.blockID);
		world.setBlock(i + 35, j + 5, k + 9, Block.blockSnow.blockID);
		world.setBlock(i + 35, j + 5, k + 10, Block.blockSnow.blockID);
		world.setBlock(i + 35, j + 5, k + 11, Block.blockSnow.blockID);
		world.setBlock(i + 35, j + 5, k + 12, Block.blockSnow.blockID);
		world.setBlock(i + 35, j + 5, k + 13, Block.blockSnow.blockID);
		world.setBlock(i + 35, j + 5, k + 25, Block.blockSnow.blockID);
		world.setBlock(i + 35, j + 5, k + 26, Block.blockSnow.blockID);
		world.setBlock(i + 35, j + 5, k + 27, Block.blockSnow.blockID);
		world.setBlock(i + 35, j + 5, k + 28, Block.blockSnow.blockID);
		world.setBlock(i + 35, j + 5, k + 29, Block.blockSnow.blockID);
		world.setBlock(i + 36, j + 0, k + 6, Block.blockSnow.blockID);
		world.setBlockMetadataWithNotify(i + 36, j + 0, k + 7, Block.furnaceIdle.blockID, 3);
		world.setBlock(i + 36, j + 0, k + 11, Block.blockGold.blockID);
		world.setBlock(i + 36, j + 0, k + 27, Block.blockGold.blockID);
		world.setBlock(i + 36, j + 0, k + 32, Block.blockSnow.blockID);
		world.setBlock(i + 36, j + 1, k + 6, Block.blockSnow.blockID);
		world.setBlock(i + 36, j + 1, k + 32, Block.blockSnow.blockID);
		world.setBlock(i + 36, j + 2, k + 6, Block.blockSnow.blockID);
		world.setBlock(i + 36, j + 2, k + 16, Block.blockSnow.blockID);
		world.setBlock(i + 36, j + 2, k + 22, Block.blockSnow.blockID);
		world.setBlock(i + 36, j + 2, k + 32, Block.blockSnow.blockID);
		world.setBlock(i + 36, j + 3, k + 7, Block.blockSnow.blockID);
		world.setBlock(i + 36, j + 3, k + 15, Block.blockSnow.blockID);
		world.setBlock(i + 36, j + 3, k + 23, Block.blockSnow.blockID);
		world.setBlock(i + 36, j + 3, k + 31, Block.blockSnow.blockID);
		world.setBlock(i + 36, j + 4, k + 8, Block.blockSnow.blockID);
		world.setBlock(i + 36, j + 4, k + 14, Block.blockSnow.blockID);
		world.setBlock(i + 36, j + 4, k + 24, Block.blockSnow.blockID);
		world.setBlock(i + 36, j + 4, k + 30, Block.blockSnow.blockID);
		world.setBlock(i + 36, j + 5, k + 9, Block.blockSnow.blockID);
		world.setBlock(i + 36, j + 5, k + 10, Block.blockSnow.blockID);
		world.setBlock(i + 36, j + 5, k + 11, Block.blockSnow.blockID);
		world.setBlock(i + 36, j + 5, k + 12, Block.blockSnow.blockID);
		world.setBlock(i + 36, j + 5, k + 13, Block.blockSnow.blockID);
		world.setBlock(i + 36, j + 5, k + 25, Block.blockSnow.blockID);
		world.setBlock(i + 36, j + 5, k + 26, Block.blockSnow.blockID);
		world.setBlock(i + 36, j + 5, k + 27, Block.blockSnow.blockID);
		world.setBlock(i + 36, j + 5, k + 28, Block.blockSnow.blockID);
		world.setBlock(i + 36, j + 5, k + 29, Block.blockSnow.blockID);
		world.setBlock(i + 37, j + 0, k + 6, Block.blockSnow.blockID);
		world.setBlockMetadataWithNotify(i + 37, j + 0, k + 7, Block.furnaceIdle.blockID, 3);
		world.setBlock(i + 37, j + 0, k + 16, Block.blockSnow.blockID);
		world.setBlock(i + 37, j + 0, k + 22, Block.blockSnow.blockID);
		world.setBlock(i + 37, j + 0, k + 32, Block.blockSnow.blockID);
		world.setBlock(i + 37, j + 1, k + 6, Block.blockSnow.blockID);
		world.setBlock(i + 37, j + 1, k + 16, Block.blockSnow.blockID);
		world.setBlock(i + 37, j + 1, k + 22, Block.blockSnow.blockID);
		world.setBlock(i + 37, j + 1, k + 32, Block.blockSnow.blockID);
		world.setBlock(i + 37, j + 2, k + 6, Block.blockSnow.blockID);
		world.setBlock(i + 37, j + 2, k + 16, Block.blockSnow.blockID);
		world.setBlock(i + 37, j + 2, k + 22, Block.blockSnow.blockID);
		world.setBlock(i + 37, j + 2, k + 32, Block.blockSnow.blockID);
		world.setBlock(i + 37, j + 3, k + 7, Block.blockSnow.blockID);
		world.setBlock(i + 37, j + 3, k + 15, Block.blockSnow.blockID);
		world.setBlock(i + 37, j + 3, k + 23, Block.blockSnow.blockID);
		world.setBlock(i + 37, j + 3, k + 31, Block.blockSnow.blockID);
		world.setBlock(i + 37, j + 4, k + 8, Block.blockSnow.blockID);
		world.setBlock(i + 37, j + 4, k + 14, Block.blockSnow.blockID);
		world.setBlock(i + 37, j + 4, k + 24, Block.blockSnow.blockID);
		world.setBlock(i + 37, j + 4, k + 30, Block.blockSnow.blockID);
		world.setBlock(i + 37, j + 5, k + 9, Block.blockSnow.blockID);
		world.setBlock(i + 37, j + 5, k + 10, Block.blockSnow.blockID);
		world.setBlock(i + 37, j + 5, k + 11, Block.blockSnow.blockID);
		world.setBlock(i + 37, j + 5, k + 12, Block.blockSnow.blockID);
		world.setBlock(i + 37, j + 5, k + 13, Block.blockSnow.blockID);
		world.setBlock(i + 37, j + 5, k + 25, Block.blockSnow.blockID);
		world.setBlock(i + 37, j + 5, k + 26, Block.blockSnow.blockID);
		world.setBlock(i + 37, j + 5, k + 27, Block.blockSnow.blockID);
		world.setBlock(i + 37, j + 5, k + 28, Block.blockSnow.blockID);
		world.setBlock(i + 37, j + 5, k + 29, Block.blockSnow.blockID);
		world.setBlock(i + 38, j + 0, k + 6, Block.blockSnow.blockID);
		world.setBlock(i + 38, j + 0, k + 16, Block.blockSnow.blockID);
		world.setBlock(i + 38, j + 0, k + 22, Block.blockSnow.blockID);
		world.setBlock(i + 38, j + 0, k + 32, Block.blockSnow.blockID);
		world.setBlock(i + 38, j + 1, k + 6, Block.blockSnow.blockID);
		world.setBlock(i + 38, j + 1, k + 16, Block.blockSnow.blockID);
		world.setBlock(i + 38, j + 1, k + 22, Block.blockSnow.blockID);
		world.setBlock(i + 38, j + 1, k + 32, Block.blockSnow.blockID);
		world.setBlock(i + 38, j + 2, k + 7, Block.blockSnow.blockID);
		world.setBlock(i + 38, j + 2, k + 15, Block.blockSnow.blockID);
		world.setBlock(i + 38, j + 2, k + 23, Block.blockSnow.blockID);
		world.setBlock(i + 38, j + 2, k + 31, Block.blockSnow.blockID);
		world.setBlock(i + 38, j + 3, k + 7, Block.blockSnow.blockID);
		world.setBlock(i + 38, j + 3, k + 15, Block.blockSnow.blockID);
		world.setBlock(i + 38, j + 3, k + 23, Block.blockSnow.blockID);
		world.setBlock(i + 38, j + 3, k + 31, Block.blockSnow.blockID);
		world.setBlock(i + 38, j + 4, k + 8, Block.blockSnow.blockID);
		world.setBlock(i + 38, j + 4, k + 9, Block.blockSnow.blockID);
		world.setBlock(i + 38, j + 4, k + 13, Block.blockSnow.blockID);
		world.setBlock(i + 38, j + 4, k + 14, Block.blockSnow.blockID);
		world.setBlock(i + 38, j + 4, k + 24, Block.blockSnow.blockID);
		world.setBlock(i + 38, j + 4, k + 25, Block.blockSnow.blockID);
		world.setBlock(i + 38, j + 4, k + 29, Block.blockSnow.blockID);
		world.setBlock(i + 38, j + 4, k + 30, Block.blockSnow.blockID);
		world.setBlock(i + 38, j + 5, k + 10, Block.blockSnow.blockID);
		world.setBlock(i + 38, j + 5, k + 11, Block.blockSnow.blockID);
		world.setBlock(i + 38, j + 5, k + 12, Block.blockSnow.blockID);
		world.setBlock(i + 38, j + 5, k + 26, Block.blockSnow.blockID);
		world.setBlock(i + 38, j + 5, k + 27, Block.blockSnow.blockID);
		world.setBlock(i + 38, j + 5, k + 28, Block.blockSnow.blockID);
		world.setBlock(i + 39, j + 0, k + 7, Block.blockSnow.blockID);
		world.setBlock(i + 39, j + 0, k + 15, Block.blockSnow.blockID);
		world.setBlock(i + 39, j + 0, k + 23, Block.blockSnow.blockID);
		world.setBlock(i + 39, j + 0, k + 31, Block.blockSnow.blockID);
		world.setBlock(i + 39, j + 1, k + 7, Block.blockSnow.blockID);
		world.setBlock(i + 39, j + 1, k + 15, Block.blockSnow.blockID);
		world.setBlock(i + 39, j + 1, k + 23, Block.blockSnow.blockID);
		world.setBlock(i + 39, j + 1, k + 31, Block.blockSnow.blockID);
		world.setBlock(i + 39, j + 2, k + 7, Block.blockSnow.blockID);
		world.setBlock(i + 39, j + 2, k + 15, Block.blockSnow.blockID);
		world.setBlock(i + 39, j + 2, k + 23, Block.blockSnow.blockID);
		world.setBlock(i + 39, j + 2, k + 31, Block.blockSnow.blockID);
		world.setBlock(i + 39, j + 3, k + 8, Block.blockSnow.blockID);
		world.setBlock(i + 39, j + 3, k + 14, Block.blockSnow.blockID);
		world.setBlock(i + 39, j + 3, k + 24, Block.blockSnow.blockID);
		world.setBlock(i + 39, j + 3, k + 30, Block.blockSnow.blockID);
		world.setBlock(i + 39, j + 4, k + 9, Block.blockSnow.blockID);
		world.setBlock(i + 39, j + 4, k + 10, Block.blockSnow.blockID);
		world.setBlock(i + 39, j + 4, k + 11, Block.blockSnow.blockID);
		world.setBlock(i + 39, j + 4, k + 12, Block.blockSnow.blockID);
		world.setBlock(i + 39, j + 4, k + 13, Block.blockSnow.blockID);
		world.setBlock(i + 39, j + 4, k + 25, Block.blockSnow.blockID);
		world.setBlock(i + 39, j + 4, k + 26, Block.blockSnow.blockID);
		world.setBlock(i + 39, j + 4, k + 27, Block.blockSnow.blockID);
		world.setBlock(i + 39, j + 4, k + 28, Block.blockSnow.blockID);
		world.setBlock(i + 39, j + 4, k + 29, Block.blockSnow.blockID);
		world.setBlock(i + 40, j + 0, k + 8, Block.blockSnow.blockID);
		world.setBlock(i + 40, j + 0, k + 14, Block.blockSnow.blockID);
		world.setBlock(i + 40, j + 0, k + 24, Block.blockSnow.blockID);
		world.setBlock(i + 40, j + 0, k + 30, Block.blockSnow.blockID);
		world.setBlock(i + 40, j + 1, k + 8, Block.blockSnow.blockID);
		world.setBlock(i + 40, j + 1, k + 14, Block.blockSnow.blockID);
		world.setBlock(i + 40, j + 1, k + 24, Block.blockSnow.blockID);
		world.setBlock(i + 40, j + 1, k + 30, Block.blockSnow.blockID);
		world.setBlock(i + 40, j + 2, k + 8, Block.blockSnow.blockID);
		world.setBlock(i + 40, j + 2, k + 9, Block.blockSnow.blockID);
		world.setBlock(i + 40, j + 2, k + 13, Block.blockSnow.blockID);
		world.setBlock(i + 40, j + 2, k + 14, Block.blockSnow.blockID);
		world.setBlock(i + 40, j + 2, k + 24, Block.blockSnow.blockID);
		world.setBlock(i + 40, j + 2, k + 25, Block.blockSnow.blockID);
		world.setBlock(i + 40, j + 2, k + 29, Block.blockSnow.blockID);
		world.setBlock(i + 40, j + 2, k + 30, Block.blockSnow.blockID);
		world.setBlock(i + 40, j + 3, k + 9, Block.blockSnow.blockID);
		world.setBlock(i + 40, j + 3, k + 10, Block.blockSnow.blockID);
		world.setBlock(i + 40, j + 3, k + 11, Block.blockSnow.blockID);
		world.setBlock(i + 40, j + 3, k + 12, Block.blockSnow.blockID);
		world.setBlock(i + 40, j + 3, k + 13, Block.blockSnow.blockID);
		world.setBlock(i + 40, j + 3, k + 25, Block.blockSnow.blockID);
		world.setBlock(i + 40, j + 3, k + 26, Block.blockSnow.blockID);
		world.setBlock(i + 40, j + 3, k + 27, Block.blockSnow.blockID);
		world.setBlock(i + 40, j + 3, k + 28, Block.blockSnow.blockID);
		world.setBlock(i + 40, j + 3, k + 29, Block.blockSnow.blockID);
		world.setBlock(i + 41, j + 0, k + 9, Block.blockSnow.blockID);
		world.setBlock(i + 41, j + 0, k + 13, Block.blockSnow.blockID);
		world.setBlock(i + 41, j + 0, k + 25, Block.blockSnow.blockID);
		world.setBlock(i + 41, j + 0, k + 29, Block.blockSnow.blockID);
		world.setBlock(i + 41, j + 1, k + 9, Block.blockSnow.blockID);
		world.setBlock(i + 41, j + 1, k + 13, Block.blockSnow.blockID);
		world.setBlock(i + 41, j + 1, k + 25, Block.blockSnow.blockID);
		world.setBlock(i + 41, j + 1, k + 29, Block.blockSnow.blockID);
		world.setBlock(i + 41, j + 2, k + 10, Block.blockSnow.blockID);
		world.setBlock(i + 41, j + 2, k + 11, Block.blockSnow.blockID);
		world.setBlock(i + 41, j + 2, k + 12, Block.blockSnow.blockID);
		world.setBlock(i + 41, j + 2, k + 26, Block.blockSnow.blockID);
		world.setBlock(i + 41, j + 2, k + 27, Block.blockSnow.blockID);
		world.setBlock(i + 41, j + 2, k + 28, Block.blockSnow.blockID);
		world.setBlock(i + 42, j + 0, k + 9, Block.blockSnow.blockID);
		world.setBlock(i + 42, j + 0, k + 13, Block.blockSnow.blockID);
		world.setBlock(i + 42, j + 0, k + 25, Block.blockSnow.blockID);
		world.setBlock(i + 42, j + 0, k + 29, Block.blockSnow.blockID);
		world.setBlock(i + 42, j + 1, k + 9, Block.blockSnow.blockID);
		world.setBlock(i + 42, j + 1, k + 13, Block.blockSnow.blockID);
		world.setBlock(i + 42, j + 1, k + 25, Block.blockSnow.blockID);
		world.setBlock(i + 42, j + 1, k + 29, Block.blockSnow.blockID);
		world.setBlock(i + 42, j + 2, k + 10, Block.blockSnow.blockID);
		world.setBlock(i + 42, j + 2, k + 11, Block.blockSnow.blockID);
		world.setBlock(i + 42, j + 2, k + 12, Block.blockSnow.blockID);
		world.setBlock(i + 42, j + 2, k + 26, Block.blockSnow.blockID);
		world.setBlock(i + 42, j + 2, k + 27, Block.blockSnow.blockID);
		world.setBlock(i + 42, j + 2, k + 28, Block.blockSnow.blockID);
		world.setBlock(i + 43, j + 0, k + 8, Block.blockSnow.blockID);
		world.setBlock(i + 43, j + 0, k + 14, Block.blockSnow.blockID);
		world.setBlock(i + 43, j + 0, k + 24, Block.blockSnow.blockID);
		world.setBlock(i + 43, j + 0, k + 30, Block.blockSnow.blockID);
		world.setBlock(i + 43, j + 1, k + 8, Block.blockSnow.blockID);
		world.setBlock(i + 43, j + 1, k + 14, Block.blockSnow.blockID);
		world.setBlock(i + 43, j + 1, k + 24, Block.blockSnow.blockID);
		world.setBlock(i + 43, j + 1, k + 30, Block.blockSnow.blockID);
		world.setBlock(i + 43, j + 2, k + 8, Block.blockSnow.blockID);
		world.setBlock(i + 43, j + 2, k + 9, Block.blockSnow.blockID);
		world.setBlock(i + 43, j + 2, k + 13, Block.blockSnow.blockID);
		world.setBlock(i + 43, j + 2, k + 14, Block.blockSnow.blockID);
		world.setBlock(i + 43, j + 2, k + 24, Block.blockSnow.blockID);
		world.setBlock(i + 43, j + 2, k + 25, Block.blockSnow.blockID);
		world.setBlock(i + 43, j + 2, k + 29, Block.blockSnow.blockID);
		world.setBlock(i + 43, j + 2, k + 30, Block.blockSnow.blockID);
		world.setBlock(i + 43, j + 3, k + 9, Block.blockSnow.blockID);
		world.setBlock(i + 43, j + 3, k + 10, Block.blockSnow.blockID);
		world.setBlock(i + 43, j + 3, k + 11, Block.blockSnow.blockID);
		world.setBlock(i + 43, j + 3, k + 12, Block.blockSnow.blockID);
		world.setBlock(i + 43, j + 3, k + 13, Block.blockSnow.blockID);
		world.setBlock(i + 43, j + 3, k + 25, Block.blockSnow.blockID);
		world.setBlock(i + 43, j + 3, k + 26, Block.blockSnow.blockID);
		world.setBlock(i + 43, j + 3, k + 27, Block.blockSnow.blockID);
		world.setBlock(i + 43, j + 3, k + 28, Block.blockSnow.blockID);
		world.setBlock(i + 43, j + 3, k + 29, Block.blockSnow.blockID);
		world.setBlock(i + 44, j + 0, k + 7, Block.blockSnow.blockID);
		world.setBlock(i + 44, j + 0, k + 15, Block.blockSnow.blockID);
		world.setBlock(i + 44, j + 0, k + 23, Block.blockSnow.blockID);
		world.setBlock(i + 44, j + 0, k + 31, Block.blockSnow.blockID);
		world.setBlock(i + 44, j + 1, k + 7, Block.blockSnow.blockID);
		world.setBlock(i + 44, j + 1, k + 15, Block.blockSnow.blockID);
		world.setBlock(i + 44, j + 1, k + 23, Block.blockSnow.blockID);
		world.setBlock(i + 44, j + 1, k + 31, Block.blockSnow.blockID);
		world.setBlock(i + 44, j + 2, k + 7, Block.blockSnow.blockID);
		world.setBlock(i + 44, j + 2, k + 15, Block.blockSnow.blockID);
		world.setBlock(i + 44, j + 2, k + 23, Block.blockSnow.blockID);
		world.setBlock(i + 44, j + 2, k + 31, Block.blockSnow.blockID);
		world.setBlock(i + 44, j + 3, k + 8, Block.blockSnow.blockID);
		world.setBlock(i + 44, j + 3, k + 14, Block.blockSnow.blockID);
		world.setBlock(i + 44, j + 3, k + 24, Block.blockSnow.blockID);
		world.setBlock(i + 44, j + 3, k + 30, Block.blockSnow.blockID);
		world.setBlock(i + 44, j + 4, k + 9, Block.blockSnow.blockID);
		world.setBlock(i + 44, j + 4, k + 10, Block.blockSnow.blockID);
		world.setBlock(i + 44, j + 4, k + 11, Block.blockSnow.blockID);
		world.setBlock(i + 44, j + 4, k + 12, Block.blockSnow.blockID);
		world.setBlock(i + 44, j + 4, k + 13, Block.blockSnow.blockID);
		world.setBlock(i + 44, j + 4, k + 25, Block.blockSnow.blockID);
		world.setBlock(i + 44, j + 4, k + 26, Block.blockSnow.blockID);
		world.setBlock(i + 44, j + 4, k + 27, Block.blockSnow.blockID);
		world.setBlock(i + 44, j + 4, k + 28, Block.blockSnow.blockID);
		world.setBlock(i + 44, j + 4, k + 29, Block.blockSnow.blockID);
		world.setBlock(i + 45, j + 0, k + 6, Block.blockSnow.blockID);
		world.setBlock(i + 45, j + 0, k + 16, Block.blockSnow.blockID);
		world.setBlock(i + 45, j + 0, k + 22, Block.blockSnow.blockID);
		world.setBlock(i + 45, j + 0, k + 32, Block.blockSnow.blockID);
		world.setBlock(i + 45, j + 1, k + 6, Block.blockSnow.blockID);
		world.setBlock(i + 45, j + 1, k + 16, Block.blockSnow.blockID);
		world.setBlock(i + 45, j + 1, k + 22, Block.blockSnow.blockID);
		world.setBlock(i + 45, j + 1, k + 32, Block.blockSnow.blockID);
		world.setBlock(i + 45, j + 2, k + 7, Block.blockSnow.blockID);
		world.setBlock(i + 45, j + 2, k + 15, Block.blockSnow.blockID);
		world.setBlock(i + 45, j + 2, k + 23, Block.blockSnow.blockID);
		world.setBlock(i + 45, j + 2, k + 31, Block.blockSnow.blockID);
		world.setBlock(i + 45, j + 3, k + 7, Block.blockSnow.blockID);
		world.setBlock(i + 45, j + 3, k + 15, Block.blockSnow.blockID);
		world.setBlock(i + 45, j + 3, k + 23, Block.blockSnow.blockID);
		world.setBlock(i + 45, j + 3, k + 31, Block.blockSnow.blockID);
		world.setBlock(i + 45, j + 4, k + 8, Block.blockSnow.blockID);
		world.setBlock(i + 45, j + 4, k + 9, Block.blockSnow.blockID);
		world.setBlock(i + 45, j + 4, k + 13, Block.blockSnow.blockID);
		world.setBlock(i + 45, j + 4, k + 14, Block.blockSnow.blockID);
		world.setBlock(i + 45, j + 4, k + 24, Block.blockSnow.blockID);
		world.setBlock(i + 45, j + 4, k + 25, Block.blockSnow.blockID);
		world.setBlock(i + 45, j + 4, k + 29, Block.blockSnow.blockID);
		world.setBlock(i + 45, j + 4, k + 30, Block.blockSnow.blockID);
		world.setBlock(i + 45, j + 5, k + 10, Block.blockSnow.blockID);
		world.setBlock(i + 45, j + 5, k + 11, Block.blockSnow.blockID);
		world.setBlock(i + 45, j + 5, k + 12, Block.blockSnow.blockID);
		world.setBlock(i + 45, j + 5, k + 26, Block.blockSnow.blockID);
		world.setBlock(i + 45, j + 5, k + 27, Block.blockSnow.blockID);
		world.setBlock(i + 45, j + 5, k + 28, Block.blockSnow.blockID);
		world.setBlock(i + 46, j + 0, k + 6, Block.blockSnow.blockID);
		world.setBlockMetadataWithNotify(i + 46, j + 0, k + 7, Block.furnaceIdle.blockID, 3);
		world.setBlock(i + 46, j + 0, k + 16, Block.blockSnow.blockID);
		world.setBlock(i + 46, j + 0, k + 22, Block.blockSnow.blockID);
		world.setBlock(i + 46, j + 0, k + 32, Block.blockSnow.blockID);
		world.setBlock(i + 46, j + 1, k + 6, Block.blockSnow.blockID);
		world.setBlock(i + 46, j + 1, k + 16, Block.blockSnow.blockID);
		world.setBlock(i + 46, j + 1, k + 22, Block.blockSnow.blockID);
		world.setBlock(i + 46, j + 1, k + 32, Block.blockSnow.blockID);
		world.setBlock(i + 46, j + 2, k + 6, Block.blockSnow.blockID);
		world.setBlock(i + 46, j + 2, k + 16, Block.blockSnow.blockID);
		world.setBlock(i + 46, j + 2, k + 22, Block.blockSnow.blockID);
		world.setBlock(i + 46, j + 2, k + 32, Block.blockSnow.blockID);
		world.setBlock(i + 46, j + 3, k + 7, Block.blockSnow.blockID);
		world.setBlock(i + 46, j + 3, k + 15, Block.blockSnow.blockID);
		world.setBlock(i + 46, j + 3, k + 23, Block.blockSnow.blockID);
		world.setBlock(i + 46, j + 3, k + 31, Block.blockSnow.blockID);
		world.setBlock(i + 46, j + 4, k + 8, Block.blockSnow.blockID);
		world.setBlock(i + 46, j + 4, k + 14, Block.blockSnow.blockID);
		world.setBlock(i + 46, j + 4, k + 24, Block.blockSnow.blockID);
		world.setBlock(i + 46, j + 4, k + 30, Block.blockSnow.blockID);
		world.setBlock(i + 46, j + 5, k + 9, Block.blockSnow.blockID);
		world.setBlock(i + 46, j + 5, k + 10, Block.blockSnow.blockID);
		world.setBlock(i + 46, j + 5, k + 11, Block.blockSnow.blockID);
		world.setBlock(i + 46, j + 5, k + 12, Block.blockSnow.blockID);
		world.setBlock(i + 46, j + 5, k + 13, Block.blockSnow.blockID);
		world.setBlock(i + 46, j + 5, k + 25, Block.blockSnow.blockID);
		world.setBlock(i + 46, j + 5, k + 26, Block.blockSnow.blockID);
		world.setBlock(i + 46, j + 5, k + 27, Block.blockSnow.blockID);
		world.setBlock(i + 46, j + 5, k + 28, Block.blockSnow.blockID);
		world.setBlock(i + 46, j + 5, k + 29, Block.blockSnow.blockID);
		world.setBlock(i + 47, j + 0, k + 6, Block.blockSnow.blockID);
		world.setBlockMetadataWithNotify(i + 47, j + 0, k + 7, Block.furnaceIdle.blockID, 3);
		world.setBlock(i + 47, j + 0, k + 11, Block.blockGold.blockID);
		world.setBlock(i + 47, j + 0, k + 27, Block.blockGold.blockID);
		world.setBlock(i + 47, j + 0, k + 32, Block.blockSnow.blockID);
		world.setBlock(i + 47, j + 1, k + 6, Block.blockSnow.blockID);
		world.setBlock(i + 47, j + 1, k + 32, Block.blockSnow.blockID);
		world.setBlock(i + 47, j + 2, k + 6, Block.blockSnow.blockID);
		world.setBlock(i + 47, j + 2, k + 16, Block.blockSnow.blockID);
		world.setBlock(i + 47, j + 2, k + 22, Block.blockSnow.blockID);
		world.setBlock(i + 47, j + 2, k + 32, Block.blockSnow.blockID);
		world.setBlock(i + 47, j + 3, k + 7, Block.blockSnow.blockID);
		world.setBlock(i + 47, j + 3, k + 15, Block.blockSnow.blockID);
		world.setBlock(i + 47, j + 3, k + 23, Block.blockSnow.blockID);
		world.setBlock(i + 47, j + 3, k + 31, Block.blockSnow.blockID);
		world.setBlock(i + 47, j + 4, k + 8, Block.blockSnow.blockID);
		world.setBlock(i + 47, j + 4, k + 14, Block.blockSnow.blockID);
		world.setBlock(i + 47, j + 4, k + 24, Block.blockSnow.blockID);
		world.setBlock(i + 47, j + 4, k + 30, Block.blockSnow.blockID);
		world.setBlock(i + 47, j + 5, k + 9, Block.blockSnow.blockID);
		world.setBlock(i + 47, j + 5, k + 10, Block.blockSnow.blockID);
		world.setBlock(i + 47, j + 5, k + 11, Block.blockSnow.blockID);
		world.setBlock(i + 47, j + 5, k + 12, Block.blockSnow.blockID);
		world.setBlock(i + 47, j + 5, k + 13, Block.blockSnow.blockID);
		world.setBlock(i + 47, j + 5, k + 25, Block.blockSnow.blockID);
		world.setBlock(i + 47, j + 5, k + 26, Block.blockSnow.blockID);
		world.setBlock(i + 47, j + 5, k + 27, Block.blockSnow.blockID);
		world.setBlock(i + 47, j + 5, k + 28, Block.blockSnow.blockID);
		world.setBlock(i + 47, j + 5, k + 29, Block.blockSnow.blockID);
		world.setBlock(i + 48, j + 0, k + 6, Block.blockSnow.blockID);
		world.setBlockMetadataWithNotify(i + 48, j + 0, k + 7, Block.furnaceIdle.blockID, 3);
		world.setBlock(i + 48, j + 0, k + 16, Block.blockSnow.blockID);
		world.setBlock(i + 48, j + 0, k + 22, Block.blockSnow.blockID);
		world.setBlock(i + 48, j + 0, k + 32, Block.blockSnow.blockID);
		world.setBlock(i + 48, j + 1, k + 6, Block.blockSnow.blockID);
		world.setBlock(i + 48, j + 1, k + 16, Block.blockSnow.blockID);
		world.setBlock(i + 48, j + 1, k + 22, Block.blockSnow.blockID);
		world.setBlock(i + 48, j + 1, k + 32, Block.blockSnow.blockID);
		world.setBlock(i + 48, j + 2, k + 6, Block.blockSnow.blockID);
		world.setBlock(i + 48, j + 2, k + 16, Block.blockSnow.blockID);
		world.setBlock(i + 48, j + 2, k + 22, Block.blockSnow.blockID);
		world.setBlock(i + 48, j + 2, k + 32, Block.blockSnow.blockID);
		world.setBlock(i + 48, j + 3, k + 7, Block.blockSnow.blockID);
		world.setBlock(i + 48, j + 3, k + 15, Block.blockSnow.blockID);
		world.setBlock(i + 48, j + 3, k + 23, Block.blockSnow.blockID);
		world.setBlock(i + 48, j + 3, k + 31, Block.blockSnow.blockID);
		world.setBlock(i + 48, j + 4, k + 8, Block.blockSnow.blockID);
		world.setBlock(i + 48, j + 4, k + 14, Block.blockSnow.blockID);
		world.setBlock(i + 48, j + 4, k + 24, Block.blockSnow.blockID);
		world.setBlock(i + 48, j + 4, k + 30, Block.blockSnow.blockID);
		world.setBlock(i + 48, j + 5, k + 9, Block.blockSnow.blockID);
		world.setBlock(i + 48, j + 5, k + 10, Block.blockSnow.blockID);
		world.setBlock(i + 48, j + 5, k + 11, Block.blockSnow.blockID);
		world.setBlock(i + 48, j + 5, k + 12, Block.blockSnow.blockID);
		world.setBlock(i + 48, j + 5, k + 13, Block.blockSnow.blockID);
		world.setBlock(i + 48, j + 5, k + 25, Block.blockSnow.blockID);
		world.setBlock(i + 48, j + 5, k + 26, Block.blockSnow.blockID);
		world.setBlock(i + 48, j + 5, k + 27, Block.blockSnow.blockID);
		world.setBlock(i + 48, j + 5, k + 28, Block.blockSnow.blockID);
		world.setBlock(i + 48, j + 5, k + 29, Block.blockSnow.blockID);
		world.setBlock(i + 49, j + 0, k + 6, Block.blockSnow.blockID);
		world.setBlock(i + 49, j + 0, k + 16, Block.blockSnow.blockID);
		world.setBlock(i + 49, j + 0, k + 22, Block.blockSnow.blockID);
		world.setBlock(i + 49, j + 0, k + 32, Block.blockSnow.blockID);
		world.setBlock(i + 49, j + 1, k + 6, Block.blockSnow.blockID);
		world.setBlock(i + 49, j + 1, k + 16, Block.blockSnow.blockID);
		world.setBlock(i + 49, j + 1, k + 22, Block.blockSnow.blockID);
		world.setBlock(i + 49, j + 1, k + 32, Block.blockSnow.blockID);
		world.setBlock(i + 49, j + 2, k + 7, Block.blockSnow.blockID);
		world.setBlock(i + 49, j + 2, k + 15, Block.blockSnow.blockID);
		world.setBlock(i + 49, j + 2, k + 23, Block.blockSnow.blockID);
		world.setBlock(i + 49, j + 2, k + 31, Block.blockSnow.blockID);
		world.setBlock(i + 49, j + 3, k + 7, Block.blockSnow.blockID);
		world.setBlock(i + 49, j + 3, k + 15, Block.blockSnow.blockID);
		world.setBlock(i + 49, j + 3, k + 23, Block.blockSnow.blockID);
		world.setBlock(i + 49, j + 3, k + 31, Block.blockSnow.blockID);
		world.setBlock(i + 49, j + 4, k + 8, Block.blockSnow.blockID);
		world.setBlock(i + 49, j + 4, k + 9, Block.blockSnow.blockID);
		world.setBlock(i + 49, j + 4, k + 13, Block.blockSnow.blockID);
		world.setBlock(i + 49, j + 4, k + 14, Block.blockSnow.blockID);
		world.setBlock(i + 49, j + 4, k + 24, Block.blockSnow.blockID);
		world.setBlock(i + 49, j + 4, k + 25, Block.blockSnow.blockID);
		world.setBlock(i + 49, j + 4, k + 29, Block.blockSnow.blockID);
		world.setBlock(i + 49, j + 4, k + 30, Block.blockSnow.blockID);
		world.setBlock(i + 49, j + 5, k + 10, Block.blockSnow.blockID);
		world.setBlock(i + 49, j + 5, k + 11, Block.blockSnow.blockID);
		world.setBlock(i + 49, j + 5, k + 12, Block.blockSnow.blockID);
		world.setBlock(i + 49, j + 5, k + 26, Block.blockSnow.blockID);
		world.setBlock(i + 49, j + 5, k + 27, Block.blockSnow.blockID);
		world.setBlock(i + 49, j + 5, k + 28, Block.blockSnow.blockID);
		world.setBlock(i + 50, j + 0, k + 7, Block.blockSnow.blockID);
		world.setBlock(i + 50, j + 0, k + 15, Block.blockSnow.blockID);
		world.setBlock(i + 50, j + 0, k + 23, Block.blockSnow.blockID);
		world.setBlock(i + 50, j + 0, k + 31, Block.blockSnow.blockID);
		world.setBlock(i + 50, j + 1, k + 7, Block.blockSnow.blockID);
		world.setBlock(i + 50, j + 1, k + 15, Block.blockSnow.blockID);
		world.setBlock(i + 50, j + 1, k + 23, Block.blockSnow.blockID);
		world.setBlock(i + 50, j + 1, k + 31, Block.blockSnow.blockID);
		world.setBlock(i + 50, j + 2, k + 7, Block.blockSnow.blockID);
		world.setBlock(i + 50, j + 2, k + 15, Block.blockSnow.blockID);
		world.setBlock(i + 50, j + 2, k + 23, Block.blockSnow.blockID);
		world.setBlock(i + 50, j + 2, k + 31, Block.blockSnow.blockID);
		world.setBlock(i + 50, j + 3, k + 8, Block.blockSnow.blockID);
		world.setBlock(i + 50, j + 3, k + 14, Block.blockSnow.blockID);
		world.setBlock(i + 50, j + 3, k + 24, Block.blockSnow.blockID);
		world.setBlock(i + 50, j + 3, k + 30, Block.blockSnow.blockID);
		world.setBlock(i + 50, j + 4, k + 9, Block.blockSnow.blockID);
		world.setBlock(i + 50, j + 4, k + 10, Block.blockSnow.blockID);
		world.setBlock(i + 50, j + 4, k + 11, Block.blockSnow.blockID);
		world.setBlock(i + 50, j + 4, k + 12, Block.blockSnow.blockID);
		world.setBlock(i + 50, j + 4, k + 13, Block.blockSnow.blockID);
		world.setBlock(i + 50, j + 4, k + 25, Block.blockSnow.blockID);
		world.setBlock(i + 50, j + 4, k + 26, Block.blockSnow.blockID);
		world.setBlock(i + 50, j + 4, k + 27, Block.blockSnow.blockID);
		world.setBlock(i + 50, j + 4, k + 28, Block.blockSnow.blockID);
		world.setBlock(i + 50, j + 4, k + 29, Block.blockSnow.blockID);
		world.setBlock(i + 51, j + 0, k + 8, Block.blockSnow.blockID);
		world.setBlock(i + 51, j + 0, k + 11, Block.blockSteel.blockID);
		world.setBlock(i + 51, j + 0, k + 14, Block.blockSnow.blockID);
		world.setBlock(i + 51, j + 0, k + 24, Block.blockSnow.blockID);
		world.setBlock(i + 51, j + 0, k + 30, Block.blockSnow.blockID);
		world.setBlock(i + 51, j + 1, k + 8, Block.blockSnow.blockID);
		world.setBlock(i + 51, j + 1, k + 14, Block.blockSnow.blockID);
		world.setBlock(i + 51, j + 1, k + 24, Block.blockSnow.blockID);
		world.setBlock(i + 51, j + 1, k + 30, Block.blockSnow.blockID);
		world.setBlock(i + 51, j + 2, k + 8, Block.blockSnow.blockID);
		world.setBlock(i + 51, j + 2, k + 9, Block.blockSnow.blockID);
		world.setBlock(i + 51, j + 2, k + 13, Block.blockSnow.blockID);
		world.setBlock(i + 51, j + 2, k + 14, Block.blockSnow.blockID);
		world.setBlock(i + 51, j + 2, k + 24, Block.blockSnow.blockID);
		world.setBlock(i + 51, j + 2, k + 25, Block.blockSnow.blockID);
		world.setBlock(i + 51, j + 2, k + 29, Block.blockSnow.blockID);
		world.setBlock(i + 51, j + 2, k + 30, Block.blockSnow.blockID);
		world.setBlock(i + 51, j + 3, k + 9, Block.blockSnow.blockID);
		world.setBlock(i + 51, j + 3, k + 10, Block.blockSnow.blockID);
		world.setBlock(i + 51, j + 3, k + 11, Block.blockSnow.blockID);
		world.setBlock(i + 51, j + 3, k + 12, Block.blockSnow.blockID);
		world.setBlock(i + 51, j + 3, k + 13, Block.blockSnow.blockID);
		world.setBlock(i + 51, j + 3, k + 25, Block.blockSnow.blockID);
		world.setBlock(i + 51, j + 3, k + 26, Block.blockSnow.blockID);
		world.setBlock(i + 51, j + 3, k + 27, Block.blockSnow.blockID);
		world.setBlock(i + 51, j + 3, k + 28, Block.blockSnow.blockID);
		world.setBlock(i + 51, j + 3, k + 29, Block.blockSnow.blockID);
		world.setBlock(i + 52, j + 0, k + 9, Block.blockSnow.blockID);
		world.setBlock(i + 52, j + 0, k + 10, Block.blockSnow.blockID);
		world.setBlock(i + 52, j + 0, k + 11, Block.blockSnow.blockID);
		world.setBlock(i + 52, j + 0, k + 12, Block.blockSnow.blockID);
		world.setBlock(i + 52, j + 0, k + 13, Block.blockSnow.blockID);
		world.setBlock(i + 52, j + 0, k + 25, Block.blockSnow.blockID);
		world.setBlock(i + 52, j + 0, k + 26, Block.blockSnow.blockID);
		world.setBlock(i + 52, j + 0, k + 27, Block.blockSnow.blockID);
		world.setBlock(i + 52, j + 0, k + 28, Block.blockSnow.blockID);
		world.setBlock(i + 52, j + 0, k + 29, Block.blockSnow.blockID);
		world.setBlock(i + 52, j + 1, k + 9, Block.blockSnow.blockID);
		world.setBlock(i + 52, j + 1, k + 10, Block.blockSnow.blockID);
		world.setBlock(i + 52, j + 1, k + 11, Block.blockSnow.blockID);
		world.setBlock(i + 52, j + 1, k + 12, Block.blockSnow.blockID);
		world.setBlock(i + 52, j + 1, k + 13, Block.blockSnow.blockID);
		world.setBlock(i + 52, j + 1, k + 25, Block.blockSnow.blockID);
		world.setBlock(i + 52, j + 1, k + 26, Block.blockSnow.blockID);
		world.setBlock(i + 52, j + 1, k + 27, Block.blockSnow.blockID);
		world.setBlock(i + 52, j + 1, k + 28, Block.blockSnow.blockID);
		world.setBlock(i + 52, j + 1, k + 29, Block.blockSnow.blockID);
		world.setBlock(i + 52, j + 2, k + 10, Block.blockSnow.blockID);
		world.setBlock(i + 52, j + 2, k + 11, Block.blockSnow.blockID);
		world.setBlock(i + 52, j + 2, k + 12, Block.blockSnow.blockID);
		world.setBlock(i + 52, j + 2, k + 26, Block.blockSnow.blockID);
		world.setBlock(i + 52, j + 2, k + 27, Block.blockSnow.blockID);
		world.setBlock(i + 52, j + 2, k + 28, Block.blockSnow.blockID);
		world.setBlock(i + 55, j + 0, k + 17, Block.blockSnow.blockID);
		world.setBlock(i + 55, j + 0, k + 21, Block.blockSnow.blockID);
		world.setBlock(i + 55, j + 1, k + 17, Block.blockSnow.blockID);
		world.setBlock(i + 55, j + 1, k + 21, Block.blockSnow.blockID);
		world.setBlock(i + 55, j + 2, k + 18, Block.blockSnow.blockID);
		world.setBlock(i + 55, j + 2, k + 20, Block.blockSnow.blockID);
		world.setBlock(i + 55, j + 3, k + 19, Block.blockSnow.blockID);
		world.setBlock(i + 56, j + 0, k + 17, Block.blockSnow.blockID);
		world.setBlock(i + 56, j + 0, k + 21, Block.blockSnow.blockID);
		world.setBlock(i + 56, j + 1, k + 17, Block.blockSnow.blockID);
		world.setBlock(i + 56, j + 1, k + 21, Block.blockSnow.blockID);
		world.setBlock(i + 56, j + 2, k + 17, Block.blockSnow.blockID);
		world.setBlock(i + 56, j + 2, k + 18, Block.blockSnow.blockID);
		world.setBlock(i + 56, j + 2, k + 20, Block.blockSnow.blockID);
		world.setBlock(i + 56, j + 2, k + 21, Block.blockSnow.blockID);
		world.setBlock(i + 56, j + 3, k + 17, Block.blockSnow.blockID);
		world.setBlock(i + 56, j + 3, k + 18, Block.blockSnow.blockID);
		world.setBlock(i + 56, j + 3, k + 19, Block.blockSnow.blockID);
		world.setBlock(i + 56, j + 3, k + 20, Block.blockSnow.blockID);
		world.setBlock(i + 56, j + 3, k + 21, Block.blockSnow.blockID);
		world.setBlock(i + 56, j + 4, k + 17, Block.blockSnow.blockID);
		world.setBlock(i + 56, j + 4, k + 18, Block.blockSnow.blockID);
		world.setBlock(i + 56, j + 4, k + 19, Block.blockSnow.blockID);
		world.setBlock(i + 56, j + 4, k + 20, Block.blockSnow.blockID);
		world.setBlock(i + 56, j + 4, k + 21, Block.blockSnow.blockID);
		world.setBlock(i + 57, j + 0, k + 15, Block.blockSnow.blockID);
		world.setBlock(i + 57, j + 0, k + 16, Block.blockSnow.blockID);
		world.setBlock(i + 57, j + 0, k + 22, Block.blockSnow.blockID);
		world.setBlock(i + 57, j + 0, k + 23, Block.blockSnow.blockID);
		world.setBlock(i + 57, j + 1, k + 15, Block.blockSnow.blockID);
		world.setBlock(i + 57, j + 1, k + 16, Block.blockSnow.blockID);
		world.setBlock(i + 57, j + 1, k + 22, Block.blockSnow.blockID);
		world.setBlock(i + 57, j + 1, k + 23, Block.blockSnow.blockID);
		world.setBlock(i + 57, j + 2, k + 15, Block.blockSnow.blockID);
		world.setBlock(i + 57, j + 2, k + 16, Block.blockSnow.blockID);
		world.setBlock(i + 57, j + 2, k + 22, Block.blockSnow.blockID);
		world.setBlock(i + 57, j + 2, k + 23, Block.blockSnow.blockID);
		world.setBlock(i + 57, j + 3, k + 15, Block.blockSnow.blockID);
		world.setBlock(i + 57, j + 3, k + 16, Block.blockSnow.blockID);
		world.setBlock(i + 57, j + 3, k + 22, Block.blockSnow.blockID);
		world.setBlock(i + 57, j + 3, k + 23, Block.blockSnow.blockID);
		world.setBlock(i + 57, j + 4, k + 15, Block.blockSnow.blockID);
		world.setBlock(i + 57, j + 4, k + 16, Block.blockSnow.blockID);
		world.setBlock(i + 57, j + 4, k + 22, Block.blockSnow.blockID);
		world.setBlock(i + 57, j + 4, k + 23, Block.blockSnow.blockID);
		world.setBlock(i + 57, j + 5, k + 17, Block.blockSnow.blockID);
		world.setBlock(i + 57, j + 5, k + 18, Block.blockSnow.blockID);
		world.setBlock(i + 57, j + 5, k + 19, Block.blockSnow.blockID);
		world.setBlock(i + 57, j + 5, k + 20, Block.blockSnow.blockID);
		world.setBlock(i + 57, j + 5, k + 21, Block.blockSnow.blockID);
		world.setBlock(i + 57, j + 6, k + 19, Block.blockSnow.blockID);
		world.setBlock(i + 58, j + 0, k + 14, Block.blockSnow.blockID);
		world.setBlock(i + 58, j + 0, k + 24, Block.blockSnow.blockID);
		world.setBlock(i + 58, j + 1, k + 14, Block.blockSnow.blockID);
		world.setBlock(i + 58, j + 1, k + 24, Block.blockSnow.blockID);
		world.setBlock(i + 58, j + 2, k + 14, Block.blockSnow.blockID);
		world.setBlock(i + 58, j + 2, k + 24, Block.blockSnow.blockID);
		world.setBlock(i + 58, j + 3, k + 14, Block.blockSnow.blockID);
		world.setBlock(i + 58, j + 3, k + 24, Block.blockSnow.blockID);
		world.setBlock(i + 58, j + 4, k + 14, Block.blockSnow.blockID);
		world.setBlock(i + 58, j + 4, k + 24, Block.blockSnow.blockID);
		world.setBlock(i + 58, j + 5, k + 15, Block.blockSnow.blockID);
		world.setBlock(i + 58, j + 5, k + 16, Block.blockSnow.blockID);
		world.setBlock(i + 58, j + 5, k + 22, Block.blockSnow.blockID);
		world.setBlock(i + 58, j + 5, k + 23, Block.blockSnow.blockID);
		world.setBlock(i + 58, j + 6, k + 17, Block.blockSnow.blockID);
		world.setBlock(i + 58, j + 6, k + 18, Block.blockSnow.blockID);
		world.setBlock(i + 58, j + 6, k + 19, Block.blockSnow.blockID);
		world.setBlock(i + 58, j + 6, k + 20, Block.blockSnow.blockID);
		world.setBlock(i + 58, j + 6, k + 21, Block.blockSnow.blockID);
		world.setBlock(i + 58, j + 7, k + 18, Block.blockSnow.blockID);
		world.setBlock(i + 58, j + 7, k + 19, Block.blockSnow.blockID);
		world.setBlock(i + 58, j + 7, k + 20, Block.blockSnow.blockID);
		world.setBlock(i + 59, j + 0, k + 13, Block.blockSnow.blockID);
		world.setBlock(i + 59, j + 0, k + 25, Block.blockSnow.blockID);
		world.setBlock(i + 59, j + 1, k + 13, Block.blockSnow.blockID);
		world.setBlock(i + 59, j + 1, k + 25, Block.blockSnow.blockID);
		world.setBlock(i + 59, j + 2, k + 13, Block.blockSnow.blockID);
		world.setBlock(i + 59, j + 2, k + 25, Block.blockSnow.blockID);
		world.setBlock(i + 59, j + 3, k + 13, Block.blockSnow.blockID);
		world.setBlock(i + 59, j + 3, k + 25, Block.blockSnow.blockID);
		world.setBlock(i + 59, j + 4, k + 13, Block.blockSnow.blockID);
		world.setBlock(i + 59, j + 4, k + 25, Block.blockSnow.blockID);
		world.setBlock(i + 59, j + 5, k + 14, Block.blockSnow.blockID);
		world.setBlock(i + 59, j + 5, k + 24, Block.blockSnow.blockID);
		world.setBlock(i + 59, j + 6, k + 15, Block.blockSnow.blockID);
		world.setBlock(i + 59, j + 6, k + 16, Block.blockSnow.blockID);
		world.setBlock(i + 59, j + 6, k + 22, Block.blockSnow.blockID);
		world.setBlock(i + 59, j + 6, k + 23, Block.blockSnow.blockID);
		world.setBlock(i + 59, j + 7, k + 17, Block.blockSnow.blockID);
		world.setBlock(i + 59, j + 7, k + 18, Block.blockSnow.blockID);
		world.setBlock(i + 59, j + 7, k + 19, Block.blockSnow.blockID);
		world.setBlock(i + 59, j + 7, k + 20, Block.blockSnow.blockID);
		world.setBlock(i + 59, j + 7, k + 21, Block.blockSnow.blockID);
		world.setBlock(i + 59, j + 8, k + 19, Block.blockSnow.blockID);
		world.setBlock(i + 60, j + 0, k + 13, Block.blockSnow.blockID);
		world.setBlock(i + 60, j + 0, k + 25, Block.blockSnow.blockID);
		world.setBlock(i + 60, j + 1, k + 13, Block.blockSnow.blockID);
		world.setBlock(i + 60, j + 1, k + 25, Block.blockSnow.blockID);
		world.setBlock(i + 60, j + 2, k + 13, Block.blockSnow.blockID);
		world.setBlock(i + 60, j + 2, k + 25, Block.blockSnow.blockID);
		world.setBlock(i + 60, j + 3, k + 13, Block.blockSnow.blockID);
		world.setBlock(i + 60, j + 3, k + 25, Block.blockSnow.blockID);
		world.setBlock(i + 60, j + 4, k + 13, Block.blockSnow.blockID);
		world.setBlock(i + 60, j + 4, k + 25, Block.blockSnow.blockID);
		world.setBlock(i + 60, j + 5, k + 14, Block.blockSnow.blockID);
		world.setBlock(i + 60, j + 5, k + 24, Block.blockSnow.blockID);
		world.setBlock(i + 60, j + 6, k + 15, Block.blockSnow.blockID);
		world.setBlock(i + 60, j + 6, k + 23, Block.blockSnow.blockID);
		world.setBlock(i + 60, j + 7, k + 16, Block.blockSnow.blockID);
		world.setBlock(i + 60, j + 7, k + 22, Block.blockSnow.blockID);
		world.setBlock(i + 60, j + 8, k + 17, Block.blockSnow.blockID);
		world.setBlock(i + 60, j + 8, k + 18, Block.blockSnow.blockID);
		world.setBlock(i + 60, j + 8, k + 19, Block.blockSnow.blockID);
		world.setBlock(i + 60, j + 8, k + 20, Block.blockSnow.blockID);
		world.setBlock(i + 60, j + 8, k + 21, Block.blockSnow.blockID);
		world.setBlock(i + 61, j + 0, k + 12, Block.blockSnow.blockID);
		world.setBlock(i + 61, j + 0, k + 26, Block.blockSnow.blockID);
		world.setBlock(i + 61, j + 1, k + 12, Block.blockSnow.blockID);
		world.setBlock(i + 61, j + 1, k + 26, Block.blockSnow.blockID);
		world.setBlock(i + 61, j + 2, k + 12, Block.blockSnow.blockID);
		world.setBlock(i + 61, j + 2, k + 26, Block.blockSnow.blockID);
		world.setBlock(i + 61, j + 3, k + 12, Block.blockSnow.blockID);
		world.setBlock(i + 61, j + 3, k + 26, Block.blockSnow.blockID);
		world.setBlock(i + 61, j + 4, k + 12, Block.blockSnow.blockID);
		world.setBlock(i + 61, j + 4, k + 26, Block.blockSnow.blockID);
		world.setBlock(i + 61, j + 5, k + 13, Block.blockSnow.blockID);
		world.setBlock(i + 61, j + 5, k + 25, Block.blockSnow.blockID);
		world.setBlock(i + 61, j + 6, k + 14, Block.blockSnow.blockID);
		world.setBlock(i + 61, j + 6, k + 24, Block.blockSnow.blockID);
		world.setBlock(i + 61, j + 7, k + 15, Block.blockSnow.blockID);
		world.setBlock(i + 61, j + 7, k + 23, Block.blockSnow.blockID);
		world.setBlock(i + 61, j + 8, k + 16, Block.blockSnow.blockID);
		world.setBlock(i + 61, j + 8, k + 17, Block.blockSnow.blockID);
		world.setBlock(i + 61, j + 8, k + 18, Block.blockSnow.blockID);
		world.setBlock(i + 61, j + 8, k + 19, Block.blockSnow.blockID);
		world.setBlock(i + 61, j + 8, k + 20, Block.blockSnow.blockID);
		world.setBlock(i + 61, j + 8, k + 21, Block.blockSnow.blockID);
		world.setBlock(i + 61, j + 8, k + 22, Block.blockSnow.blockID);
		world.setBlock(i + 62, j + 0, k + 12, Block.blockSnow.blockID);
		world.setBlock(i + 62, j + 0, k + 26, Block.blockSnow.blockID);
		world.setBlock(i + 62, j + 1, k + 12, Block.blockSnow.blockID);
		world.setBlock(i + 62, j + 1, k + 26, Block.blockSnow.blockID);
		world.setBlock(i + 62, j + 2, k + 12, Block.blockSnow.blockID);
		world.setBlock(i + 62, j + 2, k + 26, Block.blockSnow.blockID);
		world.setBlock(i + 62, j + 3, k + 12, Block.blockSnow.blockID);
		world.setBlock(i + 62, j + 3, k + 26, Block.blockSnow.blockID);
		world.setBlock(i + 62, j + 4, k + 12, Block.blockSnow.blockID);
		world.setBlock(i + 62, j + 4, k + 26, Block.blockSnow.blockID);
		world.setBlock(i + 62, j + 5, k + 13, Block.blockSnow.blockID);
		world.setBlock(i + 62, j + 5, k + 25, Block.blockSnow.blockID);
		world.setBlock(i + 62, j + 6, k + 14, Block.blockSnow.blockID);
		world.setBlock(i + 62, j + 6, k + 24, Block.blockSnow.blockID);
		world.setBlock(i + 62, j + 7, k + 14, Block.blockSnow.blockID);
		world.setBlock(i + 62, j + 7, k + 15, Block.blockSnow.blockID);
		world.setBlock(i + 62, j + 7, k + 23, Block.blockSnow.blockID);
		world.setBlock(i + 62, j + 7, k + 24, Block.blockSnow.blockID);
		world.setBlock(i + 62, j + 8, k + 16, Block.blockSnow.blockID);
		world.setBlock(i + 62, j + 8, k + 17, Block.blockSnow.blockID);
		world.setBlock(i + 62, j + 8, k + 21, Block.blockSnow.blockID);
		world.setBlock(i + 62, j + 8, k + 22, Block.blockSnow.blockID);
		world.setBlock(i + 62, j + 9, k + 18, Block.blockSnow.blockID);
		world.setBlock(i + 62, j + 9, k + 19, Block.blockSnow.blockID);
		world.setBlock(i + 62, j + 9, k + 20, Block.blockSnow.blockID);
		world.setBlock(i + 63, j + 0, k + 12, Block.blockSnow.blockID);
		world.setBlock(i + 63, j + 0, k + 13, Block.blockSteel.blockID);
		world.setBlock(i + 63, j + 0, k + 25, Block.blockSteel.blockID);
		world.setBlock(i + 63, j + 0, k + 26, Block.blockSnow.blockID);
		world.setBlock(i + 63, j + 1, k + 12, Block.blockSnow.blockID);
		world.setBlock(i + 63, j + 1, k + 26, Block.blockSnow.blockID);
		world.setBlock(i + 63, j + 2, k + 12, Block.blockSnow.blockID);
		world.setBlock(i + 63, j + 2, k + 26, Block.blockSnow.blockID);
		world.setBlock(i + 63, j + 3, k + 12, Block.blockSnow.blockID);
		world.setBlock(i + 63, j + 3, k + 26, Block.blockSnow.blockID);
		world.setBlock(i + 63, j + 4, k + 12, Block.blockSnow.blockID);
		world.setBlock(i + 63, j + 4, k + 26, Block.blockSnow.blockID);
		world.setBlock(i + 63, j + 5, k + 13, Block.blockSnow.blockID);
		world.setBlock(i + 63, j + 5, k + 25, Block.blockSnow.blockID);
		world.setBlock(i + 63, j + 6, k + 13, Block.blockSnow.blockID);
		world.setBlock(i + 63, j + 6, k + 14, Block.blockSnow.blockID);
		world.setBlock(i + 63, j + 6, k + 24, Block.blockSnow.blockID);
		world.setBlock(i + 63, j + 6, k + 25, Block.blockSnow.blockID);
		world.setBlock(i + 63, j + 7, k + 14, Block.blockSnow.blockID);
		world.setBlock(i + 63, j + 7, k + 15, Block.blockSnow.blockID);
		world.setBlock(i + 63, j + 7, k + 23, Block.blockSnow.blockID);
		world.setBlock(i + 63, j + 7, k + 24, Block.blockSnow.blockID);
		world.setBlock(i + 63, j + 8, k + 15, Block.blockSnow.blockID);
		world.setBlock(i + 63, j + 8, k + 16, Block.blockSnow.blockID);
		world.setBlock(i + 63, j + 8, k + 17, Block.blockSnow.blockID);
		world.setBlock(i + 63, j + 8, k + 21, Block.blockSnow.blockID);
		world.setBlock(i + 63, j + 8, k + 22, Block.blockSnow.blockID);
		world.setBlock(i + 63, j + 8, k + 23, Block.blockSnow.blockID);
		world.setBlock(i + 63, j + 9, k + 18, Block.blockSnow.blockID);
		world.setBlock(i + 63, j + 9, k + 19, Block.blockSnow.blockID);
		world.setBlock(i + 63, j + 9, k + 20, Block.blockSnow.blockID);
		world.setBlock(i + 64, j + 0, k + 12, Block.blockSnow.blockID);
		world.setBlock(i + 64, j + 0, k + 26, Block.blockSnow.blockID);
		world.setBlock(i + 64, j + 1, k + 12, Block.blockSnow.blockID);
		world.setBlock(i + 64, j + 1, k + 26, Block.blockSnow.blockID);
		world.setBlock(i + 64, j + 2, k + 12, Block.blockSnow.blockID);
		world.setBlock(i + 64, j + 2, k + 26, Block.blockSnow.blockID);
		world.setBlock(i + 64, j + 3, k + 12, Block.blockSnow.blockID);
		world.setBlock(i + 64, j + 3, k + 26, Block.blockSnow.blockID);
		world.setBlock(i + 64, j + 4, k + 12, Block.blockSnow.blockID);
		world.setBlock(i + 64, j + 4, k + 26, Block.blockSnow.blockID);
		world.setBlock(i + 64, j + 5, k + 13, Block.blockSnow.blockID);
		world.setBlock(i + 64, j + 5, k + 25, Block.blockSnow.blockID);
		world.setBlock(i + 64, j + 6, k + 14, Block.blockSnow.blockID);
		world.setBlock(i + 64, j + 6, k + 24, Block.blockSnow.blockID);
		world.setBlock(i + 64, j + 7, k + 14, Block.blockSnow.blockID);
		world.setBlock(i + 64, j + 7, k + 15, Block.blockSnow.blockID);
		world.setBlock(i + 64, j + 7, k + 23, Block.blockSnow.blockID);
		world.setBlock(i + 64, j + 7, k + 24, Block.blockSnow.blockID);
		world.setBlock(i + 64, j + 8, k + 16, Block.blockSnow.blockID);
		world.setBlock(i + 64, j + 8, k + 17, Block.blockSnow.blockID);
		world.setBlock(i + 64, j + 8, k + 21, Block.blockSnow.blockID);
		world.setBlock(i + 64, j + 8, k + 22, Block.blockSnow.blockID);
		world.setBlock(i + 64, j + 9, k + 18, Block.blockSnow.blockID);
		world.setBlock(i + 64, j + 9, k + 19, Block.blockSnow.blockID);
		world.setBlock(i + 64, j + 9, k + 20, Block.blockSnow.blockID);
		world.setBlock(i + 65, j + 0, k + 12, Block.blockSnow.blockID);
		world.setBlock(i + 65, j + 0, k + 26, Block.blockSnow.blockID);
		world.setBlock(i + 65, j + 1, k + 12, Block.blockSnow.blockID);
		world.setBlock(i + 65, j + 1, k + 26, Block.blockSnow.blockID);
		world.setBlock(i + 65, j + 2, k + 12, Block.blockSnow.blockID);
		world.setBlock(i + 65, j + 2, k + 26, Block.blockSnow.blockID);
		world.setBlock(i + 65, j + 3, k + 12, Block.blockSnow.blockID);
		world.setBlock(i + 65, j + 3, k + 26, Block.blockSnow.blockID);
		world.setBlock(i + 65, j + 4, k + 12, Block.blockSnow.blockID);
		world.setBlock(i + 65, j + 4, k + 26, Block.blockSnow.blockID);
		world.setBlock(i + 65, j + 5, k + 13, Block.blockSnow.blockID);
		world.setBlock(i + 65, j + 5, k + 25, Block.blockSnow.blockID);
		world.setBlock(i + 65, j + 6, k + 14, Block.blockSnow.blockID);
		world.setBlock(i + 65, j + 6, k + 24, Block.blockSnow.blockID);
		world.setBlock(i + 65, j + 7, k + 15, Block.blockSnow.blockID);
		world.setBlock(i + 65, j + 7, k + 23, Block.blockSnow.blockID);
		world.setBlock(i + 65, j + 8, k + 16, Block.blockSnow.blockID);
		world.setBlock(i + 65, j + 8, k + 17, Block.blockSnow.blockID);
		world.setBlock(i + 65, j + 8, k + 18, Block.blockSnow.blockID);
		world.setBlock(i + 65, j + 8, k + 19, Block.blockSnow.blockID);
		world.setBlock(i + 65, j + 8, k + 20, Block.blockSnow.blockID);
		world.setBlock(i + 65, j + 8, k + 21, Block.blockSnow.blockID);
		world.setBlock(i + 65, j + 8, k + 22, Block.blockSnow.blockID);
		world.setBlock(i + 66, j + 0, k + 13, Block.blockSnow.blockID);
		world.setBlock(i + 66, j + 0, k + 19, Block.oreGold.blockID);
		world.setBlock(i + 66, j + 0, k + 25, Block.blockSnow.blockID);
		world.setBlock(i + 66, j + 1, k + 13, Block.blockSnow.blockID);
		world.setBlock(i + 66, j + 1, k + 25, Block.blockSnow.blockID);
		world.setBlock(i + 66, j + 2, k + 13, Block.blockSnow.blockID);
		world.setBlock(i + 66, j + 2, k + 25, Block.blockSnow.blockID);
		world.setBlock(i + 66, j + 3, k + 13, Block.blockSnow.blockID);

		generate2(world, rand, i, j, k);
		return true;
	}

	public boolean generate2(World world, Random rand, int i, int j, int k) {
		world.setBlock(i + 66, j + 3, k + 25, Block.blockSnow.blockID);
		world.setBlock(i + 66, j + 4, k + 13, Block.blockSnow.blockID);
		world.setBlock(i + 66, j + 4, k + 25, Block.blockSnow.blockID);
		world.setBlock(i + 66, j + 5, k + 14, Block.blockSnow.blockID);
		world.setBlock(i + 66, j + 5, k + 24, Block.blockSnow.blockID);
		world.setBlock(i + 66, j + 6, k + 15, Block.blockSnow.blockID);
		world.setBlock(i + 66, j + 6, k + 23, Block.blockSnow.blockID);
		world.setBlock(i + 66, j + 7, k + 16, Block.blockSnow.blockID);
		world.setBlock(i + 66, j + 7, k + 22, Block.blockSnow.blockID);
		world.setBlock(i + 66, j + 8, k + 17, Block.blockSnow.blockID);
		world.setBlock(i + 66, j + 8, k + 18, Block.blockSnow.blockID);
		world.setBlock(i + 66, j + 8, k + 19, Block.blockSnow.blockID);
		world.setBlock(i + 66, j + 8, k + 20, Block.blockSnow.blockID);
		world.setBlock(i + 66, j + 8, k + 21, Block.blockSnow.blockID);
		world.setBlock(i + 67, j + 0, k + 13, Block.blockSnow.blockID);
		world.setBlock(i + 67, j + 0, k + 25, Block.blockSnow.blockID);
		world.setBlock(i + 67, j + 1, k + 13, Block.blockSnow.blockID);
		world.setBlock(i + 67, j + 1, k + 25, Block.blockSnow.blockID);
		world.setBlock(i + 67, j + 2, k + 13, Block.blockSnow.blockID);
		world.setBlock(i + 67, j + 2, k + 25, Block.blockSnow.blockID);
		world.setBlock(i + 67, j + 3, k + 13, Block.blockSnow.blockID);
		world.setBlock(i + 67, j + 3, k + 25, Block.blockSnow.blockID);
		world.setBlock(i + 67, j + 4, k + 13, Block.blockSnow.blockID);
		world.setBlock(i + 67, j + 4, k + 25, Block.blockSnow.blockID);
		world.setBlock(i + 67, j + 5, k + 14, Block.blockSnow.blockID);
		world.setBlock(i + 67, j + 5, k + 24, Block.blockSnow.blockID);
		world.setBlock(i + 67, j + 6, k + 15, Block.blockSnow.blockID);
		world.setBlock(i + 67, j + 6, k + 16, Block.blockSnow.blockID);
		world.setBlock(i + 67, j + 6, k + 22, Block.blockSnow.blockID);
		world.setBlock(i + 67, j + 6, k + 23, Block.blockSnow.blockID);
		world.setBlock(i + 67, j + 7, k + 17, Block.blockSnow.blockID);
		world.setBlock(i + 67, j + 7, k + 18, Block.blockSnow.blockID);
		world.setBlock(i + 67, j + 7, k + 19, Block.blockSnow.blockID);
		world.setBlock(i + 67, j + 7, k + 20, Block.blockSnow.blockID);
		world.setBlock(i + 67, j + 7, k + 21, Block.blockSnow.blockID);
		world.setBlock(i + 67, j + 8, k + 19, Block.blockSnow.blockID);
		world.setBlock(i + 68, j + 0, k + 14, Block.blockSnow.blockID);
		world.setBlock(i + 68, j + 0, k + 24, Block.blockSnow.blockID);
